{
  "version": 8,
  "blockIdVersion": 11,
  "anchorX": 0,
  "anchorY": 1,
  "anchorZ": 1,
  "blocks": [
    {
      "x": -2,
      "y": 0,
      "z": 1,
      "name": "Necrotic_Sand"
    },
    {
      "x": -1,
      "y": 0,
      "z": -1,
      "name": "Necrotic_Sand"
    },
    {
      "x": -1,
      "y": 1,
      "z": -1,
      "name": "Rock_Slate_Stalactite_Small"
    },
    {
      "x": -1,
      "y": 0,
      "z": 0,
      "name": "Necrotic_Sand"
    },
    {
      "x": -1,
      "y": 1,
      "z": 0,
      "name": "Necrotic_Sand"
    },
    {
      "x": -1,
      "y": 2,
      "z": 0,
      "name": "Rock_Slate_Stalactite_Small"
    },
    {
      "x": -1,
      "y": 0,
      "z": 1,
      "name": "Necrotic_Sand"
    },
    {
      "x": -1,
      "y": 1,
      "z": 1,
      "name": "Rock_Slate_Stalactite_Small"
    },
    {
      "x": 0,
      "y": 0,
      "z": -2,
      "name": "Necrotic_Sand"
    },
    {
      "x": 0,
      "y": 1,
      "z": -2,
      "name": "Plant_Bush_Winter",
      "support": 15
    },
    {
      "x": 0,
      "y": 0,
      "z": -1,
      "name": "Necrotic_Sand"
    },
    {
      "x": 0,
      "y": 1,
      "z": -1,
      "name": "Necrotic_Sand"
    },
    {
      "x": 0,
      "y": 2,
      "z": -1,
      "name": "Necrotic_Grass"
    },
    {
      "x": 0,
      "y": 0,
      "z": 0,
      "name": "Necrotic_Sand"
    },
    {
      "x": 0,
      "y": 1,
      "z": 0,
      "name": "Necrotic_Sand"
    },
    {
      "x": 0,
      "y": 2,
      "z": 0,
      "name": "Dead_Branch"
    },
    {
      "x": 0,
      "y": 0,
      "z": 1,
      "name": "Necrotic_Sand"
    },
    {
      "x": 0,
      "y": 1,
      "z": 1,
      "name": "Necrotic_Sand"
    },
    {
      "x": 0,
      "y": 2,
      "z": 1,
      "name": "Plant_Bush_Winter",
      "support": 15
    },
    {
      "x": 0,
      "y": 0,
      "z": 2,
      "name": "Necrotic_Sand"
    },
    {
      "x": 0,
      "y": 1,
      "z": 2,
      "name": "Necrotic_Grass"
    },
    {
      "x": 1,
      "y": 0,
      "z": -2,
      "name": "Necrotic_Sand"
    },
    {
      "x": 1,
      "y": 1,
      "z": -2,
      "name": "Necrotic_Grass"
    },
    {
      "x": 1,
      "y": 0,
      "z": -1,
      "name": "Necrotic_Sand"
    },
    {
      "x": 1,
      "y": 1,
      "z": -1,
      "name": "Rock_Slate_Stalactite_Small"
    },
    {
      "x": 1,
      "y": 0,
      "z": 0,
      "name": "Necrotic_Sand"
    },
    {
      "x": 1,
      "y": 1,
      "z": 0,
      "name": "Necrotic_Crystal"
    },
    {
      "x": 1,
      "y": 0,
      "z": 1,
      "name": "Necrotic_Sand"
    },
    {
      "x": 1,
      "y": 1,
      "z": 1,
      "name": "Rock_Slate_Stalactite_Large"
    },
    {
      "x": 1,
      "y": 2,
      "z": 1,
      "name": "Rock_Slate_Stalactite_Large",
      "filler": 1024
    },
    {
      "x": 1,
      "y": 0,
      "z": 2,
      "name": "Necrotic_Sand"
    },
    {
      "x": 1,
      "y": 1,
      "z": 2,
      "name": "Necrotic_Grass"
    },
    {
      "x": 2,
      "y": 0,
      "z": -1,
      "name": "Necrotic_Sand"
    },
    {
      "x": 2,
      "y": 1,
      "z": -1,
      "name": "Necrotic_Grass"
    },
    {
      "x": 2,
      "y": 0,
      "z": 0,
      "name": "Necrotic_Sand"
    },
    {
      "x": 2,
      "y": 1,
      "z": 0,
      "name": "Necrotic_Sand"
    },
    {
      "x": 2,
      "y": 2,
      "z": 0,
      "name": "Necrotic_Sand"
    },
    {
      "x": 2,
      "y": 3,
      "z": 0,
      "name": "Rock_Slate_Stalactite_Large"
    },
    {
      "x": 2,
      "y": 4,
      "z": 0,
      "name": "Rock_Slate_Stalactite_Large",
      "filler": 1024
    },
    {
      "x": 2,
      "y": 0,
      "z": 1,
      "name": "Necrotic_Sand"
    },
    {
      "x": 2,
      "y": 1,
      "z": 1,
      "name": "Plant_Bush_Winter",
      "support": 15
    }
  ]
}