{
  "version": 8,
  "blockIdVersion": 11,
  "anchorX": 11,
  "anchorY": 40,
  "anchorZ": -7,
  "blocks": [
    {
      "x": -28,
      "y": 23,
      "z": -1,
      "name": "Necrotic_Sand"
    },
    {
      "x": -28,
      "y": 24,
      "z": -1,
      "name": "Necrotic_Sand"
    },
    {
      "x": -28,
      "y": 25,
      "z": -1,
      "name": "Necrotic_Sand"
    },
    {
      "x": -28,
      "y": 26,
      "z": -1,
      "name": "Necrotic_Sand"
    },
    {
      "x": -28,
      "y": 27,
      "z": -1,
      "name": "Necrotic_Sand"
    },
    {
      "x": -28,
      "y": 22,
      "z": 0,
      "name": "Necrotic_Sand"
    },
    {
      "x": -28,
      "y": 23,
      "z": 0,
      "name": "Necrotic_Sand"
    },
    {
      "x": -28,
      "y": 24,
      "z": 0,
      "name": "Necrotic_Sand"
    },
    {
      "x": -28,
      "y": 25,
      "z": 0,
      "name": "Necrotic_Sand"
    },
    {
      "x": -28,
      "y": 26,
      "z": 0,
      "name": "Necrotic_Sand"
    },
    {
      "x": -28,
      "y": 27,
      "z": 0,
      "name": "Necrotic_Sand"
    },
    {
      "x": -28,
      "y": 28,
      "z": 0,
      "name": "Necrotic_Sand"
    },
    {
      "x": -28,
      "y": 22,
      "z": 1,
      "name": "Necrotic_Sand"
    },
    {
      "x": -28,
      "y": 23,
      "z": 1,
      "name": "Necrotic_Sand"
    },
    {
      "x": -28,
      "y": 24,
      "z": 1,
      "name": "Necrotic_Sand"
    },
    {
      "x": -28,
      "y": 25,
      "z": 1,
      "name": "Necrotic_Sand"
    },
    {
      "x": -28,
      "y": 26,
      "z": 1,
      "name": "Necrotic_Sand"
    },
    {
      "x": -28,
      "y": 27,
      "z": 1,
      "name": "Necrotic_Sand"
    },
    {
      "x": -28,
      "y": 28,
      "z": 1,
      "name": "Necrotic_Sand"
    },
    {
      "x": -28,
      "y": 25,
      "z": 2,
      "name": "Necrotic_Sand"
    },
    {
      "x": -28,
      "y": 26,
      "z": 2,
      "name": "Necrotic_Sand"
    },
    {
      "x": -27,
      "y": 22,
      "z": -3,
      "name": "Necrotic_Sand"
    },
    {
      "x": -27,
      "y": 23,
      "z": -3,
      "name": "Necrotic_Sand"
    },
    {
      "x": -27,
      "y": 24,
      "z": -3,
      "name": "Necrotic_Sand"
    },
    {
      "x": -27,
      "y": 25,
      "z": -3,
      "name": "Necrotic_Sand"
    },
    {
      "x": -27,
      "y": 26,
      "z": -3,
      "name": "Necrotic_Sand"
    },
    {
      "x": -27,
      "y": 27,
      "z": -3,
      "name": "Necrotic_Sand"
    },
    {
      "x": -27,
      "y": 20,
      "z": -2,
      "name": "Necrotic_Sand"
    },
    {
      "x": -27,
      "y": 21,
      "z": -2,
      "name": "Necrotic_Sand"
    },
    {
      "x": -27,
      "y": 22,
      "z": -2,
      "name": "Necrotic_Sand"
    },
    {
      "x": -27,
      "y": 23,
      "z": -2,
      "name": "Necrotic_Sand"
    },
    {
      "x": -27,
      "y": 24,
      "z": -2,
      "name": "Necrotic_Sand"
    },
    {
      "x": -27,
      "y": 25,
      "z": -2,
      "name": "Necrotic_Sand"
    },
    {
      "x": -27,
      "y": 26,
      "z": -2,
      "name": "Necrotic_Sand"
    },
    {
      "x": -27,
      "y": 27,
      "z": -2,
      "name": "Necrotic_Sand"
    },
    {
      "x": -27,
      "y": 28,
      "z": -2,
      "name": "Necrotic_Sand"
    },
    {
      "x": -27,
      "y": 29,
      "z": -2,
      "name": "Necrotic_Sand"
    },
    {
      "x": -27,
      "y": 30,
      "z": -2,
      "name": "Necrotic_Sand"
    },
    {
      "x": -27,
      "y": 19,
      "z": -1,
      "name": "Necrotic_Sand"
    },
    {
      "x": -27,
      "y": 20,
      "z": -1,
      "name": "Necrotic_Sand"
    },
    {
      "x": -27,
      "y": 21,
      "z": -1,
      "name": "Necrotic_Sand"
    },
    {
      "x": -27,
      "y": 22,
      "z": -1,
      "name": "Necrotic_Sand"
    },
    {
      "x": -27,
      "y": 23,
      "z": -1,
      "name": "Necrotic_Sand"
    },
    {
      "x": -27,
      "y": 24,
      "z": -1,
      "name": "Necrotic_Sand"
    },
    {
      "x": -27,
      "y": 25,
      "z": -1,
      "name": "Necrotic_Sand"
    },
    {
      "x": -27,
      "y": 26,
      "z": -1,
      "name": "Necrotic_Sand"
    },
    {
      "x": -27,
      "y": 27,
      "z": -1,
      "name": "Necrotic_Sand"
    },
    {
      "x": -27,
      "y": 28,
      "z": -1,
      "name": "Necrotic_Sand"
    },
    {
      "x": -27,
      "y": 29,
      "z": -1,
      "name": "Necrotic_Sand"
    },
    {
      "x": -27,
      "y": 30,
      "z": -1,
      "name": "Necrotic_Sand"
    },
    {
      "x": -27,
      "y": 31,
      "z": -1,
      "name": "Necrotic_Sand"
    },
    {
      "x": -27,
      "y": 32,
      "z": -1,
      "name": "Necrotic_Sand"
    },
    {
      "x": -27,
      "y": 18,
      "z": 0,
      "name": "Necrotic_Sand"
    },
    {
      "x": -27,
      "y": 19,
      "z": 0,
      "name": "Necrotic_Sand"
    },
    {
      "x": -27,
      "y": 20,
      "z": 0,
      "name": "Necrotic_Sand"
    },
    {
      "x": -27,
      "y": 21,
      "z": 0,
      "name": "Necrotic_Sand"
    },
    {
      "x": -27,
      "y": 22,
      "z": 0,
      "name": "Necrotic_Sand"
    },
    {
      "x": -27,
      "y": 23,
      "z": 0,
      "name": "Necrotic_Sand"
    },
    {
      "x": -27,
      "y": 24,
      "z": 0,
      "name": "Necrotic_Sand"
    },
    {
      "x": -27,
      "y": 25,
      "z": 0,
      "name": "Necrotic_Sand"
    },
    {
      "x": -27,
      "y": 26,
      "z": 0,
      "name": "Necrotic_Sand"
    },
    {
      "x": -27,
      "y": 27,
      "z": 0,
      "name": "Necrotic_Sand"
    },
    {
      "x": -27,
      "y": 28,
      "z": 0,
      "name": "Necrotic_Sand"
    },
    {
      "x": -27,
      "y": 29,
      "z": 0,
      "name": "Necrotic_Sand"
    },
    {
      "x": -27,
      "y": 30,
      "z": 0,
      "name": "Necrotic_Sand"
    },
    {
      "x": -27,
      "y": 31,
      "z": 0,
      "name": "Necrotic_Sand"
    },
    {
      "x": -27,
      "y": 32,
      "z": 0,
      "name": "Necrotic_Sand"
    },
    {
      "x": -27,
      "y": 33,
      "z": 0,
      "name": "Necrotic_Sand"
    },
    {
      "x": -27,
      "y": 34,
      "z": 0,
      "name": "Necrotic_Sand"
    },
    {
      "x": -27,
      "y": 35,
      "z": 0,
      "name": "Necrotic_Sand"
    },
    {
      "x": -27,
      "y": 36,
      "z": 0,
      "name": "Necrotic_Sand"
    },
    {
      "x": -27,
      "y": 37,
      "z": 0,
      "name": "Necrotic_Sand"
    },
    {
      "x": -27,
      "y": 38,
      "z": 0,
      "name": "Necrotic_Sand"
    },
    {
      "x": -27,
      "y": 39,
      "z": 0,
      "name": "Necrotic_Sand"
    },
    {
      "x": -27,
      "y": 40,
      "z": 0,
      "name": "Necrotic_Sand"
    },
    {
      "x": -27,
      "y": 41,
      "z": 0,
      "name": "Necrotic_Sand"
    },
    {
      "x": -27,
      "y": 42,
      "z": 0,
      "name": "Necrotic_Sand"
    },
    {
      "x": -27,
      "y": 43,
      "z": 0,
      "name": "Necrotic_Sand"
    },
    {
      "x": -27,
      "y": 44,
      "z": 0,
      "name": "Necrotic_Sand"
    },
    {
      "x": -27,
      "y": 45,
      "z": 0,
      "name": "Necrotic_Sand"
    },
    {
      "x": -27,
      "y": 46,
      "z": 0,
      "name": "Necrotic_Sand"
    },
    {
      "x": -27,
      "y": 47,
      "z": 0,
      "name": "Sword_Cemetery_1",
      "rotation": 3
    },
    {
      "x": -27,
      "y": 18,
      "z": 1,
      "name": "Necrotic_Sand"
    },
    {
      "x": -27,
      "y": 19,
      "z": 1,
      "name": "Necrotic_Sand"
    },
    {
      "x": -27,
      "y": 20,
      "z": 1,
      "name": "Necrotic_Sand"
    },
    {
      "x": -27,
      "y": 21,
      "z": 1,
      "name": "Necrotic_Sand"
    },
    {
      "x": -27,
      "y": 22,
      "z": 1,
      "name": "Necrotic_Sand"
    },
    {
      "x": -27,
      "y": 23,
      "z": 1,
      "name": "Necrotic_Sand"
    },
    {
      "x": -27,
      "y": 24,
      "z": 1,
      "name": "Necrotic_Sand"
    },
    {
      "x": -27,
      "y": 25,
      "z": 1,
      "name": "Necrotic_Sand"
    },
    {
      "x": -27,
      "y": 26,
      "z": 1,
      "name": "Necrotic_Sand"
    },
    {
      "x": -27,
      "y": 27,
      "z": 1,
      "name": "Necrotic_Sand"
    },
    {
      "x": -27,
      "y": 28,
      "z": 1,
      "name": "Necrotic_Sand"
    },
    {
      "x": -27,
      "y": 29,
      "z": 1,
      "name": "Necrotic_Sand"
    },
    {
      "x": -27,
      "y": 30,
      "z": 1,
      "name": "Necrotic_Sand"
    },
    {
      "x": -27,
      "y": 31,
      "z": 1,
      "name": "Necrotic_Sand"
    },
    {
      "x": -27,
      "y": 32,
      "z": 1,
      "name": "Necrotic_Sand"
    },
    {
      "x": -27,
      "y": 33,
      "z": 1,
      "name": "Necrotic_Sand"
    },
    {
      "x": -27,
      "y": 34,
      "z": 1,
      "name": "Necrotic_Sand"
    },
    {
      "x": -27,
      "y": 35,
      "z": 1,
      "name": "Necrotic_Sand"
    },
    {
      "x": -27,
      "y": 36,
      "z": 1,
      "name": "Necrotic_Sand"
    },
    {
      "x": -27,
      "y": 37,
      "z": 1,
      "name": "Necrotic_Sand"
    },
    {
      "x": -27,
      "y": 38,
      "z": 1,
      "name": "Necrotic_Sand"
    },
    {
      "x": -27,
      "y": 39,
      "z": 1,
      "name": "Necrotic_Sand"
    },
    {
      "x": -27,
      "y": 40,
      "z": 1,
      "name": "Necrotic_Sand"
    },
    {
      "x": -27,
      "y": 41,
      "z": 1,
      "name": "Necrotic_Sand"
    },
    {
      "x": -27,
      "y": 42,
      "z": 1,
      "name": "Necrotic_Sand"
    },
    {
      "x": -27,
      "y": 43,
      "z": 1,
      "name": "Necrotic_Sand"
    },
    {
      "x": -27,
      "y": 44,
      "z": 1,
      "name": "Necrotic_Sand"
    },
    {
      "x": -27,
      "y": 45,
      "z": 1,
      "name": "Necrotic_Sand"
    },
    {
      "x": -27,
      "y": 46,
      "z": 1,
      "name": "Necrotic_Sand"
    },
    {
      "x": -27,
      "y": 47,
      "z": 1,
      "name": "Necrotic_Sand"
    },
    {
      "x": -27,
      "y": 48,
      "z": 1,
      "name": "Sword_Cemetery_1",
      "rotation": 3
    },
    {
      "x": -27,
      "y": 19,
      "z": 2,
      "name": "Necrotic_Sand"
    },
    {
      "x": -27,
      "y": 20,
      "z": 2,
      "name": "Necrotic_Sand"
    },
    {
      "x": -27,
      "y": 21,
      "z": 2,
      "name": "Necrotic_Sand"
    },
    {
      "x": -27,
      "y": 22,
      "z": 2,
      "name": "Necrotic_Sand"
    },
    {
      "x": -27,
      "y": 23,
      "z": 2,
      "name": "Necrotic_Sand"
    },
    {
      "x": -27,
      "y": 24,
      "z": 2,
      "name": "Necrotic_Sand"
    },
    {
      "x": -27,
      "y": 25,
      "z": 2,
      "name": "Necrotic_Sand"
    },
    {
      "x": -27,
      "y": 26,
      "z": 2,
      "name": "Necrotic_Sand"
    },
    {
      "x": -27,
      "y": 27,
      "z": 2,
      "name": "Necrotic_Sand"
    },
    {
      "x": -27,
      "y": 28,
      "z": 2,
      "name": "Necrotic_Sand"
    },
    {
      "x": -27,
      "y": 29,
      "z": 2,
      "name": "Necrotic_Sand"
    },
    {
      "x": -27,
      "y": 30,
      "z": 2,
      "name": "Necrotic_Sand"
    },
    {
      "x": -27,
      "y": 31,
      "z": 2,
      "name": "Necrotic_Sand"
    },
    {
      "x": -27,
      "y": 32,
      "z": 2,
      "name": "Necrotic_Sand"
    },
    {
      "x": -27,
      "y": 33,
      "z": 2,
      "name": "Necrotic_Sand"
    },
    {
      "x": -27,
      "y": 34,
      "z": 2,
      "name": "Necrotic_Sand"
    },
    {
      "x": -27,
      "y": 35,
      "z": 2,
      "name": "Necrotic_Sand"
    },
    {
      "x": -27,
      "y": 36,
      "z": 2,
      "name": "Necrotic_Sand"
    },
    {
      "x": -27,
      "y": 37,
      "z": 2,
      "name": "Necrotic_Sand"
    },
    {
      "x": -27,
      "y": 38,
      "z": 2,
      "name": "Necrotic_Sand"
    },
    {
      "x": -27,
      "y": 39,
      "z": 2,
      "name": "Necrotic_Sand"
    },
    {
      "x": -27,
      "y": 40,
      "z": 2,
      "name": "Necrotic_Sand"
    },
    {
      "x": -27,
      "y": 41,
      "z": 2,
      "name": "Necrotic_Sand"
    },
    {
      "x": -27,
      "y": 42,
      "z": 2,
      "name": "Necrotic_Sand"
    },
    {
      "x": -27,
      "y": 43,
      "z": 2,
      "name": "Necrotic_Sand"
    },
    {
      "x": -27,
      "y": 44,
      "z": 2,
      "name": "Necrotic_Sand"
    },
    {
      "x": -27,
      "y": 45,
      "z": 2,
      "name": "Necrotic_Sand"
    },
    {
      "x": -27,
      "y": 46,
      "z": 2,
      "name": "Necrotic_Sand"
    },
    {
      "x": -27,
      "y": 21,
      "z": 3,
      "name": "Wood_Burnt_Roots"
    },
    {
      "x": -27,
      "y": 22,
      "z": 3,
      "name": "Necrotic_Sand"
    },
    {
      "x": -27,
      "y": 23,
      "z": 3,
      "name": "Necrotic_Sand"
    },
    {
      "x": -27,
      "y": 24,
      "z": 3,
      "name": "Necrotic_Sand"
    },
    {
      "x": -27,
      "y": 25,
      "z": 3,
      "name": "Necrotic_Sand"
    },
    {
      "x": -27,
      "y": 26,
      "z": 3,
      "name": "Necrotic_Sand"
    },
    {
      "x": -27,
      "y": 27,
      "z": 3,
      "name": "Necrotic_Sand"
    },
    {
      "x": -27,
      "y": 28,
      "z": 3,
      "name": "Necrotic_Sand"
    },
    {
      "x": -27,
      "y": 29,
      "z": 3,
      "name": "Necrotic_Sand"
    },
    {
      "x": -27,
      "y": 30,
      "z": 3,
      "name": "Necrotic_Sand"
    },
    {
      "x": -27,
      "y": 31,
      "z": 3,
      "name": "Necrotic_Sand"
    },
    {
      "x": -26,
      "y": 21,
      "z": -4,
      "name": "Necrotic_Sand"
    },
    {
      "x": -26,
      "y": 22,
      "z": -4,
      "name": "Necrotic_Sand"
    },
    {
      "x": -26,
      "y": 23,
      "z": -4,
      "name": "Necrotic_Sand"
    },
    {
      "x": -26,
      "y": 24,
      "z": -4,
      "name": "Necrotic_Sand"
    },
    {
      "x": -26,
      "y": 25,
      "z": -4,
      "name": "Necrotic_Sand"
    },
    {
      "x": -26,
      "y": 26,
      "z": -4,
      "name": "Necrotic_Sand"
    },
    {
      "x": -26,
      "y": 27,
      "z": -4,
      "name": "Necrotic_Sand"
    },
    {
      "x": -26,
      "y": 28,
      "z": -4,
      "name": "Necrotic_Sand"
    },
    {
      "x": -26,
      "y": 19,
      "z": -3,
      "name": "Wood_Burnt_Roots"
    },
    {
      "x": -26,
      "y": 20,
      "z": -3,
      "name": "Necrotic_Sand"
    },
    {
      "x": -26,
      "y": 21,
      "z": -3,
      "name": "Necrotic_Sand"
    },
    {
      "x": -26,
      "y": 22,
      "z": -3,
      "name": "Necrotic_Sand"
    },
    {
      "x": -26,
      "y": 23,
      "z": -3,
      "name": "Necrotic_Sand"
    },
    {
      "x": -26,
      "y": 24,
      "z": -3,
      "name": "Necrotic_Sand"
    },
    {
      "x": -26,
      "y": 25,
      "z": -3,
      "name": "Necrotic_Sand"
    },
    {
      "x": -26,
      "y": 26,
      "z": -3,
      "name": "Necrotic_Sand"
    },
    {
      "x": -26,
      "y": 27,
      "z": -3,
      "name": "Necrotic_Sand"
    },
    {
      "x": -26,
      "y": 28,
      "z": -3,
      "name": "Necrotic_Sand"
    },
    {
      "x": -26,
      "y": 29,
      "z": -3,
      "name": "Necrotic_Sand"
    },
    {
      "x": -26,
      "y": 30,
      "z": -3,
      "name": "Necrotic_Sand"
    },
    {
      "x": -26,
      "y": 18,
      "z": -2,
      "name": "Necrotic_Sand"
    },
    {
      "x": -26,
      "y": 19,
      "z": -2,
      "name": "Necrotic_Sand"
    },
    {
      "x": -26,
      "y": 20,
      "z": -2,
      "name": "Necrotic_Sand"
    },
    {
      "x": -26,
      "y": 21,
      "z": -2,
      "name": "Necrotic_Sand"
    },
    {
      "x": -26,
      "y": 22,
      "z": -2,
      "name": "Necrotic_Sand"
    },
    {
      "x": -26,
      "y": 23,
      "z": -2,
      "name": "Necrotic_Sand"
    },
    {
      "x": -26,
      "y": 24,
      "z": -2,
      "name": "Necrotic_Sand"
    },
    {
      "x": -26,
      "y": 25,
      "z": -2,
      "name": "Necrotic_Sand"
    },
    {
      "x": -26,
      "y": 26,
      "z": -2,
      "name": "Necrotic_Sand"
    },
    {
      "x": -26,
      "y": 27,
      "z": -2,
      "name": "Necrotic_Sand"
    },
    {
      "x": -26,
      "y": 28,
      "z": -2,
      "name": "Necrotic_Sand"
    },
    {
      "x": -26,
      "y": 29,
      "z": -2,
      "name": "Necrotic_Sand"
    },
    {
      "x": -26,
      "y": 30,
      "z": -2,
      "name": "Necrotic_Sand"
    },
    {
      "x": -26,
      "y": 31,
      "z": -2,
      "name": "Necrotic_Sand"
    },
    {
      "x": -26,
      "y": 32,
      "z": -2,
      "name": "Necrotic_Sand"
    },
    {
      "x": -26,
      "y": 33,
      "z": -2,
      "name": "Necrotic_Sand"
    },
    {
      "x": -26,
      "y": 34,
      "z": -2,
      "name": "Necrotic_Sand"
    },
    {
      "x": -26,
      "y": 35,
      "z": -2,
      "name": "Necrotic_Sand"
    },
    {
      "x": -26,
      "y": 36,
      "z": -2,
      "name": "Necrotic_Sand"
    },
    {
      "x": -26,
      "y": 37,
      "z": -2,
      "name": "Necrotic_Sand"
    },
    {
      "x": -26,
      "y": 38,
      "z": -2,
      "name": "Necrotic_Sand"
    },
    {
      "x": -26,
      "y": 39,
      "z": -2,
      "name": "Necrotic_Sand"
    },
    {
      "x": -26,
      "y": 40,
      "z": -2,
      "name": "Necrotic_Sand"
    },
    {
      "x": -26,
      "y": 41,
      "z": -2,
      "name": "Necrotic_Sand"
    },
    {
      "x": -26,
      "y": 42,
      "z": -2,
      "name": "Necrotic_Sand"
    },
    {
      "x": -26,
      "y": 43,
      "z": -2,
      "name": "Necrotic_Sand"
    },
    {
      "x": -26,
      "y": 44,
      "z": -2,
      "name": "Necrotic_Sand"
    },
    {
      "x": -26,
      "y": 45,
      "z": -2,
      "name": "Necrotic_Sand"
    },
    {
      "x": -26,
      "y": 46,
      "z": -2,
      "name": "Necrotic_Sand"
    },
    {
      "x": -26,
      "y": 16,
      "z": -1,
      "name": "Wood_Burnt_Roots"
    },
    {
      "x": -26,
      "y": 17,
      "z": -1,
      "name": "Necrotic_Sand"
    },
    {
      "x": -26,
      "y": 18,
      "z": -1,
      "name": "Necrotic_Sand"
    },
    {
      "x": -26,
      "y": 19,
      "z": -1,
      "name": "Necrotic_Sand"
    },
    {
      "x": -26,
      "y": 20,
      "z": -1,
      "name": "Necrotic_Sand"
    },
    {
      "x": -26,
      "y": 21,
      "z": -1,
      "name": "Necrotic_Sand"
    },
    {
      "x": -26,
      "y": 22,
      "z": -1,
      "name": "Necrotic_Sand"
    },
    {
      "x": -26,
      "y": 23,
      "z": -1,
      "name": "Necrotic_Sand"
    },
    {
      "x": -26,
      "y": 24,
      "z": -1,
      "name": "Necrotic_Sand"
    },
    {
      "x": -26,
      "y": 25,
      "z": -1,
      "name": "Necrotic_Sand"
    },
    {
      "x": -26,
      "y": 26,
      "z": -1,
      "name": "Necrotic_Sand"
    },
    {
      "x": -26,
      "y": 27,
      "z": -1,
      "name": "Necrotic_Sand"
    },
    {
      "x": -26,
      "y": 28,
      "z": -1,
      "name": "Necrotic_Sand"
    },
    {
      "x": -26,
      "y": 29,
      "z": -1,
      "name": "Necrotic_Sand"
    },
    {
      "x": -26,
      "y": 30,
      "z": -1,
      "name": "Necrotic_Sand"
    },
    {
      "x": -26,
      "y": 31,
      "z": -1,
      "name": "Necrotic_Sand"
    },
    {
      "x": -26,
      "y": 32,
      "z": -1,
      "name": "Necrotic_Sand"
    },
    {
      "x": -26,
      "y": 33,
      "z": -1,
      "name": "Necrotic_Sand"
    },
    {
      "x": -26,
      "y": 34,
      "z": -1,
      "name": "Necrotic_Sand"
    },
    {
      "x": -26,
      "y": 35,
      "z": -1,
      "name": "Necrotic_Sand"
    },
    {
      "x": -26,
      "y": 36,
      "z": -1,
      "name": "Necrotic_Sand"
    },
    {
      "x": -26,
      "y": 37,
      "z": -1,
      "name": "Necrotic_Sand"
    },
    {
      "x": -26,
      "y": 38,
      "z": -1,
      "name": "Necrotic_Sand"
    },
    {
      "x": -26,
      "y": 39,
      "z": -1,
      "name": "Necrotic_Sand"
    },
    {
      "x": -26,
      "y": 40,
      "z": -1,
      "name": "Necrotic_Sand"
    },
    {
      "x": -26,
      "y": 41,
      "z": -1,
      "name": "Necrotic_Sand"
    },
    {
      "x": -26,
      "y": 42,
      "z": -1,
      "name": "Necrotic_Sand"
    },
    {
      "x": -26,
      "y": 43,
      "z": -1,
      "name": "Necrotic_Sand"
    },
    {
      "x": -26,
      "y": 44,
      "z": -1,
      "name": "Necrotic_Sand"
    },
    {
      "x": -26,
      "y": 45,
      "z": -1,
      "name": "Necrotic_Sand"
    },
    {
      "x": -26,
      "y": 46,
      "z": -1,
      "name": "Necrotic_Sand"
    },
    {
      "x": -26,
      "y": 47,
      "z": -1,
      "name": "Necrotic_Sand"
    },
    {
      "x": -26,
      "y": 48,
      "z": -1,
      "name": "Necrotic_Sand"
    },
    {
      "x": -26,
      "y": 49,
      "z": -1,
      "name": "Necrotic_Sand"
    },
    {
      "x": -26,
      "y": 50,
      "z": -1,
      "name": "Necrotic_Sand"
    },
    {
      "x": -26,
      "y": 51,
      "z": -1,
      "name": "Necrotic_Sand"
    },
    {
      "x": -26,
      "y": 17,
      "z": 0,
      "name": "Necrotic_Sand"
    },
    {
      "x": -26,
      "y": 18,
      "z": 0,
      "name": "Necrotic_Sand"
    },
    {
      "x": -26,
      "y": 19,
      "z": 0,
      "name": "Necrotic_Sand"
    },
    {
      "x": -26,
      "y": 20,
      "z": 0,
      "name": "Necrotic_Sand"
    },
    {
      "x": -26,
      "y": 21,
      "z": 0,
      "name": "Necrotic_Sand"
    },
    {
      "x": -26,
      "y": 22,
      "z": 0,
      "name": "Necrotic_Sand"
    },
    {
      "x": -26,
      "y": 23,
      "z": 0,
      "name": "Necrotic_Sand"
    },
    {
      "x": -26,
      "y": 24,
      "z": 0,
      "name": "Necrotic_Sand"
    },
    {
      "x": -26,
      "y": 25,
      "z": 0,
      "name": "Necrotic_Sand"
    },
    {
      "x": -26,
      "y": 26,
      "z": 0,
      "name": "Necrotic_Sand"
    },
    {
      "x": -26,
      "y": 27,
      "z": 0,
      "name": "Necrotic_Sand"
    },
    {
      "x": -26,
      "y": 28,
      "z": 0,
      "name": "Necrotic_Sand"
    },
    {
      "x": -26,
      "y": 29,
      "z": 0,
      "name": "Necrotic_Sand"
    },
    {
      "x": -26,
      "y": 30,
      "z": 0,
      "name": "Necrotic_Sand"
    },
    {
      "x": -26,
      "y": 31,
      "z": 0,
      "name": "Necrotic_Sand"
    },
    {
      "x": -26,
      "y": 32,
      "z": 0,
      "name": "Necrotic_Sand"
    },
    {
      "x": -26,
      "y": 33,
      "z": 0,
      "name": "Necrotic_Sand"
    },
    {
      "x": -26,
      "y": 34,
      "z": 0,
      "name": "Necrotic_Sand"
    },
    {
      "x": -26,
      "y": 35,
      "z": 0,
      "name": "Necrotic_Sand"
    },
    {
      "x": -26,
      "y": 36,
      "z": 0,
      "name": "Necrotic_Sand"
    },
    {
      "x": -26,
      "y": 37,
      "z": 0,
      "name": "Necrotic_Sand"
    },
    {
      "x": -26,
      "y": 38,
      "z": 0,
      "name": "Necrotic_Sand"
    },
    {
      "x": -26,
      "y": 39,
      "z": 0,
      "name": "Necrotic_Sand"
    },
    {
      "x": -26,
      "y": 40,
      "z": 0,
      "name": "Necrotic_Sand"
    },
    {
      "x": -26,
      "y": 41,
      "z": 0,
      "name": "Necrotic_Sand"
    },
    {
      "x": -26,
      "y": 42,
      "z": 0,
      "name": "Necrotic_Sand"
    },
    {
      "x": -26,
      "y": 43,
      "z": 0,
      "name": "Necrotic_Sand"
    },
    {
      "x": -26,
      "y": 44,
      "z": 0,
      "name": "Necrotic_Sand"
    },
    {
      "x": -26,
      "y": 45,
      "z": 0,
      "name": "Necrotic_Sand"
    },
    {
      "x": -26,
      "y": 46,
      "z": 0,
      "name": "Necrotic_Sand"
    },
    {
      "x": -26,
      "y": 47,
      "z": 0,
      "name": "Necrotic_Sand"
    },
    {
      "x": -26,
      "y": 48,
      "z": 0,
      "name": "Necrotic_Sand"
    },
    {
      "x": -26,
      "y": 49,
      "z": 0,
      "name": "Necrotic_Sand"
    },
    {
      "x": -26,
      "y": 50,
      "z": 0,
      "name": "Necrotic_Sand"
    },
    {
      "x": -26,
      "y": 51,
      "z": 0,
      "name": "Necrotic_Sand"
    },
    {
      "x": -26,
      "y": 52,
      "z": 0,
      "name": "Necrotic_Sand"
    },
    {
      "x": -26,
      "y": 53,
      "z": 0,
      "name": "Sword_Cemetery_1",
      "rotation": 2
    },
    {
      "x": -26,
      "y": 17,
      "z": 1,
      "name": "Necrotic_Sand"
    },
    {
      "x": -26,
      "y": 18,
      "z": 1,
      "name": "Necrotic_Sand"
    },
    {
      "x": -26,
      "y": 19,
      "z": 1,
      "name": "Necrotic_Sand"
    },
    {
      "x": -26,
      "y": 20,
      "z": 1,
      "name": "Necrotic_Sand"
    },
    {
      "x": -26,
      "y": 21,
      "z": 1,
      "name": "Necrotic_Sand"
    },
    {
      "x": -26,
      "y": 22,
      "z": 1,
      "name": "Necrotic_Sand"
    },
    {
      "x": -26,
      "y": 23,
      "z": 1,
      "name": "Necrotic_Sand"
    },
    {
      "x": -26,
      "y": 24,
      "z": 1,
      "name": "Necrotic_Sand"
    },
    {
      "x": -26,
      "y": 25,
      "z": 1,
      "name": "Necrotic_Sand"
    },
    {
      "x": -26,
      "y": 26,
      "z": 1,
      "name": "Necrotic_Sand"
    },
    {
      "x": -26,
      "y": 27,
      "z": 1,
      "name": "Necrotic_Sand"
    },
    {
      "x": -26,
      "y": 28,
      "z": 1,
      "name": "Necrotic_Sand"
    },
    {
      "x": -26,
      "y": 29,
      "z": 1,
      "name": "Necrotic_Sand"
    },
    {
      "x": -26,
      "y": 30,
      "z": 1,
      "name": "Necrotic_Sand"
    },
    {
      "x": -26,
      "y": 31,
      "z": 1,
      "name": "Necrotic_Sand"
    },
    {
      "x": -26,
      "y": 32,
      "z": 1,
      "name": "Necrotic_Sand"
    },
    {
      "x": -26,
      "y": 33,
      "z": 1,
      "name": "Necrotic_Sand"
    },
    {
      "x": -26,
      "y": 34,
      "z": 1,
      "name": "Necrotic_Sand"
    },
    {
      "x": -26,
      "y": 35,
      "z": 1,
      "name": "Necrotic_Sand"
    },
    {
      "x": -26,
      "y": 36,
      "z": 1,
      "name": "Necrotic_Sand"
    },
    {
      "x": -26,
      "y": 37,
      "z": 1,
      "name": "Necrotic_Sand"
    },
    {
      "x": -26,
      "y": 38,
      "z": 1,
      "name": "Necrotic_Sand"
    },
    {
      "x": -26,
      "y": 39,
      "z": 1,
      "name": "Necrotic_Sand"
    },
    {
      "x": -26,
      "y": 40,
      "z": 1,
      "name": "Necrotic_Sand"
    },
    {
      "x": -26,
      "y": 41,
      "z": 1,
      "name": "Necrotic_Sand"
    },
    {
      "x": -26,
      "y": 42,
      "z": 1,
      "name": "Necrotic_Sand"
    },
    {
      "x": -26,
      "y": 43,
      "z": 1,
      "name": "Necrotic_Sand"
    },
    {
      "x": -26,
      "y": 44,
      "z": 1,
      "name": "Necrotic_Sand"
    },
    {
      "x": -26,
      "y": 45,
      "z": 1,
      "name": "Necrotic_Sand"
    },
    {
      "x": -26,
      "y": 46,
      "z": 1,
      "name": "Necrotic_Sand"
    },
    {
      "x": -26,
      "y": 47,
      "z": 1,
      "name": "Necrotic_Sand"
    },
    {
      "x": -26,
      "y": 48,
      "z": 1,
      "name": "Necrotic_Sand"
    },
    {
      "x": -26,
      "y": 49,
      "z": 1,
      "name": "Necrotic_Sand"
    },
    {
      "x": -26,
      "y": 50,
      "z": 1,
      "name": "Necrotic_Sand"
    },
    {
      "x": -26,
      "y": 51,
      "z": 1,
      "name": "Necrotic_Sand"
    },
    {
      "x": -26,
      "y": 52,
      "z": 1,
      "name": "Necrotic_Sand"
    },
    {
      "x": -26,
      "y": 53,
      "z": 1,
      "name": "Necrotic_Sand"
    },
    {
      "x": -26,
      "y": 69,
      "z": 1,
      "name": "Wood_Burnt_Roots"
    },
    {
      "x": -26,
      "y": 70,
      "z": 1,
      "name": "Necrotic_Sand"
    },
    {
      "x": -26,
      "y": 71,
      "z": 1,
      "name": "Necrotic_Sand"
    },
    {
      "x": -26,
      "y": 72,
      "z": 1,
      "name": "Necrotic_Sand"
    },
    {
      "x": -26,
      "y": 73,
      "z": 1,
      "name": "Sword_Cemetery_3",
      "rotation": 2
    },
    {
      "x": -26,
      "y": 79,
      "z": 1,
      "name": "Necrotic_Sand"
    },
    {
      "x": -26,
      "y": 80,
      "z": 1,
      "name": "Necrotic_Sand"
    },
    {
      "x": -26,
      "y": 81,
      "z": 1,
      "name": "Necrotic_Sand"
    },
    {
      "x": -26,
      "y": 82,
      "z": 1,
      "name": "Sword_Cemetery_1",
      "rotation": 3
    },
    {
      "x": -26,
      "y": 17,
      "z": 2,
      "name": "Necrotic_Sand"
    },
    {
      "x": -26,
      "y": 18,
      "z": 2,
      "name": "Necrotic_Sand"
    },
    {
      "x": -26,
      "y": 19,
      "z": 2,
      "name": "Necrotic_Sand"
    },
    {
      "x": -26,
      "y": 20,
      "z": 2,
      "name": "Necrotic_Sand"
    },
    {
      "x": -26,
      "y": 21,
      "z": 2,
      "name": "Necrotic_Sand"
    },
    {
      "x": -26,
      "y": 22,
      "z": 2,
      "name": "Necrotic_Sand"
    },
    {
      "x": -26,
      "y": 23,
      "z": 2,
      "name": "Necrotic_Sand"
    },
    {
      "x": -26,
      "y": 24,
      "z": 2,
      "name": "Necrotic_Sand"
    },
    {
      "x": -26,
      "y": 25,
      "z": 2,
      "name": "Necrotic_Sand"
    },
    {
      "x": -26,
      "y": 26,
      "z": 2,
      "name": "Necrotic_Sand"
    },
    {
      "x": -26,
      "y": 27,
      "z": 2,
      "name": "Necrotic_Sand"
    },
    {
      "x": -26,
      "y": 28,
      "z": 2,
      "name": "Necrotic_Sand"
    },
    {
      "x": -26,
      "y": 29,
      "z": 2,
      "name": "Necrotic_Sand"
    },
    {
      "x": -26,
      "y": 30,
      "z": 2,
      "name": "Necrotic_Sand"
    },
    {
      "x": -26,
      "y": 31,
      "z": 2,
      "name": "Necrotic_Sand"
    },
    {
      "x": -26,
      "y": 32,
      "z": 2,
      "name": "Necrotic_Sand"
    },
    {
      "x": -26,
      "y": 33,
      "z": 2,
      "name": "Necrotic_Sand"
    },
    {
      "x": -26,
      "y": 34,
      "z": 2,
      "name": "Necrotic_Sand"
    },
    {
      "x": -26,
      "y": 35,
      "z": 2,
      "name": "Necrotic_Sand"
    },
    {
      "x": -26,
      "y": 36,
      "z": 2,
      "name": "Necrotic_Sand"
    },
    {
      "x": -26,
      "y": 37,
      "z": 2,
      "name": "Necrotic_Sand"
    },
    {
      "x": -26,
      "y": 38,
      "z": 2,
      "name": "Necrotic_Sand"
    },
    {
      "x": -26,
      "y": 39,
      "z": 2,
      "name": "Necrotic_Sand"
    },
    {
      "x": -26,
      "y": 40,
      "z": 2,
      "name": "Necrotic_Sand"
    },
    {
      "x": -26,
      "y": 41,
      "z": 2,
      "name": "Necrotic_Sand"
    },
    {
      "x": -26,
      "y": 42,
      "z": 2,
      "name": "Necrotic_Sand"
    },
    {
      "x": -26,
      "y": 43,
      "z": 2,
      "name": "Necrotic_Sand"
    },
    {
      "x": -26,
      "y": 44,
      "z": 2,
      "name": "Necrotic_Sand"
    },
    {
      "x": -26,
      "y": 45,
      "z": 2,
      "name": "Necrotic_Sand"
    },
    {
      "x": -26,
      "y": 46,
      "z": 2,
      "name": "Necrotic_Sand"
    },
    {
      "x": -26,
      "y": 47,
      "z": 2,
      "name": "Necrotic_Sand"
    },
    {
      "x": -26,
      "y": 48,
      "z": 2,
      "name": "Necrotic_Sand"
    },
    {
      "x": -26,
      "y": 49,
      "z": 2,
      "name": "Necrotic_Sand"
    },
    {
      "x": -26,
      "y": 50,
      "z": 2,
      "name": "Necrotic_Sand"
    },
    {
      "x": -26,
      "y": 51,
      "z": 2,
      "name": "Necrotic_Sand"
    },
    {
      "x": -26,
      "y": 52,
      "z": 2,
      "name": "Necrotic_Sand"
    },
    {
      "x": -26,
      "y": 53,
      "z": 2,
      "name": "Sword_Cemetery_1",
      "rotation": 3
    },
    {
      "x": -26,
      "y": 72,
      "z": 2,
      "name": "Necrotic_Sand"
    },
    {
      "x": -26,
      "y": 73,
      "z": 2,
      "name": "Necrotic_Sand"
    },
    {
      "x": -26,
      "y": 74,
      "z": 2,
      "name": "Necrotic_Sand"
    },
    {
      "x": -26,
      "y": 75,
      "z": 2,
      "name": "Necrotic_Sand"
    },
    {
      "x": -26,
      "y": 76,
      "z": 2,
      "name": "Necrotic_Sand"
    },
    {
      "x": -26,
      "y": 77,
      "z": 2,
      "name": "Necrotic_Sand"
    },
    {
      "x": -26,
      "y": 78,
      "z": 2,
      "name": "Necrotic_Sand"
    },
    {
      "x": -26,
      "y": 79,
      "z": 2,
      "name": "Necrotic_Sand"
    },
    {
      "x": -26,
      "y": 80,
      "z": 2,
      "name": "Necrotic_Sand"
    },
    {
      "x": -26,
      "y": 81,
      "z": 2,
      "name": "Necrotic_Sand"
    },
    {
      "x": -26,
      "y": 82,
      "z": 2,
      "name": "Necrotic_Sand"
    },
    {
      "x": -26,
      "y": 83,
      "z": 2,
      "name": "Necrotic_Sand"
    },
    {
      "x": -26,
      "y": 84,
      "z": 2,
      "name": "Necrotic_Sand"
    },
    {
      "x": -26,
      "y": 85,
      "z": 2,
      "name": "Necrotic_Sand"
    },
    {
      "x": -26,
      "y": 86,
      "z": 2,
      "name": "Necrotic_Sand"
    },
    {
      "x": -26,
      "y": 87,
      "z": 2,
      "name": "Dead_Branch"
    },
    {
      "x": -26,
      "y": 18,
      "z": 3,
      "name": "Necrotic_Sand"
    },
    {
      "x": -26,
      "y": 19,
      "z": 3,
      "name": "Necrotic_Sand"
    },
    {
      "x": -26,
      "y": 20,
      "z": 3,
      "name": "Necrotic_Sand"
    },
    {
      "x": -26,
      "y": 21,
      "z": 3,
      "name": "Necrotic_Sand"
    },
    {
      "x": -26,
      "y": 22,
      "z": 3,
      "name": "Necrotic_Sand"
    },
    {
      "x": -26,
      "y": 23,
      "z": 3,
      "name": "Necrotic_Sand"
    },
    {
      "x": -26,
      "y": 24,
      "z": 3,
      "name": "Necrotic_Sand"
    },
    {
      "x": -26,
      "y": 25,
      "z": 3,
      "name": "Necrotic_Sand"
    },
    {
      "x": -26,
      "y": 26,
      "z": 3,
      "name": "Necrotic_Sand"
    },
    {
      "x": -26,
      "y": 27,
      "z": 3,
      "name": "Necrotic_Sand"
    },
    {
      "x": -26,
      "y": 28,
      "z": 3,
      "name": "Necrotic_Sand"
    },
    {
      "x": -26,
      "y": 29,
      "z": 3,
      "name": "Necrotic_Sand"
    },
    {
      "x": -26,
      "y": 30,
      "z": 3,
      "name": "Necrotic_Sand"
    },
    {
      "x": -26,
      "y": 31,
      "z": 3,
      "name": "Necrotic_Sand"
    },
    {
      "x": -26,
      "y": 32,
      "z": 3,
      "name": "Necrotic_Sand"
    },
    {
      "x": -26,
      "y": 33,
      "z": 3,
      "name": "Necrotic_Sand"
    },
    {
      "x": -26,
      "y": 34,
      "z": 3,
      "name": "Necrotic_Sand"
    },
    {
      "x": -26,
      "y": 35,
      "z": 3,
      "name": "Necrotic_Sand"
    },
    {
      "x": -26,
      "y": 36,
      "z": 3,
      "name": "Necrotic_Sand"
    },
    {
      "x": -26,
      "y": 37,
      "z": 3,
      "name": "Necrotic_Sand"
    },
    {
      "x": -26,
      "y": 38,
      "z": 3,
      "name": "Necrotic_Sand"
    },
    {
      "x": -26,
      "y": 39,
      "z": 3,
      "name": "Necrotic_Sand"
    },
    {
      "x": -26,
      "y": 40,
      "z": 3,
      "name": "Necrotic_Sand"
    },
    {
      "x": -26,
      "y": 41,
      "z": 3,
      "name": "Necrotic_Sand"
    },
    {
      "x": -26,
      "y": 42,
      "z": 3,
      "name": "Necrotic_Sand"
    },
    {
      "x": -26,
      "y": 43,
      "z": 3,
      "name": "Necrotic_Sand"
    },
    {
      "x": -26,
      "y": 44,
      "z": 3,
      "name": "Necrotic_Sand"
    },
    {
      "x": -26,
      "y": 45,
      "z": 3,
      "name": "Necrotic_Sand"
    },
    {
      "x": -26,
      "y": 46,
      "z": 3,
      "name": "Necrotic_Sand"
    },
    {
      "x": -26,
      "y": 47,
      "z": 3,
      "name": "Necrotic_Sand"
    },
    {
      "x": -26,
      "y": 48,
      "z": 3,
      "name": "Necrotic_Sand"
    },
    {
      "x": -26,
      "y": 49,
      "z": 3,
      "name": "Necrotic_Sand"
    },
    {
      "x": -26,
      "y": 50,
      "z": 3,
      "name": "Necrotic_Sand"
    },
    {
      "x": -26,
      "y": 76,
      "z": 3,
      "name": "Necrotic_Sand"
    },
    {
      "x": -26,
      "y": 77,
      "z": 3,
      "name": "Necrotic_Sand"
    },
    {
      "x": -26,
      "y": 78,
      "z": 3,
      "name": "Necrotic_Sand"
    },
    {
      "x": -26,
      "y": 79,
      "z": 3,
      "name": "Necrotic_Sand"
    },
    {
      "x": -26,
      "y": 80,
      "z": 3,
      "name": "Necrotic_Sand"
    },
    {
      "x": -26,
      "y": 81,
      "z": 3,
      "name": "Necrotic_Sand"
    },
    {
      "x": -26,
      "y": 82,
      "z": 3,
      "name": "Necrotic_Sand"
    },
    {
      "x": -26,
      "y": 83,
      "z": 3,
      "name": "Sword_Cemetery_1"
    },
    {
      "x": -26,
      "y": 85,
      "z": 3,
      "name": "Necrotic_Sand"
    },
    {
      "x": -26,
      "y": 86,
      "z": 3,
      "name": "Necrotic_Sand"
    },
    {
      "x": -26,
      "y": 87,
      "z": 3,
      "name": "Necrotic_Sand"
    },
    {
      "x": -26,
      "y": 88,
      "z": 3,
      "name": "Dead_Branch"
    },
    {
      "x": -26,
      "y": 20,
      "z": 4,
      "name": "Necrotic_Sand"
    },
    {
      "x": -26,
      "y": 21,
      "z": 4,
      "name": "Necrotic_Sand"
    },
    {
      "x": -26,
      "y": 22,
      "z": 4,
      "name": "Necrotic_Sand"
    },
    {
      "x": -26,
      "y": 23,
      "z": 4,
      "name": "Necrotic_Sand"
    },
    {
      "x": -26,
      "y": 24,
      "z": 4,
      "name": "Necrotic_Sand"
    },
    {
      "x": -26,
      "y": 25,
      "z": 4,
      "name": "Necrotic_Sand"
    },
    {
      "x": -26,
      "y": 26,
      "z": 4,
      "name": "Necrotic_Sand"
    },
    {
      "x": -26,
      "y": 27,
      "z": 4,
      "name": "Necrotic_Sand"
    },
    {
      "x": -26,
      "y": 28,
      "z": 4,
      "name": "Necrotic_Sand"
    },
    {
      "x": -26,
      "y": 29,
      "z": 4,
      "name": "Necrotic_Sand"
    },
    {
      "x": -26,
      "y": 30,
      "z": 4,
      "name": "Necrotic_Sand"
    },
    {
      "x": -26,
      "y": 31,
      "z": 4,
      "name": "Necrotic_Sand"
    },
    {
      "x": -26,
      "y": 32,
      "z": 4,
      "name": "Necrotic_Sand"
    },
    {
      "x": -26,
      "y": 33,
      "z": 4,
      "name": "Necrotic_Sand"
    },
    {
      "x": -26,
      "y": 34,
      "z": 4,
      "name": "Necrotic_Sand"
    },
    {
      "x": -26,
      "y": 35,
      "z": 4,
      "name": "Necrotic_Sand"
    },
    {
      "x": -26,
      "y": 36,
      "z": 4,
      "name": "Necrotic_Sand"
    },
    {
      "x": -26,
      "y": 37,
      "z": 4,
      "name": "Necrotic_Sand"
    },
    {
      "x": -26,
      "y": 38,
      "z": 4,
      "name": "Necrotic_Sand"
    },
    {
      "x": -26,
      "y": 39,
      "z": 4,
      "name": "Necrotic_Sand"
    },
    {
      "x": -26,
      "y": 40,
      "z": 4,
      "name": "Necrotic_Sand"
    },
    {
      "x": -26,
      "y": 41,
      "z": 4,
      "name": "Necrotic_Sand"
    },
    {
      "x": -26,
      "y": 42,
      "z": 4,
      "name": "Necrotic_Sand"
    },
    {
      "x": -26,
      "y": 43,
      "z": 4,
      "name": "Necrotic_Sand"
    },
    {
      "x": -26,
      "y": 44,
      "z": 4,
      "name": "Necrotic_Sand"
    },
    {
      "x": -26,
      "y": 45,
      "z": 4,
      "name": "Sword_Cemetery_1",
      "rotation": 3
    },
    {
      "x": -26,
      "y": 47,
      "z": 4,
      "name": "Necrotic_Sand"
    },
    {
      "x": -26,
      "y": 48,
      "z": 4,
      "name": "Sword_Cemetery_1",
      "rotation": 3
    },
    {
      "x": -26,
      "y": 76,
      "z": 4,
      "name": "Wood_Burnt_Roots"
    },
    {
      "x": -26,
      "y": 77,
      "z": 4,
      "name": "Necrotic_Sand"
    },
    {
      "x": -26,
      "y": 78,
      "z": 4,
      "name": "Necrotic_Sand"
    },
    {
      "x": -26,
      "y": 79,
      "z": 4,
      "name": "Necrotic_Sand"
    },
    {
      "x": -26,
      "y": 80,
      "z": 4,
      "name": "Necrotic_Sand"
    },
    {
      "x": -26,
      "y": 81,
      "z": 4,
      "name": "Necrotic_Sand"
    },
    {
      "x": -26,
      "y": 82,
      "z": 4,
      "name": "Necrotic_Mushroom_Flatcap",
      "components": {
        "Components": {
          "FarmingBlock": {
            "LastTickGameTime": "0001-01-01T12:00:00Z"
          },
          "PlacedByInteraction": {
            "WhoPlacedUuid": {
              "$binary": "bJ0Z/pHxT/WyhVA6z1mjfg==",
              "$type": "04"
            }
          }
        }
      }
    },
    {
      "x": -25,
      "y": 22,
      "z": -5,
      "name": "Necrotic_Sand"
    },
    {
      "x": -25,
      "y": 23,
      "z": -5,
      "name": "Necrotic_Sand"
    },
    {
      "x": -25,
      "y": 24,
      "z": -5,
      "name": "Necrotic_Sand"
    },
    {
      "x": -25,
      "y": 25,
      "z": -5,
      "name": "Necrotic_Sand"
    },
    {
      "x": -25,
      "y": 26,
      "z": -5,
      "name": "Necrotic_Sand"
    },
    {
      "x": -25,
      "y": 27,
      "z": -5,
      "name": "Necrotic_Sand"
    },
    {
      "x": -25,
      "y": 28,
      "z": -5,
      "name": "Necrotic_Sand"
    },
    {
      "x": -25,
      "y": 19,
      "z": -4,
      "name": "Wood_Burnt_Roots"
    },
    {
      "x": -25,
      "y": 20,
      "z": -4,
      "name": "Necrotic_Sand"
    },
    {
      "x": -25,
      "y": 21,
      "z": -4,
      "name": "Necrotic_Sand"
    },
    {
      "x": -25,
      "y": 22,
      "z": -4,
      "name": "Necrotic_Sand"
    },
    {
      "x": -25,
      "y": 23,
      "z": -4,
      "name": "Necrotic_Sand"
    },
    {
      "x": -25,
      "y": 24,
      "z": -4,
      "name": "Necrotic_Sand"
    },
    {
      "x": -25,
      "y": 25,
      "z": -4,
      "name": "Necrotic_Sand"
    },
    {
      "x": -25,
      "y": 26,
      "z": -4,
      "name": "Necrotic_Sand"
    },
    {
      "x": -25,
      "y": 27,
      "z": -4,
      "name": "Necrotic_Sand"
    },
    {
      "x": -25,
      "y": 28,
      "z": -4,
      "name": "Necrotic_Sand"
    },
    {
      "x": -25,
      "y": 29,
      "z": -4,
      "name": "Necrotic_Sand"
    },
    {
      "x": -25,
      "y": 30,
      "z": -4,
      "name": "Necrotic_Sand"
    },
    {
      "x": -25,
      "y": 18,
      "z": -3,
      "name": "Necrotic_Sand"
    },
    {
      "x": -25,
      "y": 19,
      "z": -3,
      "name": "Necrotic_Sand"
    },
    {
      "x": -25,
      "y": 20,
      "z": -3,
      "name": "Necrotic_Sand"
    },
    {
      "x": -25,
      "y": 21,
      "z": -3,
      "name": "Necrotic_Sand"
    },
    {
      "x": -25,
      "y": 22,
      "z": -3,
      "name": "Necrotic_Sand"
    },
    {
      "x": -25,
      "y": 23,
      "z": -3,
      "name": "Necrotic_Sand"
    },
    {
      "x": -25,
      "y": 24,
      "z": -3,
      "name": "Necrotic_Sand"
    },
    {
      "x": -25,
      "y": 25,
      "z": -3,
      "name": "Necrotic_Sand"
    },
    {
      "x": -25,
      "y": 26,
      "z": -3,
      "name": "Necrotic_Sand"
    },
    {
      "x": -25,
      "y": 27,
      "z": -3,
      "name": "Necrotic_Sand"
    },
    {
      "x": -25,
      "y": 28,
      "z": -3,
      "name": "Necrotic_Sand"
    },
    {
      "x": -25,
      "y": 29,
      "z": -3,
      "name": "Necrotic_Sand"
    },
    {
      "x": -25,
      "y": 30,
      "z": -3,
      "name": "Necrotic_Sand"
    },
    {
      "x": -25,
      "y": 31,
      "z": -3,
      "name": "Necrotic_Sand"
    },
    {
      "x": -25,
      "y": 32,
      "z": -3,
      "name": "Necrotic_Sand"
    },
    {
      "x": -25,
      "y": 33,
      "z": -3,
      "name": "Necrotic_Sand"
    },
    {
      "x": -25,
      "y": 34,
      "z": -3,
      "name": "Necrotic_Sand"
    },
    {
      "x": -25,
      "y": 35,
      "z": -3,
      "name": "Necrotic_Sand"
    },
    {
      "x": -25,
      "y": 36,
      "z": -3,
      "name": "Necrotic_Sand"
    },
    {
      "x": -25,
      "y": 37,
      "z": -3,
      "name": "Necrotic_Sand"
    },
    {
      "x": -25,
      "y": 38,
      "z": -3,
      "name": "Necrotic_Sand"
    },
    {
      "x": -25,
      "y": 39,
      "z": -3,
      "name": "Necrotic_Sand"
    },
    {
      "x": -25,
      "y": 40,
      "z": -3,
      "name": "Necrotic_Sand"
    },
    {
      "x": -25,
      "y": 41,
      "z": -3,
      "name": "Necrotic_Sand"
    },
    {
      "x": -25,
      "y": 42,
      "z": -3,
      "name": "Necrotic_Sand"
    },
    {
      "x": -25,
      "y": 43,
      "z": -3,
      "name": "Necrotic_Sand"
    },
    {
      "x": -25,
      "y": 44,
      "z": -3,
      "name": "Necrotic_Sand"
    },
    {
      "x": -25,
      "y": 45,
      "z": -3,
      "name": "Necrotic_Sand"
    },
    {
      "x": -25,
      "y": 46,
      "z": -3,
      "name": "Necrotic_Sand"
    },
    {
      "x": -25,
      "y": 17,
      "z": -2,
      "name": "Necrotic_Sand"
    },
    {
      "x": -25,
      "y": 18,
      "z": -2,
      "name": "Necrotic_Sand"
    },
    {
      "x": -25,
      "y": 19,
      "z": -2,
      "name": "Necrotic_Sand"
    },
    {
      "x": -25,
      "y": 20,
      "z": -2,
      "name": "Necrotic_Sand"
    },
    {
      "x": -25,
      "y": 21,
      "z": -2,
      "name": "Necrotic_Sand"
    },
    {
      "x": -25,
      "y": 22,
      "z": -2,
      "name": "Necrotic_Sand"
    },
    {
      "x": -25,
      "y": 23,
      "z": -2,
      "name": "Necrotic_Sand"
    },
    {
      "x": -25,
      "y": 24,
      "z": -2,
      "name": "Necrotic_Sand"
    },
    {
      "x": -25,
      "y": 25,
      "z": -2,
      "name": "Necrotic_Sand"
    },
    {
      "x": -25,
      "y": 26,
      "z": -2,
      "name": "Necrotic_Sand"
    },
    {
      "x": -25,
      "y": 27,
      "z": -2,
      "name": "Necrotic_Sand"
    },
    {
      "x": -25,
      "y": 28,
      "z": -2,
      "name": "Necrotic_Sand"
    },
    {
      "x": -25,
      "y": 29,
      "z": -2,
      "name": "Necrotic_Sand"
    },
    {
      "x": -25,
      "y": 30,
      "z": -2,
      "name": "Necrotic_Sand"
    },
    {
      "x": -25,
      "y": 31,
      "z": -2,
      "name": "Necrotic_Sand"
    },
    {
      "x": -25,
      "y": 32,
      "z": -2,
      "name": "Necrotic_Sand"
    },
    {
      "x": -25,
      "y": 33,
      "z": -2,
      "name": "Necrotic_Sand"
    },
    {
      "x": -25,
      "y": 34,
      "z": -2,
      "name": "Necrotic_Sand"
    },
    {
      "x": -25,
      "y": 35,
      "z": -2,
      "name": "Necrotic_Sand"
    },
    {
      "x": -25,
      "y": 36,
      "z": -2,
      "name": "Necrotic_Sand"
    },
    {
      "x": -25,
      "y": 37,
      "z": -2,
      "name": "Necrotic_Sand"
    },
    {
      "x": -25,
      "y": 38,
      "z": -2,
      "name": "Necrotic_Sand"
    },
    {
      "x": -25,
      "y": 39,
      "z": -2,
      "name": "Necrotic_Sand"
    },
    {
      "x": -25,
      "y": 40,
      "z": -2,
      "name": "Necrotic_Sand"
    },
    {
      "x": -25,
      "y": 41,
      "z": -2,
      "name": "Necrotic_Sand"
    },
    {
      "x": -25,
      "y": 42,
      "z": -2,
      "name": "Necrotic_Sand"
    },
    {
      "x": -25,
      "y": 43,
      "z": -2,
      "name": "Necrotic_Sand"
    },
    {
      "x": -25,
      "y": 44,
      "z": -2,
      "name": "Necrotic_Sand"
    },
    {
      "x": -25,
      "y": 45,
      "z": -2,
      "name": "Necrotic_Sand"
    },
    {
      "x": -25,
      "y": 46,
      "z": -2,
      "name": "Necrotic_Sand"
    },
    {
      "x": -25,
      "y": 47,
      "z": -2,
      "name": "Necrotic_Sand"
    },
    {
      "x": -25,
      "y": 48,
      "z": -2,
      "name": "Necrotic_Sand"
    },
    {
      "x": -25,
      "y": 49,
      "z": -2,
      "name": "Necrotic_Sand"
    },
    {
      "x": -25,
      "y": 50,
      "z": -2,
      "name": "Necrotic_Sand"
    },
    {
      "x": -25,
      "y": 51,
      "z": -2,
      "name": "Necrotic_Sand"
    },
    {
      "x": -25,
      "y": 52,
      "z": -2,
      "name": "Necrotic_Sand"
    },
    {
      "x": -25,
      "y": 53,
      "z": -2,
      "name": "Sword_Cemetery_1",
      "rotation": 2
    },
    {
      "x": -25,
      "y": 15,
      "z": -1,
      "name": "Wood_Burnt_Roots"
    },
    {
      "x": -25,
      "y": 16,
      "z": -1,
      "name": "Necrotic_Sand"
    },
    {
      "x": -25,
      "y": 17,
      "z": -1,
      "name": "Necrotic_Sand"
    },
    {
      "x": -25,
      "y": 18,
      "z": -1,
      "name": "Necrotic_Sand"
    },
    {
      "x": -25,
      "y": 19,
      "z": -1,
      "name": "Necrotic_Sand"
    },
    {
      "x": -25,
      "y": 20,
      "z": -1,
      "name": "Necrotic_Sand"
    },
    {
      "x": -25,
      "y": 21,
      "z": -1,
      "name": "Necrotic_Sand"
    },
    {
      "x": -25,
      "y": 22,
      "z": -1,
      "name": "Necrotic_Sand"
    },
    {
      "x": -25,
      "y": 23,
      "z": -1,
      "name": "Necrotic_Sand"
    },
    {
      "x": -25,
      "y": 24,
      "z": -1,
      "name": "Necrotic_Sand"
    },
    {
      "x": -25,
      "y": 25,
      "z": -1,
      "name": "Necrotic_Sand"
    },
    {
      "x": -25,
      "y": 26,
      "z": -1,
      "name": "Necrotic_Sand"
    },
    {
      "x": -25,
      "y": 27,
      "z": -1,
      "name": "Necrotic_Sand"
    },
    {
      "x": -25,
      "y": 28,
      "z": -1,
      "name": "Necrotic_Sand"
    },
    {
      "x": -25,
      "y": 29,
      "z": -1,
      "name": "Necrotic_Sand"
    },
    {
      "x": -25,
      "y": 30,
      "z": -1,
      "name": "Necrotic_Sand"
    },
    {
      "x": -25,
      "y": 31,
      "z": -1,
      "name": "Necrotic_Sand"
    },
    {
      "x": -25,
      "y": 32,
      "z": -1,
      "name": "Necrotic_Sand"
    },
    {
      "x": -25,
      "y": 33,
      "z": -1,
      "name": "Necrotic_Sand"
    },
    {
      "x": -25,
      "y": 34,
      "z": -1,
      "name": "Necrotic_Sand"
    },
    {
      "x": -25,
      "y": 35,
      "z": -1,
      "name": "Necrotic_Sand"
    },
    {
      "x": -25,
      "y": 36,
      "z": -1,
      "name": "Necrotic_Sand"
    },
    {
      "x": -25,
      "y": 37,
      "z": -1,
      "name": "Necrotic_Sand"
    },
    {
      "x": -25,
      "y": 38,
      "z": -1,
      "name": "Necrotic_Sand"
    },
    {
      "x": -25,
      "y": 39,
      "z": -1,
      "name": "Necrotic_Sand"
    },
    {
      "x": -25,
      "y": 40,
      "z": -1,
      "name": "Necrotic_Sand"
    },
    {
      "x": -25,
      "y": 41,
      "z": -1,
      "name": "Necrotic_Sand"
    },
    {
      "x": -25,
      "y": 42,
      "z": -1,
      "name": "Necrotic_Sand"
    },
    {
      "x": -25,
      "y": 43,
      "z": -1,
      "name": "Necrotic_Sand"
    },
    {
      "x": -25,
      "y": 44,
      "z": -1,
      "name": "Necrotic_Sand"
    },
    {
      "x": -25,
      "y": 45,
      "z": -1,
      "name": "Necrotic_Sand"
    },
    {
      "x": -25,
      "y": 46,
      "z": -1,
      "name": "Necrotic_Sand"
    },
    {
      "x": -25,
      "y": 47,
      "z": -1,
      "name": "Necrotic_Sand"
    },
    {
      "x": -25,
      "y": 48,
      "z": -1,
      "name": "Necrotic_Sand"
    },
    {
      "x": -25,
      "y": 49,
      "z": -1,
      "name": "Necrotic_Sand"
    },
    {
      "x": -25,
      "y": 50,
      "z": -1,
      "name": "Necrotic_Sand"
    },
    {
      "x": -25,
      "y": 51,
      "z": -1,
      "name": "Necrotic_Sand"
    },
    {
      "x": -25,
      "y": 52,
      "z": -1,
      "name": "Necrotic_Sand"
    },
    {
      "x": -25,
      "y": 53,
      "z": -1,
      "name": "Necrotic_Sand"
    },
    {
      "x": -25,
      "y": 16,
      "z": 0,
      "name": "Necrotic_Sand"
    },
    {
      "x": -25,
      "y": 17,
      "z": 0,
      "name": "Necrotic_Sand"
    },
    {
      "x": -25,
      "y": 18,
      "z": 0,
      "name": "Necrotic_Sand"
    },
    {
      "x": -25,
      "y": 19,
      "z": 0,
      "name": "Necrotic_Sand"
    },
    {
      "x": -25,
      "y": 20,
      "z": 0,
      "name": "Necrotic_Sand"
    },
    {
      "x": -25,
      "y": 21,
      "z": 0,
      "name": "Necrotic_Sand"
    },
    {
      "x": -25,
      "y": 22,
      "z": 0,
      "name": "Necrotic_Sand"
    },
    {
      "x": -25,
      "y": 23,
      "z": 0,
      "name": "Necrotic_Sand"
    },
    {
      "x": -25,
      "y": 24,
      "z": 0,
      "name": "Necrotic_Sand"
    },
    {
      "x": -25,
      "y": 25,
      "z": 0,
      "name": "Necrotic_Sand"
    },
    {
      "x": -25,
      "y": 26,
      "z": 0,
      "name": "Necrotic_Sand"
    },
    {
      "x": -25,
      "y": 27,
      "z": 0,
      "name": "Necrotic_Sand"
    },
    {
      "x": -25,
      "y": 28,
      "z": 0,
      "name": "Necrotic_Sand"
    },
    {
      "x": -25,
      "y": 29,
      "z": 0,
      "name": "Necrotic_Sand"
    },
    {
      "x": -25,
      "y": 30,
      "z": 0,
      "name": "Necrotic_Sand"
    },
    {
      "x": -25,
      "y": 31,
      "z": 0,
      "name": "Necrotic_Sand"
    },
    {
      "x": -25,
      "y": 32,
      "z": 0,
      "name": "Necrotic_Sand"
    },
    {
      "x": -25,
      "y": 33,
      "z": 0,
      "name": "Necrotic_Sand"
    },
    {
      "x": -25,
      "y": 34,
      "z": 0,
      "name": "Necrotic_Sand"
    },
    {
      "x": -25,
      "y": 35,
      "z": 0,
      "name": "Necrotic_Sand"
    },
    {
      "x": -25,
      "y": 36,
      "z": 0,
      "name": "Necrotic_Sand"
    },
    {
      "x": -25,
      "y": 37,
      "z": 0,
      "name": "Necrotic_Sand"
    },
    {
      "x": -25,
      "y": 38,
      "z": 0,
      "name": "Necrotic_Sand"
    },
    {
      "x": -25,
      "y": 39,
      "z": 0,
      "name": "Necrotic_Sand"
    },
    {
      "x": -25,
      "y": 40,
      "z": 0,
      "name": "Necrotic_Sand"
    },
    {
      "x": -25,
      "y": 41,
      "z": 0,
      "name": "Necrotic_Sand"
    },
    {
      "x": -25,
      "y": 42,
      "z": 0,
      "name": "Necrotic_Sand"
    },
    {
      "x": -25,
      "y": 43,
      "z": 0,
      "name": "Necrotic_Sand"
    },
    {
      "x": -25,
      "y": 44,
      "z": 0,
      "name": "Necrotic_Sand"
    },
    {
      "x": -25,
      "y": 45,
      "z": 0,
      "name": "Necrotic_Sand"
    },
    {
      "x": -25,
      "y": 46,
      "z": 0,
      "name": "Necrotic_Sand"
    },
    {
      "x": -25,
      "y": 47,
      "z": 0,
      "name": "Necrotic_Sand"
    },
    {
      "x": -25,
      "y": 48,
      "z": 0,
      "name": "Necrotic_Sand"
    },
    {
      "x": -25,
      "y": 49,
      "z": 0,
      "name": "Necrotic_Sand"
    },
    {
      "x": -25,
      "y": 50,
      "z": 0,
      "name": "Necrotic_Sand"
    },
    {
      "x": -25,
      "y": 51,
      "z": 0,
      "name": "Necrotic_Sand"
    },
    {
      "x": -25,
      "y": 52,
      "z": 0,
      "name": "Necrotic_Sand"
    },
    {
      "x": -25,
      "y": 53,
      "z": 0,
      "name": "Necrotic_Sand"
    },
    {
      "x": -25,
      "y": 54,
      "z": 0,
      "name": "Necrotic_Sand"
    },
    {
      "x": -25,
      "y": 70,
      "z": 0,
      "name": "Wood_Burnt_Roots"
    },
    {
      "x": -25,
      "y": 71,
      "z": 0,
      "name": "Necrotic_Sand"
    },
    {
      "x": -25,
      "y": 72,
      "z": 0,
      "name": "Necrotic_Sand"
    },
    {
      "x": -25,
      "y": 73,
      "z": 0,
      "name": "Necrotic_Sand"
    },
    {
      "x": -25,
      "y": 74,
      "z": 0,
      "name": "Sword_Cemetery_2",
      "rotation": 2
    },
    {
      "x": -25,
      "y": 15,
      "z": 1,
      "name": "Wood_Burnt_Roots"
    },
    {
      "x": -25,
      "y": 16,
      "z": 1,
      "name": "Necrotic_Sand"
    },
    {
      "x": -25,
      "y": 17,
      "z": 1,
      "name": "Necrotic_Sand"
    },
    {
      "x": -25,
      "y": 18,
      "z": 1,
      "name": "Necrotic_Sand"
    },
    {
      "x": -25,
      "y": 19,
      "z": 1,
      "name": "Necrotic_Sand"
    },
    {
      "x": -25,
      "y": 20,
      "z": 1,
      "name": "Necrotic_Sand"
    },
    {
      "x": -25,
      "y": 21,
      "z": 1,
      "name": "Necrotic_Sand"
    },
    {
      "x": -25,
      "y": 22,
      "z": 1,
      "name": "Necrotic_Sand"
    },
    {
      "x": -25,
      "y": 23,
      "z": 1,
      "name": "Necrotic_Sand"
    },
    {
      "x": -25,
      "y": 24,
      "z": 1,
      "name": "Necrotic_Sand"
    },
    {
      "x": -25,
      "y": 25,
      "z": 1,
      "name": "Necrotic_Sand"
    },
    {
      "x": -25,
      "y": 26,
      "z": 1,
      "name": "Necrotic_Sand"
    },
    {
      "x": -25,
      "y": 27,
      "z": 1,
      "name": "Necrotic_Sand"
    },
    {
      "x": -25,
      "y": 28,
      "z": 1,
      "name": "Necrotic_Sand"
    },
    {
      "x": -25,
      "y": 29,
      "z": 1,
      "name": "Necrotic_Sand"
    },
    {
      "x": -25,
      "y": 30,
      "z": 1,
      "name": "Necrotic_Sand"
    },
    {
      "x": -25,
      "y": 31,
      "z": 1,
      "name": "Necrotic_Sand"
    },
    {
      "x": -25,
      "y": 32,
      "z": 1,
      "name": "Necrotic_Sand"
    },
    {
      "x": -25,
      "y": 33,
      "z": 1,
      "name": "Necrotic_Sand"
    },
    {
      "x": -25,
      "y": 34,
      "z": 1,
      "name": "Necrotic_Sand"
    },
    {
      "x": -25,
      "y": 35,
      "z": 1,
      "name": "Necrotic_Sand"
    },
    {
      "x": -25,
      "y": 36,
      "z": 1,
      "name": "Necrotic_Sand"
    },
    {
      "x": -25,
      "y": 37,
      "z": 1,
      "name": "Necrotic_Sand"
    },
    {
      "x": -25,
      "y": 38,
      "z": 1,
      "name": "Necrotic_Sand"
    },
    {
      "x": -25,
      "y": 39,
      "z": 1,
      "name": "Necrotic_Sand"
    },
    {
      "x": -25,
      "y": 40,
      "z": 1,
      "name": "Necrotic_Sand"
    },
    {
      "x": -25,
      "y": 41,
      "z": 1,
      "name": "Necrotic_Sand"
    },
    {
      "x": -25,
      "y": 42,
      "z": 1,
      "name": "Necrotic_Sand"
    },
    {
      "x": -25,
      "y": 43,
      "z": 1,
      "name": "Necrotic_Sand"
    },
    {
      "x": -25,
      "y": 44,
      "z": 1,
      "name": "Necrotic_Sand"
    },
    {
      "x": -25,
      "y": 45,
      "z": 1,
      "name": "Necrotic_Sand"
    },
    {
      "x": -25,
      "y": 46,
      "z": 1,
      "name": "Necrotic_Sand"
    },
    {
      "x": -25,
      "y": 47,
      "z": 1,
      "name": "Necrotic_Sand"
    },
    {
      "x": -25,
      "y": 48,
      "z": 1,
      "name": "Necrotic_Sand"
    },
    {
      "x": -25,
      "y": 49,
      "z": 1,
      "name": "Necrotic_Sand"
    },
    {
      "x": -25,
      "y": 50,
      "z": 1,
      "name": "Necrotic_Sand"
    },
    {
      "x": -25,
      "y": 51,
      "z": 1,
      "name": "Necrotic_Sand"
    },
    {
      "x": -25,
      "y": 52,
      "z": 1,
      "name": "Necrotic_Sand"
    },
    {
      "x": -25,
      "y": 53,
      "z": 1,
      "name": "Necrotic_Sand"
    },
    {
      "x": -25,
      "y": 54,
      "z": 1,
      "name": "Necrotic_Sand"
    },
    {
      "x": -25,
      "y": 55,
      "z": 1,
      "name": "Necrotic_Sand"
    },
    {
      "x": -25,
      "y": 62,
      "z": 1,
      "name": "Necrotic_Sand"
    },
    {
      "x": -25,
      "y": 70,
      "z": 1,
      "name": "Necrotic_Sand"
    },
    {
      "x": -25,
      "y": 71,
      "z": 1,
      "name": "Necrotic_Sand"
    },
    {
      "x": -25,
      "y": 72,
      "z": 1,
      "name": "Necrotic_Sand"
    },
    {
      "x": -25,
      "y": 73,
      "z": 1,
      "name": "Necrotic_Sand"
    },
    {
      "x": -25,
      "y": 74,
      "z": 1,
      "name": "Necrotic_Sand"
    },
    {
      "x": -25,
      "y": 75,
      "z": 1,
      "name": "Necrotic_Sand"
    },
    {
      "x": -25,
      "y": 76,
      "z": 1,
      "name": "Necrotic_Sand"
    },
    {
      "x": -25,
      "y": 77,
      "z": 1,
      "name": "Necrotic_Sand"
    },
    {
      "x": -25,
      "y": 78,
      "z": 1,
      "name": "Necrotic_Sand"
    },
    {
      "x": -25,
      "y": 79,
      "z": 1,
      "name": "Necrotic_Sand"
    },
    {
      "x": -25,
      "y": 80,
      "z": 1,
      "name": "Necrotic_Sand"
    },
    {
      "x": -25,
      "y": 81,
      "z": 1,
      "name": "Necrotic_Sand"
    },
    {
      "x": -25,
      "y": 82,
      "z": 1,
      "name": "Necrotic_Sand"
    },
    {
      "x": -25,
      "y": 83,
      "z": 1,
      "name": "Necrotic_Sand"
    },
    {
      "x": -25,
      "y": 84,
      "z": 1,
      "name": "Necrotic_Sand"
    },
    {
      "x": -25,
      "y": 85,
      "z": 1,
      "name": "Necrotic_Sand"
    },
    {
      "x": -25,
      "y": 86,
      "z": 1,
      "name": "Necrotic_Sand"
    },
    {
      "x": -25,
      "y": 87,
      "z": 1,
      "name": "Necrotic_Sand"
    },
    {
      "x": -25,
      "y": 88,
      "z": 1,
      "name": "Sword_Cemetery_1",
      "rotation": 3
    },
    {
      "x": -25,
      "y": 16,
      "z": 2,
      "name": "Necrotic_Sand"
    },
    {
      "x": -25,
      "y": 17,
      "z": 2,
      "name": "Necrotic_Sand"
    },
    {
      "x": -25,
      "y": 18,
      "z": 2,
      "name": "Necrotic_Sand"
    },
    {
      "x": -25,
      "y": 19,
      "z": 2,
      "name": "Necrotic_Sand"
    },
    {
      "x": -25,
      "y": 20,
      "z": 2,
      "name": "Necrotic_Sand"
    },
    {
      "x": -25,
      "y": 21,
      "z": 2,
      "name": "Necrotic_Sand"
    },
    {
      "x": -25,
      "y": 22,
      "z": 2,
      "name": "Necrotic_Sand"
    },
    {
      "x": -25,
      "y": 23,
      "z": 2,
      "name": "Necrotic_Sand"
    },
    {
      "x": -25,
      "y": 24,
      "z": 2,
      "name": "Necrotic_Sand"
    },
    {
      "x": -25,
      "y": 25,
      "z": 2,
      "name": "Necrotic_Sand"
    },
    {
      "x": -25,
      "y": 26,
      "z": 2,
      "name": "Necrotic_Sand"
    },
    {
      "x": -25,
      "y": 27,
      "z": 2,
      "name": "Necrotic_Sand"
    },
    {
      "x": -25,
      "y": 28,
      "z": 2,
      "name": "Necrotic_Sand"
    },
    {
      "x": -25,
      "y": 29,
      "z": 2,
      "name": "Necrotic_Sand"
    },
    {
      "x": -25,
      "y": 30,
      "z": 2,
      "name": "Necrotic_Sand"
    },
    {
      "x": -25,
      "y": 31,
      "z": 2,
      "name": "Necrotic_Sand"
    },
    {
      "x": -25,
      "y": 32,
      "z": 2,
      "name": "Necrotic_Sand"
    },
    {
      "x": -25,
      "y": 33,
      "z": 2,
      "name": "Necrotic_Sand"
    },
    {
      "x": -25,
      "y": 34,
      "z": 2,
      "name": "Necrotic_Sand"
    },
    {
      "x": -25,
      "y": 35,
      "z": 2,
      "name": "Necrotic_Sand"
    },
    {
      "x": -25,
      "y": 36,
      "z": 2,
      "name": "Necrotic_Sand"
    },
    {
      "x": -25,
      "y": 37,
      "z": 2,
      "name": "Necrotic_Sand"
    },
    {
      "x": -25,
      "y": 38,
      "z": 2,
      "name": "Necrotic_Sand"
    },
    {
      "x": -25,
      "y": 39,
      "z": 2,
      "name": "Necrotic_Sand"
    },
    {
      "x": -25,
      "y": 40,
      "z": 2,
      "name": "Necrotic_Sand"
    },
    {
      "x": -25,
      "y": 41,
      "z": 2,
      "name": "Necrotic_Sand"
    },
    {
      "x": -25,
      "y": 42,
      "z": 2,
      "name": "Necrotic_Sand"
    },
    {
      "x": -25,
      "y": 43,
      "z": 2,
      "name": "Necrotic_Sand"
    },
    {
      "x": -25,
      "y": 44,
      "z": 2,
      "name": "Necrotic_Sand"
    },
    {
      "x": -25,
      "y": 45,
      "z": 2,
      "name": "Necrotic_Sand"
    },
    {
      "x": -25,
      "y": 46,
      "z": 2,
      "name": "Necrotic_Sand"
    },
    {
      "x": -25,
      "y": 47,
      "z": 2,
      "name": "Necrotic_Sand"
    },
    {
      "x": -25,
      "y": 48,
      "z": 2,
      "name": "Necrotic_Sand"
    },
    {
      "x": -25,
      "y": 49,
      "z": 2,
      "name": "Necrotic_Sand"
    },
    {
      "x": -25,
      "y": 50,
      "z": 2,
      "name": "Necrotic_Sand"
    },
    {
      "x": -25,
      "y": 51,
      "z": 2,
      "name": "Necrotic_Sand"
    },
    {
      "x": -25,
      "y": 52,
      "z": 2,
      "name": "Necrotic_Sand"
    },
    {
      "x": -25,
      "y": 53,
      "z": 2,
      "name": "Necrotic_Sand"
    },
    {
      "x": -25,
      "y": 54,
      "z": 2,
      "name": "Necrotic_Sand"
    },
    {
      "x": -25,
      "y": 55,
      "z": 2,
      "name": "Necrotic_Sand"
    },
    {
      "x": -25,
      "y": 61,
      "z": 2,
      "name": "Necrotic_Sand"
    },
    {
      "x": -25,
      "y": 62,
      "z": 2,
      "name": "Necrotic_Sand"
    },
    {
      "x": -25,
      "y": 63,
      "z": 2,
      "name": "Necrotic_Sand"
    },
    {
      "x": -25,
      "y": 65,
      "z": 2,
      "name": "Wood_Burnt_Roots"
    },
    {
      "x": -25,
      "y": 66,
      "z": 2,
      "name": "Necrotic_Sand"
    },
    {
      "x": -25,
      "y": 67,
      "z": 2,
      "name": "Necrotic_Sand"
    },
    {
      "x": -25,
      "y": 68,
      "z": 2,
      "name": "Necrotic_Sand"
    },
    {
      "x": -25,
      "y": 69,
      "z": 2,
      "name": "Necrotic_Sand"
    },
    {
      "x": -25,
      "y": 70,
      "z": 2,
      "name": "Necrotic_Sand"
    },
    {
      "x": -25,
      "y": 71,
      "z": 2,
      "name": "Necrotic_Sand"
    },
    {
      "x": -25,
      "y": 72,
      "z": 2,
      "name": "Necrotic_Sand"
    },
    {
      "x": -25,
      "y": 73,
      "z": 2,
      "name": "Necrotic_Sand"
    },
    {
      "x": -25,
      "y": 74,
      "z": 2,
      "name": "Necrotic_Sand"
    },
    {
      "x": -25,
      "y": 75,
      "z": 2,
      "name": "Necrotic_Sand"
    },
    {
      "x": -25,
      "y": 76,
      "z": 2,
      "name": "Necrotic_Sand"
    },
    {
      "x": -25,
      "y": 77,
      "z": 2,
      "name": "Necrotic_Sand"
    },
    {
      "x": -25,
      "y": 78,
      "z": 2,
      "name": "Necrotic_Sand"
    },
    {
      "x": -25,
      "y": 79,
      "z": 2,
      "name": "Necrotic_Sand"
    },
    {
      "x": -25,
      "y": 80,
      "z": 2,
      "name": "Necrotic_Sand"
    },
    {
      "x": -25,
      "y": 81,
      "z": 2,
      "name": "Necrotic_Sand"
    },
    {
      "x": -25,
      "y": 82,
      "z": 2,
      "name": "Necrotic_Sand"
    },
    {
      "x": -25,
      "y": 83,
      "z": 2,
      "name": "Necrotic_Sand"
    },
    {
      "x": -25,
      "y": 84,
      "z": 2,
      "name": "Necrotic_Sand"
    },
    {
      "x": -25,
      "y": 85,
      "z": 2,
      "name": "Necrotic_Sand"
    },
    {
      "x": -25,
      "y": 86,
      "z": 2,
      "name": "Necrotic_Sand"
    },
    {
      "x": -25,
      "y": 87,
      "z": 2,
      "name": "Necrotic_Sand"
    },
    {
      "x": -25,
      "y": 88,
      "z": 2,
      "name": "Sword_Cemetery_2",
      "rotation": 2
    },
    {
      "x": -25,
      "y": 17,
      "z": 3,
      "name": "Necrotic_Sand"
    },
    {
      "x": -25,
      "y": 18,
      "z": 3,
      "name": "Necrotic_Sand"
    },
    {
      "x": -25,
      "y": 19,
      "z": 3,
      "name": "Necrotic_Sand"
    },
    {
      "x": -25,
      "y": 20,
      "z": 3,
      "name": "Necrotic_Sand"
    },
    {
      "x": -25,
      "y": 21,
      "z": 3,
      "name": "Necrotic_Sand"
    },
    {
      "x": -25,
      "y": 22,
      "z": 3,
      "name": "Necrotic_Sand"
    },
    {
      "x": -25,
      "y": 23,
      "z": 3,
      "name": "Necrotic_Sand"
    },
    {
      "x": -25,
      "y": 24,
      "z": 3,
      "name": "Necrotic_Sand"
    },
    {
      "x": -25,
      "y": 25,
      "z": 3,
      "name": "Necrotic_Sand"
    },
    {
      "x": -25,
      "y": 26,
      "z": 3,
      "name": "Necrotic_Sand"
    },
    {
      "x": -25,
      "y": 27,
      "z": 3,
      "name": "Necrotic_Sand"
    },
    {
      "x": -25,
      "y": 28,
      "z": 3,
      "name": "Necrotic_Sand"
    },
    {
      "x": -25,
      "y": 29,
      "z": 3,
      "name": "Necrotic_Sand"
    },
    {
      "x": -25,
      "y": 30,
      "z": 3,
      "name": "Necrotic_Sand"
    },
    {
      "x": -25,
      "y": 31,
      "z": 3,
      "name": "Necrotic_Sand"
    },
    {
      "x": -25,
      "y": 32,
      "z": 3,
      "name": "Necrotic_Sand"
    },
    {
      "x": -25,
      "y": 33,
      "z": 3,
      "name": "Necrotic_Sand"
    },
    {
      "x": -25,
      "y": 34,
      "z": 3,
      "name": "Necrotic_Sand"
    },
    {
      "x": -25,
      "y": 35,
      "z": 3,
      "name": "Necrotic_Sand"
    },
    {
      "x": -25,
      "y": 36,
      "z": 3,
      "name": "Necrotic_Sand"
    },
    {
      "x": -25,
      "y": 37,
      "z": 3,
      "name": "Necrotic_Sand"
    },
    {
      "x": -25,
      "y": 38,
      "z": 3,
      "name": "Necrotic_Sand"
    },
    {
      "x": -25,
      "y": 39,
      "z": 3,
      "name": "Necrotic_Sand"
    },
    {
      "x": -25,
      "y": 40,
      "z": 3,
      "name": "Necrotic_Sand"
    },
    {
      "x": -25,
      "y": 41,
      "z": 3,
      "name": "Necrotic_Sand"
    },
    {
      "x": -25,
      "y": 42,
      "z": 3,
      "name": "Necrotic_Sand"
    },
    {
      "x": -25,
      "y": 43,
      "z": 3,
      "name": "Necrotic_Sand"
    },
    {
      "x": -25,
      "y": 44,
      "z": 3,
      "name": "Necrotic_Sand"
    },
    {
      "x": -25,
      "y": 45,
      "z": 3,
      "name": "Necrotic_Sand"
    },
    {
      "x": -25,
      "y": 46,
      "z": 3,
      "name": "Necrotic_Sand"
    },
    {
      "x": -25,
      "y": 47,
      "z": 3,
      "name": "Necrotic_Sand"
    },
    {
      "x": -25,
      "y": 48,
      "z": 3,
      "name": "Necrotic_Sand"
    },
    {
      "x": -25,
      "y": 49,
      "z": 3,
      "name": "Necrotic_Sand"
    },
    {
      "x": -25,
      "y": 50,
      "z": 3,
      "name": "Necrotic_Sand"
    },
    {
      "x": -25,
      "y": 51,
      "z": 3,
      "name": "Necrotic_Sand"
    },
    {
      "x": -25,
      "y": 52,
      "z": 3,
      "name": "Necrotic_Sand"
    },
    {
      "x": -25,
      "y": 53,
      "z": 3,
      "name": "Sword_Cemetery_1"
    },
    {
      "x": -25,
      "y": 63,
      "z": 3,
      "name": "Necrotic_Sand"
    },
    {
      "x": -25,
      "y": 64,
      "z": 3,
      "name": "Necrotic_Sand"
    },
    {
      "x": -25,
      "y": 65,
      "z": 3,
      "name": "Necrotic_Sand"
    },
    {
      "x": -25,
      "y": 66,
      "z": 3,
      "name": "Necrotic_Sand"
    },
    {
      "x": -25,
      "y": 67,
      "z": 3,
      "name": "Necrotic_Sand"
    },
    {
      "x": -25,
      "y": 68,
      "z": 3,
      "name": "Necrotic_Sand"
    },
    {
      "x": -25,
      "y": 69,
      "z": 3,
      "name": "Necrotic_Sand"
    },
    {
      "x": -25,
      "y": 70,
      "z": 3,
      "name": "Necrotic_Sand"
    },
    {
      "x": -25,
      "y": 71,
      "z": 3,
      "name": "Necrotic_Sand"
    },
    {
      "x": -25,
      "y": 72,
      "z": 3,
      "name": "Necrotic_Sand"
    },
    {
      "x": -25,
      "y": 73,
      "z": 3,
      "name": "Necrotic_Sand"
    },
    {
      "x": -25,
      "y": 74,
      "z": 3,
      "name": "Necrotic_Sand"
    },
    {
      "x": -25,
      "y": 75,
      "z": 3,
      "name": "Necrotic_Sand"
    },
    {
      "x": -25,
      "y": 76,
      "z": 3,
      "name": "Necrotic_Sand"
    },
    {
      "x": -25,
      "y": 77,
      "z": 3,
      "name": "Necrotic_Sand"
    },
    {
      "x": -25,
      "y": 78,
      "z": 3,
      "name": "Necrotic_Sand"
    },
    {
      "x": -25,
      "y": 79,
      "z": 3,
      "name": "Necrotic_Sand"
    },
    {
      "x": -25,
      "y": 80,
      "z": 3,
      "name": "Necrotic_Sand"
    },
    {
      "x": -25,
      "y": 81,
      "z": 3,
      "name": "Necrotic_Sand"
    },
    {
      "x": -25,
      "y": 82,
      "z": 3,
      "name": "Necrotic_Sand"
    },
    {
      "x": -25,
      "y": 83,
      "z": 3,
      "name": "Necrotic_Sand"
    },
    {
      "x": -25,
      "y": 84,
      "z": 3,
      "name": "Necrotic_Sand"
    },
    {
      "x": -25,
      "y": 85,
      "z": 3,
      "name": "Necrotic_Sand"
    },
    {
      "x": -25,
      "y": 86,
      "z": 3,
      "name": "Necrotic_Sand"
    },
    {
      "x": -25,
      "y": 87,
      "z": 3,
      "name": "Necrotic_Sand"
    },
    {
      "x": -25,
      "y": 88,
      "z": 3,
      "name": "Necrotic_Sand"
    },
    {
      "x": -25,
      "y": 89,
      "z": 3,
      "name": "Necrotic_Mushroom_Flatcap",
      "components": {
        "Components": {
          "FarmingBlock": {
            "LastTickGameTime": "0001-01-01T12:00:00Z"
          },
          "PlacedByInteraction": {
            "WhoPlacedUuid": {
              "$binary": "bJ0Z/pHxT/WyhVA6z1mjfg==",
              "$type": "04"
            }
          }
        }
      }
    },
    {
      "x": -25,
      "y": 18,
      "z": 4,
      "name": "Necrotic_Sand"
    },
    {
      "x": -25,
      "y": 19,
      "z": 4,
      "name": "Necrotic_Sand"
    },
    {
      "x": -25,
      "y": 20,
      "z": 4,
      "name": "Necrotic_Sand"
    },
    {
      "x": -25,
      "y": 21,
      "z": 4,
      "name": "Necrotic_Sand"
    },
    {
      "x": -25,
      "y": 22,
      "z": 4,
      "name": "Necrotic_Sand"
    },
    {
      "x": -25,
      "y": 23,
      "z": 4,
      "name": "Necrotic_Sand"
    },
    {
      "x": -25,
      "y": 24,
      "z": 4,
      "name": "Necrotic_Sand"
    },
    {
      "x": -25,
      "y": 25,
      "z": 4,
      "name": "Necrotic_Sand"
    },
    {
      "x": -25,
      "y": 26,
      "z": 4,
      "name": "Necrotic_Sand"
    },
    {
      "x": -25,
      "y": 27,
      "z": 4,
      "name": "Necrotic_Sand"
    },
    {
      "x": -25,
      "y": 28,
      "z": 4,
      "name": "Necrotic_Sand"
    },
    {
      "x": -25,
      "y": 29,
      "z": 4,
      "name": "Necrotic_Sand"
    },
    {
      "x": -25,
      "y": 30,
      "z": 4,
      "name": "Necrotic_Sand"
    },
    {
      "x": -25,
      "y": 31,
      "z": 4,
      "name": "Necrotic_Sand"
    },
    {
      "x": -25,
      "y": 32,
      "z": 4,
      "name": "Necrotic_Sand"
    },
    {
      "x": -25,
      "y": 33,
      "z": 4,
      "name": "Necrotic_Sand"
    },
    {
      "x": -25,
      "y": 34,
      "z": 4,
      "name": "Necrotic_Sand"
    },
    {
      "x": -25,
      "y": 35,
      "z": 4,
      "name": "Necrotic_Sand"
    },
    {
      "x": -25,
      "y": 36,
      "z": 4,
      "name": "Necrotic_Sand"
    },
    {
      "x": -25,
      "y": 37,
      "z": 4,
      "name": "Necrotic_Sand"
    },
    {
      "x": -25,
      "y": 38,
      "z": 4,
      "name": "Necrotic_Sand"
    },
    {
      "x": -25,
      "y": 39,
      "z": 4,
      "name": "Necrotic_Sand"
    },
    {
      "x": -25,
      "y": 40,
      "z": 4,
      "name": "Necrotic_Sand"
    },
    {
      "x": -25,
      "y": 41,
      "z": 4,
      "name": "Necrotic_Sand"
    },
    {
      "x": -25,
      "y": 42,
      "z": 4,
      "name": "Necrotic_Sand"
    },
    {
      "x": -25,
      "y": 43,
      "z": 4,
      "name": "Necrotic_Sand"
    },
    {
      "x": -25,
      "y": 44,
      "z": 4,
      "name": "Necrotic_Sand"
    },
    {
      "x": -25,
      "y": 45,
      "z": 4,
      "name": "Necrotic_Sand"
    },
    {
      "x": -25,
      "y": 46,
      "z": 4,
      "name": "Necrotic_Sand"
    },
    {
      "x": -25,
      "y": 47,
      "z": 4,
      "name": "Necrotic_Sand"
    },
    {
      "x": -25,
      "y": 48,
      "z": 4,
      "name": "Necrotic_Sand"
    },
    {
      "x": -25,
      "y": 49,
      "z": 4,
      "name": "Necrotic_Sand"
    },
    {
      "x": -25,
      "y": 50,
      "z": 4,
      "name": "Necrotic_Sand"
    },
    {
      "x": -25,
      "y": 51,
      "z": 4,
      "name": "Sword_Cemetery_1"
    },
    {
      "x": -25,
      "y": 68,
      "z": 4,
      "name": "Necrotic_Sand"
    },
    {
      "x": -25,
      "y": 69,
      "z": 4,
      "name": "Necrotic_Sand"
    },
    {
      "x": -25,
      "y": 70,
      "z": 4,
      "name": "Necrotic_Sand"
    },
    {
      "x": -25,
      "y": 71,
      "z": 4,
      "name": "Necrotic_Sand"
    },
    {
      "x": -25,
      "y": 72,
      "z": 4,
      "name": "Necrotic_Mushroom_Flatcap",
      "components": {
        "Components": {
          "FarmingBlock": {
            "LastTickGameTime": "0001-01-01T12:00:00Z"
          },
          "PlacedByInteraction": {
            "WhoPlacedUuid": {
              "$binary": "bJ0Z/pHxT/WyhVA6z1mjfg==",
              "$type": "04"
            }
          }
        }
      }
    },
    {
      "x": -25,
      "y": 76,
      "z": 4,
      "name": "Necrotic_Sand"
    },
    {
      "x": -25,
      "y": 77,
      "z": 4,
      "name": "Necrotic_Sand"
    },
    {
      "x": -25,
      "y": 78,
      "z": 4,
      "name": "Necrotic_Sand"
    },
    {
      "x": -25,
      "y": 79,
      "z": 4,
      "name": "Necrotic_Sand"
    },
    {
      "x": -25,
      "y": 80,
      "z": 4,
      "name": "Necrotic_Sand"
    },
    {
      "x": -25,
      "y": 81,
      "z": 4,
      "name": "Necrotic_Sand"
    },
    {
      "x": -25,
      "y": 82,
      "z": 4,
      "name": "Necrotic_Sand"
    },
    {
      "x": -25,
      "y": 83,
      "z": 4,
      "name": "Necrotic_Sand"
    },
    {
      "x": -25,
      "y": 84,
      "z": 4,
      "name": "Necrotic_Sand"
    },
    {
      "x": -25,
      "y": 85,
      "z": 4,
      "name": "Necrotic_Sand"
    },
    {
      "x": -25,
      "y": 86,
      "z": 4,
      "name": "Necrotic_Sand"
    },
    {
      "x": -25,
      "y": 87,
      "z": 4,
      "name": "Necrotic_Sand"
    },
    {
      "x": -25,
      "y": 88,
      "z": 4,
      "name": "Sword_Cemetery_3"
    },
    {
      "x": -25,
      "y": 20,
      "z": 5,
      "name": "Necrotic_Sand"
    },
    {
      "x": -25,
      "y": 21,
      "z": 5,
      "name": "Necrotic_Sand"
    },
    {
      "x": -25,
      "y": 22,
      "z": 5,
      "name": "Necrotic_Sand"
    },
    {
      "x": -25,
      "y": 23,
      "z": 5,
      "name": "Necrotic_Sand"
    },
    {
      "x": -25,
      "y": 24,
      "z": 5,
      "name": "Necrotic_Sand"
    },
    {
      "x": -25,
      "y": 25,
      "z": 5,
      "name": "Necrotic_Sand"
    },
    {
      "x": -25,
      "y": 26,
      "z": 5,
      "name": "Necrotic_Sand"
    },
    {
      "x": -25,
      "y": 27,
      "z": 5,
      "name": "Necrotic_Sand"
    },
    {
      "x": -25,
      "y": 28,
      "z": 5,
      "name": "Necrotic_Sand"
    },
    {
      "x": -25,
      "y": 29,
      "z": 5,
      "name": "Necrotic_Sand"
    },
    {
      "x": -25,
      "y": 30,
      "z": 5,
      "name": "Necrotic_Sand"
    },
    {
      "x": -25,
      "y": 31,
      "z": 5,
      "name": "Necrotic_Sand"
    },
    {
      "x": -25,
      "y": 32,
      "z": 5,
      "name": "Necrotic_Sand"
    },
    {
      "x": -25,
      "y": 33,
      "z": 5,
      "name": "Necrotic_Sand"
    },
    {
      "x": -25,
      "y": 34,
      "z": 5,
      "name": "Necrotic_Sand"
    },
    {
      "x": -25,
      "y": 35,
      "z": 5,
      "name": "Necrotic_Sand"
    },
    {
      "x": -25,
      "y": 36,
      "z": 5,
      "name": "Necrotic_Sand"
    },
    {
      "x": -25,
      "y": 38,
      "z": 5,
      "name": "Necrotic_Sand"
    },
    {
      "x": -25,
      "y": 39,
      "z": 5,
      "name": "Necrotic_Sand"
    },
    {
      "x": -25,
      "y": 40,
      "z": 5,
      "name": "Necrotic_Sand"
    },
    {
      "x": -25,
      "y": 41,
      "z": 5,
      "name": "Necrotic_Sand"
    },
    {
      "x": -25,
      "y": 42,
      "z": 5,
      "name": "Necrotic_Sand"
    },
    {
      "x": -25,
      "y": 43,
      "z": 5,
      "name": "Necrotic_Sand"
    },
    {
      "x": -25,
      "y": 48,
      "z": 5,
      "name": "Necrotic_Sand"
    },
    {
      "x": -25,
      "y": 49,
      "z": 5,
      "name": "Sword_Cemetery_1"
    },
    {
      "x": -25,
      "y": 77,
      "z": 5,
      "name": "Wood_Burnt_Roots"
    },
    {
      "x": -25,
      "y": 78,
      "z": 5,
      "name": "Necrotic_Sand"
    },
    {
      "x": -25,
      "y": 79,
      "z": 5,
      "name": "Necrotic_Sand"
    },
    {
      "x": -25,
      "y": 80,
      "z": 5,
      "name": "Necrotic_Sand"
    },
    {
      "x": -25,
      "y": 81,
      "z": 5,
      "name": "Dead_Branch"
    },
    {
      "x": -24,
      "y": 23,
      "z": -6,
      "name": "Necrotic_Sand"
    },
    {
      "x": -24,
      "y": 24,
      "z": -6,
      "name": "Necrotic_Sand"
    },
    {
      "x": -24,
      "y": 25,
      "z": -6,
      "name": "Necrotic_Sand"
    },
    {
      "x": -24,
      "y": 26,
      "z": -6,
      "name": "Necrotic_Sand"
    },
    {
      "x": -24,
      "y": 27,
      "z": -6,
      "name": "Necrotic_Sand"
    },
    {
      "x": -24,
      "y": 21,
      "z": -5,
      "name": "Necrotic_Sand"
    },
    {
      "x": -24,
      "y": 22,
      "z": -5,
      "name": "Necrotic_Sand"
    },
    {
      "x": -24,
      "y": 23,
      "z": -5,
      "name": "Necrotic_Sand"
    },
    {
      "x": -24,
      "y": 24,
      "z": -5,
      "name": "Necrotic_Sand"
    },
    {
      "x": -24,
      "y": 25,
      "z": -5,
      "name": "Necrotic_Sand"
    },
    {
      "x": -24,
      "y": 26,
      "z": -5,
      "name": "Necrotic_Sand"
    },
    {
      "x": -24,
      "y": 27,
      "z": -5,
      "name": "Necrotic_Sand"
    },
    {
      "x": -24,
      "y": 28,
      "z": -5,
      "name": "Necrotic_Sand"
    },
    {
      "x": -24,
      "y": 29,
      "z": -5,
      "name": "Necrotic_Sand"
    },
    {
      "x": -24,
      "y": 19,
      "z": -4,
      "name": "Necrotic_Sand"
    },
    {
      "x": -24,
      "y": 20,
      "z": -4,
      "name": "Necrotic_Sand"
    },
    {
      "x": -24,
      "y": 21,
      "z": -4,
      "name": "Necrotic_Sand"
    },
    {
      "x": -24,
      "y": 22,
      "z": -4,
      "name": "Necrotic_Sand"
    },
    {
      "x": -24,
      "y": 23,
      "z": -4,
      "name": "Necrotic_Sand"
    },
    {
      "x": -24,
      "y": 24,
      "z": -4,
      "name": "Necrotic_Sand"
    },
    {
      "x": -24,
      "y": 25,
      "z": -4,
      "name": "Necrotic_Sand"
    },
    {
      "x": -24,
      "y": 26,
      "z": -4,
      "name": "Necrotic_Sand"
    },
    {
      "x": -24,
      "y": 27,
      "z": -4,
      "name": "Necrotic_Sand"
    },
    {
      "x": -24,
      "y": 28,
      "z": -4,
      "name": "Necrotic_Sand"
    },
    {
      "x": -24,
      "y": 29,
      "z": -4,
      "name": "Necrotic_Sand"
    },
    {
      "x": -24,
      "y": 30,
      "z": -4,
      "name": "Necrotic_Sand"
    },
    {
      "x": -24,
      "y": 31,
      "z": -4,
      "name": "Necrotic_Sand"
    },
    {
      "x": -24,
      "y": 32,
      "z": -4,
      "name": "Necrotic_Sand"
    },
    {
      "x": -24,
      "y": 33,
      "z": -4,
      "name": "Necrotic_Sand"
    },
    {
      "x": -24,
      "y": 34,
      "z": -4,
      "name": "Necrotic_Sand"
    },
    {
      "x": -24,
      "y": 35,
      "z": -4,
      "name": "Necrotic_Sand"
    },
    {
      "x": -24,
      "y": 36,
      "z": -4,
      "name": "Necrotic_Sand"
    },
    {
      "x": -24,
      "y": 37,
      "z": -4,
      "name": "Necrotic_Sand"
    },
    {
      "x": -24,
      "y": 38,
      "z": -4,
      "name": "Necrotic_Sand"
    },
    {
      "x": -24,
      "y": 39,
      "z": -4,
      "name": "Necrotic_Sand"
    },
    {
      "x": -24,
      "y": 40,
      "z": -4,
      "name": "Necrotic_Sand"
    },
    {
      "x": -24,
      "y": 41,
      "z": -4,
      "name": "Necrotic_Sand"
    },
    {
      "x": -24,
      "y": 42,
      "z": -4,
      "name": "Sword_Cemetery_1",
      "rotation": 3
    },
    {
      "x": -24,
      "y": 18,
      "z": -3,
      "name": "Necrotic_Sand"
    },
    {
      "x": -24,
      "y": 19,
      "z": -3,
      "name": "Necrotic_Sand"
    },
    {
      "x": -24,
      "y": 20,
      "z": -3,
      "name": "Necrotic_Sand"
    },
    {
      "x": -24,
      "y": 21,
      "z": -3,
      "name": "Necrotic_Sand"
    },
    {
      "x": -24,
      "y": 22,
      "z": -3,
      "name": "Necrotic_Sand"
    },
    {
      "x": -24,
      "y": 23,
      "z": -3,
      "name": "Necrotic_Sand"
    },
    {
      "x": -24,
      "y": 24,
      "z": -3,
      "name": "Necrotic_Sand"
    },
    {
      "x": -24,
      "y": 25,
      "z": -3,
      "name": "Necrotic_Sand"
    },
    {
      "x": -24,
      "y": 26,
      "z": -3,
      "name": "Necrotic_Sand"
    },
    {
      "x": -24,
      "y": 27,
      "z": -3,
      "name": "Necrotic_Sand"
    },
    {
      "x": -24,
      "y": 28,
      "z": -3,
      "name": "Necrotic_Sand"
    },
    {
      "x": -24,
      "y": 29,
      "z": -3,
      "name": "Necrotic_Sand"
    },
    {
      "x": -24,
      "y": 30,
      "z": -3,
      "name": "Necrotic_Sand"
    },
    {
      "x": -24,
      "y": 31,
      "z": -3,
      "name": "Necrotic_Sand"
    },
    {
      "x": -24,
      "y": 32,
      "z": -3,
      "name": "Necrotic_Sand"
    },
    {
      "x": -24,
      "y": 33,
      "z": -3,
      "name": "Necrotic_Sand"
    },
    {
      "x": -24,
      "y": 34,
      "z": -3,
      "name": "Necrotic_Sand"
    },
    {
      "x": -24,
      "y": 35,
      "z": -3,
      "name": "Necrotic_Sand"
    },
    {
      "x": -24,
      "y": 36,
      "z": -3,
      "name": "Necrotic_Sand"
    },
    {
      "x": -24,
      "y": 37,
      "z": -3,
      "name": "Necrotic_Sand"
    },
    {
      "x": -24,
      "y": 38,
      "z": -3,
      "name": "Necrotic_Sand"
    },
    {
      "x": -24,
      "y": 39,
      "z": -3,
      "name": "Necrotic_Sand"
    },
    {
      "x": -24,
      "y": 40,
      "z": -3,
      "name": "Necrotic_Sand"
    },
    {
      "x": -24,
      "y": 41,
      "z": -3,
      "name": "Necrotic_Sand"
    },
    {
      "x": -24,
      "y": 42,
      "z": -3,
      "name": "Necrotic_Sand"
    },
    {
      "x": -24,
      "y": 43,
      "z": -3,
      "name": "Necrotic_Sand"
    },
    {
      "x": -24,
      "y": 44,
      "z": -3,
      "name": "Necrotic_Sand"
    },
    {
      "x": -24,
      "y": 45,
      "z": -3,
      "name": "Necrotic_Sand"
    },
    {
      "x": -24,
      "y": 46,
      "z": -3,
      "name": "Necrotic_Sand"
    },
    {
      "x": -24,
      "y": 47,
      "z": -3,
      "name": "Necrotic_Sand"
    },
    {
      "x": -24,
      "y": 48,
      "z": -3,
      "name": "Necrotic_Sand"
    },
    {
      "x": -24,
      "y": 49,
      "z": -3,
      "name": "Necrotic_Sand"
    },
    {
      "x": -24,
      "y": 50,
      "z": -3,
      "name": "Necrotic_Sand"
    },
    {
      "x": -24,
      "y": 17,
      "z": -2,
      "name": "Necrotic_Sand"
    },
    {
      "x": -24,
      "y": 18,
      "z": -2,
      "name": "Necrotic_Sand"
    },
    {
      "x": -24,
      "y": 19,
      "z": -2,
      "name": "Necrotic_Sand"
    },
    {
      "x": -24,
      "y": 20,
      "z": -2,
      "name": "Necrotic_Sand"
    },
    {
      "x": -24,
      "y": 21,
      "z": -2,
      "name": "Necrotic_Sand"
    },
    {
      "x": -24,
      "y": 22,
      "z": -2,
      "name": "Necrotic_Sand"
    },
    {
      "x": -24,
      "y": 23,
      "z": -2,
      "name": "Necrotic_Sand"
    },
    {
      "x": -24,
      "y": 24,
      "z": -2,
      "name": "Necrotic_Sand"
    },
    {
      "x": -24,
      "y": 25,
      "z": -2,
      "name": "Necrotic_Sand"
    },
    {
      "x": -24,
      "y": 26,
      "z": -2,
      "name": "Necrotic_Sand"
    },
    {
      "x": -24,
      "y": 27,
      "z": -2,
      "name": "Necrotic_Sand"
    },
    {
      "x": -24,
      "y": 28,
      "z": -2,
      "name": "Necrotic_Sand"
    },
    {
      "x": -24,
      "y": 29,
      "z": -2,
      "name": "Necrotic_Sand"
    },
    {
      "x": -24,
      "y": 30,
      "z": -2,
      "name": "Necrotic_Sand"
    },
    {
      "x": -24,
      "y": 31,
      "z": -2,
      "name": "Necrotic_Sand"
    },
    {
      "x": -24,
      "y": 32,
      "z": -2,
      "name": "Necrotic_Sand"
    },
    {
      "x": -24,
      "y": 33,
      "z": -2,
      "name": "Necrotic_Sand"
    },
    {
      "x": -24,
      "y": 34,
      "z": -2,
      "name": "Necrotic_Sand"
    },
    {
      "x": -24,
      "y": 35,
      "z": -2,
      "name": "Necrotic_Sand"
    },
    {
      "x": -24,
      "y": 36,
      "z": -2,
      "name": "Necrotic_Sand"
    },
    {
      "x": -24,
      "y": 37,
      "z": -2,
      "name": "Necrotic_Sand"
    },
    {
      "x": -24,
      "y": 38,
      "z": -2,
      "name": "Necrotic_Sand"
    },
    {
      "x": -24,
      "y": 39,
      "z": -2,
      "name": "Necrotic_Sand"
    },
    {
      "x": -24,
      "y": 40,
      "z": -2,
      "name": "Necrotic_Sand"
    },
    {
      "x": -24,
      "y": 41,
      "z": -2,
      "name": "Necrotic_Sand"
    },
    {
      "x": -24,
      "y": 42,
      "z": -2,
      "name": "Necrotic_Sand"
    },
    {
      "x": -24,
      "y": 43,
      "z": -2,
      "name": "Necrotic_Sand"
    },
    {
      "x": -24,
      "y": 44,
      "z": -2,
      "name": "Necrotic_Sand"
    },
    {
      "x": -24,
      "y": 45,
      "z": -2,
      "name": "Necrotic_Sand"
    },
    {
      "x": -24,
      "y": 46,
      "z": -2,
      "name": "Necrotic_Sand"
    },
    {
      "x": -24,
      "y": 47,
      "z": -2,
      "name": "Necrotic_Sand"
    },
    {
      "x": -24,
      "y": 48,
      "z": -2,
      "name": "Necrotic_Sand"
    },
    {
      "x": -24,
      "y": 49,
      "z": -2,
      "name": "Necrotic_Sand"
    },
    {
      "x": -24,
      "y": 50,
      "z": -2,
      "name": "Necrotic_Sand"
    },
    {
      "x": -24,
      "y": 51,
      "z": -2,
      "name": "Necrotic_Sand"
    },
    {
      "x": -24,
      "y": 52,
      "z": -2,
      "name": "Necrotic_Sand"
    },
    {
      "x": -24,
      "y": 53,
      "z": -2,
      "name": "Necrotic_Sand"
    },
    {
      "x": -24,
      "y": 16,
      "z": -1,
      "name": "Necrotic_Sand"
    },
    {
      "x": -24,
      "y": 17,
      "z": -1,
      "name": "Necrotic_Sand"
    },
    {
      "x": -24,
      "y": 18,
      "z": -1,
      "name": "Necrotic_Sand"
    },
    {
      "x": -24,
      "y": 19,
      "z": -1,
      "name": "Necrotic_Sand"
    },
    {
      "x": -24,
      "y": 20,
      "z": -1,
      "name": "Necrotic_Sand"
    },
    {
      "x": -24,
      "y": 21,
      "z": -1,
      "name": "Necrotic_Sand"
    },
    {
      "x": -24,
      "y": 22,
      "z": -1,
      "name": "Necrotic_Sand"
    },
    {
      "x": -24,
      "y": 23,
      "z": -1,
      "name": "Necrotic_Sand"
    },
    {
      "x": -24,
      "y": 24,
      "z": -1,
      "name": "Necrotic_Sand"
    },
    {
      "x": -24,
      "y": 25,
      "z": -1,
      "name": "Necrotic_Sand"
    },
    {
      "x": -24,
      "y": 26,
      "z": -1,
      "name": "Necrotic_Sand"
    },
    {
      "x": -24,
      "y": 27,
      "z": -1,
      "name": "Necrotic_Sand"
    },
    {
      "x": -24,
      "y": 28,
      "z": -1,
      "name": "Necrotic_Sand"
    },
    {
      "x": -24,
      "y": 29,
      "z": -1,
      "name": "Necrotic_Sand"
    },
    {
      "x": -24,
      "y": 30,
      "z": -1,
      "name": "Necrotic_Sand"
    },
    {
      "x": -24,
      "y": 31,
      "z": -1,
      "name": "Necrotic_Sand"
    },
    {
      "x": -24,
      "y": 32,
      "z": -1,
      "name": "Necrotic_Sand"
    },
    {
      "x": -24,
      "y": 33,
      "z": -1,
      "name": "Necrotic_Sand"
    },
    {
      "x": -24,
      "y": 34,
      "z": -1,
      "name": "Necrotic_Sand"
    },
    {
      "x": -24,
      "y": 35,
      "z": -1,
      "name": "Necrotic_Sand"
    },
    {
      "x": -24,
      "y": 36,
      "z": -1,
      "name": "Necrotic_Sand"
    },
    {
      "x": -24,
      "y": 37,
      "z": -1,
      "name": "Necrotic_Sand"
    },
    {
      "x": -24,
      "y": 38,
      "z": -1,
      "name": "Necrotic_Sand"
    },
    {
      "x": -24,
      "y": 39,
      "z": -1,
      "name": "Necrotic_Sand"
    },
    {
      "x": -24,
      "y": 40,
      "z": -1,
      "name": "Necrotic_Sand"
    },
    {
      "x": -24,
      "y": 41,
      "z": -1,
      "name": "Necrotic_Sand"
    },
    {
      "x": -24,
      "y": 42,
      "z": -1,
      "name": "Necrotic_Sand"
    },
    {
      "x": -24,
      "y": 43,
      "z": -1,
      "name": "Necrotic_Sand"
    },
    {
      "x": -24,
      "y": 44,
      "z": -1,
      "name": "Necrotic_Sand"
    },
    {
      "x": -24,
      "y": 45,
      "z": -1,
      "name": "Necrotic_Sand"
    },
    {
      "x": -24,
      "y": 46,
      "z": -1,
      "name": "Necrotic_Sand"
    },
    {
      "x": -24,
      "y": 47,
      "z": -1,
      "name": "Necrotic_Sand"
    },
    {
      "x": -24,
      "y": 48,
      "z": -1,
      "name": "Necrotic_Sand"
    },
    {
      "x": -24,
      "y": 49,
      "z": -1,
      "name": "Necrotic_Sand"
    },
    {
      "x": -24,
      "y": 50,
      "z": -1,
      "name": "Necrotic_Sand"
    },
    {
      "x": -24,
      "y": 51,
      "z": -1,
      "name": "Necrotic_Sand"
    },
    {
      "x": -24,
      "y": 52,
      "z": -1,
      "name": "Necrotic_Sand"
    },
    {
      "x": -24,
      "y": 53,
      "z": -1,
      "name": "Necrotic_Sand"
    },
    {
      "x": -24,
      "y": 54,
      "z": -1,
      "name": "Necrotic_Sand"
    },
    {
      "x": -24,
      "y": 55,
      "z": -1,
      "name": "Necrotic_Sand"
    },
    {
      "x": -24,
      "y": 61,
      "z": -1,
      "name": "Necrotic_Sand"
    },
    {
      "x": -24,
      "y": 15,
      "z": 0,
      "name": "Wood_Burnt_Roots"
    },
    {
      "x": -24,
      "y": 16,
      "z": 0,
      "name": "Necrotic_Sand"
    },
    {
      "x": -24,
      "y": 17,
      "z": 0,
      "name": "Necrotic_Sand"
    },
    {
      "x": -24,
      "y": 18,
      "z": 0,
      "name": "Necrotic_Sand"
    },
    {
      "x": -24,
      "y": 19,
      "z": 0,
      "name": "Necrotic_Sand"
    },
    {
      "x": -24,
      "y": 20,
      "z": 0,
      "name": "Necrotic_Sand"
    },
    {
      "x": -24,
      "y": 21,
      "z": 0,
      "name": "Necrotic_Sand"
    },
    {
      "x": -24,
      "y": 22,
      "z": 0,
      "name": "Necrotic_Sand"
    },
    {
      "x": -24,
      "y": 23,
      "z": 0,
      "name": "Necrotic_Sand"
    },
    {
      "x": -24,
      "y": 24,
      "z": 0,
      "name": "Necrotic_Sand"
    },
    {
      "x": -24,
      "y": 25,
      "z": 0,
      "name": "Necrotic_Sand"
    },
    {
      "x": -24,
      "y": 26,
      "z": 0,
      "name": "Necrotic_Sand"
    },
    {
      "x": -24,
      "y": 27,
      "z": 0,
      "name": "Necrotic_Sand"
    },
    {
      "x": -24,
      "y": 28,
      "z": 0,
      "name": "Necrotic_Sand"
    },
    {
      "x": -24,
      "y": 29,
      "z": 0,
      "name": "Necrotic_Sand"
    },
    {
      "x": -24,
      "y": 30,
      "z": 0,
      "name": "Necrotic_Sand"
    },
    {
      "x": -24,
      "y": 31,
      "z": 0,
      "name": "Necrotic_Sand"
    },
    {
      "x": -24,
      "y": 32,
      "z": 0,
      "name": "Necrotic_Sand"
    },
    {
      "x": -24,
      "y": 33,
      "z": 0,
      "name": "Necrotic_Sand"
    },
    {
      "x": -24,
      "y": 34,
      "z": 0,
      "name": "Necrotic_Sand"
    },
    {
      "x": -24,
      "y": 35,
      "z": 0,
      "name": "Necrotic_Sand"
    },
    {
      "x": -24,
      "y": 36,
      "z": 0,
      "name": "Necrotic_Sand"
    },
    {
      "x": -24,
      "y": 37,
      "z": 0,
      "name": "Necrotic_Sand"
    },
    {
      "x": -24,
      "y": 38,
      "z": 0,
      "name": "Necrotic_Sand"
    },
    {
      "x": -24,
      "y": 39,
      "z": 0,
      "name": "Necrotic_Sand"
    },
    {
      "x": -24,
      "y": 40,
      "z": 0,
      "name": "Necrotic_Sand"
    },
    {
      "x": -24,
      "y": 41,
      "z": 0,
      "name": "Necrotic_Sand"
    },
    {
      "x": -24,
      "y": 42,
      "z": 0,
      "name": "Necrotic_Sand"
    },
    {
      "x": -24,
      "y": 43,
      "z": 0,
      "name": "Necrotic_Sand"
    },
    {
      "x": -24,
      "y": 44,
      "z": 0,
      "name": "Necrotic_Sand"
    },
    {
      "x": -24,
      "y": 45,
      "z": 0,
      "name": "Necrotic_Sand"
    },
    {
      "x": -24,
      "y": 46,
      "z": 0,
      "name": "Necrotic_Sand"
    },
    {
      "x": -24,
      "y": 47,
      "z": 0,
      "name": "Necrotic_Sand"
    },
    {
      "x": -24,
      "y": 48,
      "z": 0,
      "name": "Necrotic_Sand"
    },
    {
      "x": -24,
      "y": 49,
      "z": 0,
      "name": "Necrotic_Sand"
    },
    {
      "x": -24,
      "y": 50,
      "z": 0,
      "name": "Necrotic_Sand"
    },
    {
      "x": -24,
      "y": 51,
      "z": 0,
      "name": "Necrotic_Sand"
    },
    {
      "x": -24,
      "y": 52,
      "z": 0,
      "name": "Necrotic_Sand"
    },
    {
      "x": -24,
      "y": 53,
      "z": 0,
      "name": "Necrotic_Sand"
    },
    {
      "x": -24,
      "y": 54,
      "z": 0,
      "name": "Necrotic_Sand"
    },
    {
      "x": -24,
      "y": 55,
      "z": 0,
      "name": "Necrotic_Sand"
    },
    {
      "x": -24,
      "y": 56,
      "z": 0,
      "name": "Necrotic_Sand"
    },
    {
      "x": -24,
      "y": 58,
      "z": 0,
      "name": "Necrotic_Sand"
    },
    {
      "x": -24,
      "y": 59,
      "z": 0,
      "name": "Necrotic_Sand"
    },
    {
      "x": -24,
      "y": 60,
      "z": 0,
      "name": "Necrotic_Sand"
    },
    {
      "x": -24,
      "y": 61,
      "z": 0,
      "name": "Necrotic_Sand"
    },
    {
      "x": -24,
      "y": 62,
      "z": 0,
      "name": "Necrotic_Sand"
    },
    {
      "x": -24,
      "y": 63,
      "z": 0,
      "name": "Necrotic_Mushroom_Flatcap",
      "components": {
        "Components": {
          "FarmingBlock": {
            "LastTickGameTime": "0001-01-01T12:00:00Z"
          },
          "PlacedByInteraction": {
            "WhoPlacedUuid": {
              "$binary": "bJ0Z/pHxT/WyhVA6z1mjfg==",
              "$type": "04"
            }
          }
        }
      }
    },
    {
      "x": -24,
      "y": 70,
      "z": 0,
      "name": "Wood_Burnt_Roots"
    },
    {
      "x": -24,
      "y": 71,
      "z": 0,
      "name": "Necrotic_Sand"
    },
    {
      "x": -24,
      "y": 72,
      "z": 0,
      "name": "Necrotic_Sand"
    },
    {
      "x": -24,
      "y": 73,
      "z": 0,
      "name": "Necrotic_Sand"
    },
    {
      "x": -24,
      "y": 74,
      "z": 0,
      "name": "Necrotic_Sand"
    },
    {
      "x": -24,
      "y": 75,
      "z": 0,
      "name": "Necrotic_Sand"
    },
    {
      "x": -24,
      "y": 76,
      "z": 0,
      "name": "Necrotic_Sand"
    },
    {
      "x": -24,
      "y": 77,
      "z": 0,
      "name": "Sword_Cemetery_3",
      "rotation": 1
    },
    {
      "x": -24,
      "y": 14,
      "z": 1,
      "name": "Wood_Burnt_Roots"
    },
    {
      "x": -24,
      "y": 15,
      "z": 1,
      "name": "Necrotic_Sand"
    },
    {
      "x": -24,
      "y": 16,
      "z": 1,
      "name": "Necrotic_Sand"
    },
    {
      "x": -24,
      "y": 17,
      "z": 1,
      "name": "Necrotic_Sand"
    },
    {
      "x": -24,
      "y": 18,
      "z": 1,
      "name": "Necrotic_Sand"
    },
    {
      "x": -24,
      "y": 19,
      "z": 1,
      "name": "Necrotic_Sand"
    },
    {
      "x": -24,
      "y": 20,
      "z": 1,
      "name": "Necrotic_Sand"
    },
    {
      "x": -24,
      "y": 21,
      "z": 1,
      "name": "Necrotic_Sand"
    },
    {
      "x": -24,
      "y": 22,
      "z": 1,
      "name": "Necrotic_Sand"
    },
    {
      "x": -24,
      "y": 23,
      "z": 1,
      "name": "Necrotic_Sand"
    },
    {
      "x": -24,
      "y": 24,
