{
  "version": 8,
  "blockIdVersion": 11,
  "anchorX": 1,
  "anchorY": 7,
  "anchorZ": 0,
  "blocks": [
    {
      "x": -6,
      "y": 5,
      "z": -1,
      "name": "Necrotic_Sand"
    },
    {
      "x": -6,
      "y": 6,
      "z": -1,
      "name": "Necrotic_Sand"
    },
    {
      "x": -6,
      "y": 7,
      "z": -1,
      "name": "Rubble_Slate",
      "support": 15
    },
    {
      "x": -6,
      "y": 5,
      "z": 0,
      "name": "Necrotic_Sand"
    },
    {
      "x": -6,
      "y": 6,
      "z": 0,
      "name": "Necrotic_Sand"
    },
    {
      "x": -6,
      "y": 5,
      "z": 1,
      "name": "Necrotic_Sand"
    },
    {
      "x": -6,
      "y": 6,
      "z": 1,
      "name": "Necrotic_Sand"
    },
    {
      "x": -6,
      "y": 5,
      "z": 2,
      "name": "Necrotic_Sand"
    },
    {
      "x": -6,
      "y": 6,
      "z": 2,
      "name": "Necrotic_Sand"
    },
    {
      "x": -6,
      "y": 7,
      "z": 2,
      "name": "Rubble_Slate",
      "support": 15
    },
    {
      "x": -6,
      "y": 5,
      "z": 3,
      "name": "Necrotic_Sand"
    },
    {
      "x": -6,
      "y": 6,
      "z": 3,
      "name": "Necrotic_Sand"
    },
    {
      "x": -5,
      "y": 6,
      "z": -3,
      "name": "Necrotic_Sand"
    },
    {
      "x": -5,
      "y": 5,
      "z": -2,
      "name": "Necrotic_Sand"
    },
    {
      "x": -5,
      "y": 6,
      "z": -2,
      "name": "Necrotic_Sand"
    },
    {
      "x": -5,
      "y": 7,
      "z": -2,
      "name": "Sword_Cemetery_3",
      "rotation": 2
    },
    {
      "x": -5,
      "y": 4,
      "z": -1,
      "name": "Necrotic_Sand"
    },
    {
      "x": -5,
      "y": 5,
      "z": -1,
      "name": "Necrotic_Sand"
    },
    {
      "x": -5,
      "y": 6,
      "z": -1,
      "name": "Necrotic_Sand"
    },
    {
      "x": -5,
      "y": 7,
      "z": -1,
      "name": "Plant_Bush_Dead_Tall",
      "support": 15
    },
    {
      "x": -5,
      "y": 3,
      "z": 0,
      "name": "Wood_Burnt_Roots"
    },
    {
      "x": -5,
      "y": 4,
      "z": 0,
      "name": "Necrotic_Sand"
    },
    {
      "x": -5,
      "y": 5,
      "z": 0,
      "name": "Necrotic_Sand"
    },
    {
      "x": -5,
      "y": 6,
      "z": 0,
      "name": "Necrotic_Sand"
    },
    {
      "x": -5,
      "y": 7,
      "z": 0,
      "name": "Sword_Cemetery_2",
      "rotation": 3
    },
    {
      "x": -5,
      "y": 4,
      "z": 1,
      "name": "Necrotic_Sand"
    },
    {
      "x": -5,
      "y": 5,
      "z": 1,
      "name": "Necrotic_Sand"
    },
    {
      "x": -5,
      "y": 6,
      "z": 1,
      "name": "Necrotic_Sand"
    },
    {
      "x": -5,
      "y": 7,
      "z": 1,
      "name": "Necrotic_Grass"
    },
    {
      "x": -5,
      "y": 4,
      "z": 2,
      "name": "Necrotic_Sand"
    },
    {
      "x": -5,
      "y": 5,
      "z": 2,
      "name": "Necrotic_Sand"
    },
    {
      "x": -5,
      "y": 6,
      "z": 2,
      "name": "Necrotic_Sand"
    },
    {
      "x": -5,
      "y": 7,
      "z": 2,
      "name": "Sword_Cemetery_3",
      "rotation": 3
    },
    {
      "x": -5,
      "y": 4,
      "z": 3,
      "name": "Necrotic_Sand"
    },
    {
      "x": -5,
      "y": 5,
      "z": 3,
      "name": "Necrotic_Sand"
    },
    {
      "x": -5,
      "y": 6,
      "z": 3,
      "name": "Necrotic_Sand"
    },
    {
      "x": -5,
      "y": 7,
      "z": 3,
      "name": "Plant_Bush_Winter",
      "support": 15
    },
    {
      "x": -4,
      "y": 4,
      "z": -4,
      "name": "Wood_Burnt_Roots"
    },
    {
      "x": -4,
      "y": 5,
      "z": -4,
      "name": "Necrotic_Sand"
    },
    {
      "x": -4,
      "y": 6,
      "z": -4,
      "name": "Necrotic_Sand"
    },
    {
      "x": -4,
      "y": 4,
      "z": -3,
      "name": "Necrotic_Sand"
    },
    {
      "x": -4,
      "y": 5,
      "z": -3,
      "name": "Necrotic_Sand"
    },
    {
      "x": -4,
      "y": 6,
      "z": -3,
      "name": "Necrotic_Sand"
    },
    {
      "x": -4,
      "y": 7,
      "z": -3,
      "name": "Sword_Cemetery_3",
      "rotation": 2
    },
    {
      "x": -4,
      "y": 4,
      "z": -2,
      "name": "Necrotic_Sand"
    },
    {
      "x": -4,
      "y": 5,
      "z": -2,
      "name": "Necrotic_Sand"
    },
    {
      "x": -4,
      "y": 6,
      "z": -2,
      "name": "Necrotic_Sand"
    },
    {
      "x": -4,
      "y": 7,
      "z": -2,
      "name": "Plant_Bush_Dead_Tall",
      "support": 15
    },
    {
      "x": -4,
      "y": 3,
      "z": -1,
      "name": "Necrotic_Sand"
    },
    {
      "x": -4,
      "y": 4,
      "z": -1,
      "name": "Necrotic_Sand"
    },
    {
      "x": -4,
      "y": 5,
      "z": -1,
      "name": "Necrotic_Sand"
    },
    {
      "x": -4,
      "y": 6,
      "z": -1,
      "name": "Necrotic_Sand"
    },
    {
      "x": -4,
      "y": 7,
      "z": -1,
      "name": "Sword_Cemetery_3",
      "rotation": 3
    },
    {
      "x": -4,
      "y": 3,
      "z": 0,
      "name": "Necrotic_Sand"
    },
    {
      "x": -4,
      "y": 4,
      "z": 0,
      "name": "Necrotic_Sand"
    },
    {
      "x": -4,
      "y": 5,
      "z": 0,
      "name": "Necrotic_Sand"
    },
    {
      "x": -4,
      "y": 6,
      "z": 0,
      "name": "Empty"
    },
    {
      "x": -4,
      "y": 2,
      "z": 1,
      "name": "Wood_Burnt_Roots"
    },
    {
      "x": -4,
      "y": 3,
      "z": 1,
      "name": "Necrotic_Sand"
    },
    {
      "x": -4,
      "y": 4,
      "z": 1,
      "name": "Necrotic_Sand"
    },
    {
      "x": -4,
      "y": 5,
      "z": 1,
      "name": "Necrotic_Sand"
    },
    {
      "x": -4,
      "y": 6,
      "z": 1,
      "name": "Empty"
    },
    {
      "x": -4,
      "y": 3,
      "z": 2,
      "name": "Necrotic_Sand"
    },
    {
      "x": -4,
      "y": 4,
      "z": 2,
      "name": "Necrotic_Sand"
    },
    {
      "x": -4,
      "y": 5,
      "z": 2,
      "name": "Necrotic_Sand"
    },
    {
      "x": -4,
      "y": 6,
      "z": 2,
      "name": "Empty"
    },
    {
      "x": -4,
      "y": 4,
      "z": 3,
      "name": "Necrotic_Sand"
    },
    {
      "x": -4,
      "y": 5,
      "z": 3,
      "name": "Necrotic_Sand"
    },
    {
      "x": -4,
      "y": 6,
      "z": 3,
      "name": "Necrotic_Sand"
    },
    {
      "x": -4,
      "y": 7,
      "z": 3,
      "name": "Dead_Branch"
    },
    {
      "x": -4,
      "y": 5,
      "z": 4,
      "name": "Necrotic_Sand"
    },
    {
      "x": -4,
      "y": 6,
      "z": 4,
      "name": "Necrotic_Sand"
    },
    {
      "x": -3,
      "y": 5,
      "z": -5,
      "name": "Wood_Burnt_Roots"
    },
    {
      "x": -3,
      "y": 6,
      "z": -5,
      "name": "Necrotic_Sand"
    },
    {
      "x": -3,
      "y": 4,
      "z": -4,
      "name": "Necrotic_Sand"
    },
    {
      "x": -3,
      "y": 5,
      "z": -4,
      "name": "Necrotic_Sand"
    },
    {
      "x": -3,
      "y": 6,
      "z": -4,
      "name": "Necrotic_Sand"
    },
    {
      "x": -3,
      "y": 7,
      "z": -4,
      "name": "Rubble_Slate",
      "support": 15
    },
    {
      "x": -3,
      "y": 3,
      "z": -3,
      "name": "Necrotic_Sand"
    },
    {
      "x": -3,
      "y": 4,
      "z": -3,
      "name": "Necrotic_Sand"
    },
    {
      "x": -3,
      "y": 5,
      "z": -3,
      "name": "Necrotic_Sand"
    },
    {
      "x": -3,
      "y": 6,
      "z": -3,
      "name": "Necrotic_Sand"
    },
    {
      "x": -3,
      "y": 7,
      "z": -3,
      "name": "Sword_Cemetery_2",
      "rotation": 2
    },
    {
      "x": -3,
      "y": 3,
      "z": -2,
      "name": "Necrotic_Sand"
    },
    {
      "x": -3,
      "y": 4,
      "z": -2,
      "name": "Necrotic_Sand"
    },
    {
      "x": -3,
      "y": 5,
      "z": -2,
      "name": "Necrotic_Sand"
    },
    {
      "x": -3,
      "y": 6,
      "z": -2,
      "name": "Empty"
    },
    {
      "x": -3,
      "y": 2,
      "z": -1,
      "name": "Necrotic_Sand"
    },
    {
      "x": -3,
      "y": 3,
      "z": -1,
      "name": "Necrotic_Sand"
    },
    {
      "x": -3,
      "y": 4,
      "z": -1,
      "name": "Necrotic_Sand"
    },
    {
      "x": -3,
      "y": 5,
      "z": -1,
      "name": "Necrotic_Sand"
    },
    {
      "x": -3,
      "y": 6,
      "z": -1,
      "name": "Empty"
    },
    {
      "x": -3,
      "y": 2,
      "z": 0,
      "name": "Necrotic_Sand"
    },
    {
      "x": -3,
      "y": 3,
      "z": 0,
      "name": "Necrotic_Sand"
    },
    {
      "x": -3,
      "y": 4,
      "z": 0,
      "name": "Necrotic_Sand"
    },
    {
      "x": -3,
      "y": 5,
      "z": 0,
      "name": "Necrotic_Sand"
    },
    {
      "x": -3,
      "y": 6,
      "z": 0,
      "name": "Empty"
    },
    {
      "x": -3,
      "y": 2,
      "z": 1,
      "name": "Necrotic_Sand"
    },
    {
      "x": -3,
      "y": 3,
      "z": 1,
      "name": "Necrotic_Sand"
    },
    {
      "x": -3,
      "y": 4,
      "z": 1,
      "name": "Necrotic_Sand"
    },
    {
      "x": -3,
      "y": 5,
      "z": 1,
      "name": "Necrotic_Sand"
    },
    {
      "x": -3,
      "y": 6,
      "z": 1,
      "name": "Necrotic_Sand"
    },
    {
      "x": -3,
      "y": 7,
      "z": 1,
      "name": "Necrotic_Sand"
    },
    {
      "x": -3,
      "y": 8,
      "z": 1,
      "name": "Plant_Bush_Dead_Tall",
      "support": 15
    },
    {
      "x": -3,
      "y": 2,
      "z": 2,
      "name": "Necrotic_Sand"
    },
    {
      "x": -3,
      "y": 3,
      "z": 2,
      "name": "Necrotic_Sand"
    },
    {
      "x": -3,
      "y": 4,
      "z": 2,
      "name": "Necrotic_Sand"
    },
    {
      "x": -3,
      "y": 5,
      "z": 2,
      "name": "Necrotic_Sand"
    },
    {
      "x": -3,
      "y": 6,
      "z": 2,
      "name": "Empty"
    },
    {
      "x": -3,
      "y": 2,
      "z": 3,
      "name": "Wood_Burnt_Roots"
    },
    {
      "x": -3,
      "y": 3,
      "z": 3,
      "name": "Necrotic_Sand"
    },
    {
      "x": -3,
      "y": 4,
      "z": 3,
      "name": "Necrotic_Sand"
    },
    {
      "x": -3,
      "y": 5,
      "z": 3,
      "name": "Necrotic_Sand"
    },
    {
      "x": -3,
      "y": 6,
      "z": 3,
      "name": "Empty"
    },
    {
      "x": -3,
      "y": 4,
      "z": 4,
      "name": "Necrotic_Sand"
    },
    {
      "x": -3,
      "y": 5,
      "z": 4,
      "name": "Necrotic_Sand"
    },
    {
      "x": -3,
      "y": 6,
      "z": 4,
      "name": "Necrotic_Sand"
    },
    {
      "x": -3,
      "y": 7,
      "z": 4,
      "name": "Sword_Cemetery_2",
      "rotation": 3
    },
    {
      "x": -3,
      "y": 5,
      "z": 5,
      "name": "Necrotic_Sand"
    },
    {
      "x": -3,
      "y": 6,
      "z": 5,
      "name": "Necrotic_Sand"
    },
    {
      "x": -2,
      "y": 5,
      "z": -5,
      "name": "Necrotic_Sand"
    },
    {
      "x": -2,
      "y": 6,
      "z": -5,
      "name": "Necrotic_Sand"
    },
    {
      "x": -2,
      "y": 4,
      "z": -4,
      "name": "Necrotic_Sand"
    },
    {
      "x": -2,
      "y": 5,
      "z": -4,
      "name": "Necrotic_Sand"
    },
    {
      "x": -2,
      "y": 6,
      "z": -4,
      "name": "Necrotic_Sand"
    },
    {
      "x": -2,
      "y": 7,
      "z": -4,
      "name": "Necrotic_Grass"
    },
    {
      "x": -2,
      "y": 2,
      "z": -3,
      "name": "Wood_Burnt_Roots"
    },
    {
      "x": -2,
      "y": 3,
      "z": -3,
      "name": "Necrotic_Sand"
    },
    {
      "x": -2,
      "y": 4,
      "z": -3,
      "name": "Necrotic_Sand"
    },
    {
      "x": -2,
      "y": 5,
      "z": -3,
      "name": "Necrotic_Sand"
    },
    {
      "x": -2,
      "y": 6,
      "z": -3,
      "name": "Empty"
    },
    {
      "x": -2,
      "y": 2,
      "z": -2,
      "name": "Necrotic_Sand"
    },
    {
      "x": -2,
      "y": 3,
      "z": -2,
      "name": "Necrotic_Sand"
    },
    {
      "x": -2,
      "y": 4,
      "z": -2,
      "name": "Necrotic_Sand"
    },
    {
      "x": -2,
      "y": 5,
      "z": -2,
      "name": "Necrotic_Sand"
    },
    {
      "x": -2,
      "y": 6,
      "z": -2,
      "name": "Empty"
    },
    {
      "x": -2,
      "y": 1,
      "z": -1,
      "name": "Wood_Burnt_Roots"
    },
    {
      "x": -2,
      "y": 2,
      "z": -1,
      "name": "Necrotic_Sand"
    },
    {
      "x": -2,
      "y": 3,
      "z": -1,
      "name": "Necrotic_Sand"
    },
    {
      "x": -2,
      "y": 4,
      "z": -1,
      "name": "Necrotic_Sand"
    },
    {
      "x": -2,
      "y": 5,
      "z": -1,
      "name": "Necrotic_Sand"
    },
    {
      "x": -2,
      "y": 6,
      "z": -1,
      "name": "Necrotic_Sand"
    },
    {
      "x": -2,
      "y": 7,
      "z": -1,
      "name": "Necrotic_Sand"
    },
    {
      "x": -2,
      "y": 8,
      "z": -1,
      "name": "Plant_Bush_Winter",
      "support": 15
    },
    {
      "x": -2,
      "y": 2,
      "z": 0,
      "name": "Necrotic_Sand"
    },
    {
      "x": -2,
      "y": 3,
      "z": 0,
      "name": "Necrotic_Sand"
    },
    {
      "x": -2,
      "y": 4,
      "z": 0,
      "name": "Necrotic_Sand"
    },
    {
      "x": -2,
      "y": 5,
      "z": 0,
      "name": "Necrotic_Sand"
    },
    {
      "x": -2,
      "y": 6,
      "z": 0,
      "name": "Necrotic_Sand"
    },
    {
      "x": -2,
      "y": 7,
      "z": 0,
      "name": "Necrotic_Sand"
    },
    {
      "x": -2,
      "y": 8,
      "z": 0,
      "name": "Necrotic_Grass"
    },
    {
      "x": -2,
      "y": 2,
      "z": 1,
      "name": "Necrotic_Sand"
    },
    {
      "x": -2,
      "y": 3,
      "z": 1,
      "name": "Necrotic_Sand"
    },
    {
      "x": -2,
      "y": 4,
      "z": 1,
      "name": "Necrotic_Sand"
    },
    {
      "x": -2,
      "y": 5,
      "z": 1,
      "name": "Necrotic_Sand"
    },
    {
      "x": -2,
      "y": 6,
      "z": 1,
      "name": "Necrotic_Sand"
    },
    {
      "x": -2,
      "y": 7,
      "z": 1,
      "name": "Necrotic_Sand"
    },
    {
      "x": -2,
      "y": 8,
      "z": 1,
      "name": "Sword_Cemetery_3",
      "rotation": 3
    },
    {
      "x": -2,
      "y": 2,
      "z": 2,
      "name": "Necrotic_Sand"
    },
    {
      "x": -2,
      "y": 3,
      "z": 2,
      "name": "Necrotic_Sand"
    },
    {
      "x": -2,
      "y": 4,
      "z": 2,
      "name": "Necrotic_Sand"
    },
    {
      "x": -2,
      "y": 5,
      "z": 2,
      "name": "Necrotic_Sand"
    },
    {
      "x": -2,
      "y": 6,
      "z": 2,
      "name": "Necrotic_Sand"
    },
    {
      "x": -2,
      "y": 7,
      "z": 2,
      "name": "Necrotic_Sand"
    },
    {
      "x": -2,
      "y": 8,
      "z": 2,
      "name": "Plant_Bush_Winter",
      "support": 15
    },
    {
      "x": -2,
      "y": 2,
      "z": 3,
      "name": "Necrotic_Sand"
    },
    {
      "x": -2,
      "y": 3,
      "z": 3,
      "name": "Necrotic_Sand"
    },
    {
      "x": -2,
      "y": 4,
      "z": 3,
      "name": "Necrotic_Sand"
    },
    {
      "x": -2,
      "y": 5,
      "z": 3,
      "name": "Necrotic_Sand"
    },
    {
      "x": -2,
      "y": 6,
      "z": 3,
      "name": "Empty"
    },
    {
      "x": -2,
      "y": 3,
      "z": 4,
      "name": "Necrotic_Sand"
    },
    {
      "x": -2,
      "y": 4,
      "z": 4,
      "name": "Necrotic_Sand"
    },
    {
      "x": -2,
      "y": 5,
      "z": 4,
      "name": "Necrotic_Sand"
    },
    {
      "x": -2,
      "y": 6,
      "z": 4,
      "name": "Necrotic_Sand"
    },
    {
      "x": -2,
      "y": 7,
      "z": 4,
      "name": "Sword_Cemetery_1",
      "rotation": 3
    },
    {
      "x": -2,
      "y": 4,
      "z": 5,
      "name": "Necrotic_Sand"
    },
    {
      "x": -2,
      "y": 5,
      "z": 5,
      "name": "Necrotic_Sand"
    },
    {
      "x": -2,
      "y": 6,
      "z": 5,
      "name": "Necrotic_Sand"
    },
    {
      "x": -2,
      "y": 7,
      "z": 5,
      "name": "Necrotic_Grass"
    },
    {
      "x": -2,
      "y": 5,
      "z": 6,
      "name": "Necrotic_Sand"
    },
    {
      "x": -2,
      "y": 6,
      "z": 6,
      "name": "Necrotic_Sand"
    },
    {
      "x": -1,
      "y": 5,
      "z": -5,
      "name": "Necrotic_Sand"
    },
    {
      "x": -1,
      "y": 6,
      "z": -5,
      "name": "Necrotic_Sand"
    },
    {
      "x": -1,
      "y": 4,
      "z": -4,
      "name": "Necrotic_Sand"
    },
    {
      "x": -1,
      "y": 5,
      "z": -4,
      "name": "Necrotic_Sand"
    },
    {
      "x": -1,
      "y": 6,
      "z": -4,
      "name": "Necrotic_Sand"
    },
    {
      "x": -1,
      "y": 7,
      "z": -4,
      "name": "Sword_Cemetery_2",
      "rotation": 2
    },
    {
      "x": -1,
      "y": 3,
      "z": -3,
      "name": "Necrotic_Sand"
    },
    {
      "x": -1,
      "y": 4,
      "z": -3,
      "name": "Necrotic_Sand"
    },
    {
      "x": -1,
      "y": 5,
      "z": -3,
      "name": "Necrotic_Sand"
    },
    {
      "x": -1,
      "y": 6,
      "z": -3,
      "name": "Empty"
    },
    {
      "x": -1,
      "y": 2,
      "z": -2,
      "name": "Necrotic_Sand"
    },
    {
      "x": -1,
      "y": 3,
      "z": -2,
      "name": "Necrotic_Sand"
    },
    {
      "x": -1,
      "y": 4,
      "z": -2,
      "name": "Necrotic_Sand"
    },
    {
      "x": -1,
      "y": 5,
      "z": -2,
      "name": "Necrotic_Sand"
    },
    {
      "x": -1,
      "y": 6,
      "z": -2,
      "name": "Necrotic_Sand"
    },
    {
      "x": -1,
      "y": 7,
      "z": -2,
      "name": "Necrotic_Sand"
    },
    {
      "x": -1,
      "y": 8,
      "z": -2,
      "name": "Plant_Bush_Dead_Tall",
      "support": 15
    },
    {
      "x": -1,
      "y": 2,
      "z": -1,
      "name": "Necrotic_Sand"
    },
    {
      "x": -1,
      "y": 3,
      "z": -1,
      "name": "Necrotic_Sand"
    },
    {
      "x": -1,
      "y": 4,
      "z": -1,
      "name": "Necrotic_Sand"
    },
    {
      "x": -1,
      "y": 5,
      "z": -1,
      "name": "Necrotic_Sand"
    },
    {
      "x": -1,
      "y": 6,
      "z": -1,
      "name": "Necrotic_Sand"
    },
    {
      "x": -1,
      "y": 7,
      "z": -1,
      "name": "Necrotic_Sand"
    },
    {
      "x": -1,
      "y": 8,
      "z": -1,
      "name": "Sword_Cemetery_2",
      "rotation": 3
    },
    {
      "x": -1,
      "y": 2,
      "z": 0,
      "name": "Necrotic_Sand"
    },
    {
      "x": -1,
      "y": 3,
      "z": 0,
      "name": "Necrotic_Sand"
    },
    {
      "x": -1,
      "y": 4,
      "z": 0,
      "name": "Necrotic_Sand"
    },
    {
      "x": -1,
      "y": 5,
      "z": 0,
      "name": "Necrotic_Sand"
    },
    {
      "x": -1,
      "y": 6,
      "z": 0,
      "name": "Necrotic_Sand"
    },
    {
      "x": -1,
      "y": 7,
      "z": 0,
      "name": "Necrotic_Sand"
    },
    {
      "x": -1,
      "y": 8,
      "z": 0,
      "name": "Necrotic_Sand"
    },
    {
      "x": -1,
      "y": 2,
      "z": 1,
      "name": "Necrotic_Sand"
    },
    {
      "x": -1,
      "y": 3,
      "z": 1,
      "name": "Necrotic_Sand"
    },
    {
      "x": -1,
      "y": 4,
      "z": 1,
      "name": "Necrotic_Sand"
    },
    {
      "x": -1,
      "y": 5,
      "z": 1,
      "name": "Necrotic_Sand"
    },
    {
      "x": -1,
      "y": 6,
      "z": 1,
      "name": "Necrotic_Sand"
    },
    {
      "x": -1,
      "y": 7,
      "z": 1,
      "name": "Necrotic_Sand"
    },
    {
      "x": -1,
      "y": 8,
      "z": 1,
      "name": "Necrotic_Sand"
    },
    {
      "x": -1,
      "y": 9,
      "z": 1,
      "name": "Sword_Cemetery_1",
      "rotation": 3
    },
    {
      "x": -1,
      "y": 2,
      "z": 2,
      "name": "Necrotic_Sand"
    },
    {
      "x": -1,
      "y": 3,
      "z": 2,
      "name": "Necrotic_Sand"
    },
    {
      "x": -1,
      "y": 4,
      "z": 2,
      "name": "Necrotic_Sand"
    },
    {
      "x": -1,
      "y": 5,
      "z": 2,
      "name": "Necrotic_Sand"
    },
    {
      "x": -1,
      "y": 6,
      "z": 2,
      "name": "Necrotic_Sand"
    },
    {
      "x": -1,
      "y": 7,
      "z": 2,
      "name": "Necrotic_Sand"
    },
    {
      "x": -1,
      "y": 8,
      "z": 2,
      "name": "Sword_Cemetery_1",
      "rotation": 3
    },
    {
      "x": -1,
      "y": 2,
      "z": 3,
      "name": "Necrotic_Sand"
    },
    {
      "x": -1,
      "y": 3,
      "z": 3,
      "name": "Necrotic_Sand"
    },
    {
      "x": -1,
      "y": 4,
      "z": 3,
      "name": "Necrotic_Sand"
    },
    {
      "x": -1,
      "y": 5,
      "z": 3,
      "name": "Necrotic_Sand"
    },
    {
      "x": -1,
      "y": 6,
      "z": 3,
      "name": "Empty"
    },
    {
      "x": -1,
      "y": 3,
      "z": 4,
      "name": "Necrotic_Sand"
    },
    {
      "x": -1,
      "y": 4,
      "z": 4,
      "name": "Necrotic_Sand"
    },
    {
      "x": -1,
      "y": 5,
      "z": 4,
      "name": "Necrotic_Sand"
    },
    {
      "x": -1,
      "y": 6,
      "z": 4,
      "name": "Empty"
    },
    {
      "x": -1,
      "y": 4,
      "z": 5,
      "name": "Necrotic_Sand"
    },
    {
      "x": -1,
      "y": 5,
      "z": 5,
      "name": "Necrotic_Sand"
    },
    {
      "x": -1,
      "y": 6,
      "z": 5,
      "name": "Necrotic_Sand"
    },
    {
      "x": -1,
      "y": 7,
      "z": 5,
      "name": "Sword_Cemetery_1"
    },
    {
      "x": -1,
      "y": 5,
      "z": 6,
      "name": "Necrotic_Sand"
    },
    {
      "x": -1,
      "y": 6,
      "z": 6,
      "name": "Necrotic_Sand"
    },
    {
      "x": -1,
      "y": 7,
      "z": 6,
      "name": "Rubble_Slate",
      "support": 15
    },
    {
      "x": 0,
      "y": 5,
      "z": -6,
      "name": "Necrotic_Sand"
    },
    {
      "x": 0,
      "y": 3,
      "z": -5,
      "name": "Wood_Burnt_Roots"
    },
    {
      "x": 0,
      "y": 4,
      "z": -5,
      "name": "Necrotic_Sand"
    },
    {
      "x": 0,
      "y": 5,
      "z": -5,
      "name": "Necrotic_Sand"
    },
    {
      "x": 0,
      "y": 6,
      "z": -5,
      "name": "Necrotic_Sand"
    },
    {
      "x": 0,
      "y": 7,
      "z": -5,
      "name": "Rubble_Slate",
      "support": 15
    },
    {
      "x": 0,
      "y": 3,
      "z": -4,
      "name": "Necrotic_Sand"
    },
    {
      "x": 0,
      "y": 4,
      "z": -4,
      "name": "Necrotic_Sand"
    },
    {
      "x": 0,
      "y": 5,
      "z": -4,
      "name": "Necrotic_Sand"
    },
    {
      "x": 0,
      "y": 6,
      "z": -4,
      "name": "Necrotic_Sand"
    },
    {
      "x": 0,
      "y": 7,
      "z": -4,
      "name": "Sword_Cemetery_3",
      "rotation": 2
    },
    {
      "x": 0,
      "y": 2,
      "z": -3,
      "name": "Necrotic_Sand"
    },
    {
      "x": 0,
      "y": 3,
      "z": -3,
      "name": "Necrotic_Sand"
    },
    {
      "x": 0,
      "y": 4,
      "z": -3,
      "name": "Necrotic_Sand"
    },
    {
      "x": 0,
      "y": 5,
      "z": -3,
      "name": "Necrotic_Sand"
    },
    {
      "x": 0,
      "y": 6,
      "z": -3,
      "name": "Empty"
    },
    {
      "x": 0,
      "y": 2,
      "z": -2,
      "name": "Necrotic_Sand"
    },
    {
      "x": 0,
      "y": 3,
      "z": -2,
      "name": "Necrotic_Sand"
    },
    {
      "x": 0,
      "y": 4,
      "z": -2,
      "name": "Necrotic_Sand"
    },
    {
      "x": 0,
      "y": 5,
      "z": -2,
      "name": "Necrotic_Sand"
    },
    {
      "x": 0,
      "y": 6,
      "z": -2,
      "name": "Necrotic_Sand"
    },
    {
      "x": 0,
      "y": 7,
      "z": -2,
      "name": "Necrotic_Sand"
    },
    {
      "x": 0,
      "y": 8,
      "z": -2,
      "name": "Necrotic_Grass"
    },
    {
      "x": 0,
      "y": 2,
      "z": -1,
      "name": "Necrotic_Sand"
    },
    {
      "x": 0,
      "y": 3,
      "z": -1,
      "name": "Necrotic_Sand"
    },
    {
      "x": 0,
      "y": 4,
      "z": -1,
      "name": "Necrotic_Sand"
    },
    {
      "x": 0,
      "y": 5,
      "z": -1,
      "name": "Necrotic_Sand"
    },
    {
      "x": 0,
      "y": 6,
      "z": -1,
      "name": "Necrotic_Sand"
    },
    {
      "x": 0,
      "y": 7,
      "z": -1,
      "name": "Necrotic_Sand"
    },
    {
      "x": 0,
      "y": 8,
      "z": -1,
      "name": "Necrotic_Sand"
    },
    {
      "x": 0,
      "y": 1,
      "z": 0,
      "name": "Wood_Burnt_Roots"
    },
    {
      "x": 0,
      "y": 2,
      "z": 0,
      "name": "Necrotic_Sand"
    },
    {
      "x": 0,
      "y": 3,
      "z": 0,
      "name": "Necrotic_Sand"
    },
    {
      "x": 0,
      "y": 4,
      "z": 0,
      "name": "Necrotic_Sand"
    },
    {
      "x": 0,
      "y": 5,
      "z": 0,
      "name": "Necrotic_Sand"
    },
    {
      "x": 0,
      "y": 6,
      "z": 0,
      "name": "Necrotic_Sand"
    },
    {
      "x": 0,
      "y": 7,
      "z": 0,
      "name": "Necrotic_Sand"
    },
    {
      "x": 0,
      "y": 8,
      "z": 0,
      "name": "Necrotic_Sand"
    },
    {
      "x": 0,
      "y": 9,
      "z": 0,
      "name": "Banner_1",
      "rotation": 3
    },
    {
      "x": 0,
      "y": 2,
      "z": 1,
      "name": "Necrotic_Sand"
    },
    {
      "x": 0,
      "y": 3,
      "z": 1,
      "name": "Necrotic_Sand"
    },
    {
      "x": 0,
      "y": 4,
      "z": 1,
      "name": "Necrotic_Sand"
    },
    {
      "x": 0,
      "y": 5,
      "z": 1,
      "name": "Necrotic_Sand"
    },
    {
      "x": 0,
      "y": 6,
      "z": 1,
      "name": "Necrotic_Sand"
    },
    {
      "x": 0,
      "y": 7,
      "z": 1,
      "name": "Necrotic_Sand"
    },
    {
      "x": 0,
      "y": 8,
      "z": 1,
      "name": "Necrotic_Crystal",
      "rotation": 4
    },
    {
      "x": 0,
      "y": 9,
      "z": 1,
      "name": "Plant_Bush_Winter",
      "support": 15
    },
    {
      "x": 0,
      "y": 2,
      "z": 2,
      "name": "Necrotic_Sand"
    },
    {
      "x": 0,
      "y": 3,
      "z": 2,
      "name": "Necrotic_Sand"
    },
    {
      "x": 0,
      "y": 4,
      "z": 2,
      "name": "Necrotic_Sand"
    },
    {
      "x": 0,
      "y": 5,
      "z": 2,
      "name": "Necrotic_Sand"
    },
    {
      "x": 0,
      "y": 6,
      "z": 2,
      "name": "Necrotic_Sand"
    },
    {
      "x": 0,
      "y": 7,
      "z": 2,
      "name": "Necrotic_Sand"
    },
    {
      "x": 0,
      "y": 8,
      "z": 2,
      "name": "Necrotic_Sand"
    },
    {
      "x": 0,
      "y": 2,
      "z": 3,
      "name": "Necrotic_Sand"
    },
    {
      "x": 0,
      "y": 3,
      "z": 3,
      "name": "Necrotic_Sand"
    },
    {
      "x": 0,
      "y": 4,
      "z": 3,
      "name": "Necrotic_Sand"
    },
    {
      "x": 0,
      "y": 5,
      "z": 3,
      "name": "Necrotic_Sand"
    },
    {
      "x": 0,
      "y": 6,
      "z": 3,
      "name": "Necrotic_Sand"
    },
    {
      "x": 0,
      "y": 7,
      "z": 3,
      "name": "Necrotic_Sand"
    },
    {
      "x": 0,
      "y": 8,
      "z": 3,
      "name": "Plant_Bush_Dead_Tall",
      "support": 15
    },
    {
      "x": 0,
      "y": 1,
      "z": 4,
      "name": "Wood_Burnt_Roots"
    },
    {
      "x": 0,
      "y": 2,
      "z": 4,
      "name": "Necrotic_Sand"
    },
    {
      "x": 0,
      "y": 3,
      "z": 4,
      "name": "Necrotic_Sand"
    },
    {
      "x": 0,
      "y": 4,
      "z": 4,
      "name": "Necrotic_Sand"
    },
    {
      "x": 0,
      "y": 5,
      "z": 4,
      "name": "Necrotic_Sand"
    },
    {
      "x": 0,
      "y": 6,
      "z": 4,
      "name": "Empty"
    },
    {
      "x": 0,
      "y": 3,
      "z": 5,
      "name": "Necrotic_Sand"
    },
    {
      "x": 0,
      "y": 4,
      "z": 5,
      "name": "Necrotic_Sand"
    },
    {
      "x": 0,
      "y": 5,
      "z": 5,
      "name": "Necrotic_Sand"
    },
    {
      "x": 0,
      "y": 6,
      "z": 5,
      "name": "Necrotic_Sand"
    },
    {
      "x": 0,
      "y": 7,
      "z": 5,
      "name": "Sword_Cemetery_2"
    },
    {
      "x": 0,
      "y": 3,
      "z": 6,
      "name": "Wood_Burnt_Roots"
    },
    {
      "x": 0,
      "y": 4,
      "z": 6,
      "name": "Necrotic_Sand"
    },
    {
      "x": 0,
      "y": 5,
      "z": 6,
      "name": "Necrotic_Sand"
    },
    {
      "x": 0,
      "y": 6,
      "z": 6,
      "name": "Necrotic_Sand"
    },
    {
      "x": 1,
      "y": 5,
      "z": -6,
      "name": "Necrotic_Sand"
    },
    {
      "x": 1,
      "y": 4,
      "z": -5,
      "name": "Necrotic_Sand"
    },
    {
      "x": 1,
      "y": 5,
      "z": -5,
      "name": "Necrotic_Sand"
    },
    {
      "x": 1,
      "y": 6,
      "z": -5,
      "name": "Necrotic_Sand"
    },
    {
      "x": 1,
      "y": 3,
      "z": -4,
      "name": "Necrotic_Sand"
    },
    {
      "x": 1,
      "y": 4,
      "z": -4,
      "name": "Necrotic_Sand"
    },
    {
      "x": 1,
      "y": 5,
      "z": -4,
      "name": "Necrotic_Sand"
    },
    {
      "x": 1,
      "y": 6,
      "z": -4,
      "name": "Necrotic_Sand"
    },
    {
      "x": 1,
      "y": 7,
      "z": -4,
      "name": "Sword_Cemetery_2",
      "rotation": 2
    },
    {
      "x": 1,
      "y": 2,
      "z": -3,
      "name": "Necrotic_Sand"
    },
    {
      "x": 1,
      "y": 3,
      "z": -3,
      "name": "Necrotic_Sand"
    },
    {
      "x": 1,
      "y": 4,
      "z": -3,
      "name": "Necrotic_Sand"
    },
    {
      "x": 1,
      "y": 5,
      "z": -3,
      "name": "Necrotic_Sand"
    },
    {
      "x": 1,
      "y": 6,
      "z": -3,
      "name": "Empty"
    },
    {
      "x": 1,
      "y": 2,
      "z": -2,
      "name": "Necrotic_Sand"
    },
    {
      "x": 1,
      "y": 3,
      "z": -2,
      "name": "Necrotic_Sand"
    },
    {
      "x": 1,
      "y": 4,
      "z": -2,
      "name": "Necrotic_Sand"
    },
    {
      "x": 1,
      "y": 5,
      "z": -2,
      "name": "Necrotic_Sand"
    },
    {
      "x": 1,
      "y": 6,
      "z": -2,
      "name": "Necrotic_Sand"
    },
    {
      "x": 1,
      "y": 7,
      "z": -2,
      "name": "Necrotic_Sand"
    },
    {
      "x": 1,
      "y": 8,
      "z": -2,
      "name": "Plant_Bush_Dead_Tall",
      "support": 15
    },
    {
      "x": 1,
      "y": 2,
      "z": -1,
      "name": "Necrotic_Sand"
    },
    {
      "x": 1,
      "y": 3,
      "z": -1,
      "name": "Necrotic_Sand"
    },
    {
      "x": 1,
      "y": 4,
      "z": -1,
      "name": "Necrotic_Sand"
    },
    {
      "x": 1,
      "y": 5,
      "z": -1,
      "name": "Necrotic_Sand"
    },
    {
      "x": 1,
      "y": 6,
      "z": -1,
      "name": "Necrotic_Sand"
    },
    {
      "x": 1,
      "y": 7,
      "z": -1,
      "name": "Necrotic_Sand"
    },
    {
      "x": 1,
      "y": 8,
      "z": -1,
      "name": "Necrotic_Sand"
    },
    {
      "x": 1,
      "y": 9,
      "z": -1,
      "name": "Sword_Cemetery_2",
      "rotation": 2
    },
    {
      "x": 1,
      "y": 2,
      "z": 0,
      "name": "Necrotic_Sand"
    },
    {
      "x": 1,
      "y": 3,
      "z": 0,
      "name": "Necrotic_Sand"
    },
    {
      "x": 1,
      "y": 4,
      "z": 0,
      "name": "Necrotic_Sand"
    },
    {
      "x": 1,
      "y": 5,
      "z": 0,
      "name": "Necrotic_Sand"
    },
    {
      "x": 1,
      "y": 6,
      "z": 0,
      "name": "Necrotic_Sand"
    },
    {
      "x": 1,
      "y": 7,
      "z": 0,
      "name": "Necrotic_Sand"
    },
    {
      "x": 1,
      "y": 8,
      "z": 0,
      "name": "Necrotic_Sand"
    },
    {
      "x": 1,
      "y": 9,
      "z": 0,
      "name": "Sword_Cemetery_1",
      "rotation": 1
    },
    {
      "x": 1,
      "y": 2,
      "z": 1,
      "name": "Necrotic_Sand"
    },
    {
      "x": 1,
      "y": 3,
      "z": 1,
      "name": "Necrotic_Sand"
    },
    {
      "x": 1,
      "y": 4,
      "z": 1,
      "name": "Necrotic_Sand"
    },
    {
      "x": 1,
      "y": 5,
      "z": 1,
      "name": "Necrotic_Sand"
    },
    {
      "x": 1,
      "y": 6,
      "z": 1,
      "name": "Necrotic_Sand"
    },
    {
      "x": 1,
      "y": 7,
      "z": 1,
      "name": "Necrotic_Sand"
    },
    {
      "x": 1,
      "y": 8,
      "z": 1,
      "name": "Necrotic_Sand"
    },
    {
      "x": 1,
      "y": 9,
      "z": 1,
      "name": "Sword_Cemetery_2",
      "rotation": 1
    },
    {
      "x": 1,
      "y": 2,
      "z": 2,
      "name": "Necrotic_Sand"
    },
    {
      "x": 1,
      "y": 3,
      "z": 2,
      "name": "Necrotic_Sand"
    },
    {
      "x": 1,
      "y": 4,
      "z": 2,
      "name": "Necrotic_Sand"
    },
    {
      "x": 1,
      "y": 5,
      "z": 2,
      "name": "Necrotic_Sand"
    },
    {
      "x": 1,
      "y": 6,
      "z": 2,
      "name": "Necrotic_Sand"
    },
    {
      "x": 1,
      "y": 7,
      "z": 2,
      "name": "Necrotic_Sand"
    },
    {
      "x": 1,
      "y": 8,
      "z": 2,
      "name": "Necrotic_Sand"
    },
    {
      "x": 1,
      "y": 9,
      "z": 2,
      "name": "Sword_Cemetery_1"
    },
    {
      "x": 1,
      "y": 2,
      "z": 3,
      "name": "Necrotic_Sand"
    },
    {
      "x": 1,
      "y": 3,
      "z": 3,
      "name": "Necrotic_Sand"
    },
    {
      "x": 1,
      "y": 4,
      "z": 3,
      "name": "Necrotic_Sand"
    },
    {
      "x": 1,
      "y": 5,
      "z": 3,
      "name": "Necrotic_Sand"
    },
    {
      "x": 1,
      "y": 6,
      "z": 3,
      "name": "Necrotic_Sand"
    },
    {
      "x": 1,
      "y": 7,
      "z": 3,
      "name": "Necrotic_Sand"
    },
    {
      "x": 1,
      "y": 8,
      "z": 3,
      "name": "Necrotic_Grass"
    },
    {
      "x": 1,
      "y": 2,
      "z": 4,
      "name": "Necrotic_Sand"
    },
    {
      "x": 1,
      "y": 3,
      "z": 4,
      "name": "Necrotic_Sand"
    },
    {
      "x": 1,
      "y": 4,
      "z": 4,
      "name": "Necrotic_Sand"
    },
    {
      "x": 1,
      "y": 5,
      "z": 4,
      "name": "Necrotic_Sand"
    },
    {
      "x": 1,
      "y": 6,
      "z": 4,
      "name": "Empty"
    },
    {
      "x": 1,
      "y": 3,
      "z": 5,
      "name": "Necrotic_Sand"
    },
    {
      "x": 1,
      "y": 4,
      "z": 5,
      "name": "Necrotic_Sand"
    },
    {
      "x": 1,
      "y": 5,
      "z": 5,
      "name": "Necrotic_Sand"
    },
    {
      "x": 1,
      "y": 6,
      "z": 5,
      "name": "Necrotic_Sand"
    },
    {
      "x": 1,
      "y": 7,
      "z": 5,
      "name": "Dead_Branch"
    },
    {
      "x": 1,
      "y": 4,
      "z": 6,
      "name": "Necrotic_Sand"
    },
    {
      "x": 1,
      "y": 5,
      "z": 6,
      "name": "Necrotic_Sand"
    },
    {
      "x": 1,
      "y": 6,
      "z": 6,
      "name": "Necrotic_Sand"
    },
    {
      "x": 2,
      "y": 5,
      "z": -6,
      "name": "Necrotic_Sand"
    },
    {
      "x": 2,
      "y": 6,
      "z": -6,
      "name": "Necrotic_Sand"
    },
    {
      "x": 2,
      "y": 7,
      "z": -6,
      "name": "Rubble_Slate",
      "support": 15
    },
    {
      "x": 2,
      "y": 4,
      "z": -5,
      "name": "Necrotic_Sand"
    },
    {
      "x": 2,
      "y": 5,
      "z": -5,
      "name": "Necrotic_Sand"
    },
    {
      "x": 2,
      "y": 6,
      "z": -5,
      "name": "Necrotic_Sand"
    },
    {
      "x": 2,
      "y": 3,
      "z": -4,
      "name": "Necrotic_Sand"
    },
    {
      "x": 2,
      "y": 4,
      "z": -4,
      "name": "Necrotic_Sand"
    },
    {
      "x": 2,
      "y": 5,
      "z": -4,
      "name": "Necrotic_Sand"
    },
    {
      "x": 2,
      "y": 6,
      "z": -4,
      "name": "Necrotic_Sand"
    },
    {
      "x": 2,
      "y": 7,
      "z": -4,
      "name": "Dead_Branch"
    },
    {
      "x": 2,
      "y": 2,
      "z": -3,
      "name": "Necrotic_Sand"
    },
    {
      "x": 2,
      "y": 3,
      "z": -3,
      "name": "Necrotic_Sand"
    },
    {
      "x": 2,
      "y": 4,
      "z": -3,
      "name": "Necrotic_Sand"
    },
    {
      "x": 2,
      "y": 5,
      "z": -3,
      "name": "Necrotic_Sand"
    },
    {
      "x": 2,
      "y": 6,
      "z": -3,
      "name": "Empty"
    },
    {
      "x": 2,
      "y": 2,
      "z": -2,
      "name": "Necrotic_Sand"
    },
    {
      "x": 2,
      "y": 3,
      "z": -2,
      "name": "Necrotic_Sand"
    },
    {
      "x": 2,
      "y": 4,
      "z": -2,
      "name": "Necrotic_Sand"
    },
    {
      "x": 2,
      "y": 5,
      "z": -2,
      "name": "Necrotic_Sand"
    },
    {
      "x": 2,
      "y": 6,
      "z": -2,
      "name": "Necrotic_Sand"
    },
    {
      "x": 2,
      "y": 7,
      "z": -2,
      "name": "Necrotic_Sand"
    },
    {
      "x": 2,
      "y": 8,
      "z": -2,
      "name": "Necrotic_Grass"
    },
    {
      "x": 2,
      "y": 1,
      "z": -1,
      "name": "Wood_Burnt_Roots"
    },
    {
      "x": 2,
      "y": 2,
      "z": -1,
      "name": "Necrotic_Sand"
    },
    {
      "x": 2,
      "y": 3,
      "z": -1,
      "name": "Necrotic_Sand"
    },
    {
      "x": 2,
      "y": 4,
      "z": -1,
      "name": "Necrotic_Sand"
    },
    {
      "x": 2,
      "y": 5,
      "z": -1,
      "name": "Necrotic_Sand"
    },
    {
      "x": 2,
      "y": 6,
      "z": -1,
      "name": "Necrotic_Sand"
    },
    {
      "x": 2,
      "y": 7,
      "z": -1,
      "name": "Necrotic_Sand"
    },
    {
      "x": 2,
      "y": 8,
      "z": -1,
      "name": "Sword_Cemetery_1",
      "rotation": 1
    },
    {
      "x": 2,
      "y": 2,
      "z": 0,
      "name": "Necrotic_Sand"
    },
    {
      "x": 2,
      "y": 3,
      "z": 0,
      "name": "Necrotic_Sand"
    },
    {
      "x": 2,
      "y": 4,
      "z": 0,
      "name": "Necrotic_Sand"
    },
    {
      "x": 2,
      "y": 5,
      "z": 0,
      "name": "Necrotic_Sand"
    },
    {
      "x": 2,
      "y": 6,
      "z": 0,
      "name": "Necrotic_Sand"
    },
    {
      "x": 2,
      "y": 7,
      "z": 0,
      "name": "Necrotic_Sand"
    },
    {
      "x": 2,
      "y": 8,
      "z": 0,
      "name": "Necrotic_Sand"
    },
    {
      "x": 2,
      "y": 9,
      "z": 0,
      "name": "Sword_Cemetery_2",
      "rotation": 1
    },
    {
      "x": 2,
      "y": 2,
      "z": 1,
      "name": "Necrotic_Sand"
    },
    {
      "x": 2,
      "y": 3,
      "z": 1,
      "name": "Necrotic_Sand"
    },
    {
      "x": 2,
      "y": 4,
      "z": 1,
      "name": "Necrotic_Sand"
    },
    {
      "x": 2,
      "y": 5,
      "z": 1,
      "name": "Necrotic_Sand"
    },
    {
      "x": 2,
      "y": 6,
      "z": 1,
      "name": "Necrotic_Sand"
    },
    {
      "x": 2,
      "y": 7,
      "z": 1,
      "name": "Necrotic_Sand"
    },
    {
      "x": 2,
      "y": 8,
      "z": 1,
      "name": "Necrotic_Sand"
    },
    {
      "x": 2,
      "y": 2,
      "z": 2,
      "name": "Necrotic_Sand"
    },
    {
      "x": 2,
      "y": 3,
      "z": 2,
      "name": "Necrotic_Sand"
    },
    {
      "x": 2,
      "y": 4,
      "z": 2,
      "name": "Necrotic_Sand"
    },
    {
      "x": 2,
      "y": 5,
      "z": 2,
      "name": "Necrotic_Sand"
    },
    {
      "x": 2,
      "y": 6,
      "z": 2,
      "name": "Necrotic_Sand"
    },
    {
      "x": 2,
      "y": 7,
      "z": 2,
      "name": "Necrotic_Sand"
    },
    {
      "x": 2,
      "y": 8,
      "z": 2,
      "name": "Sword_Cemetery_1",
      "rotation": 1
    },
    {
      "x": 2,
      "y": 2,
      "z": 3,
      "name": "Necrotic_Sand"
    },
    {
      "x": 2,
      "y": 3,
      "z": 3,
      "name": "Necrotic_Sand"
    },
    {
      "x": 2,
      "y": 4,
      "z": 3,
      "name": "Necrotic_Sand"
    },
    {
      "x": 2,
      "y": 5,
      "z": 3,
      "name": "Necrotic_Sand"
    },
    {
      "x": 2,
      "y": 6,
      "z": 3,
      "name": "Necrotic_Sand"
    },
    {
      "x": 2,
      "y": 7,
      "z": 3,
      "name": "Necrotic_Sand"
    },
    {
      "x": 2,
      "y": 2,
      "z": 4,
      "name": "Necrotic_Sand"
    },
    {
      "x": 2,
      "y": 3,
      "z": 4,
      "name": "Necrotic_Sand"
    },
    {
      "x": 2,
      "y": 4,
      "z": 4,
      "name": "Necrotic_Sand"
    },
    {
      "x": 2,
      "y": 5,
      "z": 4,
      "name": "Necrotic_Sand"
    },
    {
      "x": 2,
      "y": 6,
      "z": 4,
      "name": "Empty"
    },
    {
      "x": 2,
      "y": 3,
      "z": 5,
      "name": "Necrotic_Sand"
    },
    {
      "x": 2,
      "y": 4,
      "z": 5,
      "name": "Necrotic_Sand"
    },
    {
      "x": 2,
      "y": 5,
      "z": 5,
      "name": "Necrotic_Sand"
    },
    {
      "x": 2,
      "y": 6,
      "z": 5,
      "name": "Necrotic_Sand"
    },
    {
      "x": 2,
      "y": 7,
      "z": 5,
      "name": "Plant_Bush_Dead_Tall",
      "support": 15
    },
    {
      "x": 2,
      "y": 4,
      "z": 6,
      "name": "Necrotic_Sand"
    },
    {
      "x": 2,
      "y": 5,
      "z": 6,
      "name": "Necrotic_Sand"
    },
    {
      "x": 2,
      "y": 6,
      "z": 6,
      "name": "Necrotic_Sand"
    },
    {
      "x": 3,
      "y": 4,
      "z": -5,
      "name": "Wood_Burnt_Roots"
    },
    {
      "x": 3,
      "y": 5,
      "z": -5,
      "name": "Necrotic_Sand"
    },
    {
      "x": 3,
      "y": 6,
      "z": -5,
      "name": "Necrotic_Sand"
    },
    {
      "x": 3,
      "y": 4,
      "z": -4,
      "name": "Necrotic_Sand"
    },
    {
      "x": 3,
      "y": 5,
      "z": -4,
      "name": "Necrotic_Sand"
    },
    {
      "x": 3,
      "y": 6,
      "z": -4,
      "name": "Necrotic_Sand"
    },
    {
      "x": 3,
      "y": 7,
      "z": -4,
      "name": "Plant_Bush_Dead_Tall",
      "support": 15
    },
    {
      "x": 3,
      "y": 2,
      "z": -3,
      "name": "Wood_Burnt_Roots"
    },
    {
      "x": 3,
      "y": 3,
      "z": -3,
      "name": "Necrotic_Sand"
    },
    {
      "x": 3,
      "y": 4,
      "z": -3,
      "name": "Necrotic_Sand"
    },
    {
      "x": 3,
      "y": 5,
      "z": -3,
      "name": "Necrotic_Sand"
    },
    {
      "x": 3,
      "y": 6,
      "z": -3,
      "name": "Empty"
    },
    {
      "x": 3,
      "y": 2,
      "z": -2,
      "name": "Necrotic_Sand"
    },
    {
      "x": 3,
      "y": 3,
      "z": -2,
      "name": "Necrotic_Sand"
    },
    {
      "x": 3,
      "y": 4,
      "z": -2,
      "name": "Necrotic_Sand"
    },
    {
      "x": 3,
      "y": 5,
      "z": -2,
      "name": "Necrotic_Sand"
    },
    {
      "x": 3,
      "y": 6,
      "z": -2,
      "name": "Empty"
    },
    {
      "x": 3,
      "y": 2,
      "z": -1,
      "name": "Necrotic_Sand"
    },
    {
      "x": 3,
      "y": 3,
      "z": -1,
      "name": "Necrotic_Sand"
    },
    {
      "x": 3,
      "y": 4,
      "z": -1,
      "name": "Necrotic_Sand"
    },
    {
      "x": 3,
      "y": 5,
      "z": -1,
      "name": "Necrotic_Sand"
    },
    {
      "x": 3,
      "y": 6,
      "z": -1,
      "name": "Necrotic_Sand"
    },
    {
      "x": 3,
      "y": 7,
      "z": -1,
      "name": "Necrotic_Sand"
    },
    {
      "x": 3,
      "y": 8,
      "z": -1,
      "name": "Rubble_Slate",
      "support": 15
    },
    {
      "x": 3,
      "y": 2,
      "z": 0,
      "name": "Necrotic_Sand"
    },
    {
      "x": 3,
      "y": 3,
      "z": 0,
      "name": "Necrotic_Sand"
    },
    {
      "x": 3,
      "y": 4,
      "z": 0,
      "name": "Necrotic_Sand"
    },
    {
      "x": 3,
      "y": 5,
      "z": 0,
      "name": "Necrotic_Sand"
    },
    {
      "x": 3,
      "y": 6,
      "z": 0,
      "name": "Necrotic_Sand"
    },
    {
      "x": 3,
      "y": 7,
      "z": 0,
      "name": "Necrotic_Sand"
    },
    {
      "x": 3,
      "y": 8,
      "z": 0,
      "name": "Necrotic_Grass"
    },
    {
      "x": 3,
      "y": 2,
      "z": 1,
      "name": "Necrotic_Sand"
    },
    {
      "x": 3,
      "y": 3,
      "z": 1,
      "name": "Necrotic_Sand"
    },
    {
      "x": 3,
      "y": 4,
      "z": 1,
      "name": "Necrotic_Sand"
    },
    {
      "x": 3,
      "y": 5,
      "z": 1,
      "name": "Necrotic_Sand"
    },
    {
      "x": 3,
      "y": 6,
      "z": 1,
      "name": "Necrotic_Sand"
    },
    {
      "x": 3,
      "y": 7,
      "z": 1,
      "name": "Necrotic_Sand"
    },
    {
      "x": 3,
      "y": 8,
      "z": 1,
      "name": "Sword_Cemetery_1",
      "rotation": 1
    },
    {
      "x": 3,
      "y": 2,
      "z": 2,
      "name": "Necrotic_Sand"
    },
    {
      "x": 3,
      "y": 3,
      "z": 2,
      "name": "Necrotic_Sand"
    },
    {
      "x": 3,
      "y": 4,
      "z": 2,
      "name": "Necrotic_Sand"
    },
    {
      "x": 3,
      "y": 5,
      "z": 2,
      "name": "Necrotic_Sand"
    },
    {
      "x": 3,
      "y": 6,
      "z": 2,
      "name": "Necrotic_Sand"
    },
    {
      "x": 3,
      "y": 7,
      "z": 2,
      "name": "Necrotic_Sand"
    },
    {
      "x": 3,
      "y": 8,
      "z": 2,
      "name": "Plant_Bush_Dead_Tall",
      "support": 15
    },
    {
      "x": 3,
      "y": 1,
      "z": 3,
      "name": "Wood_Burnt_Roots"
    },
    {
      "x": 3,
      "y": 2,
      "z": 3,
      "name": "Necrotic_Sand"
    },
    {
      "x": 3,
      "y": 3,
      "z": 3,
      "name": "Necrotic_Sand"
    },
    {
      "x": 3,
      "y": 4,
      "z": 3,
      "name": "Necrotic_Sand"
    },
    {
      "x": 3,
      "y": 5,
      "z": 3,
      "name": "Necrotic_Sand"
    },
    {
      "x": 3,
      "y": 6,
      "z": 3,
      "name": "Necrotic_Sand"
    },
    {
      "x": 3,
      "y": 7,
      "z": 3,
      "name": "Dead_Branch"
    },
    {
      "x": 3,
      "y": 3,
      "z": 4,
      "name": "Necrotic_Sand"
    },
    {
      "x": 3,
      "y": 4,
      "z": 4,
      "name": "Necrotic_Sand"
    },
    {
      "x": 3,
      "y": 5,
      "z": 4,
      "name": "Necrotic_Sand"
    },
    {
      "x": 3,
      "y": 6,
      "z": 4,
      "name": "Necrotic_Sand"
    },
    {
      "x": 3,
      "y": 7,
      "z": 4,
      "name": "Sword_Cemetery_1"
    },
    {
      "x": 3,
      "y": 4,
      "z": 5,
      "name": "Necrotic_Sand"
    },
    {
      "x": 3,
      "y": 5,
      "z": 5,
      "name": "Necrotic_Sand"
    },
    {
      "x": 3,
      "y": 6,
      "z": 5,
      "name": "Necrotic_Sand"
    },
    {
      "x": 3,
      "y": 7,
      "z": 5,
      "name": "Plant_Bush_Winter",
      "support": 15
    },
    {
      "x": 3,
      "y": 5,
      "z": 6,
      "name": "Necrotic_Sand"
    },
    {
      "x": 3,
      "y": 6,
      "z": 6,
      "name": "Necrotic_Sand"
    },
    {
      "x": 3,
      "y": 7,
      "z": 6,
      "name": "Rubble_Slate",
      "support": 15
    },
    {
      "x": 4,
      "y": 5,
      "z": -4,
      "name": "Necrotic_Sand"
    },
    {
      "x": 4,
      "y": 6,
      "z": -4,
      "name": "Necrotic_Sand"
    },
    {
      "x": 4,
      "y": 4,
      "z": -3,
      "name": "Necrotic_Sand"
    },
    {
      "x": 4,
      "y": 5,
      "z": -3,
      "name": "Necrotic_Sand"
    },
    {
      "x": 4,
      "y": 6,
      "z": -3,
      "name": "Necrotic_Sand"
    },
    {
      "x": 4,
      "y": 7,
      "z": -3,
      "name": "Sword_Cemetery_3",
      "rotation": 2
    },
    {
      "x": 4,
      "y": 3,
      "z": -2,
      "name": "Necrotic_Sand"
    },
    {
      "x": 4,
      "y": 4,
      "z": -2,
      "name": "Necrotic_Sand"
    },
    {
      "x": 4,
      "y": 5,
      "z": -2,
      "name": "Necrotic_Sand"
    },
    {
      "x": 4,
      "y": 6,
      "z": -2,
      "name": "Empty"
    },
    {
      "x": 4,
      "y": 2,
      "z": -1,
      "name": "Necrotic_Sand"
    },
    {
      "x": 4,
      "y": 3,
      "z": -1,
      "name": "Necrotic_Sand"
    },
    {
      "x": 4,
      "y": 4,
      "z": -1,
      "name": "Necrotic_Sand"
    },
    {
      "x": 4,
      "y": 5,
      "z": -1,
      "name": "Necrotic_Sand"
    },
    {
      "x": 4,
      "y": 6,
      "z": -1,
      "name": "Empty"
    },
    {
      "x": 4,
      "y": 2,
      "z": 0,
      "name": "Necrotic_Sand"
    },
    {
      "x": 4,
      "y": 3,
      "z": 0,
      "name": "Necrotic_Sand"
    },
    {
      "x": 4,
      "y": 4,
      "z": 0,
      "name": "Necrotic_Sand"
    },
    {
      "x": 4,
      "y": 5,
      "z": 0,
      "name": "Necrotic_Sand"
    },
    {
      "x": 4,
      "y": 6,
      "z": 0,
      "name": "Empty"
    },
    {
      "x": 4,
      "y": 1,
      "z": 1,
      "name": "Wood_Burnt_Roots"
    },
    {
      "x": 4,
      "y": 2,
      "z": 1,
      "name": "Necrotic_Sand"
    },
    {
      "x": 4,
      "y": 3,
      "z": 1,
      "name": "Necrotic_Sand"
    },
    {
      "x": 4,
      "y": 4,
      "z": 1,
      "name": "Necrotic_Sand"
    },
    {
      "x": 4,
      "y": 5,
      "z": 1,
      "name": "Necrotic_Sand"
    },
    {
      "x": 4,
      "y": 6,
      "z": 1,
      "name": "Empty"
    },
    {
      "x": 4,
      "y": 3,
      "z": 2,
      "name": "Necrotic_Sand"
    },
    {
      "x": 4,
      "y": 4,
      "z": 2,
      "name": "Necrotic_Sand"
    },
    {
      "x": 4,
      "y": 5,
      "z": 2,
      "name": "Necrotic_Sand"
    },
    {
      "x": 4,
      "y": 6,
      "z": 2,
      "name": "Empty"
    },
    {
      "x": 4,
      "y": 3,
      "z": 3,
      "name": "Necrotic_Sand"
    },
    {
      "x": 4,
      "y": 4,
      "z": 3,
      "name": "Necrotic_Sand"
    },
    {
      "x": 4,
      "y": 5,
      "z": 3,
      "name": "Necrotic_Sand"
    },
    {
      "x": 4,
      "y": 6,
      "z": 3,
      "name": "Necrotic_Sand"
    },
    {
      "x": 4,
      "y": 7,
      "z": 3,
      "name": "Plant_Bush_Dead_Tall",
      "support": 15
    },
    {
      "x": 4,
      "y": 4,
      "z": 4,
      "name": "Necrotic_Sand"
    },
    {
      "x": 4,
      "y": 5,
      "z": 4,
      "name": "Necrotic_Sand"
    },
    {
      "x": 4,
      "y": 6,
      "z": 4,
      "name": "Necrotic_Sand"
    },
    {
      "x": 4,
      "y": 4,
      "z": 5,
      "name": "Wood_Burnt_Roots"
    },
    {
      "x": 4,
      "y": 5,
      "z": 5,
      "name": "Necrotic_Sand"
    },
    {
      "x": 4,
      "y": 6,
      "z": 5,
      "name": "Necrotic_Sand"
    },
    {
      "x": 5,
      "y": 5,
      "z": -3,
      "name": "Necrotic_Sand"
    },
    {
      "x": 5,
      "y": 6,
      "z": -3,
      "name": "Necrotic_Sand"
    },
    {
      "x": 5,
      "y": 4,
      "z": -2,
      "name": "Necrotic_Sand"
    },
    {
      "x": 5,
      "y": 5,
      "z": -2,
      "name": "Necrotic_Sand"
    },
    {
      "x": 5,
      "y": 6,
      "z": -2,
      "name": "Necrotic_Sand"
    },
    {
      "x": 5,
      "y": 7,
      "z": -2,
      "name": "Sword_Cemetery_2",
      "rotation": 1
    },
    {
      "x": 5,
      "y": 3,
      "z": -1,
      "name": "Necrotic_Sand"
    },
    {
      "x": 5,
      "y": 4,
      "z": -1,
      "name": "Necrotic_Sand"
    },
    {
      "x": 5,
      "y": 5,
      "z": -1,
      "name": "Necrotic_Sand"
    },
    {
      "x": 5,
      "y": 6,
      "z": -1,
      "name": "Necrotic_Sand"
    },
    {
      "x": 5,
      "y": 7,
      "z": -1,
      "name": "Plant_Bush_Winter",
      "support": 15
    },
    {
      "x": 5,
      "y": 3,
      "z": 0,
      "name": "Necrotic_Sand"
    },
    {
      "x": 5,
      "y": 4,
      "z": 0,
      "name": "Necrotic_Sand"
    },
    {
      "x": 5,
      "y": 5,
      "z": 0,
      "name": "Necrotic_Sand"
    },
    {
      "x": 5,
      "y": 6,
      "z": 0,
      "name": "Necrotic_Sand"
    },
    {
      "x": 5,
      "y": 7,
      "z": 0,
      "name": "Sword_Cemetery_3",
      "rotation": 1
    },
    {
      "x": 5,
      "y": 3,
      "z": 1,
      "name": "Necrotic_Sand"
    },
    {
      "x": 5,
      "y": 4,
      "z": 1,
      "name": "Necrotic_Sand"
    },
    {
      "x": 5,
      "y": 5,
      "z": 1,
      "name": "Necrotic_Sand"
    },
    {
      "x": 5,
      "y": 6,
      "z": 1,
      "name": "Necrotic_Sand"
    },
    {
      "x": 5,
      "y": 7,
      "z": 1,
      "name": "Plant_Bush_Winter",
      "support": 15
    },
    {
      "x": 5,
      "y": 4,
      "z": 2,
      "name": "Necrotic_Sand"
    },
    {
      "x": 5,
      "y": 5,
      "z": 2,
      "name": "Necrotic_Sand"
    },
    {
      "x": 5,
      "y": 6,
      "z": 2,
      "name": "Necrotic_Sand"
    },
    {
      "x": 5,
      "y": 7,
      "z": 2,
      "name": "Sword_Cemetery_2",
      "rotation": 1
    },
    {
      "x": 5,
      "y": 4,
      "z": 3,
      "name": "Necrotic_Sand"
    },
    {
      "x": 5,
      "y": 5,
      "z": 3,
      "name": "Necrotic_Sand"
    },
    {
      "x": 5,
      "y": 6,
      "z": 3,
      "name": "Necrotic_Sand"
    },
    {
      "x": 5,
      "y": 5,
      "z": 4,
      "name": "Necrotic_Sand"
    },
    {
      "x": 5,
      "y": 6,
      "z": 4,
      "name": "Necrotic_Sand"
    },
    {
      "x": 5,
      "y": 7,
      "z": 4,
      "name": "Rubble_Slate",
      "support": 15
    },
    {
      "x": 6,
      "y": 4,
      "z": -2,
      "name": "Wood_Burnt_Roots"
    },
    {
      "x": 6,
      "y": 5,
      "z": -2,
      "name": "Necrotic_Sand"
    },
    {
      "x": 6,
      "y": 6,
      "z": -2,
      "name": "Necrotic_Sand"
    },
    {
      "x": 6,
      "y": 4,
      "z": -1,
      "name": "Necrotic_Sand"
    },
    {
      "x": 6,
      "y": 5,
      "z": -1,
      "name": "Necrotic_Sand"
    },
    {
      "x": 6,
      "y": 6,
      "z": -1,
      "name": "Necrotic_Sand"
    },
    {
      "x": 6,
      "y": 4,
      "z": 0,
      "name": "Necrotic_Sand"
    },
    {
      "x": 6,
      "y": 5,
      "z": 0,
      "name": "Necrotic_Sand"
    },
    {
      "x": 6,
      "y": 6,
      "z": 0,
      "name": "Necrotic_Sand"
    },
    {
      "x": 6,
      "y": 3,
      "z": 1,
      "name": "Wood_Burnt_Roots"
    },
    {
      "x": 6,
      "y": 4,
      "z": 1,
      "name": "Necrotic_Sand"
    },
    {
      "x": 6,
      "y": 5,
      "z": 1,
      "name": "Necrotic_Sand"
    },
    {
      "x": 6,
      "y": 6,
      "z": 1,
      "name": "Necrotic_Sand"
    },
    {
      "x": 6,
      "y": 7,
      "z": 1,
      "name": "Rubble_Slate",
      "support": 15
    },
    {
      "x": 6,
      "y": 5,
      "z": 2,
      "name": "Necrotic_Sand"
    },
    {
      "x": 6,
      "y": 6,
      "z": 2,
      "name": "Necrotic_Sand"
    },
    {
      "x": 6,
      "y": 4,
      "z": 3,
      "name": "Wood_Burnt_Roots"
    },
    {
      "x": 6,
      "y": 5,
      "z": 3,
      "name": "Necrotic_Sand"
    },
    {
      "x": 6,
      "y": 6,
      "z": 3,
      "name": "Necrotic_Sand"
    },
    {
      "x": 7,
      "y": 5,
      "z": 0,
      "name": "Necrotic_Sand"
    },
    {
      "x": 7,
      "y": 6,
      "z": 0,
      "name": "Necrotic_Sand"
    },
    {
      "x": 7,
      "y": 5,
      "z": 1,
      "name": "Necrotic_Sand"
    },
    {
      "x": 7,
      "y": 6,
      "z": 1,
      "name": "Necrotic_Sand"
    }
  ],
  "fluids": [
    {
      "x": -4,
      "y": 6,
      "z": 0,
      "name": "Necrotic_Water_Source",
      "level": 1
    },
    {
      "x": -4,
      "y": 6,
      "z": 1,
      "name": "Necrotic_Water_Source",
      "level": 1
    },
    {
      "x": -4,
      "y": 6,
      "z": 2,
      "name": "Necrotic_Water_Source",
      "level": 1
    },
    {
      "x": -3,
      "y": 6,
      "z": -2,
      "name": "Necrotic_Water_Source",
      "level": 1
    },
    {
      "x": -3,
      "y": 6,
      "z": -1,
      "name": "Necrotic_Water",
      "level": 8
    },
    {
      "x": -3,
      "y": 6,
      "z": 0,
      "name": "Necrotic_Water_Source",
      "level": 1
    },
    {
      "x": -3,
      "y": 6,
      "z": 2,
      "name": "Necrotic_Water_Source",
      "level": 1
    },
    {
      "x": -3,
      "y": 6,
      "z": 3,
      "name": "Necrotic_Water_Source",
      "level": 1
    },
    {
      "x": -2,
      "y": 6,
      "z": -3,
      "name": "Necrotic_Water_Source",
      "level": 1
    },
    {
      "x": -2,
      "y": 6,
      "z": -2,
      "name": "Necrotic_Water_Source",
      "level": 1
    },
    {
      "x": -2,
      "y": 6,
      "z": 3,
      "name": "Necrotic_Water_Source",
      "level": 1
    },
    {
      "x": -1,
      "y": 6,
      "z": -3,
      "name": "Necrotic_Water_Source",
      "level": 1
    },
    {
      "x": -1,
      "y": 6,
      "z": 3,
      "name": "Necrotic_Water_Source",
      "level": 1
    },
    {
      "x": -1,
      "y": 6,
      "z": 4,
      "name": "Necrotic_Water_Source",
      "level": 1
    },
    {
      "x": 0,
      "y": 6,
      "z": -3,
      "name": "Necrotic_Water_Source",
      "level": 1
    },
    {
      "x": 0,
      "y": 6,
      "z": 4,
      "name": "Necrotic_Water_Source",
      "level": 1
    },
    {
      "x": 1,
      "y": 6,
      "z": -3,
      "name": "Necrotic_Water_Source",
      "level": 1
    },
    {
      "x": 1,
      "y": 6,
      "z": 4,
      "name": "Necrotic_Water_Source",
      "level": 1
    },
    {
      "x": 2,
      "y": 6,
      "z": -3,
      "name": "Necrotic_Water_Source",
      "level": 1
    },
    {
      "x": 2,
      "y": 6,
      "z": 4,
      "name": "Necrotic_Water_Source",
      "level": 1
    },
    {
      "x": 3,
      "y": 6,
      "z": -3,
      "name": "Necrotic_Water_Source",
      "level": 1
    },
    {
      "x": 3,
      "y": 6,
      "z": -2,
      "name": "Necrotic_Water_Source",
      "level": 1
    },
    {
      "x": 4,
      "y": 6,
      "z": -2,
      "name": "Necrotic_Water_Source",
      "level": 1
    },
    {
      "x": 4,
      "y": 6,
      "z": -1,
      "name": "Necrotic_Water_Source",
      "level": 1
    },
    {
      "x": 4,
      "y": 6,
      "z": 0,
      "name": "Necrotic_Water_Source",
      "level": 1
    },
    {
      "x": 4,
      "y": 6,
      "z": 1,
      "name": "Necrotic_Water_Source",
      "level": 1
    },
    {
      "x": 4,
      "y": 6,
      "z": 2,
      "name": "Necrotic_Water_Source",
      "level": 1
    }
  ]
}