{
  "version": 8,
  "blockIdVersion": 11,
  "anchorX": 15,
  "anchorY": 10,
  "anchorZ": 1,
  "blocks": [
    {
      "x": -15,
      "y": 7,
      "z": -11,
      "name": "Necrotic_Sand"
    },
    {
      "x": -15,
      "y": 7,
      "z": -10,
      "name": "Necrotic_Sand"
    },
    {
      "x": -15,
      "y": 8,
      "z": -10,
      "name": "Necrotic_Sand"
    },
    {
      "x": -15,
      "y": 6,
      "z": -9,
      "name": "Necrotic_Sand"
    },
    {
      "x": -15,
      "y": 7,
      "z": -9,
      "name": "Necrotic_Sand"
    },
    {
      "x": -15,
      "y": 8,
      "z": -9,
      "name": "Necrotic_Sand"
    },
    {
      "x": -15,
      "y": 6,
      "z": -8,
      "name": "Necrotic_Sand"
    },
    {
      "x": -15,
      "y": 7,
      "z": -8,
      "name": "Necrotic_Sand"
    },
    {
      "x": -15,
      "y": 8,
      "z": -8,
      "name": "Necrotic_Sand"
    },
    {
      "x": -15,
      "y": 5,
      "z": -7,
      "name": "Necrotic_Sand"
    },
    {
      "x": -15,
      "y": 6,
      "z": -7,
      "name": "Necrotic_Sand"
    },
    {
      "x": -15,
      "y": 7,
      "z": -7,
      "name": "Necrotic_Sand"
    },
    {
      "x": -15,
      "y": 8,
      "z": -7,
      "name": "Necrotic_Sand"
    },
    {
      "x": -15,
      "y": 6,
      "z": -6,
      "name": "Necrotic_Sand"
    },
    {
      "x": -15,
      "y": 7,
      "z": -6,
      "name": "Necrotic_Sand"
    },
    {
      "x": -15,
      "y": 8,
      "z": -6,
      "name": "Necrotic_Sand"
    },
    {
      "x": -15,
      "y": 6,
      "z": -5,
      "name": "Necrotic_Sand"
    },
    {
      "x": -15,
      "y": 7,
      "z": -5,
      "name": "Necrotic_Sand"
    },
    {
      "x": -15,
      "y": 8,
      "z": -5,
      "name": "Necrotic_Sand"
    },
    {
      "x": -15,
      "y": 5,
      "z": -4,
      "name": "Necrotic_Sand"
    },
    {
      "x": -15,
      "y": 6,
      "z": -4,
      "name": "Necrotic_Sand"
    },
    {
      "x": -15,
      "y": 7,
      "z": -4,
      "name": "Necrotic_Sand"
    },
    {
      "x": -15,
      "y": 8,
      "z": -4,
      "name": "Necrotic_Sand"
    },
    {
      "x": -15,
      "y": 6,
      "z": -3,
      "name": "Necrotic_Sand"
    },
    {
      "x": -15,
      "y": 7,
      "z": -3,
      "name": "Necrotic_Sand"
    },
    {
      "x": -15,
      "y": 8,
      "z": -3,
      "name": "Necrotic_Sand"
    },
    {
      "x": -15,
      "y": 6,
      "z": -2,
      "name": "Necrotic_Sand"
    },
    {
      "x": -15,
      "y": 7,
      "z": -2,
      "name": "Necrotic_Sand"
    },
    {
      "x": -15,
      "y": 8,
      "z": -2,
      "name": "Necrotic_Sand"
    },
    {
      "x": -15,
      "y": 6,
      "z": -1,
      "name": "Necrotic_Sand"
    },
    {
      "x": -15,
      "y": 7,
      "z": -1,
      "name": "Necrotic_Sand"
    },
    {
      "x": -15,
      "y": 8,
      "z": -1,
      "name": "Necrotic_Sand"
    },
    {
      "x": -15,
      "y": 6,
      "z": 0,
      "name": "Necrotic_Sand"
    },
    {
      "x": -15,
      "y": 7,
      "z": 0,
      "name": "Necrotic_Sand"
    },
    {
      "x": -15,
      "y": 8,
      "z": 0,
      "name": "Necrotic_Sand"
    },
    {
      "x": -15,
      "y": 5,
      "z": 1,
      "name": "Necrotic_Sand"
    },
    {
      "x": -15,
      "y": 6,
      "z": 1,
      "name": "Necrotic_Sand"
    },
    {
      "x": -15,
      "y": 7,
      "z": 1,
      "name": "Necrotic_Sand"
    },
    {
      "x": -15,
      "y": 8,
      "z": 1,
      "name": "Necrotic_Sand"
    },
    {
      "x": -15,
      "y": 9,
      "z": 1,
      "name": "Necrotic_Sand"
    },
    {
      "x": -15,
      "y": 6,
      "z": 2,
      "name": "Necrotic_Sand"
    },
    {
      "x": -15,
      "y": 7,
      "z": 2,
      "name": "Necrotic_Sand"
    },
    {
      "x": -15,
      "y": 8,
      "z": 2,
      "name": "Necrotic_Sand"
    },
    {
      "x": -15,
      "y": 9,
      "z": 2,
      "name": "Necrotic_Sand"
    },
    {
      "x": -15,
      "y": 6,
      "z": 3,
      "name": "Necrotic_Sand"
    },
    {
      "x": -15,
      "y": 7,
      "z": 3,
      "name": "Necrotic_Sand"
    },
    {
      "x": -15,
      "y": 8,
      "z": 3,
      "name": "Necrotic_Sand"
    },
    {
      "x": -15,
      "y": 9,
      "z": 3,
      "name": "Necrotic_Sand"
    },
    {
      "x": -15,
      "y": 6,
      "z": 4,
      "name": "Necrotic_Sand"
    },
    {
      "x": -15,
      "y": 7,
      "z": 4,
      "name": "Necrotic_Sand"
    },
    {
      "x": -15,
      "y": 8,
      "z": 4,
      "name": "Necrotic_Sand"
    },
    {
      "x": -15,
      "y": 9,
      "z": 4,
      "name": "Necrotic_Sand"
    },
    {
      "x": -15,
      "y": 6,
      "z": 5,
      "name": "Necrotic_Sand"
    },
    {
      "x": -15,
      "y": 7,
      "z": 5,
      "name": "Necrotic_Sand"
    },
    {
      "x": -15,
      "y": 8,
      "z": 5,
      "name": "Necrotic_Sand"
    },
    {
      "x": -15,
      "y": 9,
      "z": 5,
      "name": "Necrotic_Sand"
    },
    {
      "x": -15,
      "y": 7,
      "z": 6,
      "name": "Necrotic_Sand"
    },
    {
      "x": -15,
      "y": 8,
      "z": 6,
      "name": "Necrotic_Sand"
    },
    {
      "x": -15,
      "y": 9,
      "z": 6,
      "name": "Necrotic_Sand"
    },
    {
      "x": -15,
      "y": 7,
      "z": 7,
      "name": "Necrotic_Sand"
    },
    {
      "x": -15,
      "y": 8,
      "z": 7,
      "name": "Necrotic_Sand"
    },
    {
      "x": -14,
      "y": 7,
      "z": -15,
      "name": "Necrotic_Sand"
    },
    {
      "x": -14,
      "y": 8,
      "z": -15,
      "name": "Necrotic_Sand"
    },
    {
      "x": -14,
      "y": 6,
      "z": -14,
      "name": "Necrotic_Sand"
    },
    {
      "x": -14,
      "y": 7,
      "z": -14,
      "name": "Necrotic_Sand"
    },
    {
      "x": -14,
      "y": 8,
      "z": -14,
      "name": "Necrotic_Sand"
    },
    {
      "x": -14,
      "y": 9,
      "z": -14,
      "name": "Necrotic_Sand"
    },
    {
      "x": -14,
      "y": 6,
      "z": -13,
      "name": "Necrotic_Sand"
    },
    {
      "x": -14,
      "y": 7,
      "z": -13,
      "name": "Necrotic_Sand"
    },
    {
      "x": -14,
      "y": 8,
      "z": -13,
      "name": "Necrotic_Sand"
    },
    {
      "x": -14,
      "y": 9,
      "z": -13,
      "name": "Necrotic_Sand"
    },
    {
      "x": -14,
      "y": 5,
      "z": -12,
      "name": "Necrotic_Sand"
    },
    {
      "x": -14,
      "y": 6,
      "z": -12,
      "name": "Necrotic_Sand"
    },
    {
      "x": -14,
      "y": 7,
      "z": -12,
      "name": "Necrotic_Sand"
    },
    {
      "x": -14,
      "y": 8,
      "z": -12,
      "name": "Necrotic_Sand"
    },
    {
      "x": -14,
      "y": 9,
      "z": -12,
      "name": "Necrotic_Sand"
    },
    {
      "x": -14,
      "y": 10,
      "z": -12,
      "name": "Necrotic_Sand"
    },
    {
      "x": -14,
      "y": 5,
      "z": -11,
      "name": "Necrotic_Sand"
    },
    {
      "x": -14,
      "y": 6,
      "z": -11,
      "name": "Necrotic_Sand"
    },
    {
      "x": -14,
      "y": 7,
      "z": -11,
      "name": "Necrotic_Sand"
    },
    {
      "x": -14,
      "y": 8,
      "z": -11,
      "name": "Necrotic_Sand"
    },
    {
      "x": -14,
      "y": 9,
      "z": -11,
      "name": "Necrotic_Sand"
    },
    {
      "x": -14,
      "y": 10,
      "z": -11,
      "name": "Necrotic_Sand"
    },
    {
      "x": -14,
      "y": 5,
      "z": -10,
      "name": "Necrotic_Sand"
    },
    {
      "x": -14,
      "y": 6,
      "z": -10,
      "name": "Necrotic_Sand"
    },
    {
      "x": -14,
      "y": 7,
      "z": -10,
      "name": "Necrotic_Sand"
    },
    {
      "x": -14,
      "y": 8,
      "z": -10,
      "name": "Necrotic_Sand"
    },
    {
      "x": -14,
      "y": 9,
      "z": -10,
      "name": "Necrotic_Sand"
    },
    {
      "x": -14,
      "y": 10,
      "z": -10,
      "name": "Necrotic_Sand"
    },
    {
      "x": -14,
      "y": 4,
      "z": -9,
      "name": "Necrotic_Sand"
    },
    {
      "x": -14,
      "y": 5,
      "z": -9,
      "name": "Necrotic_Sand"
    },
    {
      "x": -14,
      "y": 6,
      "z": -9,
      "name": "Necrotic_Sand"
    },
    {
      "x": -14,
      "y": 7,
      "z": -9,
      "name": "Necrotic_Sand"
    },
    {
      "x": -14,
      "y": 8,
      "z": -9,
      "name": "Necrotic_Sand"
    },
    {
      "x": -14,
      "y": 9,
      "z": -9,
      "name": "Necrotic_Sand"
    },
    {
      "x": -14,
      "y": 10,
      "z": -9,
      "name": "Necrotic_Sand"
    },
    {
      "x": -14,
      "y": 11,
      "z": -9,
      "name": "Necrotic_Sand"
    },
    {
      "x": -14,
      "y": 4,
      "z": -8,
      "name": "Necrotic_Sand"
    },
    {
      "x": -14,
      "y": 5,
      "z": -8,
      "name": "Necrotic_Sand"
    },
    {
      "x": -14,
      "y": 6,
      "z": -8,
      "name": "Necrotic_Sand"
    },
    {
      "x": -14,
      "y": 7,
      "z": -8,
      "name": "Necrotic_Sand"
    },
    {
      "x": -14,
      "y": 8,
      "z": -8,
      "name": "Necrotic_Sand"
    },
    {
      "x": -14,
      "y": 9,
      "z": -8,
      "name": "Necrotic_Sand"
    },
    {
      "x": -14,
      "y": 10,
      "z": -8,
      "name": "Necrotic_Sand"
    },
    {
      "x": -14,
      "y": 11,
      "z": -8,
      "name": "Necrotic_Sand"
    },
    {
      "x": -14,
      "y": 12,
      "z": -8,
      "name": "Necrotic_Grass"
    },
    {
      "x": -14,
      "y": 4,
      "z": -7,
      "name": "Necrotic_Sand"
    },
    {
      "x": -14,
      "y": 5,
      "z": -7,
      "name": "Necrotic_Sand"
    },
    {
      "x": -14,
      "y": 6,
      "z": -7,
      "name": "Necrotic_Sand"
    },
    {
      "x": -14,
      "y": 7,
      "z": -7,
      "name": "Necrotic_Sand"
    },
    {
      "x": -14,
      "y": 8,
      "z": -7,
      "name": "Necrotic_Sand"
    },
    {
      "x": -14,
      "y": 9,
      "z": -7,
      "name": "Necrotic_Sand"
    },
    {
      "x": -14,
      "y": 10,
      "z": -7,
      "name": "Necrotic_Sand"
    },
    {
      "x": -14,
      "y": 11,
      "z": -7,
      "name": "Necrotic_Grass"
    },
    {
      "x": -14,
      "y": 4,
      "z": -6,
      "name": "Necrotic_Sand"
    },
    {
      "x": -14,
      "y": 5,
      "z": -6,
      "name": "Necrotic_Sand"
    },
    {
      "x": -14,
      "y": 6,
      "z": -6,
      "name": "Necrotic_Sand"
    },
    {
      "x": -14,
      "y": 7,
      "z": -6,
      "name": "Necrotic_Sand"
    },
    {
      "x": -14,
      "y": 8,
      "z": -6,
      "name": "Necrotic_Sand"
    },
    {
      "x": -14,
      "y": 9,
      "z": -6,
      "name": "Necrotic_Sand"
    },
    {
      "x": -14,
      "y": 10,
      "z": -6,
      "name": "Necrotic_Sand"
    },
    {
      "x": -14,
      "y": 4,
      "z": -5,
      "name": "Necrotic_Sand"
    },
    {
      "x": -14,
      "y": 5,
      "z": -5,
      "name": "Necrotic_Sand"
    },
    {
      "x": -14,
      "y": 6,
      "z": -5,
      "name": "Necrotic_Sand"
    },
    {
      "x": -14,
      "y": 7,
      "z": -5,
      "name": "Necrotic_Sand"
    },
    {
      "x": -14,
      "y": 8,
      "z": -5,
      "name": "Necrotic_Sand"
    },
    {
      "x": -14,
      "y": 9,
      "z": -5,
      "name": "Necrotic_Sand"
    },
    {
      "x": -14,
      "y": 10,
      "z": -5,
      "name": "Necrotic_Sand"
    },
    {
      "x": -14,
      "y": 4,
      "z": -4,
      "name": "Necrotic_Sand"
    },
    {
      "x": -14,
      "y": 5,
      "z": -4,
      "name": "Necrotic_Sand"
    },
    {
      "x": -14,
      "y": 6,
      "z": -4,
      "name": "Necrotic_Sand"
    },
    {
      "x": -14,
      "y": 7,
      "z": -4,
      "name": "Necrotic_Sand"
    },
    {
      "x": -14,
      "y": 8,
      "z": -4,
      "name": "Necrotic_Sand"
    },
    {
      "x": -14,
      "y": 9,
      "z": -4,
      "name": "Necrotic_Sand"
    },
    {
      "x": -14,
      "y": 10,
      "z": -4,
      "name": "Necrotic_Sand"
    },
    {
      "x": -14,
      "y": 15,
      "z": -4,
      "name": "Plant_Vine_Wall_Poisoned",
      "support": 15,
      "rotation": 3
    },
    {
      "x": -14,
      "y": 4,
      "z": -3,
      "name": "Necrotic_Sand"
    },
    {
      "x": -14,
      "y": 5,
      "z": -3,
      "name": "Necrotic_Sand"
    },
    {
      "x": -14,
      "y": 6,
      "z": -3,
      "name": "Necrotic_Sand"
    },
    {
      "x": -14,
      "y": 7,
      "z": -3,
      "name": "Necrotic_Sand"
    },
    {
      "x": -14,
      "y": 8,
      "z": -3,
      "name": "Necrotic_Sand"
    },
    {
      "x": -14,
      "y": 9,
      "z": -3,
      "name": "Necrotic_Sand"
    },
    {
      "x": -14,
      "y": 10,
      "z": -3,
      "name": "Necrotic_Sand"
    },
    {
      "x": -14,
      "y": 15,
      "z": -3,
      "name": "Plant_Vine_Wall_Poisoned",
      "support": 15,
      "rotation": 3
    },
    {
      "x": -14,
      "y": 17,
      "z": -3,
      "name": "Plant_Vine_Wall_Poisoned",
      "support": 15,
      "rotation": 3
    },
    {
      "x": -14,
      "y": 5,
      "z": -2,
      "name": "Necrotic_Sand"
    },
    {
      "x": -14,
      "y": 6,
      "z": -2,
      "name": "Necrotic_Sand"
    },
    {
      "x": -14,
      "y": 7,
      "z": -2,
      "name": "Necrotic_Sand"
    },
    {
      "x": -14,
      "y": 8,
      "z": -2,
      "name": "Necrotic_Sand"
    },
    {
      "x": -14,
      "y": 9,
      "z": -2,
      "name": "Necrotic_Sand"
    },
    {
      "x": -14,
      "y": 10,
      "z": -2,
      "name": "Necrotic_Sand"
    },
    {
      "x": -14,
      "y": 17,
      "z": -2,
      "name": "Plant_Vine_Wall_Poisoned",
      "support": 15,
      "rotation": 3
    },
    {
      "x": -14,
      "y": 18,
      "z": -2,
      "name": "Plant_Vine_Wall_Poisoned",
      "support": 15,
      "rotation": 3
    },
    {
      "x": -14,
      "y": 5,
      "z": -1,
      "name": "Necrotic_Sand"
    },
    {
      "x": -14,
      "y": 6,
      "z": -1,
      "name": "Necrotic_Sand"
    },
    {
      "x": -14,
      "y": 7,
      "z": -1,
      "name": "Necrotic_Sand"
    },
    {
      "x": -14,
      "y": 8,
      "z": -1,
      "name": "Necrotic_Sand"
    },
    {
      "x": -14,
      "y": 9,
      "z": -1,
      "name": "Necrotic_Sand"
    },
    {
      "x": -14,
      "y": 10,
      "z": -1,
      "name": "Necrotic_Sand"
    },
    {
      "x": -14,
      "y": 15,
      "z": -1,
      "name": "Plant_Vine_Wall_Poisoned",
      "support": 15,
      "rotation": 3
    },
    {
      "x": -14,
      "y": 18,
      "z": -1,
      "name": "Plant_Vine_Wall_Poisoned",
      "support": 15,
      "rotation": 3
    },
    {
      "x": -14,
      "y": 5,
      "z": 0,
      "name": "Necrotic_Sand"
    },
    {
      "x": -14,
      "y": 6,
      "z": 0,
      "name": "Necrotic_Sand"
    },
    {
      "x": -14,
      "y": 7,
      "z": 0,
      "name": "Necrotic_Sand"
    },
    {
      "x": -14,
      "y": 8,
      "z": 0,
      "name": "Necrotic_Sand"
    },
    {
      "x": -14,
      "y": 9,
      "z": 0,
      "name": "Necrotic_Sand"
    },
    {
      "x": -14,
      "y": 10,
      "z": 0,
      "name": "Necrotic_Sand"
    },
    {
      "x": -14,
      "y": 17,
      "z": 0,
      "name": "Plant_Vine_Wall_Poisoned",
      "support": 15,
      "rotation": 3
    },
    {
      "x": -14,
      "y": 5,
      "z": 1,
      "name": "Necrotic_Sand"
    },
    {
      "x": -14,
      "y": 6,
      "z": 1,
      "name": "Necrotic_Sand"
    },
    {
      "x": -14,
      "y": 7,
      "z": 1,
      "name": "Necrotic_Sand"
    },
    {
      "x": -14,
      "y": 8,
      "z": 1,
      "name": "Necrotic_Sand"
    },
    {
      "x": -14,
      "y": 9,
      "z": 1,
      "name": "Necrotic_Sand"
    },
    {
      "x": -14,
      "y": 10,
      "z": 1,
      "name": "Necrotic_Sand"
    },
    {
      "x": -14,
      "y": 11,
      "z": 1,
      "name": "Necrotic_Sand"
    },
    {
      "x": -14,
      "y": 5,
      "z": 2,
      "name": "Necrotic_Sand"
    },
    {
      "x": -14,
      "y": 6,
      "z": 2,
      "name": "Necrotic_Sand"
    },
    {
      "x": -14,
      "y": 7,
      "z": 2,
      "name": "Necrotic_Sand"
    },
    {
      "x": -14,
      "y": 8,
      "z": 2,
      "name": "Necrotic_Sand"
    },
    {
      "x": -14,
      "y": 9,
      "z": 2,
      "name": "Necrotic_Sand"
    },
    {
      "x": -14,
      "y": 10,
      "z": 2,
      "name": "Necrotic_Sand"
    },
    {
      "x": -14,
      "y": 11,
      "z": 2,
      "name": "Necrotic_Mud"
    },
    {
      "x": -14,
      "y": 5,
      "z": 3,
      "name": "Necrotic_Sand"
    },
    {
      "x": -14,
      "y": 6,
      "z": 3,
      "name": "Necrotic_Sand"
    },
    {
      "x": -14,
      "y": 7,
      "z": 3,
      "name": "Necrotic_Sand"
    },
    {
      "x": -14,
      "y": 8,
      "z": 3,
      "name": "Necrotic_Sand"
    },
    {
      "x": -14,
      "y": 9,
      "z": 3,
      "name": "Necrotic_Sand"
    },
    {
      "x": -14,
      "y": 10,
      "z": 3,
      "name": "Necrotic_Sand"
    },
    {
      "x": -14,
      "y": 11,
      "z": 3,
      "name": "Necrotic_Mud"
    },
    {
      "x": -14,
      "y": 5,
      "z": 4,
      "name": "Necrotic_Sand"
    },
    {
      "x": -14,
      "y": 6,
      "z": 4,
      "name": "Necrotic_Sand"
    },
    {
      "x": -14,
      "y": 7,
      "z": 4,
      "name": "Necrotic_Sand"
    },
    {
      "x": -14,
      "y": 8,
      "z": 4,
      "name": "Necrotic_Sand"
    },
    {
      "x": -14,
      "y": 9,
      "z": 4,
      "name": "Necrotic_Sand"
    },
    {
      "x": -14,
      "y": 10,
      "z": 4,
      "name": "Necrotic_Sand"
    },
    {
      "x": -14,
      "y": 11,
      "z": 4,
      "name": "Necrotic_Mud"
    },
    {
      "x": -14,
      "y": 5,
      "z": 5,
      "name": "Necrotic_Sand"
    },
    {
      "x": -14,
      "y": 6,
      "z": 5,
      "name": "Necrotic_Sand"
    },
    {
      "x": -14,
      "y": 7,
      "z": 5,
      "name": "Necrotic_Sand"
    },
    {
      "x": -14,
      "y": 8,
      "z": 5,
      "name": "Necrotic_Sand"
    },
    {
      "x": -14,
      "y": 9,
      "z": 5,
      "name": "Necrotic_Sand"
    },
    {
      "x": -14,
      "y": 10,
      "z": 5,
      "name": "Necrotic_Sand"
    },
    {
      "x": -14,
      "y": 11,
      "z": 5,
      "name": "Necrotic_Stone"
    },
    {
      "x": -14,
      "y": 5,
      "z": 6,
      "name": "Necrotic_Sand"
    },
    {
      "x": -14,
      "y": 6,
      "z": 6,
      "name": "Necrotic_Sand"
    },
    {
      "x": -14,
      "y": 7,
      "z": 6,
      "name": "Necrotic_Sand"
    },
    {
      "x": -14,
      "y": 8,
      "z": 6,
      "name": "Necrotic_Sand"
    },
    {
      "x": -14,
      "y": 9,
      "z": 6,
      "name": "Necrotic_Sand"
    },
    {
      "x": -14,
      "y": 10,
      "z": 6,
      "name": "Necrotic_Sand"
    },
    {
      "x": -14,
      "y": 11,
      "z": 6,
      "name": "Necrotic_Stone"
    },
    {
      "x": -14,
      "y": 5,
      "z": 7,
      "name": "Necrotic_Sand"
    },
    {
      "x": -14,
      "y": 6,
      "z": 7,
      "name": "Necrotic_Sand"
    },
    {
      "x": -14,
      "y": 7,
      "z": 7,
      "name": "Necrotic_Sand"
    },
    {
      "x": -14,
      "y": 8,
      "z": 7,
      "name": "Necrotic_Sand"
    },
    {
      "x": -14,
      "y": 9,
      "z": 7,
      "name": "Necrotic_Sand"
    },
    {
      "x": -14,
      "y": 10,
      "z": 7,
      "name": "Necrotic_Sand"
    },
    {
      "x": -14,
      "y": 11,
      "z": 7,
      "name": "Necrotic_Mud"
    },
    {
      "x": -14,
      "y": 6,
      "z": 8,
      "name": "Necrotic_Sand"
    },
    {
      "x": -14,
      "y": 7,
      "z": 8,
      "name": "Necrotic_Sand"
    },
    {
      "x": -14,
      "y": 8,
      "z": 8,
      "name": "Necrotic_Sand"
    },
    {
      "x": -14,
      "y": 9,
      "z": 8,
      "name": "Necrotic_Sand"
    },
    {
      "x": -14,
      "y": 10,
      "z": 8,
      "name": "Necrotic_Sand"
    },
    {
      "x": -14,
      "y": 11,
      "z": 8,
      "name": "Necrotic_Mud"
    },
    {
      "x": -14,
      "y": 6,
      "z": 9,
      "name": "Necrotic_Sand"
    },
    {
      "x": -14,
      "y": 7,
      "z": 9,
      "name": "Necrotic_Sand"
    },
    {
      "x": -14,
      "y": 8,
      "z": 9,
      "name": "Necrotic_Sand"
    },
    {
      "x": -14,
      "y": 9,
      "z": 9,
      "name": "Necrotic_Sand"
    },
    {
      "x": -14,
      "y": 10,
      "z": 9,
      "name": "Necrotic_Sand"
    },
    {
      "x": -14,
      "y": 6,
      "z": 10,
      "name": "Necrotic_Sand"
    },
    {
      "x": -14,
      "y": 7,
      "z": 10,
      "name": "Necrotic_Sand"
    },
    {
      "x": -14,
      "y": 8,
      "z": 10,
      "name": "Necrotic_Sand"
    },
    {
      "x": -14,
      "y": 9,
      "z": 10,
      "name": "Necrotic_Sand"
    },
    {
      "x": -14,
      "y": 10,
      "z": 10,
      "name": "Necrotic_Sand"
    },
    {
      "x": -14,
      "y": 7,
      "z": 11,
      "name": "Necrotic_Sand"
    },
    {
      "x": -14,
      "y": 8,
      "z": 11,
      "name": "Necrotic_Sand"
    },
    {
      "x": -14,
      "y": 9,
      "z": 11,
      "name": "Necrotic_Sand"
    },
    {
      "x": -14,
      "y": 10,
      "z": 11,
      "name": "Necrotic_Sand"
    },
    {
      "x": -14,
      "y": 7,
      "z": 12,
      "name": "Necrotic_Sand"
    },
    {
      "x": -14,
      "y": 8,
      "z": 12,
      "name": "Necrotic_Sand"
    },
    {
      "x": -14,
      "y": 9,
      "z": 12,
      "name": "Necrotic_Sand"
    },
    {
      "x": -14,
      "y": 7,
      "z": 13,
      "name": "Necrotic_Sand"
    },
    {
      "x": -14,
      "y": 8,
      "z": 13,
      "name": "Necrotic_Sand"
    },
    {
      "x": -14,
      "y": 9,
      "z": 13,
      "name": "Necrotic_Sand"
    },
    {
      "x": -13,
      "y": 8,
      "z": -17,
      "name": "Necrotic_Sand"
    },
    {
      "x": -13,
      "y": 6,
      "z": -16,
      "name": "Necrotic_Sand"
    },
    {
      "x": -13,
      "y": 7,
      "z": -16,
      "name": "Necrotic_Sand"
    },
    {
      "x": -13,
      "y": 8,
      "z": -16,
      "name": "Necrotic_Sand"
    },
    {
      "x": -13,
      "y": 9,
      "z": -16,
      "name": "Necrotic_Sand"
    },
    {
      "x": -13,
      "y": 5,
      "z": -15,
      "name": "Necrotic_Sand"
    },
    {
      "x": -13,
      "y": 6,
      "z": -15,
      "name": "Necrotic_Sand"
    },
    {
      "x": -13,
      "y": 7,
      "z": -15,
      "name": "Necrotic_Sand"
    },
    {
      "x": -13,
      "y": 8,
      "z": -15,
      "name": "Necrotic_Sand"
    },
    {
      "x": -13,
      "y": 9,
      "z": -15,
      "name": "Necrotic_Sand"
    },
    {
      "x": -13,
      "y": 10,
      "z": -15,
      "name": "Necrotic_Sand"
    },
    {
      "x": -13,
      "y": 11,
      "z": -15,
      "name": "Necrotic_Sand"
    },
    {
      "x": -13,
      "y": 5,
      "z": -14,
      "name": "Necrotic_Sand"
    },
    {
      "x": -13,
      "y": 6,
      "z": -14,
      "name": "Necrotic_Sand"
    },
    {
      "x": -13,
      "y": 7,
      "z": -14,
      "name": "Necrotic_Sand"
    },
    {
      "x": -13,
      "y": 8,
      "z": -14,
      "name": "Necrotic_Sand"
    },
    {
      "x": -13,
      "y": 9,
      "z": -14,
      "name": "Necrotic_Sand"
    },
    {
      "x": -13,
      "y": 10,
      "z": -14,
      "name": "Necrotic_Sand"
    },
    {
      "x": -13,
      "y": 11,
      "z": -14,
      "name": "Necrotic_Sand"
    },
    {
      "x": -13,
      "y": 5,
      "z": -13,
      "name": "Necrotic_Sand"
    },
    {
      "x": -13,
      "y": 6,
      "z": -13,
      "name": "Necrotic_Sand"
    },
    {
      "x": -13,
      "y": 7,
      "z": -13,
      "name": "Necrotic_Sand"
    },
    {
      "x": -13,
      "y": 8,
      "z": -13,
      "name": "Necrotic_Sand"
    },
    {
      "x": -13,
      "y": 9,
      "z": -13,
      "name": "Necrotic_Sand"
    },
    {
      "x": -13,
      "y": 10,
      "z": -13,
      "name": "Necrotic_Sand"
    },
    {
      "x": -13,
      "y": 11,
      "z": -13,
      "name": "Necrotic_Sand"
    },
    {
      "x": -13,
      "y": 5,
      "z": -12,
      "name": "Necrotic_Sand"
    },
    {
      "x": -13,
      "y": 6,
      "z": -12,
      "name": "Necrotic_Sand"
    },
    {
      "x": -13,
      "y": 7,
      "z": -12,
      "name": "Necrotic_Sand"
    },
    {
      "x": -13,
      "y": 8,
      "z": -12,
      "name": "Necrotic_Sand"
    },
    {
      "x": -13,
      "y": 9,
      "z": -12,
      "name": "Necrotic_Sand"
    },
    {
      "x": -13,
      "y": 10,
      "z": -12,
      "name": "Necrotic_Sand"
    },
    {
      "x": -13,
      "y": 11,
      "z": -12,
      "name": "Necrotic_Sand"
    },
    {
      "x": -13,
      "y": 12,
      "z": -12,
      "name": "Necrotic_Sand"
    },
    {
      "x": -13,
      "y": 5,
      "z": -11,
      "name": "Necrotic_Sand"
    },
    {
      "x": -13,
      "y": 6,
      "z": -11,
      "name": "Necrotic_Sand"
    },
    {
      "x": -13,
      "y": 7,
      "z": -11,
      "name": "Necrotic_Sand"
    },
    {
      "x": -13,
      "y": 8,
      "z": -11,
      "name": "Necrotic_Sand"
    },
    {
      "x": -13,
      "y": 9,
      "z": -11,
      "name": "Necrotic_Sand"
    },
    {
      "x": -13,
      "y": 10,
      "z": -11,
      "name": "Necrotic_Sand"
    },
    {
      "x": -13,
      "y": 11,
      "z": -11,
      "name": "Necrotic_Sand"
    },
    {
      "x": -13,
      "y": 12,
      "z": -11,
      "name": "Necrotic_Sand"
    },
    {
      "x": -13,
      "y": 3,
      "z": -10,
      "name": "Necrotic_Sand"
    },
    {
      "x": -13,
      "y": 4,
      "z": -10,
      "name": "Necrotic_Sand"
    },
    {
      "x": -13,
      "y": 5,
      "z": -10,
      "name": "Necrotic_Sand"
    },
    {
      "x": -13,
      "y": 6,
      "z": -10,
      "name": "Necrotic_Sand"
    },
    {
      "x": -13,
      "y": 7,
      "z": -10,
      "name": "Necrotic_Sand"
    },
    {
      "x": -13,
      "y": 8,
      "z": -10,
      "name": "Necrotic_Sand"
    },
    {
      "x": -13,
      "y": 9,
      "z": -10,
      "name": "Necrotic_Sand"
    },
    {
      "x": -13,
      "y": 10,
      "z": -10,
      "name": "Necrotic_Sand"
    },
    {
      "x": -13,
      "y": 11,
      "z": -10,
      "name": "Necrotic_Sand"
    },
    {
      "x": -13,
      "y": 12,
      "z": -10,
      "name": "Necrotic_Sand"
    },
    {
      "x": -13,
      "y": 3,
      "z": -9,
      "name": "Necrotic_Sand"
    },
    {
      "x": -13,
      "y": 4,
      "z": -9,
      "name": "Necrotic_Sand"
    },
    {
      "x": -13,
      "y": 5,
      "z": -9,
      "name": "Necrotic_Sand"
    },
    {
      "x": -13,
      "y": 6,
      "z": -9,
      "name": "Necrotic_Sand"
    },
    {
      "x": -13,
      "y": 7,
      "z": -9,
      "name": "Necrotic_Sand"
    },
    {
      "x": -13,
      "y": 8,
      "z": -9,
      "name": "Necrotic_Sand"
    },
    {
      "x": -13,
      "y": 9,
      "z": -9,
      "name": "Necrotic_Sand"
    },
    {
      "x": -13,
      "y": 10,
      "z": -9,
      "name": "Necrotic_Sand"
    },
    {
      "x": -13,
      "y": 11,
      "z": -9,
      "name": "Necrotic_Sand"
    },
    {
      "x": -13,
      "y": 12,
      "z": -9,
      "name": "Necrotic_Sand"
    },
    {
      "x": -13,
      "y": 3,
      "z": -8,
      "name": "Necrotic_Sand"
    },
    {
      "x": -13,
      "y": 4,
      "z": -8,
      "name": "Necrotic_Sand"
    },
    {
      "x": -13,
      "y": 5,
      "z": -8,
      "name": "Necrotic_Sand"
    },
    {
      "x": -13,
      "y": 6,
      "z": -8,
      "name": "Necrotic_Sand"
    },
    {
      "x": -13,
      "y": 7,
      "z": -8,
      "name": "Necrotic_Sand"
    },
    {
      "x": -13,
      "y": 8,
      "z": -8,
      "name": "Necrotic_Sand"
    },
    {
      "x": -13,
      "y": 9,
      "z": -8,
      "name": "Necrotic_Sand"
    },
    {
      "x": -13,
      "y": 10,
      "z": -8,
      "name": "Necrotic_Sand"
    },
    {
      "x": -13,
      "y": 11,
      "z": -8,
      "name": "Necrotic_Sand"
    },
    {
      "x": -13,
      "y": 12,
      "z": -8,
      "name": "Necrotic_Sand"
    },
    {
      "x": -13,
      "y": 3,
      "z": -7,
      "name": "Necrotic_Sand"
    },
    {
      "x": -13,
      "y": 4,
      "z": -7,
      "name": "Necrotic_Sand"
    },
    {
      "x": -13,
      "y": 5,
      "z": -7,
      "name": "Necrotic_Sand"
    },
    {
      "x": -13,
      "y": 6,
      "z": -7,
      "name": "Necrotic_Sand"
    },
    {
      "x": -13,
      "y": 7,
      "z": -7,
      "name": "Necrotic_Sand"
    },
    {
      "x": -13,
      "y": 8,
      "z": -7,
      "name": "Necrotic_Sand"
    },
    {
      "x": -13,
      "y": 9,
      "z": -7,
      "name": "Necrotic_Sand"
    },
    {
      "x": -13,
      "y": 10,
      "z": -7,
      "name": "Necrotic_Sand"
    },
    {
      "x": -13,
      "y": 11,
      "z": -7,
      "name": "Necrotic_Sand"
    },
    {
      "x": -13,
      "y": 12,
      "z": -7,
      "name": "Necrotic_Sand"
    },
    {
      "x": -13,
      "y": 3,
      "z": -6,
      "name": "Necrotic_Sand"
    },
    {
      "x": -13,
      "y": 4,
      "z": -6,
      "name": "Necrotic_Sand"
    },
    {
      "x": -13,
      "y": 5,
      "z": -6,
      "name": "Necrotic_Sand"
    },
    {
      "x": -13,
      "y": 6,
      "z": -6,
      "name": "Necrotic_Sand"
    },
    {
      "x": -13,
      "y": 7,
      "z": -6,
      "name": "Necrotic_Sand"
    },
    {
      "x": -13,
      "y": 8,
      "z": -6,
      "name": "Necrotic_Sand"
    },
    {
      "x": -13,
      "y": 9,
      "z": -6,
      "name": "Necrotic_Sand"
    },
    {
      "x": -13,
      "y": 10,
      "z": -6,
      "name": "Necrotic_Sand"
    },
    {
      "x": -13,
      "y": 11,
      "z": -6,
      "name": "Necrotic_Sand"
    },
    {
      "x": -13,
      "y": 12,
      "z": -6,
      "name": "Necrotic_Sand"
    },
    {
      "x": -13,
      "y": 15,
      "z": -6,
      "name": "Plant_Vine_Wall_Poisoned",
      "support": 15,
      "rotation": 3
    },
    {
      "x": -13,
      "y": 3,
      "z": -5,
      "name": "Necrotic_Sand"
    },
    {
      "x": -13,
      "y": 4,
      "z": -5,
      "name": "Necrotic_Sand"
    },
    {
      "x": -13,
      "y": 5,
      "z": -5,
      "name": "Necrotic_Sand"
    },
    {
      "x": -13,
      "y": 6,
      "z": -5,
      "name": "Necrotic_Sand"
    },
    {
      "x": -13,
      "y": 7,
      "z": -5,
      "name": "Necrotic_Sand"
    },
    {
      "x": -13,
      "y": 8,
      "z": -5,
      "name": "Necrotic_Sand"
    },
    {
      "x": -13,
      "y": 9,
      "z": -5,
      "name": "Necrotic_Sand"
    },
    {
      "x": -13,
      "y": 10,
      "z": -5,
      "name": "Necrotic_Sand"
    },
    {
      "x": -13,
      "y": 11,
      "z": -5,
      "name": "Necrotic_Sand"
    },
    {
      "x": -13,
      "y": 12,
      "z": -5,
      "name": "Necrotic_Sand"
    },
    {
      "x": -13,
      "y": 3,
      "z": -4,
      "name": "Necrotic_Sand"
    },
    {
      "x": -13,
      "y": 4,
      "z": -4,
      "name": "Necrotic_Sand"
    },
    {
      "x": -13,
      "y": 5,
      "z": -4,
      "name": "Necrotic_Sand"
    },
    {
      "x": -13,
      "y": 6,
      "z": -4,
      "name": "Necrotic_Sand"
    },
    {
      "x": -13,
      "y": 7,
      "z": -4,
      "name": "Necrotic_Sand"
    },
    {
      "x": -13,
      "y": 8,
      "z": -4,
      "name": "Necrotic_Sand"
    },
    {
      "x": -13,
      "y": 9,
      "z": -4,
      "name": "Necrotic_Sand"
    },
    {
      "x": -13,
      "y": 10,
      "z": -4,
      "name": "Necrotic_Sand"
    },
    {
      "x": -13,
      "y": 11,
      "z": -4,
      "name": "Necrotic_Sand"
    },
    {
      "x": -13,
      "y": 12,
      "z": -4,
      "name": "Necrotic_Sand"
    },
    {
      "x": -13,
      "y": 13,
      "z": -4,
      "name": "Necrotic_Sand"
    },
    {
      "x": -13,
      "y": 14,
      "z": -4,
      "name": "Necrotic_Sand"
    },
    {
      "x": -13,
      "y": 15,
      "z": -4,
      "name": "Necrotic_Sand"
    },
    {
      "x": -13,
      "y": 16,
      "z": -4,
      "name": "Plant_Bush_Winter"
    },
    {
      "x": -13,
      "y": 17,
      "z": -4,
      "name": "Plant_Vine_Wall_Dead",
      "support": 15,
      "rotation": 3
    },
    {
      "x": -13,
      "y": 4,
      "z": -3,
      "name": "Necrotic_Sand"
    },
    {
      "x": -13,
      "y": 5,
      "z": -3,
      "name": "Necrotic_Sand"
    },
    {
      "x": -13,
      "y": 6,
      "z": -3,
      "name": "Necrotic_Sand"
    },
    {
      "x": -13,
      "y": 7,
      "z": -3,
      "name": "Necrotic_Sand"
    },
    {
      "x": -13,
      "y": 8,
      "z": -3,
      "name": "Necrotic_Sand"
    },
    {
      "x": -13,
      "y": 9,
      "z": -3,
      "name": "Necrotic_Sand"
    },
    {
      "x": -13,
      "y": 10,
      "z": -3,
      "name": "Necrotic_Sand"
    },
    {
      "x": -13,
      "y": 11,
      "z": -3,
      "name": "Necrotic_Sand"
    },
    {
      "x": -13,
      "y": 12,
      "z": -3,
      "name": "Necrotic_Sand"
    },
    {
      "x": -13,
      "y": 13,
      "z": -3,
      "name": "Necrotic_Sand"
    },
    {
      "x": -13,
      "y": 14,
      "z": -3,
      "name": "Necrotic_Sand"
    },
    {
      "x": -13,
      "y": 15,
      "z": -3,
      "name": "Necrotic_Sand"
    },
    {
      "x": -13,
      "y": 16,
      "z": -3,
      "name": "Necrotic_Sand"
    },
    {
      "x": -13,
      "y": 17,
      "z": -3,
      "name": "Necrotic_Sand"
    },
    {
      "x": -13,
      "y": 20,
      "z": -3,
      "name": "Plant_Vine_Wall_Poisoned",
      "support": 15,
      "rotation": 3
    },
    {
      "x": -13,
      "y": 4,
      "z": -2,
      "name": "Necrotic_Sand"
    },
    {
      "x": -13,
      "y": 5,
      "z": -2,
      "name": "Necrotic_Sand"
    },
    {
      "x": -13,
      "y": 6,
      "z": -2,
      "name": "Necrotic_Sand"
    },
    {
      "x": -13,
      "y": 7,
      "z": -2,
      "name": "Necrotic_Sand"
    },
    {
      "x": -13,
      "y": 8,
      "z": -2,
      "name": "Necrotic_Sand"
    },
    {
      "x": -13,
      "y": 9,
      "z": -2,
      "name": "Necrotic_Sand"
    },
    {
      "x": -13,
      "y": 10,
      "z": -2,
      "name": "Necrotic_Sand"
    },
    {
      "x": -13,
      "y": 11,
      "z": -2,
      "name": "Necrotic_Sand"
    },
    {
      "x": -13,
      "y": 12,
      "z": -2,
      "name": "Necrotic_Sand"
    },
    {
      "x": -13,
      "y": 13,
      "z": -2,
      "name": "Necrotic_Sand"
    },
    {
      "x": -13,
      "y": 14,
      "z": -2,
      "name": "Necrotic_Sand"
    },
    {
      "x": -13,
      "y": 15,
      "z": -2,
      "name": "Necrotic_Sand"
    },
    {
      "x": -13,
      "y": 16,
      "z": -2,
      "name": "Necrotic_Sand"
    },
    {
      "x": -13,
      "y": 17,
      "z": -2,
      "name": "Necrotic_Sand"
    },
    {
      "x": -13,
      "y": 18,
      "z": -2,
      "name": "Necrotic_Sand"
    },
    {
      "x": -13,
      "y": 19,
      "z": -2,
      "name": "Necrotic_Grass"
    },
    {
      "x": -13,
      "y": 20,
      "z": -2,
      "name": "Plant_Vine_Wall_Dead",
      "support": 15,
      "rotation": 3
    },
    {
      "x": -13,
      "y": 4,
      "z": -1,
      "name": "Necrotic_Sand"
    },
    {
      "x": -13,
      "y": 5,
      "z": -1,
      "name": "Necrotic_Sand"
    },
    {
      "x": -13,
      "y": 6,
      "z": -1,
      "name": "Necrotic_Sand"
    },
    {
      "x": -13,
      "y": 7,
      "z": -1,
      "name": "Necrotic_Sand"
    },
    {
      "x": -13,
      "y": 8,
      "z": -1,
      "name": "Necrotic_Sand"
    },
    {
      "x": -13,
      "y": 9,
      "z": -1,
      "name": "Necrotic_Sand"
    },
    {
      "x": -13,
      "y": 10,
      "z": -1,
      "name": "Necrotic_Sand"
    },
    {
      "x": -13,
      "y": 11,
      "z": -1,
      "name": "Necrotic_Sand"
    },
    {
      "x": -13,
      "y": 12,
      "z": -1,
      "name": "Necrotic_Sand"
    },
    {
      "x": -13,
      "y": 13,
      "z": -1,
      "name": "Necrotic_Sand"
    },
    {
      "x": -13,
      "y": 14,
      "z": -1,
      "name": "Necrotic_Sand"
    },
    {
      "x": -13,
      "y": 15,
      "z": -1,
      "name": "Necrotic_Sand"
    },
    {
      "x": -13,
      "y": 16,
      "z": -1,
      "name": "Necrotic_Sand"
    },
    {
      "x": -13,
      "y": 17,
      "z": -1,
      "name": "Necrotic_Stone"
    },
    {
      "x": -13,
      "y": 18,
      "z": -1,
      "name": "Necrotic_Sand"
    },
    {
      "x": -13,
      "y": 20,
      "z": -1,
      "name": "Plant_Vine_Wall_Poisoned",
      "support": 15,
      "rotation": 3
    },
    {
      "x": -13,
      "y": 4,
      "z": 0,
      "name": "Necrotic_Sand"
    },
    {
      "x": -13,
      "y": 5,
      "z": 0,
      "name": "Necrotic_Sand"
    },
    {
      "x": -13,
      "y": 6,
      "z": 0,
      "name": "Necrotic_Sand"
    },
    {
      "x": -13,
      "y": 7,
      "z": 0,
      "name": "Necrotic_Sand"
    },
    {
      "x": -13,
      "y": 8,
      "z": 0,
      "name": "Necrotic_Sand"
    },
    {
      "x": -13,
      "y": 9,
      "z": 0,
      "name": "Necrotic_Sand"
    },
    {
      "x": -13,
      "y": 10,
      "z": 0,
      "name": "Necrotic_Sand"
    },
    {
      "x": -13,
      "y": 11,
      "z": 0,
      "name": "Necrotic_Sand"
    },
    {
      "x": -13,
      "y": 12,
      "z": 0,
      "name": "Necrotic_Sand"
    },
    {
      "x": -13,
      "y": 13,
      "z": 0,
      "name": "Necrotic_Stone"
    },
    {
      "x": -13,
      "y": 14,
      "z": 0,
      "name": "Necrotic_Mud"
    },
    {
      "x": -13,
      "y": 15,
      "z": 0,
      "name": "Necrotic_Sand"
    },
    {
      "x": -13,
      "y": 16,
      "z": 0,
      "name": "Necrotic_Stone"
    },
    {
      "x": -13,
      "y": 17,
      "z": 0,
      "name": "Necrotic_Stone"
    },
    {
      "x": -13,
      "y": 19,
      "z": 0,
      "name": "Plant_Vine_Wall_Poisoned",
      "support": 15,
      "rotation": 3
    },
    {
      "x": -13,
      "y": 4,
      "z": 1,
      "name": "Necrotic_Sand"
    },
    {
      "x": -13,
      "y": 5,
      "z": 1,
      "name": "Necrotic_Sand"
    },
    {
      "x": -13,
      "y": 6,
      "z": 1,
      "name": "Necrotic_Sand"
    },
    {
      "x": -13,
      "y": 7,
      "z": 1,
      "name": "Necrotic_Sand"
    },
    {
      "x": -13,
      "y": 8,
      "z": 1,
      "name": "Necrotic_Sand"
    },
    {
      "x": -13,
      "y": 9,
      "z": 1,
      "name": "Necrotic_Sand"
    },
    {
      "x": -13,
      "y": 10,
      "z": 1,
      "name": "Necrotic_Sand"
    },
    {
      "x": -13,
      "y": 11,
      "z": 1,
      "name": "Necrotic_Sand"
    },
    {
      "x": -13,
      "y": 12,
      "z": 1,
      "name": "Necrotic_Stone"
    },
    {
      "x": -13,
      "y": 13,
      "z": 1,
      "name": "Necrotic_Mud"
    },
    {
      "x": -13,
      "y": 14,
      "z": 1,
      "name": "Necrotic_Sand"
    },
    {
      "x": -13,
      "y": 15,
      "z": 1,
      "name": "Necrotic_Dirt"
    },
    {
      "x": -13,
      "y": 16,
      "z": 1,
      "name": "Necrotic_Sand"
    },
    {
      "x": -13,
      "y": 17,
      "z": 1,
      "name": "Prickly_Bush"
    },
    {
      "x": -13,
      "y": 4,
      "z": 2,
      "name": "Necrotic_Sand"
    },
    {
      "x": -13,
      "y": 5,
      "z": 2,
      "name": "Necrotic_Sand"
    },
    {
      "x": -13,
      "y": 6,
      "z": 2,
      "name": "Necrotic_Sand"
    },
    {
      "x": -13,
      "y": 7,
      "z": 2,
      "name": "Necrotic_Sand"
    },
    {
      "x": -13,
      "y": 8,
      "z": 2,
      "name": "Necrotic_Sand"
    },
    {
      "x": -13,
      "y": 9,
      "z": 2,
      "name": "Necrotic_Sand"
    },
    {
      "x": -13,
      "y": 10,
      "z": 2,
      "name": "Necrotic_Sand"
    },
    {
      "x": -13,
      "y": 11,
      "z": 2,
      "name": "Necrotic_Sand"
    },
    {
      "x": -13,
      "y": 12,
      "z": 2,
      "name": "Necrotic_Mud"
    },
    {
      "x": -13,
      "y": 13,
      "z": 2,
      "name": "Necrotic_Sand"
    },
    {
      "x": -13,
      "y": 14,
      "z": 2,
      "name": "Necrotic_Sand"
    },
    {
      "x": -13,
      "y": 15,
      "z": 2,
      "name": "Necrotic_Stone"
    },
    {
      "x": -13,
      "y": 16,
      "z": 2,
      "name": "Plant_Vine_Wall_Poisoned",
      "support": 15,
      "rotation": 3
    },
    {
      "x": -13,
      "y": 4,
      "z": 3,
      "name": "Necrotic_Stone_Deep"
    },
    {
      "x": -13,
      "y": 5,
      "z": 3,
      "name": "Necrotic_Sand"
    },
    {
      "x": -13,
      "y": 6,
      "z": 3,
      "name": "Necrotic_Sand"
    },
    {
      "x": -13,
      "y": 7,
      "z": 3,
      "name": "Necrotic_Sand"
    },
    {
      "x": -13,
      "y": 8,
      "z": 3,
      "name": "Necrotic_Sand"
    },
    {
      "x": -13,
      "y": 9,
      "z": 3,
      "name": "Necrotic_Sand"
    },
    {
      "x": -13,
      "y": 10,
      "z": 3,
      "name": "Necrotic_Sand"
    },
    {
      "x": -13,
      "y": 11,
      "z": 3,
      "name": "Necrotic_Stone"
    },
    {
      "x": -13,
      "y": 12,
      "z": 3,
      "name": "Necrotic_Stone"
    },
    {
      "x": -13,
      "y": 13,
      "z": 3,
      "name": "Necrotic_Stone"
    },
    {
      "x": -13,
      "y": 14,
      "z": 3,
      "name": "Necrotic_Sand"
    },
    {
      "x": -13,
      "y": 15,
      "z": 3,
      "name": "Rock_Slate_Stalactite_Large"
    },
    {
      "x": -13,
      "y": 16,
      "z": 3,
      "name": "Rock_Slate_Stalactite_Large",
      "filler": 1024
    },
    {
      "x": -13,
      "y": 4,
      "z": 4,
      "name": "Necrotic_Mud"
    },
    {
      "x": -13,
      "y": 5,
      "z": 4,
      "name": "Necrotic_Sand"
    },
    {
      "x": -13,
      "y": 6,
      "z": 4,
      "name": "Necrotic_Sand"
    },
    {
      "x": -13,
      "y": 7,
      "z": 4,
      "name": "Necrotic_Sand"
    },
    {
      "x": -13,
      "y": 8,
      "z": 4,
      "name": "Necrotic_Sand"
    },
    {
      "x": -13,
      "y": 9,
      "z": 4,
      "name": "Necrotic_Sand"
    },
    {
      "x": -13,
      "y": 10,
      "z": 4,
      "name": "Necrotic_Sand"
    },
    {
      "x": -13,
      "y": 11,
      "z": 4,
      "name": "Necrotic_Stone"
    },
    {
      "x": -13,
      "y": 12,
      "z": 4,
      "name": "Necrotic_Stone"
    },
    {
      "x": -13,
      "y": 13,
      "z": 4,
      "name": "Necrotic_Sand"
    },
    {
      "x": -13,
      "y": 14,
      "z": 4,
      "name": "Necrotic_Sand"
    },
    {
      "x": -13,
      "y": 4,
      "z": 5,
      "name": "Necrotic_Mud"
    },
    {
      "x": -13,
      "y": 5,
      "z": 5,
      "name": "Necrotic_Sand"
    },
    {
      "x": -13,
      "y": 6,
      "z": 5,
      "name": "Necrotic_Sand"
    },
    {
      "x": -13,
      "y": 7,
      "z": 5,
      "name": "Necrotic_Sand"
    },
    {
      "x": -13,
      "y": 8,
      "z": 5,
      "name": "Necrotic_Sand"
    },
    {
      "x": -13,
      "y": 9,
      "z": 5,
      "name": "Necrotic_Sand"
    },
    {
      "x": -13,
      "y": 10,
      "z": 5,
      "name": "Necrotic_Sand"
    },
    {
      "x": -13,
      "y": 11,
      "z": 5,
      "name": "Necrotic_Mud"
    },
    {
      "x": -13,
      "y": 12,
      "z": 5,
      "name": "Necrotic_Sand"
    },
    {
      "x": -13,
      "y": 13,
      "z": 5,
      "name": "Necrotic_Sand"
    },
    {
      "x": -13,
      "y": 14,
      "z": 5,
      "name": "Necrotic_Sand"
    },
    {
      "x": -13,
      "y": 4,
      "z": 6,
      "name": "Necrotic_Stone_Deep"
    },
    {
      "x": -13,
      "y": 5,
      "z": 6,
      "name": "Necrotic_Sand"
    },
    {
      "x": -13,
      "y": 6,
      "z": 6,
      "name": "Necrotic_Sand"
    },
    {
      "x": -13,
      "y": 7,
      "z": 6,
      "name": "Necrotic_Sand"
    },
    {
      "x": -13,
      "y": 8,
      "z": 6,
      "name": "Necrotic_Sand"
    },
    {
      "x": -13,
      "y": 9,
      "z": 6,
      "name": "Necrotic_Sand"
    },
    {
      "x": -13,
      "y": 10,
      "z": 6,
      "name": "Necrotic_Sand"
    },
    {
      "x": -13,
      "y": 11,
      "z": 6,
      "name": "Necrotic_Sand"
    },
    {
      "x": -13,
      "y": 12,
      "z": 6,
      "name": "Necrotic_Sand"
    },
    {
      "x": -13,
      "y": 13,
      "z": 6,
      "name": "Necrotic_Dirt"
    },
    {
      "x": -13,
      "y": 4,
      "z": 7,
      "name": "Necrotic_Mud"
    },
    {
      "x": -13,
      "y": 5,
      "z": 7,
      "name": "Necrotic_Sand"
    },
    {
      "x": -13,
      "y": 6,
      "z": 7,
      "name": "Necrotic_Sand"
    },
    {
      "x": -13,
      "y": 7,
      "z": 7,
      "name": "Necrotic_Sand"
    },
    {
      "x": -13,
      "y": 8,
      "z": 7,
      "name": "Necrotic_Sand"
    },
    {
      "x": -13,
      "y": 9,
      "z": 7,
      "name": "Necrotic_Sand"
    },
    {
      "x": -13,
      "y": 10,
      "z": 7,
      "name": "Necrotic_Sand"
    },
    {
      "x": -13,
      "y": 11,
      "z": 7,
      "name": "Necrotic_Stone"
    },
    {
      "x": -13,
      "y": 12,
      "z": 7,
      "name": "Necrotic_Mud"
    },
    {
      "x": -13,
      "y": 13,
      "z": 7,
      "name": "Necrotic_Sand"
    },
    {
      "x": -13,
      "y": 14,
      "z": 7,
      "name": "Necrotic_Grass"
    },
    {
      "x": -13,
      "y": 5,
      "z": 8,
      "name": "Necrotic_Sand"
    },
    {
      "x": -13,
      "y": 6,
      "z": 8,
      "name": "Necrotic_Sand"
    },
    {
      "x": -13,
      "y": 7,
      "z": 8,
      "name": "Necrotic_Sand"
    },
    {
      "x": -13,
      "y": 8,
      "z": 8,
      "name": "Necrotic_Sand"
    },
    {
      "x": -13,
      "y": 9,
      "z": 8,
      "name": "Necrotic_Sand"
    },
    {
      "x": -13,
      "y": 10,
      "z": 8,
      "name": "Necrotic_Sand"
    },
    {
      "x": -13,
      "y": 11,
      "z": 8,
      "name": "Necrotic_Mud"
    },
    {
      "x": -13,
      "y": 12,
      "z": 8,
      "name": "Necrotic_Mud"
    },
    {
      "x": -13,
      "y": 5,
      "z": 9,
      "name": "Necrotic_Sand"
    },
    {
      "x": -13,
      "y": 6,
      "z": 9,
      "name": "Necrotic_Sand"
    },
    {
      "x": -13,
      "y": 7,
      "z": 9,
      "name": "Necrotic_Sand"
    },
    {
      "x": -13,
      "y": 8,
      "z": 9,
      "name": "Necrotic_Sand"
    },
    {
      "x": -13,
      "y": 9,
      "z": 9,
      "name": "Necrotic_Sand"
    },
    {
      "x": -13,
      "y": 10,
      "z": 9,
      "name": "Necrotic_Sand"
    },
    {
      "x": -13,
      "y": 11,
      "z": 9,
      "name": "Necrotic_Stone"
    },
    {
      "x": -13,
      "y": 12,
      "z": 9,
      "name": "Necrotic_Sand"
    },
    {
      "x": -13,
      "y": 13,
      "z": 9,
      "name": "Rock_Slate_Stalactite_Small"
    },
    {
      "x": -13,
      "y": 5,
      "z": 10,
      "name": "Necrotic_Sand"
    },
    {
      "x": -13,
      "y": 6,
      "z": 10,
      "name": "Necrotic_Sand"
    },
    {
      "x": -13,
      "y": 7,
      "z": 10,
      "name": "Necrotic_Sand"
    },
    {
      "x": -13,
      "y": 8,
      "z": 10,
      "name": "Necrotic_Sand"
    },
    {
      "x": -13,
      "y": 9,
      "z": 10,
      "name": "Necrotic_Sand"
    },
    {
      "x": -13,
      "y": 10,
      "z": 10,
      "name": "Necrotic_Sand"
    },
    {
      "x": -13,
      "y": 11,
      "z": 10,
      "name": "Necrotic_Mud"
    },
    {
      "x": -13,
      "y": 12,
      "z": 10,
      "name": "Necrotic_Sand"
    },
    {
      "x": -13,
      "y": 13,
      "z": 10,
      "name": "Necrotic_Grass"
    },
    {
      "x": -13,
      "y": 5,
      "z": 11,
      "name": "Necrotic_Sand"
    },
    {
      "x": -13,
      "y": 6,
      "z": 11,
      "name": "Necrotic_Sand"
    },
    {
      "x": -13,
      "y": 7,
      "z": 11,
      "name": "Necrotic_Sand"
    },
    {
      "x": -13,
      "y": 8,
      "z": 11,
      "name": "Necrotic_Sand"
    },
    {
      "x": -13,
      "y": 9,
      "z": 11,
      "name": "Necrotic_Sand"
    },
    {
      "x": -13,
      "y": 10,
      "z": 11,
      "name": "Necrotic_Sand"
    },
    {
      "x": -13,
      "y": 11,
      "z": 11,
      "name": "Necrotic_Mud"
    },
    {
      "x": -13,
      "y": 12,
      "z": 11,
      "name": "Necrotic_Stone"
    },
    {
      "x": -13,
      "y": 5,
      "z": 12,
      "name": "Necrotic_Sand"
    },
    {
      "x": -13,
      "y": 6,
      "z": 12,
      "name": "Necrotic_Sand"
    },
    {
      "x": -13,
      "y": 7,
      "z": 12,
      "name": "Necrotic_Sand"
    },
    {
      "x": -13,
      "y": 8,
      "z": 12,
      "name": "Necrotic_Sand"
    },
    {
      "x": -13,
      "y": 9,
      "z": 12,
      "name": "Necrotic_Sand"
    },
    {
      "x": -13,
      "y": 10,
      "z": 12,
      "name": "Necrotic_Sand"
    },
    {
      "x": -13,
      "y": 11,
      "z": 12,
      "name": "Necrotic_Mud"
    },
    {
      "x": -13,
      "y": 6,
      "z": 13,
      "name": "Necrotic_Sand"
    },
    {
      "x": -13,
      "y": 7,
      "z": 13,
      "name": "Necrotic_Sand"
    },
    {
      "x": -13,
      "y": 8,
      "z": 13,
      "name": "Necrotic_Sand"
    },
    {
      "x": -13,
      "y": 9,
      "z": 13,
      "name": "Necrotic_Sand"
    },
    {
      "x": -13,
      "y": 10,
      "z": 13,
      "name": "Necrotic_Sand"
    },
    {
      "x": -13,
      "y": 11,
      "z": 13,
      "name": "Necrotic_Stone"
    },
    {
      "x": -13,
      "y": 6,
      "z": 14,
      "name": "Necrotic_Sand"
    },
    {
      "x": -13,
      "y": 7,
      "z": 14,
      "name": "Necrotic_Sand"
    },
    {
      "x": -13,
      "y": 8,
      "z": 14,
      "name": "Necrotic_Sand"
    },
    {
      "x": -13,
      "y": 9,
      "z": 14,
      "name": "Necrotic_Sand"
    },
    {
      "x": -13,
      "y": 10,
      "z": 14,
      "name": "Necrotic_Sand"
    },
    {
      "x": -13,
      "y": 11,
      "z": 14,
      "name": "Necrotic_Mud"
    },
    {
      "x": -13,
      "y": 6,
      "z": 15,
      "name": "Necrotic_Sand"
    },
    {
      "x": -13,
      "y": 7,
      "z": 15,
      "name": "Necrotic_Sand"
    },
    {
      "x": -13,
      "y": 8,
      "z": 15,
      "name": "Necrotic_Sand"
    },
    {
      "x": -13,
      "y": 9,
      "z": 15,
      "name": "Necrotic_Sand"
    },
    {
      "x": -13,
      "y": 10,
      "z": 15,
      "name": "Necrotic_Sand"
    },
    {
      "x": -13,
      "y": 11,
      "z": 15,
      "name": "Necrotic_Stone"
    },
    {
      "x": -13,
      "y": 7,
      "z": 16,
      "name": "Necrotic_Sand"
    },
    {
      "x": -13,
      "y": 8,
      "z": 16,
      "name": "Necrotic_Sand"
    },
    {
      "x": -13,
      "y": 9,
      "z": 16,
      "name": "Necrotic_Sand"
    },
    {
      "x": -13,
      "y": 10,
      "z": 16,
      "name": "Necrotic_Sand"
    },
    {
      "x": -13,
      "y": 7,
      "z": 17,
      "name": "Necrotic_Sand"
    },
    {
      "x": -13,
      "y": 8,
      "z": 17,
      "name": "Necrotic_Sand"
    },
    {
      "x": -13,
      "y": 9,
      "z": 17,
      "name": "Necrotic_Sand"
    },
    {
      "x": -13,
      "y": 10,
      "z": 17,
      "name": "Necrotic_Sand"
    },
    {
      "x": -13,
      "y": 7,
      "z": 18,
      "name": "Necrotic_Sand"
    },
    {
      "x": -13,
      "y": 8,
      "z": 18,
      "name": "Necrotic_Sand"
    },
    {
      "x": -13,
      "y": 9,
      "z": 18,
      "name": "Necrotic_Sand"
    },
    {
      "x": -13,
      "y": 8,
      "z": 19,
      "name": "Necrotic_Sand"
    },
    {
      "x": -12,
      "y": 7,
      "z": -18,
      "name": "Necrotic_Sand"
    },
    {
      "x": -12,
      "y": 8,
      "z": -18,
      "name": "Necrotic_Sand"
    },
    {
      "x": -12,
      "y": 9,
      "z": -18,
      "name": "Necrotic_Sand"
    },
    {
      "x": -12,
      "y": 10,
      "z": -18,
      "name": "Necrotic_Sand"
    },
    {
      "x": -12,
      "y": 11,
      "z": -18,
      "name": "Plant_Bush_Winter"
    },
    {
      "x": -12,
      "y": 5,
      "z": -17,
      "name": "Necrotic_Sand"
    },
    {
      "x": -12,
      "y": 6,
      "z": -17,
      "name": "Necrotic_Sand"
    },
    {
      "x": -12,
      "y": 7,
      "z": -17,
      "name": "Necrotic_Sand"
    },
    {
      "x": -12,
      "y": 8,
      "z": -17,
      "name": "Necrotic_Sand"
    },
    {
      "x": -12,
      "y": 9,
      "z": -17,
      "name": "Necrotic_Sand"
    },
    {
      "x": -12,
      "y": 10,
      "z": -17,
      "name": "Necrotic_Sand"
    },
    {
      "x": -12,
      "y": 11,
      "z": -17,
      "name": "Necrotic_Sand"
    },
    {
      "x": -12,
      "y": 5,
      "z": -16,
      "name": "Necrotic_Sand"
    },
    {
      "x": -12,
      "y": 6,
      "z": -16,
      "name": "Necrotic_Sand"
    },
    {
      "x": -12,
      "y": 7,
      "z": -16,
      "name": "Necrotic_Sand"
    },
    {
      "x": -12,
      "y": 8,
      "z": -16,
      "name": "Necrotic_Sand"
    },
    {
      "x": -12,
      "y": 9,
      "z": -16,
      "name": "Necrotic_Sand"
    },
    {
      "x": -12,
      "y": 10,
      "z": -16,
      "name": "Necrotic_Sand"
    },
    {
      "x": -12,
      "y": 11,
      "z": -16,
      "name": "Necrotic_Sand"
    },
    {
      "x": -12,
      "y": 5,
      "z": -15,
      "name": "Necrotic_Sand"
    },
    {
      "x": -12,
      "y": 6,
      "z": -15,
      "name": "Necrotic_Sand"
    },
    {
      "x": -12,
      "y": 7,
      "z": -15,
      "name": "Necrotic_Sand"
    },
    {
      "x": -12,
      "y": 8,
      "z": -15,
      "name": "Necrotic_Sand"
    },
    {
      "x": -12,
      "y": 9,
      "z": -15,
      "name": "Necrotic_Sand"
    },
    {
      "x": -12,
      "y": 10,
      "z": -15,
      "name": "Necrotic_Sand"
    },
    {
      "x": -12,
      "y": 11,
      "z": -15,
      "name": "Necrotic_Sand"
    },
    {
      "x": -12,
      "y": 12,
      "z": -15,
      "name": "Necrotic_Sand"
    },
    {
      "x": -12,
      "y": 4,
      "z": -14,
      "name": "Necrotic_Sand"
    },
    {
      "x": -12,
      "y": 5,
      "z": -14,
      "name": "Necrotic_Sand"
    },
    {
      "x": -12,
      "y": 6,
      "z": -14,
      "name": "Necrotic_Sand"
    },
    {
      "x": -12,
      "y": 7,
      "z": -14,
      "name": "Necrotic_Sand"
    },
    {
      "x": -12,
      "y": 8,
      "z": -14,
      "name": "Necrotic_Sand"
    },
    {
      "x": -12,
      "y": 9,
      "z": -14,
      "name": "Necrotic_Sand"
    },
    {
      "x": -12,
      "y": 10,
      "z": -14,
      "name": "Necrotic_Sand"
    },
    {
      "x": -12,
      "y": 11,
      "z": -14,
      "name": "Necrotic_Sand"
    },
    {
      "x": -12,
      "y": 12,
      "z": -14,
      "name": "Necrotic_Sand"
    },
    {
      "x": -12,
      "y": 4,
      "z": -13,
      "name": "Necrotic_Sand"
    },
    {
      "x": -12,
      "y": 5,
      "z": -13,
      "name": "Necrotic_Sand"
    },
    {
      "x": -12,
      "y": 6,
      "z": -13,
      "name": "Necrotic_Sand"
    },
    {
      "x": -12,
      "y": 7,
      "z": -13,
      "name": "Necrotic_Sand"
    },
    {
      "x": -12,
      "y": 8,
      "z": -13,
      "name": "Necrotic_Sand"
    },
    {
      "x": -12,
      "y": 9,
      "z": -13,
      "name": "Necrotic_Sand"
    },
    {
      "x": -12,
      "y": 10,
      "z": -13,
      "name": "Necrotic_Sand"
    },
    {
      "x": -12,
      "y": 11,
      "z": -13,
      "name": "Necrotic_Sand"
    },
    {
      "x": -12,
      "y": 12,
      "z": -13,
      "name": "Necrotic_Sand"
    },
    {
      "x": -12,
      "y": 13,
      "z": -13,
      "name": "Necrotic_Sand"
    },
    {
      "x": -12,
      "y": 14,
      "z": -13,
      "name": "Prickly_Bush"
    },
    {
      "x": -12,
      "y": 4,
      "z": -12,
      "name": "Necrotic_Sand"
    },
    {
      "x": -12,
      "y": 5,
      "z": -12,
      "name": "Necrotic_Sand"
    },
    {
      "x": -12,
      "y": 6,
      "z": -12,
      "name": "Necrotic_Sand"
    },
    {
      "x": -12,
      "y": 7,
      "z": -12,
      "name": "Necrotic_Sand"
    },
    {
      "x": -12,
      "y": 8,
      "z": -12,
      "name": "Necrotic_Sand"
    },
    {
      "x": -12,
      "y": 9,
      "z": -12,
      "name": "Necrotic_Sand"
    },
    {
      "x": -12,
      "y": 10,
      "z": -12,
      "name": "Necrotic_Sand"
    },
    {
      "x": -12,
      "y": 11,
      "z": -12,
      "name": "Necrotic_Sand"
    },
    {
      "x": -12,
      "y": 12,
      "z": -12,
      "name": "Necrotic_Sand"
    },
    {
      "x": -12,
      "y": 13,
      "z": -12,
      "name": "Necrotic_Sand"
    },
    {
      "x": -12,
      "y": 14,
      "z": -12,
      "name": "Necrotic_Grass"
    },
    {
      "x": -12,
      "y": 4,
      "z": -11,
      "name": "Necrotic_Sand"
    },
    {
      "x": -12,
      "y": 5,
      "z": -11,
      "name": "Necrotic_Sand"
    },
    {
      "x": -12,
      "y": 6,
      "z": -11,
      "name": "Necrotic_Sand"
    },
    {
      "x": -12,
      "y": 7,
      "z": -11,
      "name": "Necrotic_Sand"
    },
    {
      "x": -12,
      "y": 8,
      "z": -11,
      "name": "Necrotic_Sand"
    },
    {
      "x": -12,
      "y": 9,
      "z": -11,
      "name": "Necrotic_Sand"
    },
    {
      "x": -12,
      "y": 10,
      "z": -11,
      "name": "Necrotic_Sand"
    },
    {
      "x": -12,
      "y": 11,
      "z": -11,
      "name": "Necrotic_Sand"
    },
    {
      "x": -12,
      "y": 12,
      "z": -11,
      "name": "Necrotic_Sand"
    },
    {
      "x": -12,
      "y": 13,
      "z": -11,
      "name": "Necrotic_Sand"
    },
    {
      "x": -12,
      "y": 4,
      "z": -10,
      "name": "Necrotic_Sand"
    },
    {
      "x": -12,
      "y": 5,
      "z": -10,
      "name": "Necrotic_Sand"
    },
    {
      "x": -12,
      "y": 6,
      "z": -10,
      "name": "Necrotic_Sand"
    },
    {
      "x": -12,
      "y": 7,
      "z": -10,
      "name": "Necrotic_Sand"
    },
    {
      "x": -12,
      "y": 8,
      "z": -10,
      "name": "Necrotic_Sand"
    },
    {
      "x": -12,
      "y": 9,
      "z": -10,
      "name": "Necrotic_Sand"
    },
    {
      "x": -12,
      "y": 10,
      "z": -10,
      "name": "Necrotic_Sand"
    },
    {
      "x": -12,
      "y": 11,
      "z": -10,
      "name": "Necrotic_Sand"
    },
    {
      "x": -12,
      "y": 12,
      "z": -10,
      "name": "Necrotic_Sand"
    },
    {
      "x": -12,
      "y": 13,
      "z": -10,
      "name": "Necrotic_Sand"
    },
    {
      "x": -12,
      "y": 14,
      "z": -10,
      "name": "Plant_Bush_Winter"
    },
    {
      "x": -12,
      "y": 3,
      "z": -9,
      "name": "Necrotic_Sand"
    },
    {
      "x": -12,
      "y": 4,
      "z": -9,
      "name": "Necrotic_Sand"
    },
    {
      "x": -12,
      "y": 5,
      "z": -9,
      "name": "Necrotic_Sand"
    },
    {
      "x": -12,
      "y": 6,
      "z": -9,
      "name": "Necrotic_Sand"
    },
    {
      "x": -12,
      "y": 7,
      "z": -9,
      "name": "Necrotic_Sand"
    },
    {
      "x": -12,
      "y": 8,
      "z": -9,
      "name": "Necrotic_Sand"
    },
    {
      "x": -12,
      "y": 9,
      "z": -9,
      "name": "Necrotic_Sand"
    },
    {
      "x": -12,
      "y": 10,
      "z": -9,
      "name": "Necrotic_Sand"
    },
    {
      "x": -12,
      "y": 11,
      "z": -9,
      "name": "Necrotic_Sand"
    },
    {
      "x": -12,
      "y": 12,
      "z": -9,
      "name": "Necrotic_Sand"
    },
    {
      "x": -12,
      "y": 13,
      "z": -9,
      "name": "Necrotic_Sand"
    },
    {
      "x": -12,
      "y": 3,
      "z": -8,
      "name": "Necrotic_Sand"
    },
    {
      "x": -12,
      "y": 4,
      "z": -8,
      "name": "Necrotic_Sand"
    },
    {
      "x": -12,
      "y": 5,
      "z": -8,
      "name": "Necrotic_Sand"
    },
    {
      "x": -12,
      "y": 6,
      "z": -8,
      "name": "Necrotic_Sand"
    },
    {
      "x": -12,
      "y": 7,
      "z": -8,
      "name": "Necrotic_Sand"
    },
    {
      "x": -12,
      "y": 8,
      "z": -8,
      "name": "Necrotic_Sand"
    },
    {
      "x": -12,
      "y": 9,
      "z": -8,
      "name": "Necrotic_Sand"
    },
    {
      "x": -12,
      "y": 10,
      "z": -8,
      "name": "Necrotic_Sand"
    },
    {
      "x": -12,
      "y": 11,
      "z": -8,
      "name": "Necrotic_Sand"
    },
    {
      "x": -12,
      "y": 12,
      "z": -8,
      "name": "Necrotic_Sand"
    },
    {
      "x": -12,
      "y": 13,
      "z": -8,
      "name": "Necrotic_Sand"
    },
    {
      "x": -12,
      "y": 14,
      "z": -8,
      "name": "Necrotic_Sand"
    },
    {
      "x": -12,
      "y": 16,
      "z": -8,
      "name": "Plant_Vine_Wall_Dead",
      "support": 15,
      "rotation": 3
    },
    {
      "x": -12,
      "y": 3,
      "z": -7,
      "name": "Necrotic_Sand"
    },
    {
      "x": -12,
      "y": 4,
      "z": -7,
      "name": "Necrotic_Sand"
    },
    {
      "x": -12,
      "y": 5,
      "z": -7,
      "name": "Necrotic_Sand"
    },
    {
      "x": -12,
      "y": 6,
      "z": -7,
      "name": "Necrotic_Sand"
    },
    {
      "x": -12,
      "y": 7,
      "z": -7,
      "name": "Necrotic_Sand"
    },
    {
      "x": -12,
      "y": 8,
      "z": -7,
      "name": "Necrotic_Sand"
    },
    {
      "x": -12,
      "y": 9,
      "z": -7,
      "name": "Necrotic_Sand"
    },
    {
      "x": -12,
      "y": 10,
      "z": -7,
      "name": "Necrotic_Sand"
    },
    {
      "x": -12,
      "y": 11,
      "z": -7,
      "name": "Necrotic_Sand"
    },
    {
      "x": -12,
      "y": 12,
      "z": -7,
      "name": "Necrotic_Sand"
    },
    {
      "x": -12,
      "y": 13,
      "z": -7,
      "name": "Necrotic_Sand"
    },
    {
      "x": -12,
      "y": 14,
      "z": -7,
      "name": "Necrotic_Sand"
    },
    {
      "x": -12,
      "y": 16,
      "z": -7,
      "name": "Plant_Vine_Wall_Dead",
      "support": 15,
      "rotation": 3
    },
    {
      "x": -12,
      "y": 18,
      "z": -7,
      "name": "Plant_Vine_Wall_Poisoned",
      "support": 15,
      "rotation": 3
    },
    {
      "x": -12,
      "y": 3,
      "z": -6,
      "name": "Necrotic_Mud"
    },
    {
      "x": -12,
      "y": 4,
      "z": -6,
      "name": "Necrotic_Sand"
    },
    {
      "x": -12,
      "y": 5,
      "z": -6,
      "name": "Necrotic_Sand"
    },
    {
      "x": -12,
      "y": 6,
      "z": -6,
      "name": "Necrotic_Sand"
    },
    {
      "x": -12,
      "y": 7,
      "z": -6,
      "name": "Necrotic_Sand"
    },
    {
      "x": -12,
      "y": 8,
      "z": -6,
      "name": "Necrotic_Sand"
    },
    {
      "x": -12,
      "y": 9,
      "z": -6,
      "name": "Necrotic_Sand"
    },
    {
      "x": -12,
      "y": 10,
      "z": -6,
      "name": "Necrotic_Sand"
    },
    {
      "x": -12,
      "y": 11,
      "z": -6,
      "name": "Necrotic_Sand"
    },
    {
      "x": -12,
      "y": 12,
      "z": -6,
      "name": "Necrotic_Sand"
    },
    {
      "x": -12,
      "y": 13,
      "z": -6,
      "name": "Necrotic_Sand"
    },
    {
      "x": -12,
      "y": 14,
      "z": -6,
      "name": "Necrotic_Sand"
    },
    {
      "x": -12,
      "y": 15,
      "z": -6,
      "name": "Necrotic_Sand"
    },
    {
      "x": -12,
      "y": 16,
      "z": -6,
      "name": "Necrotic_Mud"
    },
    {
      "x": -12,
      "y": 18,
      "z": -6,
      "name": "Plant_Vine_Wall_Poisoned",
      "support": 15,
      "rotation": 3
    },
    {
      "x": -12,
      "y": 3,
      "z": -5,
      "name": "Necrotic_Stone_Deep"
    },
    {
      "x": -12,
      "y": 4,
      "z": -5,
      "name": "Necrotic_Mud"
    },
    {
      "x": -12,
      "y": 5,
      "z": -5,
      "name": "Necrotic_Sand"
    },
    {
      "x": -12,
      "y": 6,
      "z": -5,
      "name": "Necrotic_Sand"
    },
    {
      "x": -12,
      "y": 7,
      "z": -5,
      "name": "Necrotic_Sand"
    },
    {
      "x": -12,
      "y": 8,
      "z": -5,
      "name": "Necrotic_Sand"
    },
    {
      "x": -12,
      "y": 9,
      "z": -5,
      "name": "Necrotic_Sand"
    },
    {
      "x": -12,
      "y": 10,
      "z": -5,
      "name": "Necrotic_Sand"
    },
    {
      "x": -12,
      "y": 11,
      "z": -5,
      "name": "Necrotic_Sand"
    },
    {
      "x": -12,
      "y": 12,
      "z": -5,
      "name": "Necrotic_Sand"
    },
    {
      "x": -12,
      "y": 13,
      "z": -5,
      "name": "Necrotic_Sand"
    },
    {
      "x": -12,
      "y": 14,
      "z": -5,
      "name": "Necrotic_Sand"
    },
    {
      "x": -12,
      "y": 15,
      "z": -5,
      "name": "Necrotic_Sand"
    },
    {
      "x": -12,
      "y": 16,
      "z": -5,
      "name": "Necrotic_Sand"
    },
    {
      "x": -12,
      "y": 17,
      "z": -5,
      "name": "Necrotic_Sand"
    },
    {
      "x": -12,
      "y": 19,
      "z": -5,
      "name": "Plant_Vine_Wall_Poisoned",
      "support": 15,
      "rotation": 3
    },
    {
      "x": -12,
      "y": 3,
      "z": -4,
      "name": "Necrotic_Mud"
    },
    {
      "x": -12,
      "y": 4,
      "z": -4,
      "name": "Necrotic_Sand"
    },
    {
      "x": -12,
      "y": 5,
      "z": -4,
      "name": "Necrotic_Sand"
    },
    {
      "x": -12,
      "y": 6,
      "z": -4,
      "name": "Necrotic_Sand"
    },
    {
      "x": -12,
      "y": 7,
      "z": -4,
      "name": "Necrotic_Sand"
    },
    {
      "x": -12,
      "y": 8,
      "z": -4,
      "name": "Necrotic_Sand"
    },
    {
      "x": -12,
      "y": 9,
      "z": -4,
      "name": "Necrotic_Sand"
    },
    {
      "x": -12,
      "y": 10,
      "z": -4,
      "name": "Necrotic_Sand"
    },
    {
      "x": -12,
      "y": 11,
      "z": -4,
      "name": "Necrotic_Sand"
    },
    {
      "x": -12,
      "y": 12,
      "z": -4,
      "name": "Necrotic_Sand"
    },
    {
      "x": -12,
      "y": 13,
      "z": -4,
      "name": "Necrotic_Sand"
    },
    {
      "x": -12,
      "y": 14,
      "z": -4,
      "name": "Necrotic_Sand"
    },
    {
      "x": -12,
      "y": 15,
      "z": -4,
      "name": "Necrotic_Sand"
    },
    {
      "x": -12,
      "y": 16,
      "z": -4,
      "name": "Necrotic_Sand"
    },
    {
      "x": -12,
      "y": 17,
      "z": -4,
      "name": "Necrotic_Sand"
    },
    {
      "x": -12,
      "y": 18,
      "z": -4,
      "name": "Necrotic_Sand"
    },
    {
      "x": -12,
      "y": 19,
      "z": -4,
      "name": "Plant_Vine_Wall_Poisoned",
      "support": 15,
      "rotation": 3
    },
    {
      "x": -12,
      "y": 20,
      "z": -4,
      "name": "Plant_Vine_Wall_Poisoned",
      "support": 15,
      "rotation": 3
    },
    {
      "x": -12,
      "y": 3,
      "z": -3,
      "name": "Necrotic_Mud"
    },
    {
      "x": -12,
      "y": 4,
      "z": -3,
      "name": "Necrotic_Sand"
    },
    {
      "x": -12,
      "y": 5,
      "z": -3,
      "name": "Necrotic_Sand"
    },
    {
      "x": -12,
      "y": 6,
      "z": -3,
      "name": "Necrotic_Sand"
    },
    {
      "x": -12,
      "y": 7,
      "z": -3,
      "name": "Necrotic_Sand"
    },
    {
      "x": -12,
      "y": 8,
      "z": -3,
      "name": "Necrotic_Sand"
    },
    {
      "x": -12,
      "y": 9,
      "z": -3,
      "name": "Necrotic_Sand"
    },
    {
      "x": -12,
      "y": 10,
      "z": -3,
      "name": "Necrotic_Sand"
    },
    {
      "x": -12,
      "y": 11,
      "z": -3,
      "name": "Necrotic_Sand"
    },
    {
      "x": -12,
      "y": 12,
      "z": -3,
      "name": "Necrotic_Sand"
    },
    {
      "x": -12,
      "y": 13,
      "z": -3,
      "name": "Necrotic_Sand"
    },
    {
      "x": -12,
      "y": 14,
      "z": -3,
      "name": "Necrotic_Sand"
    },
    {
      "x": -12,
      "y": 15,
      "z": -3,
      "name": "Necrotic_Sand"
    },
    {
      "x": -12,
      "y": 16,
      "z": -3,
      "name": "Necrotic_Sand"
    },
    {
      "x": -12,
      "y": 17,
      "z": -3,
      "name": "Necrotic_Sand"
    },
    {
      "x": -12,
      "y": 18,
      "z": -3,
      "name": "Necrotic_Sand"
    },
    {
      "x": -12,
      "y": 19,
      "z": -3,
      "name": "Necrotic_Sand"
    },
    {
      "x": -12,
      "y": 20,
      "z": -3,
      "name": "Necrotic_Sand"
    },
    {
      "x": -12,
      "y": 21,
      "z": -3,
      "name": "Dead_Branch"
    },
    {
      "x": -12,
      "y": 3,
      "z": -2,
      "name": "Necrotic_Stone_Deep"
    },
    {
      "x": -12,
      "y": 4,
      "z": -2,
      "name": "Necrotic_Mud"
    },
    {
      "x": -12,
      "y": 5,
      "z": -2,
      "name": "Necrotic_Sand"
    },
    {
      "x": -12,
      "y": 6,
      "z": -2,
      "name": "Necrotic_Sand"
    },
    {
      "x": -12,
      "y": 7,
      "z": -2,
      "name": "Necrotic_Sand"
    },
    {
      "x": -12,
      "y": 8,
      "z": -2,
      "name": "Necrotic_Sand"
    },
    {
      "x": -12,
      "y": 9,
      "z": -2,
      "name": "Necrotic_Sand"
    },
    {
      "x": -12,
      "y": 10,
      "z": -2,
      "name": "Necrotic_Sand"
    },
    {
      "x": -12,
      "y": 11,
      "z": -2,
      "name": "Necrotic_Sand"
    },
    {
      "x": -12,
      "y": 12,
      "z": -2,
      "name": "Necrotic_Sand"
    },
    {
      "x": -12,
      "y": 13,
      "z": -2,
      "name": "Necrotic_Sand"
    },
    {
      "x": -12,
      "y": 14,
      "z": -2,
      "name": "Necrotic_Sand"
    },
    {
      "x": -12,
      "y": 15,
      "z": -2,
      "name": "Necrotic_Sand"
    },
    {
      "x": -12,
      "y": 16,
      "z": -2,
      "name": "Necrotic_Sand"
    },
    {
      "x": -12,
      "y": 17,
      "z": -2,
      "name": "Necrotic_Sand"
    },
    {
      "x": -12,
      "y": 18,
      "z": -2,
      "name": "Necrotic_Sand"
    },
    {
      "x": -12,
      "y": 19,
      "z": -2,
      "name": "Necrotic_Sand"
    },
    {
      "x": -12,
      "y": 20,
      "z": -2,
      "name": "Necrotic_Sand"
    },
    {
      "x": -12,
      "y": 22,
      "z": -2,
      "name": "Plant_Vine_Wall_Dead",
      "support": 15,
      "rotation": 3
    },
    {
      "x": -12,
      "y": 3,
      "z": -1,
      "name": "Necrotic_Mud"
    },
    {
      "x": -12,
      "y": 4,
      "z": -1,
      "name": "Necrotic_Mud"
    },
    {
      "x": -12,
      "y": 5,
      "z": -1,
      "name": "Necrotic_Sand"
    },
    {
      "x": -12,
      "y": 6,
      "z": -1,
      "name": "Necrotic_Sand"
    },
    {
      "x": -12,
      "y": 7,
      "z": -1,
      "name": "Necrotic_Sand"
    },
    {
      "x": -12,
      "y": 8,
      "z": -1,
      "name": "Necrotic_Sand"
    },
    {
      "x": -12,
      "y": 9,
      "z": -1,
      "name": "Necrotic_Sand"
    },
    {
      "x": -12,
      "y": 10,
      "z": -1,
      "name": "Necrotic_Sand"
    },
    {
      "x": -12,
      "y": 11,
      "z": -1,
      "name": "Necrotic_Sand"
    },
    {
      "x": -12,
      "y": 12,
      "z": -1,
      "name": "Necrotic_Sand"
    },
    {
      "x": -12,
      "y": 13,
      "z": -1,
      "name": "Necrotic_Sand"
    },
    {
      "x": -12,
      "y": 14,
      "z": -1,
      "name": "Necrotic_Sand"
    },
    {
      "x": -12,
      "y": 15,
      "z": -1,
      "name": "Necrotic_Sand"
    },
    {
      "x": -12,
      "y": 16,
      "z": -1,
      "name": "Necrotic_Sand"
    },
    {
      "x": -12,
      "y": 17,
      "z": -1,
      "name": "Necrotic_Sand"
    },
    {
      "x": -12,
      "y": 18,
      "z": -1,
      "name": "Necrotic_Sand"
    },
    {
      "x": -12,
      "y": 19,
      "z": -1,
      "name": "Necrotic_Sand"
    },
    {
      "x": -12,
      "y": 20,
      "z": -1,
      "name": "Necrotic_Sand"
    },
    {
      "x": -12,
      "y": 21,
      "z": -1,
      "name": "Rock_Slate_Stalactite_Large"
    },
    {
      "x": -12,
      "y": 22,
      "z": -1,
      "name": "Rock_Slate_Stalactite_Large",
      "filler": 1024
    },
    {
      "x": -12,
      "y": 3,
      "z": 0,
      "name": "Necrotic_Stone_Deep"
    },
    {
      "x": -12,
      "y": 4,
      "z": 0,
      "name": "Necrotic_Mud"
    },
    {
      "x": -12,
      "y": 5,
      "z": 0,
      "name": "Necrotic_Sand"
    },
    {
      "x": -12,
      "y": 6,
      "z": 0,
      "name": "Necrotic_Sand"
    },
    {
      "x": -12,
      "y": 7,
      "z": 0,
      "name": "Necrotic_Sand"
    },
    {
      "x": -12,
      "y": 8,
      "z": 0,
      "name": "Necrotic_Sand"
    },
    {
      "x": -12,
      "y": 9,
      "z": 0,
      "name": "Necrotic_Sand"
    },
    {
      "x": -12,
      "y": 10,
      "z": 0,
      "name": "Necrotic_Sand"
    },
    {
      "x": -12,
      "y": 11,
      "z": 0,
      "name": "Necrotic_Sand"
    },
    {
      "x": -12,
      "y": 12,
      "z": 0,
      "name": "Necrotic_Sand"
    },
    {
      "x": -12,
      "y": 13,
      "z": 0,
      "name": "Necrotic_Sand"
    },
    {
      "x": -12,
      "y": 14,
      "z": 0,
      "name": "Necrotic_Sand"
    },
    {
      "x": -12,
      "y": 15,
      "z": 0,
      "name": "Necrotic_Stone"
    },
    {
      "x": -12,
      "y": 16,
      "z": 0,
      "name": "Necrotic_Sand"
    },
    {
      "x": -12,
      "y": 17,
      "z": 0,
      "name": "Necrotic_Sand"
    },
    {
      "x": -12,
      "y": 18,
      "z": 0,
      "name": "Necrotic_Sand"
    },
    {
      "x": -12,
      "y": 19,
      "z": 0,
      "name": "Necrotic_Sand"
    },
    {
      "x": -12,
      "y": 3,
      "z": 1,
      "name": "Necrotic_Stone_Deep"
    },
    {
      "x": -12,
      "y": 4,
      "z": 1,
      "name": "Necrotic_Mud"
    },
    {
      "x": -12,
      "y": 5,
      "z": 1,
      "name": "Necrotic_Sand"
    },
    {
      "x": -12,
      "y": 6,
      "z": 1,
      "name": "Necrotic_Sand"
    },
    {
      "x": -12,
      "y": 7,
      "z": 1,
      "name": "Necrotic_Sand"
    },
    {
      "x": -12,
      "y": 8,
      "z": 1,
      "name": "Necrotic_Sand"
    },
    {
      "x": -12,
      "y": 9,
      "z": 1,
      "name": "Necrotic_Sand"
    },
    {
      "x": -12,
      "y": 10,
      "z": 1,
      "name": "Necrotic_Sand"
    },
    {
      "x": -12,
      "y": 11,
      "z": 1,
      "name": "Necrotic_Sand"
    },
    {
      "x": -12,
      "y": 12,
      "z": 1,
      "name": "Necrotic_Mud"
    },
    {
      "x": -12,
      "y": 13,
      "z": 1,
      "name": "Necrotic_Sand"
    },
    {
      "x": -12,
      "y": 14,
      "z": 1,
      "name": "Necrotic_Dirt"
    },
    {
      "x": -12,
      "y": 15,
      "z": 1,
      "name": "Necrotic_Stone"
    },
    {
      "x": -12,
      "y": 16,
      "z": 1,
      "name": "Necrotic_Dirt"
    },
    {
      "x": -12,
      "y": 17,
      "z": 1,
      "name": "Necrotic_Sand"
    },
    {
      "x": -12,
      "y": 18,
      "z": 1,
      "name": "Necrotic_Dirt"
    },
    {
      "x": -12,
      "y": 3,
      "z": 2,
      "name": "Necrotic_Mud"
    },
    {
      "x": -12,
      "y": 4,
      "z": 2,
      "name": "Necrotic_Stone_Deep"
    },
    {
      "x": -12,
      "y": 5,
      "z": 2,
      "name": "Necrotic_Sand"
    },
    {
      "x": -12,
      "y": 6,
      "z": 2,
      "name": "Necrotic_Sand"
    },
    {
      "x": -12,
      "y": 7,
      "z": 2,
      "name": "Necrotic_Sand"
    },
    {
      "x": -12,
      "y": 8,
      "z": 2,
      "name": "Necrotic_Sand"
    },
    {
      "x": -12,
      "y": 9,
      "z": 2,
      "name": "Necrotic_Sand"
    },
    {
      "x": -12,
      "y": 10,
      "z": 2,
      "name": "Necrotic_Sand"
    },
    {
      "x": -12,
      "y": 11,
      "z": 2,
      "name": "Necrotic_Sand"
    },
    {
      "x": -12,
      "y": 12,
      "z": 2,
      "name": "Necrotic_Sand"
    },
    {
      "x": -12,
      "y": 13,
      "z": 2,
      "name": "Necrotic_Sand"
    },
    {
      "x": -12,
      "y": 14,
      "z": 2,
      "name": "Necrotic_Sand"
    },
    {
      "x": -12,
      "y": 15,
      "z": 2,
      "name": "Necrotic_Sand"
    },
    {
      "x": -12,
      "y": 16,
      "z": 2,
      "name": "Necrotic_Stone"
    },
    {
      "x": -12,
      "y": 17,
      "z": 2,
      "name": "Necrotic_Sand"
    },
    {
      "x": -12,
      "y": 3,
      "z": 3,
      "name": "Necrotic_Mud"
    },
    {
      "x": -12,
      "y": 4,
      "z": 3,
      "name": "Necrotic_Mud"
    },
    {
      "x": -12,
      "y": 5,
      "z": 3,
      "name": "Necrotic_Mud"
    },
    {
      "x": -12,
      "y": 6,
      "z": 3,
      "name": "Necrotic_Sand"
    },
    {
      "x": -12,
      "y": 7,
      "z": 3,
      "name": "Necrotic_Sand"
    },
    {
      "x": -12,
      "y": 8,
      "z": 3,
      "name": "Necrotic_Sand"
    },
    {
      "x": -12,
      "y": 9,
      "z": 3,
      "name": "Necrotic_Sand"
    },
    {
      "x": -12,
      "y": 10,
      "z": 3,
      "name": "Necrotic_Sand"
    },
    {
      "x": -12,
      "y": 11,
      "z": 3,
      "name": "Necrotic_Sand"
    },
    {
      "x": -12,
      "y": 12,
      "z": 3,
      "name": "Necrotic_Sand"
    },
    {
      "x": -12,
      "y": 13,
      "z": 3,
      "name": "Necrotic_Dirt"
    },
    {
      "x": -12,
      "y": 14,
      "z": 3,
      "name": "Necrotic_Sand"
    },
    {
      "x": -12,
      "y": 15,
      "z": 3,
      "name": "Necrotic_Sand"
    },
    {
      "x": -12,
      "y": 16,
      "z": 3,
      "name": "Necrotic_Sand"
    },
    {
      "x": -12,
      "y": 17,
      "z": 3,
      "name": "Plant_Vine_Wall_Dead",
      "support": 15,
      "rotation": 3
    },
    {
      "x": -12,
      "y": 3,
      "z": 4,
      "name": "Necrotic_Mud"
    },
    {
      "x": -12,
      "y": 4,
      "z": 4,
      "name": "Necrotic_Stone_Deep"
    },
    {
      "x": -12,
      "y": 5,
      "z": 4,
      "name": "Necrotic_Stone_Deep"
    },
    {
      "x": -12,
      "y": 6,
      "z": 4,
      "name": "Necrotic_Sand"
    },
    {
      "x": -12,
      "y": 7,
      "z": 4,
      "name": "Necrotic_Sand"
    },
    {
      "x": -12,
      "y": 8,
      "z": 4,
      "name": "Necrotic_Sand"
    },
    {
      "x": -12,
      "y": 9,
      "z": 4,
      "name": "Necrotic_Sand"
    },
    {
      "x": -12,
      "y": 10,
      "z": 4,
      "name": "Necrotic_Sand"
    },
    {
      "x": -12,
      "y": 11,
      "z": 4,
      "name": "Necrotic_Sand"
    },
    {
      "x": -12,
      "y": 12,
      "z": 4,
      "name": "Necrotic_Mud"
    },
    {
      "x": -12,
      "y": 13,
      "z": 4,
      "name": "Necrotic_Sand"
    },
    {
      "x": -12,
      "y": 14,
      "z": 4,
      "name": "Necrotic_Sand"
    },
    {
      "x": -12,
      "y": 15,
      "z": 4,
      "name": "Necrotic_Sand"
    },
    {
      "x": -12,
      "y": 3,
      "z": 5,
      "name": "Necrotic_Mud"
    },
    {
      "x": -12,
      "y": 4,
      "z": 5,
      "name": "Necrotic_Stone_Deep"
    },
    {
      "x": -12,
      "y": 5,
      "z": 5,
      "name": "Necrotic_Mud"
    },
    {
      "x": -12,
      "y": 6,
      "z": 5,
      "name": "Necrotic_Sand"
    },
    {
      "x": -12,
      "y": 7,
      "z": 5,
      "name": "Necrotic_Sand"
    },
    {
      "x": -12,
      "y": 8,
      "z": 5,
      "name": "Necrotic_Sand"
    },
    {
      "x": -12,
      "y": 9,
      "z": 5,
      "name": "Necrotic_Sand"
    },
    {
      "x": -12,
      "y": 10,
      "z": 5,
      "name": "Necrotic_Sand"
    },
    {
      "x": -12,
      "y": 11,
      "z": 5,
      "name": "Necrotic_Sand"
    },
    {
      "x": -12,
      "y": 12,
      "z": 5,
      "name": "Necrotic_Dirt"
    },
    {
      "x": -12,
      "y": 13,
      "z": 5,
      "name": "Necrotic_Sand"
    },
    {
      "x": -12,
      "y": 14,
      "z": 5,
      "name": "Necrotic_Dirt"
    },
    {
      "x": -12,
      "y": 15,
      "z": 5,
      "name": "Necrotic_Sand"
    },
    {
      "x": -12,
      "y": 16,
      "z": 5,
      "name": "Plant_Vine_Wall_Poisoned",
      "support": 15,
      "rotation": 3
    },
    {
      "x": -12,
      "y": 3,
      "z": 6,
      "name": "Necrotic_Stone_Deep"
    },
    {
      "x": -12,
      "y": 4,
      "z": 6,
      "name": "Necrotic_Mud"
    },
    {
      "x": -12,
      "y": 5,
      "z": 6,
      "name": "Necrotic_Stone_Deep"
    },
    {
      "x": -12,
      "y": 6,
      "z": 6,
      "name": "Necrotic_Sand"
    },
    {
      "x": -12,
      "y": 7,
      "z": 6,
      "name": "Necrotic_Sand"
    },
    {
      "x": -12,
      "y": 8,
      "z": 6,
      "name": "Necrotic_Sand"
    },
    {
      "x": -12,
      "y": 9,
      "z": 6,
      "name": "Necrotic_Sand"
    },
    {
      "x": -12,
      "y": 10,
      "z": 6,
      "name": "Necrotic_Sand"
    },
    {
      "x": -12,
      "y": 11,
      "z": 6,
      "name": "Necrotic_Sand"
    },
    {
      "x": -12,
      "y": 12,
      "z": 6,
      "name": "Necrotic_Mud"
    },
    {
      "x": -12,
      "y": 13,
      "z": 6,
      "name": "Necrotic_Dirt"
    },
    {
      "x": -12,
      "y": 14,
      "z": 6,
      "name": "Necrotic_Sand"
    },
    {
      "x": -12,
      "y": 4,
      "z": 7,
      "name": "Necrotic_Stone_Deep"
    },
    {
      "x": -12,
      "y": 5,
      "z": 7,
      "name": "Necrotic_Mud"
    },
    {
      "x": -12,
      "y": 6,
      "z": 7,
      "name": "Necrotic_Sand"
    },
    {
      "x": -12,
      "y": 7,
      "z": 7,
      "name": "Necrotic_Sand"
    },
    {
      "x": -12,
      "y": 8,
      "z": 7,
      "name": "Necrotic_Sand"
    },
    {
      "x": -12,
      "y": 9,
      "z": 7,
      "name": "Necrotic_Sand"
    },
    {
      "x": -12,
      "y": 10,
      "z": 7,
      "name": "Necrotic_Sand"
    },
    {
      "x": -12,
      "y": 11,
      "z": 7,
      "name": "Necrotic_Sand"
    },
    {
      "x": -12,
      "y": 12,
      "z": 7,
      "name": "Necrotic_Sand"
    },
    {
      "x": -12,
      "y": 13,
      "z": 7,
      "name": "Necrotic_Sand"
    },
    {
      "x": -12,
      "y": 14,
      "z": 7,
      "name": "Necrotic_Sand"
    },
    {
      "x": -12,
      "y": 15,
      "z": 7,
      "name": "Necrotic_Grass"
    },
    {
      "x": -12,
      "y": 4,
      "z": 8,
      "name": "Necrotic_Stone_Deep"
    },
    {
      "x": -12,
      "y": 5,
      "z": 8,
      "name": "Necrotic_Stone_Deep"
    },
    {
      "x": -12,
      "y": 6,
      "z": 8,
      "name": "Necrotic_Sand"
    },
    {
      "x": -12,
      "y": 7,
      "z": 8,
      "name": "Necrotic_Sand"
    },
    {
      "x": -12,
      "y": 8,
      "z": 8,
      "name": "Necrotic_Sand"
    },
    {
      "x": -12,
      "y": 9,
      "z": 8,
      "name": "Necrotic_Sand"
    },
    {
      "x": -12,
      "y": 10,
      "z": 8,
      "name": "Necrotic_Sand"
    },
    {
      "x": -12,
      "y": 11,
      "z": 8,
      "name": "Necrotic_Sand"
    },
    {
      "x": -12,
      "y": 12,
      "z": 8,
      "name": "Necrotic_Mud"
    },
    {
      "x": -12,
      "y": 13,
      "z": 8,
      "name": "Necrotic_Sand"
    },
    {
      "x": -12,
      "y": 14,
      "z": 8,
      "name": "Necrotic_Sand"
    },
    {
      "x": -12,
      "y": 15,
      "z": 8,
      "name": "Necrotic_Sand"
    },
    {
      "x": -12,
      "y": 16,
      "z": 8,
      "name": "Plant_Crop_Mushroom_Flatcap_Green",
      "components": {
        "Components": {
          "FarmingBlock": {
            "LastTickGameTime": "0001-01-01T12:00:00Z"
          }
        }
      }
    },
    {
      "x": -12,
      "y": 4,
      "z": 9,
      "name": "Necrotic_Stone_Deep"
    },
    {
      "x": -12,
      "y": 5,
      "z": 9,
      "name": "Necrotic_Mud"
    },
    {
      "x": -12,
      "y": 6,
      "z": 9,
      "name": "Necrotic_Sand"
    },
    {
      "x": -12,
      "y": 7,
      "z": 9,
      "name": "Necrotic_Sand"
    },
    {
      "x": -12,
      "y": 8,
      "z": 9,
      "name": "Necrotic_Sand"
    },
    {
      "x": -12,
      "y": 9,
      "z": 9,
      "name": "Necrotic_Sand"
    },
    {
      "x": -12,
      "y": 10,
      "z": 9,
      "name": "Necrotic_Sand"
    },
    {
      "x": -12,
      "y": 11,
      "z": 9,
      "name": "Necrotic_Sand"
    },
    {
      "x": -12,
      "y": 12,
      "z": 9,
      "name": "Necrotic_Sand"
    },
    {
      "x": -12,
      "y": 13,
      "z": 9,
      "name": "Necrotic_Sand"
    },
    {
      "x": -12,
      "y": 14,
      "z": 9,
      "name": "Rock_Slate_Stalactite_Large"
    },
    {
      "x": -12,
      "y": 15,
      "z": 9,
      "name": "Rock_Slate_Stalactite_Large",
      "filler": 1024
    },
    {
      "x": -12,
      "y": 4,
      "z": 10,
      "name": "Necrotic_Stone_Deep"
    },
    {
      "x": -12,
      "y": 5,
      "z": 10,
      "name": "Necrotic_Sand"
    },
    {
      "x": -12,
      "y": 6,
      "z": 10,
      "name": "Necrotic_Sand"
    },
    {
      "x": -12,
      "y": 7,
      "z": 10,
      "name": "Necrotic_Sand"
    },
    {
      "x": -12,
      "y": 8,
      "z": 10,
      "name": "Necrotic_Sand"
    },
    {
      "x": -12,
      "y": 9,
      "z": 10,
      "name": "Necrotic_Sand"
    },
    {
      "x": -12,
      "y": 10,
      "z": 10,
      "name": "Necrotic_Sand"
    },
    {
      "x": -12,
      "y": 11,
      "z": 10,
      "name": "Necrotic_Sand"
    },
    {
      "x": -12,
      "y": 12,
      "z": 10,
      "name": "Necrotic_Sand"
    },
    {
      "x": -12,
      "y": 13,
      "z": 10,
      "name": "Necrotic_Sand"
    },
    {
      "x": -12,
      "y": 4,
      "z": 11,
      "name": "Necrotic_Stone_Deep"
    },
    {
      "x": -12,
      "y": 5,
      "z": 11,
      "name": "Necrotic_Sand"
    },
    {
      "x": -12,
      "y": 6,
      "z": 11,
      "name": "Necrotic_Sand"
    },
    {
      "x": -12,
      "y": 7,
      "z": 11,
      "name": "Necrotic_Sand"
    },
    {
      "x": -12,
      "y": 8,
      "z": 11,
      "name": "Necrotic_Sand"
    },
    {
      "x": -12,
      "y": 9,
      "z": 11,
      "name": "Necrotic_Sand"
    },
    {
      "x": -12,
      "y": 10,
      "z": 11,
      "name": "Necrotic_Sand"
    },
    {
      "x": -12,
      "y": 11,
      "z": 11,
      "name": "Necrotic_Stone"
    },
    {
      "x": -12,
      "y": 12,
      "z": 11,
      "name": "Necrotic_Sand"
    },
    {
      "x": -12,
      "y": 13,
      "z": 11,
      "name": "Necrotic_Sand"
    },
    {
      "x": -12,
      "y": 14,
      "z": 11,
      "name": "Rubble_Slate"
    },
    {
      "x": -12,
      "y": 4,
      "z": 12,
      "name": "Necrotic_Mud"
    },
    {
      "x": -12,
      "y": 5,
      "z": 12,
      "name": "Necrotic_Sand"
    },
    {
      "x": -12,
      "y": 6,
      "z": 12,
      "name": "Necrotic_Sand"
    },
    {
      "x": -12,
      "y": 7,
      "z": 12,
      "name": "Necrotic_Sand"
    },
    {
      "x": -12,
      "y": 8,
      "z": 12,
      "name": "Necrotic_Sand"
    },
    {
      "x": -12,
      "y": 9,
      "z": 12,
      "name": "Necrotic_Sand"
    },
    {
      "x": -12,
      "y": 10,
      "z": 12,
      "name": "Necrotic_Sand"
    },
    {
      "x": -12,
      "y": 11,
      "z": 12,
      "name": "Necrotic_Sand"
    },
    {
      "x": -12,
      "y": 12,
      "z": 12,
      "name": "Necrotic_Mud"
    },
    {
      "x": -12,
      "y": 13,
      "z": 12,
      "name": "Necrotic_Sand"
    },
    {
      "x": -12,
      "y": 14,
      "z": 12,
      "name": "Necrotic_Grass"
    },
    {
      "x": -12,
      "y": 4,
      "z": 13,
      "name": "Necrotic_Stone_Deep"
    },
    {
      "x": -12,
      "y": 5,
      "z": 13,
      "name": "Necrotic_Sand"
    },
    {
      "x": -12,
      "y": 6,
      "z": 13,
      "name": "Necrotic_Sand"
    },
    {
      "x": -12,
      "y": 7,
      "z": 13,
      "name": "Necrotic_Sand"
    },
    {
      "x": -12,
      "y": 8,
      "z": 13,
      "name": "Necrotic_Sand"
    },
    {
      "x": -12,
      "y": 9,
      "z": 13,
      "name": "Necrotic_Sand"
    },
    {
      "x": -12,
      "y": 10,
      "z": 13,
      "name": "Necrotic_Sand"
    },
    {
      "x": -12,
      "y": 11,
      "z": 13,
      "name": "Necrotic_Sand"
    },
    {
      "x": -12,
      "y": 12,
      "z": 13,
      "name": "Necrotic_Stone"
    },
    {
      "x": -12,
      "y": 13,
      "z": 13,
      "name": "Necrotic_Sand"
    },
    {
      "x": -12,
      "y": 14,
      "z": 13,
      "name": "Prickly_Bush"
    },
    {
      "x": -12,
      "y": 5,
      "z": 14,
      "name": "Necrotic_Sand"
    },
    {
      "x": -12,
      "y": 6,
      "z": 14,
      "name": "Necrotic_Sand"
    },
    {
      "x": -12,
      "y": 7,
      "z": 14,
      "name": "Necrotic_Sand"
    },
    {
      "x": -12,
      "y": 8,
      "z": 14,
      "name": "Necrotic_Sand"
    },
    {
      "x": -12,
      "y": 9,
      "z": 14,
      "name": "Necrotic_Sand"
    },
    {
      "x": -12,
      "y": 10,
      "z": 14,
      "name": "Necrotic_Sand"
    },
    {
      "x": -12,
      "y": 11,
      "z": 14,
      "name": "Necrotic_Stone"
    },
    {
      "x": -12,
      "y": 12,
      "z": 14,
      "name": "Necrotic_Stone"
    },
    {
      "x": -12,
      "y": 5,
      "z": 15,
      "name": "Necrotic_Sand"
    },
    {
      "x": -12,
      "y": 6,
      "z": 15,
      "name": "Necrotic_Sand"
    },
    {
      "x": -12,
      "y": 7,
      "z": 15,
      "name": "Necrotic_Sand"
    },
    {
      "x": -12,
      "y": 8,
      "z": 15,
      "name": "Necrotic_Sand"
    },
    {
      "x": -12,
      "y": 9,
      "z": 15,
      "name": "Necrotic_Sand"
    },
    {
      "x": -12,
      "y": 10,
      "z": 15,
      "name": "Necrotic_Sand"
    },
    {
      "x": -12,
      "y": 11,
      "z": 15,
      "name": "Necrotic_Stone"
    },
    {
      "x": -12,
      "y": 12,
      "z": 15,
      "name": "Necrotic_Stone"
    },
    {
      "x": -12,
      "y": 5,
      "z": 16,
      "name": "Necrotic_Sand"
    },
    {
      "x": -12,
      "y": 6,
      "z": 16,
      "name": "Necrotic_Sand"
    },
    {
      "x": -12,
      "y": 7,
      "z": 16,
      "name": "Necrotic_Sand"
    },
    {
      "x": -12,
      "y": 8,
      "z": 16,
      "name": "Necrotic_Sand"
    },
    {
      "x": -12,
      "y": 9,
      "z": 16,
      "name": "Necrotic_Sand"
    },
    {
      "x": -12,
      "y": 10,
      "z": 16,
      "name": "Necrotic_Sand"
    },
    {
      "x": -12,
      "y": 11,
      "z": 16,
      "name": "Necrotic_Stone"
    },
    {
      "x": -12,
      "y": 12,
      "z": 16,
      "name": "Necrotic_Mud"
    },
    {
      "x": -12,
      "y": 6,
      "z": 17,
      "name": "Necrotic_Sand"
    },
    {
      "x": -12,
      "y": 7,
      "z": 17,
      "name": "Necrotic_Sand"
    },
    {
      "x": -12,
      "y": 8,
      "z": 17,
      "name": "Necrotic_Sand"
    },
    {
      "x": -12,
      "y": 9,
      "z": 17,
      "name": "Necrotic_Sand"
    },
    {
      "x": -12,
      "y": 10,
      "z": 17,
      "name": "Necrotic_Stone"
    },
    {
      "x": -12,
      "y": 11,
      "z": 17,
      "name": "Necrotic_Stone"
    },
    {
      "x": -12,
      "y": 6,
      "z": 18,
      "name": "Necrotic_Sand"
    },
    {
      "x": -12,
      "y": 7,
      "z": 18,
      "name": "Necrotic_Sand"
    },
    {
      "x": -12,
      "y": 8,
      "z": 18,
      "name": "Necrotic_Sand"
    },
    {
      "x": -12,
      "y": 9,
      "z": 18,
      "name": "Necrotic_Sand"
    },
    {
      "x": -12,
      "y": 10,
      "z": 18,
      "name": "Necrotic_Stone"
    },
    {
      "x": -12,
      "y": 11,
      "z": 18,
      "name": "Necrotic_Mud"
    },
    {
      "x": -12,
      "y": 6,
      "z": 19,
      "name": "Necrotic_Sand"
    },
    {
      "x": -12,
      "y": 7,
      "z": 19,
      "name": "Necrotic_Sand"
    },
    {
      "x": -12,
      "y": 8,
      "z": 19,
      "name": "Necrotic_Sand"
    },
    {
      "x": -12,
      "y": 9,
      "z": 19,
      "name": "Necrotic_Sand"
    },
    {
      "x": -12,
      "y": 10,
      "z": 19,
      "name": "Necrotic_Mud"
    },
    {
      "x": -12,
      "y": 11,
      "z": 19,
      "name": "Necrotic_Mud"
    },
    {
      "x": -12,
      "y": 6,
      "z": 20,
      "name": "Necrotic_Sand"
    },
    {
      "x": -12,
      "y": 7,
      "z": 20,
      "name": "Necrotic_Sand"
    },
    {
      "x": -12,
      "y": 8,
      "z": 20,
      "name": "Necrotic_Sand"
    },
    {
      "x": -12,
      "y": 9,
      "z": 20,
      "name": "Necrotic_Sand"
    },
    {
      "x": -12,
      "y": 10,
      "z": 20,
      "name": "Necrotic_Stone"
    },
    {
      "x": -12,
      "y": 6,
      "z": 21,
      "name": "Necrotic_Sand"
    },
    {
      "x": -12,
      "y": 7,
      "z": 21,
      "name": "Necrotic_Sand"
    },
    {
      "x": -12,
      "y": 8,
      "z": 21,
      "name": "Necrotic_Sand"
    },
    {
      "x": -12,
      "y": 9,
      "z": 21,
      "name": "Necrotic_Sand"
    },
    {
      "x": -12,
      "y": 10,
      "z": 21,
      "name": "Necrotic_Stone"
    },
    {
      "x": -12,
      "y": 7,
      "z": 22,
      "name": "Necrotic_Sand"
    },
    {
      "x": -12,
      "y": 8,
      "z": 22,
      "name": "Necrotic_Sand"
    },
    {
      "x": -12,
      "y": 9,
      "z": 22,
      "name": "Necrotic_Sand"
    },
    {
      "x": -12,
      "y": 10,
      "z": 22,
      "name": "Necrotic_Mud"
    },
    {
      "x": -12,
      "y": 7,
      "z": 23,
      "name": "Necrotic_Sand"
    },
    {
      "x": -12,
      "y": 8,
      "z": 23,
      "name": "Necrotic_Sand"
    },
    {
      "x": -12,
      "y": 9,
      "z": 23,
      "name": "Necrotic_Sand"
    },
    {
      "x": -12,
      "y": 10,
      "z": 23,
      "name": "Necrotic_Sand"
    },
    {
      "x": -12,
      "y": 6,
      "z": 24,
      "name": "Necrotic_Sand"
    },
    {
      "x": -12,
      "y": 7,
      "z": 24,
      "name": "Necrotic_Sand"
    },
    {
      "x": -12,
      "y": 8,
      "z": 24,
      "name": "Necrotic_Sand"
    },
    {
      "x": -12,
      "y": 9,
      "z": 24,
      "name": "Necrotic_Sand"
    },
    {
      "x": -12,
      "y": 7,
      "z": 25,
      "name": "Necrotic_Sand"
    },
    {
      "x": -12,
      "y": 8,
      "z": 25,
      "name": "Necrotic_Sand"
    },
    {
      "x": -11,
      "y": 8,
      "z": -21,
      "name": "Necrotic_Sand"
    },
    {
      "x": -11,
      "y": 6,
      "z": -20,
      "name": "Necrotic_Sand"
    },
    {
      "x": -11,
      "y": 7,
      "z": -20,
      "name": "Necrotic_Sand"
    },
    {
      "x": -11,
      "y": 8,
      "z": -20,
      "name": "Necrotic_Sand"
    },
    {
      "x": -11,
      "y": 9,
      "z": -20,
      "name": "Necrotic_Sand"
    },
    {
      "x": -11,
      "y": 6,
      "z": -19,
      "name": "Necrotic_Sand"
    },
    {
      "x": -11,
      "y": 7,
      "z": -19,
      "name": "Necrotic_Sand"
    },
    {
      "x": -11,
      "y": 8,
      "z": -19,
      "name": "Necrotic_Sand"
    },
    {
      "x": -11,
      "y": 9,
      "z": -19,
      "name": "Necrotic_Sand"
    },
    {
      "x": -11,
      "y": 10,
      "z": -19,
      "name": "Necrotic_Sand"
    },
    {
      "x": -11,
      "y": 5,
      "z": -18,
      "name": "Necrotic_Sand"
    },
    {
      "x": -11,
      "y": 6,
      "z": -18,
      "name": "Necrotic_Sand"
    },
    {
      "x": -11,
      "y": 7,
      "z": -18,
      "name": "Necrotic_Sand"
    },
    {
      "x": -11,
      "y": 8,
      "z": -18,
      "name": "Necrotic_Sand"
    },
    {
      "x": -11,
      "y": 9,
      "z": -18,
      "name": "Necrotic_Sand"
    },
    {
      "x": -11,
      "y": 10,
      "z": -18,
      "name": "Necrotic_Sand"
    },
    {
      "x": -11,
      "y": 11,
      "z": -18,
      "name": "Necrotic_Sand"
    },
    {
      "x": -11,
      "y": 5,
      "z": -17,
      "name": "Necrotic_Sand"
    },
    {
      "x": -11,
      "y": 6,
      "z": -17,
      "name": "Necrotic_Sand"
    },
    {
      "x": -11,
      "y": 7,
      "z": -17,
      "name": "Necrotic_Sand"
    },
    {
      "x": -11,
      "y": 8,
      "z": -17,
      "name": "Necrotic_Sand"
    },
    {
      "x": -11,
      "y": 9,
      "z": -17,
      "name": "Necrotic_Sand"
    },
    {
      "x": -11,
      "y": 10,
      "z": -17,
      "name": "Necrotic_Sand"
    },
    {
      "x": -11,
      "y": 11,
      "z": -17,
      "name": "Necrotic_Sand"
    },
    {
      "x": -11,
      "y": 12,
      "z": -17,
      "name": "Necrotic_Sand"
    },
    {
      "x": -11,
      "y": 13,
      "z": -17,
      "name": "Necrotic_Grass"
    },
    {
      "x": -11,
      "y": 4,
      "z": -16,
      "name": "Necrotic_Sand"
    },
    {
      "x": -11,
      "y": 5,
      "z": -16,
      "name": "Necrotic_Sand"
    },
    {
      "x": -11,
      "y": 6,
      "z": -16,
      "name": "Necrotic_Sand"
    },
    {
      "x": -11,
      "y": 7,
      "z": -16,
      "name": "Necrotic_Sand"
    },
    {
      "x": -11,
      "y": 8,
      "z": -16,
      "name": "Necrotic_Sand"
    },
    {
      "x": -11,
      "y": 9,
      "z": -16,
      "name": "Necrotic_Sand"
    },
    {
      "x": -11,
      "y": 10,
      "z": -16,
      "name": "Necrotic_Sand"
    },
    {
      "x": -11,
      "y": 11,
      "z": -16,
      "name": "Necrotic_Sand"
    },
    {
      "x": -11,
      "y": 12,
      "z": -16,
      "name": "Necrotic_Sand"
    },
    {
      "x": -11,
      "y": 13,
      "z": -16,
      "name": "Necrotic_Sand"
    },
    {
      "x": -11,
      "y": 4,
      "z": -15,
      "name": "Necrotic_Sand"
    },
    {
      "x": -11,
      "y": 5,
      "z": -15,
      "name": "Necrotic_Sand"
    },
    {
      "x": -11,
      "y": 6,
      "z": -15,
      "name": "Necrotic_Sand"
    },
    {
      "x": -11,
      "y": 7,
      "z": -15,
      "name": "Necrotic_Sand"
    },
    {
      "x": -11,
      "y": 8,
      "z": -15,
      "name": "Necrotic_Sand"
    },
    {
      "x": -11,
      "y": 9,
      "z": -15,
      "name": "Necrotic_Sand"
    },
    {
      "x": -11,
      "y": 10,
      "z": -15,
      "name": "Necrotic_Sand"
    },
    {
      "x": -11,
      "y": 11,
      "z": -15,
      "name": "Necrotic_Sand"
    },
    {
      "x": -11,
      "y": 12,
      "z": -15,
      "name": "Necrotic_Sand"
    },
    {
      "x": -11,
      "y": 13,
      "z": -15,
      "name": "Necrotic_Sand"
    },
    {
      "x": -11,
      "y": 4,
      "z": -14,
      "name": "Necrotic_Sand"
    },
    {
      "x": -11,
      "y": 5,
      "z": -14,
      "name": "Necrotic_Sand"
    },
    {
      "x": -11,
      "y": 6,
      "z": -14,
      "name": "Necrotic_Sand"
    },
    {
      "x": -11,
      "y": 7,
      "z": -14,
      "name": "Necrotic_Sand"
    },
    {
      "x": -11,
      "y": 8,
      "z": -14,
      "name": "Necrotic_Sand"
    },
    {
      "x": -11,
      "y": 9,
      "z": -14,
      "name": "Necrotic_Sand"
    },
    {
      "x": -11,
      "y": 10,
      "z": -14,
      "name": "Necrotic_Sand"
    },
    {
      "x": -11,
      "y": 11,
      "z": -14,
      "name": "Necrotic_Sand"
    },
    {
      "x": -11,
      "y": 12,
      "z": -14,
      "name": "Necrotic_Sand"
    },
    {
      "x": -11,
      "y": 13,
      "z": -14,
      "name": "Necrotic_Sand"
    },
    {
      "x": -11,
      "y": 4,
      "z": -13,
      "name": "Necrotic_Sand"
    },
    {
      "x": -11,
      "y": 5,
      "z": -13,
      "name": "Necrotic_Sand"
    },
    {
      "x": -11,
      "y": 6,
      "z": -13,
      "name": "Necrotic_Sand"
    },
    {
      "x": -11,
      "y": 7,
      "z": -13,
      "name": "Necrotic_Sand"
    },
    {
      "x": -11,
      "y": 8,
      "z": -13,
      "name": "Necrotic_Sand"
    },
    {
      "x": -11,
      "y": 9,
      "z": -13,
