{
  "version": 8,
  "blockIdVersion": 11,
  "anchorX": 1,
  "anchorY": 11,
  "anchorZ": 6,
  "blocks": [
    {
      "x": -15,
      "y": 27,
      "z": -2,
      "name": "Wood_Petrified_Branch_Corner",
      "rotation": 3
    },
    {
      "x": -15,
      "y": 28,
      "z": -2,
      "name": "Wood_Petrified_Branch_Corner",
      "rotation": 11
    },
    {
      "x": -14,
      "y": 27,
      "z": -2,
      "name": "Wood_Petrified_Branch_Long",
      "rotation": 5
    },
    {
      "x": -14,
      "y": 30,
      "z": -2,
      "name": "Wood_Petrified_Branch_Corner",
      "rotation": 3
    },
    {
      "x": -14,
      "y": 31,
      "z": -2,
      "name": "Wood_Petrified_Branch_Long"
    },
    {
      "x": -14,
      "y": 32,
      "z": -2,
      "name": "Wood_Petrified_Branch_Corner",
      "rotation": 9
    },
    {
      "x": -13,
      "y": 26,
      "z": -2,
      "name": "Wood_Burnt_Roots"
    },
    {
      "x": -13,
      "y": 27,
      "z": -2,
      "name": "Wood_Petrified_Trunk_Full",
      "support": 2
    },
    {
      "x": -13,
      "y": 28,
      "z": -2,
      "name": "Wood_Petrified_Trunk_Full"
    },
    {
      "x": -13,
      "y": 29,
      "z": -2,
      "name": "Wood_Petrified_Branch_Long"
    },
    {
      "x": -13,
      "y": 30,
      "z": -2,
      "name": "Wood_Petrified_Branch_Corner",
      "rotation": 11
    },
    {
      "x": -13,
      "y": 27,
      "z": -1,
      "name": "Wood_Petrified_Trunk_Full",
      "support": 1
    },
    {
      "x": -12,
      "y": 25,
      "z": -1,
      "name": "Wood_Burnt_Roots"
    },
    {
      "x": -12,
      "y": 26,
      "z": -1,
      "name": "Wood_Petrified_Trunk_Full",
      "support": 4
    },
    {
      "x": -12,
      "y": 27,
      "z": -1,
      "name": "Wood_Petrified_Trunk_Full"
    },
    {
      "x": -12,
      "y": 26,
      "z": 0,
      "name": "Wood_Petrified_Trunk_Full",
      "support": 3
    },
    {
      "x": -12,
      "y": 27,
      "z": 0,
      "name": "Wood_Petrified_Trunk_Full"
    },
    {
      "x": -12,
      "y": 27,
      "z": 1,
      "name": "Plant_Vine_Wall_Poisoned",
      "support": 15,
      "rotation": 3
    },
    {
      "x": -12,
      "y": 28,
      "z": 2,
      "name": "Plant_Vine_Wall_Poisoned",
      "support": 15,
      "rotation": 3
    },
    {
      "x": -12,
      "y": 29,
      "z": 2,
      "name": "Plant_Vine_Wall_Poisoned",
      "support": 15,
      "rotation": 3
    },
    {
      "x": -12,
      "y": 28,
      "z": 3,
      "name": "Wood_Petrified_Trunk_Full",
      "support": 1
    },
    {
      "x": -11,
      "y": 25,
      "z": -1,
      "name": "Wood_Burnt_Roots"
    },
    {
      "x": -11,
      "y": 26,
      "z": -1,
      "name": "Wood_Petrified_Trunk_Full",
      "support": 3
    },
    {
      "x": -11,
      "y": 25,
      "z": 0,
      "name": "Wood_Burnt_Roots"
    },
    {
      "x": -11,
      "y": 26,
      "z": 0,
      "name": "Wood_Petrified_Trunk",
      "support": 2
    },
    {
      "x": -11,
      "y": 27,
      "z": 0,
      "name": "Wood_Petrified_Trunk"
    },
    {
      "x": -11,
      "y": 28,
      "z": 0,
      "name": "Wood_Petrified_Trunk_Full"
    },
    {
      "x": -11,
      "y": 25,
      "z": 1,
      "name": "Wood_Burnt_Roots"
    },
    {
      "x": -11,
      "y": 26,
      "z": 1,
      "name": "Wood_Petrified_Trunk",
      "support": 1
    },
    {
      "x": -11,
      "y": 27,
      "z": 1,
      "name": "Wood_Petrified_Trunk"
    },
    {
      "x": -11,
      "y": 28,
      "z": 1,
      "name": "Wood_Petrified_Trunk"
    },
    {
      "x": -11,
      "y": 29,
      "z": 1,
      "name": "Wood_Petrified_Trunk_Full"
    },
    {
      "x": -11,
      "y": 26,
      "z": 2,
      "name": "Wood_Petrified_Trunk_Full",
      "support": 2
    },
    {
      "x": -11,
      "y": 27,
      "z": 2,
      "name": "Wood_Petrified_Trunk"
    },
    {
      "x": -11,
      "y": 28,
      "z": 2,
      "name": "Wood_Petrified_Trunk"
    },
    {
      "x": -11,
      "y": 29,
      "z": 2,
      "name": "Wood_Petrified_Trunk"
    },
    {
      "x": -11,
      "y": 30,
      "z": 2,
      "name": "Wood_Petrified_Trunk_Full"
    },
    {
      "x": -11,
      "y": 26,
      "z": 3,
      "name": "Plant_Vine_Wall_Poisoned",
      "support": 15
    },
    {
      "x": -11,
      "y": 27,
      "z": 3,
      "name": "Wood_Petrified_Trunk_Full",
      "support": 1
    },
    {
      "x": -11,
      "y": 28,
      "z": 3,
      "name": "Wood_Petrified_Trunk"
    },
    {
      "x": -11,
      "y": 29,
      "z": 3,
      "name": "Wood_Petrified_Trunk_Full"
    },
    {
      "x": -11,
      "y": 27,
      "z": 4,
      "name": "Plant_Vine_Wall_Dead",
      "support": 15
    },
    {
      "x": -11,
      "y": 28,
      "z": 4,
      "name": "Plant_Vine_Wall_Poisoned",
      "support": 15
    },
    {
      "x": -10,
      "y": 26,
      "z": 0,
      "name": "Wood_Petrified_Trunk",
      "support": 1
    },
    {
      "x": -10,
      "y": 27,
      "z": 0,
      "name": "Wood_Petrified_Trunk_Full"
    },
    {
      "x": -10,
      "y": 24,
      "z": 1,
      "name": "Wood_Burnt_Roots"
    },
    {
      "x": -10,
      "y": 25,
      "z": 1,
      "name": "Wood_Petrified_Trunk",
      "support": 5
    },
    {
      "x": -10,
      "y": 26,
      "z": 1,
      "name": "Wood_Petrified_Trunk"
    },
    {
      "x": -10,
      "y": 27,
      "z": 1,
      "name": "Wood_Petrified_Trunk"
    },
    {
      "x": -10,
      "y": 28,
      "z": 1,
      "name": "Wood_Petrified_Trunk"
    },
    {
      "x": -10,
      "y": 29,
      "z": 1,
      "name": "Wood_Petrified_Trunk"
    },
    {
      "x": -10,
      "y": 30,
      "z": 1,
      "name": "Wood_Petrified_Trunk_Full"
    },
    {
      "x": -10,
      "y": 25,
      "z": 2,
      "name": "Wood_Burnt_Roots"
    },
    {
      "x": -10,
      "y": 26,
      "z": 2,
      "name": "Wood_Petrified_Trunk_Full",
      "support": 1
    },
    {
      "x": -10,
      "y": 27,
      "z": 2,
      "name": "Wood_Petrified_Trunk"
    },
    {
      "x": -10,
      "y": 28,
      "z": 2,
      "name": "Wood_Petrified_Trunk"
    },
    {
      "x": -10,
      "y": 29,
      "z": 2,
      "name": "Wood_Petrified_Trunk"
    },
    {
      "x": -10,
      "y": 30,
      "z": 2,
      "name": "Wood_Petrified_Trunk"
    },
    {
      "x": -10,
      "y": 31,
      "z": 2,
      "name": "Wood_Petrified_Trunk_Full"
    },
    {
      "x": -10,
      "y": 26,
      "z": 3,
      "name": "Plant_Vine_Wall_Poisoned",
      "support": 15
    },
    {
      "x": -10,
      "y": 27,
      "z": 3,
      "name": "Wood_Petrified_Trunk_Full",
      "support": 1
    },
    {
      "x": -10,
      "y": 28,
      "z": 3,
      "name": "Wood_Petrified_Trunk"
    },
    {
      "x": -10,
      "y": 29,
      "z": 3,
      "name": "Wood_Petrified_Trunk"
    },
    {
      "x": -10,
      "y": 30,
      "z": 3,
      "name": "Wood_Petrified_Trunk_Full"
    },
    {
      "x": -10,
      "y": 27,
      "z": 4,
      "name": "Plant_Vine_Wall_Dead",
      "support": 15
    },
    {
      "x": -10,
      "y": 29,
      "z": 4,
      "name": "Plant_Vine_Wall_Poisoned",
      "support": 15
    },
    {
      "x": -9,
      "y": 24,
      "z": 0,
      "name": "Wood_Burnt_Roots"
    },
    {
      "x": -9,
      "y": 25,
      "z": 0,
      "name": "Wood_Petrified_Trunk",
      "support": 5
    },
    {
      "x": -9,
      "y": 26,
      "z": 0,
      "name": "Wood_Petrified_Trunk_Full"
    },
    {
      "x": -9,
      "y": 31,
      "z": 0,
      "name": "Wood_Petrified_Trunk_Full",
      "support": 1
    },
    {
      "x": -9,
      "y": 36,
      "z": 0,
      "name": "Wood_Petrified_Branch_Corner",
      "rotation": 3
    },
    {
      "x": -9,
      "y": 37,
      "z": 0,
      "name": "Wood_Petrified_Branch_Corner",
      "rotation": 9
    },
    {
      "x": -9,
      "y": 24,
      "z": 1,
      "name": "Long_Roots"
    },
    {
      "x": -9,
      "y": 25,
      "z": 1,
      "name": "Wood_Petrified_Trunk",
      "support": 4
    },
    {
      "x": -9,
      "y": 26,
      "z": 1,
      "name": "Wood_Petrified_Trunk"
    },
    {
      "x": -9,
      "y": 27,
      "z": 1,
      "name": "Wood_Petrified_Trunk_Full"
    },
    {
      "x": -9,
      "y": 30,
      "z": 1,
      "name": "Wood_Petrified_Trunk_Full",
      "support": 1
    },
    {
      "x": -9,
      "y": 31,
      "z": 1,
      "name": "Wood_Petrified_Trunk"
    },
    {
      "x": -9,
      "y": 32,
      "z": 1,
      "name": "Wood_Petrified_Trunk_Full",
      "rotation": 5
    },
    {
      "x": -9,
      "y": 30,
      "z": 2,
      "name": "Wood_Petrified_Trunk_Full",
      "support": 1
    },
    {
      "x": -9,
      "y": 31,
      "z": 2,
      "name": "Wood_Petrified_Trunk_Full"
    },
    {
      "x": -9,
      "y": 30,
      "z": 3,
      "name": "Wood_Petrified_Branch_Corner",
      "rotation": 1
    },
    {
      "x": -9,
      "y": 31,
      "z": 3,
      "name": "Wood_Petrified_Branch_Corner",
      "support": 1,
      "rotation": 9
    },
    {
      "x": -8,
      "y": 31,
      "z": -1,
      "name": "Wood_Petrified_Trunk_Full",
      "support": 3
    },
    {
      "x": -8,
      "y": 32,
      "z": -1,
      "name": "Wood_Petrified_Trunk_Full"
    },
    {
      "x": -8,
      "y": 25,
      "z": 0,
      "name": "Wood_Petrified_Trunk",
      "support": 4
    },
    {
      "x": -8,
      "y": 26,
      "z": 0,
      "name": "Wood_Petrified_Trunk_Full"
    },
    {
      "x": -8,
      "y": 27,
      "z": 0,
      "name": "Plant_Bush_Winter",
      "support": 15
    },
    {
      "x": -8,
      "y": 31,
      "z": 0,
      "name": "Wood_Petrified_Trunk_Full",
      "support": 2
    },
    {
      "x": -8,
      "y": 36,
      "z": 0,
      "name": "Wood_Petrified_Branch_Long",
      "rotation": 5
    },
    {
      "x": -8,
      "y": 37,
      "z": 0,
      "name": "Wood_Petrified_Branch_Corner",
      "rotation": 1
    },
    {
      "x": -8,
      "y": 38,
      "z": 0,
      "name": "Wood_Petrified_Branch_Corner",
      "rotation": 11
    },
    {
      "x": -8,
      "y": 24,
      "z": 1,
      "name": "Wood_Burnt_Roots"
    },
    {
      "x": -8,
      "y": 25,
      "z": 1,
      "name": "Wood_Petrified_Trunk_Full",
      "support": 3
    },
    {
      "x": -8,
      "y": 26,
      "z": 1,
      "name": "Wood_Petrified_Trunk_Full"
    },
    {
      "x": -8,
      "y": 31,
      "z": 1,
      "name": "Wood_Petrified_Trunk_Full",
      "support": 1
    },
    {
      "x": -8,
      "y": 32,
      "z": 1,
      "name": "Wood_Petrified_Trunk_Full"
    },
    {
      "x": -8,
      "y": 25,
      "z": 2,
      "name": "Plant_Vine_Wall_Dead",
      "support": 15
    },
    {
      "x": -8,
      "y": 30,
      "z": 2,
      "name": "Wood_Burnt_Roots"
    },
    {
      "x": -8,
      "y": 31,
      "z": 2,
      "name": "Wood_Petrified_Trunk_Full",
      "support": 1
    },
    {
      "x": -8,
      "y": 32,
      "z": 2,
      "name": "Wood_Petrified_Trunk_Full"
    },
    {
      "x": -8,
      "y": 31,
      "z": 3,
      "name": "Wood_Petrified_Branch_Corner",
      "support": 2,
      "rotation": 1
    },
    {
      "x": -8,
      "y": 32,
      "z": 3,
      "name": "Wood_Petrified_Branch_Corner",
      "support": 3,
      "rotation": 8
    },
    {
      "x": -8,
      "y": 32,
      "z": 4,
      "name": "Wood_Petrified_Branch_Corner",
      "support": 4
    },
    {
      "x": -8,
      "y": 33,
      "z": 4,
      "name": "Wood_Petrified_Branch_Corner",
      "support": 5,
      "rotation": 9
    },
    {
      "x": -7,
      "y": 32,
      "z": -2,
      "name": "Wood_Petrified_Trunk_Full",
      "support": 2
    },
    {
      "x": -7,
      "y": 33,
      "z": -2,
      "name": "Wood_Petrified_Trunk_Full"
    },
    {
      "x": -7,
      "y": 34,
      "z": -2,
      "name": "Wood_Petrified_Branch_Corner",
      "rotation": 9
    },
    {
      "x": -7,
      "y": 32,
      "z": -1,
      "name": "Wood_Petrified_Trunk_Full",
      "support": 1
    },
    {
      "x": -7,
      "y": 24,
      "z": 0,
      "name": "Long_Roots"
    },
    {
      "x": -7,
      "y": 25,
      "z": 0,
      "name": "Wood_Petrified_Trunk_Full",
      "support": 3
    },
    {
      "x": -7,
      "y": 30,
      "z": 0,
      "name": "Wood_Burnt_Roots"
    },
    {
      "x": -7,
      "y": 31,
      "z": 0,
      "name": "Wood_Petrified_Trunk_Full",
      "support": 3
    },
    {
      "x": -7,
      "y": 32,
      "z": 0,
      "name": "Wood_Petrified_Trunk_Full"
    },
    {
      "x": -7,
      "y": 36,
      "z": 0,
      "name": "Wood_Petrified_Trunk_Full",
      "rotation": 5
    },
    {
      "x": -7,
      "y": 17,
      "z": 1,
      "name": "Furniture_Human_Ruins_Lantern_Ceiling"
    },
    {
      "x": -7,
      "y": 18,
      "z": 1,
      "name": "Deco_Iron_Chain_Small"
    },
    {
      "x": -7,
      "y": 19,
      "z": 1,
      "name": "Deco_Iron_Chain_Small"
    },
    {
      "x": -7,
      "y": 20,
      "z": 1,
      "name": "Deco_Iron_Chain_Small"
    },
    {
      "x": -7,
      "y": 21,
      "z": 1,
      "name": "Deco_Iron_Chain_Small"
    },
    {
      "x": -7,
      "y": 22,
      "z": 1,
      "name": "Deco_Iron_Chain_Small"
    },
    {
      "x": -7,
      "y": 23,
      "z": 1,
      "name": "Deco_Iron_Chain_Small"
    },
    {
      "x": -7,
      "y": 24,
      "z": 1,
      "name": "Deco_Iron_Chain_Small"
    },
    {
      "x": -7,
      "y": 25,
      "z": 1,
      "name": "Wood_Petrified_Trunk_Full",
      "support": 2
    },
    {
      "x": -7,
      "y": 31,
      "z": 1,
      "name": "Wood_Petrified_Trunk_Full",
      "support": 2
    },
    {
      "x": -7,
      "y": 32,
      "z": 1,
      "name": "Wood_Petrified_Trunk_Full"
    },
    {
      "x": -7,
      "y": 25,
      "z": 2,
      "name": "Plant_Vine_Wall_Dead",
      "support": 15
    },
    {
      "x": -7,
      "y": 31,
      "z": 2,
      "name": "Wood_Petrified_Trunk_Full",
      "support": 2
    },
    {
      "x": -7,
      "y": 32,
      "z": 2,
      "name": "Wood_Petrified_Trunk_Full"
    },
    {
      "x": -7,
      "y": 31,
      "z": 3,
      "name": "Plant_Vine_Wall_Poisoned",
      "support": 15
    },
    {
      "x": -7,
      "y": 32,
      "z": 3,
      "name": "Plant_Vine_Wall_Poisoned",
      "support": 15
    },
    {
      "x": -7,
      "y": 33,
      "z": 4,
      "name": "Wood_Petrified_Branch_Corner",
      "support": 6,
      "rotation": 1
    },
    {
      "x": -6,
      "y": 34,
      "z": -2,
      "name": "Wood_Petrified_Branch_Corner",
      "rotation": 1
    },
    {
      "x": -6,
      "y": 24,
      "z": 0,
      "name": "Wood_Burnt_Roots"
    },
    {
      "x": -6,
      "y": 25,
      "z": 0,
      "name": "Wood_Petrified_Trunk_Full",
      "support": 2
    },
    {
      "x": -6,
      "y": 30,
      "z": 0,
      "name": "Wood_Burnt_Roots"
    },
    {
      "x": -6,
      "y": 31,
      "z": 0,
      "name": "Wood_Petrified_Trunk_Full",
      "support": 4
    },
    {
      "x": -6,
      "y": 32,
      "z": 0,
      "name": "Wood_Petrified_Trunk_Full"
    },
    {
      "x": -6,
      "y": 36,
      "z": 0,
      "name": "Wood_Petrified_Trunk_Full",
      "rotation": 5
    },
    {
      "x": -6,
      "y": 25,
      "z": 1,
      "name": "Wood_Petrified_Trunk_Full",
      "support": 1
    },
    {
      "x": -6,
      "y": 26,
      "z": 1,
      "name": "Plant_Bush_Winter",
      "support": 15
    },
    {
      "x": -6,
      "y": 28,
      "z": 1,
      "name": "Wood_Petrified_Branch_Corner",
      "support": 2,
      "rotation": 3
    },
    {
      "x": -6,
      "y": 31,
      "z": 1,
      "name": "Wood_Petrified_Trunk_Full",
      "support": 3
    },
    {
      "x": -6,
      "y": 32,
      "z": 1,
      "name": "Wood_Petrified_Trunk_Full"
    },
    {
      "x": -6,
      "y": 36,
      "z": 1,
      "name": "Wood_Petrified_Trunk_Full",
      "rotation": 5
    },
    {
      "x": -6,
      "y": 25,
      "z": 2,
      "name": "Plant_Vine_Wall_Dead",
      "support": 15
    },
    {
      "x": -6,
      "y": 31,
      "z": 2,
      "name": "Plant_Vine_Wall_Poisoned",
      "support": 15
    },
    {
      "x": -6,
      "y": 7,
      "z": 7,
      "name": "Wood_Petrified_Trunk_Full",
      "support": 15,
      "rotation": 5
    },
    {
      "x": -5,
      "y": 27,
      "z": -2,
      "name": "Wood_Burnt_Roots"
    },
    {
      "x": -5,
      "y": 28,
      "z": -2,
      "name": "Wood_Petrified_Trunk_Full",
      "support": 2,
      "rotation": 4
    },
    {
      "x": -5,
      "y": 29,
      "z": -2,
      "name": "Plant_Bush_Winter",
      "support": 15
    },
    {
      "x": -5,
      "y": 25,
      "z": -1,
      "name": "Plant_Vine_Wall_Dead",
      "support": 15,
      "rotation": 2
    },
    {
      "x": -5,
      "y": 28,
      "z": -1,
      "name": "Wood_Petrified_Trunk",
      "support": 1,
      "rotation": 4
    },
    {
      "x": -5,
      "y": 24,
      "z": 0,
      "name": "Plant_Vine_Wall_Dead",
      "support": 15,
      "rotation": 2
    },
    {
      "x": -5,
      "y": 25,
      "z": 0,
      "name": "Wood_Petrified_Trunk_Full",
      "support": 1
    },
    {
      "x": -5,
      "y": 27,
      "z": 0,
      "name": "Wood_Petrified_Trunk_Full",
      "support": 1
    },
    {
      "x": -5,
      "y": 28,
      "z": 0,
      "name": "Wood_Petrified_Trunk_Full",
      "rotation": 4
    },
    {
      "x": -5,
      "y": 24,
      "z": 1,
      "name": "Wood_Petrified_Trunk",
      "support": 5
    },
    {
      "x": -5,
      "y": 25,
      "z": 1,
      "name": "Wood_Petrified_Trunk"
    },
    {
      "x": -5,
      "y": 26,
      "z": 1,
      "name": "Wood_Petrified_Trunk_Full"
    },
    {
      "x": -5,
      "y": 27,
      "z": 1,
      "name": "Wood_Petrified_Branch_Corner",
      "rotation": 3
    },
    {
      "x": -5,
      "y": 28,
      "z": 1,
      "name": "Wood_Petrified_Branch_Corner",
      "support": 1,
      "rotation": 11
    },
    {
      "x": -5,
      "y": 30,
      "z": 1,
      "name": "Wood_Burnt_Roots"
    },
    {
      "x": -5,
      "y": 31,
      "z": 1,
      "name": "Wood_Petrified_Trunk_Full",
      "support": 4
    },
    {
      "x": -5,
      "y": 32,
      "z": 1,
      "name": "Wood_Petrified_Trunk_Full"
    },
    {
      "x": -5,
      "y": 35,
      "z": 1,
      "name": "Wood_Petrified_Trunk_Full",
      "rotation": 5
    },
    {
      "x": -5,
      "y": 36,
      "z": 1,
      "name": "Wood_Petrified_Trunk_Full",
      "rotation": 5
    },
    {
      "x": -5,
      "y": 23,
      "z": 2,
      "name": "Wood_Burnt_Roots"
    },
    {
      "x": -5,
      "y": 24,
      "z": 2,
      "name": "Wood_Petrified_Trunk_Full",
      "support": 4
    },
    {
      "x": -5,
      "y": 25,
      "z": 2,
      "name": "Wood_Petrified_Trunk"
    },
    {
      "x": -5,
      "y": 26,
      "z": 2,
      "name": "Wood_Petrified_Trunk_Full"
    },
    {
      "x": -5,
      "y": 31,
      "z": 2,
      "name": "Plant_Vine_Wall_Poisoned",
      "support": 15
    },
    {
      "x": -5,
      "y": 32,
      "z": 2,
      "name": "Wood_Petrified_Trunk_Full",
      "support": 1
    },
    {
      "x": -5,
      "y": 24,
      "z": 3,
      "name": "Plant_Vine_Wall_Poisoned",
      "support": 15
    },
    {
      "x": -5,
      "y": 32,
      "z": 3,
      "name": "Plant_Vine_Wall_Poisoned",
      "support": 15
    },
    {
      "x": -5,
      "y": 7,
      "z": 6,
      "name": "Wood_Petrified_Trunk_Full",
      "support": 15
    },
    {
      "x": -5,
      "y": 8,
      "z": 6,
      "name": "Wood_Petrified_Trunk",
      "support": 15
    },
    {
      "x": -5,
      "y": 9,
      "z": 6,
      "name": "Wood_Petrified_Trunk",
      "support": 15
    },
    {
      "x": -5,
      "y": 10,
      "z": 6,
      "name": "Wood_Petrified_Trunk_Full"
    },
    {
      "x": -5,
      "y": 4,
      "z": 7,
      "name": "Wood_Burnt_Roots"
    },
    {
      "x": -5,
      "y": 5,
      "z": 7,
      "name": "Wood_Petrified_Trunk",
      "support": 15
    },
    {
      "x": -5,
      "y": 6,
      "z": 7,
      "name": "Wood_Petrified_Trunk",
      "support": 15
    },
    {
      "x": -5,
      "y": 7,
      "z": 7,
      "name": "Wood_Petrified_Trunk",
      "support": 15,
      "rotation": 5
    },
    {
      "x": -4,
      "y": 31,
      "z": -11,
      "name": "Wood_Petrified_Branch_Long",
      "rotation": 4
    },
    {
      "x": -4,
      "y": 30,
      "z": -10,
      "name": "Wood_Petrified_Branch_Corner",
      "rotation": 2
    },
    {
      "x": -4,
      "y": 31,
      "z": -10,
      "name": "Wood_Petrified_Branch_Corner",
      "rotation": 10
    },
    {
      "x": -4,
      "y": 30,
      "z": -9,
      "name": "Wood_Petrified_Branch_Long",
      "rotation": 4
    },
    {
      "x": -4,
      "y": 29,
      "z": -8,
      "name": "Wood_Burnt_Roots"
    },
    {
      "x": -4,
      "y": 30,
      "z": -8,
      "name": "Wood_Petrified_Trunk_Full",
      "support": 3,
      "rotation": 4
    },
    {
      "x": -4,
      "y": 30,
      "z": -7,
      "name": "Wood_Petrified_Trunk_Full",
      "support": 2,
      "rotation": 4
    },
    {
      "x": -4,
      "y": 28,
      "z": -3,
      "name": "Wood_Petrified_Trunk_Full",
      "support": 2,
      "rotation": 4
    },
    {
      "x": -4,
      "y": 28,
      "z": -2,
      "name": "Wood_Petrified_Trunk",
      "support": 1,
      "rotation": 4
    },
    {
      "x": -4,
      "y": 25,
      "z": -1,
      "name": "Plant_Vine_Wall_Dead",
      "support": 15,
      "rotation": 2
    },
    {
      "x": -4,
      "y": 27,
      "z": -1,
      "name": "Wood_Petrified_Trunk_Full",
      "support": 1,
      "rotation": 4
    },
    {
      "x": -4,
      "y": 28,
      "z": -1,
      "name": "Wood_Petrified_Trunk_Full",
      "rotation": 4
    },
    {
      "x": -4,
      "y": 24,
      "z": 0,
      "name": "Plant_Vine_Wall_Poisoned",
      "support": 15,
      "rotation": 2
    },
    {
      "x": -4,
      "y": 25,
      "z": 0,
      "name": "Wood_Petrified_Trunk_Full",
      "support": 1
    },
    {
      "x": -4,
      "y": 26,
      "z": 0,
      "name": "Wood_Petrified_Trunk"
    },
    {
      "x": -4,
      "y": 27,
      "z": 0,
      "name": "Wood_Petrified_Trunk_Full"
    },
    {
      "x": -4,
      "y": 24,
      "z": 1,
      "name": "Wood_Petrified_Trunk_Full",
      "support": 4
    },
    {
      "x": -4,
      "y": 25,
      "z": 1,
      "name": "Wood_Petrified_Trunk"
    },
    {
      "x": -4,
      "y": 26,
      "z": 1,
      "name": "Wood_Petrified_Trunk"
    },
    {
      "x": -4,
      "y": 27,
      "z": 1,
      "name": "Wood_Petrified_Trunk_Full"
    },
    {
      "x": -4,
      "y": 30,
      "z": 1,
      "name": "Wood_Burnt_Roots"
    },
    {
      "x": -4,
      "y": 31,
      "z": 1,
      "name": "Wood_Petrified_Trunk_Full",
      "support": 5
    },
    {
      "x": -4,
      "y": 32,
      "z": 1,
      "name": "Wood_Petrified_Trunk"
    },
    {
      "x": -4,
      "y": 33,
      "z": 1,
      "name": "Wood_Petrified_Trunk"
    },
    {
      "x": -4,
      "y": 34,
      "z": 1,
      "name": "Wood_Petrified_Trunk"
    },
    {
      "x": -4,
      "y": 35,
      "z": 1,
      "name": "Wood_Petrified_Trunk_Full",
      "rotation": 5
    },
    {
      "x": -4,
      "y": 24,
      "z": 2,
      "name": "Wood_Petrified_Trunk_Full",
      "support": 3
    },
    {
      "x": -4,
      "y": 25,
      "z": 2,
      "name": "Wood_Petrified_Trunk"
    },
    {
      "x": -4,
      "y": 26,
      "z": 2,
      "name": "Wood_Petrified_Trunk_Full"
    },
    {
      "x": -4,
      "y": 32,
      "z": 2,
      "name": "Wood_Petrified_Trunk_Full",
      "support": 1
    },
    {
      "x": -4,
      "y": 33,
      "z": 2,
      "name": "Wood_Petrified_Trunk"
    },
    {
      "x": -4,
      "y": 34,
      "z": 2,
      "name": "Wood_Petrified_Trunk_Full"
    },
    {
      "x": -4,
      "y": 24,
      "z": 3,
      "name": "Plant_Vine_Wall_Poisoned",
      "support": 15
    },
    {
      "x": -4,
      "y": 26,
      "z": 3,
      "name": "Plant_Vine_Wall_Poisoned",
      "support": 15
    },
    {
      "x": -4,
      "y": 32,
      "z": 3,
      "name": "Plant_Vine_Wall_Poisoned",
      "support": 15
    },
    {
      "x": -4,
      "y": 35,
      "z": 3,
      "name": "Wood_Petrified_Branch_Corner",
      "rotation": 3
    },
    {
      "x": -4,
      "y": 8,
      "z": 5,
      "name": "Wood_Petrified_Trunk_Full",
      "support": 15
    },
    {
      "x": -4,
      "y": 9,
      "z": 5,
      "name": "Wood_Petrified_Trunk"
    },
    {
      "x": -4,
      "y": 10,
      "z": 5,
      "name": "Wood_Petrified_Trunk_Full"
    },
    {
      "x": -4,
      "y": 8,
      "z": 6,
      "name": "Wood_Petrified_Trunk_Full",
      "support": 15
    },
    {
      "x": -4,
      "y": 9,
      "z": 6,
      "name": "Wood_Petrified_Trunk",
      "support": 15
    },
    {
      "x": -4,
      "y": 10,
      "z": 6,
      "name": "Wood_Petrified_Trunk"
    },
    {
      "x": -4,
      "y": 11,
      "z": 6,
      "name": "Wood_Petrified_Trunk_Full"
    },
    {
      "x": -4,
      "y": 12,
      "z": 6,
      "name": "Plant_Crop_Mushroom_Flatcap_Green",
      "components": {
        "Components": {
          "FarmingBlock": {
            "GrowthProgress": -73.35401153564453,
            "LastTickGameTime": "0001-01-01T12:00:00Z",
            "Generation": 1,
            "Executions": 1
          },
          "PlacedByInteraction": {
            "WhoPlacedUuid": {
              "$binary": "bJ0Z/pHxT/WyhVA6z1mjfg==",
              "$type": "04"
            }
          }
        }
      }
    },
    {
      "x": -4,
      "y": 5,
      "z": 7,
      "name": "Wood_Burnt_Roots"
    },
    {
      "x": -4,
      "y": 6,
      "z": 7,
      "name": "Wood_Petrified_Trunk",
      "support": 15
    },
    {
      "x": -4,
      "y": 7,
      "z": 7,
      "name": "Wood_Petrified_Trunk",
      "support": 15
    },
    {
      "x": -4,
      "y": 8,
      "z": 7,
      "name": "Wood_Petrified_Trunk",
      "support": 15
    },
    {
      "x": -4,
      "y": 9,
      "z": 7,
      "name": "Wood_Petrified_Trunk",
      "support": 15
    },
    {
      "x": -4,
      "y": 10,
      "z": 7,
      "name": "Wood_Petrified_Trunk"
    },
    {
      "x": -4,
      "y": 11,
      "z": 7,
      "name": "Wood_Petrified_Trunk"
    },
    {
      "x": -4,
      "y": 12,
      "z": 7,
      "name": "Wood_Petrified_Trunk_Full"
    },
    {
      "x": -4,
      "y": 13,
      "z": 7,
      "name": "Necrotic_Grass"
    },
    {
      "x": -4,
      "y": 10,
      "z": 8,
      "name": "Wood_Petrified_Trunk_Full",
      "support": 1
    },
    {
      "x": -4,
      "y": 11,
      "z": 8,
      "name": "Plant_Bush_Winter",
      "support": 15
    },
    {
      "x": -4,
      "y": 6,
      "z": 10,
      "name": "Wood_Petrified_Trunk_Full",
      "support": 15,
      "rotation": 5
    },
    {
      "x": -4,
      "y": 7,
      "z": 10,
      "name": "Wood_Petrified_Trunk_Full",
      "support": 15,
      "rotation": 5
    },
    {
      "x": -3,
      "y": 30,
      "z": -7,
      "name": "Wood_Petrified_Trunk_Full",
      "support": 1,
      "rotation": 4
    },
    {
      "x": -3,
      "y": 31,
      "z": -7,
      "name": "Wood_Petrified_Branch_Corner",
      "support": 1,
      "rotation": 2
    },
    {
      "x": -3,
      "y": 28,
      "z": -6,
      "name": "Wood_Burnt_Roots"
    },
    {
      "x": -3,
      "y": 29,
      "z": -6,
      "name": "Wood_Petrified_Trunk_Full",
      "support": 1,
      "rotation": 4
    },
    {
      "x": -3,
      "y": 30,
      "z": -6,
      "name": "Wood_Petrified_Trunk_Full",
      "rotation": 4
    },
    {
      "x": -3,
      "y": 31,
      "z": -6,
      "name": "Wood_Petrified_Branch_Corner",
      "rotation": 10
    },
    {
      "x": -3,
      "y": 28,
      "z": -5,
      "name": "Wood_Petrified_Trunk_Full",
      "support": 5,
      "rotation": 4
    },
    {
      "x": -3,
      "y": 29,
      "z": -5,
      "name": "Wood_Petrified_Trunk",
      "rotation": 4
    },
    {
      "x": -3,
      "y": 30,
      "z": -5,
      "name": "Plant_Bush_Winter",
      "support": 15
    },
    {
      "x": -3,
      "y": 28,
      "z": -4,
      "name": "Wood_Petrified_Trunk",
      "support": 4,
      "rotation": 4
    },
    {
      "x": -3,
      "y": 29,
      "z": -4,
      "name": "Wood_Petrified_Trunk",
      "rotation": 4
    },
    {
      "x": -3,
      "y": 28,
      "z": -3,
      "name": "Wood_Petrified_Trunk",
      "support": 3,
      "rotation": 4
    },
    {
      "x": -3,
      "y": 29,
      "z": -3,
      "name": "Wood_Petrified_Trunk_Full",
      "rotation": 4
    },
    {
      "x": -3,
      "y": 30,
      "z": -3,
      "name": "Plant_Bush_Winter",
      "support": 15
    },
    {
      "x": -3,
      "y": 28,
      "z": -2,
      "name": "Wood_Petrified_Trunk_Full",
      "support": 2,
      "rotation": 4
    },
    {
      "x": -3,
      "y": 25,
      "z": -1,
      "name": "Plant_Vine_Wall_Dead",
      "support": 15,
      "rotation": 2
    },
    {
      "x": -3,
      "y": 24,
      "z": 0,
      "name": "Plant_Vine_Wall_Poisoned",
      "support": 15,
      "rotation": 2
    },
    {
      "x": -3,
      "y": 25,
      "z": 0,
      "name": "Wood_Petrified_Trunk_Full",
      "support": 1
    },
    {
      "x": -3,
      "y": 26,
      "z": 0,
      "name": "Wood_Petrified_Trunk"
    },
    {
      "x": -3,
      "y": 27,
      "z": 0,
      "name": "Wood_Petrified_Trunk_Full"
    },
    {
      "x": -3,
      "y": 24,
      "z": 1,
      "name": "Wood_Petrified_Trunk_Full",
      "support": 3
    },
    {
      "x": -3,
      "y": 25,
      "z": 1,
      "name": "Wood_Petrified_Trunk"
    },
    {
      "x": -3,
      "y": 26,
      "z": 1,
      "name": "Wood_Petrified_Trunk"
    },
    {
      "x": -3,
      "y": 27,
      "z": 1,
      "name": "Wood_Petrified_Trunk_Full"
    },
    {
      "x": -3,
      "y": 33,
      "z": 1,
      "name": "Wood_Petrified_Trunk_Full",
      "support": 1
    },
    {
      "x": -3,
      "y": 23,
      "z": 2,
      "name": "Wood_Burnt_Roots"
    },
    {
      "x": -3,
      "y": 24,
      "z": 2,
      "name": "Wood_Petrified_Trunk_Full",
      "support": 2
    },
    {
      "x": -3,
      "y": 25,
      "z": 2,
      "name": "Wood_Petrified_Trunk"
    },
    {
      "x": -3,
      "y": 26,
      "z": 2,
      "name": "Wood_Petrified_Trunk_Full"
    },
    {
      "x": -3,
      "y": 27,
      "z": 2,
      "name": "Plant_Vine_Wall_Poisoned",
      "support": 15
    },
    {
      "x": -3,
      "y": 32,
      "z": 2,
      "name": "Wood_Petrified_Trunk_Full",
      "support": 2
    },
    {
      "x": -3,
      "y": 33,
      "z": 2,
      "name": "Wood_Petrified_Trunk"
    },
    {
      "x": -3,
      "y": 34,
      "z": 2,
      "name": "Wood_Petrified_Trunk_Full"
    },
    {
      "x": -3,
      "y": 24,
      "z": 3,
      "name": "Plant_Vine_Wall_Poisoned",
      "support": 15
    },
    {
      "x": -3,
      "y": 34,
      "z": 3,
      "name": "Wood_Petrified_Branch_Corner"
    },
    {
      "x": -3,
      "y": 35,
      "z": 3,
      "name": "Wood_Petrified_Branch_Corner",
      "rotation": 11
    },
    {
      "x": -3,
      "y": 8,
      "z": 5,
      "name": "Wood_Petrified_Trunk_Full",
      "support": 15
    },
    {
      "x": -3,
      "y": 9,
      "z": 5,
      "name": "Wood_Petrified_Trunk"
    },
    {
      "x": -3,
      "y": 10,
      "z": 5,
      "name": "Wood_Petrified_Trunk"
    },
    {
      "x": -3,
      "y": 11,
      "z": 5,
      "name": "Wood_Petrified_Trunk"
    },
    {
      "x": -3,
      "y": 12,
      "z": 5,
      "name": "Wood_Petrified_Trunk_Full"
    },
    {
      "x": -3,
      "y": 13,
      "z": 5,
      "name": "Plant_Bush_Dead_Twisted"
    },
    {
      "x": -3,
      "y": 15,
      "z": 5,
      "name": "Plant_Vine_Wall_Dead",
      "support": 15,
      "rotation": 3
    },
    {
      "x": -3,
      "y": 8,
      "z": 6,
      "name": "Wood_Petrified_Trunk_Full",
      "support": 15
    },
    {
      "x": -3,
      "y": 9,
      "z": 6,
      "name": "Wood_Petrified_Trunk"
    },
    {
      "x": -3,
      "y": 10,
      "z": 6,
      "name": "Wood_Petrified_Trunk"
    },
    {
      "x": -3,
      "y": 11,
      "z": 6,
      "name": "Wood_Petrified_Trunk"
    },
    {
      "x": -3,
      "y": 12,
      "z": 6,
      "name": "Wood_Petrified_Trunk"
    },
    {
      "x": -3,
      "y": 13,
      "z": 6,
      "name": "Wood_Petrified_Trunk_Full"
    },
    {
      "x": -3,
      "y": 15,
      "z": 6,
      "name": "Plant_Vine_Wall_Dead",
      "support": 15,
      "rotation": 3
    },
    {
      "x": -3,
      "y": 17,
      "z": 6,
      "name": "Plant_Vine_Wall_Dead",
      "support": 15,
      "rotation": 3
    },
    {
      "x": -3,
      "y": 9,
      "z": 7,
      "name": "Wood_Petrified_Trunk_Full",
      "support": 15
    },
    {
      "x": -3,
      "y": 10,
      "z": 7,
      "name": "Wood_Petrified_Trunk"
    },
    {
      "x": -3,
      "y": 11,
      "z": 7,
      "name": "Wood_Petrified_Trunk"
    },
    {
      "x": -3,
      "y": 12,
      "z": 7,
      "name": "Wood_Petrified_Trunk"
    },
    {
      "x": -3,
      "y": 13,
      "z": 7,
      "name": "Wood_Petrified_Trunk"
    },
    {
      "x": -3,
      "y": 14,
      "z": 7,
      "name": "Wood_Petrified_Trunk"
    },
    {
      "x": -3,
      "y": 15,
      "z": 7,
      "name": "Wood_Petrified_Trunk_Full"
    },
    {
      "x": -3,
      "y": 16,
      "z": 7,
      "name": "Plant_Vine_Wall_Dead",
      "support": 15,
      "rotation": 3
    },
    {
      "x": -3,
      "y": 17,
      "z": 7,
      "name": "Plant_Vine_Wall_Dead",
      "support": 15,
      "rotation": 3
    },
    {
      "x": -3,
      "y": 9,
      "z": 8,
      "name": "Wood_Petrified_Trunk_Full",
      "support": 15
    },
    {
      "x": -3,
      "y": 10,
      "z": 8,
      "name": "Wood_Petrified_Trunk"
    },
    {
      "x": -3,
      "y": 11,
      "z": 8,
      "name": "Wood_Petrified_Trunk"
    },
    {
      "x": -3,
      "y": 12,
      "z": 8,
      "name": "Wood_Petrified_Trunk_Full"
    },
    {
      "x": -3,
      "y": 14,
      "z": 8,
      "name": "Plant_Vine_Wall_Dead",
      "support": 15
    },
    {
      "x": -3,
      "y": 8,
      "z": 9,
      "name": "Wood_Petrified_Trunk_Full",
      "support": 15
    },
    {
      "x": -3,
      "y": 9,
      "z": 9,
      "name": "Wood_Petrified_Trunk_Full",
      "support": 15,
      "rotation": 4
    },
    {
      "x": -3,
      "y": 10,
      "z": 9,
      "name": "Wood_Petrified_Trunk_Full"
    },
    {
      "x": -3,
      "y": 11,
      "z": 9,
      "name": "Plant_Crop_Mushroom_Glowing_Violet"
    },
    {
      "x": -3,
      "y": 6,
      "z": 10,
      "name": "Wood_Petrified_Trunk_Full",
      "support": 15
    },
    {
      "x": -3,
      "y": 7,
      "z": 10,
      "name": "Wood_Petrified_Trunk_Full",
      "support": 15
    },
    {
      "x": -3,
      "y": 8,
      "z": 10,
      "name": "Wood_Petrified_Trunk_Full",
      "support": 15,
      "rotation": 4
    },
    {
      "x": -3,
      "y": 4,
      "z": 11,
      "name": "Wood_Burnt_Roots"
    },
    {
      "x": -3,
      "y": 5,
      "z": 11,
      "name": "Wood_Petrified_Trunk_Full",
      "support": 15
    },
    {
      "x": -3,
      "y": 6,
      "z": 11,
      "name": "Wood_Petrified_Trunk_Full",
      "support": 15,
      "rotation": 4
    },
    {
      "x": -2,
      "y": 29,
      "z": -6,
      "name": "Wood_Petrified_Trunk_Full",
      "support": 2,
      "rotation": 4
    },
    {
      "x": -2,
      "y": 28,
      "z": -5,
      "name": "Wood_Burnt_Roots"
    },
    {
      "x": -2,
      "y": 29,
      "z": -5,
      "name": "Wood_Petrified_Trunk_Full",
      "support": 1,
      "rotation": 4
    },
    {
      "x": -2,
      "y": 24,
      "z": 0,
      "name": "Plant_Vine_Wall_Dead",
      "support": 15,
      "rotation": 2
    },
    {
      "x": -2,
      "y": 25,
      "z": 0,
      "name": "Plant_Vine_Wall_Poisoned",
      "support": 15,
      "rotation": 2
    },
    {
      "x": -2,
      "y": 24,
      "z": 1,
      "name": "Wood_Petrified_Trunk_Full",
      "support": 2
    },
    {
      "x": -2,
      "y": 25,
      "z": 1,
      "name": "Wood_Petrified_Trunk"
    },
    {
      "x": -2,
      "y": 26,
      "z": 1,
      "name": "Wood_Petrified_Trunk_Full"
    },
    {
      "x": -2,
      "y": 33,
      "z": 1,
      "name": "Wood_Petrified_Branch_Corner",
      "rotation": 1
    },
    {
      "x": -2,
      "y": 34,
      "z": 1,
      "name": "Wood_Petrified_Branch_Corner",
      "support": 1,
      "rotation": 9
    },
    {
      "x": -2,
      "y": 23,
      "z": 2,
      "name": "Long_Roots"
    },
    {
      "x": -2,
      "y": 24,
      "z": 2,
      "name": "Wood_Petrified_Trunk_Full",
      "support": 1
    },
    {
      "x": -2,
      "y": 25,
      "z": 2,
      "name": "Wood_Petrified_Trunk"
    },
    {
      "x": -2,
      "y": 26,
      "z": 2,
      "name": "Wood_Petrified_Trunk"
    },
    {
      "x": -2,
      "y": 27,
      "z": 2,
      "name": "Wood_Petrified_Trunk_Full"
    },
    {
      "x": -2,
      "y": 24,
      "z": 3,
      "name": "Plant_Vine_Wall_Dead",
      "support": 15
    },
    {
      "x": -2,
      "y": 25,
      "z": 3,
      "name": "Wood_Petrified_Trunk_Full",
      "support": 1
    },
    {
      "x": -2,
      "y": 27,
      "z": 3,
      "name": "Plant_Vine_Wall_Poisoned",
      "support": 15
    },
    {
      "x": -2,
      "y": 8,
      "z": 4,
      "name": "Wood_Petrified_Trunk_Full",
      "support": 15
    },
    {
      "x": -2,
      "y": 9,
      "z": 4,
      "name": "Wood_Petrified_Trunk"
    },
    {
      "x": -2,
      "y": 10,
      "z": 4,
      "name": "Wood_Petrified_Trunk_Full"
    },
    {
      "x": -2,
      "y": 11,
      "z": 4,
      "name": "Necrotic_Grass"
    },
    {
      "x": -2,
      "y": 8,
      "z": 5,
      "name": "Wood_Petrified_Trunk_Full",
      "support": 15
    },
    {
      "x": -2,
      "y": 9,
      "z": 5,
      "name": "Wood_Petrified_Trunk"
    },
    {
      "x": -2,
      "y": 10,
      "z": 5,
      "name": "Wood_Petrified_Trunk"
    },
    {
      "x": -2,
      "y": 11,
      "z": 5,
      "name": "Wood_Petrified_Trunk"
    },
    {
      "x": -2,
      "y": 12,
      "z": 5,
      "name": "Wood_Petrified_Trunk"
    },
    {
      "x": -2,
      "y": 13,
      "z": 5,
      "name": "Wood_Petrified_Trunk"
    },
    {
      "x": -2,
      "y": 14,
      "z": 5,
      "name": "Wood_Petrified_Trunk"
    },
    {
      "x": -2,
      "y": 15,
      "z": 5,
      "name": "Wood_Petrified_Trunk_Full"
    },
    {
      "x": -2,
      "y": 16,
      "z": 5,
      "name": "Plant_Vine_Wall_Dead",
      "support": 15,
      "rotation": 3
    },
    {
      "x": -2,
      "y": 8,
      "z": 6,
      "name": "Wood_Petrified_Trunk_Full",
      "support": 15
    },
    {
      "x": -2,
      "y": 9,
      "z": 6,
      "name": "Wood_Petrified_Trunk"
    },
    {
      "x": -2,
      "y": 10,
      "z": 6,
      "name": "Wood_Petrified_Trunk"
    },
    {
      "x": -2,
      "y": 11,
      "z": 6,
      "name": "Wood_Petrified_Trunk"
    },
    {
      "x": -2,
      "y": 12,
      "z": 6,
      "name": "Wood_Petrified_Trunk"
    },
    {
      "x": -2,
      "y": 13,
      "z": 6,
      "name": "Wood_Petrified_Trunk"
    },
    {
      "x": -2,
      "y": 14,
      "z": 6,
      "name": "Wood_Petrified_Trunk"
    },
    {
      "x": -2,
      "y": 15,
      "z": 6,
      "name": "Wood_Petrified_Trunk"
    },
    {
      "x": -2,
      "y": 16,
      "z": 6,
      "name": "Wood_Petrified_Trunk"
    },
    {
      "x": -2,
      "y": 17,
      "z": 6,
      "name": "Wood_Petrified_Trunk_Full"
    },
    {
      "x": -2,
      "y": 18,
      "z": 6,
      "name": "Plant_Bush_Winter",
      "support": 15
    },
    {
      "x": -2,
      "y": 9,
      "z": 7,
      "name": "Wood_Petrified_Trunk_Full",
      "support": 1
    },
    {
      "x": -2,
      "y": 10,
      "z": 7,
      "name": "Wood_Petrified_Trunk"
    },
    {
      "x": -2,
      "y": 11,
      "z": 7,
      "name": "Wood_Petrified_Trunk"
    },
    {
      "x": -2,
      "y": 12,
      "z": 7,
      "name": "Wood_Petrified_Trunk"
    },
    {
      "x": -2,
      "y": 13,
      "z": 7,
      "name": "Wood_Petrified_Trunk"
    },
    {
      "x": -2,
      "y": 14,
      "z": 7,
      "name": "Wood_Petrified_Trunk"
    },
    {
      "x": -2,
      "y": 15,
      "z": 7,
      "name": "Wood_Petrified_Trunk"
    },
    {
      "x": -2,
      "y": 16,
      "z": 7,
      "name": "Wood_Petrified_Trunk"
    },
    {
      "x": -2,
      "y": 17,
      "z": 7,
      "name": "Wood_Petrified_Trunk_Full"
    },
    {
      "x": -2,
      "y": 9,
      "z": 8,
      "name": "Wood_Petrified_Trunk_Full",
      "support": 15
    },
    {
      "x": -2,
      "y": 10,
      "z": 8,
      "name": "Wood_Petrified_Trunk_Full",
      "support": 15
    },
    {
      "x": -2,
      "y": 11,
      "z": 8,
      "name": "Wood_Petrified_Trunk"
    },
    {
      "x": -2,
      "y": 12,
      "z": 8,
      "name": "Wood_Petrified_Trunk"
    },
    {
      "x": -2,
      "y": 13,
      "z": 8,
      "name": "Wood_Petrified_Trunk"
    },
    {
      "x": -2,
      "y": 14,
      "z": 8,
      "name": "Wood_Petrified_Trunk_Full"
    },
    {
      "x": -2,
      "y": 15,
      "z": 8,
      "name": "Necrotic_Grass"
    },
    {
      "x": -2,
      "y": 9,
      "z": 9,
      "name": "Wood_Petrified_Trunk_Full",
      "support": 15
    },
    {
      "x": -2,
      "y": 10,
      "z": 9,
      "name": "Wood_Petrified_Trunk"
    },
    {
      "x": -2,
      "y": 11,
      "z": 9,
      "name": "Wood_Petrified_Trunk_Full"
    },
    {
      "x": -2,
      "y": 12,
      "z": 9,
      "name": "Plant_Bush_Winter",
      "support": 15
    },
    {
      "x": -2,
      "y": 14,
      "z": 9,
      "name": "Plant_Vine_Wall_Dead",
      "support": 15
    },
    {
      "x": -1,
      "y": 24,
      "z": 0,
      "name": "Plant_Vine_Wall_Poisoned",
      "support": 15,
      "rotation": 2
    },
    {
      "x": -1,
      "y": 2,
      "z": 1,
      "name": "Wood_Burnt_Roots"
    },
    {
      "x": -1,
      "y": 3,
      "z": 1,
      "name": "Wood_Petrified_Trunk"
    },
    {
      "x": -1,
      "y": 4,
      "z": 1,
      "name": "Wood_Petrified_Trunk_Full"
    },
    {
      "x": -1,
      "y": 23,
      "z": 1,
      "name": "Plant_Vine_Wall_Poisoned",
      "support": 15,
      "rotation": 2
    },
    {
      "x": -1,
      "y": 24,
      "z": 1,
      "name": "Wood_Petrified_Trunk_Full",
      "support": 1
    },
    {
      "x": -1,
      "y": 25,
      "z": 1,
      "name": "Wood_Petrified_Trunk_Full"
    },
    {
      "x": -1,
      "y": 34,
      "z": 1,
      "name": "Wood_Petrified_Branch_Corner",
      "support": 2,
      "rotation": 1
    },
    {
      "x": -1,
      "y": 22,
      "z": 2,
      "name": "Wood_Burnt_Roots"
    },
    {
      "x": -1,
      "y": 23,
      "z": 2,
      "name": "Wood_Petrified_Trunk_Full",
      "support": 2
    },
    {
      "x": -1,
      "y": 24,
      "z": 2,
      "name": "Wood_Petrified_Trunk"
    },
    {
      "x": -1,
      "y": 25,
      "z": 2,
      "name": "Wood_Petrified_Trunk"
    },
    {
      "x": -1,
      "y": 26,
      "z": 2,
      "name": "Wood_Petrified_Trunk_Full"
    },
    {
      "x": -1,
      "y": 24,
      "z": 3,
      "name": "Wood_Petrified_Trunk_Full",
      "support": 1
    },
    {
      "x": -1,
      "y": 25,
      "z": 3,
      "name": "Wood_Petrified_Trunk_Full"
    },
    {
      "x": -1,
      "y": 9,
      "z": 4,
      "name": "Wood_Petrified_Trunk_Full",
      "support": 1
    },
    {
      "x": -1,
      "y": 10,
      "z": 4,
      "name": "Wood_Petrified_Trunk"
    },
    {
      "x": -1,
      "y": 11,
      "z": 4,
      "name": "Wood_Petrified_Trunk_Full",
      "rotation": 4
    },
    {
      "x": -1,
      "y": 12,
      "z": 4,
      "name": "Necrotic_Grass"
    },
    {
      "x": -1,
      "y": 13,
      "z": 4,
      "name": "Plant_Vine_Wall_Dead",
      "support": 15,
      "rotation": 2
    },
    {
      "x": -1,
      "y": 14,
      "z": 4,
      "name": "Plant_Vine_Wall_Dead",
      "support": 15,
      "rotation": 2
    },
    {
      "x": -1,
      "y": 17,
      "z": 4,
      "name": "Plant_Vine_Wall_Dead",
      "support": 15,
      "rotation": 3
    },
    {
      "x": -1,
      "y": 24,
      "z": 4,
      "name": "Plant_Vine_Wall_Dead",
      "support": 15
    },
    {
      "x": -1,
      "y": 25,
      "z": 4,
      "name": "Plant_Vine_Wall_Poisoned",
      "support": 15
    },
    {
      "x": -1,
      "y": 9,
      "z": 5,
      "name": "Wood_Petrified_Trunk_Full",
      "support": 1
    },
    {
      "x": -1,
      "y": 10,
      "z": 5,
      "name": "Wood_Petrified_Trunk"
    },
    {
      "x": -1,
      "y": 11,
      "z": 5,
      "name": "Wood_Petrified_Trunk"
    },
    {
      "x": -1,
      "y": 12,
      "z": 5,
      "name": "Wood_Petrified_Trunk"
    },
    {
      "x": -1,
      "y": 13,
      "z": 5,
      "name": "Wood_Petrified_Trunk"
    },
    {
      "x": -1,
      "y": 14,
      "z": 5,
      "name": "Wood_Petrified_Trunk"
    },
    {
      "x": -1,
      "y": 15,
      "z": 5,
      "name": "Wood_Petrified_Trunk"
    },
    {
      "x": -1,
      "y": 16,
      "z": 5,
      "name": "Wood_Petrified_Trunk"
    },
    {
      "x": -1,
      "y": 17,
      "z": 5,
      "name": "Wood_Petrified_Trunk"
    },
    {
      "x": -1,
      "y": 18,
      "z": 5,
      "name": "Wood_Petrified_Trunk_Full"
    },
    {
      "x": -1,
      "y": 10,
      "z": 6,
      "name": "Wood_Petrified_Trunk_Full",
      "support": 1
    },
    {
      "x": -1,
      "y": 11,
      "z": 6,
      "name": "Wood_Petrified_Trunk"
    },
    {
      "x": -1,
      "y": 12,
      "z": 6,
      "name": "Wood_Petrified_Trunk"
    },
    {
      "x": -1,
      "y": 13,
      "z": 6,
      "name": "Wood_Petrified_Trunk"
    },
    {
      "x": -1,
      "y": 14,
      "z": 6,
      "name": "Wood_Petrified_Trunk"
    },
    {
      "x": -1,
      "y": 15,
      "z": 6,
      "name": "Wood_Petrified_Trunk"
    },
    {
      "x": -1,
      "y": 16,
      "z": 6,
      "name": "Wood_Petrified_Trunk"
    },
    {
      "x": -1,
      "y": 17,
      "z": 6,
      "name": "Wood_Petrified_Trunk"
    },
    {
      "x": -1,
      "y": 18,
      "z": 6,
      "name": "Wood_Petrified_Trunk_Full"
    },
    {
      "x": -1,
      "y": 19,
      "z": 6,
      "name": "Necrotic_Grass"
    },
    {
      "x": -1,
      "y": 10,
      "z": 7,
      "name": "Wood_Petrified_Trunk_Full",
      "support": 1
    },
    {
      "x": -1,
      "y": 11,
      "z": 7,
      "name": "Wood_Petrified_Trunk"
    },
    {
      "x": -1,
      "y": 12,
      "z": 7,
      "name": "Wood_Petrified_Trunk"
    },
    {
      "x": -1,
      "y": 13,
      "z": 7,
      "name": "Wood_Petrified_Trunk"
    },
    {
      "x": -1,
      "y": 14,
      "z": 7,
      "name": "Wood_Petrified_Trunk"
    },
    {
      "x": -1,
      "y": 15,
      "z": 7,
      "name": "Wood_Petrified_Trunk"
    },
    {
      "x": -1,
      "y": 16,
      "z": 7,
      "name": "Wood_Petrified_Trunk"
    },
    {
      "x": -1,
      "y": 17,
      "z": 7,
      "name": "Wood_Petrified_Trunk_Full"
    },
    {
      "x": -1,
      "y": 18,
      "z": 7,
      "name": "Plant_Bush_Winter",
      "support": 15
    },
    {
      "x": -1,
      "y": 9,
      "z": 8,
      "name": "Wood_Petrified_Trunk_Full",
      "support": 15
    },
    {
      "x": -1,
      "y": 10,
      "z": 8,
      "name": "Wood_Petrified_Trunk"
    },
    {
      "x": -1,
      "y": 11,
      "z": 8,
      "name": "Wood_Petrified_Trunk"
    },
    {
      "x": -1,
      "y": 12,
      "z": 8,
      "name": "Wood_Petrified_Trunk"
    },
    {
      "x": -1,
      "y": 13,
      "z": 8,
      "name": "Wood_Petrified_Trunk"
    },
    {
      "x": -1,
      "y": 14,
      "z": 8,
      "name": "Wood_Petrified_Trunk"
    },
    {
      "x": -1,
      "y": 15,
      "z": 8,
      "name": "Wood_Petrified_Trunk"
    },
    {
      "x": -1,
      "y": 16,
      "z": 8,
      "name": "Plant_Bush_Winter",
      "support": 15
    },
    {
      "x": -1,
      "y": 10,
      "z": 9,
      "name": "Wood_Petrified_Trunk_Full",
      "support": 1
    },
    {
      "x": -1,
      "y": 11,
      "z": 9,
      "name": "Wood_Petrified_Trunk"
    },
    {
      "x": -1,
      "y": 12,
      "z": 9,
      "name": "Wood_Petrified_Trunk"
    },
    {
      "x": -1,
      "y": 13,
      "z": 9,
      "name": "Wood_Petrified_Trunk"
    },
    {
      "x": -1,
      "y": 14,
      "z": 9,
      "name": "Wood_Petrified_Trunk_Full"
    },
    {
      "x": -1,
      "y": 15,
      "z": 9,
      "name": "Plant_Vine_Wall_Poisoned",
      "support": 15
    },
    {
      "x": -1,
      "y": 10,
      "z": 10,
      "name": "Wood_Petrified_Trunk_Full",
      "support": 1
    },
    {
      "x": -1,
      "y": 11,
      "z": 10,
      "name": "Wood_Petrified_Trunk_Full"
    },
    {
      "x": -1,
      "y": 12,
      "z": 10,
      "name": "Plant_Bush_Winter",
      "support": 15
    },
    {
      "x": -1,
      "y": 14,
      "z": 10,
      "name": "Plant_Vine_Wall_Dead",
      "support": 15
    },
    {
      "x": -1,
      "y": 5,
      "z": 11,
      "name": "Wood_Petrified_Trunk_Full",
      "support": 2
    },
    {
      "x": 0,
      "y": 25,
      "z": 0,
      "name": "Wood_Petrified_Trunk_Full",
      "support": 2
    },
    {
      "x": 0,
      "y": 26,
      "z": 0,
      "name": "Wood_Petrified_Trunk_Full"
    },
    {
      "x": 0,
      "y": 27,
      "z": 0,
      "name": "Plant_Bush_Winter",
      "support": 15
    },
    {
      "x": 0,
      "y": 4,
      "z": 1,
      "name": "Wood_Petrified_Trunk_Full"
    },
    {
      "x": 0,
      "y": 25,
      "z": 1,
      "name": "Wood_Petrified_Trunk_Full",
      "support": 1
    },
    {
      "x": 0,
      "y": 4,
      "z": 2,
      "name": "Wood_Petrified_Trunk_Full"
    },
    {
      "x": 0,
      "y": 5,
      "z": 2,
      "name": "Wood_Petrified_Trunk"
    },
    {
      "x": 0,
      "y": 6,
      "z": 2,
      "name": "Wood_Petrified_Trunk_Full"
    },
    {
      "x": 0,
      "y": 22,
      "z": 2,
      "name": "Wood_Burnt_Roots"
    },
    {
      "x": 0,
      "y": 23,
      "z": 2,
      "name": "Wood_Petrified_Trunk_Full",
      "support": 1
    },
    {
      "x": 0,
      "y": 24,
      "z": 2,
      "name": "Wood_Petrified_Trunk"
    },
    {
      "x": 0,
      "y": 25,
      "z": 2,
      "name": "Wood_Petrified_Trunk_Full"
    },
    {
      "x": 0,
      "y": 26,
      "z": 2,
      "name": "Plant_Crop_Mushroom_Flatcap_Green",
      "components": {
        "Components": {
          "FarmingBlock": {
            "GrowthProgress": -61.12083435058594,
            "LastTickGameTime": "0001-01-01T12:00:00Z"
          },
          "PlacedByInteraction": {
            "WhoPlacedUuid": {
              "$binary": "bJ0Z/pHxT/WyhVA6z1mjfg==",
              "$type": "04"
            }
          }
        }
      }
    },
    {
      "x": 0,
      "y": 7,
      "z": 3,
      "name": "Wood_Petrified_Trunk_Full",
      "support": 2
    },
    {
      "x": 0,
      "y": 8,
      "z": 3,
      "name": "Wood_Petrified_Trunk_Full"
    },
    {
      "x": 0,
      "y": 11,
      "z": 3,
      "name": "Plant_Vine_Wall_Dead",
      "support": 15,
      "rotation": 2
    },
    {
      "x": 0,
      "y": 12,
      "z": 3,
      "name": "Plant_Vine_Wall_Dead",
      "support": 15,
      "rotation": 2
    },
    {
      "x": 0,
      "y": 17,
      "z": 3,
      "name": "Plant_Vine_Wall_Dead",
      "support": 15,
      "rotation": 2
    },
    {
      "x": 0,
      "y": 21,
      "z": 3,
      "name": "Wood_Burnt_Roots"
    },
    {
      "x": 0,
      "y": 22,
      "z": 3,
      "name": "Wood_Petrified_Trunk_Full",
      "support": 1
    },
    {
      "x": 0,
      "y": 23,
      "z": 3,
      "name": "Wood_Petrified_Trunk"
    },
    {
      "x": 0,
      "y": 24,
      "z": 3,
      "name": "Wood_Petrified_Trunk_Full"
    },
    {
      "x": 0,
      "y": 8,
      "z": 4,
      "name": "Wood_Petrified_Trunk_Full",
      "support": 1
    },
    {
      "x": 0,
      "y": 9,
      "z": 4,
      "name": "Wood_Petrified_Trunk"
    },
    {
      "x": 0,
      "y": 10,
      "z": 4,
      "name": "Wood_Petrified_Trunk"
    },
    {
      "x": 0,
      "y": 11,
      "z": 4,
      "name": "Wood_Petrified_Trunk"
    },
    {
      "x": 0,
      "y": 12,
      "z": 4,
      "name": "Wood_Petrified_Trunk_Full"
    },
    {
      "x": 0,
      "y": 14,
      "z": 4,
      "name": "Plant_Vine_Wall_Dead",
      "support": 15,
      "rotation": 2
    },
    {
      "x": 0,
      "y": 16,
      "z": 4,
      "name": "Wood_Petrified_Trunk_Full",
      "support": 1
    },
    {
      "x": 0,
      "y": 17,
      "z": 4,
      "name": "Wood_Petrified_Trunk"
    },
    {
      "x": 0,
      "y": 18,
      "z": 4,
      "name": "Wood_Petrified_Trunk_Full"
    },
    {
      "x": 0,
      "y": 20,
      "z": 4,
      "name": "Wood_Burnt_Roots"
    },
    {
      "x": 0,
      "y": 21,
      "z": 4,
      "name": "Wood_Petrified_Trunk_Full",
      "support": 1
    },
    {
      "x": 0,
      "y": 22,
      "z": 4,
      "name": "Wood_Petrified_Trunk"
    },
    {
      "x": 0,
      "y": 23,
      "z": 4,
      "name": "Wood_Petrified_Trunk"
    },
    {
      "x": 0,
      "y": 24,
      "z": 4,
      "name": "Wood_Petrified_Trunk_Full"
    },
    {
      "x": 0,
      "y": 9,
      "z": 5,
      "name": "Wood_Petrified_Trunk_Full",
      "support": 1
    },
    {
      "x": 0,
      "y": 10,
      "z": 5,
      "name": "Wood_Petrified_Trunk"
    },
    {
      "x": 0,
      "y": 11,
      "z": 5,
      "name": "Wood_Petrified_Trunk"
    },
    {
      "x": 0,
      "y": 12,
      "z": 5,
      "name": "Wood_Petrified_Trunk"
    },
    {
      "x": 0,
      "y": 13,
      "z": 5,
      "name": "Wood_Petrified_Trunk"
    },
    {
      "x": 0,
      "y": 14,
      "z": 5,
      "name": "Wood_Petrified_Trunk"
    },
    {
      "x": 0,
      "y": 15,
      "z": 5,
      "name": "Wood_Petrified_Trunk"
    },
    {
      "x": 0,
      "y": 16,
      "z": 5,
      "name": "Wood_Petrified_Trunk"
    },
    {
      "x": 0,
      "y": 17,
      "z": 5,
      "name": "Wood_Petrified_Trunk"
    },
    {
      "x": 0,
      "y": 18,
      "z": 5,
      "name": "Wood_Petrified_Trunk"
    },
    {
      "x": 0,
      "y": 19,
      "z": 5,
      "name": "Wood_Petrified_Trunk_Full"
    },
    {
      "x": 0,
      "y": 23,
      "z": 5,
      "name": "Plant_Vine_Wall_Poisoned",
      "support": 15
    },
    {
      "x": 0,
      "y": 24,
      "z": 5,
      "name": "Plant_Vine_Wall_Dead",
      "support": 15
    },
    {
      "x": 0,
      "y": 10,
      "z": 6,
      "name": "Wood_Petrified_Trunk_Full",
      "support": 15,
      "rotation": 5
    },
    {
      "x": 0,
      "y": 11,
      "z": 6,
      "name": "Wood_Petrified_Trunk"
    },
    {
      "x": 0,
      "y": 12,
      "z": 6,
      "name": "Wood_Petrified_Trunk"
    },
    {
      "x": 0,
      "y": 13,
      "z": 6,
      "name": "Wood_Petrified_Trunk"
    },
    {
      "x": 0,
      "y": 14,
      "z": 6,
      "name": "Wood_Petrified_Trunk"
    },
    {
      "x": 0,
      "y": 15,
      "z": 6,
      "name": "Wood_Petrified_Trunk"
    },
    {
      "x": 0,
      "y": 16,
      "z": 6,
      "name": "Wood_Petrified_Trunk"
    },
    {
      "x": 0,
      "y": 17,
      "z": 6,
      "name": "Wood_Petrified_Trunk"
    },
    {
      "x": 0,
      "y": 18,
      "z": 6,
      "name": "Wood_Petrified_Trunk_Full"
    },
    {
      "x": 0,
      "y": 19,
      "z": 6,
      "name": "Plant_Vine_Wall_Poisoned",
      "support": 15,
      "rotation": 3
    },
    {
      "x": 0,
      "y": 10,
      "z": 7,
      "name": "Wood_Petrified_Trunk_Full",
      "support": 2
    },
    {
      "x": 0,
      "y": 11,
      "z": 7,
      "name": "Wood_Petrified_Trunk"
    },
    {
      "x": 0,
      "y": 12,
      "z": 7,
      "name": "Wood_Petrified_Trunk"
    },
    {
      "x": 0,
      "y": 13,
      "z": 7,
      "name": "Wood_Petrified_Trunk"
    },
    {
      "x": 0,
      "y": 14,
      "z": 7,
      "name": "Wood_Petrified_Trunk"
    },
    {
      "x": 0,
      "y": 15,
      "z": 7,
      "name": "Wood_Petrified_Trunk"
    },
    {
      "x": 0,
      "y": 16,
      "z": 7,
      "name": "Wood_Petrified_Trunk"
    },
    {
      "x": 0,
      "y": 17,
      "z": 7,
      "name": "Wood_Petrified_Trunk"
    },
    {
      "x": 0,
      "y": 18,
      "z": 7,
      "name": "Wood_Petrified_Trunk_Full"
    },
    {
      "x": 0,
      "y": 19,
      "z": 7,
      "name": "Necrotic_Grass"
    },
    {
      "x": 0,
      "y": 10,
      "z": 8,
      "name": "Wood_Petrified_Trunk_Full",
      "support": 1
    },
    {
      "x": 0,
      "y": 11,
      "z": 8,
      "name": "Wood_Petrified_Trunk"
    },
    {
      "x": 0,
      "y": 12,
      "z": 8,
      "name": "Wood_Petrified_Trunk"
    },
    {
      "x": 0,
      "y": 13,
      "z": 8,
      "name": "Wood_Petrified_Trunk"
    },
    {
      "x": 0,
      "y": 14,
      "z": 8,
      "name": "Wood_Petrified_Trunk"
    },
    {
      "x": 0,
      "y": 15,
      "z": 8,
      "name": "Wood_Petrified_Trunk"
    },
    {
      "x": 0,
      "y": 16,
      "z": 8,
      "name": "Wood_Petrified_Trunk"
    },
    {
      "x": 0,
      "y": 17,
      "z": 8,
      "name": "Wood_Petrified_Trunk_Full"
    },
    {
      "x": 0,
      "y": 18,
      "z": 8,
      "name": "Necrotic_Grass"
    },
    {
      "x": 0,
      "y": 10,
      "z": 9,
      "name": "Wood_Petrified_Trunk_Full",
      "support": 1
    },
    {
      "x": 0,
      "y": 11,
      "z": 9,
      "name": "Wood_Petrified_Trunk"
    },
    {
      "x": 0,
      "y": 12,
      "z": 9,
      "name": "Wood_Petrified_Trunk"
    },
    {
      "x": 0,
      "y": 13,
      "z": 9,
      "name": "Wood_Petrified_Trunk"
    },
    {
      "x": 0,
      "y": 14,
      "z": 9,
      "name": "Wood_Petrified_Trunk_Full"
    },
    {
      "x": 0,
      "y": 16,
      "z": 9,
      "name": "Plant_Vine_Wall_Poisoned",
      "support": 15
    },
    {
      "x": 0,
      "y": 17,
      "z": 9,
      "name": "Plant_Vine_Wall_Poisoned",
      "support": 15
    },
    {
      "x": 0,
      "y": 6,
      "z": 10,
      "name": "Wood_Petrified_Trunk_Full",
      "support": 1
    },
    {
      "x": 0,
      "y": 7,
      "z": 10,
      "name": "Wood_Petrified_Trunk"
    },
    {
      "x": 0,
      "y": 8,
      "z": 10,
      "name": "Wood_Petrified_Trunk"
    },
    {
      "x": 0,
      "y": 9,
      "z": 10,
      "name": "Wood_Petrified_Trunk"
    },
    {
      "x": 0,
      "y": 10,
      "z": 10,
      "name": "Wood_Petrified_Trunk_Full"
    },
    {
      "x": 0,
      "y": 11,
      "z": 10,
      "name": "Plant_Crop_Mushroom_Flatcap_Green",
      "components": {
        "Components": {
          "FarmingBlock": {
            "GrowthProgress": -73.46279907226562,
            "LastTickGameTime": "0001-01-01T12:00:00Z",
            "Generation": 1,
            "Executions": 1
          },
          "PlacedByInteraction": {
            "WhoPlacedUuid": {
              "$binary": "bJ0Z/pHxT/WyhVA6z1mjfg==",
              "$type": "04"
            }
          }
        }
      }
    },
    {
      "x": 0,
      "y": 12,
      "z": 10,
      "name": "Plant_Vine_Wall_Poisoned",
      "support": 15
    },
    {
      "x": 0,
      "y": 14,
      "z": 10,
      "name": "Plant_Vine_Wall_Poisoned",
      "support": 15
    },
    {
      "x": 0,
      "y": 5,
      "z": 11,
      "name": "Wood_Petrified_Trunk_Full",
      "support": 1
    },
    {
      "x": 0,
      "y": 6,
      "z": 11,
      "name": "Wood_Petrified_Trunk"
    },
    {
      "x": 0,
      "y": 7,
      "z": 11,
      "name": "Wood_Petrified_Trunk_Full"
    },
    {
      "x": 1,
      "y": 25,
      "z": -1,
      "name": "Wood_Petrified_Trunk_Full",
      "support": 2
    },
    {
      "x": 1,
      "y": 26,
      "z": -1,
      "name": "Wood_Petrified_Trunk_Full"
    },
    {
      "x": 1,
      "y": 25,
      "z": 0,
      "name": "Wood_Petrified_Trunk_Full",
      "support": 1
    },
    {
      "x": 1,
      "y": 26,
      "z": 0,
      "name": "Wood_Petrified_Trunk"
    },
    {
      "x": 1,
      "y": 27,
      "z": 0,
      "name": "Wood_Petrified_Trunk_Full"
    },
    {
      "x": 1,
      "y": 23,
      "z": 1,
      "name": "Plant_Vine_Wall_Poisoned",
      "support": 15,
      "rotation": 2
    },
    {
      "x": 1,
      "y": 24,
      "z": 1,
      "name": "Wood_Petrified_Trunk_Full",
      "support": 1
    },
    {
      "x": 1,
      "y": 25,
      "z": 1,
      "name": "Wood_Petrified_Trunk"
    },
    {
      "x": 1,
      "y": 26,
      "z": 1,
      "name": "Wood_Petrified_Trunk_Full"
    },
    {
      "x": 1,
      "y": 27,
      "z": 1,
      "name": "Plant_Bush_Winter",
      "support": 15
    },
    {
      "x": 1,
      "y": 6,
      "z": 2,
      "name": "Wood_Petrified_Trunk_Full",
      "support": 1
    },
    {
      "x": 1,
      "y": 7,
      "z": 2,
      "name": "Wood_Petrified_Trunk"
    },
    {
      "x": 1,
      "y": 8,
      "z": 2,
      "name": "Wood_Petrified_Trunk_Full"
    },
    {
      "x": 1,
      "y": 20,
      "z": 2,
      "name": "Plant_Vine_Wall_Poisoned",
      "support": 15,
      "rotation": 2
    },
    {
      "x": 1,
      "y": 23,
      "z": 2,
      "name": "Wood_Petrified_Trunk_Full",
      "support": 1
    },
    {
      "x": 1,
      "y": 24,
      "z": 2,
      "name": "Wood_Petrified_Trunk"
    },
    {
      "x": 1,
      "y": 25,
      "z": 2,
      "name": "Wood_Petrified_Trunk_Full"
    },
    {
      "x": 1,
      "y": 7,
      "z": 3,
      "name": "Wood_Petrified_Trunk_Full",
      "support": 1
    },
    {
      "x": 1,
      "y": 8,
      "z": 3,
      "name": "Wood_Petrified_Trunk"
    },
    {
      "x": 1,
      "y": 9,
      "z": 3,
      "name": "Wood_Petrified_Trunk"
    },
    {
      "x": 1,
      "y": 10,
      "z": 3,
      "name": "Wood_Petrified_Trunk_Full"
    },
    {
      "x": 1,
      "y": 18,
      "z": 3,
      "name": "Plant_Vine_Wall_Dead",
      "support": 15,
      "rotation": 2
    },
    {
      "x": 1,
      "y": 20,
      "z": 3,
      "name": "Wood_Petrified_Trunk_Full",
      "support": 1
    },
    {
      "x": 1,
      "y": 21,
      "z": 3,
      "name": "Wood_Petrified_Trunk"
    },
    {
      "x": 1,
      "y": 22,
      "z": 3,
      "name": "Wood_Petrified_Trunk"
    },
    {
      "x": 1,
      "y": 23,
      "z": 3,
      "name": "Wood_Petrified_Trunk"
    },
    {
      "x": 1,
      "y": 24,
      "z": 3,
      "name": "Wood_Petrified_Trunk_Full"
    },
    {
      "x": 1,
      "y": 9,
      "z": 4,
      "name": "Wood_Petrified_Trunk_Full",
      "support": 1
    },
    {
      "x": 1,
      "y": 10,
      "z": 4,
      "name": "Wood_Petrified_Trunk"
    },
    {
      "x": 1,
      "y": 11,
      "z": 4,
      "name": "Wood_Petrified_Trunk_Full"
    },
    {
      "x": 1,
      "y": 12,
      "z": 4,
      "name": "Plant_Bush_Winter",
      "support": 15
    },
    {
      "x": 1,
      "y": 16,
      "z": 4,
      "name": "Wood_Petrified_Trunk_Full",
      "support": 1
    },
    {
      "x": 1,
      "y": 17,
      "z": 4,
      "name": "Wood_Petrified_Trunk"
    },
    {
      "x": 1,
      "y": 18,
      "z": 4,
      "name": "Wood_Petrified_Trunk"
    },
    {
      "x": 1,
      "y": 19,
      "z": 4,
      "name": "Wood_Petrified_Trunk"
    },
    {
      "x": 1,
      "y": 20,
      "z": 4,
      "name": "Wood_Petrified_Trunk"
    },
    {
      "x": 1,
      "y": 21,
      "z": 4,
      "name": "Wood_Petrified_Trunk"
    },
    {
      "x": 1,
      "y": 22,
      "z": 4,
      "name": "Wood_Petrified_Trunk"
    },
    {
      "x": 1,
      "y": 23,
      "z": 4,
      "name": "Wood_Petrified_Trunk_Full"
    },
    {
      "x": 1,
      "y": 24,
      "z": 4,
      "name": "Plant_Petals_Black"
    },
    {
      "x": 1,
      "y": 9,
      "z": 5,
      "name": "Wood_Petrified_Trunk_Full",
      "support": 2
    },
    {
      "x": 1,
      "y": 10,
      "z": 5,
      "name": "Wood_Petrified_Trunk"
    },
    {
      "x": 1,
      "y": 11,
      "z": 5,
      "name": "Wood_Petrified_Trunk_Full"
    },
    {
      "x": 1,
      "y": 12,
      "z": 5,
      "name": "Plant_Crop_Mushroom_Flatcap_Green",
      "components": {
        "Components": {
          "FarmingBlock": {
            "GrowthProgress": -73.29149627685547,
            "LastTickGameTime": "0001-01-01T12:00:00Z",
            "Generation": 1,
            "Executions": 1
          },
          "PlacedByInteraction": {
            "WhoPlacedUuid": {
              "$binary": "bJ0Z/pHxT/WyhVA6z1mjfg==",
              "$type": "04"
            }
          }
        }
      }
    },
    {
      "x": 1,
      "y": 14,
      "z": 5,
      "name": "Wood_Petrified_Trunk",
      "support": 1
    },
    {
      "x": 1,
      "y": 15,
      "z": 5,
      "name": "Wood_Petrified_Trunk"
    },
    {
      "x": 1,
      "y": 16,
      "z": 5,
      "name": "Wood_Petrified_Trunk"
    },
    {
      "x": 1,
      "y": 17,
      "z": 5,
      "name": "Wood_Petrified_Trunk"
    },
    {
      "x": 1,
      "y": 18,
      "z": 5,
      "name": "Wood_Petrified_Trunk"
    },
    {
      "x": 1,
      "y": 19,
      "z": 5,
      "name": "Wood_Petrified_Trunk_Full"
    },
    {
      "x": 1,
      "y": 20,
      "z": 5,
      "name": "Plant_Vine_Wall_Poisoned",
      "support": 15
    },
    {
      "x": 1,
      "y": 21,
      "z": 5,
      "name": "Plant_Vine_Wall_Poisoned",
      "support": 15
    },
    {
      "x": 1,
      "y": 23,
      "z": 5,
      "name": "Plant_Vine_Wall_Dead",
      "support": 15
    },
    {
      "x": 1,
      "y": 10,
      "z": 6,
      "name": "Wood_Petrified_Trunk_Full",
      "support": 1
    },
    {
      "x": 1,
      "y": 11,
      "z": 6,
      "name": "Wood_Petrified_Trunk"
    },
    {
      "x": 1,
      "y": 12,
      "z": 6,
      "name": "Wood_Petrified_Trunk"
    },
    {
      "x": 1,
      "y": 13,
      "z": 6,
      "name": "Wood_Petrified_Trunk"
    },
    {
      "x": 1,
      "y": 14,
      "z": 6,
      "name": "Wood_Petrified_Trunk"
    },
    {
      "x": 1,
      "y": 15,
      "z": 6,
      "name": "Wood_Petrified_Trunk"
    },
    {
      "x": 1,
      "y": 16,
      "z": 6,
      "name": "Wood_Petrified_Trunk"
    },
    {
      "x": 1,
      "y": 17,
      "z": 6,
      "name": "Wood_Petrified_Trunk"
    },
    {
      "x": 1,
      "y": 18,
      "z": 6,
      "name": "Wood_Petrified_Trunk"
    },
    {
      "x": 1,
      "y": 19,
      "z": 6,
      "name": "Wood_Petrified_Trunk_Full"
    },
    {
      "x": 1,
      "y": 10,
      "z": 7,
      "name": "Wood_Petrified_Trunk_Full",
      "support": 1
    },
    {
      "x": 1,
      "y": 11,
      "z": 7,
      "name": "Wood_Petrified_Trunk"
    },
    {
      "x": 1,
      "y": 12,
      "z": 7,
      "name": "Wood_Petrified_Trunk"
    },
    {
      "x": 1,
      "y": 13,
      "z": 7,
      "name": "Wood_Petrified_Trunk"
    },
    {
      "x": 1,
      "y": 14,
      "z": 7,
      "name": "Wood_Petrified_Trunk"
    },
    {
      "x": 1,
      "y": 15,
      "z": 7,
      "name": "Wood_Petrified_Trunk"
    },
    {
      "x": 1,
      "y": 16,
      "z": 7,
      "name": "Wood_Petrified_Trunk"
    },
    {
      "x": 1,
      "y": 17,
      "z": 7,
      "name": "Wood_Petrified_Trunk"
    },
    {
      "x": 1,
      "y": 18,
      "z": 7,
      "name": "Wood_Petrified_Trunk"
    },
    {
      "x": 1,
      "y": 19,
      "z": 7,
      "name": "Wood_Petrified_Trunk_Full"
    },
    {
      "x": 1,
      "y": 20,
      "z": 7,
      "name": "Plant_Bush_Winter",
      "support": 15
    },
    {
      "x": 1,
      "y": 9,
      "z": 8,
      "name": "Wood_Petrified_Trunk_Full",
      "support": 1
    },
    {
      "x": 1,
      "y": 10,
      "z": 8,
      "name": "Wood_Petrified_Trunk"
    },
    {
      "x": 1,
      "y": 11,
      "z": 8,
      "name": "Wood_Petrified_Trunk"
    },
    {
      "x": 1,
      "y": 12,
      "z": 8,
      "name": "Wood_Petrified_Trunk"
    },
    {
      "x": 1,
      "y": 13,
      "z": 8,
      "name": "Wood_Petrified_Trunk"
    },
    {
      "x": 1,
      "y": 14,
      "z": 8,
      "name": "Wood_Petrified_Trunk"
    },
    {
      "x": 1,
      "y": 15,
      "z": 8,
      "name": "Wood_Petrified_Trunk"
    },
    {
      "x": 1,
      "y": 16,
      "z": 8,
      "name": "Wood_Petrified_Trunk_Full"
    },
    {
      "x": 1,
      "y": 17,
      "z": 8,
      "name": "Necrotic_Grass"
    },
    {
      "x": 1,
      "y": 9,
      "z": 9,
      "name": "Wood_Petrified_Trunk_Full",
      "support": 1
    },
    {
      "x": 1,
      "y": 10,
      "z": 9,
      "name": "Wood_Petrified_Trunk"
    },
    {
      "x": 1,
      "y": 11,
      "z": 9,
      "name": "Wood_Petrified_Trunk"
    },
    {
      "x": 1,
      "y": 12,
      "z": 9,
      "name": "Wood_Petrified_Trunk_Full"
    },
    {
      "x": 1,
      "y": 13,
      "z": 9,
      "name": "Plant_Bush_Winter",
      "support": 15
    },
    {
      "x": 1,
      "y": 16,
      "z": 9,
      "name": "Plant_Vine_Wall_Poisoned",
      "support": 15
    },
    {
      "x": 1,
      "y": 5,
      "z": 10,
      "name": "Wood_Petrified_Trunk_Full",
      "support": 1
    },
    {
      "x": 1,
      "y": 6,
      "z": 10,
      "name": "Wood_Petrified_Trunk"
    },
    {
      "x": 1,
      "y": 7,
      "z": 10,
      "name": "Wood_Petrified_Trunk"
    },
    {
      "x": 1,
      "y": 8,
      "z": 10,
      "name": "Wood_Petrified_Trunk"
    },
    {
      "x": 1,
      "y": 9,
      "z": 10,
      "name": "Wood_Petrified_Trunk_Full"
    },
    {
      "x": 1,
      "y": 11,
      "z": 10,
      "name": "Plant_Vine_Wall_Poisoned",
      "support": 15
    },
    {
      "x": 1,
      "y": 12,
      "z": 10,
      "name": "Plant_Vine_Wall_Dead",
      "support": 15
    },
    {
      "x": 1,
      "y": 3,
      "z": 11,
      "name": "Wood_Petrified_Trunk_Full"
    },
    {
      "x": 1,
      "y": 4,
      "z": 11,
      "name": "Wood_Petrified_Trunk"
    },
    {
      "x": 1,
      "y": 5,
      "z": 11,
      "name": "Wood_Petrified_Trunk"
    },
    {
      "x": 1,
      "y": 6,
      "z": 11,
      "name": "Wood_Petrified_Trunk_Full"
    },
    {
      "x": 2,
      "y": 29,
      "z": -6,
      "name": "Wood_Petrified_Branch_Corner",
      "support": 3,
      "rotation": 2
    },
    {
      "x": 2,
      "y": 29,
      "z": -5,
      "name": "Wood_Petrified_Branch_Long",
      "support": 2,
      "rotation": 4
    },
    {
      "x": 2,
      "y": 28,
      "z": -4,
      "name": "Wood_Petrified_Branch_Corner",
      "rotation": 3
    },
    {
      "x": 2,
      "y": 29,
      "z": -4,
      "name": "Wood_Petrified_Branch_Corner",
      "support": 1,
      "rotation": 10
    },
    {
      "x": 2,
      "y": 26,
      "z": -2,
      "name": "Wood_Petrified_Trunk_Full",
      "support": 2
    },
    {
      "x": 2,
      "y": 27,
      "z": -2,
      "name": "Wood_Petrified_Trunk_Full"
    },
    {
      "x": 2,
      "y": 26,
      "z": -1,
      "name": "Wood_Petrified_Trunk_Full",
      "support": 1
    },
    {
      "x": 2,
      "y": 27,
      "z": -1,
      "name": "Wood_Petrified_Trunk"
    },
    {
      "x": 2,
      "y": 28,
      "z": -1,
      "name": "Wood_Petrified_Trunk"
    },
    {
      "x": 2,
      "y": 29,
      "z": -1,
      "name": "Wood_Petrified_Trunk_Full"
    },
    {
      "x": 2,
      "y": 30,
      "z": -1,
      "name": "Plant_Bush_Winter",
      "support": 15
    },
    {
      "x": 2,
      "y": 26,
      "z": 0,
      "name": "Wood_Petrified_Trunk_Full",
      "support": 1
    },
    {
      "x": 2,
      "y": 27,
      "z": 0,
      "name": "Wood_Petrified_Trunk"
    },
    {
      "x": 2,
      "y": 28,
      "z": 0,
      "name": "Wood_Petrified_Trunk_Full"
    },
    {
      "x": 2,
      "y": 3,
      "z": 1,
      "name": "Wood_Burnt_Roots"
    },
    {
      "x": 2,
      "y": 4,
      "z": 1,
      "name": "Wood_Petrified_Trunk"
    },
    {
      "x": 2,
      "y": 5,
      "z": 1,
      "name": "Wood_Petrified_Trunk"
    },
    {
      "x": 2,
      "y": 6,
      "z": 1,
      "name": "Wood_Petrified_Trunk_Full"
    },
    {
      "x": 2,
      "y": 6,
      "z": 2,
      "name": "Wood_Petrified_Trunk_Full",
      "support": 1
    },
    {
      "x": 2,
      "y": 9,
      "z": 2,
      "name": "Wood_Petrified_Trunk_Full",
      "support": 1
    },
    {
      "x": 2,
      "y": 18,
      "z": 2,
      "name": "Plant_Vine_Wall_Dead",
      "support": 15,
      "rotation": 2
    },
    {
      "x": 2,
      "y": 21,
      "z": 2,
      "name": "Plant_Vine_Wall_Poisoned",
      "support": 15,
      "rotation": 2
    },
    {
      "x": 2,
      "y": 22,
      "z": 2,
      "name": "Plant_Vine_Wall_Poisoned",
      "support": 15,
      "rotation": 2
    },
    {
      "x": 2,
      "y": 24,
      "z": 2,
      "name": "Wood_Petrified_Trunk_Full",
      "support": 1
    },
    {
      "x": 2,
      "y": 9,
      "z": 3,
      "name": "Wood_Petrified_Trunk_Full",
      "support": 1
    },
    {
      "x": 2,
      "y": 10,
      "z": 3,
      "name": "Wood_Petrified_Trunk"
    },
    {
      "x": 2,
      "y": 11,
      "z": 3,
      "name": "Wood_Petrified_Trunk_Full"
    },
    {
      "x": 2,
      "y": 16,
      "z": 3,
      "name": "Wood_Burnt_Roots"
    },
    {
      "x": 2,
      "y": 17,
      "z": 3,
      "name": "Wood_Petrified_Trunk_Full",
      "support": 1
    },
    {
      "x": 2,
      "y": 18,
      "z": 3,
      "name": "Wood_Petrified_Trunk"
    },
    {
      "x": 2,
      "y": 19,
      "z": 3,
      "name": "Wood_Petrified_Trunk"
    },
    {
      "x": 2,
      "y": 20,
      "z": 3,
      "name": "Wood_Petrified_Trunk"
    },
    {
      "x": 2,
      "y": 21,
      "z": 3,
      "name": "Wood_Petrified_Trunk"
    },
    {
      "x": 2,
      "y": 22,
      "z": 3,
      "name": "Wood_Petrified_Trunk"
    },
    {
      "x": 2,
      "y": 23,
      "z": 3,
      "name": "Wood_Petrified_Trunk"
    },
    {
      "x": 2,
      "y": 24,
      "z": 3,
      "name": "Wood_Petrified_Trunk_Full"
    },
    {
      "x": 2,
      "y": 9,
      "z": 4,
      "name": "Wood_Petrified_Trunk_Full",
      "support": 2
    },
    {
      "x": 2,
      "y": 10,
      "z": 4,
      "name": "Wood_Petrified_Trunk"
    },
    {
      "x": 2,
      "y": 11,
      "z": 4,
      "name": "Wood_Petrified_Trunk_Full"
    },
    {
      "x": 2,
      "y": 16,
      "z": 4,
      "name": "Wood_Petrified_Trunk_Full",
      "support": 1
    },
    {
      "x": 2,
      "y": 17,
      "z": 4,
      "name": "Wood_Petrified_Trunk"
    },
    {
      "x": 2,
      "y": 18,
      "z": 4,
      "name": "Wood_Petrified_Trunk"
    },
    {
      "x": 2,
      "y": 19,
      "z": 4,
      "name": "Wood_Petrified_Trunk"
    },
    {
      "x": 2,
      "y": 20,
      "z": 4,
      "name": "Wood_Petrified_Trunk"
    },
    {
      "x": 2,
      "y": 21,
      "z": 4,
      "name": "Wood_Petrified_Trunk"
    },
    {
      "x": 2,
      "y": 22,
      "z": 4,
      "name": "Wood_Petrified_Trunk"
    },
    {
      "x": 2,
      "y": 23,
      "z": 4,
      "name": "Wood_Petrified_Trunk_Full"
    },
    {
      "x": 2,
      "y": 24,
      "z": 4,
      "name": "Plant_Petals_Black"
    },
    {
      "x": 2,
      "y": 8,
      "z": 5,
      "name": "Wood_Burnt_Roots"
    },
    {
      "x": 2,
      "y": 9,
      "z": 5,
      "name": "Wood_Petrified_Trunk_Full",
      "support": 3
    },
    {
      "x": 2,
      "y": 10,
      "z": 5,
      "name": "Wood_Petrified_Trunk"
    },
    {
      "x": 2,
      "y": 11,
      "z": 5,
      "name": "Wood_Petrified_Trunk_Full"
    },
    {
      "x": 2,
      "y": 12,
      "z": 5,
      "name": "Plant_Bush_Winter",
      "support": 15
    },
    {
      "x": 2,
      "y": 14,
      "z": 5,
      "name": "Plant_Vine_Wall_Dead",
      "support": 15,
      "rotation": 1
    },
    {
      "x": 2,
      "y": 15,
      "z": 5,
      "name": "Wood_Petrified_Trunk_Full",
      "support": 1
    },
    {
      "x": 2,
      "y": 16,
      "z": 5,
      "name": "Wood_Petrified_Trunk"
    },
    {
      "x": 2,
      "y": 17,
      "z": 5,
      "name": "Wood_Petrified_Trunk"
    },
    {
      "x": 2,
      "y": 18,
      "z": 5,
      "name": "Wood_Petrified_Trunk"
    },
    {
      "x": 2,
      "y": 19,
      "z": 5,
      "name": "Wood_Petrified_Trunk"
    },
    {
      "x": 2,
      "y": 20,
      "z": 5,
      "name": "Wood_Petrified_Trunk_Full"
    },
    {
      "x": 2,
      "y": 22,
      "z": 5,
      "name": "Plant_Vine_Wall_Dead",
      "support": 15
    },
    {
      "x": 2,
      "y": 23,
      "z": 5,
      "name": "Plant_Vine_Wall_Poisoned",
      "support": 15
    },
    {
      "x": 2,
      "y": 10,
      "z": 6,
      "name": "Wood_Petrified_Trunk_Full",
      "support": 1,
      "rotation": 4
    },
    {
      "x": 2,
      "y": 15,
      "z": 6,
      "name": "Wood_Petrified_Trunk_Full",
      "support": 1
    },
    {
      "x": 2,
      "y": 16,
      "z": 6,
      "name": "Wood_Petrified_Trunk"
    },
    {
      "x": 2,
      "y": 17,
      "z": 6,
      "name": "Wood_Petrified_Trunk"
    },
    {
      "x": 2,
      "y": 18,
      "z": 6,
      "name": "Wood_Petrified_Trunk"
    },
    {
      "x": 2,
      "y": 19,
      "z": 6,
      "name": "Wood_Petrified_Trunk_Full"
    },
    {
      "x": 2,
      "y": 20,
      "z": 6,
      "name": "Plant_Vine_Wall_Poisoned",
      "support": 15,
      "rotation": 3
    },
    {
      "x": 2,
      "y": 9,
      "z": 7,
      "name": "Wood_Petrified_Trunk_Full",
      "support": 1
    },
    {
      "x": 2,
      "y": 10,
      "z": 7,
      "name": "Wood_Petrified_Trunk"
    },
    {
      "x": 2,
      "y": 11,
      "z": 7,
      "name": "Wood_Petrified_Trunk"
    },
    {
      "x": 2,
      "y": 12,
      "z": 7,
      "name": "Wood_Petrified_Trunk_Full"
    },
    {
      "x": 2,
      "y": 7,
      "z": 8,
      "name": "Wood_Burnt_Roots"
    },
    {
      "x": 2,
      "y": 8,
      "z": 8,
      "name": "Wood_Petrified_Trunk_Full",
      "support": 3
    },
    {
      "x": 2,
      "y": 9,
      "z": 8,
      "name": "Wood_Petrified_Trunk"
    },
    {
      "x": 2,
      "y": 10,
      "z": 8,
      "name": "Wood_Petrified_Trunk"
    },
    {
      "x": 2,
      "y": 11,
      "z": 8,
      "name": "Wood_Petrified_Trunk"
    },
    {
      "x": 2,
      "y": 12,
      "z": 8,
      "name": "Wood_Petrified_Trunk"
    },
    {
      "x": 2,
      "y": 13,
      "z": 8,
      "name": "Wood_Petrified_Trunk_Full"
    },
    {
      "x": 2,
      "y": 14,
      "z": 8,
      "name": "Necrotic_Grass"
    },
    {
      "x": 2,
      "y": 8,
      "z": 9,
      "name": "Wood_Petrified_Trunk_Full",
      "support": 4
    },
    {
      "x": 2,
      "y": 9,
      "z": 9,
      "name": "Wood_Petrified_Trunk"
    },
    {
      "x": 2,
      "y": 10,
      "z": 9,
      "name": "Wood_Petrified_Trunk"
    },
    {
      "x": 2,
      "y": 11,
      "z": 9,
      "name": "Wood_Petrified_Trunk_Full"
    },
    {
      "x": 2,
      "y": 12,
      "z": 9,
      "name": "Plant_Vine_Wall_Dead",
      "support": 15
    },
    {
      "x": 2,
      "y": 9,
      "z": 10,
      "name": "Wood_Petrified_Trunk_Full",
      "support": 1
    },
    {
      "x": 2,
      "y": 11,
      "z": 10,
      "name": "Plant_Vine_Wall_Poisoned",
      "support": 15
    },
    {
      "x": 2,
      "y": 1,
      "z": 11,
      "name": "Wood_Burnt_Roots"
    },
    {
      "x": 2,
      "y": 2,
      "z": 11,
      "name": "Wood_Petrified_Trunk"
    },
    {
      "x": 2,
      "y": 3,
      "z": 11,
      "name": "Wood_Petrified_Trunk_Full"
    },
    {
      "x": 3,
      "y": 29,
      "z": -8,
      "name": "Wood_Burnt_Roots"
    },
    {
      "x": 3,
      "y": 30,
      "z": -8,
      "name": "Wood_Petrified_Trunk_Full",
      "support": 2,
      "rotation": 4
    },
    {
      "x": 3,
      "y": 26,
      "z": -7,
      "name": "Wood_Petrified_Branch_Corner",
      "support": 2,
      "rotation": 8
    },
    {
      "x": 3,
      "y": 30,
      "z": -7,
      "name": "Wood_Petrified_Trunk_Full",
      "support": 1,
      "rotation": 4
    },
    {
      "x": 3,
      "y": 26,
      "z": -6,
      "name": "Wood_Petrified_Branch_Long",
      "support": 1,
      "rotation": 4
    },
    {
      "x": 3,
      "y": 26,
      "z": -5,
      "name": "Wood_Petrified_Branch_Corner"
    },
    {
      "x": 3,
      "y": 27,
      "z": -5,
      "name": "Wood_Petrified_Trunk_Full",
      "support": 2
    },
    {
      "x": 3,
      "y": 27,
      "z": -4,
      "name": "Wood_Petrified_Trunk_Full",
      "support": 1
    },
    {
      "x": 3,
      "y": 28,
      "z": -4,
      "name": "Wood_Petrified_Trunk_Full"
    },
    {
      "x": 3,
      "y": 26,
      "z": -3,
      "name": "Wood_Petrified_Trunk_Full",
      "support": 4
    },
    {
      "x": 3,
      "y": 27,
      "z": -3,
      "name": "Wood_Petrified_Trunk_Full"
    },
    {
      "x": 3,
      "y": 25,
      "z": -2,
      "name": "Wood_Burnt_Roots"
    },
    {
      "x": 3,
      "y": 26,
      "z": -2,
      "name": "Wood_Petrified_Trunk_Full",
      "support": 3
    },
    {
      "x": 3,
      "y": 27,
      "z": -2,
      "name": "Wood_Petrified_Trunk_Full"
    },
    {
      "x": 3,
      "y": 28,
      "z": -1,
      "name": "Wood_Petrified_Trunk_Full"
    },
    {
      "x": 3,
      "y": 29,
      "z": -1,
      "name": "Wood_Petrified_Trunk"
    },
    {
      "x": 3,
      "y": 30,
      "z": -1,
      "name": "Wood_Petrified_Trunk_Full"
    },
    {
      "x": 3,
      "y": 18,
      "z": 1,
      "name": "Plant_Vine_Wall_Poisoned",
      "support": 15,
      "rotation": 2
    },
    {
      "x": 3,
      "y": 8,
      "z": 2,
      "name": "Wood_Petrified_Trunk_Full",
      "support": 2
    },
    {
      "x": 3,
      "y": 9,
      "z": 2,
      "name": "Wood_Petrified_Trunk_Full"
    },
    {
      "x": 3,
      "y": 18,
      "z": 2,
      "name": "Wood_Petrified_Trunk_Full",
      "support": 1
    },
    {
      "x": 3,
      "y": 19,
      "z": 2,
      "name": "Wood_Petrified_Trunk_Full"
    },
    {
      "x": 3,
      "y": 20,
      "z": 2,
      "name": "Wood_Petrified_Trunk_Full",
      "support": 15
    },
    {
      "x": 3,
      "y": 21,
      "z": 2,
      "name": "Wood_Petrified_Trunk_Full",
      "support": 15
    },
    {
      "x": 3,
      "y": 22,
      "z": 2,
      "name": "Wood_Petrified_Trunk_Full",
      "support": 15
    },
    {
      "x": 3,
      "y": 9,
      "z": 3,
      "name": "Wood_Petrified_Trunk_Full",
      "support": 1
    },
    {
      "x": 3,
      "y": 10,
      "z": 3,
      "name": "Wood_Petrified_Trunk_Full"
    },
    {
      "x": 3,
      "y": 16,
      "z": 3,
      "name": "Wood_Burnt_Roots"
    },
    {
      "x": 3,
      "y": 17,
      "z": 3,
      "name": "Wood_Petrified_Trunk_Full",
      "support": 2
    },
    {
      "x": 3,
      "y": 18,
      "z": 3,
      "name": "Wood_Petrified_Trunk"
    },
    {
      "x": 3,
      "y": 19,
      "z": 3,
      "name": "Wood_Petrified_Trunk",
      "rotation": 4
    },
    {
      "x": 3,
      "y": 20,
      "z": 3,
      "name": "Wood_Petrified_Trunk"
    },
    {
      "x": 3,
      "y": 21,
      "z": 3,
      "name": "Wood_Petrified_Trunk"
    },
    {
      "x": 3,
      "y": 22,
      "z": 3,
      "name": "Wood_Petrified_Trunk_Full",
      "support": 15,
      "rotation": 4
    },
    {
      "x": 3,
      "y": 10,
      "z": 4,
      "name": "Wood_Petrified_Trunk_Full",
      "support": 1
    },
    {
      "x": 3,
      "y": 17,
      "z": 4,
      "name": "Wood_Petrified_Trunk_Full",
      "support": 1
    },
    {
      "x": 3,
      "y": 18,
      "z": 4,
      "name": "Wood_Petrified_Trunk"
    },
    {
      "x": 3,
      "y": 19,
      "z": 4,
      "name": "Wood_Petrified_Trunk"
    },
    {
      "x": 3,
      "y": 20,
      "z": 4,
      "name": "Wood_Petrified_Trunk"
    },
    {
      "x": 3,
      "y": 21,
      "z": 4,
      "name": "Wood_Petrified_Trunk"
    },
    {
      "x": 3,
      "y": 22,
      "z": 4,
      "name": "Wood_Petrified_Trunk_Full"
    },
    {
      "x": 3,
      "y": 23,
      "z": 4,
      "name": "Plant_Petals_Black"
    },
    {
      "x": 3,
      "y": 15,
      "z": 5,
      "name": "Plant_Vine_Wall_Dead",
      "support": 15,
      "rotation": 1
    },
    {
      "x": 3,
      "y": 17,
      "z": 5,
      "name": "Wood_Burnt_Roots"
    },
    {
      "x": 3,
      "y": 18,
      "z": 5,
      "name": "Wood_Petrified_Trunk_Full",
      "support": 1
    },
    {
      "x": 3,
      "y": 19,
      "z": 5,
      "name": "Wood_Petrified_Trunk"
    },
    {
      "x": 3,
      "y": 20,
      "z": 5,
      "name": "Wood_Petrified_Trunk"
    },
    {
      "x": 3,
      "y": 21,
      "z": 5,
      "name": "Wood_Petrified_Trunk_Full"
    },
    {
      "x": 3,
      "y": 22,
      "z": 5,
      "name": "Plant_Vine_Wall_Poisoned",
      "support": 15
    },
    {
      "x": 3,
      "y": 15,
      "z": 6,
      "name": "Plant_Vine_Wall_Dead",
      "support": 15,
      "rotation": 1
    },
    {
      "x": 3,
      "y": 18,
      "z": 6,
      "name": "Wood_Petrified_Trunk_Full",
      "support": 1
    },
    {
      "x": 3,
      "y": 19,
      "z": 6,
      "name": "Wood_Petrified_Trunk"
    },
    {
      "x": 3,
      "y": 20,
      "z": 6,
      "name": "Wood_Petrified_Trunk_Full"
    },
    {
      "x": 3,
      "y": 18,
      "z": 7,
      "name": "Plant_Vine_Wall_Dead",
      "support": 15
    },
    {
      "x": 3,
      "y": 8,
      "z": 8,
      "name": "Wood_Petrified_Trunk_Full",
      "support": 2
    },
    {
      "x": 3,
      "y": 9,
      "z": 8,
      "name": "Wood_Petrified_Trunk"
    },
    {
      "x": 3,
      "y": 10,
      "z": 8,
      "name": "Wood_Petrified_Trunk"
    },
    {
      "x": 3,
      "y": 11,
      "z": 8,
      "name": "Wood_Petrified_Trunk_Full"
    },
    {
      "x": 3,
      "y": 12,
      "z": 8,
      "name": "Plant_Bush_Winter",
      "support": 15
    },
    {
      "x": 3,
      "y": 9,
      "z": 9,
      "name": "Wood_Petrified_Trunk_Full",
      "support": 1
    },
    {
      "x": 3,
      "y": 10,
      "z": 9,
      "name": "Wood_Petrified_Trunk"
    },
    {
      "x": 3,
      "y": 11,
      "z": 9,
      "name": "Wood_Petrified_Trunk_Full"
    },
    {
      "x": 3,
      "y": 11,
      "z": 10,
      "name": "Plant_Vine_Wall_Dead",
      "support": 15
    },
    {
      "x": 4,
      "y": 29,
      "z": -9,
      "name": "Wood_Burnt_Roots"
    },
    {
      "x": 4,
      "y": 30,
      "z": -9,
      "name": "Wood_Petrified_Trunk_Full",
      "support": 2,
      "rotation": 4
    },
    {
      "x": 4,
      "y": 29,
      "z": -8,
      "name": "Wood_Burnt_Roots"
    },
    {
      "x": 4,
      "y": 30,
      "z": -8,
      "name": "Wood_Petrified_Trunk",
      "support": 1,
      "rotation": 4
    },
    {
      "x": 4,
      "y": 28,
      "z": -7,
      "name": "Wood_Burnt_Roots"
    },
    {
      "x": 4,
      "y": 29,
      "z": -7,
      "name": "Wood_Petrified_Trunk_Full",
      "support": 2,
      "rotation": 4
    },
    {
      "x": 4,
      "y": 30,
      "z": -7,
      "name": "Wood_Petrified_Trunk",
      "rotation": 4
    },
    {
      "x": 4,
      "y": 28,
      "z": -6,
      "name": "Wood_Burnt_Roots"
    },
    {
      "x": 4,
      "y": 29,
      "z": -6,
      "name": "Wood_Petrified_Trunk",
      "support": 1,
      "rotation": 4
    },
    {
      "x": 4,
      "y": 30,
      "z": -6,
      "name": "Wood_Petrified_Trunk_Full",
      "rotation": 4
    },
    {
      "x": 4,
      "y": 28,
      "z": -5,
      "name": "Wood_Petrified_Trunk_Full",
      "support": 2
    },
    {
      "x": 4,
      "y": 29,
      "z": -5,
      "name": "Wood_Petrified_Trunk_Full",
      "rotation": 4
    },
    {
      "x": 4,
      "y": 28,
      "z": -4,
      "name": "Wood_Petrified_Trunk_Full",
      "support": 1
    },
    {
      "x": 4,
      "y": 30,
      "z": -2,
      "name": "Wood_Petrified_Trunk_Full"
    },
    {
      "x": 4,
      "y": 31,
      "z": -2,
      "name": "Wood_Petrified_Trunk_Full"
    },
    {
      "x": 4,
      "y": 32,
      "z": -2,
      "name": "Wood_Petrified_Branch_Long"
    },
    {
      "x": 4,
      "y": 33,
      "z": -2,
      "name": "Wood_Petrified_Branch_Corner",
      "rotation": 8
    },
    {
      "x": 4,
      "y": 29,
      "z": -1,
      "name": "Wood_Petrified_Trunk_Full"
    },
    {
      "x": 4,
      "y": 30,
      "z": -1,
      "name": "Wood_Petrified_Trunk_Full"
    },
    {
      "x": 4,
      "y": 33,
      "z": -1,
      "name": "Wood_Petrified_Branch_Corner"
    },
    {
      "x": 4,
      "y": 19,
      "z": 1,
      "name": "Plant_Vine_Wall_Poisoned",
      "support": 15,
      "rotation": 2
    },
    {
      "x": 4,
      "y": 8,
      "z": 2,
      "name": "Wood_Petrified_Trunk_Full",
      "support": 1
    },
    {
      "x": 4,
      "y": 9,
      "z": 2,
      "name": "Wood_Petrified_Trunk_Full"
    },
    {
      "x": 4,
      "y": 18,
      "z": 2,
      "name": "Wood_Burnt_Roots"
    },
    {
      "x": 4,
      "y": 19,
      "z": 2,
      "name": "Wood_Petrified_Trunk_Full",
      "support": 1,
      "rotation": 4
    },
    {
      "x": 4,
      "y": 20,
      "z": 2,
      "name": "Wood_Petrified_Trunk_Full",
      "rotation": 4
    },
    {
      "x": 4,
      "y": 21,
      "z": 2,
      "name": "Plant_Bush_Winter",
      "support": 15
    },
    {
      "x": 4,
      "y": 9,
      "z": 3,
      "name": "Wood_Petrified_Trunk_Full",
      "support": 1
    },
    {
      "x": 4,
      "y": 10,
      "z": 3,
      "name": "Wood_Petrified_Trunk_Full"
    },
    {
      "x": 4,
      "y": 18,
      "z": 3,
      "name": "Wood_Petrified_Trunk_Full",
      "support": 1
    },
    {
      "x": 4,
      "y": 19,
      "z": 3,
      "name": "Wood_Petrified_Trunk",
      "rotation": 4
    },
    {
      "x": 4,
      "y": 20,
      "z": 3,
      "name": "Wood_Petrified_Trunk",
      "rotation": 4
    },
    {
      "x": 4,
      "y": 23,
      "z": 3,
      "name": "Wood_Petrified_Trunk_Full",
      "support": 1
    },
    {
      "x": 4,
      "y": 24,
      "z": 3,
      "name": "Wood_Petrified_Trunk_Full"
    },
    {
      "x": 4,
      "y": 18,
      "z": 4,
      "name": "Wood_Petrified_Trunk_Full",
      "support": 1
    },
    {
      "x": 4,
      "y": 19,
      "z": 4,
      "name": "Wood_Petrified_Trunk"
    },
    {
      "x": 4,
      "y": 20,
      "z": 4,
      "name": "Wood_Petrified_Trunk"
    },
    {
      "x": 4,
      "y": 21,
      "z": 4,
      "name": "Wood_Petrified_Trunk"
    },
    {
      "x": 4,
      "y": 22,
      "z": 4,
      "name": "Wood_Petrified_Trunk"
    },
    {
      "x": 4,
      "y": 23,
      "z": 4,
      "name": "Wood_Petrified_Trunk"
    },
    {
      "x": 4,
      "y": 24,
      "z": 4,
      "name": "Wood_Petrified_Trunk"
    },
    {
      "x": 4,
      "y": 25,
      "z": 4,
      "name": "Wood_Petrified_Trunk"
    },
    {
      "x": 4,
      "y": 26,
      "z": 4,
      "name": "Wood_Petrified_Trunk_Full"
    },
    {
      "x": 4,
      "y": 28,
      "z": 4,
      "name": "Plant_Vine_Wall_Poisoned",
      "support": 15,
      "rotation": 3
    },
    {
      "x": 4,
      "y": 18,
      "z": 5,
      "name": "Wood_Petrified_Trunk_Full",
      "support": 2
    },
    {
      "x": 4,
      "y": 19,
      "z": 5,
      "name": "Wood_Petrified_Trunk"
    },
    {
      "x": 4,
      "y": 20,
      "z": 5,
      "name": "Wood_Petrified_Trunk"
    },
    {
      "x": 4,
      "y": 21,
      "z": 5,
      "name": "Wood_Petrified_Trunk"
    },
    {
      "x": 4,
      "y": 22,
      "z": 5,
      "name": "Wood_Petrified_Trunk"
    },
    {
      "x": 4,
      "y": 23,
      "z": 5,
      "name": "Wood_Petrified_Trunk"
    },
    {
      "x": 4,
      "y": 24,
      "z": 5,
      "name": "Wood_Petrified_Trunk"
    },
    {
      "x": 4,
      "y": 25,
      "z": 5,
      "name": "Wood_Petrified_Trunk_Full"
    },
    {
      "x": 4,
      "y": 27,
      "z": 5,
      "name": "Plant_Vine_Wall_Poisoned",
      "support": 15,
      "rotation": 3
    },
    {
      "x": 4,
      "y": 28,
      "z": 5,
      "name": "Plant_Vine_Wall_Poisoned",
      "support": 15,
      "rotation": 3
    },
    {
      "x": 4,
      "y": 19,
      "z": 6,
      "name": "Wood_Petrified_Trunk_Full",
      "support": 1
    },
    {
      "x": 4,
      "y": 20,
      "z": 6,
      "name": "Wood_Petrified_Trunk"
    },
    {
      "x": 4,
      "y": 21,
      "z": 6,
      "name": "Wood_Petrified_Trunk_Full"
    },
    {
      "x": 4,
      "y": 22,
      "z": 6,
      "name": "Plant_Vine_Wall_Poisoned",
      "support": 15
    },
    {
      "x": 4,
      "y": 24,
      "z": 6,
      "name": "Plant_Vine_Wall_Dead",
      "support": 15
    },
    {
      "x": 4,
      "y": 25,
      "z": 6,
      "name": "Plant_Vine_Wall_Poisoned",
      "support": 15
    },
    {
      "x": 4,
      "y": 31,
      "z": 6,
      "name": "Wood_Petrified_Trunk_Full",
      "support": 1,
      "rotation": 4
    },
    {
      "x": 4,
      "y": 19,
      "z": 7,
      "name": "Plant_Vine_Wall_Dead",
      "support": 15
    },
    {
      "x": 4,
      "y": 22,
      "z": 7,
      "name": "Plant_Vine_Wall_Poisoned",
      "support": 15,
      "rotation": 3
    },
    {
      "x": 4,
      "y": 31,
      "z": 7,
      "name": "Wood_Petrified_Trunk",
      "support": 1,
      "rotation": 4
    },
    {
      "x": 4,
      "y": 8,
      "z": 8,
      "name": "Wood_Petrified_Trunk_Full",
      "support": 1
    },
    {
      "x": 4,
      "y": 31,
      "z": 8,
      "name": "Wood_Petrified_Trunk",
      "support": 2,
      "rotation": 4
    },
    {
      "x": 4,
      "y": 32,
      "z": 8,
      "name": "Wood_Petrified_Trunk_Full",
      "rotation": 4
    },
    {
      "x": 4,
      "y": 33,
      "z": 8,
      "name": "Wood_Petrified_Branch_Corner",
      "rotation": 8
    },
    {
      "x": 4,
      "y": 8,
      "z": 9,
      "name": "Wood_Petrified_Trunk_Full",
      "support": 2
    },
    {
      "x": 4,
      "y": 9,
      "z": 9,
      "name": "Wood_Petrified_Trunk_Full"
    },
    {
      "x": 4,
      "y": 31,
      "z": 9,
      "name": "Wood_Petrified_Trunk_Full",
      "support": 3,
      "rotation": 4
    },
    {
      "x": 4,
      "y": 32,
      "z": 9,
      "name": "Wood_Petrified_Trunk_Full",
      "rotation": 4
    },
    {
      "x": 4,
      "y": 33,
      "z": 9,
      "name": "Wood_Petrified_Branch_Long",
      "support": 1,
      "rotation": 4
    },
    {
      "x": 4,
      "y": 24,
      "z": 10,
      "name": "Plant_Vine_Wall_Poisoned",
      "support": 15,
      "rotation": 3
    },
    {
      "x": 4,
      "y": 33,
      "z": 10,
      "name": "Wood_Petrified_Branch_Corner",
      "support": 2
    },
    {
      "x": 4,
      "y": 34,
      "z": 10,
      "name": "Wood_Petrified_Branch_Corner",
      "support": 3,
      "rotation": 8
    },
    {
      "x": 4,
      "y": 24,
      "z": 11,
      "name": "Plant_Vine_Wall_Poisoned",
      "support": 15,
      "rotation": 3
    },
    {
      "x": 4,
      "y": 34,
      "z": 11,
      "name": "Wood_Petrified_Branch_Long",
      "support": 4,
      "rotation": 4
    },
    {
      "x": 4,
      "y": 25,
      "z": 12,
      "name": "Wood_Petrified_Branch_Corner",
      "support": 2,
      "rotation": 3
    },
    {
      "x": 4,
      "y": 26,
      "z": 12,
      "name": "Wood_Petrified_Branch_Corner",
      "support": 3,
      "rotation": 8
    },
    {
      "x": 4,
      "y": 34,
      "z": 12,
      "name": "Wood_Petrified_Branch_Corner",
      "support": 5,
      "rotation": 10
    },
    {
      "x": 4,
      "y": 25,
      "z": 13,
      "name": "Wood_Petrified_Branch_Corner",
      "support": 5
    },
    {
      "x": 4,
      "y": 26,
      "z": 13,
      "name": "Wood_Petrified_Branch_Corner",
      "support": 4,
      "rotation": 10
    },
    {
      "x": 5,
      "y": 29,
      "z": -6,
      "name": "Wood_Petrified_Trunk_Full",
      "support": 2,
      "rotation": 4
    },
    {
      "x": 5,
      "y": 29,
      "z": -5,
      "name": "Wood_Petrified_Trunk_Full",
      "support": 1,
      "rotation": 4
    },
    {
      "x": 5,
      "y": 19,
      "z": -1,
      "name": "Plant_Vine_Wall_Poisoned",
      "support": 15,
      "rotation": 3
    },
    {
      "x": 5,
      "y": 19,
      "z": 0,
      "name": "Plant_Vine_Wall_Dead",
      "support": 15,
      "rotation": 2
    },
    {
      "x": 5,
      "y": 7,
      "z": 1,
      "name": "Wood_Petrified_Trunk_Full",
      "support": 2
    },
    {
      "x": 5,
      "y": 19,
      "z": 1,
      "name": "Wood_Petrified_Trunk_Full",
      "support": 1,
      "rotation": 4
    },
    {
      "x": 5,
      "y": 20,
      "z": 1,
      "name": "Wood_Petrified_Trunk_Full",
      "rotation": 4
    },
    {
      "x": 5,
      "y": 21,
      "z": 1,
      "name": "Necrotic_Grass"
    },
    {
      "x": 5,
      "y": 7,
      "z": 2,
      "name": "Wood_Petrified_Trunk_Full",
      "support": 1
    },
    {
      "x": 5,
      "y": 8,
      "z": 2,
      "name": "Wood_Petrified_Trunk_Full"
    },
    {
      "x": 5,
      "y": 18,
      "z": 2,
      "name": "Wood_Petrified_Trunk_Full",
      "support": 3,
      "rotation": 4
    },
    {
      "x": 5,
      "y": 19,
      "z": 2,
      "name": "Wood_Petrified_Trunk"
    },
    {
      "x": 5,
      "y": 20,
      "z": 2,
      "name": "Wood_Petrified_Trunk",
      "rotation": 4
    },
    {
      "x": 5,
      "y": 29,
      "z": 2,
      "name": "Plant_Vine_Wall_Poisoned",
      "support": 15,
      "rotation": 3
    },
    {
      "x": 5,
      "y": 3,
      "z": 3,
      "name": "Wood_Burnt_Roots"
    },
    {
      "x": 5,
      "y": 4,
      "z": 3,
      "name": "Wood_Petrified_Trunk"
    },
    {
      "x": 5,
      "y": 5,
      "z": 3,
      "name": "Wood_Petrified_Trunk"
    },
    {
      "x": 5,
      "y": 6,
      "z": 3,
      "name": "Wood_Petrified_Trunk"
    },
    {
      "x": 5,
      "y": 7,
      "z": 3,
      "name": "Wood_Petrified_Trunk_Full"
    },
    {
      "x": 5,
      "y": 18,
      "z": 3,
      "name": "Wood_Petrified_Trunk_Full",
      "support": 2
    },
    {
      "x": 5,
      "y": 19,
      "z": 3,
      "name": "Wood_Petrified_Trunk"
    },
    {
      "x": 5,
      "y": 20,
      "z": 3,
      "name": "Wood_Petrified_Trunk_Full",
      "rotation": 4
    },
    {
      "x": 5,
      "y": 24,
      "z": 3,
      "name": "Wood_Petrified_Trunk_Full",
      "support": 1
    },
    {
      "x": 5,
      "y": 25,
      "z": 3,
      "name": "Wood_Petrified_Trunk"
    },
    {
      "x": 5,
      "y": 26,
      "z": 3,
      "name": "Wood_Petrified_Trunk"
    },
    {
      "x": 5,
      "y": 27,
      "z": 3,
      "name": "Wood_Petrified_Trunk_Full"
    },
    {
      "x": 5,
      "y": 29,
      "z": 3,
      "name": "Plant_Vine_Wall_Poisoned",
      "support": 15,
      "rotation": 3
    },
    {
      "x": 5,
      "y": 18,
      "z": 4,
      "name": "Wood_Petrified_Trunk_Full",
