{
  "version": 8,
  "blockIdVersion": 11,
  "anchorX": -3,
  "anchorY": 2,
  "anchorZ": -1,
  "blocks": [
    {
      "x": -7,
      "y": 0,
      "z": -5,
      "name": "Necrotic_Stone"
    },
    {
      "x": -7,
      "y": 1,
      "z": -5,
      "name": "Rock_Slate_Cobble"
    },
    {
      "x": -7,
      "y": 0,
      "z": -4,
      "name": "Necrotic_Stone"
    },
    {
      "x": -7,
      "y": 1,
      "z": -4,
      "name": "Rock_Slate_Cobble"
    },
    {
      "x": -7,
      "y": 0,
      "z": -3,
      "name": "Necrotic_Stone"
    },
    {
      "x": -7,
      "y": 1,
      "z": -3,
      "name": "Rock_Slate_Cobble"
    },
    {
      "x": -7,
      "y": 0,
      "z": -2,
      "name": "Necrotic_Stone"
    },
    {
      "x": -7,
      "y": 1,
      "z": -2,
      "name": "Rock_Slate_Cobble"
    },
    {
      "x": -7,
      "y": 2,
      "z": -2,
      "name": "Necrotic_Fence",
      "rotation": 3
    },
    {
      "x": -7,
      "y": 0,
      "z": -1,
      "name": "Necrotic_Stone"
    },
    {
      "x": -7,
      "y": 1,
      "z": -1,
      "name": "Rock_Slate_Cobble"
    },
    {
      "x": -7,
      "y": 2,
      "z": -1,
      "name": "Necrotic_Fence",
      "rotation": 3
    },
    {
      "x": -7,
      "y": 6,
      "z": -1,
      "name": "Rock_Slate_Cobble_Roof_Shallow",
      "rotation": 3
    },
    {
      "x": -7,
      "y": -1,
      "z": 0,
      "name": "Necrotic_Stone"
    },
    {
      "x": -7,
      "y": 0,
      "z": 0,
      "name": "Necrotic_Stone"
    },
    {
      "x": -7,
      "y": 1,
      "z": 0,
      "name": "Rock_Slate_Cobble"
    },
    {
      "x": -7,
      "y": 2,
      "z": 0,
      "name": "Necrotic_Fence",
      "rotation": 3
    },
    {
      "x": -7,
      "y": 6,
      "z": 0,
      "name": "Rock_Slate_Cobble_Roof_Shallow",
      "rotation": 3
    },
    {
      "x": -7,
      "y": -1,
      "z": 1,
      "name": "Necrotic_Stone"
    },
    {
      "x": -7,
      "y": 0,
      "z": 1,
      "name": "Necrotic_Stone"
    },
    {
      "x": -7,
      "y": 1,
      "z": 1,
      "name": "Rock_Slate_Cobble"
    },
    {
      "x": -7,
      "y": 2,
      "z": 1,
      "name": "Necrotic_Fence",
      "rotation": 3
    },
    {
      "x": -7,
      "y": 6,
      "z": 1,
      "name": "Rock_Slate_Cobble_Roof_Shallow",
      "rotation": 3
    },
    {
      "x": -7,
      "y": -1,
      "z": 2,
      "name": "Necrotic_Stone"
    },
    {
      "x": -7,
      "y": 0,
      "z": 2,
      "name": "Necrotic_Stone"
    },
    {
      "x": -7,
      "y": 1,
      "z": 2,
      "name": "Rock_Slate_Cobble"
    },
    {
      "x": -7,
      "y": 2,
      "z": 2,
      "name": "Necrotic_Fence",
      "rotation": 3
    },
    {
      "x": -7,
      "y": 6,
      "z": 2,
      "name": "Rock_Slate_Cobble_Roof_Shallow",
      "rotation": 3
    },
    {
      "x": -7,
      "y": -1,
      "z": 3,
      "name": "Necrotic_Stone"
    },
    {
      "x": -7,
      "y": 0,
      "z": 3,
      "name": "Necrotic_Stone"
    },
    {
      "x": -7,
      "y": 1,
      "z": 3,
      "name": "Rock_Slate_Cobble"
    },
    {
      "x": -7,
      "y": 2,
      "z": 3,
      "name": "Necrotic_Fence",
      "rotation": 3
    },
    {
      "x": -7,
      "y": 6,
      "z": 3,
      "name": "Rock_Slate_Cobble_Roof_Shallow",
      "rotation": 3
    },
    {
      "x": -7,
      "y": 0,
      "z": 4,
      "name": "Necrotic_Stone"
    },
    {
      "x": -7,
      "y": 1,
      "z": 4,
      "name": "Rock_Slate_Cobble"
    },
    {
      "x": -7,
      "y": 2,
      "z": 4,
      "name": "Necrotic_Fence",
      "rotation": 3
    },
    {
      "x": -7,
      "y": 6,
      "z": 4,
      "name": "Rock_Slate_Cobble_Roof_Shallow",
      "rotation": 3
    },
    {
      "x": -7,
      "y": 0,
      "z": 5,
      "name": "Necrotic_Stone"
    },
    {
      "x": -7,
      "y": 1,
      "z": 5,
      "name": "Rock_Slate_Cobble"
    },
    {
      "x": -7,
      "y": 2,
      "z": 5,
      "name": "Necrotic_Fence",
      "rotation": 3
    },
    {
      "x": -7,
      "y": 6,
      "z": 5,
      "name": "Rock_Slate_Cobble_Roof_Shallow",
      "rotation": 3
    },
    {
      "x": -7,
      "y": 0,
      "z": 6,
      "name": "Necrotic_Stone"
    },
    {
      "x": -7,
      "y": 1,
      "z": 6,
      "name": "Rock_Slate_Cobble"
    },
    {
      "x": -7,
      "y": 6,
      "z": 6,
      "name": "Rock_Slate_Cobble_Roof_Shallow",
      "rotation": 3
    },
    {
      "x": -7,
      "y": 0,
      "z": 7,
      "name": "Necrotic_Stone"
    },
    {
      "x": -7,
      "y": 1,
      "z": 7,
      "name": "Rock_Slate_Cobble"
    },
    {
      "x": -7,
      "y": 6,
      "z": 7,
      "name": "Rock_Slate_Cobble_Roof_Shallow",
      "rotation": 3
    },
    {
      "x": -6,
      "y": 0,
      "z": -7,
      "name": "Necrotic_Stone"
    },
    {
      "x": -6,
      "y": 1,
      "z": -7,
      "name": "Necrotic_Sand",
      "support": 15
    },
    {
      "x": -6,
      "y": 0,
      "z": -6,
      "name": "Necrotic_Stone"
    },
    {
      "x": -6,
      "y": 1,
      "z": -6,
      "name": "Necrotic_Sand",
      "support": 15
    },
    {
      "x": -6,
      "y": -1,
      "z": -5,
      "name": "Necrotic_Stone"
    },
    {
      "x": -6,
      "y": 0,
      "z": -5,
      "name": "Necrotic_Stone"
    },
    {
      "x": -6,
      "y": 1,
      "z": -5,
      "name": "Necrotic_Sand",
      "support": 15
    },
    {
      "x": -6,
      "y": 2,
      "z": -5,
      "name": "Prickly_Bush"
    },
    {
      "x": -6,
      "y": -1,
      "z": -4,
      "name": "Necrotic_Stone"
    },
    {
      "x": -6,
      "y": 0,
      "z": -4,
      "name": "Necrotic_Stone"
    },
    {
      "x": -6,
      "y": 1,
      "z": -4,
      "name": "Rock_Slate_Cobble"
    },
    {
      "x": -6,
      "y": -1,
      "z": -3,
      "name": "Necrotic_Stone"
    },
    {
      "x": -6,
      "y": 0,
      "z": -3,
      "name": "Necrotic_Stone"
    },
    {
      "x": -6,
      "y": 1,
      "z": -3,
      "name": "Rock_Slate_Cobble"
    },
    {
      "x": -6,
      "y": -3,
      "z": -2,
      "name": "Wood_Burnt_Roots"
    },
    {
      "x": -6,
      "y": -2,
      "z": -2,
      "name": "Necrotic_Stone"
    },
    {
      "x": -6,
      "y": -1,
      "z": -2,
      "name": "Necrotic_Stone"
    },
    {
      "x": -6,
      "y": 0,
      "z": -2,
      "name": "Necrotic_Stone"
    },
    {
      "x": -6,
      "y": 1,
      "z": -2,
      "name": "Rock_Slate_Cobble"
    },
    {
      "x": -6,
      "y": 2,
      "z": -2,
      "name": "Rubble_Slate_Medium",
      "support": 15
    },
    {
      "x": -6,
      "y": -2,
      "z": -1,
      "name": "Necrotic_Stone"
    },
    {
      "x": -6,
      "y": -1,
      "z": -1,
      "name": "Necrotic_Stone"
    },
    {
      "x": -6,
      "y": 0,
      "z": -1,
      "name": "Necrotic_Stone"
    },
    {
      "x": -6,
      "y": 1,
      "z": -1,
      "name": "Rock_Slate_Cobble"
    },
    {
      "x": -6,
      "y": 2,
      "z": -1,
      "name": "Plant_Bush_Winter",
      "support": 15
    },
    {
      "x": -6,
      "y": 6,
      "z": -1,
      "name": "Rock_Slate_Cobble_Roof_Shallow",
      "filler": 1,
      "rotation": 3
    },
    {
      "x": -6,
      "y": -2,
      "z": 0,
      "name": "Necrotic_Stone"
    },
    {
      "x": -6,
      "y": -1,
      "z": 0,
      "name": "Necrotic_Stone"
    },
    {
      "x": -6,
      "y": 0,
      "z": 0,
      "name": "Necrotic_Stone"
    },
    {
      "x": -6,
      "y": 1,
      "z": 0,
      "name": "Rock_Slate_Cobble"
    },
    {
      "x": -6,
      "y": 6,
      "z": 0,
      "name": "Rock_Slate_Cobble_Roof_Shallow",
      "filler": 1,
      "rotation": 3
    },
    {
      "x": -6,
      "y": -2,
      "z": 1,
      "name": "Necrotic_Stone"
    },
    {
      "x": -6,
      "y": -1,
      "z": 1,
      "name": "Necrotic_Stone"
    },
    {
      "x": -6,
      "y": 0,
      "z": 1,
      "name": "Necrotic_Stone"
    },
    {
      "x": -6,
      "y": 1,
      "z": 1,
      "name": "Rock_Slate_Cobble"
    },
    {
      "x": -6,
      "y": 2,
      "z": 1,
      "name": "Plant_Leaves_Camphor",
      "support": 15
    },
    {
      "x": -6,
      "y": 6,
      "z": 1,
      "name": "Rock_Slate_Cobble_Roof_Shallow",
      "filler": 1,
      "rotation": 3
    },
    {
      "x": -6,
      "y": -3,
      "z": 2,
      "name": "Wood_Burnt_Roots"
    },
    {
      "x": -6,
      "y": -2,
      "z": 2,
      "name": "Necrotic_Stone"
    },
    {
      "x": -6,
      "y": -1,
      "z": 2,
      "name": "Necrotic_Stone"
    },
    {
      "x": -6,
      "y": 0,
      "z": 2,
      "name": "Necrotic_Stone"
    },
    {
      "x": -6,
      "y": 1,
      "z": 2,
      "name": "Rock_Slate_Cobble"
    },
    {
      "x": -6,
      "y": 2,
      "z": 2,
      "name": "Plant_Leaves_Dead",
      "support": 15
    },
    {
      "x": -6,
      "y": 3,
      "z": 2,
      "name": "Plant_Leaves_Dead",
      "support": 15
    },
    {
      "x": -6,
      "y": 6,
      "z": 2,
      "name": "Rock_Slate_Cobble_Roof_Shallow",
      "filler": 1,
      "rotation": 3
    },
    {
      "x": -6,
      "y": 7,
      "z": 2,
      "name": "Plant_Leaves_Dead",
      "support": 15
    },
    {
      "x": -6,
      "y": -2,
      "z": 3,
      "name": "Necrotic_Stone"
    },
    {
      "x": -6,
      "y": -1,
      "z": 3,
      "name": "Necrotic_Stone"
    },
    {
      "x": -6,
      "y": 0,
      "z": 3,
      "name": "Necrotic_Stone"
    },
    {
      "x": -6,
      "y": 1,
      "z": 3,
      "name": "Rock_Slate_Cobble"
    },
    {
      "x": -6,
      "y": 2,
      "z": 3,
      "name": "Plant_Leaves_Dead",
      "support": 15
    },
    {
      "x": -6,
      "y": 6,
      "z": 3,
      "name": "Rock_Slate_Cobble_Roof_Shallow",
      "filler": 1,
      "rotation": 3
    },
    {
      "x": -6,
      "y": 7,
      "z": 3,
      "name": "Plant_Leaves_Dead",
      "support": 15
    },
    {
      "x": -6,
      "y": -3,
      "z": 4,
      "name": "Wood_Burnt_Roots"
    },
    {
      "x": -6,
      "y": -2,
      "z": 4,
      "name": "Necrotic_Stone"
    },
    {
      "x": -6,
      "y": -1,
      "z": 4,
      "name": "Necrotic_Stone"
    },
    {
      "x": -6,
      "y": 0,
      "z": 4,
      "name": "Necrotic_Stone"
    },
    {
      "x": -6,
      "y": 1,
      "z": 4,
      "name": "Rock_Slate_Cobble"
    },
    {
      "x": -6,
      "y": 2,
      "z": 4,
      "name": "Plant_Bush_Winter",
      "support": 15
    },
    {
      "x": -6,
      "y": 6,
      "z": 4,
      "name": "Rock_Slate_Cobble_Roof_Shallow",
      "filler": 1,
      "rotation": 3
    },
    {
      "x": -6,
      "y": -1,
      "z": 5,
      "name": "Necrotic_Stone"
    },
    {
      "x": -6,
      "y": 0,
      "z": 5,
      "name": "Necrotic_Stone"
    },
    {
      "x": -6,
      "y": 1,
      "z": 5,
      "name": "Rock_Slate_Cobble"
    },
    {
      "x": -6,
      "y": 6,
      "z": 5,
      "name": "Rock_Slate_Cobble_Roof_Shallow",
      "filler": 1,
      "rotation": 3
    },
    {
      "x": -6,
      "y": 7,
      "z": 5,
      "name": "Plant_Leaves_Dead",
      "support": 15
    },
    {
      "x": -6,
      "y": -1,
      "z": 6,
      "name": "Necrotic_Stone"
    },
    {
      "x": -6,
      "y": 0,
      "z": 6,
      "name": "Necrotic_Stone"
    },
    {
      "x": -6,
      "y": 1,
      "z": 6,
      "name": "Rock_Slate_Cobble"
    },
    {
      "x": -6,
      "y": 6,
      "z": 6,
      "name": "Rock_Slate_Cobble_Roof_Shallow",
      "filler": 1,
      "rotation": 3
    },
    {
      "x": -6,
      "y": 7,
      "z": 6,
      "name": "Plant_Leaves_Dead",
      "support": 15
    },
    {
      "x": -6,
      "y": 0,
      "z": 7,
      "name": "Necrotic_Stone"
    },
    {
      "x": -6,
      "y": 1,
      "z": 7,
      "name": "Rock_Slate_Cobble"
    },
    {
      "x": -6,
      "y": 6,
      "z": 7,
      "name": "Rock_Slate_Cobble_Roof_Shallow",
      "filler": 1,
      "rotation": 3
    },
    {
      "x": -6,
      "y": 0,
      "z": 8,
      "name": "Necrotic_Stone"
    },
    {
      "x": -6,
      "y": 1,
      "z": 8,
      "name": "Rock_Slate_Cobble"
    },
    {
      "x": -5,
      "y": 0,
      "z": -8,
      "name": "Necrotic_Stone"
    },
    {
      "x": -5,
      "y": 1,
      "z": -8,
      "name": "Necrotic_Sand",
      "support": 15
    },
    {
      "x": -5,
      "y": 0,
      "z": -7,
      "name": "Necrotic_Stone"
    },
    {
      "x": -5,
      "y": 1,
      "z": -7,
      "name": "Necrotic_Sand",
      "support": 15
    },
    {
      "x": -5,
      "y": -2,
      "z": -6,
      "name": "Wood_Burnt_Roots"
    },
    {
      "x": -5,
      "y": -1,
      "z": -6,
      "name": "Necrotic_Stone"
    },
    {
      "x": -5,
      "y": 0,
      "z": -6,
      "name": "Necrotic_Stone"
    },
    {
      "x": -5,
      "y": 1,
      "z": -6,
      "name": "Necrotic_Sand",
      "support": 15
    },
    {
      "x": -5,
      "y": 2,
      "z": -6,
      "name": "Rubble_Slate_Medium",
      "support": 15
    },
    {
      "x": -5,
      "y": -1,
      "z": -5,
      "name": "Necrotic_Stone"
    },
    {
      "x": -5,
      "y": 0,
      "z": -5,
      "name": "Necrotic_Stone"
    },
    {
      "x": -5,
      "y": 1,
      "z": -5,
      "name": "Necrotic_Sand",
      "support": 15
    },
    {
      "x": -5,
      "y": -1,
      "z": -4,
      "name": "Necrotic_Stone"
    },
    {
      "x": -5,
      "y": 0,
      "z": -4,
      "name": "Necrotic_Stone"
    },
    {
      "x": -5,
      "y": 1,
      "z": -4,
      "name": "Necrotic_Sand",
      "support": 15
    },
    {
      "x": -5,
      "y": -2,
      "z": -3,
      "name": "Necrotic_Stone"
    },
    {
      "x": -5,
      "y": -1,
      "z": -3,
      "name": "Necrotic_Stone"
    },
    {
      "x": -5,
      "y": 0,
      "z": -3,
      "name": "Necrotic_Stone"
    },
    {
      "x": -5,
      "y": 1,
      "z": -3,
      "name": "Necrotic_Sand",
      "support": 15
    },
    {
      "x": -5,
      "y": 2,
      "z": -3,
      "name": "Plant_Crop_Mushroom_Flatcap_Green",
      "components": {
        "Components": {
          "FarmingBlock": {
            "LastTickGameTime": "0001-01-01T12:00:00Z"
          }
        }
      }
    },
    {
      "x": -5,
      "y": -2,
      "z": -2,
      "name": "Necrotic_Stone"
    },
    {
      "x": -5,
      "y": -1,
      "z": -2,
      "name": "Necrotic_Stone"
    },
    {
      "x": -5,
      "y": 0,
      "z": -2,
      "name": "Necrotic_Stone"
    },
    {
      "x": -5,
      "y": 1,
      "z": -2,
      "name": "Rock_Slate_Cobble"
    },
    {
      "x": -5,
      "y": 2,
      "z": -2,
      "name": "Necrotic_Grass"
    },
    {
      "x": -5,
      "y": -2,
      "z": -1,
      "name": "Necrotic_Stone"
    },
    {
      "x": -5,
      "y": -1,
      "z": -1,
      "name": "Necrotic_Stone"
    },
    {
      "x": -5,
      "y": 0,
      "z": -1,
      "name": "Necrotic_Stone"
    },
    {
      "x": -5,
      "y": 1,
      "z": -1,
      "name": "Rock_Slate_Cobble"
    },
    {
      "x": -5,
      "y": 2,
      "z": -1,
      "name": "Rock_Slate_Brick_Pillar_Base"
    },
    {
      "x": -5,
      "y": 3,
      "z": -1,
      "name": "Rock_Slate_Brick_Pillar_Base"
    },
    {
      "x": -5,
      "y": 4,
      "z": -1,
      "name": "Rock_Slate_Brick_Pillar_Middle"
    },
    {
      "x": -5,
      "y": 5,
      "z": -1,
      "name": "Rock_Slate_Brick_Pillar_Base",
      "rotation": 8
    },
    {
      "x": -5,
      "y": 6,
      "z": -1,
      "name": "Rock_Slate_Brick_Ornate"
    },
    {
      "x": -5,
      "y": 7,
      "z": -1,
      "name": "Rock_Slate_Brick_Roof",
      "rotation": 3
    },
    {
      "x": -5,
      "y": -3,
      "z": 0,
      "name": "Necrotic_Stone"
    },
    {
      "x": -5,
      "y": -2,
      "z": 0,
      "name": "Necrotic_Stone"
    },
    {
      "x": -5,
      "y": -1,
      "z": 0,
      "name": "Necrotic_Stone"
    },
    {
      "x": -5,
      "y": 0,
      "z": 0,
      "name": "Necrotic_Stone"
    },
    {
      "x": -5,
      "y": 1,
      "z": 0,
      "name": "Rock_Slate_Cobble"
    },
    {
      "x": -5,
      "y": 2,
      "z": 0,
      "name": "Rock_Slate_Brick_Decorative"
    },
    {
      "x": -5,
      "y": 3,
      "z": 0,
      "name": "Rock_Slate_Brick"
    },
    {
      "x": -5,
      "y": 4,
      "z": 0,
      "name": "Rock_Slate_Brick"
    },
    {
      "x": -5,
      "y": 5,
      "z": 0,
      "name": "Rock_Slate_Brick_Decorative"
    },
    {
      "x": -5,
      "y": 6,
      "z": 0,
      "name": "Rock_Slate_Brick_Decorative"
    },
    {
      "x": -5,
      "y": 7,
      "z": 0,
      "name": "Rock_Slate_Brick_Roof",
      "rotation": 3
    },
    {
      "x": -5,
      "y": -3,
      "z": 1,
      "name": "Necrotic_Stone"
    },
    {
      "x": -5,
      "y": -2,
      "z": 1,
      "name": "Necrotic_Stone"
    },
    {
      "x": -5,
      "y": -1,
      "z": 1,
      "name": "Necrotic_Stone"
    },
    {
      "x": -5,
      "y": 0,
      "z": 1,
      "name": "Necrotic_Stone"
    },
    {
      "x": -5,
      "y": 1,
      "z": 1,
      "name": "Rock_Slate_Cobble"
    },
    {
      "x": -5,
      "y": 2,
      "z": 1,
      "name": "Rock_Slate_Brick"
    },
    {
      "x": -5,
      "y": 3,
      "z": 1,
      "name": "Rock_Slate_Brick"
    },
    {
      "x": -5,
      "y": 4,
      "z": 1,
      "name": "Necrotic_Window",
      "rotation": 1
    },
    {
      "x": -5,
      "y": 5,
      "z": 1,
      "name": "Rock_Slate_Brick"
    },
    {
      "x": -5,
      "y": 6,
      "z": 1,
      "name": "Rock_Slate_Brick"
    },
    {
      "x": -5,
      "y": 7,
      "z": 1,
      "name": "Rock_Slate_Brick_Roof",
      "rotation": 3
    },
    {
      "x": -5,
      "y": 8,
      "z": 1,
      "name": "Plant_Leaves_Dead",
      "support": 15
    },
    {
      "x": -5,
      "y": -3,
      "z": 2,
      "name": "Necrotic_Stone"
    },
    {
      "x": -5,
      "y": -2,
      "z": 2,
      "name": "Necrotic_Stone"
    },
    {
      "x": -5,
      "y": -1,
      "z": 2,
      "name": "Necrotic_Stone"
    },
    {
      "x": -5,
      "y": 0,
      "z": 2,
      "name": "Necrotic_Stone"
    },
    {
      "x": -5,
      "y": 1,
      "z": 2,
      "name": "Rock_Slate_Cobble"
    },
    {
      "x": -5,
      "y": 2,
      "z": 2,
      "name": "Rock_Slate_Brick_Decorative"
    },
    {
      "x": -5,
      "y": 3,
      "z": 2,
      "name": "Rock_Slate_Brick"
    },
    {
      "x": -5,
      "y": 4,
      "z": 2,
      "name": "Rock_Slate_Brick"
    },
    {
      "x": -5,
      "y": 5,
      "z": 2,
      "name": "Rock_Slate_Brick_Decorative"
    },
    {
      "x": -5,
      "y": 6,
      "z": 2,
      "name": "Rock_Slate_Brick"
    },
    {
      "x": -5,
      "y": 7,
      "z": 2,
      "name": "Rock_Slate_Brick_Roof",
      "rotation": 3
    },
    {
      "x": -5,
      "y": -3,
      "z": 3,
      "name": "Necrotic_Stone"
    },
    {
      "x": -5,
      "y": -2,
      "z": 3,
      "name": "Necrotic_Stone"
    },
    {
      "x": -5,
      "y": -1,
      "z": 3,
      "name": "Necrotic_Stone"
    },
    {
      "x": -5,
      "y": 0,
      "z": 3,
      "name": "Necrotic_Stone"
    },
    {
      "x": -5,
      "y": 1,
      "z": 3,
      "name": "Rock_Slate_Cobble"
    },
    {
      "x": -5,
      "y": 2,
      "z": 3,
      "name": "Rock_Slate_Brick"
    },
    {
      "x": -5,
      "y": 3,
      "z": 3,
      "name": "Rock_Slate_Brick"
    },
    {
      "x": -5,
      "y": 4,
      "z": 3,
      "name": "Necrotic_Window",
      "rotation": 1
    },
    {
      "x": -5,
      "y": 5,
      "z": 3,
      "name": "Rock_Slate_Brick"
    },
    {
      "x": -5,
      "y": 6,
      "z": 3,
      "name": "Rock_Slate_Brick"
    },
    {
      "x": -5,
      "y": 7,
      "z": 3,
      "name": "Rock_Slate_Brick_Roof",
      "rotation": 3
    },
    {
      "x": -5,
      "y": -2,
      "z": 4,
      "name": "Necrotic_Stone"
    },
    {
      "x": -5,
      "y": -1,
      "z": 4,
      "name": "Necrotic_Stone"
    },
    {
      "x": -5,
      "y": 0,
      "z": 4,
      "name": "Necrotic_Stone"
    },
    {
      "x": -5,
      "y": 1,
      "z": 4,
      "name": "Rock_Slate_Cobble"
    },
    {
      "x": -5,
      "y": 2,
      "z": 4,
      "name": "Rock_Slate_Brick_Decorative"
    },
    {
      "x": -5,
      "y": 3,
      "z": 4,
      "name": "Rock_Slate_Brick"
    },
    {
      "x": -5,
      "y": 4,
      "z": 4,
      "name": "Rock_Slate_Brick"
    },
    {
      "x": -5,
      "y": 5,
      "z": 4,
      "name": "Rock_Slate_Brick_Decorative"
    },
    {
      "x": -5,
      "y": 6,
      "z": 4,
      "name": "Rock_Slate_Brick"
    },
    {
      "x": -5,
      "y": 7,
      "z": 4,
      "name": "Rock_Slate_Brick_Roof",
      "rotation": 3
    },
    {
      "x": -5,
      "y": 8,
      "z": 4,
      "name": "Plant_Leaves_Dead",
      "support": 15
    },
    {
      "x": -5,
      "y": -1,
      "z": 5,
      "name": "Necrotic_Stone"
    },
    {
      "x": -5,
      "y": 0,
      "z": 5,
      "name": "Necrotic_Stone"
    },
    {
      "x": -5,
      "y": 1,
      "z": 5,
      "name": "Rock_Slate_Cobble"
    },
    {
      "x": -5,
      "y": 2,
      "z": 5,
      "name": "Rock_Slate_Brick"
    },
    {
      "x": -5,
      "y": 3,
      "z": 5,
      "name": "Rock_Slate_Brick"
    },
    {
      "x": -5,
      "y": 4,
      "z": 5,
      "name": "Necrotic_Window",
      "rotation": 1
    },
    {
      "x": -5,
      "y": 5,
      "z": 5,
      "name": "Rock_Slate_Brick"
    },
    {
      "x": -5,
      "y": 6,
      "z": 5,
      "name": "Rock_Slate_Brick"
    },
    {
      "x": -5,
      "y": 7,
      "z": 5,
      "name": "Rock_Slate_Brick_Roof",
      "rotation": 3
    },
    {
      "x": -5,
      "y": -2,
      "z": 6,
      "name": "Wood_Burnt_Roots"
    },
    {
      "x": -5,
      "y": -1,
      "z": 6,
      "name": "Necrotic_Stone"
    },
    {
      "x": -5,
      "y": 0,
      "z": 6,
      "name": "Necrotic_Stone"
    },
    {
      "x": -5,
      "y": 1,
      "z": 6,
      "name": "Rock_Slate_Cobble"
    },
    {
      "x": -5,
      "y": 2,
      "z": 6,
      "name": "Rock_Slate_Brick_Decorative"
    },
    {
      "x": -5,
      "y": 3,
      "z": 6,
      "name": "Rock_Slate_Brick"
    },
    {
      "x": -5,
      "y": 4,
      "z": 6,
      "name": "Rock_Slate_Brick"
    },
    {
      "x": -5,
      "y": 5,
      "z": 6,
      "name": "Rock_Slate_Brick_Decorative"
    },
    {
      "x": -5,
      "y": 6,
      "z": 6,
      "name": "Rock_Slate_Brick"
    },
    {
      "x": -5,
      "y": 7,
      "z": 6,
      "name": "Rock_Slate_Brick_Roof",
      "rotation": 3
    },
    {
      "x": -5,
      "y": 0,
      "z": 7,
      "name": "Necrotic_Stone"
    },
    {
      "x": -5,
      "y": 1,
      "z": 7,
      "name": "Rock_Slate_Cobble"
    },
    {
      "x": -5,
      "y": 2,
      "z": 7,
      "name": "Rock_Slate_Brick_Pillar_Base"
    },
    {
      "x": -5,
      "y": 3,
      "z": 7,
      "name": "Rock_Slate_Brick_Pillar_Middle"
    },
    {
      "x": -5,
      "y": 4,
      "z": 7,
      "name": "Rock_Slate_Brick_Pillar_Middle"
    },
    {
      "x": -5,
      "y": 5,
      "z": 7,
      "name": "Rock_Slate_Brick_Pillar_Middle"
    },
    {
      "x": -5,
      "y": 6,
      "z": 7,
      "name": "Rock_Slate_Brick_Decorative"
    },
    {
      "x": -5,
      "y": 7,
      "z": 7,
      "name": "Rock_Slate_Brick_Roof",
      "rotation": 3
    },
    {
      "x": -5,
      "y": 0,
      "z": 8,
      "name": "Necrotic_Stone"
    },
    {
      "x": -5,
      "y": 1,
      "z": 8,
      "name": "Rock_Slate_Cobble"
    },
    {
      "x": -5,
      "y": 0,
      "z": 9,
      "name": "Necrotic_Stone"
    },
    {
      "x": -5,
      "y": 1,
      "z": 9,
      "name": "Rock_Slate_Cobble"
    },
    {
      "x": -4,
      "y": 0,
      "z": -9,
      "name": "Necrotic_Stone"
    },
    {
      "x": -4,
      "y": 1,
      "z": -9,
      "name": "Necrotic_Sand",
      "support": 15
    },
    {
      "x": -4,
      "y": 0,
      "z": -8,
      "name": "Necrotic_Stone"
    },
    {
      "x": -4,
      "y": 1,
      "z": -8,
      "name": "Necrotic_Sand",
      "support": 15
    },
    {
      "x": -4,
      "y": -1,
      "z": -7,
      "name": "Necrotic_Stone"
    },
    {
      "x": -4,
      "y": 0,
      "z": -7,
      "name": "Necrotic_Stone"
    },
    {
      "x": -4,
      "y": 1,
      "z": -7,
      "name": "Necrotic_Sand",
      "support": 15
    },
    {
      "x": -4,
      "y": 2,
      "z": -7,
      "name": "Plant_Crop_Mushroom_Flatcap_Green",
      "components": {
        "Components": {
          "FarmingBlock": {
            "LastTickGameTime": "0001-01-01T12:00:00Z"
          }
        }
      }
    },
    {
      "x": -4,
      "y": -2,
      "z": -6,
      "name": "Wood_Burnt_Roots"
    },
    {
      "x": -4,
      "y": -1,
      "z": -6,
      "name": "Necrotic_Stone"
    },
    {
      "x": -4,
      "y": 0,
      "z": -6,
      "name": "Necrotic_Stone"
    },
    {
      "x": -4,
      "y": 1,
      "z": -6,
      "name": "Necrotic_Sand",
      "support": 15
    },
    {
      "x": -4,
      "y": -1,
      "z": -5,
      "name": "Necrotic_Stone"
    },
    {
      "x": -4,
      "y": 0,
      "z": -5,
      "name": "Necrotic_Stone"
    },
    {
      "x": -4,
      "y": 1,
      "z": -5,
      "name": "Necrotic_Sand",
      "support": 15
    },
    {
      "x": -4,
      "y": -2,
      "z": -4,
      "name": "Necrotic_Stone"
    },
    {
      "x": -4,
      "y": -1,
      "z": -4,
      "name": "Necrotic_Stone"
    },
    {
      "x": -4,
      "y": 0,
      "z": -4,
      "name": "Necrotic_Stone"
    },
    {
      "x": -4,
      "y": 1,
      "z": -4,
      "name": "Necrotic_Sand",
      "support": 15
    },
    {
      "x": -4,
      "y": -2,
      "z": -3,
      "name": "Necrotic_Stone"
    },
    {
      "x": -4,
      "y": -1,
      "z": -3,
      "name": "Necrotic_Stone"
    },
    {
      "x": -4,
      "y": 0,
      "z": -3,
      "name": "Necrotic_Stone"
    },
    {
      "x": -4,
      "y": 1,
      "z": -3,
      "name": "Necrotic_Sand",
      "support": 15
    },
    {
      "x": -4,
      "y": -3,
      "z": -2,
      "name": "Necrotic_Stone"
    },
    {
      "x": -4,
      "y": -2,
      "z": -2,
      "name": "Necrotic_Stone"
    },
    {
      "x": -4,
      "y": -1,
      "z": -2,
      "name": "Necrotic_Stone"
    },
    {
      "x": -4,
      "y": 0,
      "z": -2,
      "name": "Necrotic_Stone"
    },
    {
      "x": -4,
      "y": 1,
      "z": -2,
      "name": "Necrotic_Sand",
      "support": 15
    },
    {
      "x": -4,
      "y": -3,
      "z": -1,
      "name": "Necrotic_Stone"
    },
    {
      "x": -4,
      "y": -2,
      "z": -1,
      "name": "Necrotic_Stone"
    },
    {
      "x": -4,
      "y": -1,
      "z": -1,
      "name": "Necrotic_Stone"
    },
    {
      "x": -4,
      "y": 0,
      "z": -1,
      "name": "Necrotic_Stone"
    },
    {
      "x": -4,
      "y": 1,
      "z": -1,
      "name": "Rock_Slate_Cobble"
    },
    {
      "x": -4,
      "y": 2,
      "z": -1,
      "name": "Rock_Slate_Cobble_Stairs",
      "rotation": 2
    },
    {
      "x": -4,
      "y": 7,
      "z": -1,
      "name": "Wood_Burnt_Roots"
    },
    {
      "x": -4,
      "y": 8,
      "z": -1,
      "name": "Rock_Slate_Cobble_Roof_Steep",
      "rotation": 3
    },
    {
      "x": -4,
      "y": 9,
      "z": -1,
      "name": "Rock_Slate_Cobble_Roof_Steep",
      "filler": 1024,
      "rotation": 3
    },
    {
      "x": -4,
      "y": -3,
      "z": 0,
      "name": "Necrotic_Stone"
    },
    {
      "x": -4,
      "y": -2,
      "z": 0,
      "name": "Necrotic_Stone"
    },
    {
      "x": -4,
      "y": -1,
      "z": 0,
      "name": "Necrotic_Stone"
    },
    {
      "x": -4,
      "y": 0,
      "z": 0,
      "name": "Necrotic_Stone"
    },
    {
      "x": -4,
      "y": 1,
      "z": 0,
      "name": "Rock_Slate_Cobble"
    },
    {
      "x": -4,
      "y": 2,
      "z": 0,
      "name": "Rock_Slate_Brick"
    },
    {
      "x": -4,
      "y": 3,
      "z": 0,
      "name": "*Furniture_Temple_Dark_Door_Medium_State_Definitions_CloseDoorIn",
      "filler": 30,
      "rotation": 2
    },
    {
      "x": -4,
      "y": 4,
      "z": 0,
      "name": "*Furniture_Temple_Dark_Door_Medium_State_Definitions_CloseDoorIn",
      "filler": 1054,
      "rotation": 2
    },
    {
      "x": -4,
      "y": 5,
      "z": 0,
      "name": "*Furniture_Temple_Dark_Door_Medium_State_Definitions_CloseDoorIn",
      "filler": 2078,
      "rotation": 2
    },
    {
      "x": -4,
      "y": 6,
      "z": 0,
      "name": "Rock_Slate_Brick"
    },
    {
      "x": -4,
      "y": 7,
      "z": 0,
      "name": "Rock_Slate_Brick"
    },
    {
      "x": -4,
      "y": 8,
      "z": 0,
      "name": "Rock_Slate_Cobble_Roof_Steep",
      "rotation": 3
    },
    {
      "x": -4,
      "y": 9,
      "z": 0,
      "name": "Rock_Slate_Cobble_Roof_Steep",
      "filler": 1024,
      "rotation": 3
    },
    {
      "x": -4,
      "y": -3,
      "z": 1,
      "name": "Necrotic_Stone"
    },
    {
      "x": -4,
      "y": -2,
      "z": 1,
      "name": "Necrotic_Stone"
    },
    {
      "x": -4,
      "y": -1,
      "z": 1,
      "name": "Necrotic_Stone"
    },
    {
      "x": -4,
      "y": 0,
      "z": 1,
      "name": "Necrotic_Stone"
    },
    {
      "x": -4,
      "y": 1,
      "z": 1,
      "name": "Rock_Slate_Cobble"
    },
    {
      "x": -4,
      "y": 2,
      "z": 1,
      "name": "Rock_Slate_Brick"
    },
    {
      "x": -4,
      "y": 6,
      "z": 1,
      "name": "Rock_Slate_Brick"
    },
    {
      "x": -4,
      "y": 7,
      "z": 1,
      "name": "Rock_Slate_Brick"
    },
    {
      "x": -4,
      "y": 8,
      "z": 1,
      "name": "Rock_Slate_Cobble_Roof_Steep",
      "rotation": 3
    },
    {
      "x": -4,
      "y": 9,
      "z": 1,
      "name": "Rock_Slate_Cobble_Roof_Steep",
      "filler": 1024,
      "rotation": 3
    },
    {
      "x": -4,
      "y": -3,
      "z": 2,
      "name": "Necrotic_Stone"
    },
    {
      "x": -4,
      "y": -2,
      "z": 2,
      "name": "Necrotic_Stone"
    },
    {
      "x": -4,
      "y": -1,
      "z": 2,
      "name": "Necrotic_Stone"
    },
    {
      "x": -4,
      "y": 0,
      "z": 2,
      "name": "Necrotic_Stone"
    },
    {
      "x": -4,
      "y": 1,
      "z": 2,
      "name": "Rock_Slate_Cobble"
    },
    {
      "x": -4,
      "y": 2,
      "z": 2,
      "name": "Rock_Slate_Brick"
    },
    {
      "x": -4,
      "y": 6,
      "z": 2,
      "name": "Rock_Slate_Brick"
    },
    {
      "x": -4,
      "y": 7,
      "z": 2,
      "name": "Rock_Slate_Brick"
    },
    {
      "x": -4,
      "y": 8,
      "z": 2,
      "name": "Rock_Slate_Cobble_Roof_Steep",
      "rotation": 3
    },
    {
      "x": -4,
      "y": 9,
      "z": 2,
      "name": "Rock_Slate_Cobble_Roof_Steep",
      "filler": 1024,
      "rotation": 3
    },
    {
      "x": -4,
      "y": -3,
      "z": 3,
      "name": "Necrotic_Stone"
    },
    {
      "x": -4,
      "y": -2,
      "z": 3,
      "name": "Necrotic_Stone"
    },
    {
      "x": -4,
      "y": -1,
      "z": 3,
      "name": "Necrotic_Stone"
    },
    {
      "x": -4,
      "y": 0,
      "z": 3,
      "name": "Necrotic_Stone"
    },
    {
      "x": -4,
      "y": 1,
      "z": 3,
      "name": "Rock_Slate_Cobble"
    },
    {
      "x": -4,
      "y": 2,
      "z": 3,
      "name": "Rock_Slate_Brick"
    },
    {
      "x": -4,
      "y": 6,
      "z": 3,
      "name": "Rock_Slate_Brick"
    },
    {
      "x": -4,
      "y": 7,
      "z": 3,
      "name": "Rock_Slate_Brick"
    },
    {
      "x": -4,
      "y": 8,
      "z": 3,
      "name": "Rock_Slate_Cobble_Roof_Steep",
      "rotation": 3
    },
    {
      "x": -4,
      "y": 9,
      "z": 3,
      "name": "Rock_Slate_Cobble_Roof_Steep",
      "filler": 1024,
      "rotation": 3
    },
    {
      "x": -4,
      "y": -3,
      "z": 4,
      "name": "Necrotic_Stone"
    },
    {
      "x": -4,
      "y": -2,
      "z": 4,
      "name": "Necrotic_Stone"
    },
    {
      "x": -4,
      "y": -1,
      "z": 4,
      "name": "Necrotic_Stone"
    },
    {
      "x": -4,
      "y": 0,
      "z": 4,
      "name": "Necrotic_Stone"
    },
    {
      "x": -4,
      "y": 1,
      "z": 4,
      "name": "Rock_Slate_Cobble"
    },
    {
      "x": -4,
      "y": 2,
      "z": 4,
      "name": "Rock_Slate_Brick"
    },
    {
      "x": -4,
      "y": 6,
      "z": 4,
      "name": "Rock_Slate_Brick"
    },
    {
      "x": -4,
      "y": 7,
      "z": 4,
      "name": "Rock_Slate_Brick"
    },
    {
      "x": -4,
      "y": 8,
      "z": 4,
      "name": "Rock_Slate_Cobble_Roof_Steep",
      "rotation": 3
    },
    {
      "x": -4,
      "y": 9,
      "z": 4,
      "name": "Rock_Slate_Cobble_Roof_Steep",
      "filler": 1024,
      "rotation": 3
    },
    {
      "x": -4,
      "y": -2,
      "z": 5,
      "name": "Necrotic_Stone"
    },
    {
      "x": -4,
      "y": -1,
      "z": 5,
      "name": "Necrotic_Stone"
    },
    {
      "x": -4,
      "y": 0,
      "z": 5,
      "name": "Necrotic_Stone"
    },
    {
      "x": -4,
      "y": 1,
      "z": 5,
      "name": "Rock_Slate_Cobble"
    },
    {
      "x": -4,
      "y": 2,
      "z": 5,
      "name": "Rock_Slate_Brick"
    },
    {
      "x": -4,
      "y": 3,
      "z": 5,
      "name": "Furniture_Temple_Dark_Stool",
      "rotation": 2
    },
    {
      "x": -4,
      "y": 6,
      "z": 5,
      "name": "Rock_Slate_Brick"
    },
    {
      "x": -4,
      "y": 7,
      "z": 5,
      "name": "Rock_Slate_Brick"
    },
    {
      "x": -4,
      "y": 8,
      "z": 5,
      "name": "Rock_Slate_Cobble_Roof_Steep",
      "rotation": 3
    },
    {
      "x": -4,
      "y": 9,
      "z": 5,
      "name": "Rock_Slate_Cobble_Roof_Steep",
      "filler": 1024,
      "rotation": 3
    },
    {
      "x": -4,
      "y": -2,
      "z": 6,
      "name": "Wood_Burnt_Roots"
    },
    {
      "x": -4,
      "y": -1,
      "z": 6,
      "name": "Necrotic_Stone"
    },
    {
      "x": -4,
      "y": 0,
      "z": 6,
      "name": "Necrotic_Stone"
    },
    {
      "x": -4,
      "y": 1,
      "z": 6,
      "name": "Rock_Slate_Cobble"
    },
    {
      "x": -4,
      "y": 2,
      "z": 6,
      "name": "Rock_Slate_Brick"
    },
    {
      "x": -4,
      "y": 3,
      "z": 6,
      "name": "Rock_Slate_Brick"
    },
    {
      "x": -4,
      "y": 4,
      "z": 6,
      "name": "Rock_Slate_Brick"
    },
    {
      "x": -4,
      "y": 5,
      "z": 6,
      "name": "Rock_Slate_Brick"
    },
    {
      "x": -4,
      "y": 6,
      "z": 6,
      "name": "Rock_Slate_Brick"
    },
    {
      "x": -4,
      "y": 7,
      "z": 6,
      "name": "Rock_Slate_Brick"
    },
    {
      "x": -4,
      "y": 8,
      "z": 6,
      "name": "Rock_Slate_Cobble_Roof_Steep",
      "rotation": 3
    },
    {
      "x": -4,
      "y": 9,
      "z": 6,
      "name": "Rock_Slate_Cobble_Roof_Steep",
      "filler": 1024,
      "rotation": 3
    },
    {
      "x": -4,
      "y": -1,
      "z": 7,
      "name": "Necrotic_Stone"
    },
    {
      "x": -4,
      "y": 0,
      "z": 7,
      "name": "Necrotic_Stone"
    },
    {
      "x": -4,
      "y": 1,
      "z": 7,
      "name": "Rock_Slate_Cobble"
    },
    {
      "x": -4,
      "y": 2,
      "z": 7,
      "name": "*Rock_Slate_Cobble_Half_State_Definitions_Block"
    },
    {
      "x": -4,
      "y": 3,
      "z": 7,
      "name": "Rock_Slate_Beam"
    },
    {
      "x": -4,
      "y": 4,
      "z": 7,
      "name": "Plant_Leaves_Dead",
      "support": 15
    },
    {
      "x": -4,
      "y": 5,
      "z": 7,
      "name": "Plant_Leaves_Dead",
      "support": 15
    },
    {
      "x": -4,
      "y": 6,
      "z": 7,
      "name": "Rock_Slate_Brick_Pillar_Middle",
      "rotation": 7
    },
    {
      "x": -4,
      "y": 7,
      "z": 7,
      "name": "Rock_Slate_Brick"
    },
    {
      "x": -4,
      "y": 8,
      "z": 7,
      "name": "Rock_Slate_Cobble_Roof_Steep",
      "rotation": 3
    },
    {
      "x": -4,
      "y": 9,
      "z": 7,
      "name": "Rock_Slate_Cobble_Roof_Steep",
      "filler": 1024,
      "rotation": 3
    },
    {
      "x": -4,
      "y": 0,
      "z": 8,
      "name": "Necrotic_Stone"
    },
    {
      "x": -4,
      "y": 1,
      "z": 8,
      "name": "Rock_Slate_Cobble"
    },
    {
      "x": -4,
      "y": 2,
      "z": 8,
      "name": "Rock_Slate_Cobble_Half"
    },
    {
      "x": -4,
      "y": 0,
      "z": 9,
      "name": "Necrotic_Stone"
    },
    {
      "x": -4,
      "y": 1,
      "z": 9,
      "name": "Rock_Slate_Cobble"
    },
    {
      "x": -3,
      "y": 0,
      "z": -9,
      "name": "Necrotic_Stone"
    },
    {
      "x": -3,
      "y": 1,
      "z": -9,
      "name": "Necrotic_Sand"
    },
    {
      "x": -3,
      "y": 2,
      "z": -9,
      "name": "Necrotic_Fence",
      "rotation": 2
    },
    {
      "x": -3,
      "y": -1,
      "z": -8,
      "name": "Necrotic_Stone"
    },
    {
      "x": -3,
      "y": 0,
      "z": -8,
      "name": "Necrotic_Stone"
    },
    {
      "x": -3,
      "y": 1,
      "z": -8,
      "name": "Necrotic_Sand",
      "support": 15
    },
    {
      "x": -3,
      "y": -2,
      "z": -7,
      "name": "Wood_Burnt_Roots"
    },
    {
      "x": -3,
      "y": -1,
      "z": -7,
      "name": "Necrotic_Stone"
    },
    {
      "x": -3,
      "y": 0,
      "z": -7,
      "name": "Necrotic_Stone"
    },
    {
      "x": -3,
      "y": 1,
      "z": -7,
      "name": "Necrotic_Sand",
      "support": 15
    },
    {
      "x": -3,
      "y": 2,
      "z": -7,
      "name": "Rubble_Slate",
      "support": 15
    },
    {
      "x": -3,
      "y": -2,
      "z": -6,
      "name": "Necrotic_Stone"
    },
    {
      "x": -3,
      "y": -1,
      "z": -6,
      "name": "Necrotic_Stone"
    },
    {
      "x": -3,
      "y": 0,
      "z": -6,
      "name": "Necrotic_Stone"
    },
    {
      "x": -3,
      "y": 1,
      "z": -6,
      "name": "Necrotic_Sand"
    },
    {
      "x": -3,
      "y": -2,
      "z": -5,
      "name": "Necrotic_Stone"
    },
    {
      "x": -3,
      "y": -1,
      "z": -5,
      "name": "Necrotic_Stone"
    },
    {
      "x": -3,
      "y": 0,
      "z": -5,
      "name": "Necrotic_Stone"
    },
    {
      "x": -3,
      "y": 1,
      "z": -5,
      "name": "Necrotic_Sand",
      "support": 15
    },
    {
      "x": -3,
      "y": -4,
      "z": -4,
      "name": "Wood_Burnt_Roots"
    },
    {
      "x": -3,
      "y": -3,
      "z": -4,
      "name": "Necrotic_Stone"
    },
    {
      "x": -3,
      "y": -2,
      "z": -4,
      "name": "Necrotic_Stone"
    },
    {
      "x": -3,
      "y": -1,
      "z": -4,
      "name": "Necrotic_Stone"
    },
    {
      "x": -3,
      "y": 0,
      "z": -4,
      "name": "Necrotic_Stone"
    },
    {
      "x": -3,
      "y": 1,
      "z": -4,
      "name": "Necrotic_Sand",
      "support": 15
    },
    {
      "x": -3,
      "y": -3,
      "z": -3,
      "name": "Necrotic_Stone"
    },
    {
      "x": -3,
      "y": -2,
      "z": -3,
      "name": "Necrotic_Stone"
    },
    {
      "x": -3,
      "y": -1,
      "z": -3,
      "name": "Necrotic_Stone"
    },
    {
      "x": -3,
      "y": 0,
      "z": -3,
      "name": "Necrotic_Stone"
    },
    {
      "x": -3,
      "y": 1,
      "z": -3,
      "name": "Necrotic_Sand",
      "support": 15
    },
    {
      "x": -3,
      "y": -3,
      "z": -2,
      "name": "Necrotic_Stone"
    },
    {
      "x": -3,
      "y": -2,
      "z": -2,
      "name": "Necrotic_Stone"
    },
    {
      "x": -3,
      "y": -1,
      "z": -2,
      "name": "Necrotic_Stone"
    },
    {
      "x": -3,
      "y": 0,
      "z": -2,
      "name": "Necrotic_Stone"
    },
    {
      "x": -3,
      "y": 1,
      "z": -2,
      "name": "Necrotic_Sand",
      "support": 15
    },
    {
      "x": -3,
      "y": -3,
      "z": -1,
      "name": "Necrotic_Stone"
    },
    {
      "x": -3,
      "y": -2,
      "z": -1,
      "name": "Necrotic_Stone"
    },
    {
      "x": -3,
      "y": -1,
      "z": -1,
      "name": "Necrotic_Stone"
    },
    {
      "x": -3,
      "y": 0,
      "z": -1,
      "name": "Necrotic_Stone"
    },
    {
      "x": -3,
      "y": 1,
      "z": -1,
      "name": "Rock_Slate_Cobble"
    },
    {
      "x": -3,
      "y": 2,
      "z": -1,
      "name": "Rock_Slate_Cobble_Stairs",
      "rotation": 2
    },
    {
      "x": -3,
      "y": 7,
      "z": -1,
      "name": "Plant_Leaves_Dead",
      "support": 15
    },
    {
      "x": -3,
      "y": 8,
      "z": -1,
      "name": "Wood_Burnt_Roots"
    },
    {
      "x": -3,
      "y": 9,
      "z": -1,
      "name": "Rock_Slate_Brick"
    },
    {
      "x": -3,
      "y": 10,
      "z": -1,
      "name": "Rock_Slate_Cobble_Wall",
      "rotation": 1
    },
    {
      "x": -3,
      "y": -3,
      "z": 0,
      "name": "Necrotic_Stone"
    },
    {
      "x": -3,
      "y": -2,
      "z": 0,
      "name": "Necrotic_Stone"
    },
    {
      "x": -3,
      "y": -1,
      "z": 0,
      "name": "Necrotic_Stone"
    },
    {
      "x": -3,
      "y": 0,
      "z": 0,
      "name": "Necrotic_Stone"
    },
    {
      "x": -3,
      "y": 1,
      "z": 0,
      "name": "Rock_Slate_Cobble"
    },
    {
      "x": -3,
      "y": 2,
      "z": 0,
      "name": "Rock_Slate_Brick"
    },
    {
      "x": -3,
      "y": 3,
      "z": 0,
      "name": "*Furniture_Temple_Dark_Door_Medium_State_Definitions_CloseDoorIn",
      "filler": 31,
      "rotation": 2
    },
    {
      "x": -3,
      "y": 4,
      "z": 0,
      "name": "*Furniture_Temple_Dark_Door_Medium_State_Definitions_CloseDoorIn",
      "filler": 1055,
      "rotation": 2
    },
    {
      "x": -3,
      "y": 5,
      "z": 0,
      "name": "*Furniture_Temple_Dark_Door_Medium_State_Definitions_CloseDoorIn",
      "filler": 2079,
      "rotation": 2
    },
    {
      "x": -3,
      "y": 6,
      "z": 0,
      "name": "Rock_Slate_Brick"
    },
    {
      "x": -3,
      "y": 7,
      "z": 0,
      "name": "Rock_Slate_Brick"
    },
    {
      "x": -3,
      "y": 8,
      "z": 0,
      "name": "Rock_Slate_Brick"
    },
    {
      "x": -3,
      "y": 9,
      "z": 0,
      "name": "Rock_Slate_Brick"
    },
    {
      "x": -3,
      "y": 10,
      "z": 0,
      "name": "Rock_Slate_Cobble_Wall",
      "rotation": 1
    },
    {
      "x": -3,
      "y": -3,
      "z": 1,
      "name": "Necrotic_Stone"
    },
    {
      "x": -3,
      "y": -2,
      "z": 1,
      "name": "Necrotic_Stone"
    },
    {
      "x": -3,
      "y": -1,
      "z": 1,
      "name": "Necrotic_Stone"
    },
    {
      "x": -3,
      "y": 0,
      "z": 1,
      "name": "Necrotic_Stone"
    },
    {
      "x": -3,
      "y": 1,
      "z": 1,
      "name": "Rock_Slate_Cobble"
    },
    {
      "x": -3,
      "y": 2,
      "z": 1,
      "name": "Rock_Slate_Brick"
    },
    {
      "x": -3,
      "y": 6,
      "z": 1,
      "name": "Rock_Slate_Brick"
    },
    {
      "x": -3,
      "y": 7,
      "z": 1,
      "name": "Rock_Slate_Brick"
    },
    {
      "x": -3,
      "y": 8,
      "z": 1,
      "name": "Rock_Slate_Brick"
    },
    {
      "x": -3,
      "y": 9,
      "z": 1,
      "name": "Rock_Slate_Brick"
    },
    {
      "x": -3,
      "y": 10,
      "z": 1,
      "name": "Rock_Slate_Cobble_Wall",
      "rotation": 1
    },
    {
      "x": -3,
      "y": -3,
      "z": 2,
      "name": "Necrotic_Stone"
    },
    {
      "x": -3,
      "y": -2,
      "z": 2,
      "name": "Necrotic_Stone"
    },
    {
      "x": -3,
      "y": -1,
      "z": 2,
      "name": "Necrotic_Stone"
    },
    {
      "x": -3,
      "y": 0,
      "z": 2,
      "name": "Necrotic_Stone"
    },
    {
      "x": -3,
      "y": 1,
      "z": 2,
      "name": "Rock_Slate_Cobble"
    },
    {
      "x": -3,
      "y": 2,
      "z": 2,
      "name": "Rock_Slate_Brick"
    },
    {
      "x": -3,
      "y": 3,
      "z": 2,
      "name": "Furniture_Temple_Dark_Coffin",
      "filler": 992,
      "rotation": 1
    },
    {
      "x": -3,
      "y": 6,
      "z": 2,
      "name": "Rock_Slate_Brick"
    },
    {
      "x": -3,
      "y": 7,
      "z": 2,
      "name": "Rock_Slate_Brick"
    },
    {
      "x": -3,
      "y": 8,
      "z": 2,
      "name": "Rock_Slate_Brick"
    },
    {
      "x": -3,
      "y": 9,
      "z": 2,
      "name": "Rock_Slate_Brick"
    },
    {
      "x": -3,
      "y": 10,
      "z": 2,
      "name": "Rock_Slate_Cobble_Wall",
      "rotation": 1
    },
    {
      "x": -3,
      "y": -3,
      "z": 3,
      "name": "Necrotic_Stone"
    },
    {
      "x": -3,
      "y": -2,
      "z": 3,
      "name": "Necrotic_Stone"
    },
    {
      "x": -3,
      "y": -1,
      "z": 3,
      "name": "Necrotic_Stone"
    },
    {
      "x": -3,
      "y": 0,
      "z": 3,
      "name": "Necrotic_Stone"
    },
    {
      "x": -3,
      "y": 1,
      "z": 3,
      "name": "Rock_Slate_Cobble"
    },
    {
      "x": -3,
      "y": 2,
      "z": 3,
      "name": "Rock_Slate_Brick"
    },
    {
      "x": -3,
      "y": 3,
      "z": 3,
      "name": "Furniture_Temple_Dark_Coffin",
      "rotation": 1
    },
    {
      "x": -3,
      "y": 6,
      "z": 3,
      "name": "Rock_Slate_Brick"
    },
    {
      "x": -3,
      "y": 7,
      "z": 3,
      "name": "Rock_Slate_Brick"
    },
    {
      "x": -3,
      "y": 8,
      "z": 3,
      "name": "Rock_Slate_Brick"
    },
    {
      "x": -3,
      "y": 9,
      "z": 3,
      "name": "Rock_Slate_Brick"
    },
    {
      "x": -3,
      "y": 10,
      "z": 3,
      "name": "Rock_Slate_Cobble_Wall",
      "rotation": 1
    },
    {
      "x": -3,
      "y": -3,
      "z": 4,
      "name": "Necrotic_Stone"
    },
    {
      "x": -3,
      "y": -2,
      "z": 4,
      "name": "Necrotic_Stone"
    },
    {
      "x": -3,
      "y": -1,
      "z": 4,
      "name": "Necrotic_Stone"
    },
    {
      "x": -3,
      "y": 0,
      "z": 4,
      "name": "Necrotic_Stone"
    },
    {
      "x": -3,
      "y": 1,
      "z": 4,
      "name": "Rock_Slate_Cobble"
    },
    {
      "x": -3,
      "y": 2,
      "z": 4,
      "name": "Rock_Slate_Brick"
    },
    {
      "x": -3,
      "y": 6,
      "z": 4,
      "name": "Rock_Slate_Brick"
    },
    {
      "x": -3,
      "y": 7,
      "z": 4,
      "name": "Rock_Slate_Brick"
    },
    {
      "x": -3,
      "y": 8,
      "z": 4,
      "name": "Rock_Slate_Brick"
    },
    {
      "x": -3,
      "y": 9,
      "z": 4,
      "name": "Rock_Slate_Brick"
    },
    {
      "x": -3,
      "y": 10,
      "z": 4,
      "name": "Rock_Slate_Cobble_Wall",
      "rotation": 1
    },
    {
      "x": -3,
      "y": -2,
      "z": 5,
      "name": "Necrotic_Stone"
    },
    {
      "x": -3,
      "y": -1,
      "z": 5,
      "name": "Necrotic_Stone"
    },
    {
      "x": -3,
      "y": 0,
      "z": 5,
      "name": "Necrotic_Stone"
    },
    {
      "x": -3,
      "y": 1,
      "z": 5,
      "name": "Rock_Slate_Cobble"
    },
    {
      "x": -3,
      "y": 2,
      "z": 5,
      "name": "Rock_Slate_Brick"
    },
    {
      "x": -3,
      "y": 3,
      "z": 5,
      "name": "Furniture_Human_Ruins_Brazier"
    },
    {
      "x": -3,
      "y": 6,
      "z": 5,
      "name": "Rock_Slate_Brick"
    },
    {
      "x": -3,
      "y": 7,
      "z": 5,
      "name": "Rock_Slate_Brick"
    },
    {
      "x": -3,
      "y": 8,
      "z": 5,
      "name": "Rock_Slate_Brick"
    },
    {
      "x": -3,
      "y": 9,
      "z": 5,
      "name": "Rock_Slate_Brick"
    },
    {
      "x": -3,
      "y": 10,
      "z": 5,
      "name": "Rock_Slate_Cobble_Wall",
      "rotation": 1
    },
    {
      "x": -3,
      "y": -2,
      "z": 6,
      "name": "Necrotic_Stone"
    },
    {
      "x": -3,
      "y": -1,
      "z": 6,
      "name": "Necrotic_Stone"
    },
    {
      "x": -3,
      "y": 0,
      "z": 6,
      "name": "Necrotic_Stone"
    },
    {
      "x": -3,
      "y": 1,
      "z": 6,
      "name": "Rock_Slate_Cobble"
    },
    {
      "x": -3,
      "y": 2,
      "z": 6,
      "name": "Rock_Slate_Brick"
    },
    {
      "x": -3,
      "y": 3,
      "z": 6,
      "name": "Rock_Slate_Brick"
    },
    {
      "x": -3,
      "y": 4,
      "z": 6,
      "name": "Necrotic_Window"
    },
    {
      "x": -3,
      "y": 5,
      "z": 6,
      "name": "Rock_Slate_Brick"
    },
    {
      "x": -3,
      "y": 6,
      "z": 6,
      "name": "Rock_Slate_Brick"
    },
    {
      "x": -3,
      "y": 7,
      "z": 6,
      "name": "Rock_Slate_Brick"
    },
    {
      "x": -3,
      "y": 8,
      "z": 6,
      "name": "Rock_Slate_Brick"
    },
    {
      "x": -3,
      "y": 9,
      "z": 6,
      "name": "Rock_Slate_Brick"
    },
    {
      "x": -3,
      "y": 10,
      "z": 6,
      "name": "Rock_Slate_Cobble_Wall",
      "rotation": 1
    },
    {
      "x": -3,
      "y": -2,
      "z": 7,
      "name": "Wood_Burnt_Roots"
    },
    {
      "x": -3,
      "y": -1,
      "z": 7,
      "name": "Necrotic_Stone"
    },
    {
      "x": -3,
      "y": 0,
      "z": 7,
      "name": "Necrotic_Stone"
    },
    {
      "x": -3,
      "y": 1,
      "z": 7,
      "name": "Rock_Slate_Cobble"
    },
    {
      "x": -3,
      "y": 2,
      "z": 7,
      "name": "*Rock_Slate_Cobble_Half_State_Definitions_Block"
    },
    {
      "x": -3,
      "y": 3,
      "z": 7,
      "name": "Rock_Slate_Beam"
    },
    {
      "x": -3,
      "y": 5,
      "z": 7,
      "name": "Plant_Leaves_Dead",
      "support": 15
    },
    {
      "x": -3,
      "y": 6,
      "z": 7,
      "name": "Rock_Slate_Brick_Pillar_Middle",
      "rotation": 7
    },
    {
      "x": -3,
      "y": 7,
      "z": 7,
      "name": "Rock_Slate_Brick"
    },
    {
      "x": -3,
      "y": 8,
      "z": 7,
      "name": "Rock_Slate_Brick"
    },
    {
      "x": -3,
      "y": 9,
      "z": 7,
      "name": "Rock_Slate_Brick"
    },
    {
      "x": -3,
      "y": 10,
      "z": 7,
      "name": "Rock_Slate_Cobble_Wall",
      "rotation": 1
    },
    {
      "x": -3,
      "y": -1,
      "z": 8,
      "name": "Necrotic_Stone"
    },
    {
      "x": -3,
      "y": 0,
      "z": 8,
      "name": "Necrotic_Stone"
    },
    {
      "x": -3,
      "y": 1,
      "z": 8,
      "name": "Rock_Slate_Cobble"
    },
    {
      "x": -3,
      "y": 2,
      "z": 8,
      "name": "Rock_Slate_Cobble_Half"
    },
    {
      "x": -3,
      "y": 0,
      "z": 9,
      "name": "Necrotic_Stone"
    },
    {
      "x": -3,
      "y": 1,
      "z": 9,
      "name": "Rock_Slate_Cobble"
    },
    {
      "x": -3,
      "y": 2,
      "z": 9,
      "name": "Rock_Slate_Brick_Wall",
      "rotation": 2
    },
    {
      "x": -2,
      "y": 0,
      "z": -9,
      "name": "Necrotic_Stone"
    },
    {
      "x": -2,
      "y": 1,
      "z": -9,
      "name": "Necrotic_Sand"
    },
    {
      "x": -2,
      "y": 2,
      "z": -9,
      "name": "Necrotic_Fence",
      "rotation": 2
    },
    {
      "x": -2,
      "y": -2,
      "z": -8,
      "name": "Wood_Burnt_Roots"
    },
    {
      "x": -2,
      "y": -1,
      "z": -8,
      "name": "Necrotic_Stone"
    },
    {
      "x": -2,
      "y": 0,
      "z": -8,
      "name": "Necrotic_Stone"
    },
    {
      "x": -2,
      "y": 1,
      "z": -8,
      "name": "Necrotic_Sand"
    },
    {
      "x": -2,
      "y": -1,
      "z": -7,
      "name": "Necrotic_Stone"
    },
    {
      "x": -2,
      "y": 0,
      "z": -7,
      "name": "Necrotic_Stone"
    },
    {
      "x": -2,
      "y": 1,
      "z": -7,
      "name": "Necrotic_Sand",
      "support": 15
    },
    {
      "x": -2,
      "y": -2,
      "z": -6,
      "name": "Necrotic_Stone"
    },
    {
      "x": -2,
      "y": -1,
      "z": -6,
      "name": "Necrotic_Stone"
    },
    {
      "x": -2,
      "y": 0,
      "z": -6,
      "name": "Necrotic_Stone"
    },
    {
      "x": -2,
      "y": 1,
      "z": -6,
      "name": "Necrotic_Sand"
    },
    {
      "x": -2,
      "y": -3,
      "z": -5,
      "name": "Necrotic_Stone"
    },
    {
      "x": -2,
      "y": -2,
      "z": -5,
      "name": "Necrotic_Stone"
    },
    {
      "x": -2,
      "y": -1,
      "z": -5,
      "name": "Necrotic_Stone"
    },
    {
      "x": -2,
      "y": 0,
      "z": -5,
      "name": "Necrotic_Stone"
    },
    {
      "x": -2,
      "y": 1,
      "z": -5,
      "name": "Necrotic_Sand",
      "support": 15
    },
    {
      "x": -2,
      "y": -3,
      "z": -4,
      "name": "Necrotic_Stone"
    },
    {
      "x": -2,
      "y": -2,
      "z": -4,
      "name": "Necrotic_Stone"
    },
    {
      "x": -2,
      "y": -1,
      "z": -4,
      "name": "Necrotic_Stone"
    },
    {
      "x": -2,
      "y": 0,
      "z": -4,
      "name": "Necrotic_Sand",
      "support": 15
    },
    {
      "x": -2,
      "y": 1,
      "z": -4,
      "name": "Necrotic_Sand",
      "support": 15
    },
    {
      "x": -2,
      "y": -3,
      "z": -3,
      "name": "Necrotic_Stone"
    },
    {
      "x": -2,
      "y": -2,
      "z": -3,
      "name": "Necrotic_Stone"
    },
    {
      "x": -2,
      "y": -1,
      "z": -3,
      "name": "Necrotic_Stone"
    },
    {
      "x": -2,
      "y": 0,
      "z": -3,
      "name": "Necrotic_Stone"
    },
    {
      "x": -2,
      "y": 1,
      "z": -3,
      "name": "Necrotic_Sand",
      "support": 15
    },
    {
      "x": -2,
      "y": -3,
      "z": -2,
      "name": "Necrotic_Stone"
    },
    {
      "x": -2,
      "y": -2,
      "z": -2,
      "name": "Necrotic_Stone"
    },
    {
      "x": -2,
      "y": -1,
      "z": -2,
      "name": "Necrotic_Stone"
    },
    {
      "x": -2,
      "y": 0,
      "z": -2,
      "name": "Necrotic_Stone"
    },
    {
      "x": -2,
      "y": 1,
      "z": -2,
      "name": "Necrotic_Sand",
      "support": 15
    },
    {
      "x": -2,
      "y": 2,
      "z": -2,
      "name": "Rubble_Slate",
      "support": 15
    },
    {
      "x": -2,
      "y": -3,
      "z": -1,
      "name": "Necrotic_Stone"
    },
    {
      "x": -2,
      "y": -2,
      "z": -1,
      "name": "Necrotic_Stone"
    },
    {
      "x": -2,
      "y": -1,
      "z": -1,
      "name": "Necrotic_Stone"
    },
    {
      "x": -2,
      "y": 0,
      "z": -1,
      "name": "Necrotic_Stone"
    },
    {
      "x": -2,
      "y": 1,
      "z": -1,
      "name": "Rock_Slate_Cobble"
    },
    {
      "x": -2,
      "y": 2,
      "z": -1,
      "name": "Rock_Slate_Cobble_Stairs",
      "rotation": 2
    },
    {
      "x": -2,
      "y": 7,
      "z": -1,
      "name": "Wood_Burnt_Roots"
    },
    {
      "x": -2,
      "y": 8,
      "z": -1,
      "name": "Rock_Slate_Cobble_Roof_Steep",
      "rotation": 1
    },
    {
      "x": -2,
      "y": 9,
      "z": -1,
      "name": "Rock_Slate_Cobble_Roof_Steep",
      "filler": 1024,
      "rotation": 1
    },
    {
      "x": -2,
      "y": -4,
      "z": 0,
      "name": "Wood_Burnt_Roots"
    },
    {
      "x": -2,
      "y": -3,
      "z": 0,
      "name": "Necrotic_Stone"
    },
    {
      "x": -2,
      "y": -2,
      "z": 0,
      "name": "Necrotic_Stone"
    },
    {
      "x": -2,
      "y": -1,
      "z": 0,
      "name": "Necrotic_Stone"
    },
    {
      "x": -2,
      "y": 0,
      "z": 0,
      "name": "Necrotic_Stone"
    },
    {
      "x": -2,
      "y": 1,
      "z": 0,
      "name": "Rock_Slate_Cobble"
    },
    {
      "x": -2,
      "y": 2,
      "z": 0,
      "name": "Rock_Slate_Brick"
    },
    {
      "x": -2,
      "y": 3,
      "z": 0,
      "name": "*Furniture_Temple_Dark_Door_Medium_State_Definitions_CloseDoorIn",
      "rotation": 2
    },
    {
      "x": -2,
      "y": 4,
      "z": 0,
      "name": "*Furniture_Temple_Dark_Door_Medium_State_Definitions_CloseDoorIn",
      "filler": 1024,
      "rotation": 2
    },
    {
      "x": -2,
      "y": 5,
      "z": 0,
      "name": "*Furniture_Temple_Dark_Door_Medium_State_Definitions_CloseDoorIn",
      "filler": 2048,
      "rotation": 2
    },
    {
      "x": -2,
      "y": 6,
      "z": 0,
      "name": "Rock_Slate_Brick"
    },
    {
      "x": -2,
      "y": 7,
      "z": 0,
      "name": "Rock_Slate_Brick"
    },
    {
      "x": -2,
      "y": 8,
      "z": 0,
      "name": "Rock_Slate_Cobble_Roof_Steep",
      "rotation": 1
    },
    {
      "x": -2,
      "y": 9,
      "z": 0,
      "name": "Rock_Slate_Cobble_Roof_Steep",
      "filler": 1024,
      "rotation": 1
    },
    {
      "x": -2,
      "y": -4,
      "z": 1,
      "name": "Wood_Burnt_Roots"
    },
    {
      "x": -2,
      "y": -3,
      "z": 1,
      "name": "Necrotic_Stone"
    },
    {
      "x": -2,
      "y": -2,
      "z": 1,
      "name": "Necrotic_Stone"
    },
    {
      "x": -2,
      "y": -1,
      "z": 1,
      "name": "Necrotic_Stone"
    },
    {
      "x": -2,
      "y": 0,
      "z": 1,
      "name": "Necrotic_Stone"
    },
    {
      "x": -2,
      "y": 1,
      "z": 1,
      "name": "Rock_Slate_Cobble"
    },
    {
      "x": -2,
      "y": 2,
      "z": 1,
      "name": "Rock_Slate_Brick"
    },
    {
      "x": -2,
      "y": 6,
      "z": 1,
      "name": "Rock_Slate_Brick"
    },
    {
      "x": -2,
      "y": 7,
      "z": 1,
      "name": "Rock_Slate_Brick"
    },
    {
      "x": -2,
      "y": 8,
      "z": 1,
      "name": "Rock_Slate_Cobble_Roof_Steep",
      "rotation": 1
    },
    {
      "x": -2,
      "y": 9,
      "z": 1,
      "name": "Rock_Slate_Cobble_Roof_Steep",
      "filler": 1024,
      "rotation": 1
    },
    {
      "x": -2,
      "y": -3,
      "z": 2,
      "name": "Necrotic_Stone"
    },
    {
      "x": -2,
      "y": -2,
      "z": 2,
      "name": "Necrotic_Stone"
    },
    {
      "x": -2,
      "y": -1,
      "z": 2,
      "name": "Necrotic_Stone"
    },
    {
      "x": -2,
      "y": 0,
      "z": 2,
      "name": "Necrotic_Stone"
    },
    {
      "x": -2,
      "y": 1,
      "z": 2,
      "name": "Rock_Slate_Cobble"
    },
    {
      "x": -2,
      "y": 2,
      "z": 2,
      "name": "Rock_Slate_Brick"
    },
    {
      "x": -2,
      "y": 6,
      "z": 2,
      "name": "Rock_Slate_Brick"
    },
    {
      "x": -2,
      "y": 7,
      "z": 2,
      "name": "Rock_Slate_Brick"
    },
    {
      "x": -2,
      "y": 8,
      "z": 2,
      "name": "Rock_Slate_Cobble_Roof_Steep",
      "rotation": 1
    },
    {
      "x": -2,
      "y": 9,
      "z": 2,
      "name": "Rock_Slate_Cobble_Roof_Steep",
      "filler": 1024,
      "rotation": 1
    },
    {
      "x": -2,
      "y": -4,
      "z": 3,
      "name": "Wood_Burnt_Roots"
    },
    {
      "x": -2,
      "y": -3,
      "z": 3,
      "name": "Necrotic_Stone"
    },
    {
      "x": -2,
      "y": -2,
      "z": 3,
      "name": "Necrotic_Stone"
    },
    {
      "x": -2,
      "y": -1,
      "z": 3,
      "name": "Necrotic_Stone"
    },
    {
      "x": -2,
      "y": 0,
      "z": 3,
      "name": "Necrotic_Stone"
    },
    {
      "x": -2,
      "y": 1,
      "z": 3,
      "name": "Rock_Slate_Cobble"
    },
    {
      "x": -2,
      "y": 2,
      "z": 3,
      "name": "Rock_Slate_Brick"
    },
    {
      "x": -2,
      "y": 6,
      "z": 3,
      "name": "Rock_Slate_Brick"
    },
    {
      "x": -2,
      "y": 7,
      "z": 3,
      "name": "Rock_Slate_Brick"
    },
    {
      "x": -2,
      "y": 8,
      "z": 3,
      "name": "Rock_Slate_Cobble_Roof_Steep",
      "rotation": 1
    },
    {
      "x": -2,
      "y": 9,
      "z": 3,
      "name": "Rock_Slate_Cobble_Roof_Steep",
      "filler": 1024,
      "rotation": 1
    },
    {
      "x": -2,
      "y": -3,
      "z": 4,
      "name": "Necrotic_Stone"
    },
    {
      "x": -2,
      "y": -2,
      "z": 4,
      "name": "Necrotic_Stone"
    },
    {
      "x": -2,
      "y": -1,
      "z": 4,
      "name": "Necrotic_Stone"
    },
    {
      "x": -2,
      "y": 0,
      "z": 4,
      "name": "Necrotic_Stone"
    },
    {
      "x": -2,
      "y": 1,
      "z": 4,
      "name": "Rock_Slate_Cobble"
    },
    {
      "x": -2,
      "y": 2,
      "z": 4,
      "name": "Rock_Slate_Brick"
    },
    {
      "x": -2,
      "y": 6,
      "z": 4,
      "name": "Rock_Slate_Brick"
    },
    {
      "x": -2,
      "y": 7,
      "z": 4,
      "name": "Rock_Slate_Brick"
    },
    {
      "x": -2,
      "y": 8,
      "z": 4,
      "name": "Rock_Slate_Cobble_Roof_Steep",
      "rotation": 1
    },
    {
      "x": -2,
      "y": 9,
      "z": 4,
      "name": "Rock_Slate_Cobble_Roof_Steep",
      "filler": 1024,
      "rotation": 1
    },
    {
      "x": -2,
      "y": -3,
      "z": 5,
      "name": "Necrotic_Stone"
    },
    {
      "x": -2,
      "y": -2,
      "z": 5,
      "name": "Necrotic_Stone"
    },
    {
      "x": -2,
      "y": -1,
      "z": 5,
      "name": "Necrotic_Stone"
    },
    {
      "x": -2,
      "y": 0,
      "z": 5,
      "name": "Necrotic_Stone"
    },
    {
      "x": -2,
      "y": 1,
      "z": 5,
      "name": "Rock_Slate_Cobble"
    },
    {
      "x": -2,
      "y": 2,
      "z": 5,
      "name": "Rock_Slate_Brick"
    },
    {
      "x": -2,
      "y": 3,
      "z": 5,
      "name": "Furniture_Temple_Dark_Stool",
      "rotation": 2
    },
    {
      "x": -2,
      "y": 6,
      "z": 5,
      "name": "Rock_Slate_Brick"
    },
    {
      "x": -2,
      "y": 7,
      "z": 5,
      "name": "Rock_Slate_Brick"
    },
    {
      "x": -2,
      "y": 8,
      "z": 5,
      "name": "Rock_Slate_Cobble_Roof_Steep",
      "rotation": 1
    },
    {
      "x": -2,
      "y": 9,
      "z": 5,
      "name": "Rock_Slate_Cobble_Roof_Steep",
      "filler": 1024,
      "rotation": 1
    },
    {
      "x": -2,
      "y": -2,
      "z": 6,
      "name": "Necrotic_Stone"
    },
    {
      "x": -2,
      "y": -1,
      "z": 6,
      "name": "Necrotic_Stone"
    },
    {
      "x": -2,
      "y": 0,
      "z": 6,
      "name": "Necrotic_Stone"
    },
    {
      "x": -2,
      "y": 1,
      "z": 6,
      "name": "Rock_Slate_Cobble"
    },
    {
      "x": -2,
      "y": 2,
      "z": 6,
      "name": "Rock_Slate_Brick"
    },
    {
      "x": -2,
      "y": 3,
      "z": 6,
      "name": "Rock_Slate_Brick"
    },
    {
      "x": -2,
      "y": 4,
      "z": 6,
      "name": "Rock_Slate_Brick"
    },
    {
      "x": -2,
      "y": 5,
      "z": 6,
      "name": "Rock_Slate_Brick"
    },
    {
      "x": -2,
      "y": 6,
      "z": 6,
      "name": "Rock_Slate_Brick"
    },
    {
      "x": -2,
      "y": 7,
      "z": 6,
      "name": "Rock_Slate_Brick"
    },
    {
      "x": -2,
      "y": 8,
      "z": 6,
      "name": "Rock_Slate_Cobble_Roof_Steep",
      "rotation": 1
    },
    {
      "x": -2,
      "y": 9,
      "z": 6,
      "name": "Rock_Slate_Cobble_Roof_Steep",
      "filler": 1024,
      "rotation": 1
    },
    {
      "x": -2,
      "y": -1,
      "z": 7,
      "name": "Necrotic_Stone"
    },
    {
      "x": -2,
      "y": 0,
      "z": 7,
      "name": "Necrotic_Stone"
    },
    {
      "x": -2,
      "y": 1,
      "z": 7,
      "name": "Rock_Slate_Cobble"
    },
    {
      "x": -2,
      "y": 2,
      "z": 7,
      "name": "*Rock_Slate_Cobble_Half_State_Definitions_Block"
    },
    {
      "x": -2,
      "y": 3,
      "z": 7,
      "name": "Rock_Slate_Beam"
    },
    {
      "x": -2,
      "y": 5,
      "z": 7,
      "name": "Plant_Leaves_Dead",
      "support": 15
    },
    {
      "x": -2,
      "y": 6,
      "z": 7,
      "name": "Rock_Slate_Brick_Pillar_Middle",
      "rotation": 7
    },
    {
      "x": -2,
      "y": 7,
      "z": 7,
      "name": "Rock_Slate_Brick"
    },
    {
      "x": -2,
      "y": 8,
      "z": 7,
      "name": "Rock_Slate_Cobble_Roof_Steep",
      "rotation": 1
    },
    {
      "x": -2,
      "y": 9,
      "z": 7,
      "name": "Rock_Slate_Cobble_Roof_Steep",
      "filler": 1024,
      "rotation": 1
    },
    {
      "x": -2,
      "y": -1,
      "z": 8,
      "name": "Necrotic_Stone"
    },
    {
      "x": -2,
      "y": 0,
      "z": 8,
      "name": "Necrotic_Stone"
    },
    {
      "x": -2,
      "y": 1,
      "z": 8,
      "name": "Rock_Slate_Cobble"
    },
    {
      "x": -2,
      "y": 2,
      "z": 8,
      "name": "Rock_Slate_Cobble_Half"
    },
    {
      "x": -2,
      "y": 0,
      "z": 9,
      "name": "Necrotic_Stone"
    },
    {
      "x": -2,
      "y": 1,
      "z": 9,
      "name": "Rock_Slate_Cobble"
    },
    {
      "x": -2,
      "y": 2,
      "z": 9,
      "name": "Rock_Slate_Brick_Wall",
      "rotation": 2
    },
    {
      "x": -1,
      "y": 0,
      "z": -9,
      "name": "Necrotic_Stone"
    },
    {
      "x": -1,
      "y": 1,
      "z": -9,
      "name": "Necrotic_Sand"
    },
    {
      "x": -1,
      "y": 2,
      "z": -9,
      "name": "Necrotic_Fence",
      "rotation": 2
    },
    {
      "x": -1,
      "y": -1,
      "z": -8,
      "name": "Necrotic_Stone"
    },
    {
      "x": -1,
      "y": 0,
      "z": -8,
      "name": "Necrotic_Stone"
    },
    {
      "x": -1,
      "y": 1,
      "z": -8,
      "name": "Necrotic_Sand",
      "support": 15
    },
    {
      "x": -1,
      "y": 2,
      "z": -8,
      "name": "Plant_Crop_Mushroom_Flatcap_Green",
      "components": {
        "Components": {
          "FarmingBlock": {
            "LastTickGameTime": "0001-01-01T12:00:00Z"
          }
        }
      }
    },
    {
      "x": -1,
      "y": -2,
      "z": -7,
      "name": "Necrotic_Stone"
    },
    {
      "x": -1,
      "y": -1,
      "z": -7,
      "name": "Necrotic_Stone"
    },
    {
      "x": -1,
      "y": 0,
      "z": -7,
      "name": "Necrotic_Stone"
    },
    {
      "x": -1,
      "y": 1,
      "z": -7,
      "name": "Necrotic_Sand"
    },
    {
      "x": -1,
      "y": -2,
      "z": -6,
      "name": "Necrotic_Stone"
    },
    {
      "x": -1,
      "y": -1,
      "z": -6,
      "name": "Necrotic_Stone"
    },
    {
      "x": -1,
      "y": 0,
      "z": -6,
      "name": "Necrotic_Stone"
    },
    {
      "x": -1,
      "y": 1,
      "z": -6,
      "name": "Necrotic_Sand",
      "support": 15
    },
    {
      "x": -1,
      "y": -3,
      "z": -5,
      "name": "Necrotic_Stone"
    },
    {
      "x": -1,
      "y": -2,
      "z": -5,
      "name": "Necrotic_Stone"
    },
    {
      "x": -1,
      "y": -1,
      "z": -5,
      "name": "Necrotic_Stone"
    },
    {
      "x": -1,
      "y": 0,
      "z": -5,
      "name": "Necrotic_Stone"
    },
    {
      "x": -1,
      "y": 1,
      "z": -5,
      "name": "Necrotic_Sand",
      "support": 15
    },
    {
      "x": -1,
      "y": -3,
      "z": -4,
      "name": "Necrotic_Stone"
    },
    {
      "x": -1,
      "y": -2,
      "z": -4,
      "name": "Necrotic_Stone"
    },
    {
      "x": -1,
      "y": -1,
      "z": -4,
      "name": "Necrotic_Stone"
    },
    {
      "x": -1,
      "y": 0,
      "z": -4,
      "name": "Necrotic_Stone"
    },
    {
      "x": -1,
      "y": 1,
      "z": -4,
      "name": "Necrotic_Sand"
    },
    {
      "x": -1,
      "y": -4,
      "z": -3,
      "name": "Wood_Burnt_Roots"
    },
    {
      "x": -1,
      "y": -3,
      "z": -3,
      "name": "Necrotic_Stone"
    },
    {
      "x": -1,
      "y": -2,
      "z": -3,
      "name": "Necrotic_Stone"
    },
    {
      "x": -1,
      "y": -1,
      "z": -3,
      "name": "Necrotic_Stone"
    },
    {
      "x": -1,
      "y": 0,
      "z": -3,
      "name": "Necrotic_Stone"
    },
    {
      "x": -1,
      "y": 1,
      "z": -3,
      "name": "Necrotic_Sand"
    },
    {
      "x": -1,
      "y": 2,
      "z": -3,
      "name": "Rubble_Slate",
      "support": 15
    },
    {
      "x": -1,
      "y": -3,
      "z": -2,
      "name": "Necrotic_Stone"
    },
    {
      "x": -1,
      "y": -2,
      "z": -2,
      "name": "Necrotic_Stone"
    },
    {
      "x": -1,
      "y": -1,
      "z": -2,
      "name": "Necrotic_Stone"
    },
    {
      "x": -1,
      "y": 0,
      "z": -2,
      "name": "Necrotic_Stone"
    },
    {
      "x": -1,
      "y": 1,
      "z": -2,
      "name": "Necrotic_Sand",
      "support": 15
    },
    {
      "x": -1,
      "y": 2,
      "z": -2,
      "name": "Plant_Leaves_Camphor",
      "support": 15
    },
    {
      "x": -1,
      "y": -3,
      "z": -1,
      "name": "Necrotic_Stone"
    },
    {
      "x": -1,
      "y": -2,
      "z": -1,
      "name": "Necrotic_Stone"
    },
    {
      "x": -1,
      "y": -1,
      "z": -1,
      "name": "Necrotic_Stone"
    },
    {
      "x": -1,
      "y": 0,
      "z": -1,
      "name": "Necrotic_Stone"
    },
    {
      "x": -1,
      "y": 1,
      "z": -1,
      "name": "Rock_Slate_Cobble"
    },
    {
      "x": -1,
      "y": 2,
      "z": -1,
      "name": "Rock_Slate_Brick_Pillar_Base"
    },
    {
      "x": -1,
      "y": 3,
      "z": -1,
      "name": "Rock_Slate_Brick_Pillar_Base"
    },
    {
      "x": -1,
      "y": 4,
      "z": -1,
      "name": "Rock_Slate_Brick_Pillar_Middle"
    },
    {
      "x": -1,
      "y": 5,
      "z": -1,
      "name": "Rock_Slate_Brick_Pillar_Base",
      "rotation": 8
    },
    {
      "x": -1,
      "y": 6,
      "z": -1,
      "name": "Rock_Slate_Brick_Ornate"
    },
    {
      "x": -1,
      "y": 7,
      "z": -1,
      "name": "Rock_Slate_Brick_Roof",
      "rotation": 1
    },
    {
      "x": -1,
      "y": -3,
      "z": 0,
      "name": "Necrotic_Stone"
    },
    {
      "x": -1,
      "y": -2,
      "z": 0,
      "name": "Necrotic_Stone"
    },
    {
      "x": -1,
      "y": -1,
      "z": 0,
      "name": "Necrotic_Stone"
    },
    {
      "x": -1,
      "y": 0,
      "z": 0,
      "name": "Necrotic_Stone"
    },
    {
      "x": -1,
      "y": 1,
      "z": 0,
      "name": "Rock_Slate_Cobble"
    },
    {
      "x": -1,
      "y": 2,
      "z": 0,
      "name": "Rock_Slate_Brick"
    },
    {
      "x": -1,
      "y": 3,
      "z": 0,
      "name": "Rock_Slate_Brick_Decorative"
    },
    {
      "x": -1,
      "y": 4,
      "z": 0,
      "name": "Rock_Slate_Brick"
    },
    {
      "x": -1,
      "y": 5,
      "z": 0,
      "name": "Rock_Slate_Brick_Decorative"
    },
    {
      "x": -1,
      "y": 6,
      "z": 0,
      "name": "Rock_Slate_Brick"
    },
    {
      "x": -1,
      "y": 7,
      "z": 0,
      "name": "Rock_Slate_Brick_Roof",
      "rotation": 1
    },
    {
      "x": -1,
      "y": -3,
      "z": 1,
      "name": "Necrotic_Stone"
    },
    {
      "x": -1,
      "y": -2,
      "z": 1,
      "name": "Necrotic_Stone"
    },
    {
      "x": -1,
      "y": -1,
      "z": 1,
      "name": "Necrotic_Stone"
    },
    {
      "x": -1,
      "y": 0,
      "z": 1,
      "name": "Necrotic_Stone"
    },
    {
      "x": -1,
      "y": 1,
      "z": 1,
      "name": "Rock_Slate_Cobble"
    },
    {
      "x": -1,
      "y": 2,
      "z": 1,
      "name": "Rock_Slate_Brick"
    },
    {
      "x": -1,
      "y": 3,
      "z": 1,
      "name": "Rock_Slate_Brick"
    },
    {
      "x": -1,
      "y": 4,
      "z": 1,
      "name": "Necrotic_Window",
      "rotation": 1
    },
    {
      "x": -1,
      "y": 5,
      "z": 1,
      "name": "Rock_Slate_Brick"
    },
    {
      "x": -1,
      "y": 6,
      "z": 1,
      "name": "Rock_Slate_Brick"
    },
    {
      "x": -1,
      "y": 7,
      "z": 1,
      "name": "Rock_Slate_Brick_Roof",
      "rotation": 1
    },
    {
      "x": -1,
      "y": -3,
      "z": 2,
      "name": "Necrotic_Stone"
    },
    {
      "x": -1,
      "y": -2,
      "z": 2,
      "name": "Necrotic_Stone"
    },
    {
      "x": -1,
      "y": -1,
      "z": 2,
      "name": "Necrotic_Stone"
    },
    {
      "x": -1,
      "y": 0,
      "z": 2,
      "name": "Necrotic_Stone"
    },
    {
      "x": -1,
      "y": 1,
      "z": 2,
      "name": "Rock_Slate_Cobble"
    },
    {
      "x": -1,
      "y": 2,
      "z": 2,
      "name": "Rock_Slate_Brick"
    },
    {
      "x": -1,
      "y": 3,
      "z": 2,
      "name": "Rock_Slate_Brick_Decorative"
    },
    {
      "x": -1,
      "y": 4,
      "z": 2,
      "name": "Rock_Slate_Brick"
    },
    {
      "x": -1,
      "y": 5,
      "z": 2,
      "name": "Rock_Slate_Brick_Decorative"
    },
    {
      "x": -1,
      "y": 6,
      "z": 2,
      "name": "Rock_Slate_Brick"
    },
    {
      "x": -1,
      "y": 7,
      "z": 2,
      "name": "Rock_Slate_Brick_Roof",
      "rotation": 1
    },
    {
      "x": -1,
      "y": -3,
      "z": 3,
      "name": "Necrotic_Stone"
    },
    {
      "x": -1,
      "y": -2,
      "z": 3,
      "name": "Necrotic_Stone"
    },
    {
      "x": -1,
      "y": -1,
      "z": 3,
      "name": "Necrotic_Stone"
    },
    {
      "x": -1,
      "y": 0,
      "z": 3,
      "name": "Necrotic_Stone"
    },
    {
      "x": -1,
      "y": 1,
      "z": 3,
      "name": "Rock_Slate_Cobble"
    },
    {
      "x": -1,
      "y": 2,
      "z": 3,
      "name": "Rock_Slate_Brick"
    },
    {
      "x": -1,
      "y": 3,
      "z": 3,
      "name": "Rock_Slate_Brick"
    },
    {
      "x": -1,
      "y": 4,
      "z": 3,
      "name": "Necrotic_Window",
      "rotation": 1
    },
    {
      "x": -1,
      "y": 5,
      "z": 3,
      "name": "Rock_Slate_Brick"
    },
    {
      "x": -1,
      "y": 6,
      "z": 3,
      "name": "Rock_Slate_Brick"
    },
    {
      "x": -1,
      "y": 7,
      "z": 3,
      "name": "Rock_Slate_Brick_Roof",
      "rotation": 1
    },
    {
      "x": -1,
      "y": -3,
      "z": 4,
      "name": "Necrotic_Stone"
    },
    {
      "x": -1,
      "y": -2,
      "z": 4,
      "name": "Necrotic_Stone"
    },
    {
      "x": -1,
      "y": -1,
      "z": 4,
      "name": "Necrotic_Stone"
    },
    {
      "x": -1,
      "y": 0,
      "z": 4,
      "name": "Necrotic_Stone"
    },
    {
      "x": -1,
      "y": 1,
      "z": 4,
      "name": "Rock_Slate_Cobble"
    },
    {
      "x": -1,
      "y": 2,
      "z": 4,
      "name": "Rock_Slate_Brick"
    },
    {
      "x": -1,
      "y": 3,
      "z": 4,
      "name": "Rock_Slate_Brick_Decorative"
    },
    {
      "x": -1,
      "y": 4,
      "z": 4,
      "name": "Rock_Slate_Brick"
    },
    {
      "x": -1,
      "y": 5,
      "z": 4,
      "name": "Rock_Slate_Brick_Decorative"
    },
    {
      "x": -1,
      "y": 6,
      "z": 4,
      "name": "Rock_Slate_Brick"
    },
    {
      "x": -1,
      "y": 7,
      "z": 4,
      "name": "Rock_Slate_Brick_Roof",
      "rotation": 1
    },
    {
      "x": -1,
      "y": -3,
      "z": 5,
      "name": "Necrotic_Stone"
    },
    {
      "x": -1,
      "y": -2,
      "z": 5,
      "name": "Necrotic_Stone"
    },
    {
      "x": -1,
      "y": -1,
      "z": 5,
      "name": "Necrotic_Stone"
    },
    {
      "x": -1,
      "y": 0,
      "z": 5,
      "name": "Necrotic_Stone"
    },
    {
      "x": -1,
      "y": 1,
      "z": 5,
      "name": "Rock_Slate_Cobble"
    },
    {
      "x": -1,
      "y": 2,
      "z": 5,
      "name": "Rock_Slate_Brick"
    },
    {
      "x": -1,
      "y": 3,
      "z": 5,
      "name": "Rock_Slate_Brick"
    },
    {
      "x": -1,
      "y": 4,
      "z": 5,
      "name": "Necrotic_Window",
      "rotation": 1
    },
    {
      "x": -1,
      "y": 5,
      "z": 5,
      "name": "Rock_Slate_Brick"
    },
    {
      "x": -1,
      "y": 6,
      "z": 5,
      "name": "Rock_Slate_Brick"
    },
    {
      "x": -1,
      "y": 7,
      "z": 5,
      "name": "Rock_Slate_Brick_Roof",
      "rotation": 1
    },
    {
      "x": -1,
      "y": -3,
      "z": 6,
      "name": "Necrotic_Stone"
    },
    {
      "x": -1,
      "y": -2,
      "z": 6,
      "name": "Necrotic_Stone"
    },
    {
      "x": -1,
      "y": -1,
      "z": 6,
      "name": "Necrotic_Stone"
    },
    {
      "x": -1,
      "y": 0,
      "z": 6,
      "name": "Necrotic_Stone"
    },
    {
      "x": -1,
      "y": 1,
      "z": 6,
      "name": "Rock_Slate_Cobble"
    },
    {
      "x": -1,
      "y": 2,
      "z": 6,
      "name": "Rock_Slate_Brick"
    },
    {
      "x": -1,
      "y": 3,
      "z": 6,
      "name": "Rock_Slate_Brick_Decorative"
    },
    {
      "x": -1,
      "y": 4,
      "z": 6,
      "name": "Rock_Slate_Brick"
    },
    {
      "x": -1,
      "y": 5,
      "z": 6,
      "name": "Rock_Slate_Brick_Decorative"
    },
    {
      "x": -1,
      "y": 6,
      "z": 6,
      "name": "Rock_Slate_Brick"
    },
    {
      "x": -1,
      "y": 7,
      "z": 6,
      "name": "Rock_Slate_Brick_Roof",
      "rotation": 1
    },
    {
      "x": -1,
      "y": -2,
      "z": 7,
      "name": "Necrotic_Stone"
    },
    {
      "x": -1,
      "y": -1,
      "z": 7,
      "name": "Necrotic_Stone"
    },
    {
      "x": -1,
      "y": 0,
      "z": 7,
      "name": "Necrotic_Stone"
    },
    {
      "x": -1,
      "y": 1,
      "z": 7,
      "name": "Rock_Slate_Cobble"
    },
    {
      "x": -1,
      "y": 2,
      "z": 7,
      "name": "Rock_Slate_Cobble"
    },
    {
      "x": -1,
      "y": 3,
      "z": 7,
      "name": "Rock_Slate_Brick_Pillar_Base"
    },
    {
      "x": -1,
      "y": 4,
      "z": 7,
      "name": "Rock_Slate_Brick_Pillar_Middle"
    },
    {
      "x": -1,
      "y": 5,
      "z": 7,
      "name": "Rock_Slate_Brick_Pillar_Middle"
    },
    {
      "x": -1,
      "y": 6,
      "z": 7,
      "name": "Rock_Slate_Brick_Decorative"
    },
    {
      "x": -1,
      "y": 7,
      "z": 7,
      "name": "Rock_Slate_Brick_Roof",
      "rotation": 1
    },
    {
      "x": -1,
      "y": -2,
      "z": 8,
      "name": "Wood_Burnt_Roots"
    },
    {
      "x": -1,
      "y": -1,
      "z": 8,
      "name": "Necrotic_Stone"
    },
    {
      "x": -1,
      "y": 0,
      "z": 8,
      "name": "Necrotic_Stone"
    },
    {
      "x": -1,
      "y": 1,
      "z": 8,
      "name": "Rock_Slate_Cobble"
    },
    {
      "x": -1,
      "y": 2,
      "z": 8,
      "name": "Rock_Slate_Cobble_Half"
    },
    {
      "x": -1,
      "y": 0,
      "z": 9,
      "name": "Necrotic_Stone"
    },
    {
      "x": -1,
      "y": 1,
      "z": 9,
      "name": "Rock_Slate_Cobble"
    },
    {
      "x": -1,
      "y": 2,
      "z": 9,
      "name": "Rock_Slate_Brick_Wall",
      "rotation": 2
    },
    {
      "x": 0,
      "y": 0,
      "z": -9,
      "name": "Necrotic_Stone"
    },
    {
      "x": 0,
      "y": 1,
      "z": -9,
      "name": "Necrotic_Sand"
    },
    {
      "x": 0,
      "y": 2,
      "z": -9,
      "name": "Necrotic_Fence",
      "rotation": 2
    },
    {
      "x": 0,
      "y": -1,
      "z": -8,
      "name": "Necrotic_Stone"
    },
    {
      "x": 0,
      "y": 0,
      "z": -8,
      "name": "Necrotic_Stone"
    },
    {
      "x": 0,
      "y": 1,
      "z": -8,
      "name": "Necrotic_Sand",
      "support": 15
    },
    {
      "x": 0,
      "y": -3,
      "z": -7,
      "name": "Long_Roots"
    },
    {
      "x": 0,
      "y": -2,
      "z": -7,
      "name": "Necrotic_Stone"
    },
    {
      "x": 0,
      "y": -1,
      "z": -7,
      "name": "Necrotic_Stone"
    },
    {
      "x": 0,
      "y": 0,
      "z": -7,
      "name": "Necrotic_Stone"
    },
    {
      "x": 0,
      "y": 1,
      "z": -7,
      "name": "Necrotic_Sand"
    },
    {
      "x": 0,
      "y": -2,
      "z": -6,
      "name": "Necrotic_Stone"
    },
    {
      "x": 0,
      "y": -1,
      "z": -6,
      "name": "Necrotic_Stone"
    },
    {
      "x": 0,
      "y": 0,
      "z": -6,
      "name": "Necrotic_Stone"
    },
    {
      "x": 0,
      "y": 1,
      "z": -6,
      "name": "Necrotic_Sand",
      "support": 15
    },
    {
      "x": 0,
      "y": -3,
      "z": -5,
      "name": "Necrotic_Stone"
    },
    {
      "x": 0,
      "y": -2,
      "z": -5,
      "name": "Necrotic_Stone"
    },
    {
      "x": 0,
      "y": -1,
      "z": -5,
      "name": "Necrotic_Stone"
    },
    {
      "x": 0,
      "y": 0,
      "z": -5,
      "name": "Necrotic_Stone"
    },
    {
      "x": 0,
      "y": 1,
      "z": -5,
      "name": "Necrotic_Sand",
      "support": 15
    },
    {
      "x": 0,
      "y": -3,
      "z": -4,
      "name": "Necrotic_Stone"
    },
    {
      "x": 0,
      "y": -2,
      "z": -4,
      "name": "Necrotic_Stone"
    },
    {
      "x": 0,
      "y": -1,
      "z": -4,
      "name": "Necrotic_Stone"
    },
    {
      "x": 0,
      "y": 0,
      "z": -4,
      "name": "Necrotic_Stone"
    },
    {
      "x": 0,
      "y": 1,
      "z": -4,
      "name": "Necrotic_Sand",
      "support": 15
    },
    {
      "x": 0,
      "y": 2,
      "z": -4,
      "name": "Necrotic_Grass"
    },
    {
      "x": 0,
      "y": -3,
      "z": -3,
      "name": "Necrotic_Stone"
    },
    {
      "x": 0,
      "y": -2,
      "z": -3,
      "name": "Necrotic_Stone"
    },
    {
      "x": 0,
      "y": -1,
      "z": -3,
      "name": "Necrotic_Stone"
    },
    {
      "x": 0,
      "y": 0,
      "z": -3,
      "name": "Necrotic_Stone"
    },
    {
      "x": 0,
      "y": 1,
      "z": -3,
      "name": "Rock_Slate_Cobble"
    },
    {
      "x": 0,
      "y": 2,
      "z": -3,
      "name": "Rock_Slate_Cobble_Half"
    },
    {
      "x": 0,
      "y": -4,
      "z": -2,
      "name": "Wood_Burnt_Roots"
    },
    {
      "x": 0,
      "y": -3,
      "z": -2,
      "name": "Necrotic_Stone"
    },
    {
      "x": 0,
      "y": -2,
      "z": -2,
      "name": "Necrotic_Stone"
    },
    {
      "x": 0,
      "y": -1,
      "z": -2,
      "name": "Necrotic_Stone"
    },
    {
      "x": 0,
      "y": 0,
      "z": -2,
      "name": "Necrotic_Stone"
    },
    {
      "x": 0,
      "y": 1,
      "z": -2,
      "name": "Rock_Slate_Cobble"
    },
    {
      "x": 0,
      "y": 2,
      "z": -2,
      "name": "Necrotic_Sand"
    },
    {
      "x": 0,
      "y": -3,
      "z": -1,
      "name": "Necrotic_Stone"
    },
    {
      "x": 0,
      "y": -2,
      "z": -1,
      "name": "Necrotic_Stone"
    },
    {
      "x": 0,
      "y": -1,
      "z": -1,
      "name": "Necrotic_Stone"
    },
    {
      "x": 0,
      "y": 0,
      "z": -1,
      "name": "Necrotic_Stone"
    },
    {
      "x": 0,
      "y": 1,
      "z": -1,
      "name": "Rock_Slate_Cobble"
    },
    {
      "x": 0,
      "y": 2,
      "z": -1,
      "name": "Necrotic_Sand",
      "support": 15
    },
    {
      "x": 0,
      "y": 3,
      "z": -1,
      "name": "Rubble_Slate",
      "support": 15
    },
    {
      "x": 0,
      "y": 6,
      "z": -1,
      "name": "Rock_Slate_Cobble_Roof_Shallow",
      "filler": 31,
      "rotation": 1
    },
    {
      "x": 0,
      "y": -3,
      "z": 0,
      "name": "Necrotic_Stone"
    },
    {
      "x": 0,
      "y": -2,
      "z": 0,
      "name": "Necrotic_Stone"
    },
    {
      "x": 0,
      "y": -1,
      "z": 0,
      "name": "Necrotic_Stone"
    },
    {
      "x": 0,
      "y": 0,
      "z": 0,
      "name": "Necrotic_Stone"
    },
    {
      "x": 0,
      "y": 1,
      "z": 0,
      "name": "Rock_Slate_Cobble"
    },
    {
      "x": 0,
      "y": 2,
      "z": 0,
      "name": "Rock_Slate_Cobble"
    },
    {
      "x": 0,
      "y": 3,
      "z": 0,
      "name": "Plant_Bush_Winter",
      "support": 15
    },
    {
      "x": 0,
      "y": 6,
      "z": 0,
      "name": "Rock_Slate_Cobble_Roof_Shallow",
      "filler": 31,
      "rotation": 1
    },
    {
      "x": 0,
      "y": -3,
      "z": 1,
      "name": "Necrotic_Stone"
    },
    {
      "x": 0,
      "y": -2,
      "z": 1,
      "name": "Necrotic_Stone"
    },
    {
      "x": 0,
      "y": -1,
      "z": 1,
      "name": "Necrotic_Stone"
    },
    {
      "x": 0,
      "y": 0,
      "z": 1,
      "name": "Necrotic_Stone"
    },
    {
      "x": 0,
      "y": 1,
      "z": 1,
      "name": "Rock_Slate_Cobble"
    },
    {
      "x": 0,
      "y": 2,
      "z": 1,
      "name": "Necrotic_Sand",
      "support": 15
    },
    {
      "x": 0,
      "y": 6,
      "z": 1,
      "name": "Rock_Slate_Cobble_Roof_Shallow",
      "filler": 31,
      "rotation": 1
    },
    {
      "x": 0,
      "y": -3,
      "z": 2,
      "name": "Necrotic_Stone"
    },
    {
      "x": 0,
      "y": -2,
      "z": 2,
      "name": "Necrotic_Stone"
    },
    {
      "x": 0,
      "y": -1,
      "z": 2,
      "name": "Necrotic_Stone"
    },
    {
      "x": 0,
      "y": 0,
      "z": 2,
      "name": "Necrotic_Stone"
    },
    {
      "x": 0,
      "y": 1,
      "z": 2,
      "name": "Rock_Slate_Cobble"
    },
    {
      "x": 0,
      "y": 2,
      "z": 2,
      "name": "Rock_Slate_Cobble"
    },
    {
      "x": 0,
      "y": 3,
      "z": 2,
      "name": "Plant_Leaves_Dead",
      "support": 15
    },
    {
      "x": 0,
      "y": 4,
      "z": 2,
      "name": "Plant_Leaves_Dead",
      "support": 15
    },
    {
      "x": 0,
      "y": 5,
      "z": 2,
      "name": "Plant_Leaves_Dead",
      "support": 15
    },
    {
      "x": 0,
      "y": 6,
      "z": 2,
      "name": "Rock_Slate_Cobble_Roof_Shallow",
      "filler": 31,
      "rotation": 1
    },
    {
      "x": 0,
      "y": -3,
      "z": 3,
      "name": "Necrotic_Stone"
    },
    {
      "x": 0,
      "y": -2,
      "z": 3,
      "name": "Necrotic_Stone"
    },
    {
      "x": 0,
      "y": -1,
      "z": 3,
      "name": "Necrotic_Stone"
    },
    {
      "x": 0,
      "y": 0,
      "z": 3,
      "name": "Necrotic_Stone"
    },
    {
      "x": 0,
      "y": 1,
      "z": 3,
      "name": "Rock_Slate_Cobble"
    },
    {
      "x": 0,
      "y": 2,
      "z": 3,
      "name": "Necrotic_Sand",
      "support": 15
    },
    {
      "x": 0,
      "y": 4,
      "z": 3,
      "name": "Plant_Leaves_Dead",
      "support": 15
    },
    {
      "x": 0,
      "y": 5,
      "z": 3,
      "name": "Plant_Leaves_Dead",
      "support": 15
    },
    {
      "x": 0,
      "y": 6,
      "z": 3,
      "name": "Rock_Slate_Cobble_Roof_Shallow",
      "filler": 31,
      "rotation": 1
    },
    {
      "x": 0,
      "y": -3,
      "z": 4,
      "name": "Necrotic_Stone"
    },
    {
      "x": 0,
      "y": -2,
      "z": 4,
      "name": "Necrotic_Stone"
    },
    {
      "x": 0,
      "y": -1,
      "z": 4,
      "name": "Necrotic_Stone"
    },
    {
      "x": 0,
      "y": 0,
      "z": 4,
      "name": "Necrotic_Stone"
    },
    {
      "x": 0,
      "y": 1,
      "z": 4,
      "name": "Rock_Slate_Cobble"
    },
    {
      "x": 0,
      "y": 2,
      "z": 4,
      "name": "Necrotic_Sand",
      "support": 15
    },
    {
      "x": 0,
      "y": 5,
      "z": 4,
      "name": "Plant_Leaves_Dead",
      "support": 15
    },
    {
      "x": 0,
      "y": 6,
      "z": 4,
      "name": "Rock_Slate_Cobble_Roof_Shallow",
      "filler": 31,
      "rotation": 1
    },
    {
      "x": 0,
      "y": -3,
      "z": 5,
      "name": "Necrotic_Stone"
    },
    {
      "x": 0,
      "y": -2,
      "z": 5,
      "name": "Necrotic_Stone"
    },
    {
      "x": 0,
      "y": -1,
      "z": 5,
      "name": "Necrotic_Stone"
    },
    {
      "x": 0,
      "y": 0,
      "z": 5,
      "name": "Necrotic_Stone"
    },
    {
      "x": 0,
      "y": 1,
      "z": 5,
      "name": "Rock_Slate_Cobble"
    },
    {
      "x": 0,
      "y": 2,
      "z": 5,
      "name": "Rock_Slate_Cobble"
    },
    {
      "x": 0,
      "y": 5,
      "z": 5,
      "name": "Plant_Leaves_Dead",
      "support": 15
    },
    {
      "x": 0,
      "y": 6,
      "z": 5,
      "name": "Rock_Slate_Cobble_Roof_Shallow",
      "filler": 31,
      "rotation": 1
    },
    {
      "x": 0,
      "y": -3,
      "z": 6,
      "name": "Necrotic_Stone"
    },
    {
      "x": 0,
      "y": -2,
      "z": 6,
      "name": "Necrotic_Stone"
    },
    {
      "x": 0,
      "y": -1,
      "z": 6,
      "name": "Necrotic_Stone"
    },
    {
      "x": 0,
      "y": 0,
      "z": 6,
      "name": "Necrotic_Stone"
    },
    {
      "x": 0,
      "y": 1,
      "z": 6,
      "name": "Rock_Slate_Cobble"
    },
    {
      "x": 0,
      "y": 2,
      "z": 6,
      "name": "Rock_Slate_Cobble"
    },
    {
      "x": 0,
      "y": 3,
      "z": 6,
      "name": "Plant_Leaves_Camphor",
      "support": 15
    },
    {
      "x": 0,
      "y": 5,
      "z": 6,
      "name": "Plant_Leaves_Dead",
      "support": 15
    },
    {
      "x": 0,
      "y": 6,
      "z": 6,
      "name": "Rock_Slate_Cobble_Roof_Shallow",
      "filler": 31,
      "rotation": 1
    },
    {
      "x": 0,
      "y": -2,
      "z": 7,
      "name": "Necrotic_Stone"
    },
    {
      "x": 0,
      "y": -1,
      "z": 7,
      "name": "Necrotic_Stone"
    },
    {
      "x": 0,
      "y": 0,
      "z": 7,
      "name": "Necrotic_Stone"
    },
    {
      "x": 0,
      "y": 1,
      "z": 7,
      "name": "Rock_Slate_Cobble"
    },
    {
      "x": 0,
      "y": 2,
      "z": 7,
      "name": "Rock_Slate_Cobble"
    },
    {
      "x": 0,
      "y": 6,
      "z": 7,
      "name": "Rock_Slate_Cobble_Roof_Shallow",
      "filler": 31,
      "rotation": 1
    },
    {
      "x": 0,
      "y": -2,
      "z": 8,
      "name": "Wood_Burnt_Roots"
    },
    {
      "x": 0,
      "y": -1,
      "z": 8,
      "name": "Necrotic_Stone"
    },
    {
      "x": 0,
      "y": 0,
      "z": 8,
      "name": "Necrotic_Stone"
    },
    {
      "x": 0,
      "y": 1,
      "z": 8,
      "name": "Rock_Slate_Cobble"
    },
    {
      "x": 0,
      "y": 2,
      "z": 8,
      "name": "Rock_Slate_Cobble_Half"
    },
    {
      "x": 0,
      "y": 0,
      "z": 9,
      "name": "Necrotic_Stone"
    },
    {
      "x": 0,
      "y": 1,
      "z": 9,
      "name": "Rock_Slate_Cobble"
    },
    {
      "x": 0,
      "y": 2,
      "z": 9,
      "name": "Rock_Slate_Brick_Wall",
      "rotation": 2
    },
    {
      "x": 1,
      "y": 0,
      "z": -9,
      "name": "Necrotic_Stone"
    },
    {
      "x": 1,
      "y": 1,
      "z": -9,
      "name": "Necrotic_Sand"
    },
    {
      "x": 1,
      "y": 2,
      "z": -9,
      "name": "Necrotic_Fence",
      "rotation": 2
    },
    {
      "x": 1,
      "y": -1,
      "z": -8,
      "name": "Necrotic_Stone"
    },
    {
      "x": 1,
      "y": 0,
      "z": -8,
      "name": "Necrotic_Stone"
    },
    {
      "x": 1,
      "y": 1,
      "z": -8,
      "name": "Necrotic_Sand",
      "support": 15
    },
    {
      "x": 1,
      "y": -2,
      "z": -7,
      "name": "Necrotic_Stone"
    },
    {
      "x": 1,
      "y": -1,
      "z": -7,
      "name": "Necrotic_Stone"
    },
    {
      "x": 1,
      "y": 0,
      "z": -7,
      "name": "Necrotic_Stone"
    },
    {
      "x": 1,
      "y": 1,
      "z": -7,
      "name": "Necrotic_Sand",
      "support": 15
    },
    {
      "x": 1,
      "y": -2,
      "z": -6,
      "name": "Necrotic_Stone"
    },
    {
      "x": 1,
      "y": -1,
      "z": -6,
      "name": "Necrotic_Stone"
    },
    {
      "x": 1,
      "y": 0,
      "z": -6,
      "name": "Necrotic_Stone"
    },
    {
      "x": 1,
      "y": 1,
      "z": -6,
      "name": "Necrotic_Sand",
      "support": 15
    },
    {
      "x": 1,
      "y": -3,
      "z": -5,
      "name": "Necrotic_Stone"
    },
    {
      "x": 1,
      "y": -2,
      "z": -5,
      "name": "Necrotic_Stone"
    },
    {
      "x": 1,
      "y": -1,
      "z": -5,
      "name": "Necrotic_Stone"
    },
    {
      "x": 1,
      "y": 0,
      "z": -5,
      "name": "Necrotic_Stone"
    },
    {
      "x": 1,
      "y": 1,
      "z": -5,
      "name": "Necrotic_Sand",
      "support": 15
    },
    {
      "x": 1,
      "y": -3,
      "z": -4,
      "name": "Necrotic_Stone"
    },
    {
      "x": 1,
      "y": -2,
      "z": -4,
      "name": "Necrotic_Stone"
    },
    {
      "x": 1,
      "y": -1,
      "z": -4,
      "name": "Necrotic_Stone"
    },
    {
      "x": 1,
      "y": 0,
      "z": -4,
      "name": "Necrotic_Stone"
    },
    {
      "x": 1,
      "y": 1,
      "z": -4,
      "name": "Necrotic_Sand",
      "support": 15
    },
    {
      "x": 1,
      "y": 2,
      "z": -4,
      "name": "Dead_Branch"
    },
    {
      "x": 1,
      "y": -3,
      "z": -3,
      "name": "Necrotic_Stone"
    },
    {
      "x": 1,
      "y": -2,
      "z": -3,
      "name": "Necrotic_Stone"
    },
    {
      "x": 1,
      "y": -1,
      "z": -3,
      "name": "Necrotic_Stone"
    },
    {
      "x": 1,
      "y": 0,
      "z": -3,
      "name": "Necrotic_Stone"
    },
    {
      "x": 1,
      "y": 1,
      "z": -3,
      "name": "Rock_Slate_Cobble"
    },
    {
      "x": 1,
      "y": 2,
      "z": -3,
      "name": "Rock_Slate_Cobble_Half"
    },
    {
      "x": 1,
      "y": -3,
      "z": -2,
      "name": "Necrotic_Stone"
    },
    {
      "x": 1,
      "y": -2,
      "z": -2,
      "name": "Necrotic_Stone"
    },
    {
      "x": 1,
      "y": -1,
      "z": -2,
      "name": "Necrotic_Stone"
    },
    {
      "x": 1,
      "y": 0,
      "z": -2,
      "name": "Necrotic_Stone"
    },
    {
      "x": 1,
      "y": 1,
      "z": -2,
      "name": "Rock_Slate_Cobble"
    },
    {
      "x": 1,
      "y": 2,
      "z": -2,
      "name": "Necrotic_Sand",
      "support": 15
    },
    {
      "x": 1,
      "y": -3,
      "z": -1,
      "name": "Necrotic_Stone"
    },
    {
      "x": 1,
      "y": -2,
      "z": -1,
      "name": "Necrotic_Stone"
    },
    {
      "x": 1,
      "y": -1,
      "z": -1,
      "name": "Necrotic_Stone"
    },
    {
      "x": 1,
      "y": 0,
      "z": -1,
      "name": "Necrotic_Stone"
    },
    {
      "x": 1,
      "y": 1,
      "z": -1,
      "name": "Rock_Slate_Cobble"
    },
    {
      "x": 1,
      "y": 2,
      "z": -1,
      "name": "Necrotic_Sand",
      "support": 15
    },
    {
      "x": 1,
      "y": 3,
      "z": -1,
      "name": "Necrotic_Grass"
    },
    {
      "x": 1,
      "y": 6,
      "z": -1,
      "name": "Rock_Slate_Cobble_Roof_Shallow",
      "rotation": 1
    },
    {
      "x": 1,
      "y": -4,
      "z": 0,
      "name": "Wood_Burnt_Roots"
    },
    {
      "x": 1,
      "y": -3,
      "z": 0,
      "name": "Necrotic_Stone"
    },
    {
      "x": 1,
      "y": -2,
      "z": 0,
      "name": "Necrotic_Stone"
    },
    {
      "x": 1,
      "y": -1,
      "z": 0,
      "name": "Necrotic_Stone"
    },
    {
      "x": 1,
      "y": 0,
      "z": 0,
      "name": "Necrotic_Stone"
    },
    {
      "x": 1,
      "y": 1,
      "z": 0,
      "name": "Rock_Slate_Cobble"
    },
    {
      "x": 1,
      "y": 2,
      "z": 0,
      "name": "Necrotic_Sand",
      "support": 15
    },
    {
      "x": 1,
      "y": 6,
      "z": 0,
      "name": "Rock_Slate_Cobble_Roof_Shallow",
      "rotation": 1
    },
    {
      "x": 1,
      "y": -3,
      "z": 1,
      "name": "Necrotic_Stone"
    },
    {
      "x": 1,
      "y": -2,
      "z": 1,
      "name": "Necrotic_Stone"
    },
    {
      "x": 1,
      "y": -1,
      "z": 1,
      "name": "Necrotic_Stone"
    },
    {
      "x": 1,
      "y": 0,
      "z": 1,
      "name": "Necrotic_Stone"
    },
    {
      "x": 1,
      "y": 1,
      "z": 1,
      "name": "Rock_Slate_Cobble"
    },
    {
      "x": 1,
      "y": 2,
      "z": 1,
      "name": "Necrotic_Sand",
      "support": 15
    },
    {
      "x": 1,
      "y": 6,
      "z": 1,
      "name": "Rock_Slate_Cobble_Roof_Shallow",
      "rotation": 1
    },
    {
      "x": 1,
      "y": -3,
      "z": 2,
      "name": "Necrotic_Stone"
    },
    {
      "x": 1,
      "y": -2,
      "z": 2,
      "name": "Necrotic_Stone"
    },
    {
      "x": 1,
      "y": -1,
      "z": 2,
      "name": "Necrotic_Stone"
    },
    {
      "x": 1,
      "y": 0,
      "z": 2,
      "name": "Necrotic_Stone"
    },
    {
      "x": 1,
      "y": 1,
      "z": 2,
      "name": "Rock_Slate_Cobble"
    },
    {
      "x": 1,
      "y": 2,
      "z": 2,
      "name": "Necrotic_Sand",
      "support": 15
    },
    {
      "x": 1,
      "y": 3,
      "z": 2,
      "name": "Necrotic_Grass"
    },
    {
      "x": 1,
      "y": 6,
      "z": 2,
      "name": "Rock_Slate_Cobble_Roof_Shallow",
      "rotation": 1
    },
    {
      "x": 1,
      "y": -4,
      "z": 3,
      "name": "Wood_Burnt_Roots"
    },
    {
      "x": 1,
      "y": -3,
      "z": 3,
      "name": "Necrotic_Stone"
    },
    {
      "x": 1,
      "y": -2,
      "z": 3,
      "name": "Necrotic_Stone"
    },
    {
      "x": 1,
      "y": -1,
      "z": 3,
      "name": "Necrotic_Stone"
    },
    {
      "x": 1,
      "y": 0,
      "z": 3,
      "name": "Necrotic_Stone"
    },
    {
      "x": 1,
      "y": 1,
      "z": 3,
      "name": "Rock_Slate_Cobble"
    },
    {
      "x": 1,
      "y": 2,
      "z": 3,
      "name": "Necrotic_Sand"
    },
    {
      "x": 1,
      "y": 6,
      "z": 3,
      "name": "Rock_Slate_Cobble_Roof_Shallow",
      "rotation": 1
    },
    {
      "x": 1,
      "y": -3,
      "z": 4,
      "name": "Necrotic_Stone"
    },
    {
      "x": 1,
      "y": -2,
      "z": 4,
      "name": "Necrotic_Stone"
    },
    {
      "x": 1,
      "y": -1,
      "z": 4,
      "name": "Necrotic_Stone"
    },
    {
      "x": 1,
      "y": 0,
      "z": 4,
      "name": "Necrotic_Stone"
    },
    {
      "x": 1,
      "y": 1,
      "z": 4,
      "name": "Rock_Slate_Cobble"
    },
    {
      "x": 1,
      "y": 2,
      "z": 4,
      "name": "Necrotic_Sand"
    },
    {
      "x": 1,
      "y": 6,
      "z": 4,
      "name": "Rock_Slate_Cobble_Roof_Shallow",
      "rotation": 1
    },
    {
      "x": 1,
      "y": -3,
      "z": 5,
      "name": "Necrotic_Stone"
    },
    {
      "x": 1,
      "y": -2,
      "z": 5,
      "name": "Necrotic_Stone"
    },
    {
      "x": 1,
      "y": -1,
      "z": 5,
      "name": "Necrotic_Stone"
    },
    {
      "x": 1,
      "y": 0,
      "z": 5,
      "name": "Necrotic_Stone"
    },
    {
      "x": 1,
      "y": 1,
      "z": 5,
      "name": "Rock_Slate_Cobble"
    },
    {
      "x": 1,
      "y": 2,
      "z": 5,
      "name": "Rock_Slate_Cobble"
    },
    {
      "x": 1,
      "y": 3,
      "z": 5,
      "name": "Tombstone_2",
      "rotation": 1
    },
    {
      "x": 1,
      "y": 6,
      "z": 5,
      "name": "Rock_Slate_Cobble_Roof_Shallow",
      "rotation": 1
    },
    {
      "x": 1,
      "y": -3,
      "z": 6,
      "name": "Necrotic_Stone"
    },
    {
      "x": 1,
      "y": -2,
      "z": 6,
      "name": "Necrotic_Stone"
    },
    {
      "x": 1,
      "y": -1,
      "z": 6,
      "name": "Necrotic_Stone"
    },
    {
      "x": 1,
      "y": 0,
      "z": 6,
      "name": "Necrotic_Stone"
    },
    {
      "x": 1,
      "y": 1,
      "z": 6,
      "name": "Rock_Slate_Cobble"
    },
    {
      "x": 1,
      "y": 2,
      "z": 6,
      "name": "Rock_Slate_Cobble"
    },
    {
      "x": 1,
      "y": 6,
      "z": 6,
      "name": "Rock_Slate_Cobble_Roof_Shallow",
      "rotation": 1
    },
    {
      "x": 1,
      "y": -2,
      "z": 7,
      "name": "Necrotic_Stone"
    },
    {
      "x": 1,
      "y": -1,
      "z": 7,
      "name": "Necrotic_Stone"
    },
    {
      "x": 1,
      "y": 0,
      "z": 7,
      "name": "Necrotic_Stone"
    },
    {
      "x": 1,
      "y": 1,
      "z": 7,
      "name": "Rock_Slate_Cobble"
    },
    {
      "x": 1,
      "y": 2,
      "z": 7,
      "name": "Rock_Slate_Cobble"
    },
    {
      "x": 1,
      "y": 6,
      "z": 7,
      "name": "Rock_Slate_Cobble_Roof_Shallow",
      "rotation": 1
    },
    {
      "x": 1,
      "y": -2,
      "z": 8,
      "name": "Wood_Burnt_Roots"
    },
    {
      "x": 1,
      "y": -1,
      "z": 8,
      "name": "Necrotic_Stone"
    },
    {
      "x": 1,
      "y": 0,
      "z": 8,
      "name": "Necrotic_Stone"
    },
    {
      "x": 1,
      "y": 1,
      "z": 8,
      "name": "Rock_Slate_Cobble"
    },
    {
      "x": 1,
      "y": 2,
      "z": 8,
      "name": "Rock_Slate_Cobble_Half"
    },
    {
      "x": 1,
      "y": 0,
      "z": 9,
