{
  "version": 8,
  "blockIdVersion": 11,
  "anchorX": 2,
  "anchorY": 1,
  "anchorZ": 0,
  "blocks": [
    {
      "x": -3,
      "y": 0,
      "z": 0,
      "name": "Necrotic_Sand"
    },
    {
      "x": -3,
      "y": 1,
      "z": 0,
      "name": "Plant_Crop_Mushroom_Flatcap_Green",
      "components": {
        "Components": {
          "FarmingBlock": {
            "LastTickGameTime": "0001-01-01T12:00:00Z"
          },
          "PlacedByInteraction": {
            "WhoPlacedUuid": {
              "$binary": "bJ0Z/pHxT/WyhVA6z1mjfg==",
              "$type": "04"
            }
          }
        }
      }
    },
    {
      "x": -3,
      "y": 4,
      "z": 0,
      "name": "Plant_Vine_Wall_Dead",
      "support": 15,
      "rotation": 3
    },
    {
      "x": -3,
      "y": 0,
      "z": 1,
      "name": "Necrotic_Sand"
    },
    {
      "x": -3,
      "y": 1,
      "z": 1,
      "name": "Necrotic_Sand"
    },
    {
      "x": -3,
      "y": 2,
      "z": 1,
      "name": "Necrotic_Sand"
    },
    {
      "x": -3,
      "y": 3,
      "z": 1,
      "name": "Plant_Bush_Winter",
      "support": 15
    },
    {
      "x": -3,
      "y": 4,
      "z": 1,
      "name": "Plant_Vine_Wall_Poisoned",
      "support": 15,
      "rotation": 3
    },
    {
      "x": -3,
      "y": 5,
      "z": 1,
      "name": "Plant_Vine_Wall_Poisoned",
      "support": 15,
      "rotation": 3
    },
    {
      "x": -3,
      "y": -1,
      "z": 2,
      "name": "Necrotic_Sand"
    },
    {
      "x": -3,
      "y": 0,
      "z": 2,
      "name": "Necrotic_Sand"
    },
    {
      "x": -3,
      "y": 1,
      "z": 2,
      "name": "Necrotic_Sand"
    },
    {
      "x": -3,
      "y": 2,
      "z": 2,
      "name": "Necrotic_Sand"
    },
    {
      "x": -3,
      "y": 3,
      "z": 2,
      "name": "Rubble_Slate_Medium",
      "support": 15
    },
    {
      "x": -3,
      "y": 0,
      "z": 3,
      "name": "Necrotic_Sand"
    },
    {
      "x": -3,
      "y": 1,
      "z": 3,
      "name": "Necrotic_Sand"
    },
    {
      "x": -3,
      "y": 2,
      "z": 3,
      "name": "Rock_Slate_Stalactite_Large"
    },
    {
      "x": -3,
      "y": 3,
      "z": 3,
      "name": "Rock_Slate_Stalactite_Large",
      "filler": 1024
    },
    {
      "x": -2,
      "y": -2,
      "z": -1,
      "name": "Wood_Burnt_Roots"
    },
    {
      "x": -2,
      "y": -1,
      "z": -1,
      "name": "Necrotic_Sand"
    },
    {
      "x": -2,
      "y": 0,
      "z": -1,
      "name": "Necrotic_Sand"
    },
    {
      "x": -2,
      "y": 1,
      "z": -1,
      "name": "Necrotic_Sand"
    },
    {
      "x": -2,
      "y": 2,
      "z": -1,
      "name": "Necrotic_Sand"
    },
    {
      "x": -2,
      "y": 3,
      "z": -1,
      "name": "Rubble_Slate_Medium",
      "support": 15
    },
    {
      "x": -2,
      "y": 4,
      "z": -1,
      "name": "Plant_Vine_Wall_Poisoned",
      "support": 15,
      "rotation": 2
    },
    {
      "x": -2,
      "y": -2,
      "z": 0,
      "name": "Necrotic_Sand"
    },
    {
      "x": -2,
      "y": -1,
      "z": 0,
      "name": "Necrotic_Sand"
    },
    {
      "x": -2,
      "y": 0,
      "z": 0,
      "name": "Necrotic_Sand"
    },
    {
      "x": -2,
      "y": 1,
      "z": 0,
      "name": "Necrotic_Sand"
    },
    {
      "x": -2,
      "y": 2,
      "z": 0,
      "name": "Necrotic_Sand"
    },
    {
      "x": -2,
      "y": 3,
      "z": 0,
      "name": "Necrotic_Sand"
    },
    {
      "x": -2,
      "y": 4,
      "z": 0,
      "name": "Necrotic_Sand"
    },
    {
      "x": -2,
      "y": 5,
      "z": 0,
      "name": "Rubble_Slate",
      "support": 15
    },
    {
      "x": -2,
      "y": 6,
      "z": 0,
      "name": "Plant_Vine_Wall_Poisoned",
      "support": 15,
      "rotation": 3
    },
    {
      "x": -2,
      "y": 7,
      "z": 0,
      "name": "Plant_Vine_Wall_Dead",
      "support": 15,
      "rotation": 3
    },
    {
      "x": -2,
      "y": -2,
      "z": 1,
      "name": "Wood_Burnt_Roots"
    },
    {
      "x": -2,
      "y": -1,
      "z": 1,
      "name": "Necrotic_Sand"
    },
    {
      "x": -2,
      "y": 0,
      "z": 1,
      "name": "Necrotic_Sand"
    },
    {
      "x": -2,
      "y": 1,
      "z": 1,
      "name": "Necrotic_Sand"
    },
    {
      "x": -2,
      "y": 2,
      "z": 1,
      "name": "Necrotic_Sand"
    },
    {
      "x": -2,
      "y": 3,
      "z": 1,
      "name": "Necrotic_Sand"
    },
    {
      "x": -2,
      "y": 4,
      "z": 1,
      "name": "Necrotic_Sand"
    },
    {
      "x": -2,
      "y": 5,
      "z": 1,
      "name": "Necrotic_Sand"
    },
    {
      "x": -2,
      "y": 6,
      "z": 1,
      "name": "Rubble_Slate",
      "support": 15
    },
    {
      "x": -2,
      "y": 7,
      "z": 1,
      "name": "Plant_Vine_Wall_Poisoned",
      "support": 15,
      "rotation": 3
    },
    {
      "x": -2,
      "y": -3,
      "z": 2,
      "name": "Wood_Burnt_Roots"
    },
    {
      "x": -2,
      "y": -2,
      "z": 2,
      "name": "Necrotic_Sand"
    },
    {
      "x": -2,
      "y": -1,
      "z": 2,
      "name": "Necrotic_Sand"
    },
    {
      "x": -2,
      "y": 0,
      "z": 2,
      "name": "Necrotic_Sand"
    },
    {
      "x": -2,
      "y": 1,
      "z": 2,
      "name": "Necrotic_Sand"
    },
    {
      "x": -2,
      "y": 2,
      "z": 2,
      "name": "Necrotic_Sand"
    },
    {
      "x": -2,
      "y": 3,
      "z": 2,
      "name": "Necrotic_Sand"
    },
    {
      "x": -2,
      "y": 4,
      "z": 2,
      "name": "Plant_Crop_Mushroom_Flatcap_Green",
      "components": {
        "Components": {
          "FarmingBlock": {
            "LastTickGameTime": "0001-01-01T12:00:00Z"
          },
          "PlacedByInteraction": {
            "WhoPlacedUuid": {
              "$binary": "bJ0Z/pHxT/WyhVA6z1mjfg==",
              "$type": "04"
            }
          }
        }
      }
    },
    {
      "x": -2,
      "y": 5,
      "z": 2,
      "name": "Plant_Vine_Wall_Dead",
      "support": 15,
      "rotation": 3
    },
    {
      "x": -2,
      "y": -1,
      "z": 3,
      "name": "Necrotic_Sand"
    },
    {
      "x": -2,
      "y": 0,
      "z": 3,
      "name": "Necrotic_Sand"
    },
    {
      "x": -2,
      "y": 1,
      "z": 3,
      "name": "Necrotic_Sand"
    },
    {
      "x": -2,
      "y": 2,
      "z": 3,
      "name": "Necrotic_Sand"
    },
    {
      "x": -2,
      "y": 3,
      "z": 3,
      "name": "Necrotic_Sand"
    },
    {
      "x": -2,
      "y": 4,
      "z": 3,
      "name": "Rock_Slate_Stalactite_Small"
    },
    {
      "x": -2,
      "y": 0,
      "z": 4,
      "name": "Necrotic_Sand"
    },
    {
      "x": -2,
      "y": 1,
      "z": 4,
      "name": "Necrotic_Sand"
    },
    {
      "x": -2,
      "y": 2,
      "z": 4,
      "name": "Plant_Vine_Wall_Poisoned",
      "support": 15,
      "rotation": 3
    },
    {
      "x": -2,
      "y": 3,
      "z": 4,
      "name": "Plant_Vine_Wall_Dead",
      "support": 15
    },
    {
      "x": -1,
      "y": -1,
      "z": -3,
      "name": "Necrotic_Sand"
    },
    {
      "x": -1,
      "y": 0,
      "z": -3,
      "name": "Necrotic_Sand"
    },
    {
      "x": -1,
      "y": -2,
      "z": -2,
      "name": "Wood_Burnt_Roots"
    },
    {
      "x": -1,
      "y": -1,
      "z": -2,
      "name": "Necrotic_Sand"
    },
    {
      "x": -1,
      "y": 0,
      "z": -2,
      "name": "Necrotic_Sand"
    },
    {
      "x": -1,
      "y": 1,
      "z": -2,
      "name": "Necrotic_Sand"
    },
    {
      "x": -1,
      "y": 2,
      "z": -2,
      "name": "Rock_Slate_Stalactite_Large"
    },
    {
      "x": -1,
      "y": 3,
      "z": -2,
      "name": "Rock_Slate_Stalactite_Large",
      "filler": 1024
    },
    {
      "x": -1,
      "y": 4,
      "z": -2,
      "name": "Plant_Vine_Wall_Poisoned",
      "support": 15,
      "rotation": 2
    },
    {
      "x": -1,
      "y": -2,
      "z": -1,
      "name": "Necrotic_Sand"
    },
    {
      "x": -1,
      "y": -1,
      "z": -1,
      "name": "Necrotic_Sand"
    },
    {
      "x": -1,
      "y": 0,
      "z": -1,
      "name": "Necrotic_Sand"
    },
    {
      "x": -1,
      "y": 1,
      "z": -1,
      "name": "Necrotic_Sand"
    },
    {
      "x": -1,
      "y": 2,
      "z": -1,
      "name": "Necrotic_Sand"
    },
    {
      "x": -1,
      "y": 3,
      "z": -1,
      "name": "Necrotic_Sand"
    },
    {
      "x": -1,
      "y": 4,
      "z": -1,
      "name": "Necrotic_Sand"
    },
    {
      "x": -1,
      "y": 5,
      "z": -1,
      "name": "Rock_Slate_Stalactite_Small"
    },
    {
      "x": -1,
      "y": 6,
      "z": -1,
      "name": "Plant_Vine_Wall_Dead",
      "support": 15,
      "rotation": 3
    },
    {
      "x": -1,
      "y": 7,
      "z": -1,
      "name": "Plant_Vine_Wall_Poisoned",
      "support": 15,
      "rotation": 2
    },
    {
      "x": -1,
      "y": -3,
      "z": 0,
      "name": "Necrotic_Sand"
    },
    {
      "x": -1,
      "y": -2,
      "z": 0,
      "name": "Necrotic_Sand"
    },
    {
      "x": -1,
      "y": -1,
      "z": 0,
      "name": "Necrotic_Sand"
    },
    {
      "x": -1,
      "y": 0,
      "z": 0,
      "name": "Necrotic_Sand"
    },
    {
      "x": -1,
      "y": 1,
      "z": 0,
      "name": "Necrotic_Sand"
    },
    {
      "x": -1,
      "y": 2,
      "z": 0,
      "name": "Necrotic_Sand"
    },
    {
      "x": -1,
      "y": 3,
      "z": 0,
      "name": "Necrotic_Sand"
    },
    {
      "x": -1,
      "y": 4,
      "z": 0,
      "name": "Necrotic_Sand"
    },
    {
      "x": -1,
      "y": 5,
      "z": 0,
      "name": "Necrotic_Sand"
    },
    {
      "x": -1,
      "y": 6,
      "z": 0,
      "name": "Necrotic_Sand"
    },
    {
      "x": -1,
      "y": 7,
      "z": 0,
      "name": "Necrotic_Sand"
    },
    {
      "x": -1,
      "y": 8,
      "z": 0,
      "name": "Rock_Slate_Stalactite_Small"
    },
    {
      "x": -1,
      "y": -2,
      "z": 1,
      "name": "Necrotic_Sand"
    },
    {
      "x": -1,
      "y": -1,
      "z": 1,
      "name": "Necrotic_Sand"
    },
    {
      "x": -1,
      "y": 0,
      "z": 1,
      "name": "Necrotic_Sand"
    },
    {
      "x": -1,
      "y": 1,
      "z": 1,
      "name": "Necrotic_Sand"
    },
    {
      "x": -1,
      "y": 2,
      "z": 1,
      "name": "Necrotic_Sand"
    },
    {
      "x": -1,
      "y": 3,
      "z": 1,
      "name": "Necrotic_Sand"
    },
    {
      "x": -1,
      "y": 4,
      "z": 1,
      "name": "Necrotic_Sand"
    },
    {
      "x": -1,
      "y": 5,
      "z": 1,
      "name": "Necrotic_Sand"
    },
    {
      "x": -1,
      "y": 6,
      "z": 1,
      "name": "Necrotic_Sand"
    },
    {
      "x": -1,
      "y": 7,
      "z": 1,
      "name": "Necrotic_Sand"
    },
    {
      "x": -1,
      "y": 8,
      "z": 1,
      "name": "Plant_Bush_Winter",
      "support": 15
    },
    {
      "x": -1,
      "y": 9,
      "z": 1,
      "name": "Plant_Vine_Wall_Poisoned",
      "support": 15,
      "rotation": 3
    },
    {
      "x": -1,
      "y": 10,
      "z": 1,
      "name": "Plant_Vine_Wall_Dead",
      "support": 15,
      "rotation": 3
    },
    {
      "x": -1,
      "y": -3,
      "z": 2,
      "name": "Necrotic_Sand"
    },
    {
      "x": -1,
      "y": -2,
      "z": 2,
      "name": "Necrotic_Sand"
    },
    {
      "x": -1,
      "y": -1,
      "z": 2,
      "name": "Necrotic_Sand"
    },
    {
      "x": -1,
      "y": 0,
      "z": 2,
      "name": "Necrotic_Sand"
    },
    {
      "x": -1,
      "y": 1,
      "z": 2,
      "name": "Necrotic_Sand"
    },
    {
      "x": -1,
      "y": 2,
      "z": 2,
      "name": "Necrotic_Sand"
    },
    {
      "x": -1,
      "y": 3,
      "z": 2,
      "name": "Necrotic_Sand"
    },
    {
      "x": -1,
      "y": 4,
      "z": 2,
      "name": "Necrotic_Sand"
    },
    {
      "x": -1,
      "y": 5,
      "z": 2,
      "name": "Necrotic_Sand"
    },
    {
      "x": -1,
      "y": 6,
      "z": 2,
      "name": "Plant_Vine_Wall_Dead",
      "support": 15
    },
    {
      "x": -1,
      "y": 7,
      "z": 2,
      "name": "Plant_Vine_Wall_Poisoned",
      "support": 15
    },
    {
      "x": -1,
      "y": 8,
      "z": 2,
      "name": "Plant_Vine_Wall_Dead",
      "support": 15,
      "rotation": 3
    },
    {
      "x": -1,
      "y": -3,
      "z": 3,
      "name": "Wood_Burnt_Roots"
    },
    {
      "x": -1,
      "y": -2,
      "z": 3,
      "name": "Necrotic_Sand"
    },
    {
      "x": -1,
      "y": -1,
      "z": 3,
      "name": "Necrotic_Sand"
    },
    {
      "x": -1,
      "y": 0,
      "z": 3,
      "name": "Necrotic_Sand"
    },
    {
      "x": -1,
      "y": 1,
      "z": 3,
      "name": "Necrotic_Sand"
    },
    {
      "x": -1,
      "y": 2,
      "z": 3,
      "name": "Necrotic_Sand"
    },
    {
      "x": -1,
      "y": 3,
      "z": 3,
      "name": "Necrotic_Sand"
    },
    {
      "x": -1,
      "y": 4,
      "z": 3,
      "name": "Rock_Slate_Stalactite_Large"
    },
    {
      "x": -1,
      "y": 5,
      "z": 3,
      "name": "Rock_Slate_Stalactite_Large",
      "filler": 1024
    },
    {
      "x": -1,
      "y": -1,
      "z": 4,
      "name": "Necrotic_Sand"
    },
    {
      "x": -1,
      "y": 0,
      "z": 4,
      "name": "Necrotic_Sand"
    },
    {
      "x": -1,
      "y": 1,
      "z": 4,
      "name": "Necrotic_Sand"
    },
    {
      "x": -1,
      "y": 2,
      "z": 4,
      "name": "Necrotic_Sand"
    },
    {
      "x": -1,
      "y": 3,
      "z": 4,
      "name": "Rubble_Slate_Medium",
      "support": 15
    },
    {
      "x": 0,
      "y": -2,
      "z": -3,
      "name": "Wood_Burnt_Roots"
    },
    {
      "x": 0,
      "y": -1,
      "z": -3,
      "name": "Necrotic_Sand"
    },
    {
      "x": 0,
      "y": 0,
      "z": -3,
      "name": "Necrotic_Sand"
    },
    {
      "x": 0,
      "y": 1,
      "z": -3,
      "name": "Prickly_Bush"
    },
    {
      "x": 0,
      "y": 3,
      "z": -3,
      "name": "Plant_Vine_Wall_Dead",
      "support": 15,
      "rotation": 2
    },
    {
      "x": 0,
      "y": 4,
      "z": -3,
      "name": "Plant_Vine_Wall_Poisoned",
      "support": 15,
      "rotation": 2
    },
    {
      "x": 0,
      "y": -2,
      "z": -2,
      "name": "Necrotic_Sand"
    },
    {
      "x": 0,
      "y": -1,
      "z": -2,
      "name": "Necrotic_Sand"
    },
    {
      "x": 0,
      "y": 0,
      "z": -2,
      "name": "Necrotic_Sand"
    },
    {
      "x": 0,
      "y": 1,
      "z": -2,
      "name": "Necrotic_Sand"
    },
    {
      "x": 0,
      "y": 2,
      "z": -2,
      "name": "Necrotic_Sand"
    },
    {
      "x": 0,
      "y": 3,
      "z": -2,
      "name": "Necrotic_Sand"
    },
    {
      "x": 0,
      "y": 4,
      "z": -2,
      "name": "Necrotic_Sand"
    },
    {
      "x": 0,
      "y": 5,
      "z": -2,
      "name": "Rock_Slate_Stalactite_Small"
    },
    {
      "x": 0,
      "y": -3,
      "z": -1,
      "name": "Necrotic_Sand"
    },
    {
      "x": 0,
      "y": -2,
      "z": -1,
      "name": "Necrotic_Sand"
    },
    {
      "x": 0,
      "y": -1,
      "z": -1,
      "name": "Necrotic_Sand"
    },
    {
      "x": 0,
      "y": 0,
      "z": -1,
      "name": "Necrotic_Sand"
    },
    {
      "x": 0,
      "y": 1,
      "z": -1,
      "name": "Necrotic_Sand"
    },
    {
      "x": 0,
      "y": 2,
      "z": -1,
      "name": "Necrotic_Sand"
    },
    {
      "x": 0,
      "y": 3,
      "z": -1,
      "name": "Necrotic_Sand"
    },
    {
      "x": 0,
      "y": 4,
      "z": -1,
      "name": "Necrotic_Sand"
    },
    {
      "x": 0,
      "y": 5,
      "z": -1,
      "name": "Necrotic_Sand"
    },
    {
      "x": 0,
      "y": 6,
      "z": -1,
      "name": "Necrotic_Sand"
    },
    {
      "x": 0,
      "y": 7,
      "z": -1,
      "name": "Rock_Slate_Stalactite_Small"
    },
    {
      "x": 0,
      "y": 8,
      "z": -1,
      "name": "Plant_Vine_Wall_Poisoned",
      "support": 15,
      "rotation": 2
    },
    {
      "x": 0,
      "y": -5,
      "z": 0,
      "name": "Necrotic_Sand"
    },
    {
      "x": 0,
      "y": -4,
      "z": 0,
      "name": "Necrotic_Sand"
    },
    {
      "x": 0,
      "y": -3,
      "z": 0,
      "name": "Necrotic_Sand"
    },
    {
      "x": 0,
      "y": -2,
      "z": 0,
      "name": "Necrotic_Sand"
    },
    {
      "x": 0,
      "y": -1,
      "z": 0,
      "name": "Necrotic_Sand"
    },
    {
      "x": 0,
      "y": 0,
      "z": 0,
      "name": "Necrotic_Sand"
    },
    {
      "x": 0,
      "y": 1,
      "z": 0,
      "name": "Necrotic_Sand"
    },
    {
      "x": 0,
      "y": 2,
      "z": 0,
      "name": "Necrotic_Sand"
    },
    {
      "x": 0,
      "y": 3,
      "z": 0,
      "name": "Necrotic_Sand"
    },
    {
      "x": 0,
      "y": 4,
      "z": 0,
      "name": "Necrotic_Sand"
    },
    {
      "x": 0,
      "y": 5,
      "z": 0,
      "name": "Necrotic_Sand"
    },
    {
      "x": 0,
      "y": 6,
      "z": 0,
      "name": "Necrotic_Sand"
    },
    {
      "x": 0,
      "y": 7,
      "z": 0,
      "name": "Necrotic_Sand"
    },
    {
      "x": 0,
      "y": 8,
      "z": 0,
      "name": "Necrotic_Sand"
    },
    {
      "x": 0,
      "y": 9,
      "z": 0,
      "name": "Rock_Slate_Stalactite_Small"
    },
    {
      "x": 0,
      "y": -3,
      "z": 1,
      "name": "Wood_Burnt_Roots"
    },
    {
      "x": 0,
      "y": -2,
      "z": 1,
      "name": "Necrotic_Sand"
    },
    {
      "x": 0,
      "y": -1,
      "z": 1,
      "name": "Necrotic_Sand"
    },
    {
      "x": 0,
      "y": 0,
      "z": 1,
      "name": "Necrotic_Sand"
    },
    {
      "x": 0,
      "y": 1,
      "z": 1,
      "name": "Necrotic_Sand"
    },
    {
      "x": 0,
      "y": 2,
      "z": 1,
      "name": "Necrotic_Sand"
    },
    {
      "x": 0,
      "y": 3,
      "z": 1,
      "name": "Necrotic_Sand"
    },
    {
      "x": 0,
      "y": 4,
      "z": 1,
      "name": "Necrotic_Sand"
    },
    {
      "x": 0,
      "y": 5,
      "z": 1,
      "name": "Necrotic_Sand"
    },
    {
      "x": 0,
      "y": 6,
      "z": 1,
      "name": "Necrotic_Sand"
    },
    {
      "x": 0,
      "y": 7,
      "z": 1,
      "name": "Necrotic_Sand"
    },
    {
      "x": 0,
      "y": 8,
      "z": 1,
      "name": "Necrotic_Sand"
    },
    {
      "x": 0,
      "y": 9,
      "z": 1,
      "name": "Necrotic_Sand"
    },
    {
      "x": 0,
      "y": 10,
      "z": 1,
      "name": "Necrotic_Sand"
    },
    {
      "x": 0,
      "y": 11,
      "z": 1,
      "name": "Rock_Slate_Stalactite_Large"
    },
    {
      "x": 0,
      "y": 12,
      "z": 1,
      "name": "Rock_Slate_Stalactite_Large",
      "filler": 1024
    },
    {
      "x": 0,
      "y": 14,
      "z": 1,
      "name": "Plant_Vine_Wall_Dead",
      "support": 15,
      "rotation": 3
    },
    {
      "x": 0,
      "y": -3,
      "z": 2,
      "name": "Necrotic_Sand"
    },
    {
      "x": 0,
      "y": -2,
      "z": 2,
      "name": "Necrotic_Sand"
    },
    {
      "x": 0,
      "y": -1,
      "z": 2,
      "name": "Necrotic_Sand"
    },
    {
      "x": 0,
      "y": 0,
      "z": 2,
      "name": "Necrotic_Sand"
    },
    {
      "x": 0,
      "y": 1,
      "z": 2,
      "name": "Necrotic_Sand"
    },
    {
      "x": 0,
      "y": 2,
      "z": 2,
      "name": "Necrotic_Sand"
    },
    {
      "x": 0,
      "y": 3,
      "z": 2,
      "name": "Necrotic_Sand"
    },
    {
      "x": 0,
      "y": 4,
      "z": 2,
      "name": "Necrotic_Sand"
    },
    {
      "x": 0,
      "y": 5,
      "z": 2,
      "name": "Necrotic_Sand"
    },
    {
      "x": 0,
      "y": 6,
      "z": 2,
      "name": "Necrotic_Sand"
    },
    {
      "x": 0,
      "y": 7,
      "z": 2,
      "name": "Necrotic_Sand"
    },
    {
      "x": 0,
      "y": 8,
      "z": 2,
      "name": "Necrotic_Sand"
    },
    {
      "x": 0,
      "y": 9,
      "z": 2,
      "name": "Rock_Slate_Stalactite_Large"
    },
    {
      "x": 0,
      "y": 10,
      "z": 2,
      "name": "Rock_Slate_Stalactite_Large",
      "filler": 1024
    },
    {
      "x": 0,
      "y": -4,
      "z": 3,
      "name": "Necrotic_Sand"
    },
    {
      "x": 0,
      "y": -3,
      "z": 3,
      "name": "Necrotic_Sand"
    },
    {
      "x": 0,
      "y": -2,
      "z": 3,
      "name": "Necrotic_Sand"
    },
    {
      "x": 0,
      "y": -1,
      "z": 3,
      "name": "Necrotic_Sand"
    },
    {
      "x": 0,
      "y": 0,
      "z": 3,
      "name": "Necrotic_Sand"
    },
    {
      "x": 0,
      "y": 1,
      "z": 3,
      "name": "Necrotic_Sand"
    },
    {
      "x": 0,
      "y": 2,
      "z": 3,
      "name": "Necrotic_Sand"
    },
    {
      "x": 0,
      "y": 3,
      "z": 3,
      "name": "Necrotic_Sand"
    },
    {
      "x": 0,
      "y": 4,
      "z": 3,
      "name": "Necrotic_Sand"
    },
    {
      "x": 0,
      "y": 5,
      "z": 3,
      "name": "Necrotic_Sand"
    },
    {
      "x": 0,
      "y": 6,
      "z": 3,
      "name": "Rubble_Slate_Medium",
      "support": 15
    },
    {
      "x": 0,
      "y": 7,
      "z": 3,
      "name": "Plant_Vine_Wall_Poisoned",
      "support": 15
    },
    {
      "x": 0,
      "y": 8,
      "z": 3,
      "name": "Plant_Vine_Wall_Poisoned",
      "support": 15
    },
    {
      "x": 0,
      "y": -1,
      "z": 4,
      "name": "Necrotic_Sand"
    },
    {
      "x": 0,
      "y": 0,
      "z": 4,
      "name": "Necrotic_Sand"
    },
    {
      "x": 0,
      "y": 1,
      "z": 4,
      "name": "Necrotic_Sand"
    },
    {
      "x": 0,
      "y": 2,
      "z": 4,
      "name": "Necrotic_Sand"
    },
    {
      "x": 0,
      "y": 3,
      "z": 4,
      "name": "Necrotic_Sand"
    },
    {
      "x": 0,
      "y": 4,
      "z": 4,
      "name": "Necrotic_Sand"
    },
    {
      "x": 0,
      "y": 5,
      "z": 4,
      "name": "Rubble_Slate",
      "support": 15
    },
    {
      "x": 1,
      "y": -1,
      "z": -3,
      "name": "Necrotic_Sand"
    },
    {
      "x": 1,
      "y": 0,
      "z": -3,
      "name": "Necrotic_Sand"
    },
    {
      "x": 1,
      "y": 1,
      "z": -3,
      "name": "Necrotic_Sand"
    },
    {
      "x": 1,
      "y": 2,
      "z": -3,
      "name": "Plant_Bush_Winter",
      "support": 15
    },
    {
      "x": 1,
      "y": 3,
      "z": -3,
      "name": "Plant_Vine_Wall_Dead",
      "support": 15,
      "rotation": 2
    },
    {
      "x": 1,
      "y": -3,
      "z": -2,
      "name": "Wood_Burnt_Roots"
    },
    {
      "x": 1,
      "y": -2,
      "z": -2,
      "name": "Necrotic_Sand"
    },
    {
      "x": 1,
      "y": -1,
      "z": -2,
      "name": "Necrotic_Sand"
    },
    {
      "x": 1,
      "y": 0,
      "z": -2,
      "name": "Necrotic_Sand"
    },
    {
      "x": 1,
      "y": 1,
      "z": -2,
      "name": "Necrotic_Sand"
    },
    {
      "x": 1,
      "y": 2,
      "z": -2,
      "name": "Necrotic_Sand"
    },
    {
      "x": 1,
      "y": 3,
      "z": -2,
      "name": "Necrotic_Sand"
    },
    {
      "x": 1,
      "y": 4,
      "z": -2,
      "name": "Rubble_Slate_Medium",
      "support": 15
    },
    {
      "x": 1,
      "y": 6,
      "z": -2,
      "name": "Plant_Vine_Wall_Poisoned",
      "support": 15,
      "rotation": 2
    },
    {
      "x": 1,
      "y": -2,
      "z": -1,
      "name": "Necrotic_Sand"
    },
    {
      "x": 1,
      "y": -1,
      "z": -1,
      "name": "Necrotic_Sand"
    },
    {
      "x": 1,
      "y": 0,
      "z": -1,
      "name": "Necrotic_Sand"
    },
    {
      "x": 1,
      "y": 1,
      "z": -1,
      "name": "Necrotic_Sand"
    },
    {
      "x": 1,
      "y": 2,
      "z": -1,
      "name": "Necrotic_Sand"
    },
    {
      "x": 1,
      "y": 3,
      "z": -1,
      "name": "Necrotic_Sand"
    },
    {
      "x": 1,
      "y": 4,
      "z": -1,
      "name": "Necrotic_Sand"
    },
    {
      "x": 1,
      "y": 5,
      "z": -1,
      "name": "Necrotic_Sand"
    },
    {
      "x": 1,
      "y": 6,
      "z": -1,
      "name": "Necrotic_Sand"
    },
    {
      "x": 1,
      "y": 7,
      "z": -1,
      "name": "Plant_Bush_Winter",
      "support": 15
    },
    {
      "x": 1,
      "y": 8,
      "z": -1,
      "name": "Plant_Vine_Wall_Dead",
      "support": 15,
      "rotation": 2
    },
    {
      "x": 1,
      "y": 10,
      "z": -1,
      "name": "Plant_Vine_Wall_Poisoned",
      "support": 15,
      "rotation": 2
    },
    {
      "x": 1,
      "y": 11,
      "z": -1,
      "name": "Plant_Vine_Wall_Poisoned",
      "support": 15,
      "rotation": 2
    },
    {
      "x": 1,
      "y": -2,
      "z": 0,
      "name": "Necrotic_Sand"
    },
    {
      "x": 1,
      "y": -1,
      "z": 0,
      "name": "Necrotic_Sand"
    },
    {
      "x": 1,
      "y": 0,
      "z": 0,
      "name": "Necrotic_Sand"
    },
    {
      "x": 1,
      "y": 1,
      "z": 0,
      "name": "Necrotic_Sand"
    },
    {
      "x": 1,
      "y": 2,
      "z": 0,
      "name": "Necrotic_Sand"
    },
    {
      "x": 1,
      "y": 3,
      "z": 0,
      "name": "Necrotic_Sand"
    },
    {
      "x": 1,
      "y": 4,
      "z": 0,
      "name": "Necrotic_Sand"
    },
    {
      "x": 1,
      "y": 5,
      "z": 0,
      "name": "Necrotic_Sand"
    },
    {
      "x": 1,
      "y": 6,
      "z": 0,
      "name": "Necrotic_Sand"
    },
    {
      "x": 1,
      "y": 7,
      "z": 0,
      "name": "Necrotic_Crystal"
    },
    {
      "x": 1,
      "y": 8,
      "z": 0,
      "name": "Necrotic_Sand"
    },
    {
      "x": 1,
      "y": 9,
      "z": 0,
      "name": "Necrotic_Sand"
    },
    {
      "x": 1,
      "y": 10,
      "z": 0,
      "name": "Necrotic_Sand"
    },
    {
      "x": 1,
      "y": 11,
      "z": 0,
      "name": "Necrotic_Sand"
    },
    {
      "x": 1,
      "y": 12,
      "z": 0,
      "name": "Plant_Crop_Mushroom_Flatcap_Green",
      "components": {
        "Components": {
          "FarmingBlock": {
            "LastTickGameTime": "0001-01-01T12:00:00Z"
          },
          "PlacedByInteraction": {
            "WhoPlacedUuid": {
              "$binary": "bJ0Z/pHxT/WyhVA6z1mjfg==",
              "$type": "04"
            }
          }
        }
      }
    },
    {
      "x": 1,
      "y": 13,
      "z": 0,
      "name": "Plant_Vine_Wall_Dead",
      "support": 15,
      "rotation": 2
    },
    {
      "x": 1,
      "y": 14,
      "z": 0,
      "name": "Plant_Vine_Wall_Poisoned",
      "support": 15,
      "rotation": 2
    },
    {
      "x": 1,
      "y": -3,
      "z": 1,
      "name": "Wood_Burnt_Roots"
    },
    {
      "x": 1,
      "y": -2,
      "z": 1,
      "name": "Necrotic_Sand"
    },
    {
      "x": 1,
      "y": -1,
      "z": 1,
      "name": "Necrotic_Sand"
    },
    {
      "x": 1,
      "y": 0,
      "z": 1,
      "name": "Necrotic_Sand"
    },
    {
      "x": 1,
      "y": 1,
      "z": 1,
      "name": "Necrotic_Sand"
    },
    {
      "x": 1,
      "y": 2,
      "z": 1,
      "name": "Necrotic_Sand"
    },
    {
      "x": 1,
      "y": 3,
      "z": 1,
      "name": "Necrotic_Sand"
    },
    {
      "x": 1,
      "y": 4,
      "z": 1,
      "name": "Necrotic_Sand"
    },
    {
      "x": 1,
      "y": 5,
      "z": 1,
      "name": "Necrotic_Sand"
    },
    {
      "x": 1,
      "y": 6,
      "z": 1,
      "name": "Necrotic_Sand"
    },
    {
      "x": 1,
      "y": 7,
      "z": 1,
      "name": "Necrotic_Sand"
    },
    {
      "x": 1,
      "y": 8,
      "z": 1,
      "name": "Necrotic_Sand"
    },
    {
      "x": 1,
      "y": 9,
      "z": 1,
      "name": "Necrotic_Sand"
    },
    {
      "x": 1,
      "y": 10,
      "z": 1,
      "name": "Necrotic_Sand"
    },
    {
      "x": 1,
      "y": 11,
      "z": 1,
      "name": "Necrotic_Sand"
    },
    {
      "x": 1,
      "y": 12,
      "z": 1,
      "name": "Necrotic_Sand"
    },
    {
      "x": 1,
      "y": 13,
      "z": 1,
      "name": "Necrotic_Sand"
    },
    {
      "x": 1,
      "y": 14,
      "z": 1,
      "name": "Necrotic_Sand"
    },
    {
      "x": 1,
      "y": 15,
      "z": 1,
      "name": "Rock_Slate_Stalactite_Large"
    },
    {
      "x": 1,
      "y": 16,
      "z": 1,
      "name": "Rock_Slate_Stalactite_Large",
      "filler": 1024
    },
    {
      "x": 1,
      "y": -2,
      "z": 2,
      "name": "Necrotic_Sand"
    },
    {
      "x": 1,
      "y": -1,
      "z": 2,
      "name": "Necrotic_Sand"
    },
    {
      "x": 1,
      "y": 0,
      "z": 2,
      "name": "Necrotic_Sand"
    },
    {
      "x": 1,
      "y": 1,
      "z": 2,
      "name": "Necrotic_Sand"
    },
    {
      "x": 1,
      "y": 2,
      "z": 2,
      "name": "Necrotic_Sand"
    },
    {
      "x": 1,
      "y": 3,
      "z": 2,
      "name": "Necrotic_Sand"
    },
    {
      "x": 1,
      "y": 4,
      "z": 2,
      "name": "Necrotic_Sand"
    },
    {
      "x": 1,
      "y": 5,
      "z": 2,
      "name": "Necrotic_Sand"
    },
    {
      "x": 1,
      "y": 6,
      "z": 2,
      "name": "Necrotic_Sand"
    },
    {
      "x": 1,
      "y": 7,
      "z": 2,
      "name": "Necrotic_Sand"
    },
    {
      "x": 1,
      "y": 8,
      "z": 2,
      "name": "Necrotic_Sand"
    },
    {
      "x": 1,
      "y": 9,
      "z": 2,
      "name": "Necrotic_Sand"
    },
    {
      "x": 1,
      "y": 10,
      "z": 2,
      "name": "Rubble_Slate",
      "support": 15
    },
    {
      "x": 1,
      "y": 12,
      "z": 2,
      "name": "Plant_Vine_Wall_Poisoned",
      "support": 15
    },
    {
      "x": 1,
      "y": 13,
      "z": 2,
      "name": "Plant_Vine_Wall_Dead",
      "support": 15
    },
    {
      "x": 1,
      "y": 14,
      "z": 2,
      "name": "Plant_Vine_Wall_Poisoned",
      "support": 15
    },
    {
      "x": 1,
      "y": -2,
      "z": 3,
      "name": "Necrotic_Sand"
    },
    {
      "x": 1,
      "y": -1,
      "z": 3,
      "name": "Necrotic_Sand"
    },
    {
      "x": 1,
      "y": 0,
      "z": 3,
      "name": "Necrotic_Sand"
    },
    {
      "x": 1,
      "y": 1,
      "z": 3,
      "name": "Necrotic_Sand"
    },
    {
      "x": 1,
      "y": 2,
      "z": 3,
      "name": "Necrotic_Sand"
    },
    {
      "x": 1,
      "y": 3,
      "z": 3,
      "name": "Necrotic_Sand"
    },
    {
      "x": 1,
      "y": 4,
      "z": 3,
      "name": "Necrotic_Sand"
    },
    {
      "x": 1,
      "y": 5,
      "z": 3,
      "name": "Necrotic_Sand"
    },
    {
      "x": 1,
      "y": 6,
      "z": 3,
      "name": "Necrotic_Sand"
    },
    {
      "x": 1,
      "y": 7,
      "z": 3,
      "name": "Rock_Slate_Stalactite_Large"
    },
    {
      "x": 1,
      "y": 8,
      "z": 3,
      "name": "Rock_Slate_Stalactite_Large",
      "filler": 1024
    },
    {
      "x": 1,
      "y": 9,
      "z": 3,
      "name": "Plant_Vine_Wall_Poisoned",
      "support": 15
    },
    {
      "x": 1,
      "y": -2,
      "z": 4,
      "name": "Wood_Burnt_Roots"
    },
    {
      "x": 1,
      "y": -1,
      "z": 4,
      "name": "Necrotic_Sand"
    },
    {
      "x": 1,
      "y": 0,
      "z": 4,
      "name": "Necrotic_Sand"
    },
    {
      "x": 1,
      "y": 1,
      "z": 4,
      "name": "Necrotic_Sand"
    },
    {
      "x": 1,
      "y": 2,
      "z": 4,
      "name": "Necrotic_Sand"
    },
    {
      "x": 1,
      "y": 3,
      "z": 4,
      "name": "Necrotic_Sand"
    },
    {
      "x": 1,
      "y": 4,
      "z": 4,
      "name": "Plant_Bush_Winter",
      "support": 15
    },
    {
      "x": 1,
      "y": 5,
      "z": 4,
      "name": "Plant_Vine_Wall_Dead",
      "support": 15
    },
    {
      "x": 1,
      "y": 6,
      "z": 4,
      "name": "Plant_Vine_Wall_Poisoned",
      "support": 15
    },
    {
      "x": 2,
      "y": 1,
      "z": -3,
      "name": "Plant_Vine_Wall_Poisoned",
      "support": 15,
      "rotation": 1
    },
    {
      "x": 2,
      "y": 2,
      "z": -3,
      "name": "Plant_Vine_Wall_Dead",
      "support": 15,
      "rotation": 2
    },
    {
      "x": 2,
      "y": -2,
      "z": -2,
      "name": "Wood_Burnt_Roots"
    },
    {
      "x": 2,
      "y": -1,
      "z": -2,
      "name": "Necrotic_Sand"
    },
    {
      "x": 2,
      "y": 0,
      "z": -2,
      "name": "Necrotic_Sand"
    },
    {
      "x": 2,
      "y": 1,
      "z": -2,
      "name": "Necrotic_Sand"
    },
    {
      "x": 2,
      "y": 2,
      "z": -2,
      "name": "Necrotic_Sand"
    },
    {
      "x": 2,
      "y": 3,
      "z": -2,
      "name": "Rock_Slate_Stalactite_Large"
    },
    {
      "x": 2,
      "y": 4,
      "z": -2,
      "name": "Rock_Slate_Stalactite_Large",
      "filler": 1024
    },
    {
      "x": 2,
      "y": 5,
      "z": -2,
      "name": "Plant_Vine_Wall_Poisoned",
      "support": 15,
      "rotation": 2
    },
    {
      "x": 2,
      "y": -4,
      "z": -1,
      "name": "Necrotic_Sand"
    },
    {
      "x": 2,
      "y": -3,
      "z": -1,
      "name": "Necrotic_Sand"
    },
    {
      "x": 2,
      "y": -2,
      "z": -1,
      "name": "Necrotic_Sand"
    },
    {
      "x": 2,
      "y": -1,
      "z": -1,
      "name": "Necrotic_Sand"
    },
    {
      "x": 2,
      "y": 0,
      "z": -1,
      "name": "Necrotic_Sand"
    },
    {
      "x": 2,
      "y": 1,
      "z": -1,
      "name": "Necrotic_Sand"
    },
    {
      "x": 2,
      "y": 2,
      "z": -1,
      "name": "Necrotic_Sand"
    },
    {
      "x": 2,
      "y": 3,
      "z": -1,
      "name": "Necrotic_Sand"
    },
    {
      "x": 2,
      "y": 4,
      "z": -1,
      "name": "Necrotic_Sand"
    },
    {
      "x": 2,
      "y": 5,
      "z": -1,
      "name": "Necrotic_Sand"
    },
    {
      "x": 2,
      "y": 8,
      "z": -1,
      "name": "Plant_Vine_Wall_Dead",
      "support": 15,
      "rotation": 2
    },
    {
      "x": 2,
      "y": 9,
      "z": -1,
      "name": "Plant_Vine_Wall_Poisoned",
      "support": 15,
      "rotation": 2
    },
    {
      "x": 2,
      "y": 10,
      "z": -1,
      "name": "Plant_Vine_Wall_Dead",
      "support": 15,
      "rotation": 2
    },
    {
      "x": 2,
      "y": -4,
      "z": 0,
      "name": "Wood_Burnt_Roots"
    },
    {
      "x": 2,
      "y": -3,
      "z": 0,
      "name": "Necrotic_Sand"
    },
    {
      "x": 2,
      "y": -2,
      "z": 0,
      "name": "Necrotic_Sand"
    },
    {
      "x": 2,
      "y": -1,
      "z": 0,
      "name": "Necrotic_Sand"
    },
    {
      "x": 2,
      "y": 0,
      "z": 0,
      "name": "Necrotic_Sand"
    },
    {
      "x": 2,
      "y": 1,
      "z": 0,
      "name": "Necrotic_Sand"
    },
    {
      "x": 2,
      "y": 2,
      "z": 0,
      "name": "Necrotic_Sand"
    },
    {
      "x": 2,
      "y": 3,
      "z": 0,
      "name": "Necrotic_Sand"
    },
    {
      "x": 2,
      "y": 4,
      "z": 0,
      "name": "Necrotic_Sand"
    },
    {
      "x": 2,
      "y": 5,
      "z": 0,
      "name": "Necrotic_Sand"
    },
    {
      "x": 2,
      "y": 6,
      "z": 0,
      "name": "Necrotic_Sand"
    },
    {
      "x": 2,
      "y": 7,
      "z": 0,
      "name": "Necrotic_Sand"
    },
    {
      "x": 2,
      "y": 8,
      "z": 0,
      "name": "Necrotic_Sand"
    },
    {
      "x": 2,
      "y": 9,
      "z": 0,
      "name": "Necrotic_Sand"
    },
    {
      "x": 2,
      "y": 10,
      "z": 0,
      "name": "Necrotic_Sand"
    },
    {
      "x": 2,
      "y": 11,
      "z": 0,
      "name": "Plant_Bush_Winter",
      "support": 15
    },
    {
      "x": 2,
      "y": 12,
      "z": 0,
      "name": "Plant_Vine_Wall_Dead",
      "support": 15,
      "rotation": 2
    },
    {
      "x": 2,
      "y": -2,
      "z": 1,
      "name": "Necrotic_Sand"
    },
    {
      "x": 2,
      "y": -1,
      "z": 1,
      "name": "Necrotic_Sand"
    },
    {
      "x": 2,
      "y": 0,
      "z": 1,
      "name": "Necrotic_Sand"
    },
    {
      "x": 2,
      "y": 1,
      "z": 1,
      "name": "Necrotic_Sand"
    },
    {
      "x": 2,
      "y": 2,
      "z": 1,
      "name": "Necrotic_Sand"
    },
    {
      "x": 2,
      "y": 3,
      "z": 1,
      "name": "Necrotic_Sand"
    },
    {
      "x": 2,
      "y": 4,
      "z": 1,
      "name": "Necrotic_Sand"
    },
    {
      "x": 2,
      "y": 5,
      "z": 1,
      "name": "Necrotic_Sand"
    },
    {
      "x": 2,
      "y": 6,
      "z": 1,
      "name": "Necrotic_Sand"
    },
    {
      "x": 2,
      "y": 7,
      "z": 1,
      "name": "Necrotic_Sand"
    },
    {
      "x": 2,
      "y": 8,
      "z": 1,
      "name": "Necrotic_Sand"
    },
    {
      "x": 2,
      "y": 9,
      "z": 1,
      "name": "Necrotic_Sand"
    },
    {
      "x": 2,
      "y": 10,
      "z": 1,
      "name": "Necrotic_Sand"
    },
    {
      "x": 2,
      "y": 11,
      "z": 1,
      "name": "Necrotic_Sand"
    },
    {
      "x": 2,
      "y": 12,
      "z": 1,
      "name": "Necrotic_Sand"
    },
    {
      "x": 2,
      "y": 13,
      "z": 1,
      "name": "Prickly_Bush"
    },
    {
      "x": 2,
      "y": 14,
      "z": 1,
      "name": "Plant_Vine_Wall_Dead",
      "support": 15,
      "rotation": 1
    },
    {
      "x": 2,
      "y": -3,
      "z": 2,
      "name": "Wood_Burnt_Roots"
    },
    {
      "x": 2,
      "y": -2,
      "z": 2,
      "name": "Necrotic_Sand"
    },
    {
      "x": 2,
      "y": -1,
      "z": 2,
      "name": "Necrotic_Sand"
    },
    {
      "x": 2,
      "y": 0,
      "z": 2,
      "name": "Necrotic_Sand"
    },
    {
      "x": 2,
      "y": 1,
      "z": 2,
      "name": "Necrotic_Sand"
    },
    {
      "x": 2,
      "y": 2,
      "z": 2,
      "name": "Necrotic_Sand"
    },
    {
      "x": 2,
      "y": 3,
      "z": 2,
      "name": "Necrotic_Sand"
    },
    {
      "x": 2,
      "y": 4,
      "z": 2,
      "name": "Necrotic_Sand"
    },
    {
      "x": 2,
      "y": 5,
      "z": 2,
      "name": "Necrotic_Sand"
    },
    {
      "x": 2,
      "y": 6,
      "z": 2,
      "name": "Necrotic_Sand"
    },
    {
      "x": 2,
      "y": 7,
      "z": 2,
      "name": "Necrotic_Sand"
    },
    {
      "x": 2,
      "y": 8,
      "z": 2,
      "name": "Necrotic_Sand"
    },
    {
      "x": 2,
      "y": 9,
      "z": 2,
      "name": "Necrotic_Sand"
    },
    {
      "x": 2,
      "y": 10,
      "z": 2,
      "name": "Plant_Bush_Winter",
      "support": 15
    },
    {
      "x": 2,
      "y": 12,
      "z": 2,
      "name": "Plant_Vine_Wall_Poisoned",
      "support": 15
    },
    {
      "x": 2,
      "y": -3,
      "z": 3,
      "name": "Necrotic_Sand"
    },
    {
      "x": 2,
      "y": -2,
      "z": 3,
      "name": "Necrotic_Sand"
    },
    {
      "x": 2,
      "y": -1,
      "z": 3,
      "name": "Necrotic_Sand"
    },
    {
      "x": 2,
      "y": 0,
      "z": 3,
      "name": "Necrotic_Sand"
    },
    {
      "x": 2,
      "y": 1,
      "z": 3,
      "name": "Necrotic_Sand"
    },
    {
      "x": 2,
      "y": 2,
      "z": 3,
      "name": "Necrotic_Sand"
    },
    {
      "x": 2,
      "y": 3,
      "z": 3,
      "name": "Necrotic_Sand"
    },
    {
      "x": 2,
      "y": 4,
      "z": 3,
      "name": "Necrotic_Sand"
    },
    {
      "x": 2,
      "y": 5,
      "z": 3,
      "name": "Necrotic_Sand"
    },
    {
      "x": 2,
      "y": 6,
      "z": 3,
      "name": "Plant_Crop_Mushroom_Flatcap_Green",
      "components": {
        "Components": {
          "FarmingBlock": {
            "LastTickGameTime": "0001-01-01T12:00:00Z"
          },
          "PlacedByInteraction": {
            "WhoPlacedUuid": {
              "$binary": "bJ0Z/pHxT/WyhVA6z1mjfg==",
              "$type": "04"
            }
          }
        }
      }
    },
    {
      "x": 2,
      "y": 8,
      "z": 3,
      "name": "Plant_Vine_Wall_Poisoned",
      "support": 15
    },
    {
      "x": 2,
      "y": 9,
      "z": 3,
      "name": "Plant_Vine_Wall_Poisoned",
      "support": 15
    },
    {
      "x": 2,
      "y": -3,
      "z": 4,
      "name": "Wood_Burnt_Roots"
    },
    {
      "x": 2,
      "y": -2,
      "z": 4,
      "name": "Necrotic_Sand"
    },
    {
      "x": 2,
      "y": -1,
      "z": 4,
      "name": "Necrotic_Sand"
    },
    {
      "x": 2,
      "y": 0,
      "z": 4,
      "name": "Necrotic_Sand"
    },
    {
      "x": 2,
      "y": 1,
      "z": 4,
      "name": "Necrotic_Sand"
    },
    {
      "x": 2,
      "y": 2,
      "z": 4,
      "name": "Necrotic_Sand"
    },
    {
      "x": 2,
      "y": 3,
      "z": 4,
      "name": "Rock_Slate_Stalactite_Large"
    },
    {
      "x": 2,
      "y": 4,
      "z": 4,
      "name": "Rock_Slate_Stalactite_Large",
      "filler": 1024
    },
    {
      "x": 2,
      "y": 5,
      "z": 4,
      "name": "Plant_Vine_Wall_Poisoned",
      "support": 15
    },
    {
      "x": 3,
      "y": 0,
      "z": -2,
      "name": "Necrotic_Sand"
    },
    {
      "x": 3,
      "y": 1,
      "z": -2,
      "name": "Rock_Slate_Stalactite_Large"
    },
    {
      "x": 3,
      "y": 2,
      "z": -2,
      "name": "Rock_Slate_Stalactite_Large",
      "filler": 1024
    },
    {
      "x": 3,
      "y": 3,
      "z": -2,
      "name": "Plant_Vine_Wall_Poisoned",
      "support": 15,
      "rotation": 2
    },
    {
      "x": 3,
      "y": 0,
      "z": -1,
      "name": "Necrotic_Sand"
    },
    {
      "x": 3,
      "y": 1,
      "z": -1,
      "name": "Necrotic_Sand"
    },
    {
      "x": 3,
      "y": 2,
      "z": -1,
      "name": "Necrotic_Sand"
    },
    {
      "x": 3,
      "y": 3,
      "z": -1,
      "name": "Necrotic_Sand"
    },
    {
      "x": 3,
      "y": 4,
      "z": -1,
      "name": "Rock_Slate_Stalactite_Small"
    },
    {
      "x": 3,
      "y": 6,
      "z": -1,
      "name": "Plant_Vine_Wall_Poisoned",
      "support": 15,
      "rotation": 2
    },
    {
      "x": 3,
      "y": -2,
      "z": 0,
      "name": "Necrotic_Sand"
    },
    {
      "x": 3,
      "y": -1,
      "z": 0,
      "name": "Necrotic_Sand"
    },
    {
      "x": 3,
      "y": 0,
      "z": 0,
      "name": "Necrotic_Sand"
    },
    {
      "x": 3,
      "y": 1,
      "z": 0,
      "name": "Necrotic_Sand"
    },
    {
      "x": 3,
      "y": 2,
      "z": 0,
      "name": "Necrotic_Sand"
    },
    {
      "x": 3,
      "y": 3,
      "z": 0,
      "name": "Necrotic_Sand"
    },
    {
      "x": 3,
      "y": 4,
      "z": 0,
      "name": "Necrotic_Sand"
    },
    {
      "x": 3,
      "y": 5,
      "z": 0,
      "name": "Necrotic_Sand"
    },
    {
      "x": 3,
      "y": 6,
      "z": 0,
      "name": "Necrotic_Sand"
    },
    {
      "x": 3,
      "y": 7,
      "z": 0,
      "name": "Rock_Slate_Stalactite_Large"
    },
    {
      "x": 3,
      "y": 8,
      "z": 0,
      "name": "Rock_Slate_Stalactite_Large",
      "filler": 1024
    },
    {
      "x": 3,
      "y": 10,
      "z": 0,
      "name": "Plant_Vine_Wall_Poisoned",
      "support": 15,
      "rotation": 1
    },
    {
      "x": 3,
      "y": -3,
      "z": 1,
      "name": "Necrotic_Sand"
    },
    {
      "x": 3,
      "y": -2,
      "z": 1,
      "name": "Necrotic_Sand"
    },
    {
      "x": 3,
      "y": -1,
      "z": 1,
      "name": "Necrotic_Sand"
    },
    {
      "x": 3,
      "y": 0,
      "z": 1,
      "name": "Necrotic_Sand"
    },
    {
      "x": 3,
      "y": 1,
      "z": 1,
      "name": "Necrotic_Sand"
    },
    {
      "x": 3,
      "y": 2,
      "z": 1,
      "name": "Necrotic_Sand"
    },
    {
      "x": 3,
      "y": 3,
      "z": 1,
      "name": "Necrotic_Sand"
    },
    {
      "x": 3,
      "y": 4,
      "z": 1,
      "name": "Necrotic_Sand"
    },
    {
      "x": 3,
      "y": 5,
      "z": 1,
      "name": "Necrotic_Sand"
    },
    {
      "x": 3,
      "y": 6,
      "z": 1,
      "name": "Necrotic_Sand"
    },
    {
      "x": 3,
      "y": 7,
      "z": 1,
      "name": "Rock_Slate_Stalactite_Large"
    },
    {
      "x": 3,
      "y": 8,
      "z": 1,
      "name": "Rock_Slate_Stalactite_Large",
      "filler": 1024
    },
    {
      "x": 3,
      "y": 9,
      "z": 1,
      "name": "Plant_Vine_Wall_Poisoned",
      "support": 15,
      "rotation": 1
    },
    {
      "x": 3,
      "y": 11,
      "z": 1,
      "name": "Plant_Vine_Wall_Poisoned",
      "support": 15,
      "rotation": 1
    },
    {
      "x": 3,
      "y": 12,
      "z": 1,
      "name": "Plant_Vine_Wall_Dead",
      "support": 15,
      "rotation": 1
    },
    {
      "x": 3,
      "y": -4,
      "z": 2,
      "name": "Necrotic_Sand"
    },
    {
      "x": 3,
      "y": -3,
      "z": 2,
      "name": "Necrotic_Sand"
    },
    {
      "x": 3,
      "y": -2,
      "z": 2,
      "name": "Necrotic_Sand"
    },
    {
      "x": 3,
      "y": -1,
      "z": 2,
      "name": "Necrotic_Sand"
    },
    {
      "x": 3,
      "y": 0,
      "z": 2,
      "name": "Necrotic_Sand"
    },
    {
      "x": 3,
      "y": 1,
      "z": 2,
      "name": "Necrotic_Sand"
    },
    {
      "x": 3,
      "y": 2,
      "z": 2,
      "name": "Necrotic_Sand"
    },
    {
      "x": 3,
      "y": 3,
      "z": 2,
      "name": "Necrotic_Sand"
    },
    {
      "x": 3,
      "y": 4,
      "z": 2,
      "name": "Necrotic_Sand"
    },
    {
      "x": 3,
      "y": 5,
      "z": 2,
      "name": "Necrotic_Sand"
    },
    {
      "x": 3,
      "y": 6,
      "z": 2,
      "name": "Necrotic_Sand"
    },
    {
      "x": 3,
      "y": 7,
      "z": 2,
      "name": "Rubble_Slate_Medium",
      "support": 15
    },
    {
      "x": 3,
      "y": 8,
      "z": 2,
      "name": "Plant_Vine_Wall_Poisoned",
      "support": 15,
      "rotation": 1
    },
    {
      "x": 3,
      "y": 9,
      "z": 2,
      "name": "Plant_Vine_Wall_Poisoned",
      "support": 15,
      "rotation": 1
    },
    {
      "x": 3,
      "y": -2,
      "z": 3,
      "name": "Wood_Burnt_Roots"
    },
    {
      "x": 3,
      "y": -1,
      "z": 3,
      "name": "Necrotic_Sand"
    },
    {
      "x": 3,
      "y": 0,
      "z": 3,
      "name": "Necrotic_Sand"
    },
    {
      "x": 3,
      "y": 1,
      "z": 3,
      "name": "Necrotic_Sand"
    },
    {
      "x": 3,
      "y": 2,
      "z": 3,
      "name": "Necrotic_Sand"
    },
    {
      "x": 3,
      "y": 3,
      "z": 3,
      "name": "Necrotic_Sand"
    },
    {
      "x": 3,
      "y": 4,
      "z": 3,
      "name": "Plant_Bush_Winter",
      "support": 15
    },
    {
      "x": 3,
      "y": 0,
      "z": 4,
      "name": "Necrotic_Sand"
    },
    {
      "x": 3,
      "y": 1,
      "z": 4,
      "name": "Rubble_Slate",
      "support": 15
    },
    {
      "x": 3,
      "y": 2,
      "z": 4,
      "name": "Plant_Vine_Wall_Poisoned",
      "support": 15
    },
    {
      "x": 3,
      "y": 3,
      "z": 4,
      "name": "Plant_Vine_Wall_Dead",
      "support": 15
    },
    {
      "x": 4,
      "y": 0,
      "z": -1,
      "name": "Necrotic_Sand"
    },
    {
      "x": 4,
      "y": 1,
      "z": -1,
      "name": "Plant_Bush_Winter",
      "support": 15
    },
    {
      "x": 4,
      "y": 3,
      "z": -1,
      "name": "Plant_Vine_Wall_Poisoned",
      "support": 15,
      "rotation": 2
    },
    {
      "x": 4,
      "y": -2,
      "z": 0,
      "name": "Wood_Burnt_Roots"
    },
    {
      "x": 4,
      "y": -1,
      "z": 0,
      "name": "Necrotic_Sand"
    },
    {
      "x": 4,
      "y": 0,
      "z": 0,
      "name": "Necrotic_Sand"
    },
    {
      "x": 4,
      "y": 1,
      "z": 0,
      "name": "Necrotic_Sand"
    },
    {
      "x": 4,
      "y": 2,
      "z": 0,
      "name": "Necrotic_Sand"
    },
    {
      "x": 4,
      "y": 3,
      "z": 0,
      "name": "Necrotic_Sand"
    },
    {
      "x": 4,
      "y": 4,
      "z": 0,
      "name": "Rubble_Slate",
      "support": 15
    },
    {
      "x": 4,
      "y": 6,
      "z": 0,
      "name": "Plant_Vine_Wall_Dead",
      "support": 15,
      "rotation": 1
    },
    {
      "x": 4,
      "y": -1,
      "z": 1,
      "name": "Necrotic_Sand"
    },
    {
      "x": 4,
      "y": 0,
      "z": 1,
      "name": "Necrotic_Sand"
    },
    {
      "x": 4,
      "y": 1,
      "z": 1,
      "name": "Necrotic_Sand"
    },
    {
      "x": 4,
      "y": 2,
      "z": 1,
      "name": "Necrotic_Sand"
    },
    {
      "x": 4,
      "y": 3,
      "z": 1,
      "name": "Necrotic_Sand"
    },
    {
      "x": 4,
      "y": 4,
      "z": 1,
      "name": "Rock_Slate_Stalactite_Large"
    },
    {
      "x": 4,
      "y": 5,
      "z": 1,
      "name": "Rock_Slate_Stalactite_Large",
      "filler": 1024
    },
    {
      "x": 4,
      "y": 6,
      "z": 1,
      "name": "Plant_Vine_Wall_Dead",
      "support": 15,
      "rotation": 1
    },
    {
      "x": 4,
      "y": -1,
      "z": 2,
      "name": "Wood_Burnt_Roots"
    },
    {
      "x": 4,
      "y": 0,
      "z": 2,
      "name": "Necrotic_Sand"
    },
    {
      "x": 4,
      "y": 1,
      "z": 2,
      "name": "Necrotic_Sand"
    },
    {
      "x": 4,
      "y": 2,
      "z": 2,
      "name": "Necrotic_Sand"
    },
    {
      "x": 4,
      "y": 3,
      "z": 2,
      "name": "Rubble_Slate",
      "support": 15
    },
    {
      "x": 4,
      "y": 5,
      "z": 2,
      "name": "Plant_Vine_Wall_Dead",
      "support": 15,
      "rotation": 1
    },
    {
      "x": 4,
      "y": 6,
      "z": 2,
      "name": "Plant_Vine_Wall_Poisoned",
      "support": 15,
      "rotation": 1
    },
    {
      "x": 4,
      "y": 3,
      "z": 3,
      "name": "Plant_Vine_Wall_Poisoned",
      "support": 15,
      "rotation": 1
    }
  ]
}