{
  "version": 8,
  "blockIdVersion": 11,
  "anchorX": 0,
  "anchorY": 10,
  "anchorZ": -7,
  "blocks": [
    {
      "x": -9,
      "y": 8,
      "z": -1,
      "name": "Soil_Dirt"
    },
    {
      "x": -9,
      "y": 9,
      "z": -1,
      "name": "Soil_Dirt"
    },
    {
      "x": -9,
      "y": 7,
      "z": 0,
      "name": "Soil_Dirt"
    },
    {
      "x": -9,
      "y": 8,
      "z": 0,
      "name": "Soil_Dirt"
    },
    {
      "x": -9,
      "y": 9,
      "z": 0,
      "name": "Soil_Dirt"
    },
    {
      "x": -9,
      "y": 10,
      "z": 0,
      "name": "Soil_Grass"
    },
    {
      "x": -9,
      "y": 11,
      "z": 0,
      "name": "Rock_Slate_Brick_Decorative"
    },
    {
      "x": -9,
      "y": 12,
      "z": 0,
      "name": "Empty"
    },
    {
      "x": -9,
      "y": 13,
      "z": 0,
      "name": "Empty"
    },
    {
      "x": -9,
      "y": 7,
      "z": 1,
      "name": "Soil_Dirt"
    },
    {
      "x": -9,
      "y": 8,
      "z": 1,
      "name": "Soil_Dirt"
    },
    {
      "x": -9,
      "y": 9,
      "z": 1,
      "name": "Soil_Dirt"
    },
    {
      "x": -9,
      "y": 10,
      "z": 1,
      "name": "Soil_Grass"
    },
    {
      "x": -9,
      "y": 11,
      "z": 1,
      "name": "Rock_Slate_Brick_Decorative"
    },
    {
      "x": -9,
      "y": 12,
      "z": 1,
      "name": "Empty"
    },
    {
      "x": -9,
      "y": 13,
      "z": 1,
      "name": "Empty"
    },
    {
      "x": -9,
      "y": 14,
      "z": 1,
      "name": "Empty"
    },
    {
      "x": -9,
      "y": 7,
      "z": 2,
      "name": "Soil_Dirt"
    },
    {
      "x": -9,
      "y": 8,
      "z": 2,
      "name": "Soil_Dirt"
    },
    {
      "x": -9,
      "y": 9,
      "z": 2,
      "name": "Soil_Dirt"
    },
    {
      "x": -9,
      "y": 10,
      "z": 2,
      "name": "Soil_Grass"
    },
    {
      "x": -9,
      "y": 11,
      "z": 2,
      "name": "Rock_Slate_Brick_Decorative"
    },
    {
      "x": -9,
      "y": 12,
      "z": 2,
      "name": "Empty"
    },
    {
      "x": -9,
      "y": 13,
      "z": 2,
      "name": "Empty"
    },
    {
      "x": -9,
      "y": 14,
      "z": 2,
      "name": "Empty"
    },
    {
      "x": -9,
      "y": 15,
      "z": 2,
      "name": "Empty"
    },
    {
      "x": -9,
      "y": 8,
      "z": 3,
      "name": "Soil_Dirt"
    },
    {
      "x": -9,
      "y": 9,
      "z": 3,
      "name": "Soil_Dirt"
    },
    {
      "x": -9,
      "y": 10,
      "z": 3,
      "name": "Soil_Grass"
    },
    {
      "x": -9,
      "y": 11,
      "z": 3,
      "name": "Rock_Slate_Brick_Decorative"
    },
    {
      "x": -9,
      "y": 12,
      "z": 3,
      "name": "Empty"
    },
    {
      "x": -9,
      "y": 13,
      "z": 3,
      "name": "Empty"
    },
    {
      "x": -9,
      "y": 14,
      "z": 3,
      "name": "Empty"
    },
    {
      "x": -9,
      "y": 15,
      "z": 3,
      "name": "Empty"
    },
    {
      "x": -9,
      "y": 8,
      "z": 4,
      "name": "Soil_Dirt"
    },
    {
      "x": -9,
      "y": 9,
      "z": 4,
      "name": "Soil_Dirt"
    },
    {
      "x": -9,
      "y": 10,
      "z": 4,
      "name": "Soil_Grass"
    },
    {
      "x": -9,
      "y": 11,
      "z": 4,
      "name": "Rock_Slate_Brick_Decorative"
    },
    {
      "x": -9,
      "y": 12,
      "z": 4,
      "name": "Empty"
    },
    {
      "x": -9,
      "y": 13,
      "z": 4,
      "name": "Empty"
    },
    {
      "x": -9,
      "y": 14,
      "z": 4,
      "name": "Empty"
    },
    {
      "x": -9,
      "y": 15,
      "z": 4,
      "name": "Empty"
    },
    {
      "x": -9,
      "y": 8,
      "z": 5,
      "name": "Wood_Dry_Roots"
    },
    {
      "x": -9,
      "y": 9,
      "z": 5,
      "name": "Soil_Dirt"
    },
    {
      "x": -9,
      "y": 10,
      "z": 5,
      "name": "Soil_Grass"
    },
    {
      "x": -9,
      "y": 11,
      "z": 5,
      "name": "Rock_Slate_Brick_Decorative"
    },
    {
      "x": -9,
      "y": 12,
      "z": 5,
      "name": "Empty"
    },
    {
      "x": -9,
      "y": 13,
      "z": 5,
      "name": "Empty"
    },
    {
      "x": -9,
      "y": 14,
      "z": 5,
      "name": "Empty"
    },
    {
      "x": -9,
      "y": 10,
      "z": 6,
      "name": "Soil_Grass"
    },
    {
      "x": -9,
      "y": 11,
      "z": 6,
      "name": "Rock_Slate_Brick_Decorative"
    },
    {
      "x": -9,
      "y": 12,
      "z": 6,
      "name": "Empty"
    },
    {
      "x": -9,
      "y": 13,
      "z": 6,
      "name": "Empty"
    },
    {
      "x": -8,
      "y": 6,
      "z": -3,
      "name": "Soil_Dirt"
    },
    {
      "x": -8,
      "y": 7,
      "z": -3,
      "name": "Soil_Dirt"
    },
    {
      "x": -8,
      "y": 8,
      "z": -3,
      "name": "Soil_Dirt"
    },
    {
      "x": -8,
      "y": 9,
      "z": -3,
      "name": "Soil_Grass"
    },
    {
      "x": -8,
      "y": 4,
      "z": -2,
      "name": "Soil_Dirt"
    },
    {
      "x": -8,
      "y": 5,
      "z": -2,
      "name": "Soil_Dirt"
    },
    {
      "x": -8,
      "y": 6,
      "z": -2,
      "name": "Soil_Dirt"
    },
    {
      "x": -8,
      "y": 7,
      "z": -2,
      "name": "Soil_Dirt"
    },
    {
      "x": -8,
      "y": 8,
      "z": -2,
      "name": "Soil_Dirt"
    },
    {
      "x": -8,
      "y": 9,
      "z": -2,
      "name": "Soil_Grass"
    },
    {
      "x": -8,
      "y": 10,
      "z": -2,
      "name": "Plant_Grass_Sharp_Tall",
      "support": 15
    },
    {
      "x": -8,
      "y": 11,
      "z": -2,
      "name": "Plant_Grass_Sharp_Tall",
      "filler": 1024
    },
    {
      "x": -8,
      "y": 4,
      "z": -1,
      "name": "Soil_Dirt"
    },
    {
      "x": -8,
      "y": 5,
      "z": -1,
      "name": "Soil_Dirt"
    },
    {
      "x": -8,
      "y": 6,
      "z": -1,
      "name": "Soil_Dirt"
    },
    {
      "x": -8,
      "y": 7,
      "z": -1,
      "name": "Soil_Dirt"
    },
    {
      "x": -8,
      "y": 8,
      "z": -1,
      "name": "Soil_Dirt"
    },
    {
      "x": -8,
      "y": 9,
      "z": -1,
      "name": "Soil_Dirt"
    },
    {
      "x": -8,
      "y": 10,
      "z": -1,
      "name": "Soil_Grass"
    },
    {
      "x": -8,
      "y": 11,
      "z": -1,
      "name": "Plant_Grass_Sharp_Tall",
      "support": 15
    },
    {
      "x": -8,
      "y": 12,
      "z": -1,
      "name": "Plant_Grass_Sharp_Tall",
      "filler": 1024
    },
    {
      "x": -8,
      "y": 4,
      "z": 0,
      "name": "Soil_Dirt"
    },
    {
      "x": -8,
      "y": 5,
      "z": 0,
      "name": "Soil_Dirt"
    },
    {
      "x": -8,
      "y": 6,
      "z": 0,
      "name": "Soil_Dirt"
    },
    {
      "x": -8,
      "y": 7,
      "z": 0,
      "name": "Soil_Dirt"
    },
    {
      "x": -8,
      "y": 8,
      "z": 0,
      "name": "Soil_Dirt"
    },
    {
      "x": -8,
      "y": 9,
      "z": 0,
      "name": "Soil_Dirt"
    },
    {
      "x": -8,
      "y": 10,
      "z": 0,
      "name": "Soil_Grass"
    },
    {
      "x": -8,
      "y": 11,
      "z": 0,
      "name": "Rock_Slate_Brick_Decorative"
    },
    {
      "x": -8,
      "y": 12,
      "z": 0,
      "name": "Empty"
    },
    {
      "x": -8,
      "y": 13,
      "z": 0,
      "name": "Empty"
    },
    {
      "x": -8,
      "y": 14,
      "z": 0,
      "name": "Empty"
    },
    {
      "x": -8,
      "y": 4,
      "z": 1,
      "name": "Soil_Dirt"
    },
    {
      "x": -8,
      "y": 5,
      "z": 1,
      "name": "Soil_Dirt"
    },
    {
      "x": -8,
      "y": 6,
      "z": 1,
      "name": "Soil_Dirt"
    },
    {
      "x": -8,
      "y": 7,
      "z": 1,
      "name": "Soil_Dirt"
    },
    {
      "x": -8,
      "y": 8,
      "z": 1,
      "name": "Soil_Dirt"
    },
    {
      "x": -8,
      "y": 9,
      "z": 1,
      "name": "Soil_Dirt"
    },
    {
      "x": -8,
      "y": 10,
      "z": 1,
      "name": "Rock_Slate_Brick_Ornate"
    },
    {
      "x": -8,
      "y": 11,
      "z": 1,
      "name": "Empty"
    },
    {
      "x": -8,
      "y": 12,
      "z": 1,
      "name": "Empty"
    },
    {
      "x": -8,
      "y": 13,
      "z": 1,
      "name": "Empty"
    },
    {
      "x": -8,
      "y": 14,
      "z": 1,
      "name": "Empty"
    },
    {
      "x": -8,
      "y": 15,
      "z": 1,
      "name": "Empty"
    },
    {
      "x": -8,
      "y": 4,
      "z": 2,
      "name": "Soil_Dirt"
    },
    {
      "x": -8,
      "y": 5,
      "z": 2,
      "name": "Soil_Dirt"
    },
    {
      "x": -8,
      "y": 6,
      "z": 2,
      "name": "Soil_Dirt"
    },
    {
      "x": -8,
      "y": 7,
      "z": 2,
      "name": "Soil_Dirt"
    },
    {
      "x": -8,
      "y": 8,
      "z": 2,
      "name": "Soil_Dirt"
    },
    {
      "x": -8,
      "y": 9,
      "z": 2,
      "name": "Soil_Dirt"
    },
    {
      "x": -8,
      "y": 10,
      "z": 2,
      "name": "Rock_Slate_Brick_Ornate"
    },
    {
      "x": -8,
      "y": 11,
      "z": 2,
      "name": "Empty"
    },
    {
      "x": -8,
      "y": 12,
      "z": 2,
      "name": "Empty"
    },
    {
      "x": -8,
      "y": 13,
      "z": 2,
      "name": "Empty"
    },
    {
      "x": -8,
      "y": 14,
      "z": 2,
      "name": "Empty"
    },
    {
      "x": -8,
      "y": 15,
      "z": 2,
      "name": "Empty"
    },
    {
      "x": -8,
      "y": 5,
      "z": 3,
      "name": "Soil_Dirt"
    },
    {
      "x": -8,
      "y": 6,
      "z": 3,
      "name": "Soil_Dirt"
    },
    {
      "x": -8,
      "y": 7,
      "z": 3,
      "name": "Soil_Dirt"
    },
    {
      "x": -8,
      "y": 8,
      "z": 3,
      "name": "Soil_Dirt"
    },
    {
      "x": -8,
      "y": 9,
      "z": 3,
      "name": "Soil_Dirt"
    },
    {
      "x": -8,
      "y": 10,
      "z": 3,
      "name": "Rock_Slate_Brick_Ornate"
    },
    {
      "x": -8,
      "y": 11,
      "z": 3,
      "name": "Empty"
    },
    {
      "x": -8,
      "y": 12,
      "z": 3,
      "name": "Empty"
    },
    {
      "x": -8,
      "y": 13,
      "z": 3,
      "name": "Empty"
    },
    {
      "x": -8,
      "y": 14,
      "z": 3,
      "name": "Empty"
    },
    {
      "x": -8,
      "y": 15,
      "z": 3,
      "name": "Empty"
    },
    {
      "x": -8,
      "y": 6,
      "z": 4,
      "name": "Soil_Dirt"
    },
    {
      "x": -8,
      "y": 7,
      "z": 4,
      "name": "Soil_Dirt"
    },
    {
      "x": -8,
      "y": 8,
      "z": 4,
      "name": "Soil_Dirt"
    },
    {
      "x": -8,
      "y": 9,
      "z": 4,
      "name": "Soil_Dirt"
    },
    {
      "x": -8,
      "y": 10,
      "z": 4,
      "name": "Rock_Slate_Brick_Ornate"
    },
    {
      "x": -8,
      "y": 11,
      "z": 4,
      "name": "Empty"
    },
    {
      "x": -8,
      "y": 12,
      "z": 4,
      "name": "Empty"
    },
    {
      "x": -8,
      "y": 13,
      "z": 4,
      "name": "Empty"
    },
    {
      "x": -8,
      "y": 14,
      "z": 4,
      "name": "Empty"
    },
    {
      "x": -8,
      "y": 15,
      "z": 4,
      "name": "Empty"
    },
    {
      "x": -8,
      "y": 7,
      "z": 5,
      "name": "Soil_Dirt"
    },
    {
      "x": -8,
      "y": 8,
      "z": 5,
      "name": "Soil_Dirt"
    },
    {
      "x": -8,
      "y": 9,
      "z": 5,
      "name": "Soil_Dirt"
    },
    {
      "x": -8,
      "y": 10,
      "z": 5,
      "name": "Rock_Slate_Brick_Ornate"
    },
    {
      "x": -8,
      "y": 11,
      "z": 5,
      "name": "Empty"
    },
    {
      "x": -8,
      "y": 12,
      "z": 5,
      "name": "Empty"
    },
    {
      "x": -8,
      "y": 13,
      "z": 5,
      "name": "Empty"
    },
    {
      "x": -8,
      "y": 14,
      "z": 5,
      "name": "Empty"
    },
    {
      "x": -8,
      "y": 15,
      "z": 5,
      "name": "Empty"
    },
    {
      "x": -8,
      "y": 9,
      "z": 6,
      "name": "Soil_Dirt"
    },
    {
      "x": -8,
      "y": 10,
      "z": 6,
      "name": "Soil_Grass"
    },
    {
      "x": -8,
      "y": 11,
      "z": 6,
      "name": "Rock_Slate_Brick_Decorative"
    },
    {
      "x": -8,
      "y": 12,
      "z": 6,
      "name": "Empty"
    },
    {
      "x": -8,
      "y": 13,
      "z": 6,
      "name": "Empty"
    },
    {
      "x": -8,
      "y": 14,
      "z": 6,
      "name": "Empty"
    },
    {
      "x": -7,
      "y": 6,
      "z": -4,
      "name": "Soil_Dirt"
    },
    {
      "x": -7,
      "y": 7,
      "z": -4,
      "name": "Soil_Dirt"
    },
    {
      "x": -7,
      "y": 8,
      "z": -4,
      "name": "Soil_Dirt"
    },
    {
      "x": -7,
      "y": 9,
      "z": -4,
      "name": "Soil_Grass"
    },
    {
      "x": -7,
      "y": 3,
      "z": -3,
      "name": "Soil_Dirt"
    },
    {
      "x": -7,
      "y": 4,
      "z": -3,
      "name": "Soil_Dirt"
    },
    {
      "x": -7,
      "y": 5,
      "z": -3,
      "name": "Soil_Dirt"
    },
    {
      "x": -7,
      "y": 6,
      "z": -3,
      "name": "Soil_Dirt"
    },
    {
      "x": -7,
      "y": 7,
      "z": -3,
      "name": "Soil_Dirt"
    },
    {
      "x": -7,
      "y": 8,
      "z": -3,
      "name": "Soil_Dirt"
    },
    {
      "x": -7,
      "y": 9,
      "z": -3,
      "name": "Soil_Grass"
    },
    {
      "x": -7,
      "y": 10,
      "z": -3,
      "name": "Plant_Grass_Sharp_Tall",
      "support": 15
    },
    {
      "x": -7,
      "y": 11,
      "z": -3,
      "name": "Plant_Grass_Sharp_Tall",
      "filler": 1024
    },
    {
      "x": -7,
      "y": 2,
      "z": -2,
      "name": "Wood_Dry_Roots"
    },
    {
      "x": -7,
      "y": 3,
      "z": -2,
      "name": "Soil_Dirt"
    },
    {
      "x": -7,
      "y": 4,
      "z": -2,
      "name": "Soil_Dirt"
    },
    {
      "x": -7,
      "y": 5,
      "z": -2,
      "name": "Soil_Dirt"
    },
    {
      "x": -7,
      "y": 6,
      "z": -2,
      "name": "Soil_Dirt"
    },
    {
      "x": -7,
      "y": 7,
      "z": -2,
      "name": "Soil_Dirt"
    },
    {
      "x": -7,
      "y": 8,
      "z": -2,
      "name": "Soil_Dirt"
    },
    {
      "x": -7,
      "y": 9,
      "z": -2,
      "name": "Soil_Dirt"
    },
    {
      "x": -7,
      "y": 10,
      "z": -2,
      "name": "Soil_Grass"
    },
    {
      "x": -7,
      "y": 3,
      "z": -1,
      "name": "Soil_Dirt"
    },
    {
      "x": -7,
      "y": 4,
      "z": -1,
      "name": "Soil_Dirt"
    },
    {
      "x": -7,
      "y": 5,
      "z": -1,
      "name": "Soil_Dirt"
    },
    {
      "x": -7,
      "y": 6,
      "z": -1,
      "name": "Soil_Dirt"
    },
    {
      "x": -7,
      "y": 7,
      "z": -1,
      "name": "Soil_Dirt"
    },
    {
      "x": -7,
      "y": 8,
      "z": -1,
      "name": "Soil_Dirt"
    },
    {
      "x": -7,
      "y": 9,
      "z": -1,
      "name": "Soil_Dirt"
    },
    {
      "x": -7,
      "y": 10,
      "z": -1,
      "name": "Soil_Grass"
    },
    {
      "x": -7,
      "y": 11,
      "z": -1,
      "name": "Plant_Grass_Sharp_Tall",
      "support": 15
    },
    {
      "x": -7,
      "y": 12,
      "z": -1,
      "name": "Plant_Grass_Sharp_Tall",
      "filler": 1024
    },
    {
      "x": -7,
      "y": 3,
      "z": 0,
      "name": "Soil_Dirt"
    },
    {
      "x": -7,
      "y": 4,
      "z": 0,
      "name": "Soil_Dirt"
    },
    {
      "x": -7,
      "y": 5,
      "z": 0,
      "name": "Soil_Dirt"
    },
    {
      "x": -7,
      "y": 6,
      "z": 0,
      "name": "Soil_Dirt"
    },
    {
      "x": -7,
      "y": 7,
      "z": 0,
      "name": "Soil_Dirt"
    },
    {
      "x": -7,
      "y": 8,
      "z": 0,
      "name": "Soil_Dirt"
    },
    {
      "x": -7,
      "y": 9,
      "z": 0,
      "name": "Soil_Dirt"
    },
    {
      "x": -7,
      "y": 10,
      "z": 0,
      "name": "Soil_Grass"
    },
    {
      "x": -7,
      "y": 11,
      "z": 0,
      "name": "Rock_Slate_Brick"
    },
    {
      "x": -7,
      "y": 12,
      "z": 0,
      "name": "Rock_Slate_Brick_Ornate"
    },
    {
      "x": -7,
      "y": 13,
      "z": 0,
      "name": "Rock_Slate_Brick_Beam"
    },
    {
      "x": -7,
      "y": 14,
      "z": 0,
      "name": "Rock_Slate_Brick_Beam"
    },
    {
      "x": -7,
      "y": 15,
      "z": 0,
      "name": "Rock_Slate_Brick_Ornate"
    },
    {
      "x": -7,
      "y": 16,
      "z": 0,
      "name": "Rock_Slate_Brick_Pillar_Base"
    },
    {
      "x": -7,
      "y": 17,
      "z": 0,
      "name": "Rock_Slate_Brick_Pillar_Middle"
    },
    {
      "x": -7,
      "y": 18,
      "z": 0,
      "name": "Furniture_Human_Ruins_Brazier"
    },
    {
      "x": -7,
      "y": 3,
      "z": 1,
      "name": "Soil_Dirt"
    },
    {
      "x": -7,
      "y": 4,
      "z": 1,
      "name": "Soil_Dirt"
    },
    {
      "x": -7,
      "y": 5,
      "z": 1,
      "name": "Soil_Dirt"
    },
    {
      "x": -7,
      "y": 6,
      "z": 1,
      "name": "Soil_Dirt"
    },
    {
      "x": -7,
      "y": 7,
      "z": 1,
      "name": "Soil_Dirt"
    },
    {
      "x": -7,
      "y": 8,
      "z": 1,
      "name": "Soil_Dirt"
    },
    {
      "x": -7,
      "y": 9,
      "z": 1,
      "name": "Soil_Dirt"
    },
    {
      "x": -7,
      "y": 10,
      "z": 1,
      "name": "Rock_Slate_Brick_Ornate"
    },
    {
      "x": -7,
      "y": 11,
      "z": 1,
      "name": "Empty"
    },
    {
      "x": -7,
      "y": 12,
      "z": 1,
      "name": "Empty"
    },
    {
      "x": -7,
      "y": 13,
      "z": 1,
      "name": "Empty"
    },
    {
      "x": -7,
      "y": 14,
      "z": 1,
      "name": "Empty"
    },
    {
      "x": -7,
      "y": 15,
      "z": 1,
      "name": "Empty"
    },
    {
      "x": -7,
      "y": 2,
      "z": 2,
      "name": "Wood_Dry_Roots"
    },
    {
      "x": -7,
      "y": 3,
      "z": 2,
      "name": "Soil_Dirt"
    },
    {
      "x": -7,
      "y": 4,
      "z": 2,
      "name": "Soil_Dirt"
    },
    {
      "x": -7,
      "y": 5,
      "z": 2,
      "name": "Soil_Dirt"
    },
    {
      "x": -7,
      "y": 6,
      "z": 2,
      "name": "Soil_Dirt"
    },
    {
      "x": -7,
      "y": 7,
      "z": 2,
      "name": "Soil_Dirt"
    },
    {
      "x": -7,
      "y": 8,
      "z": 2,
      "name": "Soil_Dirt"
    },
    {
      "x": -7,
      "y": 9,
      "z": 2,
      "name": "Soil_Dirt"
    },
    {
      "x": -7,
      "y": 10,
      "z": 2,
      "name": "Rock_Slate_Brick_Ornate"
    },
    {
      "x": -7,
      "y": 11,
      "z": 2,
      "name": "Empty"
    },
    {
      "x": -7,
      "y": 12,
      "z": 2,
      "name": "Empty"
    },
    {
      "x": -7,
      "y": 13,
      "z": 2,
      "name": "Empty"
    },
    {
      "x": -7,
      "y": 14,
      "z": 2,
      "name": "Empty"
    },
    {
      "x": -7,
      "y": 15,
      "z": 2,
      "name": "Empty"
    },
    {
      "x": -7,
      "y": 3,
      "z": 3,
      "name": "Soil_Dirt"
    },
    {
      "x": -7,
      "y": 4,
      "z": 3,
      "name": "Soil_Dirt"
    },
    {
      "x": -7,
      "y": 5,
      "z": 3,
      "name": "Soil_Dirt"
    },
    {
      "x": -7,
      "y": 6,
      "z": 3,
      "name": "Soil_Dirt"
    },
    {
      "x": -7,
      "y": 7,
      "z": 3,
      "name": "Soil_Dirt"
    },
    {
      "x": -7,
      "y": 8,
      "z": 3,
      "name": "Soil_Dirt"
    },
    {
      "x": -7,
      "y": 9,
      "z": 3,
      "name": "Soil_Dirt"
    },
    {
      "x": -7,
      "y": 10,
      "z": 3,
      "name": "Rock_Slate_Brick_Ornate"
    },
    {
      "x": -7,
      "y": 11,
      "z": 3,
      "name": "Empty"
    },
    {
      "x": -7,
      "y": 12,
      "z": 3,
      "name": "Empty"
    },
    {
      "x": -7,
      "y": 13,
      "z": 3,
      "name": "Empty"
    },
    {
      "x": -7,
      "y": 14,
      "z": 3,
      "name": "Empty"
    },
    {
      "x": -7,
      "y": 15,
      "z": 3,
      "name": "Empty"
    },
    {
      "x": -7,
      "y": 4,
      "z": 4,
      "name": "Soil_Dirt"
    },
    {
      "x": -7,
      "y": 5,
      "z": 4,
      "name": "Soil_Dirt"
    },
    {
      "x": -7,
      "y": 6,
      "z": 4,
      "name": "Soil_Dirt"
    },
    {
      "x": -7,
      "y": 7,
      "z": 4,
      "name": "Soil_Dirt"
    },
    {
      "x": -7,
      "y": 8,
      "z": 4,
      "name": "Soil_Dirt"
    },
    {
      "x": -7,
      "y": 9,
      "z": 4,
      "name": "Soil_Dirt"
    },
    {
      "x": -7,
      "y": 10,
      "z": 4,
      "name": "Rock_Slate_Brick_Ornate"
    },
    {
      "x": -7,
      "y": 11,
      "z": 4,
      "name": "Empty"
    },
    {
      "x": -7,
      "y": 12,
      "z": 4,
      "name": "Empty"
    },
    {
      "x": -7,
      "y": 13,
      "z": 4,
      "name": "Empty"
    },
    {
      "x": -7,
      "y": 14,
      "z": 4,
      "name": "Empty"
    },
    {
      "x": -7,
      "y": 15,
      "z": 4,
      "name": "Empty"
    },
    {
      "x": -7,
      "y": 5,
      "z": 5,
      "name": "Soil_Dirt"
    },
    {
      "x": -7,
      "y": 6,
      "z": 5,
      "name": "Soil_Dirt"
    },
    {
      "x": -7,
      "y": 7,
      "z": 5,
      "name": "Soil_Dirt"
    },
    {
      "x": -7,
      "y": 8,
      "z": 5,
      "name": "Soil_Dirt"
    },
    {
      "x": -7,
      "y": 9,
      "z": 5,
      "name": "Soil_Dirt"
    },
    {
      "x": -7,
      "y": 10,
      "z": 5,
      "name": "Rock_Slate_Brick_Ornate"
    },
    {
      "x": -7,
      "y": 11,
      "z": 5,
      "name": "Empty"
    },
    {
      "x": -7,
      "y": 12,
      "z": 5,
      "name": "Empty"
    },
    {
      "x": -7,
      "y": 13,
      "z": 5,
      "name": "Empty"
    },
    {
      "x": -7,
      "y": 14,
      "z": 5,
      "name": "Empty"
    },
    {
      "x": -7,
      "y": 15,
      "z": 5,
      "name": "Empty"
    },
    {
      "x": -7,
      "y": 6,
      "z": 6,
      "name": "Wood_Dry_Roots"
    },
    {
      "x": -7,
      "y": 7,
      "z": 6,
      "name": "Soil_Dirt"
    },
    {
      "x": -7,
      "y": 8,
      "z": 6,
      "name": "Soil_Dirt"
    },
    {
      "x": -7,
      "y": 9,
      "z": 6,
      "name": "Soil_Dirt"
    },
    {
      "x": -7,
      "y": 10,
      "z": 6,
      "name": "Soil_Grass"
    },
    {
      "x": -7,
      "y": 11,
      "z": 6,
      "name": "Rock_Slate_Brick_Decorative"
    },
    {
      "x": -7,
      "y": 12,
      "z": 6,
      "name": "Empty"
    },
    {
      "x": -7,
      "y": 13,
      "z": 6,
      "name": "Empty"
    },
    {
      "x": -7,
      "y": 14,
      "z": 6,
      "name": "Empty"
    },
    {
      "x": -7,
      "y": 15,
      "z": 6,
      "name": "Empty"
    },
    {
      "x": -6,
      "y": 6,
      "z": -5,
      "name": "Soil_Dirt"
    },
    {
      "x": -6,
      "y": 7,
      "z": -5,
      "name": "Soil_Dirt"
    },
    {
      "x": -6,
      "y": 8,
      "z": -5,
      "name": "Soil_Dirt"
    },
    {
      "x": -6,
      "y": 9,
      "z": -5,
      "name": "Soil_Grass"
    },
    {
      "x": -6,
      "y": 3,
      "z": -4,
      "name": "Soil_Dirt"
    },
    {
      "x": -6,
      "y": 4,
      "z": -4,
      "name": "Soil_Dirt"
    },
    {
      "x": -6,
      "y": 5,
      "z": -4,
      "name": "Soil_Dirt"
    },
    {
      "x": -6,
      "y": 6,
      "z": -4,
      "name": "Soil_Dirt"
    },
    {
      "x": -6,
      "y": 7,
      "z": -4,
      "name": "Soil_Dirt"
    },
    {
      "x": -6,
      "y": 8,
      "z": -4,
      "name": "Soil_Dirt"
    },
    {
      "x": -6,
      "y": 9,
      "z": -4,
      "name": "Soil_Dirt"
    },
    {
      "x": -6,
      "y": 10,
      "z": -4,
      "name": "Soil_Grass"
    },
    {
      "x": -6,
      "y": 11,
      "z": -4,
      "name": "Plant_Grass_Sharp_Tall",
      "support": 15
    },
    {
      "x": -6,
      "y": 12,
      "z": -4,
      "name": "Plant_Grass_Sharp_Tall",
      "filler": 1024
    },
    {
      "x": -6,
      "y": 2,
      "z": -3,
      "name": "Soil_Dirt"
    },
    {
      "x": -6,
      "y": 3,
      "z": -3,
      "name": "Soil_Dirt"
    },
    {
      "x": -6,
      "y": 4,
      "z": -3,
      "name": "Soil_Dirt"
    },
    {
      "x": -6,
      "y": 5,
      "z": -3,
      "name": "Soil_Dirt"
    },
    {
      "x": -6,
      "y": 6,
      "z": -3,
      "name": "Soil_Dirt"
    },
    {
      "x": -6,
      "y": 7,
      "z": -3,
      "name": "Soil_Dirt"
    },
    {
      "x": -6,
      "y": 8,
      "z": -3,
      "name": "Soil_Dirt"
    },
    {
      "x": -6,
      "y": 9,
      "z": -3,
      "name": "Soil_Dirt"
    },
    {
      "x": -6,
      "y": 10,
      "z": -3,
      "name": "Soil_Grass"
    },
    {
      "x": -6,
      "y": 11,
      "z": -3,
      "name": "Plant_Crop_Berry_Block",
      "components": {
        "Components": {
          "FarmingBlock": {
            "LastTickGameTime": "0001-01-01T12:00:00Z"
          },
          "PlacedByInteraction": {
            "WhoPlacedUuid": {
              "$binary": "bJ0Z/pHxT/WyhVA6z1mjfg==",
              "$type": "04"
            }
          }
        }
      },
      "support": 15
    },
    {
      "x": -6,
      "y": 2,
      "z": -2,
      "name": "Soil_Dirt"
    },
    {
      "x": -6,
      "y": 3,
      "z": -2,
      "name": "Soil_Dirt"
    },
    {
      "x": -6,
      "y": 4,
      "z": -2,
      "name": "Soil_Dirt"
    },
    {
      "x": -6,
      "y": 5,
      "z": -2,
      "name": "Soil_Dirt"
    },
    {
      "x": -6,
      "y": 6,
      "z": -2,
      "name": "Soil_Dirt"
    },
    {
      "x": -6,
      "y": 7,
      "z": -2,
      "name": "Soil_Dirt"
    },
    {
      "x": -6,
      "y": 8,
      "z": -2,
      "name": "Soil_Dirt"
    },
    {
      "x": -6,
      "y": 9,
      "z": -2,
      "name": "Soil_Dirt"
    },
    {
      "x": -6,
      "y": 10,
      "z": -2,
      "name": "Soil_Grass"
    },
    {
      "x": -6,
      "y": 2,
      "z": -1,
      "name": "Soil_Dirt"
    },
    {
      "x": -6,
      "y": 3,
      "z": -1,
      "name": "Soil_Dirt"
    },
    {
      "x": -6,
      "y": 4,
      "z": -1,
      "name": "Soil_Dirt"
    },
    {
      "x": -6,
      "y": 5,
      "z": -1,
      "name": "Soil_Dirt"
    },
    {
      "x": -6,
      "y": 6,
      "z": -1,
      "name": "Soil_Dirt"
    },
    {
      "x": -6,
      "y": 7,
      "z": -1,
      "name": "Soil_Dirt"
    },
    {
      "x": -6,
      "y": 8,
      "z": -1,
      "name": "Soil_Dirt"
    },
    {
      "x": -6,
      "y": 9,
      "z": -1,
      "name": "Soil_Dirt"
    },
    {
      "x": -6,
      "y": 10,
      "z": -1,
      "name": "Soil_Grass"
    },
    {
      "x": -6,
      "y": 11,
      "z": -1,
      "name": "Plant_Crop_Berry_Block",
      "components": {
        "Components": {
          "FarmingBlock": {
            "LastTickGameTime": "0001-01-01T12:00:00Z"
          },
          "PlacedByInteraction": {
            "WhoPlacedUuid": {
              "$binary": "bJ0Z/pHxT/WyhVA6z1mjfg==",
              "$type": "04"
            }
          }
        }
      },
      "support": 15
    },
    {
      "x": -6,
      "y": 1,
      "z": 0,
      "name": "Soil_Dirt"
    },
    {
      "x": -6,
      "y": 2,
      "z": 0,
      "name": "Soil_Dirt"
    },
    {
      "x": -6,
      "y": 3,
      "z": 0,
      "name": "Soil_Dirt"
    },
    {
      "x": -6,
      "y": 4,
      "z": 0,
      "name": "Soil_Dirt"
    },
    {
      "x": -6,
      "y": 5,
      "z": 0,
      "name": "Soil_Dirt"
    },
    {
      "x": -6,
      "y": 6,
      "z": 0,
      "name": "Soil_Dirt"
    },
    {
      "x": -6,
      "y": 7,
      "z": 0,
      "name": "Soil_Dirt"
    },
    {
      "x": -6,
      "y": 8,
      "z": 0,
      "name": "Soil_Dirt"
    },
    {
      "x": -6,
      "y": 9,
      "z": 0,
      "name": "Soil_Dirt"
    },
    {
      "x": -6,
      "y": 10,
      "z": 0,
      "name": "Rock_Slate_Brick_Ornate"
    },
    {
      "x": -6,
      "y": 11,
      "z": 0,
      "name": "Rock_Slate_Brick"
    },
    {
      "x": -6,
      "y": 12,
      "z": 0,
      "name": "Empty"
    },
    {
      "x": -6,
      "y": 13,
      "z": 0,
      "name": "Empty"
    },
    {
      "x": -6,
      "y": 14,
      "z": 0,
      "name": "Empty"
    },
    {
      "x": -6,
      "y": 15,
      "z": 0,
      "name": "Rock_Slate_Cobble_Stairs",
      "rotation": 11
    },
    {
      "x": -6,
      "y": 2,
      "z": 1,
      "name": "Soil_Dirt"
    },
    {
      "x": -6,
      "y": 3,
      "z": 1,
      "name": "Soil_Dirt"
    },
    {
      "x": -6,
      "y": 4,
      "z": 1,
      "name": "Soil_Dirt"
    },
    {
      "x": -6,
      "y": 5,
      "z": 1,
      "name": "Soil_Dirt"
    },
    {
      "x": -6,
      "y": 6,
      "z": 1,
      "name": "Soil_Dirt"
    },
    {
      "x": -6,
      "y": 7,
      "z": 1,
      "name": "Soil_Dirt"
    },
    {
      "x": -6,
      "y": 8,
      "z": 1,
      "name": "Soil_Dirt"
    },
    {
      "x": -6,
      "y": 9,
      "z": 1,
      "name": "Soil_Dirt"
    },
    {
      "x": -6,
      "y": 10,
      "z": 1,
      "name": "Rock_Slate_Brick_Ornate"
    },
    {
      "x": -6,
      "y": 11,
      "z": 1,
      "name": "Empty"
    },
    {
      "x": -6,
      "y": 12,
      "z": 1,
      "name": "Empty"
    },
    {
      "x": -6,
      "y": 13,
      "z": 1,
      "name": "Empty"
    },
    {
      "x": -6,
      "y": 14,
      "z": 1,
      "name": "Empty"
    },
    {
      "x": -6,
      "y": 15,
      "z": 1,
      "name": "Empty"
    },
    {
      "x": -6,
      "y": 2,
      "z": 2,
      "name": "Soil_Dirt"
    },
    {
      "x": -6,
      "y": 3,
      "z": 2,
      "name": "Soil_Dirt"
    },
    {
      "x": -6,
      "y": 4,
      "z": 2,
      "name": "Soil_Dirt"
    },
    {
      "x": -6,
      "y": 5,
      "z": 2,
      "name": "Soil_Dirt"
    },
    {
      "x": -6,
      "y": 6,
      "z": 2,
      "name": "Soil_Dirt"
    },
    {
      "x": -6,
      "y": 7,
      "z": 2,
      "name": "Soil_Dirt"
    },
    {
      "x": -6,
      "y": 8,
      "z": 2,
      "name": "Soil_Dirt"
    },
    {
      "x": -6,
      "y": 9,
      "z": 2,
      "name": "Soil_Dirt"
    },
    {
      "x": -6,
      "y": 10,
      "z": 2,
      "name": "Rock_Slate_Brick_Ornate"
    },
    {
      "x": -6,
      "y": 11,
      "z": 2,
      "name": "Empty"
    },
    {
      "x": -6,
      "y": 12,
      "z": 2,
      "name": "Empty"
    },
    {
      "x": -6,
      "y": 13,
      "z": 2,
      "name": "Empty"
    },
    {
      "x": -6,
      "y": 14,
      "z": 2,
      "name": "Empty"
    },
    {
      "x": -6,
      "y": 15,
      "z": 2,
      "name": "Empty"
    },
    {
      "x": -6,
      "y": 2,
      "z": 3,
      "name": "Soil_Dirt"
    },
    {
      "x": -6,
      "y": 3,
      "z": 3,
      "name": "Soil_Dirt"
    },
    {
      "x": -6,
      "y": 4,
      "z": 3,
      "name": "Soil_Dirt"
    },
    {
      "x": -6,
      "y": 5,
      "z": 3,
      "name": "Soil_Dirt"
    },
    {
      "x": -6,
      "y": 6,
      "z": 3,
      "name": "Soil_Dirt"
    },
    {
      "x": -6,
      "y": 7,
      "z": 3,
      "name": "Soil_Dirt"
    },
    {
      "x": -6,
      "y": 8,
      "z": 3,
      "name": "Soil_Dirt"
    },
    {
      "x": -6,
      "y": 9,
      "z": 3,
      "name": "Soil_Dirt"
    },
    {
      "x": -6,
      "y": 10,
      "z": 3,
      "name": "Rock_Slate_Brick_Ornate"
    },
    {
      "x": -6,
      "y": 11,
      "z": 3,
      "name": "Empty"
    },
    {
      "x": -6,
      "y": 12,
      "z": 3,
      "name": "Empty"
    },
    {
      "x": -6,
      "y": 13,
      "z": 3,
      "name": "Empty"
    },
    {
      "x": -6,
      "y": 14,
      "z": 3,
      "name": "Empty"
    },
    {
      "x": -6,
      "y": 15,
      "z": 3,
      "name": "Empty"
    },
    {
      "x": -6,
      "y": 3,
      "z": 4,
      "name": "Soil_Dirt"
    },
    {
      "x": -6,
      "y": 4,
      "z": 4,
      "name": "Soil_Dirt"
    },
    {
      "x": -6,
      "y": 5,
      "z": 4,
      "name": "Soil_Dirt"
    },
    {
      "x": -6,
      "y": 6,
      "z": 4,
      "name": "Soil_Dirt"
    },
    {
      "x": -6,
      "y": 7,
      "z": 4,
      "name": "Soil_Dirt"
    },
    {
      "x": -6,
      "y": 8,
      "z": 4,
      "name": "Soil_Dirt"
    },
    {
      "x": -6,
      "y": 9,
      "z": 4,
      "name": "Soil_Dirt"
    },
    {
      "x": -6,
      "y": 10,
      "z": 4,
      "name": "Rock_Slate_Brick_Ornate"
    },
    {
      "x": -6,
      "y": 11,
      "z": 4,
      "name": "Empty"
    },
    {
      "x": -6,
      "y": 12,
      "z": 4,
      "name": "Empty"
    },
    {
      "x": -6,
      "y": 13,
      "z": 4,
      "name": "Empty"
    },
    {
      "x": -6,
      "y": 14,
      "z": 4,
      "name": "Empty"
    },
    {
      "x": -6,
      "y": 15,
      "z": 4,
      "name": "Empty"
    },
    {
      "x": -6,
      "y": 4,
      "z": 5,
      "name": "Soil_Dirt"
    },
    {
      "x": -6,
      "y": 5,
      "z": 5,
      "name": "Soil_Dirt"
    },
    {
      "x": -6,
      "y": 6,
      "z": 5,
      "name": "Soil_Dirt"
    },
    {
      "x": -6,
      "y": 7,
      "z": 5,
      "name": "Soil_Dirt"
    },
    {
      "x": -6,
      "y": 8,
      "z": 5,
      "name": "Soil_Dirt"
    },
    {
      "x": -6,
      "y": 9,
      "z": 5,
      "name": "Soil_Dirt"
    },
    {
      "x": -6,
      "y": 10,
      "z": 5,
      "name": "Rock_Slate_Brick_Ornate"
    },
    {
      "x": -6,
      "y": 11,
      "z": 5,
      "name": "Empty"
    },
    {
      "x": -6,
      "y": 12,
      "z": 5,
      "name": "Empty"
    },
    {
      "x": -6,
      "y": 13,
      "z": 5,
      "name": "Empty"
    },
    {
      "x": -6,
      "y": 14,
      "z": 5,
      "name": "Empty"
    },
    {
      "x": -6,
      "y": 15,
      "z": 5,
      "name": "Empty"
    },
    {
      "x": -6,
      "y": 5,
      "z": 6,
      "name": "Soil_Dirt"
    },
    {
      "x": -6,
      "y": 6,
      "z": 6,
      "name": "Soil_Dirt"
    },
    {
      "x": -6,
      "y": 7,
      "z": 6,
      "name": "Soil_Dirt"
    },
    {
      "x": -6,
      "y": 8,
      "z": 6,
      "name": "Soil_Dirt"
    },
    {
      "x": -6,
      "y": 9,
      "z": 6,
      "name": "Soil_Dirt"
    },
    {
      "x": -6,
      "y": 10,
      "z": 6,
      "name": "Soil_Grass"
    },
    {
      "x": -6,
      "y": 11,
      "z": 6,
      "name": "Rock_Slate_Brick_Decorative"
    },
    {
      "x": -6,
      "y": 12,
      "z": 6,
      "name": "Empty"
    },
    {
      "x": -6,
      "y": 13,
      "z": 6,
      "name": "Empty"
    },
    {
      "x": -6,
      "y": 14,
      "z": 6,
      "name": "Empty"
    },
    {
      "x": -6,
      "y": 15,
      "z": 6,
      "name": "Empty"
    },
    {
      "x": -6,
      "y": 7,
      "z": 7,
      "name": "Soil_Dirt"
    },
    {
      "x": -6,
      "y": 8,
      "z": 7,
      "name": "Soil_Dirt"
    },
    {
      "x": -6,
      "y": 9,
      "z": 7,
      "name": "Soil_Dirt"
    },
    {
      "x": -6,
      "y": 10,
      "z": 7,
      "name": "Soil_Grass"
    },
    {
      "x": -5,
      "y": 6,
      "z": -6,
      "name": "Soil_Dirt"
    },
    {
      "x": -5,
      "y": 7,
      "z": -6,
      "name": "Soil_Dirt"
    },
    {
      "x": -5,
      "y": 8,
      "z": -6,
      "name": "Soil_Dirt"
    },
    {
      "x": -5,
      "y": 9,
      "z": -6,
      "name": "Soil_Grass"
    },
    {
      "x": -5,
      "y": 10,
      "z": -6,
      "name": "Plant_Grass_Sharp_Tall",
      "support": 15
    },
    {
      "x": -5,
      "y": 11,
      "z": -6,
      "name": "Plant_Grass_Sharp_Tall",
      "filler": 1024
    },
    {
      "x": -5,
      "y": 3,
      "z": -5,
      "name": "Soil_Dirt"
    },
    {
      "x": -5,
      "y": 4,
      "z": -5,
      "name": "Soil_Dirt"
    },
    {
      "x": -5,
      "y": 5,
      "z": -5,
      "name": "Soil_Dirt"
    },
    {
      "x": -5,
      "y": 6,
      "z": -5,
      "name": "Soil_Dirt"
    },
    {
      "x": -5,
      "y": 7,
      "z": -5,
      "name": "Soil_Dirt"
    },
    {
      "x": -5,
      "y": 8,
      "z": -5,
      "name": "Soil_Dirt"
    },
    {
      "x": -5,
      "y": 9,
      "z": -5,
      "name": "Soil_Dirt"
    },
    {
      "x": -5,
      "y": 10,
      "z": -5,
      "name": "Rock_Slate_Brick_Stairs",
      "rotation": 2
    },
    {
      "x": -5,
      "y": 2,
      "z": -4,
      "name": "Soil_Dirt"
    },
    {
      "x": -5,
      "y": 3,
      "z": -4,
      "name": "Soil_Dirt"
    },
    {
      "x": -5,
      "y": 4,
      "z": -4,
      "name": "Soil_Dirt"
    },
    {
      "x": -5,
      "y": 5,
      "z": -4,
      "name": "Soil_Dirt"
    },
    {
      "x": -5,
      "y": 6,
      "z": -4,
      "name": "Soil_Dirt"
    },
    {
      "x": -5,
      "y": 7,
      "z": -4,
      "name": "Soil_Dirt"
    },
    {
      "x": -5,
      "y": 8,
      "z": -4,
      "name": "Soil_Dirt"
    },
    {
      "x": -5,
      "y": 9,
      "z": -4,
      "name": "Soil_Dirt"
    },
    {
      "x": -5,
      "y": 10,
      "z": -4,
      "name": "Soil_Grass"
    },
    {
      "x": -5,
      "y": 11,
      "z": -4,
      "name": "Rock_Slate_Brick"
    },
    {
      "x": -5,
      "y": 12,
      "z": -4,
      "name": "Rock_Slate_Brick_Ornate"
    },
    {
      "x": -5,
      "y": 13,
      "z": -4,
      "name": "Rock_Slate_Brick_Beam"
    },
    {
      "x": -5,
      "y": 14,
      "z": -4,
      "name": "Rock_Slate_Brick_Beam"
    },
    {
      "x": -5,
      "y": 15,
      "z": -4,
      "name": "Rock_Slate_Brick_Ornate"
    },
    {
      "x": -5,
      "y": 16,
      "z": -4,
      "name": "Rock_Slate_Brick_Pillar_Base"
    },
    {
      "x": -5,
      "y": 17,
      "z": -4,
      "name": "Rock_Slate_Brick_Pillar_Middle"
    },
    {
      "x": -5,
      "y": 18,
      "z": -4,
      "name": "Furniture_Human_Ruins_Brazier"
    },
    {
      "x": -5,
      "y": 1,
      "z": -3,
      "name": "Soil_Dirt"
    },
    {
      "x": -5,
      "y": 2,
      "z": -3,
      "name": "Soil_Dirt"
    },
    {
      "x": -5,
      "y": 3,
      "z": -3,
      "name": "Soil_Dirt"
    },
    {
      "x": -5,
      "y": 4,
      "z": -3,
      "name": "Soil_Dirt"
    },
    {
      "x": -5,
      "y": 5,
      "z": -3,
      "name": "Soil_Dirt"
    },
    {
      "x": -5,
      "y": 6,
      "z": -3,
      "name": "Soil_Dirt"
    },
    {
      "x": -5,
      "y": 7,
      "z": -3,
      "name": "Soil_Dirt"
    },
    {
      "x": -5,
      "y": 8,
      "z": -3,
      "name": "Soil_Dirt"
    },
    {
      "x": -5,
      "y": 9,
      "z": -3,
      "name": "Soil_Dirt"
    },
    {
      "x": -5,
      "y": 10,
      "z": -3,
      "name": "Soil_Grass"
    },
    {
      "x": -5,
      "y": 11,
      "z": -3,
      "name": "Rock_Slate_Brick"
    },
    {
      "x": -5,
      "y": 12,
      "z": -3,
      "name": "Empty"
    },
    {
      "x": -5,
      "y": 13,
      "z": -3,
      "name": "Empty"
    },
    {
      "x": -5,
      "y": 14,
      "z": -3,
      "name": "Empty"
    },
    {
      "x": -5,
      "y": 15,
      "z": -3,
      "name": "Rock_Slate_Cobble_Stairs",
      "rotation": 10
    },
    {
      "x": -5,
      "y": 1,
      "z": -2,
      "name": "Soil_Dirt"
    },
    {
      "x": -5,
      "y": 2,
      "z": -2,
      "name": "Soil_Dirt"
    },
    {
      "x": -5,
      "y": 3,
      "z": -2,
      "name": "Soil_Dirt"
    },
    {
      "x": -5,
      "y": 4,
      "z": -2,
      "name": "Soil_Dirt"
    },
    {
      "x": -5,
      "y": 5,
      "z": -2,
      "name": "Soil_Dirt"
    },
    {
      "x": -5,
      "y": 6,
      "z": -2,
      "name": "Soil_Dirt"
    },
    {
      "x": -5,
      "y": 7,
      "z": -2,
      "name": "Soil_Dirt"
    },
    {
      "x": -5,
      "y": 8,
      "z": -2,
      "name": "Soil_Dirt"
    },
    {
      "x": -5,
      "y": 9,
      "z": -2,
      "name": "Soil_Dirt"
    },
    {
      "x": -5,
      "y": 10,
      "z": -2,
      "name": "Soil_Grass"
    },
    {
      "x": -5,
      "y": 11,
      "z": -2,
      "name": "Rock_Slate_Brick"
    },
    {
      "x": -5,
      "y": 12,
      "z": -2,
      "name": "Empty"
    },
    {
      "x": -5,
      "y": 13,
      "z": -2,
      "name": "Empty"
    },
    {
      "x": -5,
      "y": 14,
      "z": -2,
      "name": "Empty"
    },
    {
      "x": -5,
      "y": 15,
      "z": -2,
      "name": "Rock_Slate_Brick_Half",
      "rotation": 8
    },
    {
      "x": -5,
      "y": 1,
      "z": -1,
      "name": "Soil_Dirt"
    },
    {
      "x": -5,
      "y": 2,
      "z": -1,
      "name": "Soil_Dirt"
    },
    {
      "x": -5,
      "y": 3,
      "z": -1,
      "name": "Soil_Dirt"
    },
    {
      "x": -5,
      "y": 4,
      "z": -1,
      "name": "Soil_Dirt"
    },
    {
      "x": -5,
      "y": 5,
      "z": -1,
      "name": "Soil_Dirt"
    },
    {
      "x": -5,
      "y": 6,
      "z": -1,
      "name": "Soil_Dirt"
    },
    {
      "x": -5,
      "y": 7,
      "z": -1,
      "name": "Soil_Dirt"
    },
    {
      "x": -5,
      "y": 8,
      "z": -1,
      "name": "Soil_Dirt"
    },
    {
      "x": -5,
      "y": 9,
      "z": -1,
      "name": "Soil_Dirt"
    },
    {
      "x": -5,
      "y": 10,
      "z": -1,
      "name": "Soil_Grass"
    },
    {
      "x": -5,
      "y": 11,
      "z": -1,
      "name": "Rock_Slate_Brick"
    },
    {
      "x": -5,
      "y": 12,
      "z": -1,
      "name": "Empty"
    },
    {
      "x": -5,
      "y": 13,
      "z": -1,
      "name": "Empty"
    },
    {
      "x": -5,
      "y": 14,
      "z": -1,
      "name": "Empty"
    },
    {
      "x": -5,
      "y": 15,
      "z": -1,
      "name": "Rock_Slate_Brick_Half",
      "rotation": 8
    },
    {
      "x": -5,
      "y": 1,
      "z": 0,
      "name": "Soil_Dirt"
    },
    {
      "x": -5,
      "y": 2,
      "z": 0,
      "name": "Soil_Dirt"
    },
    {
      "x": -5,
      "y": 3,
      "z": 0,
      "name": "Soil_Dirt"
    },
    {
      "x": -5,
      "y": 4,
      "z": 0,
      "name": "Soil_Dirt"
    },
    {
      "x": -5,
      "y": 5,
      "z": 0,
      "name": "Soil_Dirt"
    },
    {
      "x": -5,
      "y": 6,
      "z": 0,
      "name": "Soil_Dirt"
    },
    {
      "x": -5,
      "y": 7,
      "z": 0,
      "name": "Soil_Dirt"
    },
    {
      "x": -5,
      "y": 8,
      "z": 0,
      "name": "Soil_Dirt"
    },
    {
      "x": -5,
      "y": 9,
      "z": 0,
      "name": "Soil_Dirt"
    },
    {
      "x": -5,
      "y": 10,
      "z": 0,
      "name": "Rock_Slate_Brick_Ornate"
    },
    {
      "x": -5,
      "y": 11,
      "z": 0,
      "name": "Rock_Slate_Brick"
    },
    {
      "x": -5,
      "y": 12,
      "z": 0,
      "name": "Empty"
    },
    {
      "x": -5,
      "y": 13,
      "z": 0,
      "name": "Empty"
    },
    {
      "x": -5,
      "y": 14,
      "z": 0,
      "name": "Empty"
    },
    {
      "x": -5,
      "y": 15,
      "z": 0,
      "name": "Rock_Slate_Brick_Half",
      "rotation": 8
    },
    {
      "x": -5,
      "y": 1,
      "z": 1,
      "name": "Soil_Dirt"
    },
    {
      "x": -5,
      "y": 2,
      "z": 1,
      "name": "Soil_Dirt"
    },
    {
      "x": -5,
      "y": 3,
      "z": 1,
      "name": "Soil_Dirt"
    },
    {
      "x": -5,
      "y": 4,
      "z": 1,
      "name": "Soil_Dirt"
    },
    {
      "x": -5,
      "y": 5,
      "z": 1,
      "name": "Soil_Dirt"
    },
    {
      "x": -5,
      "y": 6,
      "z": 1,
      "name": "Soil_Dirt"
    },
    {
      "x": -5,
      "y": 7,
      "z": 1,
      "name": "Soil_Dirt"
    },
    {
      "x": -5,
      "y": 8,
      "z": 1,
      "name": "Soil_Dirt"
    },
    {
      "x": -5,
      "y": 9,
      "z": 1,
      "name": "Soil_Dirt"
    },
    {
      "x": -5,
      "y": 10,
      "z": 1,
      "name": "Rock_Slate_Brick_Ornate"
    },
    {
      "x": -5,
      "y": 11,
      "z": 1,
      "name": "Empty"
    },
    {
      "x": -5,
      "y": 12,
      "z": 1,
      "name": "Empty"
    },
    {
      "x": -5,
      "y": 13,
      "z": 1,
      "name": "Empty"
    },
    {
      "x": -5,
      "y": 14,
      "z": 1,
      "name": "Empty"
    },
    {
      "x": -5,
      "y": 15,
      "z": 1,
      "name": "Empty"
    },
    {
      "x": -5,
      "y": 1,
      "z": 2,
      "name": "Soil_Dirt"
    },
    {
      "x": -5,
      "y": 2,
      "z": 2,
      "name": "Soil_Dirt"
    },
    {
      "x": -5,
      "y": 3,
      "z": 2,
      "name": "Soil_Dirt"
    },
    {
      "x": -5,
      "y": 4,
      "z": 2,
      "name": "Soil_Dirt"
    },
    {
      "x": -5,
      "y": 5,
      "z": 2,
      "name": "Soil_Dirt"
    },
    {
      "x": -5,
      "y": 6,
      "z": 2,
      "name": "Soil_Dirt"
    },
    {
      "x": -5,
      "y": 7,
      "z": 2,
      "name": "Soil_Dirt"
    },
    {
      "x": -5,
      "y": 8,
      "z": 2,
      "name": "Soil_Dirt"
    },
    {
      "x": -5,
      "y": 9,
      "z": 2,
      "name": "Soil_Dirt"
    },
    {
      "x": -5,
      "y": 10,
      "z": 2,
      "name": "Rock_Slate_Brick_Ornate"
    },
    {
      "x": -5,
      "y": 11,
      "z": 2,
      "name": "Empty"
    },
    {
      "x": -5,
      "y": 12,
      "z": 2,
      "name": "Empty"
    },
    {
      "x": -5,
      "y": 13,
      "z": 2,
      "name": "Empty"
    },
    {
      "x": -5,
      "y": 14,
      "z": 2,
      "name": "Empty"
    },
    {
      "x": -5,
      "y": 15,
      "z": 2,
      "name": "Empty"
    },
    {
      "x": -5,
      "y": 1,
      "z": 3,
      "name": "Soil_Dirt"
    },
    {
      "x": -5,
      "y": 2,
      "z": 3,
      "name": "Soil_Dirt"
    },
    {
      "x": -5,
      "y": 3,
      "z": 3,
      "name": "Soil_Dirt"
    },
    {
      "x": -5,
      "y": 4,
      "z": 3,
      "name": "Soil_Dirt"
    },
    {
      "x": -5,
      "y": 5,
      "z": 3,
      "name": "Soil_Dirt"
    },
    {
      "x": -5,
      "y": 6,
      "z": 3,
      "name": "Soil_Dirt"
    },
    {
      "x": -5,
      "y": 7,
      "z": 3,
      "name": "Soil_Dirt"
    },
    {
      "x": -5,
      "y": 8,
      "z": 3,
      "name": "Soil_Dirt"
    },
    {
      "x": -5,
      "y": 9,
      "z": 3,
      "name": "Soil_Dirt"
    },
    {
      "x": -5,
      "y": 10,
      "z": 3,
      "name": "Rock_Slate_Brick_Ornate"
    },
    {
      "x": -5,
      "y": 11,
      "z": 3,
      "name": "Empty"
    },
    {
      "x": -5,
      "y": 12,
      "z": 3,
      "name": "Empty"
    },
    {
      "x": -5,
      "y": 13,
      "z": 3,
      "name": "Empty"
    },
    {
      "x": -5,
      "y": 14,
      "z": 3,
      "name": "Empty"
    },
    {
      "x": -5,
      "y": 15,
      "z": 3,
      "name": "Empty"
    },
    {
      "x": -5,
      "y": 2,
      "z": 4,
      "name": "Soil_Dirt"
    },
    {
      "x": -5,
      "y": 3,
      "z": 4,
      "name": "Soil_Dirt"
    },
    {
      "x": -5,
      "y": 4,
      "z": 4,
      "name": "Soil_Dirt"
    },
    {
      "x": -5,
      "y": 5,
      "z": 4,
      "name": "Soil_Dirt"
    },
    {
      "x": -5,
      "y": 6,
      "z": 4,
      "name": "Soil_Dirt"
    },
    {
      "x": -5,
      "y": 7,
      "z": 4,
      "name": "Soil_Dirt"
    },
    {
      "x": -5,
      "y": 8,
      "z": 4,
      "name": "Soil_Dirt"
    },
    {
      "x": -5,
      "y": 9,
      "z": 4,
      "name": "Soil_Dirt"
    },
    {
      "x": -5,
      "y": 10,
      "z": 4,
      "name": "Rock_Slate_Brick_Ornate"
    },
    {
      "x": -5,
      "y": 11,
      "z": 4,
      "name": "Empty"
    },
    {
      "x": -5,
      "y": 12,
      "z": 4,
      "name": "Empty"
    },
    {
      "x": -5,
      "y": 13,
      "z": 4,
      "name": "Empty"
    },
    {
      "x": -5,
      "y": 14,
      "z": 4,
      "name": "Empty"
    },
    {
      "x": -5,
      "y": 15,
      "z": 4,
      "name": "Empty"
    },
    {
      "x": -5,
      "y": 16,
      "z": 4,
      "name": "Empty"
    },
    {
      "x": -5,
      "y": 17,
      "z": 4,
      "name": "Empty"
    },
    {
      "x": -5,
      "y": 18,
      "z": 4,
      "name": "Empty"
    },
    {
      "x": -5,
      "y": 19,
      "z": 4,
      "name": "Empty"
    },
    {
      "x": -5,
      "y": 3,
      "z": 5,
      "name": "Soil_Dirt"
    },
    {
      "x": -5,
      "y": 4,
      "z": 5,
      "name": "Soil_Dirt"
    },
    {
      "x": -5,
      "y": 5,
      "z": 5,
      "name": "Soil_Dirt"
    },
    {
      "x": -5,
      "y": 6,
      "z": 5,
      "name": "Soil_Dirt"
    },
    {
      "x": -5,
      "y": 7,
      "z": 5,
      "name": "Soil_Dirt"
    },
    {
      "x": -5,
      "y": 8,
      "z": 5,
      "name": "Soil_Dirt"
    },
    {
      "x": -5,
      "y": 9,
      "z": 5,
      "name": "Soil_Dirt"
    },
    {
      "x": -5,
      "y": 10,
      "z": 5,
      "name": "Rock_Slate_Brick_Ornate"
    },
    {
      "x": -5,
      "y": 11,
      "z": 5,
      "name": "Empty"
    },
    {
      "x": -5,
      "y": 12,
      "z": 5,
      "name": "Empty"
    },
    {
      "x": -5,
      "y": 13,
      "z": 5,
      "name": "Empty"
    },
    {
      "x": -5,
      "y": 14,
      "z": 5,
      "name": "Empty"
    },
    {
      "x": -5,
      "y": 15,
      "z": 5,
      "name": "Empty"
    },
    {
      "x": -5,
      "y": 3,
      "z": 6,
      "name": "Wood_Dry_Roots"
    },
    {
      "x": -5,
      "y": 4,
      "z": 6,
      "name": "Soil_Dirt"
    },
    {
      "x": -5,
      "y": 5,
      "z": 6,
      "name": "Soil_Dirt"
    },
    {
      "x": -5,
      "y": 6,
      "z": 6,
      "name": "Soil_Dirt"
    },
    {
      "x": -5,
      "y": 7,
      "z": 6,
      "name": "Soil_Dirt"
    },
    {
      "x": -5,
      "y": 8,
      "z": 6,
      "name": "Soil_Dirt"
    },
    {
      "x": -5,
      "y": 9,
      "z": 6,
      "name": "Soil_Dirt"
    },
    {
      "x": -5,
      "y": 10,
      "z": 6,
      "name": "Soil_Grass"
    },
    {
      "x": -5,
      "y": 11,
      "z": 6,
      "name": "Rock_Slate_Brick_Decorative"
    },
    {
      "x": -5,
      "y": 12,
      "z": 6,
      "name": "Empty"
    },
    {
      "x": -5,
      "y": 13,
      "z": 6,
      "name": "Empty"
    },
    {
      "x": -5,
      "y": 14,
      "z": 6,
      "name": "Empty"
    },
    {
      "x": -5,
      "y": 15,
      "z": 6,
      "name": "Empty"
    },
    {
      "x": -5,
      "y": 5,
      "z": 7,
      "name": "Soil_Dirt"
    },
    {
      "x": -5,
      "y": 6,
      "z": 7,
      "name": "Soil_Dirt"
    },
    {
      "x": -5,
      "y": 7,
      "z": 7,
      "name": "Soil_Dirt"
    },
    {
      "x": -5,
      "y": 8,
      "z": 7,
      "name": "Soil_Dirt"
    },
    {
      "x": -5,
      "y": 9,
      "z": 7,
      "name": "Soil_Dirt"
    },
    {
      "x": -5,
      "y": 10,
      "z": 7,
      "name": "Soil_Grass"
    },
    {
      "x": -4,
      "y": 6,
      "z": -7,
      "name": "Soil_Dirt"
    },
    {
      "x": -4,
      "y": 7,
      "z": -7,
      "name": "Soil_Dirt"
    },
    {
      "x": -4,
      "y": 8,
      "z": -7,
      "name": "Soil_Dirt"
    },
    {
      "x": -4,
      "y": 9,
      "z": -7,
      "name": "Soil_Grass"
    },
    {
      "x": -4,
      "y": 10,
      "z": -7,
      "name": "Plant_Grass_Sharp_Tall",
      "support": 15
    },
    {
      "x": -4,
      "y": 11,
      "z": -7,
      "name": "Plant_Grass_Sharp_Tall",
      "filler": 1024
    },
    {
      "x": -4,
      "y": 3,
      "z": -6,
      "name": "Soil_Dirt"
    },
    {
      "x": -4,
      "y": 4,
      "z": -6,
      "name": "Soil_Dirt"
    },
    {
      "x": -4,
      "y": 5,
      "z": -6,
      "name": "Soil_Dirt"
    },
    {
      "x": -4,
      "y": 6,
      "z": -6,
      "name": "Soil_Dirt"
    },
    {
      "x": -4,
      "y": 7,
      "z": -6,
      "name": "Soil_Dirt"
    },
    {
      "x": -4,
      "y": 8,
      "z": -6,
      "name": "Soil_Dirt"
    },
    {
      "x": -4,
      "y": 9,
      "z": -6,
      "name": "Soil_Dirt"
    },
    {
      "x": -4,
      "y": 10,
      "z": -6,
      "name": "Rock_Slate_Brick_Stairs",
      "rotation": 3
    },
    {
      "x": -4,
      "y": 1,
      "z": -5,
      "name": "Wood_Dry_Roots"
    },
    {
      "x": -4,
      "y": 2,
      "z": -5,
      "name": "Soil_Dirt"
    },
    {
      "x": -4,
      "y": 3,
      "z": -5,
      "name": "Soil_Dirt"
    },
    {
      "x": -4,
      "y": 4,
      "z": -5,
      "name": "Soil_Dirt"
    },
    {
      "x": -4,
      "y": 5,
      "z": -5,
      "name": "Soil_Dirt"
    },
    {
      "x": -4,
      "y": 6,
      "z": -5,
      "name": "Soil_Dirt"
    },
    {
      "x": -4,
      "y": 7,
      "z": -5,
      "name": "Soil_Dirt"
    },
    {
      "x": -4,
      "y": 8,
      "z": -5,
      "name": "Soil_Dirt"
    },
    {
      "x": -4,
      "y": 9,
      "z": -5,
      "name": "Soil_Dirt"
    },
    {
      "x": -4,
      "y": 10,
      "z": -5,
      "name": "*Rock_Slate_Brick_Stairs_State_Definitions_Inverted_Corner_Right",
      "rotation": 3
    },
    {
      "x": -4,
      "y": 11,
      "z": -5,
      "name": "Empty"
    },
    {
      "x": -4,
      "y": 12,
      "z": -5,
      "name": "Empty"
    },
    {
      "x": -4,
      "y": 1,
      "z": -4,
      "name": "Soil_Dirt"
    },
    {
      "x": -4,
      "y": 2,
      "z": -4,
      "name": "Soil_Dirt"
    },
    {
      "x": -4,
      "y": 3,
      "z": -4,
      "name": "Soil_Dirt"
    },
    {
      "x": -4,
      "y": 4,
      "z": -4,
      "name": "Soil_Dirt"
    },
    {
      "x": -4,
      "y": 5,
      "z": -4,
      "name": "Soil_Dirt"
    },
    {
      "x": -4,
      "y": 6,
      "z": -4,
      "name": "Soil_Dirt"
    },
    {
      "x": -4,
      "y": 7,
      "z": -4,
      "name": "Soil_Dirt"
    },
    {
      "x": -4,
      "y": 8,
      "z": -4,
      "name": "Soil_Dirt"
    },
    {
      "x": -4,
      "y": 9,
      "z": -4,
      "name": "Soil_Dirt"
    },
    {
      "x": -4,
      "y": 10,
      "z": -4,
      "name": "Soil_Grass"
    },
    {
      "x": -4,
      "y": 11,
      "z": -4,
      "name": "Rock_Slate_Brick_Stairs",
      "rotation": 2
    },
    {
      "x": -4,
      "y": 12,
      "z": -4,
      "name": "Empty"
    },
    {
      "x": -4,
      "y": 13,
      "z": -4,
      "name": "Empty"
    },
    {
      "x": -4,
      "y": 14,
      "z": -4,
      "name": "Empty"
    },
    {
      "x": -4,
      "y": 15,
      "z": -4,
      "name": "Rock_Slate_Cobble_Stairs",
      "rotation": 11
    },
    {
      "x": -4,
      "y": 1,
      "z": -3,
      "name": "Soil_Dirt"
    },
    {
      "x": -4,
      "y": 2,
      "z": -3,
      "name": "Soil_Dirt"
    },
    {
      "x": -4,
      "y": 3,
      "z": -3,
      "name": "Soil_Dirt"
    },
    {
      "x": -4,
      "y": 4,
      "z": -3,
      "name": "Soil_Dirt"
    },
    {
      "x": -4,
      "y": 5,
      "z": -3,
      "name": "Soil_Dirt"
    },
    {
      "x": -4,
      "y": 6,
      "z": -3,
      "name": "Soil_Dirt"
    },
    {
      "x": -4,
      "y": 7,
      "z": -3,
      "name": "Soil_Dirt"
    },
    {
      "x": -4,
      "y": 8,
      "z": -3,
      "name": "Soil_Dirt"
    },
    {
      "x": -4,
      "y": 9,
      "z": -3,
      "name": "Soil_Dirt"
    },
    {
      "x": -4,
      "y": 10,
      "z": -3,
      "name": "Soil_Grass"
    },
    {
      "x": -4,
      "y": 11,
      "z": -3,
      "name": "Rock_Slate_Brick"
    },
    {
      "x": -4,
      "y": 12,
      "z": -3,
      "name": "Empty"
    },
    {
      "x": -4,
      "y": 13,
      "z": -3,
      "name": "Empty"
    },
    {
      "x": -4,
      "y": 14,
      "z": -3,
      "name": "Empty"
    },
    {
      "x": -4,
      "y": 15,
      "z": -3,
      "name": "Empty"
    },
    {
      "x": -4,
      "y": 0,
      "z": -2,
      "name": "Soil_Dirt"
    },
    {
      "x": -4,
      "y": 1,
      "z": -2,
      "name": "Soil_Dirt"
    },
    {
      "x": -4,
      "y": 2,
      "z": -2,
      "name": "Soil_Dirt"
    },
    {
      "x": -4,
      "y": 3,
      "z": -2,
      "name": "Soil_Dirt"
    },
    {
      "x": -4,
      "y": 4,
      "z": -2,
      "name": "Soil_Dirt"
    },
    {
      "x": -4,
      "y": 5,
      "z": -2,
      "name": "Soil_Dirt"
    },
    {
      "x": -4,
      "y": 6,
      "z": -2,
      "name": "Soil_Dirt"
    },
    {
      "x": -4,
      "y": 7,
      "z": -2,
      "name": "Soil_Dirt"
    },
    {
      "x": -4,
      "y": 8,
      "z": -2,
      "name": "Soil_Dirt"
    },
    {
      "x": -4,
      "y": 9,
      "z": -2,
      "name": "Soil_Dirt"
    },
    {
      "x": -4,
      "y": 10,
      "z": -2,
      "name": "Soil_Grass"
    },
    {
      "x": -4,
      "y": 11,
      "z": -2,
      "name": "Rock_Slate_Brick"
    },
    {
      "x": -4,
      "y": 12,
      "z": -2,
      "name": "Furniture_Temple_Dark_Statue_Gaia",
      "rotation": 1
    },
    {
      "x": -4,
      "y": 13,
      "z": -2,
      "name": "Furniture_Temple_Dark_Statue_Gaia",
      "filler": 1024,
      "rotation": 1
    },
    {
      "x": -4,
      "y": 14,
      "z": -2,
      "name": "Furniture_Temple_Dark_Statue_Gaia",
      "filler": 2048,
      "rotation": 1
    },
    {
      "x": -4,
      "y": 15,
      "z": -2,
      "name": "Empty"
    },
    {
      "x": -4,
      "y": 0,
      "z": -1,
      "name": "Soil_Dirt"
    },
    {
      "x": -4,
      "y": 1,
      "z": -1,
      "name": "Soil_Dirt"
    },
    {
      "x": -4,
      "y": 2,
      "z": -1,
      "name": "Soil_Dirt"
    },
    {
      "x": -4,
      "y": 3,
      "z": -1,
      "name": "Soil_Dirt"
    },
    {
      "x": -4,
      "y": 4,
      "z": -1,
      "name": "Soil_Dirt"
    },
    {
      "x": -4,
      "y": 5,
      "z": -1,
      "name": "Soil_Dirt"
    },
    {
      "x": -4,
      "y": 6,
      "z": -1,
      "name": "Soil_Dirt"
    },
    {
      "x": -4,
      "y": 7,
      "z": -1,
      "name": "Soil_Dirt"
    },
    {
      "x": -4,
      "y": 8,
      "z": -1,
      "name": "Soil_Dirt"
    },
    {
      "x": -4,
      "y": 9,
      "z": -1,
      "name": "Soil_Dirt"
    },
    {
      "x": -4,
      "y": 10,
      "z": -1,
      "name": "Soil_Grass"
    },
    {
      "x": -4,
      "y": 11,
      "z": -1,
      "name": "Rock_Slate_Brick"
    },
    {
      "x": -4,
      "y": 12,
      "z": -1,
      "name": "Empty"
    },
    {
      "x": -4,
      "y": 13,
      "z": -1,
      "name": "Empty"
    },
    {
      "x": -4,
      "y": 14,
      "z": -1,
      "name": "Empty"
    },
    {
      "x": -4,
      "y": 15,
      "z": -1,
      "name": "Empty"
    },
    {
      "x": -4,
      "y": 0,
      "z": 0,
      "name": "Soil_Dirt"
    },
    {
      "x": -4,
      "y": 1,
      "z": 0,
      "name": "Soil_Dirt"
    },
    {
      "x": -4,
      "y": 2,
      "z": 0,
      "name": "Soil_Dirt"
    },
    {
      "x": -4,
      "y": 3,
      "z": 0,
      "name": "Soil_Dirt"
    },
    {
      "x": -4,
      "y": 4,
      "z": 0,
      "name": "Soil_Dirt"
    },
    {
      "x": -4,
      "y": 5,
      "z": 0,
      "name": "Soil_Dirt"
    },
    {
      "x": -4,
      "y": 6,
      "z": 0,
      "name": "Soil_Dirt"
    },
    {
      "x": -4,
      "y": 7,
      "z": 0,
      "name": "Soil_Dirt"
    },
    {
      "x": -4,
      "y": 8,
      "z": 0,
      "name": "Soil_Dirt"
    },
    {
      "x": -4,
      "y": 9,
      "z": 0,
      "name": "Soil_Dirt"
    },
    {
      "x": -4,
      "y": 10,
      "z": 0,
      "name": "Soil_Grass"
    },
    {
      "x": -4,
      "y": 11,
      "z": 0,
      "name": "Rock_Slate_Brick_Decorative"
    },
    {
      "x": -4,
      "y": 12,
      "z": 0,
      "name": "Plant_Bush_Dead_Tall",
      "support": 15
    },
    {
      "x": -4,
      "y": 13,
      "z": 0,
      "name": "Empty"
    },
    {
      "x": -4,
      "y": 14,
      "z": 0,
      "name": "Empty"
    },
    {
      "x": -4,
      "y": 15,
      "z": 0,
      "name": "Rock_Slate_Brick_Half",
      "rotation": 8
    },
    {
      "x": -4,
      "y": 0,
      "z": 1,
      "name": "Soil_Dirt"
    },
    {
      "x": -4,
      "y": 1,
      "z": 1,
      "name": "Soil_Dirt"
    },
    {
      "x": -4,
      "y": 2,
      "z": 1,
      "name": "Soil_Dirt"
    },
    {
      "x": -4,
      "y": 3,
      "z": 1,
      "name": "Soil_Dirt"
    },
    {
      "x": -4,
      "y": 4,
      "z": 1,
      "name": "Soil_Dirt"
    },
    {
      "x": -4,
      "y": 5,
      "z": 1,
      "name": "Soil_Dirt"
    },
    {
      "x": -4,
      "y": 6,
      "z": 1,
      "name": "Soil_Dirt"
    },
    {
      "x": -4,
      "y": 7,
      "z": 1,
      "name": "Soil_Dirt"
    },
    {
      "x": -4,
      "y": 8,
      "z": 1,
      "name": "Soil_Dirt"
    },
    {
      "x": -4,
      "y": 9,
      "z": 1,
      "name": "Soil_Dirt"
    },
    {
      "x": -4,
      "y": 10,
      "z": 1,
      "name": "Rock_Slate_Brick_Ornate"
    },
    {
      "x": -4,
      "y": 11,
      "z": 1,
      "name": "Empty"
    },
    {
      "x": -4,
      "y": 12,
      "z": 1,
      "name": "Empty"
    },
    {
      "x": -4,
      "y": 13,
      "z": 1,
      "name": "Empty"
    },
    {
      "x": -4,
      "y": 14,
      "z": 1,
      "name": "Empty"
    },
    {
      "x": -4,
      "y": 15,
      "z": 1,
      "name": "Empty"
    },
    {
      "x": -4,
      "y": 18,
      "z": 1,
      "name": "Rock_Slate_Brick_Stairs",
      "rotation": 9
    },
    {
      "x": -4,
      "y": 0,
      "z": 2,
      "name": "Soil_Dirt"
    },
    {
      "x": -4,
      "y": 1,
      "z": 2,
      "name": "Soil_Dirt"
    },
    {
      "x": -4,
      "y": 2,
      "z": 2,
      "name": "Soil_Dirt"
    },
    {
      "x": -4,
      "y": 3,
      "z": 2,
      "name": "Soil_Dirt"
    },
    {
      "x": -4,
      "y": 4,
      "z": 2,
      "name": "Soil_Dirt"
    },
    {
      "x": -4,
      "y": 5,
      "z": 2,
      "name": "Soil_Dirt"
    },
    {
      "x": -4,
      "y": 6,
      "z": 2,
      "name": "Soil_Dirt"
    },
    {
      "x": -4,
      "y": 7,
      "z": 2,
      "name": "Soil_Dirt"
    },
    {
      "x": -4,
      "y": 8,
      "z": 2,
      "name": "Soil_Dirt"
    },
    {
      "x": -4,
      "y": 9,
      "z": 2,
      "name": "Soil_Dirt"
    },
    {
      "x": -4,
      "y": 10,
      "z": 2,
      "name": "Rock_Slate_Brick_Ornate"
    },
    {
      "x": -4,
      "y": 11,
      "z": 2,
      "name": "Empty"
    },
    {
      "x": -4,
      "y": 12,
      "z": 2,
      "name": "Empty"
    },
    {
      "x": -4,
      "y": 13,
      "z": 2,
      "name": "Empty"
    },
    {
      "x": -4,
      "y": 14,
      "z": 2,
      "name": "Empty"
    },
    {
      "x": -4,
      "y": 15,
      "z": 2,
      "name": "Empty"
    },
    {
      "x": -4,
      "y": 18,
      "z": 2,
      "name": "Rock_Slate_Brick_Stairs",
      "rotation": 9
    },
    {
      "x": -4,
      "y": 1,
      "z": 3,
      "name": "Soil_Dirt"
    },
    {
      "x": -4,
      "y": 2,
      "z": 3,
      "name": "Soil_Dirt"
    },
    {
      "x": -4,
      "y": 3,
      "z": 3,
      "name": "Soil_Dirt"
    },
    {
      "x": -4,
      "y": 4,
      "z": 3,
      "name": "Soil_Dirt"
    },
    {
      "x": -4,
      "y": 5,
      "z": 3,
      "name": "Soil_Dirt"
    },
    {
      "x": -4,
      "y": 6,
      "z": 3,
      "name": "Soil_Dirt"
    },
    {
      "x": -4,
      "y": 7,
      "z": 3,
      "name": "Soil_Dirt"
    },
    {
      "x": -4,
      "y": 8,
      "z": 3,
      "name": "Soil_Dirt"
    },
    {
      "x": -4,
      "y": 9,
      "z": 3,
      "name": "Soil_Dirt"
    },
    {
      "x": -4,
      "y": 10,
      "z": 3,
      "name": "Rock_Slate_Brick_Ornate"
    },
    {
      "x": -4,
      "y": 11,
      "z": 3,
      "name": "Empty"
    },
    {
      "x": -4,
      "y": 12,
      "z": 3,
      "name": "Empty"
    },
    {
      "x": -4,
      "y": 13,
      "z": 3,
      "name": "Empty"
    },
    {
      "x": -4,
      "y": 14,
      "z": 3,
      "name": "Empty"
    },
    {
      "x": -4,
      "y": 15,
      "z": 3,
      "name": "Empty"
    },
    {
      "x": -4,
      "y": 18,
      "z": 3,
      "name": "Rock_Slate_Brick_Stairs",
      "rotation": 9
    },
    {
      "x": -4,
      "y": 19,
      "z": 3,
      "name": "Rock_Slate_Brick_Ornate"
    },
    {
      "x": -4,
      "y": 20,
      "z": 3,
      "name": "Rock_Slate_Brick_Decorative"
    },
    {
      "x": -4,
      "y": 21,
      "z": 3,
      "name": "Rock_Slate_Brick_Wall",
      "rotation": 2
    },
    {
      "x": -4,
      "y": 1,
      "z": 4,
      "name": "Soil_Dirt"
    },
    {
      "x": -4,
      "y": 2,
      "z": 4,
      "name": "Soil_Dirt"
    },
    {
      "x": -4,
      "y": 3,
      "z": 4,
      "name": "Soil_Dirt"
    },
    {
      "x": -4,
      "y": 4,
      "z": 4,
      "name": "Soil_Dirt"
    },
    {
      "x": -4,
      "y": 5,
      "z": 4,
      "name": "Soil_Dirt"
    },
    {
      "x": -4,
      "y": 6,
      "z": 4,
      "name": "Soil_Dirt"
    },
    {
      "x": -4,
      "y": 7,
      "z": 4,
      "name": "Soil_Dirt"
    },
    {
      "x": -4,
      "y": 8,
      "z": 4,
      "name": "Soil_Dirt"
    },
    {
      "x": -4,
      "y": 9,
      "z": 4,
      "name": "Soil_Dirt"
    },
    {
      "x": -4,
      "y": 10,
      "z": 4,
      "name": "Rock_Slate_Brick_Ornate"
    },
    {
      "x": -4,
      "y": 11,
      "z": 4,
      "name": "Empty"
    },
    {
      "x": -4,
      "y": 12,
      "z": 4,
      "name": "Empty"
    },
    {
      "x": -4,
      "y": 13,
      "z": 4,
      "name": "Empty"
    },
    {
      "x": -4,
      "y": 14,
      "z": 4,
      "name": "Empty"
    },
    {
      "x": -4,
      "y": 15,
      "z": 4,
      "name": "Empty"
    },
    {
      "x": -4,
      "y": 18,
      "z": 4,
      "name": "*Furniture_Crude_Trapdoor_State_Definitions_CloseDoorOut",
      "rotation": 3
    },
    {
      "x": -4,
      "y": 19,
      "z": 4,
      "name": "Rock_Slate_Brick_Decorative"
    },
    {
      "x": -4,
      "y": 2,
      "z": 5,
      "name": "Soil_Dirt"
    },
    {
      "x": -4,
      "y": 3,
      "z": 5,
      "name": "Soil_Dirt"
    },
    {
      "x": -4,
      "y": 4,
      "z": 5,
      "name": "Soil_Dirt"
    },
    {
      "x": -4,
      "y": 5,
      "z": 5,
      "name": "Soil_Dirt"
    },
    {
      "x": -4,
      "y": 6,
      "z": 5,
      "name": "Soil_Dirt"
    },
    {
      "x": -4,
      "y": 7,
      "z": 5,
      "name": "Soil_Dirt"
    },
    {
      "x": -4,
      "y": 8,
      "z": 5,
      "name": "Soil_Dirt"
    },
    {
      "x": -4,
      "y": 9,
      "z": 5,
      "name": "Soil_Dirt"
    },
    {
      "x": -4,
      "y": 10,
      "z": 5,
      "name": "Rock_Slate_Brick_Ornate"
    },
    {
      "x": -4,
      "y": 11,
      "z": 5,
      "name": "Empty"
    },
    {
      "x": -4,
      "y": 12,
      "z": 5,
      "name": "Empty"
    },
    {
      "x": -4,
      "y": 13,
      "z": 5,
      "name": "Empty"
    },
    {
      "x": -4,
      "y": 14,
      "z": 5,
      "name": "Empty"
    },
    {
      "x": -4,
      "y": 15,
      "z": 5,
      "name": "Empty"
    },
    {
      "x": -4,
      "y": 18,
      "z": 5,
      "name": "Rock_Slate_Brick_Stairs",
      "rotation": 9
    },
    {
      "x": -4,
      "y": 19,
      "z": 5,
      "name": "Rock_Slate_Brick_Ornate"
    },
    {
      "x": -4,
      "y": 20,
      "z": 5,
      "name": "Rock_Slate_Brick_Decorative"
    },
    {
      "x": -4,
      "y": 21,
      "z": 5,
      "name": "Rock_Slate_Brick_Wall",
      "rotation": 2
    },
    {
      "x": -4,
      "y": 3,
      "z": 6,
      "name": "Soil_Dirt"
    },
    {
      "x": -4,
      "y": 4,
      "z": 6,
      "name": "Soil_Dirt"
    },
    {
      "x": -4,
      "y": 5,
      "z": 6,
      "name": "Soil_Dirt"
    },
    {
      "x": -4,
      "y": 6,
      "z": 6,
      "name": "Soil_Dirt"
    },
    {
      "x": -4,
      "y": 7,
      "z": 6,
      "name": "Soil_Dirt"
    },
    {
      "x": -4,
      "y": 8,
      "z": 6,
      "name": "Soil_Dirt"
    },
    {
      "x": -4,
      "y": 9,
      "z": 6,
      "name": "Soil_Dirt"
    },
    {
      "x": -4,
      "y": 10,
      "z": 6,
      "name": "Soil_Grass"
    },
    {
      "x": -4,
      "y": 11,
      "z": 6,
      "name": "Rock_Slate_Brick_Decorative"
    },
    {
      "x": -4,
      "y": 12,
      "z": 6,
      "name": "Empty"
    },
    {
      "x": -4,
      "y": 13,
      "z": 6,
      "name": "Empty"
    },
    {
      "x": -4,
      "y": 14,
      "z": 6,
      "name": "Empty"
    },
    {
      "x": -4,
      "y": 15,
      "z": 6,
      "name": "Empty"
    },
    {
      "x": -4,
      "y": 18,
      "z": 6,
      "name": "Rock_Slate_Brick_Stairs",
      "rotation": 9
    },
    {
      "x": -4,
      "y": 3,
      "z": 7,
      "name": "Wood_Dry_Roots"
    },
    {
      "x": -4,
      "y": 4,
      "z": 7,
      "name": "Soil_Dirt"
    },
    {
      "x": -4,
      "y": 5,
      "z": 7,
      "name": "Soil_Dirt"
    },
    {
      "x": -4,
      "y": 6,
      "z": 7,
      "name": "Soil_Dirt"
    },
    {
      "x": -4,
      "y": 7,
      "z": 7,
      "name": "Soil_Dirt"
    },
    {
      "x": -4,
      "y": 8,
      "z": 7,
      "name": "Soil_Dirt"
    },
    {
      "x": -4,
      "y": 9,
      "z": 7,
      "name": "Soil_Dirt"
    },
    {
      "x": -4,
      "y": 10,
      "z": 7,
      "name": "Soil_Grass"
    },
    {
      "x": -4,
      "y": 18,
      "z": 7,
      "name": "Rock_Slate_Brick_Stairs",
      "rotation": 9
    },
    {
      "x": -4,
      "y": 6,
      "z": 8,
      "name": "Soil_Dirt"
    },
    {
      "x": -4,
      "y": 7,
      "z": 8,
      "name": "Soil_Dirt"
    },
    {
      "x": -4,
      "y": 8,
      "z": 8,
      "name": "Soil_Dirt"
    },
    {
      "x": -4,
      "y": 9,
      "z": 8,
      "name": "Soil_Grass"
    },
    {
      "x": -3,
      "y": 6,
      "z": -8,
      "name": "Soil_Dirt"
    },
    {
      "x": -3,
      "y": 7,
      "z": -8,
      "name": "Soil_Dirt"
    },
    {
      "x": -3,
      "y": 8,
      "z": -8,
      "name": "Soil_Dirt"
    },
    {
      "x": -3,
      "y": 9,
      "z": -8,
      "name": "Soil_Grass"
    },
    {
      "x": -3,
      "y": 3,
      "z": -7,
      "name": "Soil_Dirt"
    },
    {
      "x": -3,
      "y": 4,
      "z": -7,
      "name": "Soil_Dirt"
    },
    {
      "x": -3,
      "y": 5,
      "z": -7,
      "name": "Soil_Dirt"
    },
    {
      "x": -3,
      "y": 6,
      "z": -7,
      "name": "Soil_Dirt"
    },
    {
      "x": -3,
      "y": 7,
      "z": -7,
      "name": "Soil_Dirt"
    },
    {
      "x": -3,
      "y": 8,
      "z": -7,
      "name": "Soil_Dirt"
    },
    {
      "x": -3,
      "y": 9,
      "z": -7,
      "name": "Soil_Dirt"
    },
    {
      "x": -3,
      "y": 10,
      "z": -7,
      "name": "Rock_Slate_Brick_Stairs",
      "rotation": 2
    },
    {
      "x": -3,
      "y": 2,
      "z": -6,
      "name": "Soil_Dirt"
    },
    {
      "x": -3,
      "y": 3,
      "z": -6,
      "name": "Soil_Dirt"
    },
    {
      "x": -3,
      "y": 4,
      "z": -6,
      "name": "Soil_Dirt"
    },
    {
      "x": -3,
      "y": 5,
      "z": -6,
      "name": "Soil_Dirt"
    },
    {
      "x": -3,
      "y": 6,
      "z": -6,
      "name": "Soil_Dirt"
    },
    {
      "x": -3,
      "y": 7,
      "z": -6,
      "name": "Soil_Dirt"
    },
    {
      "x": -3,
      "y": 8,
      "z": -6,
      "name": "Soil_Dirt"
    },
    {
      "x": -3,
      "y": 9,
      "z": -6,
      "name": "Soil_Dirt"
    },
    {
      "x": -3,
      "y": 10,
      "z": -6,
      "name": "Soil_Grass"
    },
    {
      "x": -3,
      "y": 11,
      "z": -6,
      "name": "*Rock_Slate_Brick_Stairs_State_Definitions_Corner_Left",
      "rotation": 2
    },
    {
      "x": -3,
      "y": 12,
      "z": -6,
      "name": "Empty"
    },
    {
      "x": -3,
      "y": 1,
      "z": -5,
      "name": "Soil_Dirt"
    },
    {
      "x": -3,
      "y": 2,
      "z": -5,
      "name": "Soil_Dirt"
    },
    {
      "x": -3,
      "y": 3,
      "z": -5,
      "name": "Soil_Dirt"
    },
    {
      "x": -3,
      "y": 4,
      "z": -5,
      "name": "Soil_Dirt"
    },
    {
      "x": -3,
      "y": 5,
      "z": -5,
      "name": "Soil_Dirt"
    },
    {
      "x": -3,
      "y": 6,
      "z": -5,
      "name": "Soil_Dirt"
    },
    {
      "x": -3,
      "y": 7,
      "z": -5,
      "name": "Soil_Dirt"
    },
    {
      "x": -3,
      "y": 8,
      "z": -5,
      "name": "Soil_Dirt"
    },
    {
      "x": -3,
      "y": 9,
      "z": -5,
      "name": "Soil_Dirt"
    },
    {
      "x": -3,
      "y": 10,
      "z": -5,
      "name": "Soil_Grass"
    },
    {
      "x": -3,
      "y": 11,
      "z": -5,
      "name": "Rock_Slate_Brick_Stairs",
      "rotation": 3
    },
    {
      "x": -3,
      "y": 12,
      "z": -5,
      "name": "Empty"
    },
    {
      "x": -3,
      "y": 13,
      "z": -5,
      "name": "Empty"
    },
    {
      "x": -3,
      "y": 1,
      "z": -4,
      "name": "Soil_Dirt"
    },
    {
      "x": -3,
      "y": 2,
      "z": -4,
      "name": "Soil_Dirt"
    },
    {
      "x": -3,
      "y": 3,
      "z": -4,
      "name": "Soil_Dirt"
    },
    {
      "x": -3,
      "y": 4,
      "z": -4,
      "name": "Soil_Dirt"
    },
    {
      "x": -3,
      "y": 5,
      "z": -4,
      "name": "Soil_Dirt"
    },
    {
      "x": -3,
      "y": 6,
      "z": -4,
      "name": "Soil_Dirt"
    },
    {
      "x": -3,
      "y": 7,
      "z": -4,
      "name": "Soil_Dirt"
    },
    {
      "x": -3,
      "y": 8,
      "z": -4,
      "name": "Soil_Dirt"
    },
    {
      "x": -3,
      "y": 9,
      "z": -4,
      "name": "Soil_Dirt"
    },
    {
      "x": -3,
      "y": 10,
      "z": -4,
      "name": "Soil_Grass"
    },
    {
      "x": -3,
      "y": 11,
      "z": -4,
      "name": "*Rock_Slate_Brick_Stairs_State_Definitions_Inverted_Corner_Left",
      "rotation": 2
    },
    {
      "x": -3,
      "y": 12,
      "z": -4,
      "name": "Plant_Bush_Dead_Tall",
      "support": 15
    },
    {
      "x": -3,
      "y": 13,
      "z": -4,
      "name": "Empty"
    },
    {
      "x": -3,
      "y": 14,
      "z": -4,
      "name": "Empty"
    },
    {
      "x": -3,
      "y": 15,
      "z": -4,
      "name": "Rock_Slate_Brick_Half",
      "rotation": 8
    },
    {
      "x": -3,
      "y": 0,
      "z": -3,
      "name": "Soil_Dirt"
    },
    {
      "x": -3,
      "y": 1,
      "z": -3,
      "name": "Soil_Dirt"
    },
    {
      "x": -3,
      "y": 2,
      "z": -3,
      "name": "Soil_Dirt"
    },
    {
      "x": -3,
      "y": 3,
      "z": -3,
      "name": "Soil_Dirt"
    },
    {
      "x": -3,
      "y": 4,
      "z": -3,
      "name": "Soil_Dirt"
    },
    {
      "x": -3,
      "y": 5,
      "z": -3,
      "name": "Soil_Dirt"
    },
    {
      "x": -3,
      "y": 6,
      "z": -3,
      "name": "Soil_Dirt"
    },
    {
      "x": -3,
      "y": 7,
      "z": -3,
      "name": "Soil_Dirt"
    },
    {
      "x": -3,
      "y": 8,
      "z": -3,
      "name": "Soil_Dirt"
    },
    {
      "x": -3,
      "y": 9,
      "z": -3,
      "name": "Soil_Dirt"
    },
    {
      "x": -3,
      "y": 10,
      "z": -3,
      "name": "Soil_Grass"
    },
    {
      "x": -3,
      "y": 11,
      "z": -3,
      "name": "Rock_Slate_Brick"
    },
    {
      "x": -3,
      "y": 12,
      "z": -3,
      "name": "Empty"
    },
    {
      "x": -3,
      "y": 13,
      "z": -3,
      "name": "Empty"
    },
    {
      "x": -3,
      "y": 14,
      "z": -3,
      "name": "Empty"
    },
    {
      "x": -3,
      "y": 15,
      "z": -3,
      "name": "Empty"
    },
    {
      "x": -3,
      "y": 0,
      "z": -2,
      "name": "Soil_Dirt"
    },
    {
      "x": -3,
      "y": 1,
      "z": -2,
      "name": "Soil_Dirt"
    },
    {
      "x": -3,
      "y": 2,
      "z": -2,
      "name": "Soil_Dirt"
    },
    {
      "x": -3,
      "y": 3,
      "z": -2,
      "name": "Soil_Dirt"
    },
    {
      "x": -3,
      "y": 4,
      "z": -2,
      "name": "Soil_Dirt"
    },
    {
      "x": -3,
      "y": 5,
      "z": -2,
      "name": "Soil_Dirt"
    },
    {
      "x": -3,
      "y": 6,
      "z": -2,
      "name": "Soil_Dirt"
    },
    {
      "x": -3,
      "y": 7,
      "z": -2,
      "name": "Soil_Dirt"
    },
    {
      "x": -3,
      "y": 8,
      "z": -2,
      "name": "Soil_Dirt"
    },
    {
      "x": -3,
      "y": 9,
      "z": -2,
      "name": "Soil_Dirt"
    },
    {
      "x": -3,
      "y": 10,
      "z": -2,
      "name": "Soil_Grass"
    },
    {
      "x": -3,
      "y": 11,
      "z": -2,
      "name": "Rock_Slate_Brick"
    },
    {
      "x": -3,
      "y": 12,
      "z": -2,
      "name": "Ritual_Brazier",
      "rotation": 3
    },
    {
      "x": -3,
      "y": 13,
      "z": -2,
      "name": "Empty"
    },
    {
      "x": -3,
      "y": 14,
      "z": -2,
      "name": "Empty"
    },
    {
      "x": -3,
      "y": 15,
      "z": -2,
      "name": "Empty"
    },
    {
      "x": -3,
      "y": 0,
      "z": -1,
      "name": "Soil_Dirt"
    },
    {
      "x": -3,
      "y": 1,
      "z": -1,
      "name": "Soil_Dirt"
    },
    {
      "x": -3,
      "y": 2,
      "z": -1,
      "name": "Soil_Dirt"
    },
    {
      "x": -3,
      "y": 3,
      "z": -1,
      "name": "Soil_Dirt"
    },
    {
      "x": -3,
      "y": 4,
      "z": -1,
      "name": "Soil_Dirt"
    },
    {
      "x": -3,
      "y": 5,
      "z": -1,
      "name": "Soil_Dirt"
    },
    {
      "x": -3,
      "y": 6,
      "z": -1,
      "name": "Soil_Dirt"
    },
    {
      "x": -3,
      "y": 7,
      "z": -1,
      "name": "Soil_Dirt"
    },
    {
      "x": -3,
      "y": 8,
      "z": -1,
      "name": "Soil_Dirt"
    },
    {
      "x": -3,
      "y": 9,
      "z": -1,
      "name": "Soil_Dirt"
    },
    {
      "x": -3,
      "y": 10,
      "z": -1,
      "name": "Soil_Grass"
    },
    {
      "x": -3,
      "y": 11,
      "z": -1,
      "name": "Rock_Slate_Brick"
    },
    {
      "x": -3,
      "y": 12,
      "z": -1,
      "name": "Empty"
    },
    {
      "x": -3,
      "y": 13,
      "z": -1,
      "name": "Empty"
    },
    {
      "x": -3,
      "y": 14,
      "z": -1,
      "name": "Empty"
    },
    {
      "x": -3,
      "y": 15,
      "z": -1,
      "name": "Empty"
    },
    {
      "x": -3,
      "y": 0,
      "z": 0,
      "name": "Soil_Dirt"
    },
    {
      "x": -3,
      "y": 1,
      "z": 0,
      "name": "Soil_Dirt"
    },
    {
      "x": -3,
      "y": 2,
      "z": 0,
      "name": "Soil_Dirt"
    },
    {
      "x": -3,
      "y": 3,
      "z": 0,
      "name": "Soil_Dirt"
    },
    {
      "x": -3,
      "y": 4,
      "z": 0,
      "name": "Soil_Dirt"
    },
    {
      "x": -3,
      "y": 5,
      "z": 0,
      "name": "Soil_Dirt"
    },
    {
      "x": -3,
      "y": 6,
      "z": 0,
      "name": "Soil_Dirt"
    },
    {
      "x": -3,
      "y": 7,
      "z": 0,
      "name": "Soil_Dirt"
    },
    {
      "x": -3,
      "y": 8,
      "z": 0,
      "name": "Soil_Dirt"
    },
    {
      "x": -3,
      "y": 9,
      "z": 0,
      "name": "Soil_Dirt"
    },
    {
      "x": -3,
      "y": 10,
      "z": 0,
      "name": "Soil_Grass"
    },
    {
      "x": -3,
      "y": 11,
      "z": 0,
      "name": "Rock_Slate"
    },
    {
      "x": -3,
      "y": 12,
      "z": 0,
      "name": "Rock_Slate_Brick_Ornate"
    },
    {
      "x": -3,
      "y": 13,
      "z": 0,
      "name": "Empty"
    },
    {
      "x": -3,
      "y": 14,
      "z": 0,
      "name": "Empty"
    },
    {
      "x": -3,
      "y": 15,
      "z": 0,
      "name": "Rock_Slate_Cobble_Stairs",
      "rotation": 9
    },
    {
      "x": -3,
      "y": 18,
      "z": 0,
      "name": "Rock_Slate_Brick_Stairs",
      "rotation": 8
    },
    {
      "x": -3,
      "y": 0,
      "z": 1,
      "name": "Soil_Dirt"
    },
    {
      "x": -3,
      "y": 1,
      "z": 1,
      "name": "Soil_Dirt"
    },
    {
      "x": -3,
      "y": 2,
      "z": 1,
      "name": "Soil_Dirt"
    },
    {
      "x": -3,
      "y": 3,
      "z": 1,
      "name": "Soil_Dirt"
    },
    {
      "x": -3,
      "y": 4,
      "z": 1,
      "name": "Soil_Dirt"
    },
    {
      "x": -3,
      "y": 5,
      "z": 1,
      "name": "Soil_Dirt"
    },
    {
      "x": -3,
      "y": 6,
      "z": 1,
      "name": "Soil_Dirt"
    },
    {
      "x": -3,
      "y": 7,
      "z": 1,
      "name": "Soil_Dirt"
    },
    {
      "x": -3,
      "y": 8,
      "z": 1,
      "name": "Soil_Dirt"
    },
    {
      "x": -3,
      "y": 9,
      "z": 1,
      "name": "Soil_Dirt"
    },
    {
      "x": -3,
      "y": 10,
      "z": 1,
      "name": "Soil_Grass"
    },
    {
      "x": -3,
      "y": 11,
      "z": 1,
      "name": "Rock_Slate_Brick"
    },
    {
      "x": -3,
      "y": 12,
      "z": 1,
      "name": "Rock_Slate_Brick_Wall",
      "rotation": 1
    },
    {
      "x": -3,
      "y": 13,
      "z": 1,
      "name": "Empty"
    },
    {
      "x": -3,
      "y": 14,
      "z": 1,
      "name": "Empty"
    },
    {
      "x": -3,
      "y": 15,
      "z": 1,
      "name": "Empty"
    },
    {
      "x": -3,
      "y": 17,
      "z": 1,
      "name": "*Rock_Slate_Brick_Stairs_State_Definitions_Corner_Right",
      "rotation": 8
    },
    {
      "x": -3,
      "y": 18,
      "z": 1,
      "name": "Wood_Beech_Trunk",
      "rotation": 2
    },
    {
      "x": -3,
      "y": 19,
      "z": 1,
      "name": "Rock_Slate_Brick_Half"
    },
    {
      "x": -3,
      "y": 0,
      "z": 2,
      "name": "Soil_Dirt"
    },
    {
      "x": -3,
      "y": 1,
      "z": 2,
      "name": "Soil_Dirt"
    },
    {
      "x": -3,
      "y": 2,
      "z": 2,
      "name": "Soil_Dirt"
    },
    {
      "x": -3,
      "y": 3,
      "z": 2,
      "name": "Soil_Dirt"
    },
    {
      "x": -3,
      "y": 4,
      "z": 2,
      "name": "Soil_Dirt"
    },
    {
      "x": -3,
      "y": 5,
      "z": 2,
      "name": "Soil_Dirt"
    },
    {
      "x": -3,
      "y": 6,
      "z": 2,
      "name": "Soil_Dirt"
    },
    {
      "x": -3,
      "y": 7,
      "z": 2,
      "name": "Soil_Dirt"
    },
    {
      "x": -3,
      "y": 8,
      "z": 2,
      "name": "Soil_Dirt"
    },
    {
      "x": -3,
      "y": 9,
      "z": 2,
      "name": "Soil_Dirt"
    },
    {
      "x": -3,
      "y": 10,
      "z": 2,
      "name": "Soil_Grass"
    },
    {
      "x": -3,
      "y": 11,
      "z": 2,
      "name": "Rock_Slate_Brick"
    },
    {
      "x": -3,
      "y": 12,
      "z": 2,
      "name": "Rock_Slate_Brick_Wall",
      "rotation": 1
    },
    {
      "x": -3,
      "y": 13,
      "z": 2,
      "name": "Empty"
    },
    {
      "x": -3,
      "y": 14,
      "z": 2,
      "name": "Empty"
    },
    {
      "x": -3,
      "y": 15,
      "z": 2,
      "name": "Empty"
    },
    {
      "x": -3,
      "y": 16,
      "z": 2,
      "name": "*Furniture_Ancient_Trapdoor_State_Definitions_OpenDoorOut",
      "rotation": 3
    },
    {
      "x": -3,
      "y": 17,
      "z": 2,
      "name": "Rock_Slate_Brick_Stairs",
      "rotation": 9
    },
    {
      "x": -3,
      "y": 18,
      "z": 2,
      "name": "Wood_Beech_Trunk",
      "rotation": 2
    },
    {
      "x": -3,
      "y": 19,
      "z": 2,
      "name": "Rock_Slate_Brick_Half"
    },
    {
      "x": -3,
      "y": 0,
      "z": 3,
      "name": "Soil_Dirt"
    },
    {
      "x": -3,
      "y": 1,
      "z": 3,
      "name": "Soil_Dirt"
    },
    {
      "x": -3,
      "y": 2,
      "z": 3,
      "name": "Soil_Dirt"
    },
    {
      "x": -3,
      "y": 3,
      "z": 3,
      "name": "Soil_Dirt"
    },
    {
      "x": -3,
      "y": 4,
      "z": 3,
      "name": "Soil_Dirt"
    },
    {
      "x": -3,
      "y": 5,
      "z": 3,
      "name": "Soil_Dirt"
    },
    {
      "x": -3,
      "y": 6,
      "z": 3,
      "name": "Soil_Dirt"
    },
    {
      "x": -3,
      "y": 7,
      "z": 3,
      "name": "Soil_Dirt"
    },
    {
      "x": -3,
      "y": 8,
      "z": 3,
      "name": "Soil_Dirt"
    },
    {
      "x": -3,
      "y": 9,
      "z": 3,
      "name": "Soil_Dirt"
    },
    {
      "x": -3,
      "y": 10,
      "z": 3,
      "name": "Soil_Grass"
    },
    {
      "x": -3,
      "y": 11,
      "z": 3,
      "name": "Rock_Slate_Brick"
    },
    {
      "x": -3,
      "y": 12,
      "z": 3,
      "name": "Rock_Slate_Brick_Wall",
      "rotation": 1
    },
    {
      "x": -3,
      "y": 13,
      "z": 3,
      "name": "Empty"
    },
    {
      "x": -3,
      "y": 14,
      "z": 3,
      "name": "Empty"
    },
    {
      "x": -3,
      "y": 15,
      "z": 3,
      "name": "Empty"
    },
    {
      "x": -3,
      "y": 17,
      "z": 3,
      "name": "Rock_Slate_Brick_Stairs",
      "rotation": 9
    },
    {
      "x": -3,
      "y": 18,
      "z": 3,
      "name": "Wood_Beech_Trunk",
      "rotation": 2
    },
    {
      "x": -3,
      "y": 19,
      "z": 3,
      "name": "Rock_Slate_Brick_Ornate"
    },
    {
      "x": -3,
      "y": 20,
      "z": 3,
      "name": "Rock_Slate_Brick_Decorative"
    },
    {
      "x": -3,
      "y": 21,
      "z": 3,
      "name": "Rock_Slate_Brick_Wall",
      "rotation": 2
    },
    {
      "x": -3,
      "y": 1,
      "z": 4,
      "name": "Soil_Dirt"
    },
    {
      "x": -3,
      "y": 2,
      "z": 4,
      "name": "Soil_Dirt"
    },
    {
      "x": -3,
      "y": 3,
      "z": 4,
      "name": "Soil_Dirt"
    },
    {
      "x": -3,
      "y": 4,
      "z": 4,
      "name": "Soil_Dirt"
    },
    {
      "x": -3,
      "y": 5,
      "z": 4,
      "name": "Soil_Dirt"
    },
    {
      "x": -3,
      "y": 6,
      "z": 4,
      "name": "Soil_Dirt"
    },
    {
      "x": -3,
      "y": 7,
      "z": 4,
      "name": "Soil_Dirt"
    },
    {
      "x": -3,
      "y": 8,
      "z": 4,
      "name": "Soil_Dirt"
    },
    {
      "x": -3,
      "y": 9,
      "z": 4,
      "name": "Soil_Dirt"
    },
    {
      "x": -3,
      "y": 10,
      "z": 4,
      "name": "Soil_Grass"
    },
    {
      "x": -3,
      "y": 11,
      "z": 4,
      "name": "Rock_Slate_Brick"
    },
    {
      "x": -3,
      "y": 12,
      "z": 4,
      "name": "Rock_Slate_Brick_Wall",
      "rotation": 1
    },
    {
      "x": -3,
      "y": 13,
      "z": 4,
      "name": "Empty"
    },
    {
      "x": -3,
      "y": 14,
      "z": 4,
      "name": "Empty"
    },
    {
      "x": -3,
      "y": 15,
      "z": 4,
      "name": "Empty"
    },
    {
      "x": -3,
      "y": 17,
      "z": 4,
      "name": "Rock_Slate_Brick_Stairs",
      "rotation": 9
    },
    {
      "x": -3,
      "y": 18,
      "z": 4,
      "name": "Wood_Beech_Trunk",
      "support": 1,
      "rotation": 2
    },
    {
      "x": -3,
      "y": 19,
      "z": 4,
      "name": "Rock_Slate_Brick_Decorative"
    },
    {
      "x": -3,
      "y": 1,
      "z": 5,
      "name": "Soil_Dirt"
    },
    {
      "x": -3,
      "y": 2,
      "z": 5,
      "name": "Soil_Dirt"
    },
    {
      "x": -3,
      "y": 3,
      "z": 5,
      "name": "Soil_Dirt"
    },
    {
      "x": -3,
      "y": 4,
      "z": 5,
      "name": "Soil_Dirt"
    },
    {
      "x": -3,
      "y": 5,
      "z": 5,
      "name": "Soil_Dirt"
    },
    {
      "x": -3,
      "y": 6,
      "z": 5,
      "name": "Soil_Dirt"
    },
    {
      "x": -3,
      "y": 7,
      "z": 5,
      "name": "Soil_Dirt"
    },
    {
      "x": -3,
      "y": 8,
      "z": 5,
      "name": "Soil_Dirt"
    },
    {
      "x": -3,
      "y": 9,
      "z": 5,
      "name": "Soil_Dirt"
    },
    {
      "x": -3,
      "y": 10,
      "z": 5,
      "name": "Soil_Grass"
    },
    {
      "x": -3,
      "y": 11,
      "z": 5,
      "name": "Rock_Slate_Brick"
    },
    {
      "x": -3,
      "y": 12,
      "z": 5,
      "name": "Rock_Slate_Brick_Wall",
      "rotation": 1
    },
    {
      "x": -3,
      "y": 13,
      "z": 5,
      "name": "Empty"
    },
    {
      "x": -3,
      "y": 14,
      "z": 5,
      "name": "Empty"
    },
    {
      "x": -3,
      "y": 15,
      "z": 5,
      "name": "Empty"
    },
    {
      "x": -3,
      "y": 17,
      "z": 5,
      "name": "Rock_Slate_Brick_Stairs",
      "rotation": 9
    },
    {
      "x": -3,
      "y": 18,
      "z": 5,
      "name": "Wood_Beech_Trunk",
      "rotation": 2
    },
    {
      "x": -3,
      "y": 19,
      "z": 5,
      "name": "Rock_Slate_Brick_Ornate"
    },
    {
      "x": -3,
      "y": 20,
      "z": 5,
      "name": "Rock_Slate_Brick_Decorative"
    },
    {
      "x": -3,
      "y": 21,
      "z": 5,
      "name": "Rock_Slate_Brick_Wall",
      "rotation": 2
    },
    {
      "x": -3,
      "y": 2,
      "z": 6,
      "name": "Soil_Dirt"
    },
    {
      "x": -3,
      "y": 3,
      "z": 6,
      "name": "Soil_Dirt"
    },
    {
      "x": -3,
      "y": 4,
      "z": 6,
      "name": "Soil_Dirt"
    },
    {
      "x": -3,
      "y": 5,
      "z": 6,
      "name": "Soil_Dirt"
    },
    {
      "x": -3,
      "y": 6,
      "z": 6,
      "name": "Soil_Dirt"
    },
    {
      "x": -3,
      "y": 7,
      "z": 6,
      "name": "Soil_Dirt"
    },
    {
      "x": -3,
      "y": 8,
      "z": 6,
      "name": "Soil_Dirt"
    },
    {
      "x": -3,
      "y": 9,
      "z": 6,
      "name": "Soil_Dirt"
    },
    {
      "x": -3,
      "y": 10,
      "z": 6,
      "name": "Soil_Grass"
    },
    {
      "x": -3,
      "y": 11,
      "z": 6,
      "name": "Rock_Slate_Brick"
    },
    {
      "x": -3,
      "y": 12,
      "z": 6,
      "name": "Rock_Slate_Brick_Ornate"
    },
    {
      "x": -3,
      "y": 13,
      "z": 6,
      "name": "Empty"
    },
    {
      "x": -3,
      "y": 14,
      "z": 6,
      "name": "Empty"
    },
    {
      "x": -3,
      "y": 15,
      "z": 6,
      "name": "Empty"
    },
    {
      "x": -3,
      "y": 16,
      "z": 6,
      "name": "*Furniture_Ancient_Trapdoor_State_Definitions_OpenDoorOut",
      "rotation": 3
    },
    {
      "x": -3,
      "y": 17,
      "z": 6,
      "name": "Rock_Slate_Brick_Stairs",
      "rotation": 9
    },
    {
      "x": -3,
      "y": 18,
      "z": 6,
      "name": "Wood_Banyan_Trunk",
      "rotation": 2
    },
    {
      "x": -3,
      "y": 19,
      "z": 6,
      "name": "Rock_Slate_Brick_Half"
    },
    {
      "x": -3,
      "y": 3,
      "z": 7,
      "name": "Soil_Dirt"
    },
    {
      "x": -3,
      "y": 4,
      "z": 7,
      "name": "Soil_Dirt"
    },
    {
      "x": -3,
      "y": 5,
      "z": 7,
      "name": "Soil_Dirt"
    },
    {
      "x": -3,
      "y": 6,
      "z": 7,
      "name": "Soil_Dirt"
    },
    {
      "x": -3,
      "y": 7,
      "z": 7,
      "name": "Soil_Dirt"
    },
    {
      "x": -3,
      "y": 8,
      "z": 7,
      "name": "Soil_Dirt"
    },
    {
      "x": -3,
      "y": 9,
      "z": 7,
      "name": "Soil_Dirt"
    },
    {
      "x": -3,
      "y": 10,
      "z": 7,
      "name": "Soil_Grass"
    },
    {
      "x": -3,
      "y": 17,
      "z": 7,
      "name": "*Rock_Slate_Brick_Stairs_State_Definitions_Corner_Left",
      "rotation": 10
    },
    {
      "x": -3,
      "y": 18,
      "z": 7,
      "name": "Wood_Banyan_Trunk",
      "rotation": 2
    },
    {
      "x": -3,
      "y": 19,
      "z": 7,
      "name": "Rock_Slate_Brick_Half"
    },
    {
      "x": -3,
      "y": 5,
      "z": 8,
      "name": "Soil_Dirt"
    },
    {
      "x": -3,
      "y": 6,
      "z": 8,
      "name": "Soil_Dirt"
    },
    {
      "x": -3,
      "y": 7,
      "z": 8,
      "name": "Soil_Dirt"
    },
    {
      "x": -3,
      "y": 8,
      "z": 8,
      "name": "Soil_Dirt"
    },
    {
      "x": -3,
      "y": 9,
      "z": 8,
      "name": "Soil_Grass"
    },
    {
      "x": -3,
      "y": 18,
      "z": 8,
      "name": "Rock_Slate_Brick_Stairs",
      "rotation": 10
    },
    {
      "x": -2,
      "y": 4,
      "z": -8,
      "name": "Wood_Dry_Roots"
    },
    {
      "x": -2,
      "y": 5,
      "z": -8,
      "name": "Soil_Dirt"
    },
    {
      "x": -2,
      "y": 6,
      "z": -8,
      "name": "Soil_Dirt"
    },
    {
      "x": -2,
      "y": 7,
      "z": -8,
      "name": "Soil_Dirt"
    },
    {
      "x": -2,
      "y": 8,
      "z": -8,
      "name": "Soil_Dirt"
    },
    {
      "x": -2,
      "y": 9,
      "z": -8,
      "name": "Soil_Grass"
    },
    {
      "x": -2,
      "y": 3,
      "z": -7,
      "name": "Soil_Dirt"
    },
    {
      "x": -2,
      "y": 4,
      "z": -7,
      "name": "Soil_Dirt"
    },
    {
      "x": -2,
      "y": 5,
      "z": -7,
      "name": "Soil_Dirt"
    },
    {
      "x": -2,
      "y": 6,
      "z": -7,
      "name": "Soil_Dirt"
    },
    {
      "x": -2,
      "y": 7,
      "z": -7,
      "name": "Soil_Dirt"
    },
    {
      "x": -2,
      "y": 8,
      "z": -7,
      "name": "Soil_Dirt"
    },
    {
      "x": -2,
      "y": 9,
      "z": -7,
      "name": "Soil_Dirt"
    },
    {
      "x": -2,
      "y": 10,
      "z": -7,
      "name": "Rock_Slate_Brick_Stairs",
      "rotation": 2
    },
    {
      "x": -2,
      "y": 2,
      "z": -6,
      "name": "Soil_Dirt"
    },
    {
      "x": -2,
      "y": 3,
      "z": -6,
      "name": "Soil_Dirt"
    },
    {
      "x": -2,
      "y": 4,
      "z": -6,
      "name": "Soil_Dirt"
    },
    {
      "x": -2,
      "y": 5,
      "z": -6,
      "name": "Soil_Dirt"
    },
    {
      "x": -2,
      "y": 6,
      "z": -6,
      "name": "Soil_Dirt"
    },
    {
      "x": -2,
      "y": 7,
      "z": -6,
      "name": "Soil_Dirt"
    },
    {
      "x": -2,
      "y": 8,
      "z": -6,
      "name": "Soil_Dirt"
    },
    {
      "x": -2,
      "y": 9,
      "z": -6,
      "name": "Soil_Dirt"
    },
    {
      "x": -2,
      "y": 10,
      "z": -6,
      "name": "Soil_Grass"
    },
    {
      "x": -2,
      "y": 11,
      "z": -6,
      "name": "Rock_Slate_Brick_Stairs",
      "rotation": 2
    },
    {
      "x": -2,
      "y": 12,
      "z": -6,
      "name": "Empty"
    },
    {
      "x": -2,
      "y": 13,
      "z": -6,
      "name": "Empty"
    },
    {
      "x": -2,
      "y": 1,
      "z": -5,
      "name": "Soil_Dirt"
    },
    {
      "x": -2,
      "y": 2,
      "z": -5,
      "name": "Soil_Dirt"
    },
    {
      "x": -2,
      "y": 3,
      "z": -5,
      "name": "Soil_Dirt"
    },
    {
      "x": -2,
      "y": 4,
      "z": -5,
      "name": "Soil_Dirt"
    },
    {
      "x": -2,
      "y": 5,
      "z": -5,
      "name": "Soil_Dirt"
    },
    {
      "x": -2,
      "y": 6,
      "z": -5,
      "name": "Soil_Dirt"
    },
    {
      "x": -2,
      "y": 7,
      "z": -5,
      "name": "Soil_Dirt"
    },
    {
      "x": -2,
      "y": 8,
      "z": -5,
      "name": "Soil_Dirt"
    },
    {
      "x": -2,
      "y": 9,
      "z": -5,
      "name": "Soil_Dirt"
    },
    {
      "x": -2,
      "y": 10,
      "z": -5,
      "name": "Soil_Grass"
    },
    {
      "x": -2,
      "y": 11,
      "z": -5,
      "name": "Rock_Slate_Brick"
    },
    {
      "x": -2,
      "y": 12,
      "z": -5,
      "name": "Furniture_Temple_Dark_Brazier"
    },
    {
      "x": -2,
      "y": 13,
      "z": -5,
      "name": "Empty"
    },
    {
      "x": -2,
      "y": 14,
      "z": -5,
      "name": "Empty"
    },
    {
      "x": -2,
      "y": 0,
      "z": -4,
      "name": "Soil_Dirt"
    },
    {
      "x": -2,
      "y": 1,
      "z": -4,
      "name": "Soil_Dirt"
    },
    {
      "x": -2,
      "y": 2,
      "z": -4,
      "name": "Soil_Dirt"
    },
    {
      "x": -2,
      "y": 3,
      "z": -4,
      "name": "Soil_Dirt"
    },
    {
      "x": -2,
      "y": 4,
      "z": -4,
      "name": "Soil_Dirt"
    },
    {
      "x": -2,
      "y": 5,
      "z": -4,
      "name": "Soil_Dirt"
    },
    {
      "x": -2,
      "y": 6,
      "z": -4,
      "name": "Soil_Dirt"
    },
    {
      "x": -2,
      "y": 7,
      "z": -4,
      "name": "Soil_Dirt"
    },
    {
      "x": -2,
      "y": 8,
      "z": -4,
      "name": "Soil_Dirt"
    },
    {
      "x": -2,
      "y": 9,
      "z": -4,
      "name": "Soil_Dirt"
    },
    {
      "x": -2,
      "y": 10,
      "z": -4,
      "name": "Soil_Grass"
    },
    {
      "x": -2,
      "y": 11,
      "z": -4,
      "name": "Rock_Slate_Brick"
    },
    {
      "x": -2,
      "y": 12,
      "z": -4,
      "name": "Rock_Slate_Brick_Decorative"
    },
    {
      "x": -2,
      "y": 13,
      "z": -4,
      "name": "Rock_Slate_Brick_Beam"
    },
    {
      "x": -2,
      "y": 14,
      "z": -4,
      "name": "Rock_Slate_Beam"
    },
    {
      "x": -2,
      "y": 15,
      "z": -4,
      "name": "Rock_Slate_Brick_Ornate"
    },
    {
      "x": -2,
      "y": 16,
      "z": -4,
      "name": "Rock_Slate_Brick_Pillar_Base"
    },
    {
      "x": -2,
      "y": 17,
      "z": -4,
      "name": "Rock_Slate_Brick_Pillar_Middle"
    },
    {
      "x": -2,
      "y": 18,
      "z": -4,
      "name": "Rock_Slate_Brick_Pillar_Base",
      "rotation": 8
    },
    {
      "x": -2,
      "y": 19,
      "z": -4,
      "name": "*Furniture_Human_Ruins_Brazier_State_Definitions_Off"
    },
    {
      "x": -2,
      "y": 0,
      "z": -3,
      "name": "Soil_Dirt"
    },
    {
      "x": -2,
      "y": 1,
      "z": -3,
      "name": "Soil_Dirt"
    },
    {
      "x": -2,
      "y": 2,
      "z": -3,
      "name": "Soil_Dirt"
    },
    {
      "x": -2,
      "y": 3,
      "z": -3,
      "name": "Soil_Dirt"
    },
    {
      "x": -2,
      "y": 4,
      "z": -3,
      "name": "Soil_Dirt"
    },
    {
      "x": -2,
      "y": 5,
      "z": -3,
      "name": "Soil_Dirt"
    },
    {
      "x": -2,
      "y": 6,
      "z": -3,
      "name": "Soil_Dirt"
    },
    {
      "x": -2,
      "y": 7,
      "z": -3,
      "name": "Soil_Dirt"
    },
    {
      "x": -2,
      "y": 8,
      "z": -3,
      "name": "Soil_Dirt"
    },
    {
      "x": -2,
      "y": 9,
      "z": -3,
      "name": "Soil_Dirt"
    },
    {
      "x": -2,
      "y": 10,
      "z": -3,
      "name": "Soil_Grass"
    },
    {
      "x": -2,
      "y": 11,
      "z": -3,
      "name": "Rock_Slate_Brick"
    },
    {
      "x": -2,
      "y": 12,
      "z": -3,
      "name": "Empty"
    },
    {
      "x": -2,
      "y": 13,
      "z": -3,
      "name": "Empty"
    },
    {
      "x": -2,
      "y": 14,
      "z": -3,
      "name": "Empty"
    },
    {
      "x": -2,
      "y": 15,
      "z": -3,
      "name": "Rock_Slate_Cobble_Stairs",
      "rotation": 10
    },
    {
      "x": -2,
      "y": 0,
      "z": -2,
      "name": "Soil_Dirt"
    },
    {
      "x": -2,
      "y": 1,
      "z": -2,
      "name": "Soil_Dirt"
    },
    {
      "x": -2,
      "y": 2,
      "z": -2,
      "name": "Soil_Dirt"
    },
    {
      "x": -2,
      "y": 3,
      "z": -2,
      "name": "Soil_Dirt"
    },
    {
      "x": -2,
      "y": 4,
      "z": -2,
      "name": "Soil_Dirt"
    },
    {
      "x": -2,
      "y": 5,
      "z": -2,
      "name": "Soil_Dirt"
    },
    {
      "x": -2,
      "y": 6,
      "z": -2,
      "name": "Soil_Dirt"
    },
    {
      "x": -2,
      "y": 7,
      "z": -2,
      "name": "Soil_Dirt"
    },
    {
      "x": -2,
      "y": 8,
      "z": -2,
      "name": "Soil_Dirt"
    },
    {
      "x": -2,
      "y": 9,
      "z": -2,
      "name": "Soil_Dirt"
    },
    {
      "x": -2,
      "y": 10,
      "z": -2,
      "name": "Soil_Grass"
    },
    {
      "x": -2,
      "y": 11,
      "z": -2,
      "name": "Rock_Slate_Brick"
    },
    {
      "x": -2,
      "y": 12,
      "z": -2,
      "name": "Empty"
    },
    {
      "x": -2,
      "y": 13,
      "z": -2,
      "name": "Empty"
    },
    {
      "x": -2,
      "y": 14,
      "z": -2,
      "name": "Empty"
    },
    {
      "x": -2,
      "y": 15,
      "z": -2,
      "name": "Rock_Slate_Brick_Half",
      "rotation": 8
    },
    {
      "x": -2,
      "y": 0,
      "z": -1,
      "name": "Soil_Dirt"
    },
    {
      "x": -2,
      "y": 1,
      "z": -1,
      "name": "Soil_Dirt"
    },
    {
      "x": -2,
      "y": 2,
      "z": -1,
      "name": "Soil_Dirt"
    },
    {
      "x": -2,
      "y": 3,
      "z": -1,
