{
  "version": 8,
  "blockIdVersion": 11,
  "anchorX": -10,
  "anchorY": 15,
  "anchorZ": 8,
  "blocks": [
    {
      "x": -19,
      "y": 11,
      "z": -2,
      "name": "Rock_Slate"
    },
    {
      "x": -19,
      "y": 10,
      "z": -1,
      "name": "Rock_Slate"
    },
    {
      "x": -19,
      "y": 11,
      "z": -1,
      "name": "Rock_Slate"
    },
    {
      "x": -19,
      "y": 12,
      "z": -1,
      "name": "Rock_Slate"
    },
    {
      "x": -19,
      "y": 10,
      "z": 0,
      "name": "Rock_Slate"
    },
    {
      "x": -19,
      "y": 11,
      "z": 0,
      "name": "Rock_Slate"
    },
    {
      "x": -19,
      "y": 12,
      "z": 0,
      "name": "Rock_Slate"
    },
    {
      "x": -19,
      "y": 10,
      "z": 1,
      "name": "Rock_Slate"
    },
    {
      "x": -19,
      "y": 11,
      "z": 1,
      "name": "Rock_Slate"
    },
    {
      "x": -19,
      "y": 12,
      "z": 1,
      "name": "Rock_Slate"
    },
    {
      "x": -19,
      "y": 10,
      "z": 2,
      "name": "Rock_Slate"
    },
    {
      "x": -19,
      "y": 11,
      "z": 2,
      "name": "Rock_Slate"
    },
    {
      "x": -19,
      "y": 11,
      "z": 3,
      "name": "Rock_Volcanic_Cobble"
    },
    {
      "x": -19,
      "y": 10,
      "z": 4,
      "name": "Rock_Volcanic_Cobble"
    },
    {
      "x": -19,
      "y": 11,
      "z": 4,
      "name": "Rock_Volcanic_Cobble"
    },
    {
      "x": -19,
      "y": 12,
      "z": 4,
      "name": "Rock_Volcanic_Cobble"
    },
    {
      "x": -19,
      "y": 11,
      "z": 5,
      "name": "Rock_Volcanic_Cobble"
    },
    {
      "x": -19,
      "y": 12,
      "z": 5,
      "name": "Rock_Volcanic_Cobble"
    },
    {
      "x": -19,
      "y": 13,
      "z": 5,
      "name": "Rock_Volcanic_Cobble"
    },
    {
      "x": -19,
      "y": 12,
      "z": 6,
      "name": "Rock_Volcanic_Cobble"
    },
    {
      "x": -18,
      "y": 9,
      "z": -5,
      "name": "Rock_Slate"
    },
    {
      "x": -18,
      "y": 10,
      "z": -5,
      "name": "Rock_Slate"
    },
    {
      "x": -18,
      "y": 11,
      "z": -5,
      "name": "Rock_Slate"
    },
    {
      "x": -18,
      "y": 12,
      "z": -5,
      "name": "Rock_Slate"
    },
    {
      "x": -18,
      "y": 9,
      "z": -4,
      "name": "Rock_Slate"
    },
    {
      "x": -18,
      "y": 10,
      "z": -4,
      "name": "Rock_Slate"
    },
    {
      "x": -18,
      "y": 11,
      "z": -4,
      "name": "Rock_Slate"
    },
    {
      "x": -18,
      "y": 12,
      "z": -4,
      "name": "Rock_Slate"
    },
    {
      "x": -18,
      "y": 9,
      "z": -3,
      "name": "Rock_Slate"
    },
    {
      "x": -18,
      "y": 10,
      "z": -3,
      "name": "Rock_Slate"
    },
    {
      "x": -18,
      "y": 11,
      "z": -3,
      "name": "Rock_Slate"
    },
    {
      "x": -18,
      "y": 12,
      "z": -3,
      "name": "Rock_Slate"
    },
    {
      "x": -18,
      "y": 13,
      "z": -3,
      "name": "Rock_Slate"
    },
    {
      "x": -18,
      "y": 8,
      "z": -2,
      "name": "Rock_Slate"
    },
    {
      "x": -18,
      "y": 9,
      "z": -2,
      "name": "Rock_Slate"
    },
    {
      "x": -18,
      "y": 10,
      "z": -2,
      "name": "Rock_Slate"
    },
    {
      "x": -18,
      "y": 11,
      "z": -2,
      "name": "Rock_Slate"
    },
    {
      "x": -18,
      "y": 12,
      "z": -2,
      "name": "Rock_Slate"
    },
    {
      "x": -18,
      "y": 13,
      "z": -2,
      "name": "Rock_Slate"
    },
    {
      "x": -18,
      "y": 8,
      "z": -1,
      "name": "Rock_Slate"
    },
    {
      "x": -18,
      "y": 9,
      "z": -1,
      "name": "Rock_Slate"
    },
    {
      "x": -18,
      "y": 10,
      "z": -1,
      "name": "Rock_Slate"
    },
    {
      "x": -18,
      "y": 11,
      "z": -1,
      "name": "Rock_Slate"
    },
    {
      "x": -18,
      "y": 12,
      "z": -1,
      "name": "Rock_Slate"
    },
    {
      "x": -18,
      "y": 13,
      "z": -1,
      "name": "Rock_Slate"
    },
    {
      "x": -18,
      "y": 8,
      "z": 0,
      "name": "Rock_Slate"
    },
    {
      "x": -18,
      "y": 9,
      "z": 0,
      "name": "Rock_Slate"
    },
    {
      "x": -18,
      "y": 10,
      "z": 0,
      "name": "Rock_Slate"
    },
    {
      "x": -18,
      "y": 11,
      "z": 0,
      "name": "Rock_Slate"
    },
    {
      "x": -18,
      "y": 12,
      "z": 0,
      "name": "Rock_Slate"
    },
    {
      "x": -18,
      "y": 13,
      "z": 0,
      "name": "Rock_Slate"
    },
    {
      "x": -18,
      "y": 8,
      "z": 1,
      "name": "Rock_Slate"
    },
    {
      "x": -18,
      "y": 9,
      "z": 1,
      "name": "Rock_Slate"
    },
    {
      "x": -18,
      "y": 10,
      "z": 1,
      "name": "Rock_Slate"
    },
    {
      "x": -18,
      "y": 11,
      "z": 1,
      "name": "Rock_Slate"
    },
    {
      "x": -18,
      "y": 12,
      "z": 1,
      "name": "Rock_Slate"
    },
    {
      "x": -18,
      "y": 13,
      "z": 1,
      "name": "Rock_Slate"
    },
    {
      "x": -18,
      "y": 8,
      "z": 2,
      "name": "Rock_Slate"
    },
    {
      "x": -18,
      "y": 9,
      "z": 2,
      "name": "Rock_Slate"
    },
    {
      "x": -18,
      "y": 10,
      "z": 2,
      "name": "Rock_Slate"
    },
    {
      "x": -18,
      "y": 11,
      "z": 2,
      "name": "Rock_Slate"
    },
    {
      "x": -18,
      "y": 12,
      "z": 2,
      "name": "Rock_Slate"
    },
    {
      "x": -18,
      "y": 13,
      "z": 2,
      "name": "Rock_Slate"
    },
    {
      "x": -18,
      "y": 8,
      "z": 3,
      "name": "Rock_Slate"
    },
    {
      "x": -18,
      "y": 9,
      "z": 3,
      "name": "Rock_Slate"
    },
    {
      "x": -18,
      "y": 10,
      "z": 3,
      "name": "Rock_Slate"
    },
    {
      "x": -18,
      "y": 11,
      "z": 3,
      "name": "Rock_Slate"
    },
    {
      "x": -18,
      "y": 12,
      "z": 3,
      "name": "Rock_Slate"
    },
    {
      "x": -18,
      "y": 13,
      "z": 3,
      "name": "Rock_Slate"
    },
    {
      "x": -18,
      "y": 9,
      "z": 4,
      "name": "Rock_Slate"
    },
    {
      "x": -18,
      "y": 10,
      "z": 4,
      "name": "Rock_Slate"
    },
    {
      "x": -18,
      "y": 11,
      "z": 4,
      "name": "Rock_Slate"
    },
    {
      "x": -18,
      "y": 12,
      "z": 4,
      "name": "Rock_Slate"
    },
    {
      "x": -18,
      "y": 13,
      "z": 4,
      "name": "Rock_Slate"
    },
    {
      "x": -18,
      "y": 9,
      "z": 5,
      "name": "Rock_Slate"
    },
    {
      "x": -18,
      "y": 10,
      "z": 5,
      "name": "Rock_Slate"
    },
    {
      "x": -18,
      "y": 11,
      "z": 5,
      "name": "Rock_Slate"
    },
    {
      "x": -18,
      "y": 12,
      "z": 5,
      "name": "Rock_Slate"
    },
    {
      "x": -18,
      "y": 13,
      "z": 5,
      "name": "Rock_Slate"
    },
    {
      "x": -18,
      "y": 14,
      "z": 5,
      "name": "Rock_Slate"
    },
    {
      "x": -18,
      "y": 9,
      "z": 6,
      "name": "Rock_Slate"
    },
    {
      "x": -18,
      "y": 10,
      "z": 6,
      "name": "Rock_Slate"
    },
    {
      "x": -18,
      "y": 11,
      "z": 6,
      "name": "Rock_Slate"
    },
    {
      "x": -18,
      "y": 12,
      "z": 6,
      "name": "Rock_Slate"
    },
    {
      "x": -18,
      "y": 13,
      "z": 6,
      "name": "Rock_Slate"
    },
    {
      "x": -18,
      "y": 9,
      "z": 7,
      "name": "Rock_Slate"
    },
    {
      "x": -18,
      "y": 10,
      "z": 7,
      "name": "Rock_Slate"
    },
    {
      "x": -18,
      "y": 11,
      "z": 7,
      "name": "Rock_Slate"
    },
    {
      "x": -18,
      "y": 12,
      "z": 7,
      "name": "Rock_Slate"
    },
    {
      "x": -17,
      "y": 9,
      "z": -7,
      "name": "Rock_Slate"
    },
    {
      "x": -17,
      "y": 10,
      "z": -7,
      "name": "Rock_Slate"
    },
    {
      "x": -17,
      "y": 11,
      "z": -7,
      "name": "Rock_Slate"
    },
    {
      "x": -17,
      "y": 12,
      "z": -7,
      "name": "Rock_Slate"
    },
    {
      "x": -17,
      "y": 13,
      "z": -7,
      "name": "Rock_Slate"
    },
    {
      "x": -17,
      "y": 8,
      "z": -6,
      "name": "Rock_Slate"
    },
    {
      "x": -17,
      "y": 9,
      "z": -6,
      "name": "Rock_Slate"
    },
    {
      "x": -17,
      "y": 10,
      "z": -6,
      "name": "Rock_Slate"
    },
    {
      "x": -17,
      "y": 11,
      "z": -6,
      "name": "Rock_Slate"
    },
    {
      "x": -17,
      "y": 12,
      "z": -6,
      "name": "Rock_Slate"
    },
    {
      "x": -17,
      "y": 13,
      "z": -6,
      "name": "Rock_Slate"
    },
    {
      "x": -17,
      "y": 8,
      "z": -5,
      "name": "Rock_Slate"
    },
    {
      "x": -17,
      "y": 9,
      "z": -5,
      "name": "Rock_Slate"
    },
    {
      "x": -17,
      "y": 10,
      "z": -5,
      "name": "Rock_Slate"
    },
    {
      "x": -17,
      "y": 11,
      "z": -5,
      "name": "Rock_Slate"
    },
    {
      "x": -17,
      "y": 12,
      "z": -5,
      "name": "Rock_Slate"
    },
    {
      "x": -17,
      "y": 13,
      "z": -5,
      "name": "Rock_Slate"
    },
    {
      "x": -17,
      "y": 7,
      "z": -4,
      "name": "Rock_Slate"
    },
    {
      "x": -17,
      "y": 8,
      "z": -4,
      "name": "Rock_Slate"
    },
    {
      "x": -17,
      "y": 9,
      "z": -4,
      "name": "Rock_Slate"
    },
    {
      "x": -17,
      "y": 10,
      "z": -4,
      "name": "Rock_Slate"
    },
    {
      "x": -17,
      "y": 11,
      "z": -4,
      "name": "Rock_Slate"
    },
    {
      "x": -17,
      "y": 12,
      "z": -4,
      "name": "Rock_Slate"
    },
    {
      "x": -17,
      "y": 13,
      "z": -4,
      "name": "Rock_Slate"
    },
    {
      "x": -17,
      "y": 14,
      "z": -4,
      "name": "Rock_Slate"
    },
    {
      "x": -17,
      "y": 7,
      "z": -3,
      "name": "Rock_Slate"
    },
    {
      "x": -17,
      "y": 8,
      "z": -3,
      "name": "Rock_Slate"
    },
    {
      "x": -17,
      "y": 9,
      "z": -3,
      "name": "Rock_Slate"
    },
    {
      "x": -17,
      "y": 10,
      "z": -3,
      "name": "Rock_Slate"
    },
    {
      "x": -17,
      "y": 11,
      "z": -3,
      "name": "Rock_Slate"
    },
    {
      "x": -17,
      "y": 12,
      "z": -3,
      "name": "Rock_Slate"
    },
    {
      "x": -17,
      "y": 13,
      "z": -3,
      "name": "Rock_Slate"
    },
    {
      "x": -17,
      "y": 14,
      "z": -3,
      "name": "Rock_Slate"
    },
    {
      "x": -17,
      "y": 7,
      "z": -2,
      "name": "Rock_Slate"
    },
    {
      "x": -17,
      "y": 8,
      "z": -2,
      "name": "Rock_Slate"
    },
    {
      "x": -17,
      "y": 9,
      "z": -2,
      "name": "Rock_Slate"
    },
    {
      "x": -17,
      "y": 10,
      "z": -2,
      "name": "Rock_Slate"
    },
    {
      "x": -17,
      "y": 11,
      "z": -2,
      "name": "Rock_Slate"
    },
    {
      "x": -17,
      "y": 12,
      "z": -2,
      "name": "Rock_Slate"
    },
    {
      "x": -17,
      "y": 13,
      "z": -2,
      "name": "Rock_Slate"
    },
    {
      "x": -17,
      "y": 14,
      "z": -2,
      "name": "Rock_Slate"
    },
    {
      "x": -17,
      "y": 7,
      "z": -1,
      "name": "Rock_Slate"
    },
    {
      "x": -17,
      "y": 8,
      "z": -1,
      "name": "Rock_Slate"
    },
    {
      "x": -17,
      "y": 9,
      "z": -1,
      "name": "Rock_Slate"
    },
    {
      "x": -17,
      "y": 10,
      "z": -1,
      "name": "Rock_Slate"
    },
    {
      "x": -17,
      "y": 11,
      "z": -1,
      "name": "Rock_Slate"
    },
    {
      "x": -17,
      "y": 12,
      "z": -1,
      "name": "Rock_Slate"
    },
    {
      "x": -17,
      "y": 13,
      "z": -1,
      "name": "Rock_Slate"
    },
    {
      "x": -17,
      "y": 14,
      "z": -1,
      "name": "Rock_Slate"
    },
    {
      "x": -17,
      "y": 7,
      "z": 0,
      "name": "Rock_Slate"
    },
    {
      "x": -17,
      "y": 8,
      "z": 0,
      "name": "Rock_Slate"
    },
    {
      "x": -17,
      "y": 9,
      "z": 0,
      "name": "Rock_Slate"
    },
    {
      "x": -17,
      "y": 10,
      "z": 0,
      "name": "Rock_Slate"
    },
    {
      "x": -17,
      "y": 11,
      "z": 0,
      "name": "Rock_Slate"
    },
    {
      "x": -17,
      "y": 12,
      "z": 0,
      "name": "Rock_Slate"
    },
    {
      "x": -17,
      "y": 13,
      "z": 0,
      "name": "Rock_Slate"
    },
    {
      "x": -17,
      "y": 14,
      "z": 0,
      "name": "Rock_Slate"
    },
    {
      "x": -17,
      "y": 7,
      "z": 1,
      "name": "Rock_Slate"
    },
    {
      "x": -17,
      "y": 8,
      "z": 1,
      "name": "Rock_Slate"
    },
    {
      "x": -17,
      "y": 9,
      "z": 1,
      "name": "Rock_Slate"
    },
    {
      "x": -17,
      "y": 10,
      "z": 1,
      "name": "Rock_Slate"
    },
    {
      "x": -17,
      "y": 11,
      "z": 1,
      "name": "Rock_Slate"
    },
    {
      "x": -17,
      "y": 12,
      "z": 1,
      "name": "Rock_Slate"
    },
    {
      "x": -17,
      "y": 13,
      "z": 1,
      "name": "Rock_Slate"
    },
    {
      "x": -17,
      "y": 14,
      "z": 1,
      "name": "Rock_Slate"
    },
    {
      "x": -17,
      "y": 23,
      "z": 1,
      "name": "Rock_Slate_Brick_Half",
      "rotation": 7
    },
    {
      "x": -17,
      "y": 24,
      "z": 1,
      "name": "*Rock_Slate_Brick_Wall_State_Definitions_Corner",
      "rotation": 1
    },
    {
      "x": -17,
      "y": 7,
      "z": 2,
      "name": "Rock_Slate"
    },
    {
      "x": -17,
      "y": 8,
      "z": 2,
      "name": "Rock_Slate"
    },
    {
      "x": -17,
      "y": 9,
      "z": 2,
      "name": "Rock_Slate"
    },
    {
      "x": -17,
      "y": 10,
      "z": 2,
      "name": "Rock_Slate"
    },
    {
      "x": -17,
      "y": 11,
      "z": 2,
      "name": "Rock_Slate"
    },
    {
      "x": -17,
      "y": 12,
      "z": 2,
      "name": "Rock_Slate"
    },
    {
      "x": -17,
      "y": 13,
      "z": 2,
      "name": "Rock_Slate"
    },
    {
      "x": -17,
      "y": 14,
      "z": 2,
      "name": "Rock_Slate"
    },
    {
      "x": -17,
      "y": 23,
      "z": 2,
      "name": "Rock_Slate_Brick_Half",
      "rotation": 7
    },
    {
      "x": -17,
      "y": 24,
      "z": 2,
      "name": "Rock_Slate_Brick_Wall",
      "rotation": 1
    },
    {
      "x": -17,
      "y": 7,
      "z": 3,
      "name": "Rock_Slate"
    },
    {
      "x": -17,
      "y": 8,
      "z": 3,
      "name": "Rock_Slate"
    },
    {
      "x": -17,
      "y": 9,
      "z": 3,
      "name": "Rock_Slate"
    },
    {
      "x": -17,
      "y": 10,
      "z": 3,
      "name": "Rock_Slate"
    },
    {
      "x": -17,
      "y": 11,
      "z": 3,
      "name": "Rock_Slate"
    },
    {
      "x": -17,
      "y": 12,
      "z": 3,
      "name": "Rock_Slate"
    },
    {
      "x": -17,
      "y": 13,
      "z": 3,
      "name": "Rock_Slate"
    },
    {
      "x": -17,
      "y": 14,
      "z": 3,
      "name": "Rock_Slate"
    },
    {
      "x": -17,
      "y": 23,
      "z": 3,
      "name": "Rock_Slate_Brick_Half",
      "rotation": 7
    },
    {
      "x": -17,
      "y": 24,
      "z": 3,
      "name": "*Rock_Slate_Brick_Wall_State_Definitions_Corner",
      "rotation": 2
    },
    {
      "x": -17,
      "y": 7,
      "z": 4,
      "name": "Rock_Slate"
    },
    {
      "x": -17,
      "y": 8,
      "z": 4,
      "name": "Rock_Slate"
    },
    {
      "x": -17,
      "y": 9,
      "z": 4,
      "name": "Rock_Slate"
    },
    {
      "x": -17,
      "y": 10,
      "z": 4,
      "name": "Rock_Slate"
    },
    {
      "x": -17,
      "y": 11,
      "z": 4,
      "name": "Rock_Slate"
    },
    {
      "x": -17,
      "y": 12,
      "z": 4,
      "name": "Rock_Slate"
    },
    {
      "x": -17,
      "y": 13,
      "z": 4,
      "name": "Rock_Slate"
    },
    {
      "x": -17,
      "y": 14,
      "z": 4,
      "name": "Rock_Slate"
    },
    {
      "x": -17,
      "y": 7,
      "z": 5,
      "name": "Rock_Slate"
    },
    {
      "x": -17,
      "y": 8,
      "z": 5,
      "name": "Rock_Slate"
    },
    {
      "x": -17,
      "y": 9,
      "z": 5,
      "name": "Rock_Slate"
    },
    {
      "x": -17,
      "y": 10,
      "z": 5,
      "name": "Rock_Slate"
    },
    {
      "x": -17,
      "y": 11,
      "z": 5,
      "name": "Rock_Slate"
    },
    {
      "x": -17,
      "y": 12,
      "z": 5,
      "name": "Rock_Slate"
    },
    {
      "x": -17,
      "y": 13,
      "z": 5,
      "name": "Rock_Slate"
    },
    {
      "x": -17,
      "y": 14,
      "z": 5,
      "name": "Rock_Slate"
    },
    {
      "x": -17,
      "y": 7,
      "z": 6,
      "name": "Rock_Slate"
    },
    {
      "x": -17,
      "y": 8,
      "z": 6,
      "name": "Rock_Slate"
    },
    {
      "x": -17,
      "y": 9,
      "z": 6,
      "name": "Rock_Slate"
    },
    {
      "x": -17,
      "y": 10,
      "z": 6,
      "name": "Rock_Slate"
    },
    {
      "x": -17,
      "y": 11,
      "z": 6,
      "name": "Rock_Slate"
    },
    {
      "x": -17,
      "y": 12,
      "z": 6,
      "name": "Rock_Slate"
    },
    {
      "x": -17,
      "y": 13,
      "z": 6,
      "name": "Rock_Slate"
    },
    {
      "x": -17,
      "y": 14,
      "z": 6,
      "name": "Rock_Slate"
    },
    {
      "x": -17,
      "y": 7,
      "z": 7,
      "name": "Rock_Slate"
    },
    {
      "x": -17,
      "y": 8,
      "z": 7,
      "name": "Rock_Slate"
    },
    {
      "x": -17,
      "y": 9,
      "z": 7,
      "name": "Rock_Slate"
    },
    {
      "x": -17,
      "y": 10,
      "z": 7,
      "name": "Rock_Slate"
    },
    {
      "x": -17,
      "y": 11,
      "z": 7,
      "name": "Rock_Slate"
    },
    {
      "x": -17,
      "y": 12,
      "z": 7,
      "name": "Rock_Slate"
    },
    {
      "x": -17,
      "y": 13,
      "z": 7,
      "name": "Rock_Slate"
    },
    {
      "x": -17,
      "y": 14,
      "z": 7,
      "name": "Rock_Slate"
    },
    {
      "x": -17,
      "y": 7,
      "z": 8,
      "name": "Rock_Slate"
    },
    {
      "x": -17,
      "y": 8,
      "z": 8,
      "name": "Rock_Slate"
    },
    {
      "x": -17,
      "y": 9,
      "z": 8,
      "name": "Rock_Slate"
    },
    {
      "x": -17,
      "y": 10,
      "z": 8,
      "name": "Rock_Slate"
    },
    {
      "x": -17,
      "y": 11,
      "z": 8,
      "name": "Rock_Slate"
    },
    {
      "x": -17,
      "y": 12,
      "z": 8,
      "name": "Rock_Slate"
    },
    {
      "x": -17,
      "y": 10,
      "z": 9,
      "name": "Rock_Slate"
    },
    {
      "x": -17,
      "y": 11,
      "z": 9,
      "name": "Rock_Slate"
    },
    {
      "x": -16,
      "y": 10,
      "z": -9,
      "name": "Rock_Slate"
    },
    {
      "x": -16,
      "y": 11,
      "z": -9,
      "name": "Rock_Slate"
    },
    {
      "x": -16,
      "y": 12,
      "z": -9,
      "name": "Rock_Slate"
    },
    {
      "x": -16,
      "y": 8,
      "z": -8,
      "name": "Rock_Slate"
    },
    {
      "x": -16,
      "y": 9,
      "z": -8,
      "name": "Rock_Slate"
    },
    {
      "x": -16,
      "y": 10,
      "z": -8,
      "name": "Rock_Slate"
    },
    {
      "x": -16,
      "y": 11,
      "z": -8,
      "name": "Rock_Slate"
    },
    {
      "x": -16,
      "y": 12,
      "z": -8,
      "name": "Rock_Slate"
    },
    {
      "x": -16,
      "y": 13,
      "z": -8,
      "name": "Rock_Slate"
    },
    {
      "x": -16,
      "y": 7,
      "z": -7,
      "name": "Rock_Slate"
    },
    {
      "x": -16,
      "y": 8,
      "z": -7,
      "name": "Rock_Slate"
    },
    {
      "x": -16,
      "y": 9,
      "z": -7,
      "name": "Rock_Slate"
    },
    {
      "x": -16,
      "y": 10,
      "z": -7,
      "name": "Rock_Slate"
    },
    {
      "x": -16,
      "y": 11,
      "z": -7,
      "name": "Rock_Slate"
    },
    {
      "x": -16,
      "y": 12,
      "z": -7,
      "name": "Rock_Slate"
    },
    {
      "x": -16,
      "y": 13,
      "z": -7,
      "name": "Rock_Slate"
    },
    {
      "x": -16,
      "y": 14,
      "z": -7,
      "name": "Rock_Slate"
    },
    {
      "x": -16,
      "y": 7,
      "z": -6,
      "name": "Rock_Slate"
    },
    {
      "x": -16,
      "y": 8,
      "z": -6,
      "name": "Rock_Slate"
    },
    {
      "x": -16,
      "y": 9,
      "z": -6,
      "name": "Rock_Slate"
    },
    {
      "x": -16,
      "y": 10,
      "z": -6,
      "name": "Rock_Slate"
    },
    {
      "x": -16,
      "y": 11,
      "z": -6,
      "name": "Rock_Slate"
    },
    {
      "x": -16,
      "y": 12,
      "z": -6,
      "name": "Rock_Slate"
    },
    {
      "x": -16,
      "y": 13,
      "z": -6,
      "name": "Rock_Slate"
    },
    {
      "x": -16,
      "y": 14,
      "z": -6,
      "name": "Rock_Slate"
    },
    {
      "x": -16,
      "y": 6,
      "z": -5,
      "name": "Rock_Slate"
    },
    {
      "x": -16,
      "y": 7,
      "z": -5,
      "name": "Rock_Slate"
    },
    {
      "x": -16,
      "y": 8,
      "z": -5,
      "name": "Rock_Slate"
    },
    {
      "x": -16,
      "y": 9,
      "z": -5,
      "name": "Rock_Slate"
    },
    {
      "x": -16,
      "y": 10,
      "z": -5,
      "name": "Rock_Slate"
    },
    {
      "x": -16,
      "y": 11,
      "z": -5,
      "name": "Rock_Slate"
    },
    {
      "x": -16,
      "y": 12,
      "z": -5,
      "name": "Rock_Slate"
    },
    {
      "x": -16,
      "y": 13,
      "z": -5,
      "name": "Rock_Slate"
    },
    {
      "x": -16,
      "y": 14,
      "z": -5,
      "name": "Rock_Slate"
    },
    {
      "x": -16,
      "y": 6,
      "z": -4,
      "name": "Rock_Slate"
    },
    {
      "x": -16,
      "y": 7,
      "z": -4,
      "name": "Rock_Slate"
    },
    {
      "x": -16,
      "y": 8,
      "z": -4,
      "name": "Rock_Slate"
    },
    {
      "x": -16,
      "y": 9,
      "z": -4,
      "name": "Rock_Slate"
    },
    {
      "x": -16,
      "y": 10,
      "z": -4,
      "name": "Rock_Slate"
    },
    {
      "x": -16,
      "y": 11,
      "z": -4,
      "name": "Rock_Slate"
    },
    {
      "x": -16,
      "y": 12,
      "z": -4,
      "name": "Rock_Slate"
    },
    {
      "x": -16,
      "y": 13,
      "z": -4,
      "name": "Rock_Slate"
    },
    {
      "x": -16,
      "y": 14,
      "z": -4,
      "name": "Rock_Slate"
    },
    {
      "x": -16,
      "y": 6,
      "z": -3,
      "name": "Rock_Slate"
    },
    {
      "x": -16,
      "y": 7,
      "z": -3,
      "name": "Rock_Slate"
    },
    {
      "x": -16,
      "y": 8,
      "z": -3,
      "name": "Rock_Slate"
    },
    {
      "x": -16,
      "y": 9,
      "z": -3,
      "name": "Rock_Slate"
    },
    {
      "x": -16,
      "y": 10,
      "z": -3,
      "name": "Rock_Slate"
    },
    {
      "x": -16,
      "y": 11,
      "z": -3,
      "name": "Rock_Slate"
    },
    {
      "x": -16,
      "y": 12,
      "z": -3,
      "name": "Rock_Slate"
    },
    {
      "x": -16,
      "y": 13,
      "z": -3,
      "name": "Rock_Slate"
    },
    {
      "x": -16,
      "y": 14,
      "z": -3,
      "name": "Rock_Slate"
    },
    {
      "x": -16,
      "y": 6,
      "z": -2,
      "name": "Rock_Slate"
    },
    {
      "x": -16,
      "y": 7,
      "z": -2,
      "name": "Rock_Slate"
    },
    {
      "x": -16,
      "y": 8,
      "z": -2,
      "name": "Rock_Slate"
    },
    {
      "x": -16,
      "y": 9,
      "z": -2,
      "name": "Rock_Slate"
    },
    {
      "x": -16,
      "y": 10,
      "z": -2,
      "name": "Rock_Slate"
    },
    {
      "x": -16,
      "y": 11,
      "z": -2,
      "name": "Rock_Slate"
    },
    {
      "x": -16,
      "y": 12,
      "z": -2,
      "name": "Rock_Slate"
    },
    {
      "x": -16,
      "y": 13,
      "z": -2,
      "name": "Rock_Slate"
    },
    {
      "x": -16,
      "y": 14,
      "z": -2,
      "name": "Rock_Slate"
    },
    {
      "x": -16,
      "y": 27,
      "z": -2,
      "name": "Banner_2",
      "rotation": 3
    },
    {
      "x": -16,
      "y": 5,
      "z": -1,
      "name": "Rock_Slate"
    },
    {
      "x": -16,
      "y": 6,
      "z": -1,
      "name": "Rock_Slate"
    },
    {
      "x": -16,
      "y": 7,
      "z": -1,
      "name": "Rock_Slate"
    },
    {
      "x": -16,
      "y": 8,
      "z": -1,
      "name": "Rock_Slate"
    },
    {
      "x": -16,
      "y": 9,
      "z": -1,
      "name": "Rock_Slate"
    },
    {
      "x": -16,
      "y": 10,
      "z": -1,
      "name": "Rock_Slate"
    },
    {
      "x": -16,
      "y": 11,
      "z": -1,
      "name": "Rock_Slate"
    },
    {
      "x": -16,
      "y": 12,
      "z": -1,
      "name": "Rock_Slate"
    },
    {
      "x": -16,
      "y": 13,
      "z": -1,
      "name": "Rock_Slate"
    },
    {
      "x": -16,
      "y": 14,
      "z": -1,
      "name": "Rock_Slate"
    },
    {
      "x": -16,
      "y": 15,
      "z": -1,
      "name": "Sword_Cemetery_3",
      "rotation": 2
    },
    {
      "x": -16,
      "y": 5,
      "z": 0,
      "name": "Rock_Slate"
    },
    {
      "x": -16,
      "y": 6,
      "z": 0,
      "name": "Rock_Slate"
    },
    {
      "x": -16,
      "y": 7,
      "z": 0,
      "name": "Rock_Slate"
    },
    {
      "x": -16,
      "y": 8,
      "z": 0,
      "name": "Rock_Slate"
    },
    {
      "x": -16,
      "y": 9,
      "z": 0,
      "name": "Rock_Slate"
    },
    {
      "x": -16,
      "y": 10,
      "z": 0,
      "name": "Rock_Slate"
    },
    {
      "x": -16,
      "y": 11,
      "z": 0,
      "name": "Rock_Slate"
    },
    {
      "x": -16,
      "y": 12,
      "z": 0,
      "name": "Rock_Slate"
    },
    {
      "x": -16,
      "y": 13,
      "z": 0,
      "name": "Rock_Slate"
    },
    {
      "x": -16,
      "y": 14,
      "z": 0,
      "name": "Rock_Slate"
    },
    {
      "x": -16,
      "y": 23,
      "z": 0,
      "name": "Rock_Slate_Brick_Decorative"
    },
    {
      "x": -16,
      "y": 24,
      "z": 0,
      "name": "*Rock_Slate_Brick_Wall_State_Definitions_Corner",
      "rotation": 1
    },
    {
      "x": -16,
      "y": 6,
      "z": 1,
      "name": "Rock_Slate"
    },
    {
      "x": -16,
      "y": 7,
      "z": 1,
      "name": "Rock_Slate"
    },
    {
      "x": -16,
      "y": 8,
      "z": 1,
      "name": "Rock_Slate"
    },
    {
      "x": -16,
      "y": 9,
      "z": 1,
      "name": "Rock_Slate"
    },
    {
      "x": -16,
      "y": 10,
      "z": 1,
      "name": "Rock_Slate"
    },
    {
      "x": -16,
      "y": 11,
      "z": 1,
      "name": "Rock_Slate"
    },
    {
      "x": -16,
      "y": 12,
      "z": 1,
      "name": "Rock_Slate"
    },
    {
      "x": -16,
      "y": 13,
      "z": 1,
      "name": "Rock_Slate"
    },
    {
      "x": -16,
      "y": 14,
      "z": 1,
      "name": "Rock_Slate"
    },
    {
      "x": -16,
      "y": 23,
      "z": 1,
      "name": "Rock_Slate_Brick_Decorative"
    },
    {
      "x": -16,
      "y": 24,
      "z": 1,
      "name": "*Rock_Slate_Brick_Wall_State_Definitions_Corner",
      "rotation": 3
    },
    {
      "x": -16,
      "y": 6,
      "z": 2,
      "name": "Rock_Slate"
    },
    {
      "x": -16,
      "y": 7,
      "z": 2,
      "name": "Rock_Slate"
    },
    {
      "x": -16,
      "y": 8,
      "z": 2,
      "name": "Rock_Slate"
    },
    {
      "x": -16,
      "y": 9,
      "z": 2,
      "name": "Rock_Slate"
    },
    {
      "x": -16,
      "y": 10,
      "z": 2,
      "name": "Rock_Slate"
    },
    {
      "x": -16,
      "y": 11,
      "z": 2,
      "name": "Rock_Slate"
    },
    {
      "x": -16,
      "y": 12,
      "z": 2,
      "name": "Rock_Slate"
    },
    {
      "x": -16,
      "y": 13,
      "z": 2,
      "name": "Rock_Slate"
    },
    {
      "x": -16,
      "y": 14,
      "z": 2,
      "name": "Rock_Slate"
    },
    {
      "x": -16,
      "y": 23,
      "z": 2,
      "name": "Rock_Slate_Brick_Decorative"
    },
    {
      "x": -16,
      "y": 6,
      "z": 3,
      "name": "Rock_Slate"
    },
    {
      "x": -16,
      "y": 7,
      "z": 3,
      "name": "Rock_Slate"
    },
    {
      "x": -16,
      "y": 8,
      "z": 3,
      "name": "Rock_Slate"
    },
    {
      "x": -16,
      "y": 9,
      "z": 3,
      "name": "Rock_Slate"
    },
    {
      "x": -16,
      "y": 10,
      "z": 3,
      "name": "Rock_Slate"
    },
    {
      "x": -16,
      "y": 11,
      "z": 3,
      "name": "Rock_Slate"
    },
    {
      "x": -16,
      "y": 12,
      "z": 3,
      "name": "Rock_Slate"
    },
    {
      "x": -16,
      "y": 13,
      "z": 3,
      "name": "Rock_Slate"
    },
    {
      "x": -16,
      "y": 14,
      "z": 3,
      "name": "Rock_Slate"
    },
    {
      "x": -16,
      "y": 15,
      "z": 3,
      "name": "Sword_Cemetery_3",
      "rotation": 3
    },
    {
      "x": -16,
      "y": 23,
      "z": 3,
      "name": "Rock_Slate_Brick_Decorative"
    },
    {
      "x": -16,
      "y": 24,
      "z": 3,
      "name": "*Rock_Slate_Brick_Wall_State_Definitions_Corner"
    },
    {
      "x": -16,
      "y": 6,
      "z": 4,
      "name": "Rock_Slate"
    },
    {
      "x": -16,
      "y": 7,
      "z": 4,
      "name": "Rock_Slate"
    },
    {
      "x": -16,
      "y": 8,
      "z": 4,
      "name": "Rock_Slate"
    },
    {
      "x": -16,
      "y": 9,
      "z": 4,
      "name": "Rock_Slate"
    },
    {
      "x": -16,
      "y": 10,
      "z": 4,
      "name": "Rock_Slate"
    },
    {
      "x": -16,
      "y": 11,
      "z": 4,
      "name": "Rock_Slate"
    },
    {
      "x": -16,
      "y": 12,
      "z": 4,
      "name": "Rock_Slate"
    },
    {
      "x": -16,
      "y": 13,
      "z": 4,
      "name": "Rock_Slate"
    },
    {
      "x": -16,
      "y": 14,
      "z": 4,
      "name": "Rock_Slate"
    },
    {
      "x": -16,
      "y": 15,
      "z": 4,
      "name": "Necrotic_Brick_Stone"
    },
    {
      "x": -16,
      "y": 23,
      "z": 4,
      "name": "Rock_Slate_Brick_Decorative"
    },
    {
      "x": -16,
      "y": 24,
      "z": 4,
      "name": "*Rock_Slate_Brick_Wall_State_Definitions_Corner",
      "rotation": 2
    },
    {
      "x": -16,
      "y": 6,
      "z": 5,
      "name": "Rock_Slate"
    },
    {
      "x": -16,
      "y": 7,
      "z": 5,
      "name": "Rock_Slate"
    },
    {
      "x": -16,
      "y": 8,
      "z": 5,
      "name": "Rock_Slate"
    },
    {
      "x": -16,
      "y": 9,
      "z": 5,
      "name": "Rock_Slate"
    },
    {
      "x": -16,
      "y": 10,
      "z": 5,
      "name": "Rock_Slate"
    },
    {
      "x": -16,
      "y": 11,
      "z": 5,
      "name": "Rock_Slate"
    },
    {
      "x": -16,
      "y": 12,
      "z": 5,
      "name": "Rock_Slate"
    },
    {
      "x": -16,
      "y": 13,
      "z": 5,
      "name": "Rock_Slate"
    },
    {
      "x": -16,
      "y": 14,
      "z": 5,
      "name": "Rock_Slate"
    },
    {
      "x": -16,
      "y": 15,
      "z": 5,
      "name": "Rock_Slate"
    },
    {
      "x": -16,
      "y": 6,
      "z": 6,
      "name": "Rock_Slate"
    },
    {
      "x": -16,
      "y": 7,
      "z": 6,
      "name": "Rock_Slate"
    },
    {
      "x": -16,
      "y": 8,
      "z": 6,
      "name": "Rock_Slate"
    },
    {
      "x": -16,
      "y": 9,
      "z": 6,
      "name": "Rock_Slate"
    },
    {
      "x": -16,
      "y": 10,
      "z": 6,
      "name": "Rock_Slate"
    },
    {
      "x": -16,
      "y": 11,
      "z": 6,
      "name": "Rock_Slate"
    },
    {
      "x": -16,
      "y": 12,
      "z": 6,
      "name": "Rock_Slate"
    },
    {
      "x": -16,
      "y": 13,
      "z": 6,
      "name": "Rock_Slate"
    },
    {
      "x": -16,
      "y": 14,
      "z": 6,
      "name": "Rock_Slate"
    },
    {
      "x": -16,
      "y": 15,
      "z": 6,
      "name": "Necrotic_Dirt"
    },
    {
      "x": -16,
      "y": 16,
      "z": 6,
      "name": "Plant_Bush_Winter",
      "support": 15
    },
    {
      "x": -16,
      "y": 27,
      "z": 6,
      "name": "Banner_2",
      "rotation": 3
    },
    {
      "x": -16,
      "y": 6,
      "z": 7,
      "name": "Rock_Slate"
    },
    {
      "x": -16,
      "y": 7,
      "z": 7,
      "name": "Rock_Slate"
    },
    {
      "x": -16,
      "y": 8,
      "z": 7,
      "name": "Rock_Slate"
    },
    {
      "x": -16,
      "y": 9,
      "z": 7,
      "name": "Rock_Slate"
    },
    {
      "x": -16,
      "y": 10,
      "z": 7,
      "name": "Rock_Slate"
    },
    {
      "x": -16,
      "y": 11,
      "z": 7,
      "name": "Rock_Slate"
    },
    {
      "x": -16,
      "y": 12,
      "z": 7,
      "name": "Rock_Slate"
    },
    {
      "x": -16,
      "y": 13,
      "z": 7,
      "name": "Rock_Slate"
    },
    {
      "x": -16,
      "y": 14,
      "z": 7,
      "name": "Rock_Slate"
    },
    {
      "x": -16,
      "y": 15,
      "z": 7,
      "name": "Necrotic_Dirt"
    },
    {
      "x": -16,
      "y": 16,
      "z": 7,
      "name": "Necrotic_Grass"
    },
    {
      "x": -16,
      "y": 6,
      "z": 8,
      "name": "Rock_Slate"
    },
    {
      "x": -16,
      "y": 7,
      "z": 8,
      "name": "Rock_Slate"
    },
    {
      "x": -16,
      "y": 8,
      "z": 8,
      "name": "Rock_Slate"
    },
    {
      "x": -16,
      "y": 9,
      "z": 8,
      "name": "Rock_Slate"
    },
    {
      "x": -16,
      "y": 10,
      "z": 8,
      "name": "Rock_Slate"
    },
    {
      "x": -16,
      "y": 11,
      "z": 8,
      "name": "Rock_Slate"
    },
    {
      "x": -16,
      "y": 12,
      "z": 8,
      "name": "Rock_Slate"
    },
    {
      "x": -16,
      "y": 13,
      "z": 8,
      "name": "Rock_Slate"
    },
    {
      "x": -16,
      "y": 14,
      "z": 8,
      "name": "Rock_Slate"
    },
    {
      "x": -16,
      "y": 6,
      "z": 9,
      "name": "Rock_Slate"
    },
    {
      "x": -16,
      "y": 8,
      "z": 9,
      "name": "Rock_Slate"
    },
    {
      "x": -16,
      "y": 9,
      "z": 9,
      "name": "Rock_Slate"
    },
    {
      "x": -16,
      "y": 10,
      "z": 9,
      "name": "Rock_Slate"
    },
    {
      "x": -16,
      "y": 11,
      "z": 9,
      "name": "Rock_Slate"
    },
    {
      "x": -16,
      "y": 12,
      "z": 9,
      "name": "Rock_Slate"
    },
    {
      "x": -15,
      "y": 9,
      "z": -10,
      "name": "Rock_Slate"
    },
    {
      "x": -15,
      "y": 10,
      "z": -10,
      "name": "Rock_Slate"
    },
    {
      "x": -15,
      "y": 11,
      "z": -10,
      "name": "Rock_Slate"
    },
    {
      "x": -15,
      "y": 12,
      "z": -10,
      "name": "Rock_Slate"
    },
    {
      "x": -15,
      "y": 7,
      "z": -9,
      "name": "Rock_Slate"
    },
    {
      "x": -15,
      "y": 8,
      "z": -9,
      "name": "Rock_Slate"
    },
    {
      "x": -15,
      "y": 9,
      "z": -9,
      "name": "Rock_Slate"
    },
    {
      "x": -15,
      "y": 10,
      "z": -9,
      "name": "Rock_Slate"
    },
    {
      "x": -15,
      "y": 11,
      "z": -9,
      "name": "Rock_Slate"
    },
    {
      "x": -15,
      "y": 12,
      "z": -9,
      "name": "Rock_Slate"
    },
    {
      "x": -15,
      "y": 13,
      "z": -9,
      "name": "Rock_Slate"
    },
    {
      "x": -15,
      "y": 6,
      "z": -8,
      "name": "Rock_Slate"
    },
    {
      "x": -15,
      "y": 7,
      "z": -8,
      "name": "Rock_Slate"
    },
    {
      "x": -15,
      "y": 8,
      "z": -8,
      "name": "Rock_Slate"
    },
    {
      "x": -15,
      "y": 9,
      "z": -8,
      "name": "Rock_Slate"
    },
    {
      "x": -15,
      "y": 10,
      "z": -8,
      "name": "Rock_Slate"
    },
    {
      "x": -15,
      "y": 11,
      "z": -8,
      "name": "Rock_Slate"
    },
    {
      "x": -15,
      "y": 12,
      "z": -8,
      "name": "Rock_Slate"
    },
    {
      "x": -15,
      "y": 13,
      "z": -8,
      "name": "Rock_Slate"
    },
    {
      "x": -15,
      "y": 6,
      "z": -7,
      "name": "Rock_Slate"
    },
    {
      "x": -15,
      "y": 7,
      "z": -7,
      "name": "Rock_Slate"
    },
    {
      "x": -15,
      "y": 8,
      "z": -7,
      "name": "Rock_Slate"
    },
    {
      "x": -15,
      "y": 9,
      "z": -7,
      "name": "Rock_Slate"
    },
    {
      "x": -15,
      "y": 10,
      "z": -7,
      "name": "Rock_Slate"
    },
    {
      "x": -15,
      "y": 11,
      "z": -7,
      "name": "Rock_Slate"
    },
    {
      "x": -15,
      "y": 12,
      "z": -7,
      "name": "Rock_Slate"
    },
    {
      "x": -15,
      "y": 13,
      "z": -7,
      "name": "Rock_Slate"
    },
    {
      "x": -15,
      "y": 14,
      "z": -7,
      "name": "Rock_Slate"
    },
    {
      "x": -15,
      "y": 5,
      "z": -6,
      "name": "Rock_Slate"
    },
    {
      "x": -15,
      "y": 6,
      "z": -6,
      "name": "Rock_Slate"
    },
    {
      "x": -15,
      "y": 7,
      "z": -6,
      "name": "Rock_Slate"
    },
    {
      "x": -15,
      "y": 8,
      "z": -6,
      "name": "Rock_Slate"
    },
    {
      "x": -15,
      "y": 9,
      "z": -6,
      "name": "Rock_Slate"
    },
    {
      "x": -15,
      "y": 10,
      "z": -6,
      "name": "Rock_Slate"
    },
    {
      "x": -15,
      "y": 11,
      "z": -6,
      "name": "Rock_Slate"
    },
    {
      "x": -15,
      "y": 12,
      "z": -6,
      "name": "Rock_Slate"
    },
    {
      "x": -15,
      "y": 13,
      "z": -6,
      "name": "Rock_Slate"
    },
    {
      "x": -15,
      "y": 14,
      "z": -6,
      "name": "Rock_Slate"
    },
    {
      "x": -15,
      "y": 15,
      "z": -6,
      "name": "Empty"
    },
    {
      "x": -15,
      "y": 16,
      "z": -6,
      "name": "Empty"
    },
    {
      "x": -15,
      "y": 17,
      "z": -6,
      "name": "Empty"
    },
    {
      "x": -15,
      "y": 18,
      "z": -6,
      "name": "Empty"
    },
    {
      "x": -15,
      "y": 19,
      "z": -6,
      "name": "Empty"
    },
    {
      "x": -15,
      "y": 20,
      "z": -6,
      "name": "Empty"
    },
    {
      "x": -15,
      "y": 21,
      "z": -6,
      "name": "Empty"
    },
    {
      "x": -15,
      "y": 22,
      "z": -6,
      "name": "Empty"
    },
    {
      "x": -15,
      "y": 23,
      "z": -6,
      "name": "Empty"
    },
    {
      "x": -15,
      "y": 24,
      "z": -6,
      "name": "Empty"
    },
    {
      "x": -15,
      "y": 25,
      "z": -6,
      "name": "Empty"
    },
    {
      "x": -15,
      "y": 26,
      "z": -6,
      "name": "Empty"
    },
    {
      "x": -15,
      "y": 27,
      "z": -6,
      "name": "Empty"
    },
    {
      "x": -15,
      "y": 28,
      "z": -6,
      "name": "Empty"
    },
    {
      "x": -15,
      "y": 29,
      "z": -6,
      "name": "Empty"
    },
    {
      "x": -15,
      "y": 30,
      "z": -6,
      "name": "Empty"
    },
    {
      "x": -15,
      "y": 31,
      "z": -6,
      "name": "Empty"
    },
    {
      "x": -15,
      "y": 32,
      "z": -6,
      "name": "Empty"
    },
    {
      "x": -15,
      "y": 33,
      "z": -6,
      "name": "Empty"
    },
    {
      "x": -15,
      "y": 34,
      "z": -6,
      "name": "Empty"
    },
    {
      "x": -15,
      "y": 5,
      "z": -5,
      "name": "Rock_Slate"
    },
    {
      "x": -15,
      "y": 6,
      "z": -5,
      "name": "Rock_Slate"
    },
    {
      "x": -15,
      "y": 7,
      "z": -5,
      "name": "Rock_Slate"
    },
    {
      "x": -15,
      "y": 8,
      "z": -5,
      "name": "Rock_Slate"
    },
    {
      "x": -15,
      "y": 9,
      "z": -5,
      "name": "Rock_Slate"
    },
    {
      "x": -15,
      "y": 10,
      "z": -5,
      "name": "Rock_Slate"
    },
    {
      "x": -15,
      "y": 11,
      "z": -5,
      "name": "Rock_Slate"
    },
    {
      "x": -15,
      "y": 12,
      "z": -5,
      "name": "Rock_Slate"
    },
    {
      "x": -15,
      "y": 13,
      "z": -5,
      "name": "Rock_Slate"
    },
    {
      "x": -15,
      "y": 14,
      "z": -5,
      "name": "Necrotic_Sand"
    },
    {
      "x": -15,
      "y": 15,
      "z": -5,
      "name": "Empty"
    },
    {
      "x": -15,
      "y": 16,
      "z": -5,
      "name": "Empty"
    },
    {
      "x": -15,
      "y": 17,
      "z": -5,
      "name": "Empty"
    },
    {
      "x": -15,
      "y": 18,
      "z": -5,
      "name": "Empty"
    },
    {
      "x": -15,
      "y": 19,
      "z": -5,
      "name": "Empty"
    },
    {
      "x": -15,
      "y": 20,
      "z": -5,
      "name": "Empty"
    },
    {
      "x": -15,
      "y": 21,
      "z": -5,
      "name": "Empty"
    },
    {
      "x": -15,
      "y": 22,
      "z": -5,
      "name": "Empty"
    },
    {
      "x": -15,
      "y": 23,
      "z": -5,
      "name": "Empty"
    },
    {
      "x": -15,
      "y": 24,
      "z": -5,
      "name": "Empty"
    },
    {
      "x": -15,
      "y": 25,
      "z": -5,
      "name": "Empty"
    },
    {
      "x": -15,
      "y": 26,
      "z": -5,
      "name": "Empty"
    },
    {
      "x": -15,
      "y": 27,
      "z": -5,
      "name": "Empty"
    },
    {
      "x": -15,
      "y": 28,
      "z": -5,
      "name": "Empty"
    },
    {
      "x": -15,
      "y": 29,
      "z": -5,
      "name": "Empty"
    },
    {
      "x": -15,
      "y": 30,
      "z": -5,
      "name": "Empty"
    },
    {
      "x": -15,
      "y": 31,
      "z": -5,
      "name": "Empty"
    },
    {
      "x": -15,
      "y": 32,
      "z": -5,
      "name": "Empty"
    },
    {
      "x": -15,
      "y": 33,
      "z": -5,
      "name": "Empty"
    },
    {
      "x": -15,
      "y": 34,
      "z": -5,
      "name": "Empty"
    },
    {
      "x": -15,
      "y": 5,
      "z": -4,
      "name": "Rock_Slate"
    },
    {
      "x": -15,
      "y": 6,
      "z": -4,
      "name": "Rock_Slate"
    },
    {
      "x": -15,
      "y": 7,
      "z": -4,
      "name": "Rock_Slate"
    },
    {
      "x": -15,
      "y": 8,
      "z": -4,
      "name": "Rock_Slate"
    },
    {
      "x": -15,
      "y": 9,
      "z": -4,
      "name": "Rock_Slate"
    },
    {
      "x": -15,
      "y": 10,
      "z": -4,
      "name": "Rock_Slate"
    },
    {
      "x": -15,
      "y": 11,
      "z": -4,
      "name": "Rock_Slate"
    },
    {
      "x": -15,
      "y": 12,
      "z": -4,
      "name": "Rock_Slate"
    },
    {
      "x": -15,
      "y": 13,
      "z": -4,
      "name": "Rock_Slate"
    },
    {
      "x": -15,
      "y": 14,
      "z": -4,
      "name": "Necrotic_Sand"
    },
    {
      "x": -15,
      "y": 15,
      "z": -4,
      "name": "Necrotic_Grass"
    },
    {
      "x": -15,
      "y": 16,
      "z": -4,
      "name": "Empty"
    },
    {
      "x": -15,
      "y": 17,
      "z": -4,
      "name": "Empty"
    },
    {
      "x": -15,
      "y": 18,
      "z": -4,
      "name": "Empty"
    },
    {
      "x": -15,
      "y": 19,
      "z": -4,
      "name": "Empty"
    },
    {
      "x": -15,
      "y": 20,
      "z": -4,
      "name": "Empty"
    },
    {
      "x": -15,
      "y": 21,
      "z": -4,
      "name": "Empty"
    },
    {
      "x": -15,
      "y": 22,
      "z": -4,
      "name": "Empty"
    },
    {
      "x": -15,
      "y": 23,
      "z": -4,
      "name": "Empty"
    },
    {
      "x": -15,
      "y": 24,
      "z": -4,
      "name": "Empty"
    },
    {
      "x": -15,
      "y": 25,
      "z": -4,
      "name": "Empty"
    },
    {
      "x": -15,
      "y": 26,
      "z": -4,
      "name": "Empty"
    },
    {
      "x": -15,
      "y": 27,
      "z": -4,
      "name": "Empty"
    },
    {
      "x": -15,
      "y": 28,
      "z": -4,
      "name": "Empty"
    },
    {
      "x": -15,
      "y": 29,
      "z": -4,
      "name": "Empty"
    },
    {
      "x": -15,
      "y": 30,
      "z": -4,
      "name": "Empty"
    },
    {
      "x": -15,
      "y": 31,
      "z": -4,
      "name": "Empty"
    },
    {
      "x": -15,
      "y": 32,
      "z": -4,
      "name": "Empty"
    },
    {
      "x": -15,
      "y": 33,
      "z": -4,
      "name": "Empty"
    },
    {
      "x": -15,
      "y": 34,
      "z": -4,
      "name": "Empty"
    },
    {
      "x": -15,
      "y": 5,
      "z": -3,
      "name": "Rock_Slate"
    },
    {
      "x": -15,
      "y": 6,
      "z": -3,
      "name": "Rock_Slate"
    },
    {
      "x": -15,
      "y": 7,
      "z": -3,
      "name": "Rock_Slate"
    },
    {
      "x": -15,
      "y": 8,
      "z": -3,
      "name": "Rock_Slate"
    },
    {
      "x": -15,
      "y": 9,
      "z": -3,
      "name": "Rock_Slate"
    },
    {
      "x": -15,
      "y": 10,
      "z": -3,
      "name": "Rock_Slate"
    },
    {
      "x": -15,
      "y": 11,
      "z": -3,
      "name": "Rock_Slate"
    },
    {
      "x": -15,
      "y": 12,
      "z": -3,
      "name": "Rock_Slate"
    },
    {
      "x": -15,
      "y": 13,
      "z": -3,
      "name": "Rock_Slate"
    },
    {
      "x": -15,
      "y": 14,
      "z": -3,
      "name": "Rock_Slate"
    },
    {
      "x": -15,
      "y": 15,
      "z": -3,
      "name": "Rock_Slate_Brick_Decorative"
    },
    {
      "x": -15,
      "y": 16,
      "z": -3,
      "name": "Empty"
    },
    {
      "x": -15,
      "y": 17,
      "z": -3,
      "name": "Empty"
    },
    {
      "x": -15,
      "y": 18,
      "z": -3,
      "name": "Empty"
    },
    {
      "x": -15,
      "y": 19,
      "z": -3,
      "name": "Empty"
    },
    {
      "x": -15,
      "y": 20,
      "z": -3,
      "name": "Empty"
    },
    {
      "x": -15,
      "y": 21,
      "z": -3,
      "name": "Empty"
    },
    {
      "x": -15,
      "y": 22,
      "z": -3,
      "name": "Empty"
    },
    {
      "x": -15,
      "y": 23,
      "z": -3,
      "name": "Empty"
    },
    {
      "x": -15,
      "y": 24,
      "z": -3,
      "name": "Empty"
    },
    {
      "x": -15,
      "y": 25,
      "z": -3,
      "name": "Empty"
    },
    {
      "x": -15,
      "y": 26,
      "z": -3,
      "name": "Empty"
    },
    {
      "x": -15,
      "y": 27,
      "z": -3,
      "name": "Empty"
    },
    {
      "x": -15,
      "y": 28,
      "z": -3,
      "name": "Rock_Slate_Brick_Decorative"
    },
    {
      "x": -15,
      "y": 29,
      "z": -3,
      "name": "Rock_Slate_Brick_Decorative"
    },
    {
      "x": -15,
      "y": 30,
      "z": -3,
      "name": "Empty"
    },
    {
      "x": -15,
      "y": 31,
      "z": -3,
      "name": "Empty"
    },
    {
      "x": -15,
      "y": 32,
      "z": -3,
      "name": "Empty"
    },
    {
      "x": -15,
      "y": 33,
      "z": -3,
      "name": "Empty"
    },
    {
      "x": -15,
      "y": 34,
      "z": -3,
      "name": "Empty"
    },
    {
      "x": -15,
      "y": 5,
      "z": -2,
      "name": "Rock_Slate"
    },
    {
      "x": -15,
      "y": 6,
      "z": -2,
      "name": "Rock_Slate"
    },
    {
      "x": -15,
      "y": 7,
      "z": -2,
      "name": "Rock_Slate"
    },
    {
      "x": -15,
      "y": 8,
      "z": -2,
      "name": "Rock_Slate"
    },
    {
      "x": -15,
      "y": 9,
      "z": -2,
      "name": "Rock_Slate"
    },
    {
      "x": -15,
      "y": 10,
      "z": -2,
      "name": "Rock_Slate"
    },
    {
      "x": -15,
      "y": 11,
      "z": -2,
      "name": "Rock_Slate"
    },
    {
      "x": -15,
      "y": 12,
      "z": -2,
      "name": "Rock_Slate"
    },
    {
      "x": -15,
      "y": 13,
      "z": -2,
      "name": "Rock_Slate"
    },
    {
      "x": -15,
      "y": 14,
      "z": -2,
      "name": "Rock_Slate"
    },
    {
      "x": -15,
      "y": 15,
      "z": -2,
      "name": "Rock_Slate_Brick_Decorative"
    },
    {
      "x": -15,
      "y": 16,
      "z": -2,
      "name": "Rock_Slate_Brick_Decorative"
    },
    {
      "x": -15,
      "y": 17,
      "z": -2,
      "name": "Rock_Slate_Brick_Decorative"
    },
    {
      "x": -15,
      "y": 18,
      "z": -2,
      "name": "Rock_Slate_Brick_Half",
      "rotation": 7
    },
    {
      "x": -15,
      "y": 19,
      "z": -2,
      "name": "Rock_Slate_Brick_Half",
      "rotation": 7
    },
    {
      "x": -15,
      "y": 20,
      "z": -2,
      "name": "Rock_Slate_Brick_Half",
      "rotation": 7
    },
    {
      "x": -15,
      "y": 21,
      "z": -2,
      "name": "Rock_Slate_Brick_Half",
      "rotation": 7
    },
    {
      "x": -15,
      "y": 22,
      "z": -2,
      "name": "Rock_Slate_Brick_Decorative"
    },
    {
      "x": -15,
      "y": 23,
      "z": -2,
      "name": "Rock_Slate_Brick_Decorative"
    },
    {
      "x": -15,
      "y": 24,
      "z": -2,
      "name": "Necrotic_Pillar"
    },
    {
      "x": -15,
      "y": 25,
      "z": -2,
      "name": "Necrotic_Pillar"
    },
    {
      "x": -15,
      "y": 26,
      "z": -2,
      "name": "Necrotic_Pillar",
      "rotation": 8
    },
    {
      "x": -15,
      "y": 27,
      "z": -2,
      "name": "Necrotic_Stone_Brick_Decorative"
    },
    {
      "x": -15,
      "y": 28,
      "z": -2,
      "name": "Rock_Slate_Brick_Decorative"
    },
    {
      "x": -15,
      "y": 29,
      "z": -2,
      "name": "Rock_Slate_Brick_Decorative"
    },
    {
      "x": -15,
      "y": 30,
      "z": -2,
      "name": "Necrotic_Pillar"
    },
    {
      "x": -15,
      "y": 31,
      "z": -2,
      "name": "Necrotic_Pillar"
    },
    {
      "x": -15,
      "y": 32,
      "z": -2,
      "name": "Necrotic_Pillar"
    },
    {
      "x": -15,
      "y": 33,
      "z": -2,
      "name": "Necrotic_Pillar"
    },
    {
      "x": -15,
      "y": 34,
      "z": -2,
      "name": "Necrotic_Pillar",
      "rotation": 8
    },
    {
      "x": -15,
      "y": 35,
      "z": -2,
      "name": "Necrotic_Stone_Brick_Decorative"
    },
    {
      "x": -15,
      "y": 36,
      "z": -2,
      "name": "Rock_Slate_Brick_Decorative"
    },
    {
      "x": -15,
      "y": 5,
      "z": -1,
      "name": "Rock_Slate"
    },
    {
      "x": -15,
      "y": 6,
      "z": -1,
      "name": "Rock_Slate"
    },
    {
      "x": -15,
      "y": 7,
      "z": -1,
      "name": "Rock_Slate"
    },
    {
      "x": -15,
      "y": 8,
      "z": -1,
      "name": "Rock_Slate"
    },
    {
      "x": -15,
      "y": 9,
      "z": -1,
      "name": "Rock_Slate"
    },
    {
      "x": -15,
      "y": 10,
      "z": -1,
      "name": "Rock_Slate"
    },
    {
      "x": -15,
      "y": 11,
      "z": -1,
      "name": "Rock_Slate"
    },
    {
      "x": -15,
      "y": 12,
      "z": -1,
      "name": "Rock_Slate"
    },
    {
      "x": -15,
      "y": 13,
      "z": -1,
      "name": "Rock_Slate"
    },
    {
      "x": -15,
      "y": 14,
      "z": -1,
      "name": "Rock_Slate"
    },
    {
      "x": -15,
      "y": 15,
      "z": -1,
      "name": "Rock_Slate_Brick_Decorative"
    },
    {
      "x": -15,
      "y": 16,
      "z": -1,
      "name": "Rock_Slate_Brick_Decorative"
    },
    {
      "x": -15,
      "y": 17,
      "z": -1,
      "name": "Rock_Slate_Brick_Stairs"
    },
    {
      "x": -15,
      "y": 18,
      "z": -1,
      "name": "Empty"
    },
    {
      "x": -15,
      "y": 19,
      "z": -1,
      "name": "Empty"
    },
    {
      "x": -15,
      "y": 20,
      "z": -1,
      "name": "Empty"
    },
    {
      "x": -15,
      "y": 21,
      "z": -1,
      "name": "Empty"
    },
    {
      "x": -15,
      "y": 22,
      "z": -1,
      "name": "Rock_Slate_Brick_Stairs",
      "rotation": 10
    },
    {
      "x": -15,
      "y": 23,
      "z": -1,
      "name": "Rock_Slate_Brick_Decorative"
    },
    {
      "x": -15,
      "y": 24,
      "z": -1,
      "name": "Furniture_Human_Ruins_Brazier"
    },
    {
      "x": -15,
      "y": 25,
      "z": -1,
      "name": "Empty"
    },
    {
      "x": -15,
      "y": 26,
      "z": -1,
      "name": "Empty"
    },
    {
      "x": -15,
      "y": 27,
      "z": -1,
      "name": "Rock_Slate_Brick_Stairs",
      "rotation": 10
    },
    {
      "x": -15,
      "y": 28,
      "z": -1,
      "name": "Rock_Slate_Brick_Decorative"
    },
    {
      "x": -15,
      "y": 29,
      "z": -1,
      "name": "Rock_Slate_Brick_Half",
      "rotation": 7
    },
    {
      "x": -15,
      "y": 30,
      "z": -1,
      "name": "Empty"
    },
    {
      "x": -15,
      "y": 31,
      "z": -1,
      "name": "Empty"
    },
    {
      "x": -15,
      "y": 32,
      "z": -1,
      "name": "Empty"
    },
    {
      "x": -15,
      "y": 33,
      "z": -1,
      "name": "Empty"
    },
    {
      "x": -15,
      "y": 34,
      "z": -1,
      "name": "Empty"
    },
    {
      "x": -15,
      "y": 5,
      "z": 0,
      "name": "Rock_Slate"
    },
    {
      "x": -15,
      "y": 6,
      "z": 0,
      "name": "Rock_Slate"
    },
    {
      "x": -15,
      "y": 7,
      "z": 0,
      "name": "Rock_Slate"
    },
    {
      "x": -15,
      "y": 8,
      "z": 0,
      "name": "Rock_Slate"
    },
    {
      "x": -15,
      "y": 9,
      "z": 0,
      "name": "Rock_Slate"
    },
    {
      "x": -15,
      "y": 10,
      "z": 0,
      "name": "Rock_Slate"
    },
    {
      "x": -15,
      "y": 11,
      "z": 0,
      "name": "Rock_Slate"
    },
    {
      "x": -15,
      "y": 12,
      "z": 0,
      "name": "Rock_Slate"
    },
    {
      "x": -15,
      "y": 13,
      "z": 0,
      "name": "Rock_Slate"
    },
    {
      "x": -15,
      "y": 14,
      "z": 0,
      "name": "Rock_Slate"
    },
    {
      "x": -15,
      "y": 15,
      "z": 0,
      "name": "Rock_Slate_Brick_Decorative"
    },
    {
      "x": -15,
      "y": 16,
      "z": 0,
      "name": "Rock_Slate_Brick_Decorative"
    },
    {
      "x": -15,
      "y": 17,
      "z": 0,
      "name": "Furniture_Human_Ruins_Brazier"
    },
    {
      "x": -15,
      "y": 18,
      "z": 0,
      "name": "Empty"
    },
    {
      "x": -15,
      "y": 19,
      "z": 0,
      "name": "Empty"
    },
    {
      "x": -15,
      "y": 20,
      "z": 0,
      "name": "Empty"
    },
    {
      "x": -15,
      "y": 21,
      "z": 0,
      "name": "Empty"
    },
    {
      "x": -15,
      "y": 22,
      "z": 0,
      "name": "Rock_Slate_Brick_Half",
      "rotation": 8
    },
    {
      "x": -15,
      "y": 23,
      "z": 0,
      "name": "Rock_Slate_Brick_Decorative"
    },
    {
      "x": -15,
      "y": 24,
      "z": 0,
      "name": "Rock_Slate_Brick_Wall"
    },
    {
      "x": -15,
      "y": 25,
      "z": 0,
      "name": "Empty"
    },
    {
      "x": -15,
      "y": 26,
      "z": 0,
      "name": "Empty"
    },
    {
      "x": -15,
      "y": 27,
      "z": 0,
      "name": "Empty"
    },
    {
      "x": -15,
      "y": 28,
      "z": 0,
      "name": "Rock_Slate_Brick_Decorative"
    },
    {
      "x": -15,
      "y": 29,
      "z": 0,
      "name": "Rock_Slate_Brick_Half",
      "rotation": 7
    },
    {
      "x": -15,
      "y": 30,
      "z": 0,
      "name": "Empty"
    },
    {
      "x": -15,
      "y": 31,
      "z": 0,
      "name": "Empty"
    },
    {
      "x": -15,
      "y": 32,
      "z": 0,
      "name": "Empty"
    },
    {
      "x": -15,
      "y": 33,
      "z": 0,
      "name": "Empty"
    },
    {
      "x": -15,
      "y": 34,
      "z": 0,
      "name": "Empty"
    },
    {
      "x": -15,
      "y": 5,
      "z": 1,
      "name": "Rock_Slate"
    },
    {
      "x": -15,
      "y": 6,
      "z": 1,
      "name": "Rock_Slate"
    },
    {
      "x": -15,
      "y": 7,
      "z": 1,
      "name": "Rock_Slate"
    },
    {
      "x": -15,
      "y": 8,
      "z": 1,
      "name": "Rock_Slate"
    },
    {
      "x": -15,
      "y": 9,
      "z": 1,
      "name": "Rock_Slate"
    },
    {
      "x": -15,
      "y": 10,
      "z": 1,
      "name": "Rock_Slate"
    },
    {
      "x": -15,
      "y": 11,
      "z": 1,
      "name": "Rock_Slate"
    },
    {
      "x": -15,
      "y": 12,
      "z": 1,
      "name": "Rock_Slate"
    },
    {
      "x": -15,
      "y": 13,
      "z": 1,
      "name": "Rock_Slate"
    },
    {
      "x": -15,
      "y": 14,
      "z": 1,
      "name": "Rock_Slate"
    },
    {
      "x": -15,
      "y": 15,
      "z": 1,
      "name": "Rock_Slate_Brick_Decorative"
    },
    {
      "x": -15,
      "y": 16,
      "z": 1,
      "name": "Empty"
    },
    {
      "x": -15,
      "y": 17,
      "z": 1,
      "name": "Empty"
    },
    {
      "x": -15,
      "y": 18,
      "z": 1,
      "name": "Empty"
    },
    {
      "x": -15,
      "y": 19,
      "z": 1,
      "name": "Empty"
    },
    {
      "x": -15,
      "y": 20,
      "z": 1,
      "name": "Empty"
    },
    {
      "x": -15,
      "y": 21,
      "z": 1,
      "name": "Empty"
    },
    {
      "x": -15,
      "y": 22,
      "z": 1,
      "name": "Rock_Slate_Brick_Half",
      "rotation": 8
    },
    {
      "x": -15,
      "y": 23,
      "z": 1,
      "name": "Rock_Slate_Brick_Decorative"
    },
    {
      "x": -15,
      "y": 24,
      "z": 1,
      "name": "Empty"
    },
    {
      "x": -15,
      "y": 25,
      "z": 1,
      "name": "Empty"
    },
    {
      "x": -15,
      "y": 26,
      "z": 1,
      "name": "Empty"
    },
    {
      "x": -15,
      "y": 27,
      "z": 1,
      "name": "Empty"
    },
    {
      "x": -15,
      "y": 28,
      "z": 1,
      "name": "Rock_Slate_Brick_Half",
      "rotation": 8
    },
    {
      "x": -15,
      "y": 29,
      "z": 1,
      "name": "Rock_Slate_Brick_Half",
      "rotation": 7
    },
    {
      "x": -15,
      "y": 30,
      "z": 1,
      "name": "Empty"
    },
    {
      "x": -15,
      "y": 31,
      "z": 1,
      "name": "Empty"
    },
    {
      "x": -15,
      "y": 32,
      "z": 1,
      "name": "Empty"
    },
    {
      "x": -15,
      "y": 33,
      "z": 1,
      "name": "Empty"
    },
    {
      "x": -15,
      "y": 34,
      "z": 1,
      "name": "Empty"
    },
    {
      "x": -15,
      "y": 5,
      "z": 2,
      "name": "Rock_Slate"
    },
    {
      "x": -15,
      "y": 6,
      "z": 2,
      "name": "Rock_Slate"
    },
    {
      "x": -15,
      "y": 7,
      "z": 2,
      "name": "Rock_Slate"
    },
    {
      "x": -15,
      "y": 8,
      "z": 2,
      "name": "Rock_Slate"
    },
    {
      "x": -15,
      "y": 9,
      "z": 2,
      "name": "Rock_Slate"
    },
    {
      "x": -15,
      "y": 10,
      "z": 2,
      "name": "Rock_Slate"
    },
    {
      "x": -15,
      "y": 11,
      "z": 2,
      "name": "Rock_Slate"
    },
    {
      "x": -15,
      "y": 12,
      "z": 2,
      "name": "Rock_Slate"
    },
    {
      "x": -15,
      "y": 13,
      "z": 2,
      "name": "Rock_Slate"
    },
    {
      "x": -15,
      "y": 14,
      "z": 2,
      "name": "Rock_Slate"
    },
    {
      "x": -15,
      "y": 15,
      "z": 2,
      "name": "Rock_Slate_Brick_Decorative"
    },
    {
      "x": -15,
      "y": 16,
      "z": 2,
      "name": "Sword_Cemetery_1",
      "rotation": 3
    },
    {
      "x": -15,
      "y": 17,
      "z": 2,
      "name": "Empty"
    },
    {
      "x": -15,
      "y": 18,
      "z": 2,
      "name": "Empty"
    },
    {
      "x": -15,
      "y": 19,
      "z": 2,
      "name": "Empty"
    },
    {
      "x": -15,
      "y": 20,
      "z": 2,
      "name": "Empty"
    },
    {
      "x": -15,
      "y": 21,
      "z": 2,
      "name": "Empty"
    },
    {
      "x": -15,
      "y": 22,
      "z": 2,
      "name": "Empty"
    },
    {
      "x": -15,
      "y": 23,
      "z": 2,
      "name": "Rock_Slate_Brick_Decorative"
    },
    {
      "x": -15,
      "y": 24,
      "z": 2,
      "name": "Empty"
    },
    {
      "x": -15,
      "y": 25,
      "z": 2,
      "name": "Empty"
    },
    {
      "x": -15,
      "y": 26,
      "z": 2,
      "name": "Empty"
    },
    {
      "x": -15,
      "y": 27,
      "z": 2,
      "name": "Empty"
    },
    {
      "x": -15,
      "y": 28,
      "z": 2,
      "name": "Rock_Slate_Brick_Half",
      "rotation": 8
    },
    {
      "x": -15,
      "y": 29,
      "z": 2,
      "name": "Rock_Slate_Brick_Half",
      "rotation": 7
    },
    {
      "x": -15,
      "y": 30,
      "z": 2,
      "name": "Empty"
    },
    {
      "x": -15,
      "y": 31,
      "z": 2,
      "name": "Empty"
    },
    {
      "x": -15,
      "y": 32,
      "z": 2,
      "name": "Empty"
    },
    {
      "x": -15,
      "y": 33,
      "z": 2,
      "name": "Empty"
    },
    {
      "x": -15,
      "y": 34,
      "z": 2,
      "name": "Empty"
    },
    {
      "x": -15,
      "y": 5,
      "z": 3,
      "name": "Rock_Slate"
    },
    {
      "x": -15,
      "y": 6,
      "z": 3,
      "name": "Rock_Slate"
    },
    {
      "x": -15,
      "y": 7,
      "z": 3,
      "name": "Rock_Slate"
    },
    {
      "x": -15,
      "y": 8,
      "z": 3,
      "name": "Rock_Slate"
    },
    {
      "x": -15,
      "y": 9,
      "z": 3,
      "name": "Rock_Slate"
    },
    {
      "x": -15,
      "y": 10,
      "z": 3,
      "name": "Rock_Slate"
    },
    {
      "x": -15,
      "y": 11,
      "z": 3,
      "name": "Rock_Slate"
    },
    {
      "x": -15,
      "y": 12,
      "z": 3,
      "name": "Rock_Slate"
    },
    {
      "x": -15,
      "y": 13,
      "z": 3,
      "name": "Rock_Slate"
    },
    {
      "x": -15,
      "y": 14,
      "z": 3,
      "name": "Rock_Slate"
    },
    {
      "x": -15,
      "y": 15,
      "z": 3,
      "name": "Necrotic_Brick_Stone"
    },
    {
      "x": -15,
      "y": 16,
      "z": 3,
      "name": "Empty"
    },
    {
      "x": -15,
      "y": 17,
      "z": 3,
      "name": "Empty"
    },
    {
      "x": -15,
      "y": 18,
      "z": 3,
      "name": "Empty"
    },
    {
      "x": -15,
      "y": 19,
      "z": 3,
      "name": "Empty"
    },
    {
      "x": -15,
      "y": 20,
      "z": 3,
      "name": "Empty"
    },
    {
      "x": -15,
      "y": 21,
      "z": 3,
      "name": "Empty"
    },
    {
      "x": -15,
      "y": 22,
      "z": 3,
      "name": "Rock_Slate_Brick_Half",
      "rotation": 8
    },
    {
      "x": -15,
      "y": 23,
      "z": 3,
      "name": "Rock_Slate_Brick_Decorative"
    },
    {
      "x": -15,
      "y": 24,
      "z": 3,
      "name": "Empty"
    },
    {
      "x": -15,
      "y": 25,
      "z": 3,
      "name": "Empty"
    },
    {
      "x": -15,
      "y": 26,
      "z": 3,
      "name": "Empty"
    },
    {
      "x": -15,
      "y": 27,
      "z": 3,
      "name": "Empty"
    },
    {
      "x": -15,
      "y": 28,
      "z": 3,
      "name": "Rock_Slate_Brick_Half",
      "rotation": 8
    },
    {
      "x": -15,
      "y": 29,
      "z": 3,
      "name": "Rock_Slate_Brick_Half",
      "rotation": 7
    },
    {
      "x": -15,
      "y": 30,
      "z": 3,
      "name": "Empty"
    },
    {
      "x": -15,
      "y": 31,
      "z": 3,
      "name": "Empty"
    },
    {
      "x": -15,
      "y": 32,
      "z": 3,
      "name": "Empty"
    },
    {
      "x": -15,
      "y": 33,
      "z": 3,
      "name": "Empty"
    },
    {
      "x": -15,
      "y": 34,
      "z": 3,
      "name": "Empty"
    },
    {
      "x": -15,
      "y": 5,
      "z": 4,
      "name": "Rock_Slate"
    },
    {
      "x": -15,
      "y": 6,
      "z": 4,
      "name": "Rock_Slate"
    },
    {
      "x": -15,
      "y": 7,
      "z": 4,
      "name": "Rock_Slate"
    },
    {
      "x": -15,
      "y": 8,
      "z": 4,
      "name": "Rock_Slate"
    },
    {
      "x": -15,
      "y": 9,
      "z": 4,
      "name": "Rock_Slate"
    },
    {
      "x": -15,
      "y": 10,
      "z": 4,
      "name": "Rock_Slate"
    },
    {
      "x": -15,
      "y": 11,
      "z": 4,
      "name": "Rock_Slate"
    },
    {
      "x": -15,
      "y": 12,
      "z": 4,
      "name": "Rock_Slate"
    },
    {
      "x": -15,
      "y": 13,
      "z": 4,
      "name": "Rock_Slate"
    },
    {
      "x": -15,
      "y": 14,
      "z": 4,
      "name": "Rock_Slate"
    },
    {
      "x": -15,
      "y": 15,
      "z": 4,
      "name": "Necrotic_Brick_Stone"
    },
    {
      "x": -15,
      "y": 16,
      "z": 4,
      "name": "Sword_Cemetery_2",
      "rotation": 3
    },
    {
      "x": -15,
      "y": 17,
      "z": 4,
      "name": "Empty"
    },
    {
      "x": -15,
      "y": 18,
      "z": 4,
      "name": "Empty"
    },
    {
      "x": -15,
      "y": 19,
      "z": 4,
      "name": "Empty"
    },
    {
      "x": -15,
      "y": 20,
      "z": 4,
      "name": "Empty"
    },
    {
      "x": -15,
      "y": 21,
      "z": 4,
      "name": "Empty"
    },
    {
      "x": -15,
      "y": 22,
      "z": 4,
      "name": "Rock_Slate_Brick_Half",
      "rotation": 8
    },
    {
      "x": -15,
      "y": 23,
      "z": 4,
      "name": "Rock_Slate_Brick_Decorative"
    },
    {
      "x": -15,
      "y": 24,
      "z": 4,
      "name": "Rock_Slate_Brick_Wall"
    },
    {
      "x": -15,
      "y": 25,
      "z": 4,
      "name": "Empty"
    },
    {
      "x": -15,
      "y": 26,
      "z": 4,
      "name": "Empty"
    },
    {
      "x": -15,
      "y": 27,
      "z": 4,
      "name": "Empty"
    },
    {
      "x": -15,
      "y": 28,
      "z": 4,
      "name": "Rock_Slate_Brick_Decorative"
    },
    {
      "x": -15,
      "y": 29,
      "z": 4,
      "name": "Rock_Slate_Brick_Half",
      "rotation": 7
    },
    {
      "x": -15,
      "y": 30,
      "z": 4,
      "name": "Empty"
    },
    {
      "x": -15,
      "y": 31,
      "z": 4,
      "name": "Empty"
    },
    {
      "x": -15,
      "y": 32,
      "z": 4,
      "name": "Empty"
    },
    {
      "x": -15,
      "y": 33,
      "z": 4,
      "name": "Empty"
    },
    {
      "x": -15,
      "y": 34,
      "z": 4,
      "name": "Empty"
    },
    {
      "x": -15,
      "y": 5,
      "z": 5,
      "name": "Rock_Slate"
    },
    {
      "x": -15,
      "y": 6,
      "z": 5,
      "name": "Rock_Slate"
    },
    {
      "x": -15,
      "y": 7,
      "z": 5,
      "name": "Rock_Slate"
    },
    {
      "x": -15,
      "y": 8,
      "z": 5,
      "name": "Rock_Slate"
    },
    {
      "x": -15,
      "y": 9,
      "z": 5,
      "name": "Rock_Slate"
    },
    {
      "x": -15,
      "y": 10,
      "z": 5,
      "name": "Rock_Slate"
    },
    {
      "x": -15,
      "y": 11,
      "z": 5,
      "name": "Rock_Slate"
    },
    {
      "x": -15,
      "y": 12,
      "z": 5,
      "name": "Rock_Slate"
    },
    {
      "x": -15,
      "y": 13,
      "z": 5,
      "name": "Rock_Slate"
    },
    {
      "x": -15,
      "y": 14,
      "z": 5,
      "name": "Rock_Slate"
    },
    {
      "x": -15,
      "y": 15,
      "z": 5,
      "name": "Rock_Slate"
    },
    {
      "x": -15,
      "y": 16,
      "z": 5,
      "name": "Rock_Slate_Brick_Decorative"
    },
    {
      "x": -15,
      "y": 17,
      "z": 5,
      "name": "Furniture_Human_Ruins_Brazier"
    },
    {
      "x": -15,
      "y": 18,
      "z": 5,
      "name": "Empty"
    },
    {
      "x": -15,
      "y": 19,
      "z": 5,
      "name": "Empty"
    },
    {
      "x": -15,
      "y": 20,
      "z": 5,
      "name": "Empty"
    },
    {
      "x": -15,
      "y": 21,
      "z": 5,
      "name": "Empty"
    },
    {
      "x": -15,
      "y": 22,
      "z": 5,
      "name": "Rock_Slate_Brick_Decorative"
    },
    {
      "x": -15,
      "y": 23,
      "z": 5,
      "name": "Rock_Slate_Brick_Decorative"
    },
    {
      "x": -15,
      "y": 24,
      "z": 5,
      "name": "Furniture_Human_Ruins_Brazier"
    },
    {
      "x": -15,
      "y": 25,
      "z": 5,
      "name": "Empty"
    },
    {
      "x": -15,
      "y": 26,
      "z": 5,
      "name": "Empty"
    },
    {
      "x": -15,
      "y": 27,
      "z": 5,
      "name": "Rock_Slate_Brick_Stairs",
      "rotation": 8
    },
    {
      "x": -15,
      "y": 28,
      "z": 5,
      "name": "Rock_Slate_Brick_Decorative"
    },
    {
      "x": -15,
      "y": 29,
      "z": 5,
      "name": "Rock_Slate_Brick_Half",
      "rotation": 7
    },
    {
      "x": -15,
      "y": 30,
      "z": 5,
      "name": "Empty"
    },
    {
      "x": -15,
      "y": 31,
      "z": 5,
      "name": "Empty"
    },
    {
      "x": -15,
      "y": 32,
      "z": 5,
      "name": "Empty"
    },
    {
      "x": -15,
      "y": 33,
      "z": 5,
      "name": "Empty"
    },
    {
      "x": -15,
      "y": 34,
      "z": 5,
      "name": "Empty"
    },
    {
      "x": -15,
      "y": 5,
      "z": 6,
      "name": "Rock_Slate"
    },
    {
      "x": -15,
      "y": 6,
      "z": 6,
      "name": "Rock_Slate"
    },
    {
      "x": -15,
      "y": 7,
      "z": 6,
      "name": "Rock_Slate"
    },
    {
      "x": -15,
      "y": 8,
      "z": 6,
      "name": "Rock_Slate"
    },
    {
      "x": -15,
      "y": 9,
      "z": 6,
      "name": "Rock_Slate"
    },
    {
      "x": -15,
      "y": 10,
      "z": 6,
      "name": "Rock_Slate"
    },
    {
      "x": -15,
      "y": 11,
      "z": 6,
      "name": "Rock_Slate"
    },
    {
      "x": -15,
      "y": 12,
      "z": 6,
      "name": "Rock_Slate"
    },
    {
      "x": -15,
      "y": 13,
      "z": 6,
      "name": "Rock_Slate"
    },
    {
      "x": -15,
      "y": 14,
      "z": 6,
      "name": "Rock_Slate"
    },
    {
      "x": -15,
      "y": 15,
      "z": 6,
      "name": "Rock_Slate"
    },
    {
      "x": -15,
      "y": 16,
      "z": 6,
      "name": "Rock_Slate_Brick_Decorative"
    },
    {
      "x": -15,
      "y": 17,
      "z": 6,
      "name": "Rock_Slate_Brick_Decorative"
    },
    {
      "x": -15,
      "y": 18,
      "z": 6,
      "name": "Rock_Slate_Brick_Half",
      "rotation": 7
    },
    {
      "x": -15,
      "y": 19,
      "z": 6,
      "name": "Rock_Slate_Brick_Half",
      "rotation": 7
    },
    {
      "x": -15,
      "y": 20,
      "z": 6,
      "name": "Rock_Slate_Brick_Half",
      "rotation": 7
    },
    {
      "x": -15,
      "y": 21,
      "z": 6,
      "name": "Rock_Slate_Brick_Half",
      "rotation": 7
    },
    {
      "x": -15,
      "y": 22,
      "z": 6,
      "name": "Rock_Slate_Brick_Decorative"
    },
    {
      "x": -15,
      "y": 23,
      "z": 6,
      "name": "Rock_Slate_Brick_Decorative"
    },
    {
      "x": -15,
      "y": 24,
      "z": 6,
      "name": "Necrotic_Pillar"
    },
    {
      "x": -15,
      "y": 25,
      "z": 6,
      "name": "Necrotic_Pillar"
    },
    {
      "x": -15,
      "y": 26,
      "z": 6,
      "name": "Necrotic_Pillar",
      "rotation": 8
    },
    {
      "x": -15,
      "y": 27,
      "z": 6,
      "name": "Necrotic_Stone_Brick_Decorative"
    },
    {
      "x": -15,
      "y": 28,
      "z": 6,
      "name": "Rock_Slate_Brick_Decorative"
    },
    {
      "x": -15,
      "y": 29,
      "z": 6,
      "name": "Rock_Slate_Brick_Decorative"
    },
    {
      "x": -15,
      "y": 30,
      "z": 6,
      "name": "Necrotic_Pillar"
    },
    {
      "x": -15,
      "y": 31,
      "z": 6,
      "name": "Necrotic_Pillar"
    },
    {
      "x": -15,
      "y": 32,
      "z": 6,
      "name": "Necrotic_Pillar"
    },
    {
      "x": -15,
      "y": 33,
      "z": 6,
      "name": "Necrotic_Pillar"
    },
    {
      "x": -15,
      "y": 34,
      "z": 6,
      "name": "Empty"
    },
    {
      "x": -15,
      "y": 5,
      "z": 7,
      "name": "Rock_Slate"
    },
    {
      "x": -15,
      "y": 6,
      "z": 7,
      "name": "Rock_Slate"
    },
    {
      "x": -15,
      "y": 7,
      "z": 7,
      "name": "Rock_Slate"
    },
    {
      "x": -15,
      "y": 8,
      "z": 7,
      "name": "Rock_Slate"
    },
    {
      "x": -15,
      "y": 9,
      "z": 7,
      "name": "Rock_Slate"
    },
    {
      "x": -15,
      "y": 10,
      "z": 7,
      "name": "Rock_Slate"
    },
    {
      "x": -15,
      "y": 11,
      "z": 7,
      "name": "Rock_Slate"
    },
    {
      "x": -15,
      "y": 12,
      "z": 7,
      "name": "Rock_Slate"
    },
    {
      "x": -15,
      "y": 13,
      "z": 7,
      "name": "Rock_Slate"
    },
    {
      "x": -15,
      "y": 14,
      "z": 7,
      "name": "Rock_Slate"
    },
    {
      "x": -15,
      "y": 15,
      "z": 7,
      "name": "Necrotic_Dirt"
    },
    {
      "x": -15,
      "y": 16,
      "z": 7,
      "name": "Rubble_Slate"
    },
    {
      "x": -15,
      "y": 17,
      "z": 7,
      "name": "Empty"
    },
    {
      "x": -15,
      "y": 18,
      "z": 7,
      "name": "Empty"
    },
    {
      "x": -15,
      "y": 19,
      "z": 7,
      "name": "Empty"
    },
    {
      "x": -15,
      "y": 20,
      "z": 7,
      "name": "Empty"
    },
    {
      "x": -15,
      "y": 21,
      "z": 7,
      "name": "Empty"
    },
    {
      "x": -15,
      "y": 22,
      "z": 7,
      "name": "Empty"
    },
    {
      "x": -15,
      "y": 23,
      "z": 7,
      "name": "Empty"
    },
    {
      "x": -15,
      "y": 24,
      "z": 7,
      "name": "Empty"
    },
    {
      "x": -15,
      "y": 25,
      "z": 7,
      "name": "Empty"
    },
    {
      "x": -15,
      "y": 26,
      "z": 7,
      "name": "Empty"
    },
    {
      "x": -15,
      "y": 27,
      "z": 7,
      "name": "Empty"
    },
    {
      "x": -15,
      "y": 28,
      "z": 7,
      "name": "Rock_Slate_Brick_Decorative"
    },
    {
      "x": -15,
      "y": 29,
      "z": 7,
      "name": "Rock_Slate_Brick_Decorative"
    },
    {
      "x": -15,
      "y": 30,
      "z": 7,
      "name": "Empty"
    },
    {
      "x": -15,
      "y": 31,
      "z": 7,
      "name": "Empty"
    },
    {
      "x": -15,
      "y": 32,
      "z": 7,
      "name": "Empty"
    },
    {
      "x": -15,
      "y": 33,
      "z": 7,
      "name": "Empty"
    },
    {
      "x": -15,
      "y": 34,
      "z": 7,
      "name": "Empty"
    },
    {
      "x": -15,
      "y": 6,
      "z": 8,
      "name": "Rock_Slate"
    },
    {
      "x": -15,
      "y": 7,
      "z": 8,
      "name": "Rock_Slate"
    },
    {
      "x": -15,
      "y": 8,
      "z": 8,
      "name": "Rock_Slate"
    },
    {
      "x": -15,
      "y": 9,
      "z": 8,
      "name": "Rock_Slate"
    },
    {
      "x": -15,
      "y": 10,
      "z": 8,
      "name": "Rock_Slate"
    },
    {
      "x": -15,
      "y": 11,
      "z": 8,
      "name": "Rock_Slate"
    },
    {
      "x": -15,
      "y": 12,
      "z": 8,
      "name": "Rock_Slate"
    },
    {
      "x": -15,
      "y": 13,
      "z": 8,
      "name": "Rock_Slate"
    },
    {
      "x": -15,
      "y": 14,
      "z": 8,
      "name": "Rock_Slate"
    },
    {
      "x": -15,
      "y": 15,
      "z": 8,
      "name": "Sword_Cemetery_2"
    },
    {
      "x": -15,
      "y": 6,
      "z": 9,
      "name": "Rock_Slate"
    },
    {
      "x": -15,
      "y": 7,
      "z": 9,
      "name": "Rock_Slate"
    },
    {
      "x": -15,
      "y": 8,
      "z": 9,
      "name": "Rock_Slate"
    },
    {
      "x": -15,
      "y": 9,
      "z": 9,
      "name": "Rock_Slate"
    },
    {
      "x": -15,
      "y": 10,
      "z": 9,
      "name": "Rock_Slate"
    },
    {
      "x": -15,
      "y": 11,
      "z": 9,
      "name": "Rock_Slate"
    },
    {
      "x": -15,
      "y": 12,
      "z": 9,
      "name": "Rock_Slate"
    },
    {
      "x": -15,
      "y": 13,
      "z": 9,
      "name": "Rock_Slate"
    },
    {
      "x": -15,
      "y": 9,
      "z": 10,
      "name": "Rock_Slate"
    },
    {
      "x": -15,
      "y": 10,
      "z": 10,
      "name": "Rock_Slate"
    },
    {
      "x": -15,
      "y": 11,
      "z": 10,
      "name": "Rock_Slate"
    },
    {
      "x": -15,
      "y": 12,
      "z": 10,
      "name": "Rock_Slate"
    },
    {
      "x": -14,
      "y": 8,
      "z": -11,
      "name": "Rock_Slate"
    },
    {
      "x": -14,
      "y": 9,
      "z": -11,
      "name": "Rock_Slate"
    },
    {
      "x": -14,
      "y": 10,
      "z": -11,
      "name": "Rock_Slate"
    },
    {
      "x": -14,
      "y": 6,
      "z": -10,
      "name": "Rock_Slate"
    },
    {
      "x": -14,
      "y": 7,
      "z": -10,
      "name": "Rock_Slate"
    },
    {
      "x": -14,
      "y": 8,
      "z": -10,
      "name": "Rock_Slate"
    },
    {
      "x": -14,
      "y": 9,
      "z": -10,
      "name": "Rock_Slate"
    },
    {
      "x": -14,
      "y": 10,
      "z": -10,
      "name": "Rock_Slate"
    },
    {
      "x": -14,
      "y": 11,
      "z": -10,
      "name": "Rock_Slate"
    },
    {
      "x": -14,
      "y": 12,
      "z": -10,
      "name": "Rock_Slate"
    },
    {
      "x": -14,
      "y": 13,
      "z": -10,
      "name": "Rock_Slate"
    },
    {
      "x": -14,
      "y": 5,
      "z": -9,
      "name": "Rock_Slate"
    },
    {
      "x": -14,
      "y": 6,
      "z": -9,
      "name": "Rock_Slate"
    },
    {
      "x": -14,
      "y": 7,
      "z": -9,
      "name": "Rock_Slate"
    },
    {
      "x": -14,
      "y": 8,
      "z": -9,
      "name": "Rock_Slate"
    },
    {
      "x": -14,
      "y": 9,
      "z": -9,
      "name": "Rock_Slate"
    },
    {
      "x": -14,
      "y": 10,
      "z": -9,
      "name": "Rock_Slate"
    },
    {
      "x": -14,
      "y": 11,
      "z": -9,
      "name": "Rock_Slate"
    },
    {
      "x": -14,
      "y": 12,
      "z": -9,
      "name": "Rock_Slate"
    },
    {
      "x": -14,
      "y": 13,
      "z": -9,
      "name": "Rock_Slate"
    },
    {
      "x": -14,
      "y": 14,
      "z": -9,
      "name": "Rock_Slate"
    },
    {
      "x": -14,
      "y": 5,
      "z": -8,
      "name": "Rock_Slate"
    },
    {
      "x": -14,
      "y": 6,
      "z": -8,
      "name": "Rock_Slate"
    },
    {
      "x": -14,
      "y": 7,
      "z": -8,
      "name": "Rock_Slate"
    },
    {
      "x": -14,
      "y": 8,
      "z": -8,
      "name": "Rock_Slate"
    },
    {
      "x": -14,
      "y": 9,
      "z": -8,
      "name": "Rock_Slate"
    },
    {
      "x": -14,
      "y": 10,
      "z": -8,
      "name": "Rock_Slate"
    },
    {
      "x": -14,
      "y": 11,
      "z": -8,
      "name": "Rock_Slate"
    },
    {
      "x": -14,
      "y": 12,
      "z": -8,
      "name": "Rock_Slate"
    },
    {
      "x": -14,
      "y": 13,
      "z": -8,
      "name": "Rock_Slate"
    },
    {
      "x": -14,
      "y": 14,
      "z": -8,
      "name": "Rock_Slate"
    },
    {
      "x": -14,
      "y": 5,
      "z": -7,
      "name": "Rock_Slate"
    },
    {
      "x": -14,
      "y": 6,
      "z": -7,
      "name": "Rock_Slate"
    },
    {
      "x": -14,
      "y": 7,
      "z": -7,
      "name": "Rock_Slate"
    },
    {
      "x": -14,
      "y": 8,
      "z": -7,
      "name": "Rock_Slate"
    },
    {
      "x": -14,
      "y": 9,
      "z": -7,
      "name": "Rock_Slate"
    },
    {
      "x": -14,
      "y": 10,
      "z": -7,
      "name": "Rock_Slate"
    },
    {
      "x": -14,
      "y": 11,
      "z": -7,
      "name": "Rock_Slate"
    },
    {
      "x": -14,
      "y": 12,
      "z": -7,
      "name": "Rock_Slate"
    },
    {
      "x": -14,
      "y": 13,
      "z": -7,
      "name": "Rock_Slate"
    },
    {
      "x": -14,
      "y": 14,
      "z": -7,
      "name": "Rock_Slate"
    },
    {
      "x": -14,
      "y": 25,
      "z": -7,
      "name": "Rock_Slate_Brick_Half",
      "rotation": 7
    },
    {
      "x": -14,
      "y": 4,
      "z": -6,
      "name": "Rock_Slate"
    },
    {
      "x": -14,
      "y": 5,
      "z": -6,
      "name": "Rock_Slate"
    },
    {
      "x": -14,
      "y": 6,
      "z": -6,
      "name": "Rock_Slate"
    },
    {
      "x": -14,
      "y": 7,
      "z": -6,
      "name": "Rock_Slate"
    },
    {
      "x": -14,
      "y": 8,
      "z": -6,
      "name": "Rock_Slate"
    },
    {
      "x": -14,
      "y": 9,
      "z": -6,
      "name": "Rock_Slate"
    },
    {
      "x": -14,
      "y": 10,
      "z": -6,
      "name": "Rock_Slate"
    },
    {
      "x": -14,
      "y": 11,
      "z": -6,
      "name": "Rock_Slate"
    },
    {
      "x": -14,
      "y": 12,
      "z": -6,
      "name": "Rock_Slate"
    },
    {
      "x": -14,
      "y": 13,
      "z": -6,
      "name": "Rock_Slate"
    },
    {
      "x": -14,
      "y": 14,
      "z": -6,
      "name": "Necrotic_Sand"
    },
    {
      "x": -14,
      "y": 15,
      "z": -6,
      "name": "Empty"
    },
    {
      "x": -14,
      "y": 16,
      "z": -6,
      "name": "Empty"
    },
    {
      "x": -14,
      "y": 17,
      "z": -6,
      "name": "Empty"
    },
    {
      "x": -14,
      "y": 18,
      "z": -6,
      "name": "Empty"
    },
    {
      "x": -14,
      "y": 19,
      "z": -6,
      "name": "Empty"
    },
    {
      "x": -14,
      "y": 20,
      "z": -6,
      "name": "Empty"
    },
    {
      "x": -14,
      "y": 21,
      "z": -6,
      "name": "Empty"
    },
    {
      "x": -14,
      "y": 22,
      "z": -6,
      "name": "Empty"
    },
    {
      "x": -14,
      "y": 23,
      "z": -6,
      "name": "Empty"
    },
    {
      "x": -14,
      "y": 24,
      "z": -6,
      "name": "Empty"
    },
    {
      "x": -14,
      "y": 25,
      "z": -6,
      "name": "Rock_Slate_Brick_Half",
      "rotation": 7
    },
    {
      "x": -14,
      "y": 26,
      "z": -6,
      "name": "Empty"
    },
    {
      "x": -14,
      "y": 27,
      "z": -6,
      "name": "Empty"
    },
    {
      "x": -14,
      "y": 28,
      "z": -6,
      "name": "Empty"
    },
    {
      "x": -14,
      "y": 29,
      "z": -6,
      "name": "Empty"
    },
    {
      "x": -14,
      "y": 30,
      "z": -6,
      "name": "Empty"
    },
    {
      "x": -14,
      "y": 31,
      "z": -6,
      "name": "Empty"
    },
    {
      "x": -14,
      "y": 32,
      "z": -6,
      "name": "Empty"
    },
    {
      "x": -14,
      "y": 33,
      "z": -6,
      "name": "Empty"
    },
    {
      "x": -14,
      "y": 34,
      "z": -6,
      "name": "Empty"
    },
    {
      "x": -14,
      "y": 4,
      "z": -5,
      "name": "Rock_Slate"
    },
    {
      "x": -14,
      "y": 5,
      "z": -5,
      "name": "Rock_Slate"
    },
    {
      "x": -14,
      "y": 6,
      "z": -5,
      "name": "Rock_Slate"
    },
    {
      "x": -14,
      "y": 7,
      "z": -5,
      "name": "Rock_Slate"
    },
    {
      "x": -14,
      "y": 8,
      "z": -5,
      "name": "Rock_Slate"
    },
    {
      "x": -14,
      "y": 9,
      "z": -5,
      "name": "Rock_Slate"
    },
    {
      "x": -14,
      "y": 10,
      "z": -5,
      "name": "Rock_Slate"
    },
    {
      "x": -14,
      "y": 11,
      "z": -5,
      "name": "Rock_Slate"
    },
    {
      "x": -14,
      "y": 12,
      "z": -5,
      "name": "Rock_Slate"
    },
    {
      "x": -14,
      "y": 13,
      "z": -5,
      "name": "Rock_Slate"
    },
    {
      "x": -14,
      "y": 14,
      "z": -5,
      "name": "Necrotic_Sand"
    },
    {
      "x": -14,
      "y": 15,
      "z": -5,
      "name": "Sword_Cemetery_3",
      "rotation": 2
    },
    {
      "x": -14,
      "y": 16,
      "z": -5,
      "name": "Empty"
    },
    {
      "x": -14,
      "y": 17,
      "z": -5,
      "name": "Empty"
    },
    {
      "x": -14,
      "y": 18,
      "z": -5,
      "name": "Empty"
    },
    {
      "x": -14,
      "y": 19,
      "z": -5,
      "name": "Empty"
    },
    {
      "x": -14,
      "y": 20,
      "z": -5,
      "name": "Empty"
    },
    {
      "x": -14,
      "y": 21,
      "z": -5,
      "name": "Empty"
    },
    {
      "x": -14,
      "y": 22,
      "z": -5,
      "name": "Empty"
    },
    {
      "x": -14,
      "y": 23,
      "z": -5,
      "name": "Empty"
    },
    {
      "x": -14,
      "y": 24,
      "z": -5,
      "name": "Empty"
    },
    {
      "x": -14,
      "y": 25,
      "z": -5,
      "name": "Rock_Slate_Brick_Half",
      "rotation": 7
    },
    {
      "x": -14,
      "y": 26,
      "z": -5,
      "name": "Empty"
    },
    {
      "x": -14,
      "y": 27,
      "z": -5,
      "name": "Empty"
    },
    {
      "x": -14,
      "y": 28,
      "z": -5,
      "name": "Empty"
    },
    {
      "x": -14,
      "y": 29,
      "z": -5,
      "name": "Empty"
    },
    {
      "x": -14,
      "y": 30,
      "z": -5,
      "name": "Empty"
    },
    {
      "x": -14,
      "y": 31,
      "z": -5,
      "name": "Empty"
    },
    {
      "x": -14,
      "y": 32,
      "z": -5,
      "name": "Empty"
    },
    {
      "x": -14,
      "y": 33,
      "z": -5,
      "name": "Empty"
    },
    {
      "x": -14,
      "y": 34,
      "z": -5,
      "name": "Empty"
    },
    {
      "x": -14,
      "y": 4,
      "z": -4,
      "name": "Rock_Slate"
    },
    {
      "x": -14,
      "y": 5,
      "z": -4,
      "name": "Rock_Slate"
    },
    {
      "x": -14,
      "y": 6,
      "z": -4,
      "name": "Rock_Slate"
    },
    {
      "x": -14,
      "y": 7,
      "z": -4,
      "name": "Rock_Slate"
    },
    {
      "x": -14,
      "y": 8,
      "z": -4,
      "name": "Rock_Slate"
    },
    {
      "x": -14,
      "y": 9,
      "z": -4,
      "name": "Rock_Slate"
    },
    {
      "x": -14,
      "y": 10,
      "z": -4,
      "name": "Rock_Slate"
    },
    {
      "x": -14,
      "y": 11,
      "z": -4,
      "name": "Rock_Slate"
    },
    {
      "x": -14,
      "y": 12,
      "z": -4,
      "name": "Rock_Slate"
    },
    {
      "x": -14,
      "y": 13,
      "z": -4,
      "name": "Rock_Slate"
    },
    {
      "x": -14,
      "y": 14,
      "z": -4,
      "name": "Necrotic_Sand"
    },
    {
      "x": -14,
      "y": 15,
      "z": -4,
      "name": "Plant_Bush_Winter",
      "support": 15
    },
    {
      "x": -14,
      "y": 16,
      "z": -4,
      "name": "Empty"
    },
    {
      "x": -14,
      "y": 17,
      "z": -4,
      "name": "Empty"
    },
    {
      "x": -14,
      "y": 18,
      "z": -4,
      "name": "Empty"
    },
    {
      "x": -14,
      "y": 19,
      "z": -4,
      "name": "Empty"
    },
    {
      "x": -14,
      "y": 20,
      "z": -4,
      "name": "Empty"
    },
    {
      "x": -14,
      "y": 21,
      "z": -4,
      "name": "Empty"
    },
    {
      "x": -14,
      "y": 22,
      "z": -4,
      "name": "Empty"
    },
    {
      "x": -14,
      "y": 23,
      "z": -4,
      "name": "Empty"
    },
    {
      "x": -14,
      "y": 24,
      "z": -4,
      "name": "Empty"
    },
    {
      "x": -14,
      "y": 25,
      "z": -4,
      "name": "Rock_Slate_Brick_Half",
      "rotation": 7
    },
    {
      "x": -14,
      "y": 26,
      "z": -4,
      "name": "Empty"
    },
    {
      "x": -14,
      "y": 27,
      "z": -4,
      "name": "Empty"
    },
    {
      "x": -14,
      "y": 28,
      "z": -4,
      "name": "Empty"
    },
    {
      "x": -14,
      "y": 29,
      "z": -4,
      "name": "Empty"
    },
    {
      "x": -14,
      "y": 30,
      "z": -4,
      "name": "Empty"
    },
    {
      "x": -14,
      "y": 31,
      "z": -4,
      "name": "Empty"
    },
    {
      "x": -14,
      "y": 32,
      "z": -4,
      "name": "Empty"
    },
    {
      "x": -14,
      "y": 33,
      "z": -4,
      "name": "Empty"
    },
    {
      "x": -14,
      "y": 34,
      "z": -4,
      "name": "Empty"
    },
    {
      "x": -14,
      "y": 4,
      "z": -3,
      "name": "Rock_Slate"
    },
    {
      "x": -14,
      "y": 5,
      "z": -3,
      "name": "Rock_Slate"
    },
    {
      "x": -14,
      "y": 6,
      "z": -3,
      "name": "Rock_Slate"
    },
    {
      "x": -14,
      "y": 7,
      "z": -3,
      "name": "Rock_Slate"
    },
    {
      "x": -14,
      "y": 8,
      "z": -3,
      "name": "Rock_Slate"
    },
    {
      "x": -14,
      "y": 9,
      "z": -3,
      "name": "Rock_Slate"
    },
    {
      "x": -14,
      "y": 10,
      "z": -3,
      "name": "Rock_Slate"
    },
    {
      "x": -14,
      "y": 11,
      "z": -3,
      "name": "Rock_Slate"
    },
    {
      "x": -14,
      "y": 12,
      "z": -3,
      "name": "Rock_Slate"
    },
    {
      "x": -14,
      "y": 13,
      "z": -3,
      "name": "Rock_Slate"
    },
    {
      "x": -14,
      "y": 14,
      "z": -3,
      "name": "Rock_Slate"
    },
    {
      "x": -14,
      "y": 15,
      "z": -3,
      "name": "Rock_Slate_Brick_Decorative"
    },
    {
      "x": -14,
      "y": 16,
      "z": -3,
      "name": "Rock_Slate_Brick_Decorative"
    },
    {
      "x": -14,
      "y": 17,
      "z": -3,
      "name": "Rock_Slate_Brick_Decorative"
    },
    {
      "x": -14,
      "y": 18,
      "z": -3,
      "name": "Rock_Slate_Brick_Half",
      "rotation": 6
    },
    {
      "x": -14,
      "y": 19,
      "z": -3,
      "name": "Rock_Slate_Brick_Half",
      "rotation": 6
    },
    {
      "x": -14,
      "y": 20,
      "z": -3,
      "name": "Rock_Slate_Brick_Half",
      "rotation": 6
    },
    {
      "x": -14,
      "y": 21,
      "z": -3,
      "name": "Rock_Slate_Brick_Half",
      "rotation": 6
    },
    {
      "x": -14,
      "y": 22,
      "z": -3,
      "name": "Rock_Slate_Brick_Decorative"
    },
    {
      "x": -14,
      "y": 23,
      "z": -3,
      "name": "Rock_Slate_Brick_Decorative"
    },
    {
      "x": -14,
      "y": 24,
      "z": -3,
      "name": "Necrotic_Pillar"
    },
    {
      "x": -14,
      "y": 25,
      "z": -3,
      "name": "Necrotic_Pillar"
    },
    {
      "x": -14,
      "y": 26,
      "z": -3,
      "name": "Necrotic_Pillar",
      "rotation": 8
    },
    {
      "x": -14,
      "y": 27,
      "z": -3,
      "name": "Necrotic_Stone_Brick_Decorative"
    },
    {
      "x": -14,
      "y": 28,
      "z": -3,
      "name": "Rock_Slate_Brick_Decorative"
    },
    {
      "x": -14,
      "y": 29,
      "z": -3,
      "name": "Rock_Slate_Brick_Decorative"
    },
    {
      "x": -14,
      "y": 30,
      "z": -3,
      "name": "Necrotic_Pillar"
    },
    {
      "x": -14,
      "y": 31,
      "z": -3,
      "name": "Necrotic_Pillar"
    },
    {
      "x": -14,
      "y": 32,
      "z": -3,
      "name": "Necrotic_Pillar"
    },
    {
      "x": -14,
      "y": 33,
      "z": -3,
      "name": "Necrotic_Pillar"
    },
    {
      "x": -14,
      "y": 34,
      "z": -3,
      "name": "Necrotic_Pillar",
      "rotation": 8
    },
    {
      "x": -14,
      "y": 35,
      "z": -3,
      "name": "Necrotic_Stone_Brick_Decorative"
    },
    {
      "x": -14,
      "y": 36,
      "z": -3,
      "name": "Rock_Slate_Brick_Decorative"
    },
    {
      "x": -14,
      "y": 37,
      "z": -3,
      "name": "Rock_Slate_Brick_Decorative"
    },
    {
      "x": -14,
      "y": 4,
      "z": -2,
      "name": "Rock_Slate"
    },
    {
      "x": -14,
      "y": 5,
      "z": -2,
      "name": "Rock_Slate"
    },
    {
      "x": -14,
      "y": 6,
      "z": -2,
      "name": "Rock_Slate"
    },
    {
      "x": -14,
      "y": 7,
      "z": -2,
      "name": "Rock_Slate"
    },
    {
      "x": -14,
      "y": 8,
      "z": -2,
      "name": "Rock_Slate"
    },
    {
      "x": -14,
      "y": 9,
      "z": -2,
      "name": "Rock_Slate"
    },
    {
      "x": -14,
      "y": 10,
      "z": -2,
      "name": "Rock_Slate"
    },
    {
      "x": -14,
      "y": 11,
      "z": -2,
      "name": "Rock_Slate"
    },
    {
      "x": -14,
      "y": 12,
      "z": -2,
      "name": "Rock_Slate"
    },
    {
      "x": -14,
      "y": 13,
      "z": -2,
      "name": "Rock_Slate"
    },
    {
      "x": -14,
      "y": 14,
      "z": -2,
      "name": "Rock_Slate"
    },
    {
      "x": -14,
      "y": 15,
      "z": -2,
      "name": "Necrotic_Brick_Stone"
    },
    {
      "x": -14,
      "y": 16,
      "z": -2,
      "name": "Necrotic_Brick_Stone"
    },
    {
      "x": -14,
      "y": 17,
      "z": -2,
      "name": "Necrotic_Brick_Stone"
    },
    {
      "x": -14,
      "y": 18,
      "z": -2,
      "name": "Necrotic_Brick_Stone"
    },
    {
      "x": -14,
      "y": 19,
      "z": -2,
      "name": "Necrotic_Brick_Stone"
    },
    {
      "x": -14,
      "y": 20,
      "z": -2,
      "name": "Necrotic_Brick_Stone"
    },
    {
      "x": -14,
      "y": 21,
      "z": -2,
      "name": "Necrotic_Brick_Stone"
    },
    {
      "x": -14,
      "y": 22,
      "z": -2,
      "name": "Necrotic_Brick_Stone"
    },
    {
      "x": -14,
      "y": 23,
      "z": -2,
      "name": "Rock_Slate_Brick_Decorative"
    },
    {
      "x": -14,
      "y": 24,
      "z": -2,
      "name": "Necrotic_Brick_Stone"
    },
    {
      "x": -14,
      "y": 25,
      "z": -2,
      "name": "Necrotic_Brick_Stone"
    },
    {
      "x": -14,
      "y": 26,
      "z": -2,
      "name": "Necrotic_Brick_Stone"
    },
    {
      "x": -14,
      "y": 27,
      "z": -2,
      "name": "Necrotic_Brick_Stone"
    },
    {
      "x": -14,
      "y": 28,
      "z": -2,
      "name": "Necrotic_Brick_Stone"
    },
    {
      "x": -14,
      "y": 29,
      "z": -2,
      "name": "Necrotic_Brick_Stone"
    },
    {
      "x": -14,
      "y": 30,
      "z": -2,
      "name": "Necrotic_Brick_Stone"
    },
    {
      "x": -14,
      "y": 31,
      "z": -2,
      "name": "Necrotic_Brick_Stone"
    },
    {
      "x": -14,
      "y": 32,
      "z": -2,
      "name": "Necrotic_Brick_Stone"
    },
    {
      "x": -14,
      "y": 33,
      "z": -2,
      "name": "Necrotic_Brick_Stone"
    },
    {
      "x": -14,
      "y": 34,
      "z": -2,
      "name": "Necrotic_Brick_Stone"
    },
    {
      "x": -14,
      "y": 35,
      "z": -2,
      "name": "Necrotic_Brick_Stone"
    },
    {
      "x": -14,
      "y": 36,
      "z": -2,
      "name": "Necrotic_Brick_Stone"
    },
    {
      "x": -14,
      "y": 37,
      "z": -2,
      "name": "Rock_Slate_Brick_Decorative"
    },
    {
      "x": -14,
      "y": 4,
      "z": -1,
      "name": "Rock_Slate"
    },
    {
      "x": -14,
      "y": 5,
      "z": -1,
      "name": "Rock_Slate"
    },
    {
      "x": -14,
      "y": 6,
      "z": -1,
      "name": "Rock_Slate"
    },
    {
      "x": -14,
      "y": 7,
      "z": -1,
      "name": "Rock_Slate"
    },
    {
      "x": -14,
      "y": 8,
      "z": -1,
      "name": "Rock_Slate"
    },
    {
      "x": -14,
      "y": 9,
      "z": -1,
      "name": "Rock_Slate"
    },
    {
      "x": -14,
      "y": 10,
      "z": -1,
      "name": "Rock_Slate"
    },
    {
      "x": -14,
      "y": 11,
      "z": -1,
      "name": "Rock_Slate"
    },
    {
      "x": -14,
      "y": 12,
      "z": -1,
      "name": "Rock_Slate"
    },
    {
      "x": -14,
      "y": 13,
      "z": -1,
      "name": "Rock_Slate"
    },
    {
      "x": -14,
      "y": 14,
      "z": -1,
      "name": "Rock_Slate"
    },
    {
      "x": -14,
      "y": 15,
      "z": -1,
      "name": "Necrotic_Brick_Stone"
    },
    {
      "x": -14,
      "y": 16,
      "z": -1,
      "name": "Necrotic_Brick_Stone"
    },
    {
      "x": -14,
      "y": 17,
      "z": -1,
      "name": "Necrotic_Brick_Stone"
    },
    {
      "x": -14,
      "y": 18,
      "z": -1,
      "name": "Necrotic_Brick_Stone"
    },
    {
      "x": -14,
      "y": 19,
      "z": -1,
      "name": "Necrotic_Brick_Stone"
    },
    {
      "x": -14,
      "y": 20,
      "z": -1,
      "name": "Necrotic_Brick_Stone"
    },
    {
      "x": -14,
      "y": 21,
      "z": -1,
      "name": "Necrotic_Brick_Stone"
    },
    {
      "x": -14,
      "y": 22,
      "z": -1,
      "name": "Necrotic_Brick_Stone"
    },
    {
      "x": -14,
      "y": 23,
      "z": -1,
      "name": "Rock_Slate_Brick_Decorative"
    },
    {
      "x": -14,
      "y": 24,
      "z": -1,
      "name": "Necrotic_Pebbles"
    },
    {
      "x": -14,
      "y": 25,
      "z": -1,
      "name": "Necrotic_Pebbles"
    },
    {
      "x": -14,
      "y": 26,
      "z": -1,
      "name": "Necrotic_Pebbles"
    },
    {
      "x": -14,
      "y": 27,
      "z": -1,
      "name": "Necrotic_Pebbles"
    },
    {
      "x": -14,
      "y": 28,
      "z": -1,
      "name": "Necrotic_Brick_Stone"
    },
    {
      "x": -14,
      "y": 29,
      "z": -1,
      "name": "Necrotic_Brick_Stone"
    },
    {
      "x": -14,
      "y": 30,
      "z": -1,
      "name": "Necrotic_Pebbles"
    },
    {
      "x": -14,
      "y": 31,
      "z": -1,
      "name": "Necrotic_Pebbles"
    },
    {
      "x": -14,
      "y": 32,
      "z": -1,
      "name": "Necrotic_Pebbles"
    },
    {
      "x": -14,
      "y": 33,
      "z": -1,
      "name": "Rock_Slate_Brick_Half",
      "rotation": 7
    },
    {
      "x": -14,
      "y": 34,
      "z": -1,
      "name": "Rock_Slate_Brick_Half",
      "rotation": 7
    },
    {
      "x": -14,
      "y": 35,
      "z": -1,
      "name": "Necrotic_Brick_Stone"
    },
    {
      "x": -14,
      "y": 36,
      "z": -1,
      "name": "Rock_Slate_Brick_Decorative"
    },
    {
      "x": -14,
      "y": 37,
      "z": -1,
      "name": "Rock_Slate_Brick_Decorative"
    },
    {
      "x": -14,
      "y": 4,
      "z": 0,
      "name": "Rock_Slate"
    },
    {
      "x": -14,
      "y": 5,
      "z": 0,
      "name": "Rock_Slate"
    },
    {
      "x": -14,
      "y": 6,
      "z": 0,
      "name": "Rock_Slate"
    },
    {
      "x": -14,
      "y": 7,
      "z": 0,
      "name": "Rock_Slate"
    },
    {
      "x": -14,
      "y": 8,
      "z": 0,
      "name": "Rock_Slate"
    },
    {
      "x": -14,
      "y": 9,
      "z": 0,
      "name": "Rock_Slate"
    },
    {
      "x": -14,
      "y": 10,
      "z": 0,
      "name": "Rock_Slate"
    },
    {
      "x": -14,
      "y": 11,
      "z": 0,
      "name": "Rock_Slate"
    },
    {
      "x": -14,
      "y": 12,
      "z": 0,
      "name": "Rock_Slate"
    },
    {
      "x": -14,
      "y": 13,
      "z": 0,
      "name": "Rock_Slate"
    },
    {
      "x": -14,
      "y": 14,
      "z": 0,
      "name": "Rock_Slate"
    },
    {
      "x": -14,
      "y": 15,
      "z": 0,
      "name": "Necrotic_Brick_Stone"
    },
    {
      "x": -14,
      "y": 16,
      "z": 0,
      "name": "Necrotic_Brick_Stone"
    },
    {
      "x": -14,
      "y": 17,
      "z": 0,
      "name": "Necrotic_Brick_Stone"
    },
    {
      "x": -14,
      "y": 18,
      "z": 0,
      "name": "Necrotic_Brick_Stone"
    },
    {
      "x": -14,
      "y": 19,
      "z": 0,
      "name": "Necrotic_Brick_Stone"
    },
    {
      "x": -14,
      "y": 20,
      "z": 0,
      "name": "Necrotic_Window",
      "rotation": 1
    },
    {
      "x": -14,
      "y": 21,
      "z": 0,
      "name": "Necrotic_Window",
      "rotation": 1
    },
    {
      "x": -14,
      "y": 22,
      "z": 0,
      "name": "Necrotic_Brick_Stone"
    },
    {
      "x": -14,
      "y": 23,
      "z": 0,
      "name": "Rock_Slate_Brick_Decorative"
    },
    {
      "x": -14,
      "y": 24,
      "z": 0,
      "name": "Necrotic_Pebbles"
    },
    {
      "x": -14,
      "y": 25,
      "z": 0,
      "name": "Necrotic_Window",
      "rotation": 1
    },
    {
      "x": -14,
      "y": 26,
      "z": 0,
      "name": "Necrotic_Window",
      "rotation": 1
    },
    {
      "x": -14,
      "y": 27,
      "z": 0,
      "name": "Necrotic_Pebbles"
    },
    {
      "x": -14,
      "y": 28,
      "z": 0,
      "name": "Necrotic_Brick_Stone"
    },
    {
      "x": -14,
      "y": 29,
      "z": 0,
      "name": "Necrotic_Brick_Stone"
    },
    {
      "x": -14,
      "y": 30,
      "z": 0,
      "name": "Necrotic_Pebbles"
    },
    {
      "x": -14,
      "y": 31,
      "z": 0,
      "name": "Necrotic_Pebbles"
    },
    {
      "x": -14,
      "y": 32,
      "z": 0,
      "name": "Rock_Slate_Brick_Half",
      "rotation": 7
    },
    {
      "x": -14,
      "y": 33,
      "z": 0,
      "name": "Rock_Slate_Brick_Half",
      "rotation": 7
    },
    {
      "x": -14,
      "y": 34,
      "z": 0,
      "name": "Rock_Slate_Brick_Half",
      "rotation": 7
    },
    {
      "x": -14,
      "y": 35,
      "z": 0,
      "name": "Rock_Slate_Brick_Decorative"
    },
    {
      "x": -14,
      "y": 36,
      "z": 0,
      "name": "Rock_Slate_Brick_Decorative"
    },
    {
      "x": -14,
      "y": 4,
      "z": 1,
      "name": "Rock_Slate"
    },
    {
      "x": -14,
