{
  "version": 8,
  "blockIdVersion": 11,
  "anchorX": 1,
  "anchorY": 6,
  "anchorZ": -1,
  "blocks": [
    {
      "x": -7,
      "y": 6,
      "z": -1,
      "name": "Necrotic_Sand"
    },
    {
      "x": -7,
      "y": 6,
      "z": 0,
      "name": "Necrotic_Sand"
    },
    {
      "x": -7,
      "y": 6,
      "z": 1,
      "name": "Necrotic_Sand"
    },
    {
      "x": -7,
      "y": 7,
      "z": 1,
      "name": "Dead_Branch"
    },
    {
      "x": -6,
      "y": 6,
      "z": -3,
      "name": "Necrotic_Sand"
    },
    {
      "x": -6,
      "y": 7,
      "z": -3,
      "name": "Necrotic_Grass"
    },
    {
      "x": -6,
      "y": 5,
      "z": -2,
      "name": "Wood_Burnt_Roots"
    },
    {
      "x": -6,
      "y": 6,
      "z": -2,
      "name": "Necrotic_Sand"
    },
    {
      "x": -6,
      "y": 4,
      "z": -1,
      "name": "Necrotic_Mud"
    },
    {
      "x": -6,
      "y": 5,
      "z": -1,
      "name": "Necrotic_Stone"
    },
    {
      "x": -6,
      "y": 6,
      "z": -1,
      "name": "Necrotic_Sand"
    },
    {
      "x": -6,
      "y": 7,
      "z": -1,
      "name": "Necrotic_Grass"
    },
    {
      "x": -6,
      "y": 4,
      "z": 0,
      "name": "Necrotic_Mud"
    },
    {
      "x": -6,
      "y": 5,
      "z": 0,
      "name": "Necrotic_Stone"
    },
    {
      "x": -6,
      "y": 6,
      "z": 0,
      "name": "Necrotic_Sand"
    },
    {
      "x": -6,
      "y": 5,
      "z": 1,
      "name": "Necrotic_Stone"
    },
    {
      "x": -6,
      "y": 6,
      "z": 1,
      "name": "Necrotic_Sand"
    },
    {
      "x": -6,
      "y": 5,
      "z": 2,
      "name": "Necrotic_Stone"
    },
    {
      "x": -6,
      "y": 6,
      "z": 2,
      "name": "Necrotic_Sand"
    },
    {
      "x": -6,
      "y": 5,
      "z": 3,
      "name": "Wood_Burnt_Roots"
    },
    {
      "x": -6,
      "y": 6,
      "z": 3,
      "name": "Necrotic_Sand"
    },
    {
      "x": -5,
      "y": 6,
      "z": -3,
      "name": "Necrotic_Sand"
    },
    {
      "x": -5,
      "y": 4,
      "z": -2,
      "name": "Necrotic_Mud"
    },
    {
      "x": -5,
      "y": 5,
      "z": -2,
      "name": "Necrotic_Stone"
    },
    {
      "x": -5,
      "y": 6,
      "z": -2,
      "name": "Necrotic_Sand"
    },
    {
      "x": -5,
      "y": 3,
      "z": -1,
      "name": "Necrotic_Stone_Deep"
    },
    {
      "x": -5,
      "y": 4,
      "z": -1,
      "name": "Necrotic_Mud"
    },
    {
      "x": -5,
      "y": 5,
      "z": -1,
      "name": "Necrotic_Stone"
    },
    {
      "x": -5,
      "y": 6,
      "z": -1,
      "name": "Necrotic_Sand"
    },
    {
      "x": -5,
      "y": 3,
      "z": 0,
      "name": "Necrotic_Stone_Deep"
    },
    {
      "x": -5,
      "y": 4,
      "z": 0,
      "name": "Necrotic_Mud"
    },
    {
      "x": -5,
      "y": 5,
      "z": 0,
      "name": "Necrotic_Stone"
    },
    {
      "x": -5,
      "y": 6,
      "z": 0,
      "name": "Necrotic_Sand"
    },
    {
      "x": -5,
      "y": 3,
      "z": 1,
      "name": "Wood_Burnt_Roots"
    },
    {
      "x": -5,
      "y": 4,
      "z": 1,
      "name": "Necrotic_Mud"
    },
    {
      "x": -5,
      "y": 5,
      "z": 1,
      "name": "Necrotic_Stone"
    },
    {
      "x": -5,
      "y": 6,
      "z": 1,
      "name": "Necrotic_Sand"
    },
    {
      "x": -5,
      "y": 4,
      "z": 2,
      "name": "Necrotic_Mud"
    },
    {
      "x": -5,
      "y": 5,
      "z": 2,
      "name": "Necrotic_Stone"
    },
    {
      "x": -5,
      "y": 6,
      "z": 2,
      "name": "Necrotic_Sand"
    },
    {
      "x": -5,
      "y": 5,
      "z": 3,
      "name": "Necrotic_Stone"
    },
    {
      "x": -5,
      "y": 6,
      "z": 3,
      "name": "Necrotic_Sand"
    },
    {
      "x": -5,
      "y": 7,
      "z": 3,
      "name": "Plant_Crop_Mushroom_Flatcap_Green",
      "components": {
        "Components": {
          "FarmingBlock": {
            "LastTickGameTime": "0001-01-01T12:00:00Z"
          }
        }
      }
    },
    {
      "x": -5,
      "y": 6,
      "z": 4,
      "name": "Necrotic_Sand"
    },
    {
      "x": -5,
      "y": 7,
      "z": 4,
      "name": "Necrotic_Grass"
    },
    {
      "x": -4,
      "y": 6,
      "z": -4,
      "name": "Necrotic_Sand"
    },
    {
      "x": -4,
      "y": 4,
      "z": -3,
      "name": "Necrotic_Mud"
    },
    {
      "x": -4,
      "y": 5,
      "z": -3,
      "name": "Necrotic_Stone"
    },
    {
      "x": -4,
      "y": 6,
      "z": -3,
      "name": "Necrotic_Sand"
    },
    {
      "x": -4,
      "y": 3,
      "z": -2,
      "name": "Necrotic_Stone_Deep"
    },
    {
      "x": -4,
      "y": 4,
      "z": -2,
      "name": "Necrotic_Mud"
    },
    {
      "x": -4,
      "y": 5,
      "z": -2,
      "name": "Necrotic_Stone"
    },
    {
      "x": -4,
      "y": 6,
      "z": -2,
      "name": "Necrotic_Sand"
    },
    {
      "x": -4,
      "y": 7,
      "z": -2,
      "name": "Necrotic_Sand"
    },
    {
      "x": -4,
      "y": 3,
      "z": -1,
      "name": "Necrotic_Stone_Deep"
    },
    {
      "x": -4,
      "y": 4,
      "z": -1,
      "name": "Necrotic_Mud"
    },
    {
      "x": -4,
      "y": 5,
      "z": -1,
      "name": "Necrotic_Stone"
    },
    {
      "x": -4,
      "y": 6,
      "z": -1,
      "name": "Necrotic_Sand"
    },
    {
      "x": -4,
      "y": 7,
      "z": -1,
      "name": "Necrotic_Sand"
    },
    {
      "x": -4,
      "y": 2,
      "z": 0,
      "name": "Wood_Burnt_Roots"
    },
    {
      "x": -4,
      "y": 3,
      "z": 0,
      "name": "Necrotic_Stone_Deep"
    },
    {
      "x": -4,
      "y": 4,
      "z": 0,
      "name": "Necrotic_Mud"
    },
    {
      "x": -4,
      "y": 5,
      "z": 0,
      "name": "Necrotic_Stone"
    },
    {
      "x": -4,
      "y": 6,
      "z": 0,
      "name": "Necrotic_Sand"
    },
    {
      "x": -4,
      "y": 7,
      "z": 0,
      "name": "Necrotic_Sand"
    },
    {
      "x": -4,
      "y": 8,
      "z": 0,
      "name": "Sword_Cemetery_3"
    },
    {
      "x": -4,
      "y": 3,
      "z": 1,
      "name": "Necrotic_Stone_Deep"
    },
    {
      "x": -4,
      "y": 4,
      "z": 1,
      "name": "Necrotic_Mud"
    },
    {
      "x": -4,
      "y": 5,
      "z": 1,
      "name": "Necrotic_Stone"
    },
    {
      "x": -4,
      "y": 6,
      "z": 1,
      "name": "Necrotic_Sand"
    },
    {
      "x": -4,
      "y": 7,
      "z": 1,
      "name": "Necrotic_Sand"
    },
    {
      "x": -4,
      "y": 8,
      "z": 1,
      "name": "Sword_Cemetery_2"
    },
    {
      "x": -4,
      "y": 4,
      "z": 2,
      "name": "Necrotic_Mud"
    },
    {
      "x": -4,
      "y": 5,
      "z": 2,
      "name": "Necrotic_Stone"
    },
    {
      "x": -4,
      "y": 6,
      "z": 2,
      "name": "Necrotic_Sand"
    },
    {
      "x": -4,
      "y": 7,
      "z": 2,
      "name": "Necrotic_Sand"
    },
    {
      "x": -4,
      "y": 5,
      "z": 3,
      "name": "Necrotic_Stone"
    },
    {
      "x": -4,
      "y": 6,
      "z": 3,
      "name": "Necrotic_Sand"
    },
    {
      "x": -4,
      "y": 5,
      "z": 4,
      "name": "Wood_Burnt_Roots"
    },
    {
      "x": -4,
      "y": 6,
      "z": 4,
      "name": "Necrotic_Sand"
    },
    {
      "x": -3,
      "y": 5,
      "z": -4,
      "name": "Wood_Burnt_Roots"
    },
    {
      "x": -3,
      "y": 6,
      "z": -4,
      "name": "Necrotic_Sand"
    },
    {
      "x": -3,
      "y": 7,
      "z": -4,
      "name": "Necrotic_Grass"
    },
    {
      "x": -3,
      "y": 4,
      "z": -3,
      "name": "Necrotic_Mud"
    },
    {
      "x": -3,
      "y": 5,
      "z": -3,
      "name": "Necrotic_Stone"
    },
    {
      "x": -3,
      "y": 6,
      "z": -3,
      "name": "Necrotic_Sand"
    },
    {
      "x": -3,
      "y": 7,
      "z": -3,
      "name": "Necrotic_Sand"
    },
    {
      "x": -3,
      "y": 2,
      "z": -2,
      "name": "Wood_Burnt_Roots"
    },
    {
      "x": -3,
      "y": 3,
      "z": -2,
      "name": "Necrotic_Stone_Deep"
    },
    {
      "x": -3,
      "y": 4,
      "z": -2,
      "name": "Necrotic_Mud"
    },
    {
      "x": -3,
      "y": 5,
      "z": -2,
      "name": "Necrotic_Stone"
    },
    {
      "x": -3,
      "y": 6,
      "z": -2,
      "name": "Necrotic_Sand"
    },
    {
      "x": -3,
      "y": 7,
      "z": -2,
      "name": "Necrotic_Sand"
    },
    {
      "x": -3,
      "y": 8,
      "z": -2,
      "name": "Dead_Branch"
    },
    {
      "x": -3,
      "y": 3,
      "z": -1,
      "name": "Necrotic_Stone_Deep"
    },
    {
      "x": -3,
      "y": 4,
      "z": -1,
      "name": "Necrotic_Mud"
    },
    {
      "x": -3,
      "y": 5,
      "z": -1,
      "name": "Necrotic_Stone"
    },
    {
      "x": -3,
      "y": 6,
      "z": -1,
      "name": "Necrotic_Sand"
    },
    {
      "x": -3,
      "y": 7,
      "z": -1,
      "name": "Necrotic_Sand"
    },
    {
      "x": -3,
      "y": 3,
      "z": 0,
      "name": "Necrotic_Stone_Deep"
    },
    {
      "x": -3,
      "y": 4,
      "z": 0,
      "name": "Necrotic_Mud"
    },
    {
      "x": -3,
      "y": 5,
      "z": 0,
      "name": "Necrotic_Stone"
    },
    {
      "x": -3,
      "y": 6,
      "z": 0,
      "name": "Necrotic_Sand"
    },
    {
      "x": -3,
      "y": 7,
      "z": 0,
      "name": "Necrotic_Sand"
    },
    {
      "x": -3,
      "y": 3,
      "z": 1,
      "name": "Necrotic_Stone_Deep"
    },
    {
      "x": -3,
      "y": 4,
      "z": 1,
      "name": "Necrotic_Mud"
    },
    {
      "x": -3,
      "y": 5,
      "z": 1,
      "name": "Necrotic_Stone"
    },
    {
      "x": -3,
      "y": 6,
      "z": 1,
      "name": "Necrotic_Sand"
    },
    {
      "x": -3,
      "y": 7,
      "z": 1,
      "name": "Necrotic_Sand"
    },
    {
      "x": -3,
      "y": 3,
      "z": 2,
      "name": "Necrotic_Stone_Deep"
    },
    {
      "x": -3,
      "y": 4,
      "z": 2,
      "name": "Necrotic_Mud"
    },
    {
      "x": -3,
      "y": 5,
      "z": 2,
      "name": "Necrotic_Stone"
    },
    {
      "x": -3,
      "y": 6,
      "z": 2,
      "name": "Necrotic_Sand"
    },
    {
      "x": -3,
      "y": 7,
      "z": 2,
      "name": "Necrotic_Sand"
    },
    {
      "x": -3,
      "y": 8,
      "z": 2,
      "name": "Plant_Crop_Mushroom_Flatcap_Green",
      "components": {
        "Components": {
          "FarmingBlock": {
            "LastTickGameTime": "0001-01-01T12:00:00Z"
          }
        }
      }
    },
    {
      "x": -3,
      "y": 3,
      "z": 3,
      "name": "Wood_Burnt_Roots"
    },
    {
      "x": -3,
      "y": 4,
      "z": 3,
      "name": "Necrotic_Mud"
    },
    {
      "x": -3,
      "y": 5,
      "z": 3,
      "name": "Necrotic_Stone"
    },
    {
      "x": -3,
      "y": 6,
      "z": 3,
      "name": "Necrotic_Sand"
    },
    {
      "x": -3,
      "y": 6,
      "z": 4,
      "name": "Necrotic_Sand"
    },
    {
      "x": -3,
      "y": 7,
      "z": 4,
      "name": "Necrotic_Grass"
    },
    {
      "x": -3,
      "y": 6,
      "z": 5,
      "name": "Necrotic_Sand"
    },
    {
      "x": -2,
      "y": 5,
      "z": -5,
      "name": "Wood_Burnt_Roots"
    },
    {
      "x": -2,
      "y": 6,
      "z": -5,
      "name": "Necrotic_Sand"
    },
    {
      "x": -2,
      "y": 4,
      "z": -4,
      "name": "Necrotic_Mud"
    },
    {
      "x": -2,
      "y": 5,
      "z": -4,
      "name": "Necrotic_Stone"
    },
    {
      "x": -2,
      "y": 6,
      "z": -4,
      "name": "Necrotic_Sand"
    },
    {
      "x": -2,
      "y": 4,
      "z": -3,
      "name": "Necrotic_Mud"
    },
    {
      "x": -2,
      "y": 5,
      "z": -3,
      "name": "Necrotic_Stone"
    },
    {
      "x": -2,
      "y": 6,
      "z": -3,
      "name": "Necrotic_Sand"
    },
    {
      "x": -2,
      "y": 7,
      "z": -3,
      "name": "Necrotic_Sand"
    },
    {
      "x": -2,
      "y": 3,
      "z": -2,
      "name": "Necrotic_Stone_Deep"
    },
    {
      "x": -2,
      "y": 4,
      "z": -2,
      "name": "Necrotic_Mud"
    },
    {
      "x": -2,
      "y": 5,
      "z": -2,
      "name": "Necrotic_Stone"
    },
    {
      "x": -2,
      "y": 6,
      "z": -2,
      "name": "Necrotic_Sand"
    },
    {
      "x": -2,
      "y": 7,
      "z": -2,
      "name": "Necrotic_Sand"
    },
    {
      "x": -2,
      "y": 3,
      "z": -1,
      "name": "Necrotic_Stone_Deep"
    },
    {
      "x": -2,
      "y": 4,
      "z": -1,
      "name": "Necrotic_Mud"
    },
    {
      "x": -2,
      "y": 5,
      "z": -1,
      "name": "Necrotic_Stone"
    },
    {
      "x": -2,
      "y": 6,
      "z": -1,
      "name": "Necrotic_Sand"
    },
    {
      "x": -2,
      "y": 7,
      "z": -1,
      "name": "Necrotic_Sand"
    },
    {
      "x": -2,
      "y": 2,
      "z": 0,
      "name": "Necrotic_Stone_Deep"
    },
    {
      "x": -2,
      "y": 3,
      "z": 0,
      "name": "Necrotic_Stone_Deep"
    },
    {
      "x": -2,
      "y": 4,
      "z": 0,
      "name": "Necrotic_Mud"
    },
    {
      "x": -2,
      "y": 5,
      "z": 0,
      "name": "Necrotic_Stone"
    },
    {
      "x": -2,
      "y": 6,
      "z": 0,
      "name": "Necrotic_Sand"
    },
    {
      "x": -2,
      "y": 7,
      "z": 0,
      "name": "Necrotic_Sand"
    },
    {
      "x": -2,
      "y": 3,
      "z": 1,
      "name": "Necrotic_Stone_Deep"
    },
    {
      "x": -2,
      "y": 4,
      "z": 1,
      "name": "Necrotic_Mud"
    },
    {
      "x": -2,
      "y": 5,
      "z": 1,
      "name": "Necrotic_Stone"
    },
    {
      "x": -2,
      "y": 6,
      "z": 1,
      "name": "Necrotic_Sand"
    },
    {
      "x": -2,
      "y": 7,
      "z": 1,
      "name": "Necrotic_Sand"
    },
    {
      "x": -2,
      "y": 3,
      "z": 2,
      "name": "Necrotic_Stone_Deep"
    },
    {
      "x": -2,
      "y": 4,
      "z": 2,
      "name": "Necrotic_Mud"
    },
    {
      "x": -2,
      "y": 5,
      "z": 2,
      "name": "Necrotic_Stone"
    },
    {
      "x": -2,
      "y": 6,
      "z": 2,
      "name": "Necrotic_Sand"
    },
    {
      "x": -2,
      "y": 7,
      "z": 2,
      "name": "Necrotic_Sand"
    },
    {
      "x": -2,
      "y": 3,
      "z": 3,
      "name": "Necrotic_Stone_Deep"
    },
    {
      "x": -2,
      "y": 4,
      "z": 3,
      "name": "Necrotic_Mud"
    },
    {
      "x": -2,
      "y": 5,
      "z": 3,
      "name": "Necrotic_Stone"
    },
    {
      "x": -2,
      "y": 6,
      "z": 3,
      "name": "Necrotic_Sand"
    },
    {
      "x": -2,
      "y": 7,
      "z": 3,
      "name": "Necrotic_Sand"
    },
    {
      "x": -2,
      "y": 4,
      "z": 4,
      "name": "Necrotic_Mud"
    },
    {
      "x": -2,
      "y": 5,
      "z": 4,
      "name": "Necrotic_Stone"
    },
    {
      "x": -2,
      "y": 6,
      "z": 4,
      "name": "Necrotic_Sand"
    },
    {
      "x": -2,
      "y": 7,
      "z": 4,
      "name": "Sword_Cemetery_1"
    },
    {
      "x": -2,
      "y": 5,
      "z": 5,
      "name": "Necrotic_Stone"
    },
    {
      "x": -2,
      "y": 6,
      "z": 5,
      "name": "Necrotic_Sand"
    },
    {
      "x": -1,
      "y": 6,
      "z": -6,
      "name": "Necrotic_Sand"
    },
    {
      "x": -1,
      "y": 7,
      "z": -6,
      "name": "Prickly_Bush"
    },
    {
      "x": -1,
      "y": 5,
      "z": -5,
      "name": "Necrotic_Stone"
    },
    {
      "x": -1,
      "y": 6,
      "z": -5,
      "name": "Necrotic_Sand"
    },
    {
      "x": -1,
      "y": 3,
      "z": -4,
      "name": "Wood_Burnt_Roots"
    },
    {
      "x": -1,
      "y": 4,
      "z": -4,
      "name": "Necrotic_Mud"
    },
    {
      "x": -1,
      "y": 5,
      "z": -4,
      "name": "Necrotic_Stone"
    },
    {
      "x": -1,
      "y": 6,
      "z": -4,
      "name": "Necrotic_Sand"
    },
    {
      "x": -1,
      "y": 7,
      "z": -4,
      "name": "Sword_Cemetery_1"
    },
    {
      "x": -1,
      "y": 3,
      "z": -3,
      "name": "Necrotic_Stone_Deep"
    },
    {
      "x": -1,
      "y": 4,
      "z": -3,
      "name": "Necrotic_Mud"
    },
    {
      "x": -1,
      "y": 5,
      "z": -3,
      "name": "Necrotic_Stone"
    },
    {
      "x": -1,
      "y": 6,
      "z": -3,
      "name": "Necrotic_Sand"
    },
    {
      "x": -1,
      "y": 7,
      "z": -3,
      "name": "Necrotic_Sand"
    },
    {
      "x": -1,
      "y": 3,
      "z": -2,
      "name": "Necrotic_Stone_Deep"
    },
    {
      "x": -1,
      "y": 4,
      "z": -2,
      "name": "Necrotic_Mud"
    },
    {
      "x": -1,
      "y": 5,
      "z": -2,
      "name": "Necrotic_Stone"
    },
    {
      "x": -1,
      "y": 6,
      "z": -2,
      "name": "Necrotic_Sand"
    },
    {
      "x": -1,
      "y": 7,
      "z": -2,
      "name": "Necrotic_Sand"
    },
    {
      "x": -1,
      "y": 2,
      "z": -1,
      "name": "Necrotic_Stone_Deep"
    },
    {
      "x": -1,
      "y": 3,
      "z": -1,
      "name": "Necrotic_Stone_Deep"
    },
    {
      "x": -1,
      "y": 4,
      "z": -1,
      "name": "Necrotic_Mud"
    },
    {
      "x": -1,
      "y": 5,
      "z": -1,
      "name": "Necrotic_Stone"
    },
    {
      "x": -1,
      "y": 6,
      "z": -1,
      "name": "Necrotic_Sand"
    },
    {
      "x": -1,
      "y": 7,
      "z": -1,
      "name": "Necrotic_Sand"
    },
    {
      "x": -1,
      "y": 8,
      "z": -1,
      "name": "Necrotic_Sand"
    },
    {
      "x": -1,
      "y": 2,
      "z": 0,
      "name": "Necrotic_Stone_Deep"
    },
    {
      "x": -1,
      "y": 3,
      "z": 0,
      "name": "Necrotic_Stone_Deep"
    },
    {
      "x": -1,
      "y": 4,
      "z": 0,
      "name": "Necrotic_Mud"
    },
    {
      "x": -1,
      "y": 5,
      "z": 0,
      "name": "Necrotic_Stone"
    },
    {
      "x": -1,
      "y": 6,
      "z": 0,
      "name": "Necrotic_Sand"
    },
    {
      "x": -1,
      "y": 7,
      "z": 0,
      "name": "Necrotic_Sand"
    },
    {
      "x": -1,
      "y": 8,
      "z": 0,
      "name": "Necrotic_Sand"
    },
    {
      "x": -1,
      "y": 9,
      "z": 0,
      "name": "Sword_Cemetery_2",
      "rotation": 2
    },
    {
      "x": -1,
      "y": 2,
      "z": 1,
      "name": "Necrotic_Stone_Deep"
    },
    {
      "x": -1,
      "y": 3,
      "z": 1,
      "name": "Necrotic_Stone_Deep"
    },
    {
      "x": -1,
      "y": 4,
      "z": 1,
      "name": "Necrotic_Mud"
    },
    {
      "x": -1,
      "y": 5,
      "z": 1,
      "name": "Necrotic_Stone"
    },
    {
      "x": -1,
      "y": 6,
      "z": 1,
      "name": "Necrotic_Sand"
    },
    {
      "x": -1,
      "y": 7,
      "z": 1,
      "name": "Necrotic_Sand"
    },
    {
      "x": -1,
      "y": 3,
      "z": 2,
      "name": "Necrotic_Stone_Deep"
    },
    {
      "x": -1,
      "y": 4,
      "z": 2,
      "name": "Necrotic_Mud"
    },
    {
      "x": -1,
      "y": 5,
      "z": 2,
      "name": "Necrotic_Stone"
    },
    {
      "x": -1,
      "y": 6,
      "z": 2,
      "name": "Necrotic_Sand"
    },
    {
      "x": -1,
      "y": 7,
      "z": 2,
      "name": "Necrotic_Sand"
    },
    {
      "x": -1,
      "y": 3,
      "z": 3,
      "name": "Necrotic_Stone_Deep"
    },
    {
      "x": -1,
      "y": 4,
      "z": 3,
      "name": "Necrotic_Mud"
    },
    {
      "x": -1,
      "y": 5,
      "z": 3,
      "name": "Necrotic_Stone"
    },
    {
      "x": -1,
      "y": 6,
      "z": 3,
      "name": "Necrotic_Sand"
    },
    {
      "x": -1,
      "y": 7,
      "z": 3,
      "name": "Necrotic_Sand"
    },
    {
      "x": -1,
      "y": 8,
      "z": 3,
      "name": "Dead_Branch"
    },
    {
      "x": -1,
      "y": 4,
      "z": 4,
      "name": "Necrotic_Mud"
    },
    {
      "x": -1,
      "y": 5,
      "z": 4,
      "name": "Necrotic_Stone"
    },
    {
      "x": -1,
      "y": 6,
      "z": 4,
      "name": "Necrotic_Sand"
    },
    {
      "x": -1,
      "y": 4,
      "z": 5,
      "name": "Wood_Burnt_Roots"
    },
    {
      "x": -1,
      "y": 5,
      "z": 5,
      "name": "Necrotic_Stone"
    },
    {
      "x": -1,
      "y": 6,
      "z": 5,
      "name": "Necrotic_Sand"
    },
    {
      "x": -1,
      "y": 6,
      "z": 6,
      "name": "Necrotic_Sand"
    },
    {
      "x": 0,
      "y": 6,
      "z": -6,
      "name": "Necrotic_Sand"
    },
    {
      "x": 0,
      "y": 4,
      "z": -5,
      "name": "Wood_Burnt_Roots"
    },
    {
      "x": 0,
      "y": 5,
      "z": -5,
      "name": "Necrotic_Stone"
    },
    {
      "x": 0,
      "y": 6,
      "z": -5,
      "name": "Necrotic_Sand"
    },
    {
      "x": 0,
      "y": 7,
      "z": -5,
      "name": "Plant_Crop_Mushroom_Flatcap_Green",
      "components": {
        "Components": {
          "FarmingBlock": {
            "LastTickGameTime": "0001-01-01T12:00:00Z"
          }
        }
      }
    },
    {
      "x": 0,
      "y": 4,
      "z": -4,
      "name": "Necrotic_Mud"
    },
    {
      "x": 0,
      "y": 5,
      "z": -4,
      "name": "Necrotic_Stone"
    },
    {
      "x": 0,
      "y": 6,
      "z": -4,
      "name": "Necrotic_Sand"
    },
    {
      "x": 0,
      "y": 3,
      "z": -3,
      "name": "Necrotic_Stone_Deep"
    },
    {
      "x": 0,
      "y": 4,
      "z": -3,
      "name": "Necrotic_Mud"
    },
    {
      "x": 0,
      "y": 5,
      "z": -3,
      "name": "Necrotic_Stone"
    },
    {
      "x": 0,
      "y": 6,
      "z": -3,
      "name": "Necrotic_Sand"
    },
    {
      "x": 0,
      "y": 7,
      "z": -3,
      "name": "Necrotic_Sand"
    },
    {
      "x": 0,
      "y": 2,
      "z": -2,
      "name": "Wood_Burnt_Roots"
    },
    {
      "x": 0,
      "y": 3,
      "z": -2,
      "name": "Necrotic_Stone_Deep"
    },
    {
      "x": 0,
      "y": 4,
      "z": -2,
      "name": "Necrotic_Mud"
    },
    {
      "x": 0,
      "y": 5,
      "z": -2,
      "name": "Necrotic_Stone"
    },
    {
      "x": 0,
      "y": 6,
      "z": -2,
      "name": "Necrotic_Sand"
    },
    {
      "x": 0,
      "y": 7,
      "z": -2,
      "name": "Necrotic_Sand"
    },
    {
      "x": 0,
      "y": 8,
      "z": -2,
      "name": "Necrotic_Sand"
    },
    {
      "x": 0,
      "y": 2,
      "z": -1,
      "name": "Necrotic_Stone_Deep"
    },
    {
      "x": 0,
      "y": 3,
      "z": -1,
      "name": "Necrotic_Stone_Deep"
    },
    {
      "x": 0,
      "y": 4,
      "z": -1,
      "name": "Necrotic_Mud"
    },
    {
      "x": 0,
      "y": 5,
      "z": -1,
      "name": "Necrotic_Stone"
    },
    {
      "x": 0,
      "y": 6,
      "z": -1,
      "name": "Necrotic_Sand"
    },
    {
      "x": 0,
      "y": 7,
      "z": -1,
      "name": "Necrotic_Sand"
    },
    {
      "x": 0,
      "y": 8,
      "z": -1,
      "name": "Necrotic_Sand"
    },
    {
      "x": 0,
      "y": 9,
      "z": -1,
      "name": "Necrotic_Sand"
    },
    {
      "x": 0,
      "y": 10,
      "z": -1,
      "name": "Sword_Cemetery_3",
      "rotation": 2
    },
    {
      "x": 0,
      "y": 1,
      "z": 0,
      "name": "Wood_Burnt_Roots"
    },
    {
      "x": 0,
      "y": 2,
      "z": 0,
      "name": "Necrotic_Stone_Deep"
    },
    {
      "x": 0,
      "y": 3,
      "z": 0,
      "name": "Necrotic_Stone_Deep"
    },
    {
      "x": 0,
      "y": 4,
      "z": 0,
      "name": "Necrotic_Mud"
    },
    {
      "x": 0,
      "y": 5,
      "z": 0,
      "name": "Necrotic_Stone"
    },
    {
      "x": 0,
      "y": 6,
      "z": 0,
      "name": "Necrotic_Sand"
    },
    {
      "x": 0,
      "y": 7,
      "z": 0,
      "name": "Necrotic_Sand"
    },
    {
      "x": 0,
      "y": 8,
      "z": 0,
      "name": "Necrotic_Sand"
    },
    {
      "x": 0,
      "y": 9,
      "z": 0,
      "name": "Necrotic_Sand"
    },
    {
      "x": 0,
      "y": 2,
      "z": 1,
      "name": "Necrotic_Stone_Deep"
    },
    {
      "x": 0,
      "y": 3,
      "z": 1,
      "name": "Necrotic_Stone_Deep"
    },
    {
      "x": 0,
      "y": 4,
      "z": 1,
      "name": "Necrotic_Mud"
    },
    {
      "x": 0,
      "y": 5,
      "z": 1,
      "name": "Necrotic_Stone"
    },
    {
      "x": 0,
      "y": 6,
      "z": 1,
      "name": "Necrotic_Sand"
    },
    {
      "x": 0,
      "y": 7,
      "z": 1,
      "name": "Necrotic_Sand"
    },
    {
      "x": 0,
      "y": 8,
      "z": 1,
      "name": "Necrotic_Sand"
    },
    {
      "x": 0,
      "y": 2,
      "z": 2,
      "name": "Wood_Burnt_Roots"
    },
    {
      "x": 0,
      "y": 3,
      "z": 2,
      "name": "Necrotic_Stone_Deep"
    },
    {
      "x": 0,
      "y": 4,
      "z": 2,
      "name": "Necrotic_Mud"
    },
    {
      "x": 0,
      "y": 5,
      "z": 2,
      "name": "Necrotic_Stone"
    },
    {
      "x": 0,
      "y": 6,
      "z": 2,
      "name": "Necrotic_Sand"
    },
    {
      "x": 0,
      "y": 7,
      "z": 2,
      "name": "Necrotic_Sand"
    },
    {
      "x": 0,
      "y": 8,
      "z": 2,
      "name": "Prickly_Bush"
    },
    {
      "x": 0,
      "y": 3,
      "z": 3,
      "name": "Necrotic_Stone_Deep"
    },
    {
      "x": 0,
      "y": 4,
      "z": 3,
      "name": "Necrotic_Mud"
    },
    {
      "x": 0,
      "y": 5,
      "z": 3,
      "name": "Necrotic_Stone"
    },
    {
      "x": 0,
      "y": 6,
      "z": 3,
      "name": "Necrotic_Sand"
    },
    {
      "x": 0,
      "y": 7,
      "z": 3,
      "name": "Necrotic_Sand"
    },
    {
      "x": 0,
      "y": 4,
      "z": 4,
      "name": "Necrotic_Mud"
    },
    {
      "x": 0,
      "y": 5,
      "z": 4,
      "name": "Necrotic_Stone"
    },
    {
      "x": 0,
      "y": 6,
      "z": 4,
      "name": "Necrotic_Sand"
    },
    {
      "x": 0,
      "y": 7,
      "z": 4,
      "name": "Necrotic_Grass"
    },
    {
      "x": 0,
      "y": 5,
      "z": 5,
      "name": "Necrotic_Stone"
    },
    {
      "x": 0,
      "y": 6,
      "z": 5,
      "name": "Necrotic_Sand"
    },
    {
      "x": 0,
      "y": 5,
      "z": 6,
      "name": "Wood_Burnt_Roots"
    },
    {
      "x": 0,
      "y": 6,
      "z": 6,
      "name": "Necrotic_Sand"
    },
    {
      "x": 1,
      "y": 5,
      "z": -6,
      "name": "Wood_Burnt_Roots"
    },
    {
      "x": 1,
      "y": 6,
      "z": -6,
      "name": "Necrotic_Sand"
    },
    {
      "x": 1,
      "y": 5,
      "z": -5,
      "name": "Necrotic_Stone"
    },
    {
      "x": 1,
      "y": 6,
      "z": -5,
      "name": "Necrotic_Sand"
    },
    {
      "x": 1,
      "y": 4,
      "z": -4,
      "name": "Necrotic_Mud"
    },
    {
      "x": 1,
      "y": 5,
      "z": -4,
      "name": "Necrotic_Stone"
    },
    {
      "x": 1,
      "y": 6,
      "z": -4,
      "name": "Necrotic_Sand"
    },
    {
      "x": 1,
      "y": 3,
      "z": -3,
      "name": "Necrotic_Stone_Deep"
    },
    {
      "x": 1,
      "y": 4,
      "z": -3,
      "name": "Necrotic_Mud"
    },
    {
      "x": 1,
      "y": 5,
      "z": -3,
      "name": "Necrotic_Stone"
    },
    {
      "x": 1,
      "y": 6,
      "z": -3,
      "name": "Necrotic_Sand"
    },
    {
      "x": 1,
      "y": 7,
      "z": -3,
      "name": "Necrotic_Sand"
    },
    {
      "x": 1,
      "y": 3,
      "z": -2,
      "name": "Necrotic_Stone_Deep"
    },
    {
      "x": 1,
      "y": 4,
      "z": -2,
      "name": "Necrotic_Mud"
    },
    {
      "x": 1,
      "y": 5,
      "z": -2,
      "name": "Necrotic_Stone"
    },
    {
      "x": 1,
      "y": 6,
      "z": -2,
      "name": "Necrotic_Sand"
    },
    {
      "x": 1,
      "y": 7,
      "z": -2,
      "name": "Necrotic_Sand"
    },
    {
      "x": 1,
      "y": 8,
      "z": -2,
      "name": "Necrotic_Sand"
    },
    {
      "x": 1,
      "y": 2,
      "z": -1,
      "name": "Necrotic_Stone_Deep"
    },
    {
      "x": 1,
      "y": 3,
      "z": -1,
      "name": "Necrotic_Stone_Deep"
    },
    {
      "x": 1,
      "y": 4,
      "z": -1,
      "name": "Necrotic_Mud"
    },
    {
      "x": 1,
      "y": 5,
      "z": -1,
      "name": "Necrotic_Stone"
    },
    {
      "x": 1,
      "y": 6,
      "z": -1,
      "name": "Necrotic_Sand"
    },
    {
      "x": 1,
      "y": 7,
      "z": -1,
      "name": "Necrotic_Sand"
    },
    {
      "x": 1,
      "y": 8,
      "z": -1,
      "name": "Necrotic_Sand"
    },
    {
      "x": 1,
      "y": 9,
      "z": -1,
      "name": "Necrotic_Sand"
    },
    {
      "x": 1,
      "y": 2,
      "z": 0,
      "name": "Necrotic_Stone_Deep"
    },
    {
      "x": 1,
      "y": 3,
      "z": 0,
      "name": "Necrotic_Stone_Deep"
    },
    {
      "x": 1,
      "y": 4,
      "z": 0,
      "name": "Necrotic_Mud"
    },
    {
      "x": 1,
      "y": 5,
      "z": 0,
      "name": "Necrotic_Stone"
    },
    {
      "x": 1,
      "y": 6,
      "z": 0,
      "name": "Necrotic_Sand"
    },
    {
      "x": 1,
      "y": 7,
      "z": 0,
      "name": "Necrotic_Sand"
    },
    {
      "x": 1,
      "y": 8,
      "z": 0,
      "name": "Necrotic_Sand"
    },
    {
      "x": 1,
      "y": 9,
      "z": 0,
      "name": "Necrotic_Sand"
    },
    {
      "x": 1,
      "y": 10,
      "z": 0,
      "name": "Banner_1",
      "rotation": 2
    },
    {
      "x": 1,
      "y": 2,
      "z": 1,
      "name": "Necrotic_Stone_Deep"
    },
    {
      "x": 1,
      "y": 3,
      "z": 1,
      "name": "Necrotic_Stone_Deep"
    },
    {
      "x": 1,
      "y": 4,
      "z": 1,
      "name": "Necrotic_Mud"
    },
    {
      "x": 1,
      "y": 5,
      "z": 1,
      "name": "Necrotic_Stone"
    },
    {
      "x": 1,
      "y": 6,
      "z": 1,
      "name": "Necrotic_Sand"
    },
    {
      "x": 1,
      "y": 7,
      "z": 1,
      "name": "Necrotic_Sand"
    },
    {
      "x": 1,
      "y": 8,
      "z": 1,
      "name": "Necrotic_Sand"
    },
    {
      "x": 1,
      "y": 3,
      "z": 2,
      "name": "Necrotic_Stone_Deep"
    },
    {
      "x": 1,
      "y": 4,
      "z": 2,
      "name": "Necrotic_Mud"
    },
    {
      "x": 1,
      "y": 5,
      "z": 2,
      "name": "Necrotic_Stone"
    },
    {
      "x": 1,
      "y": 6,
      "z": 2,
      "name": "Necrotic_Sand"
    },
    {
      "x": 1,
      "y": 7,
      "z": 2,
      "name": "Necrotic_Sand"
    },
    {
      "x": 1,
      "y": 3,
      "z": 3,
      "name": "Necrotic_Stone_Deep"
    },
    {
      "x": 1,
      "y": 4,
      "z": 3,
      "name": "Necrotic_Mud"
    },
    {
      "x": 1,
      "y": 5,
      "z": 3,
      "name": "Necrotic_Stone"
    },
    {
      "x": 1,
      "y": 6,
      "z": 3,
      "name": "Necrotic_Sand"
    },
    {
      "x": 1,
      "y": 7,
      "z": 3,
      "name": "Necrotic_Sand"
    },
    {
      "x": 1,
      "y": 4,
      "z": 4,
      "name": "Wood_Burnt_Roots"
    },
    {
      "x": 1,
      "y": 5,
      "z": 4,
      "name": "Necrotic_Stone"
    },
    {
      "x": 1,
      "y": 6,
      "z": 4,
      "name": "Necrotic_Sand"
    },
    {
      "x": 1,
      "y": 5,
      "z": 5,
      "name": "Necrotic_Stone"
    },
    {
      "x": 1,
      "y": 6,
      "z": 5,
      "name": "Necrotic_Sand"
    },
    {
      "x": 1,
      "y": 7,
      "z": 5,
      "name": "Prickly_Bush"
    },
    {
      "x": 1,
      "y": 6,
      "z": 6,
      "name": "Necrotic_Sand"
    },
    {
      "x": 2,
      "y": 5,
      "z": -5,
      "name": "Necrotic_Stone"
    },
    {
      "x": 2,
      "y": 6,
      "z": -5,
      "name": "Necrotic_Sand"
    },
    {
      "x": 2,
      "y": 5,
      "z": -4,
      "name": "Necrotic_Stone"
    },
    {
      "x": 2,
      "y": 6,
      "z": -4,
      "name": "Necrotic_Sand"
    },
    {
      "x": 2,
      "y": 7,
      "z": -4,
      "name": "Necrotic_Grass"
    },
    {
      "x": 2,
      "y": 3,
      "z": -3,
      "name": "Necrotic_Stone_Deep"
    },
    {
      "x": 2,
      "y": 4,
      "z": -3,
      "name": "Necrotic_Mud"
    },
    {
      "x": 2,
      "y": 5,
      "z": -3,
      "name": "Necrotic_Stone"
    },
    {
      "x": 2,
      "y": 6,
      "z": -3,
      "name": "Necrotic_Sand"
    },
    {
      "x": 2,
      "y": 7,
      "z": -3,
      "name": "Necrotic_Sand"
    },
    {
      "x": 2,
      "y": 8,
      "z": -3,
      "name": "Sword_Cemetery_3"
    },
    {
      "x": 2,
      "y": 2,
      "z": -2,
      "name": "Wood_Burnt_Roots"
    },
    {
      "x": 2,
      "y": 3,
      "z": -2,
      "name": "Necrotic_Stone_Deep"
    },
    {
      "x": 2,
      "y": 4,
      "z": -2,
      "name": "Necrotic_Mud"
    },
    {
      "x": 2,
      "y": 5,
      "z": -2,
      "name": "Necrotic_Stone"
    },
    {
      "x": 2,
      "y": 6,
      "z": -2,
      "name": "Necrotic_Sand"
    },
    {
      "x": 2,
      "y": 7,
      "z": -2,
      "name": "Necrotic_Sand"
    },
    {
      "x": 2,
      "y": 3,
      "z": -1,
      "name": "Necrotic_Stone_Deep"
    },
    {
      "x": 2,
      "y": 4,
      "z": -1,
      "name": "Necrotic_Mud"
    },
    {
      "x": 2,
      "y": 5,
      "z": -1,
      "name": "Necrotic_Stone"
    },
    {
      "x": 2,
      "y": 6,
      "z": -1,
      "name": "Necrotic_Sand"
    },
    {
      "x": 2,
      "y": 7,
      "z": -1,
      "name": "Necrotic_Sand"
    },
    {
      "x": 2,
      "y": 8,
      "z": -1,
      "name": "Necrotic_Sand"
    },
    {
      "x": 2,
      "y": 9,
      "z": -1,
      "name": "Plant_Crop_Mushroom_Flatcap_Green",
      "components": {
        "Components": {
          "FarmingBlock": {
            "GrowthProgress": -84.55961608886719,
            "LastTickGameTime": "0001-01-01T12:00:00Z"
          },
          "PlacedByInteraction": {
            "WhoPlacedUuid": {
              "$binary": "bJ0Z/pHxT/WyhVA6z1mjfg==",
              "$type": "04"
            }
          }
        }
      }
    },
    {
      "x": 2,
      "y": 1,
      "z": 0,
      "name": "Wood_Burnt_Roots"
    },
    {
      "x": 2,
      "y": 2,
      "z": 0,
      "name": "Necrotic_Stone_Deep"
    },
    {
      "x": 2,
      "y": 3,
      "z": 0,
      "name": "Necrotic_Stone_Deep"
    },
    {
      "x": 2,
      "y": 4,
      "z": 0,
      "name": "Necrotic_Mud"
    },
    {
      "x": 2,
      "y": 5,
      "z": 0,
      "name": "Necrotic_Stone"
    },
    {
      "x": 2,
      "y": 6,
      "z": 0,
      "name": "Necrotic_Sand"
    },
    {
      "x": 2,
      "y": 7,
      "z": 0,
      "name": "Necrotic_Sand"
    },
    {
      "x": 2,
      "y": 8,
      "z": 0,
      "name": "Necrotic_Sand"
    },
    {
      "x": 2,
      "y": 9,
      "z": 0,
      "name": "Sword_Cemetery_2",
      "rotation": 2
    },
    {
      "x": 2,
      "y": 3,
      "z": 1,
      "name": "Necrotic_Stone_Deep"
    },
    {
      "x": 2,
      "y": 4,
      "z": 1,
      "name": "Necrotic_Mud"
    },
    {
      "x": 2,
      "y": 5,
      "z": 1,
      "name": "Necrotic_Stone"
    },
    {
      "x": 2,
      "y": 6,
      "z": 1,
      "name": "Necrotic_Sand"
    },
    {
      "x": 2,
      "y": 7,
      "z": 1,
      "name": "Necrotic_Sand"
    },
    {
      "x": 2,
      "y": 2,
      "z": 2,
      "name": "Wood_Burnt_Roots"
    },
    {
      "x": 2,
      "y": 3,
      "z": 2,
      "name": "Necrotic_Stone_Deep"
    },
    {
      "x": 2,
      "y": 4,
      "z": 2,
      "name": "Necrotic_Mud"
    },
    {
      "x": 2,
      "y": 5,
      "z": 2,
      "name": "Necrotic_Stone"
    },
    {
      "x": 2,
      "y": 6,
      "z": 2,
      "name": "Necrotic_Sand"
    },
    {
      "x": 2,
      "y": 7,
      "z": 2,
      "name": "Necrotic_Sand"
    },
    {
      "x": 2,
      "y": 4,
      "z": 3,
      "name": "Necrotic_Mud"
    },
    {
      "x": 2,
      "y": 5,
      "z": 3,
      "name": "Necrotic_Stone"
    },
    {
      "x": 2,
      "y": 6,
      "z": 3,
      "name": "Necrotic_Sand"
    },
    {
      "x": 2,
      "y": 7,
      "z": 3,
      "name": "Necrotic_Sand"
    },
    {
      "x": 2,
      "y": 8,
      "z": 3,
      "name": "Necrotic_Grass"
    },
    {
      "x": 2,
      "y": 5,
      "z": 4,
      "name": "Necrotic_Stone"
    },
    {
      "x": 2,
      "y": 6,
      "z": 4,
      "name": "Necrotic_Sand"
    },
    {
      "x": 2,
      "y": 5,
      "z": 5,
      "name": "Necrotic_Stone"
    },
    {
      "x": 2,
      "y": 6,
      "z": 5,
      "name": "Necrotic_Sand"
    },
    {
      "x": 2,
      "y": 6,
      "z": 6,
      "name": "Necrotic_Sand"
    },
    {
      "x": 3,
      "y": 5,
      "z": -5,
      "name": "Wood_Burnt_Roots"
    },
    {
      "x": 3,
      "y": 6,
      "z": -5,
      "name": "Necrotic_Sand"
    },
    {
      "x": 3,
      "y": 4,
      "z": -4,
      "name": "Wood_Burnt_Roots"
    },
    {
      "x": 3,
      "y": 5,
      "z": -4,
      "name": "Necrotic_Stone"
    },
    {
      "x": 3,
      "y": 6,
      "z": -4,
      "name": "Necrotic_Sand"
    },
    {
      "x": 3,
      "y": 4,
      "z": -3,
      "name": "Necrotic_Mud"
    },
    {
      "x": 3,
      "y": 5,
      "z": -3,
      "name": "Necrotic_Stone"
    },
    {
      "x": 3,
      "y": 6,
      "z": -3,
      "name": "Necrotic_Sand"
    },
    {
      "x": 3,
      "y": 7,
      "z": -3,
      "name": "Necrotic_Sand"
    },
    {
      "x": 3,
      "y": 3,
      "z": -2,
      "name": "Necrotic_Stone_Deep"
    },
    {
      "x": 3,
      "y": 4,
      "z": -2,
      "name": "Necrotic_Mud"
    },
    {
      "x": 3,
      "y": 5,
      "z": -2,
      "name": "Necrotic_Stone"
    },
    {
      "x": 3,
      "y": 6,
      "z": -2,
      "name": "Necrotic_Sand"
    },
    {
      "x": 3,
      "y": 7,
      "z": -2,
      "name": "Necrotic_Sand"
    },
    {
      "x": 3,
      "y": 3,
      "z": -1,
      "name": "Necrotic_Stone_Deep"
    },
    {
      "x": 3,
      "y": 4,
      "z": -1,
      "name": "Necrotic_Mud"
    },
    {
      "x": 3,
      "y": 5,
      "z": -1,
      "name": "Necrotic_Stone"
    },
    {
      "x": 3,
      "y": 6,
      "z": -1,
      "name": "Necrotic_Sand"
    },
    {
      "x": 3,
      "y": 7,
      "z": -1,
      "name": "Necrotic_Sand"
    },
    {
      "x": 3,
      "y": 8,
      "z": -1,
      "name": "Sword_Cemetery_2"
    },
    {
      "x": 3,
      "y": 3,
      "z": 0,
      "name": "Necrotic_Stone_Deep"
    },
    {
      "x": 3,
      "y": 4,
      "z": 0,
      "name": "Necrotic_Mud"
    },
    {
      "x": 3,
      "y": 5,
      "z": 0,
      "name": "Necrotic_Stone"
    },
    {
      "x": 3,
      "y": 6,
      "z": 0,
      "name": "Necrotic_Sand"
    },
    {
      "x": 3,
      "y": 7,
      "z": 0,
      "name": "Necrotic_Sand"
    },
    {
      "x": 3,
      "y": 3,
      "z": 1,
      "name": "Necrotic_Stone_Deep"
    },
    {
      "x": 3,
      "y": 4,
      "z": 1,
      "name": "Necrotic_Mud"
    },
    {
      "x": 3,
      "y": 5,
      "z": 1,
      "name": "Necrotic_Stone"
    },
    {
      "x": 3,
      "y": 6,
      "z": 1,
      "name": "Necrotic_Sand"
    },
    {
      "x": 3,
      "y": 7,
      "z": 1,
      "name": "Necrotic_Sand"
    },
    {
      "x": 3,
      "y": 3,
      "z": 2,
      "name": "Necrotic_Stone_Deep"
    },
    {
      "x": 3,
      "y": 4,
      "z": 2,
      "name": "Necrotic_Mud"
    },
    {
      "x": 3,
      "y": 5,
      "z": 2,
      "name": "Necrotic_Stone"
    },
    {
      "x": 3,
      "y": 6,
      "z": 2,
      "name": "Necrotic_Sand"
    },
    {
      "x": 3,
      "y": 7,
      "z": 2,
      "name": "Necrotic_Sand"
    },
    {
      "x": 3,
      "y": 4,
      "z": 3,
      "name": "Necrotic_Mud"
    },
    {
      "x": 3,
      "y": 5,
      "z": 3,
      "name": "Necrotic_Stone"
    },
    {
      "x": 3,
      "y": 6,
      "z": 3,
      "name": "Necrotic_Sand"
    },
    {
      "x": 3,
      "y": 7,
      "z": 3,
      "name": "Necrotic_Sand"
    },
    {
      "x": 3,
      "y": 5,
      "z": 4,
      "name": "Necrotic_Stone"
    },
    {
      "x": 3,
      "y": 6,
      "z": 4,
      "name": "Necrotic_Sand"
    },
    {
      "x": 3,
      "y": 4,
      "z": 5,
      "name": "Wood_Burnt_Roots"
    },
    {
      "x": 3,
      "y": 5,
      "z": 5,
      "name": "Necrotic_Stone"
    },
    {
      "x": 3,
      "y": 6,
      "z": 5,
      "name": "Necrotic_Sand"
    },
    {
      "x": 3,
      "y": 6,
      "z": 6,
      "name": "Necrotic_Sand"
    },
    {
      "x": 4,
      "y": 6,
      "z": -5,
      "name": "Necrotic_Sand"
    },
    {
      "x": 4,
      "y": 7,
      "z": -5,
      "name": "Sword_Cemetery_1",
      "rotation": 2
    },
    {
      "x": 4,
      "y": 5,
      "z": -4,
      "name": "Necrotic_Stone"
    },
    {
      "x": 4,
      "y": 6,
      "z": -4,
      "name": "Necrotic_Sand"
    },
    {
      "x": 4,
      "y": 7,
      "z": -4,
      "name": "Necrotic_Grass"
    },
    {
      "x": 4,
      "y": 5,
      "z": -3,
      "name": "Necrotic_Stone"
    },
    {
      "x": 4,
      "y": 6,
      "z": -3,
      "name": "Necrotic_Sand"
    },
    {
      "x": 4,
      "y": 7,
      "z": -3,
      "name": "Necrotic_Sand"
    },
    {
      "x": 4,
      "y": 3,
      "z": -2,
      "name": "Wood_Burnt_Roots"
    },
    {
      "x": 4,
      "y": 4,
      "z": -2,
      "name": "Necrotic_Mud"
    },
    {
      "x": 4,
      "y": 5,
      "z": -2,
      "name": "Necrotic_Stone"
    },
    {
      "x": 4,
      "y": 6,
      "z": -2,
      "name": "Necrotic_Sand"
    },
    {
      "x": 4,
      "y": 7,
      "z": -2,
      "name": "Necrotic_Sand"
    },
    {
      "x": 4,
      "y": 3,
      "z": -1,
      "name": "Necrotic_Stone_Deep"
    },
    {
      "x": 4,
      "y": 4,
      "z": -1,
      "name": "Necrotic_Mud"
    },
    {
      "x": 4,
      "y": 5,
      "z": -1,
      "name": "Necrotic_Stone"
    },
    {
      "x": 4,
      "y": 6,
      "z": -1,
      "name": "Necrotic_Sand"
    },
    {
      "x": 4,
      "y": 7,
      "z": -1,
      "name": "Necrotic_Sand"
    },
    {
      "x": 4,
      "y": 8,
      "z": -1,
      "name": "Necrotic_Grass"
    },
    {
      "x": 4,
      "y": 3,
      "z": 0,
      "name": "Necrotic_Stone_Deep"
    },
    {
      "x": 4,
      "y": 4,
      "z": 0,
      "name": "Necrotic_Mud"
    },
    {
      "x": 4,
      "y": 5,
      "z": 0,
      "name": "Necrotic_Stone"
    },
    {
      "x": 4,
      "y": 6,
      "z": 0,
      "name": "Necrotic_Sand"
    },
    {
      "x": 4,
      "y": 7,
      "z": 0,
      "name": "Necrotic_Sand"
    },
    {
      "x": 4,
      "y": 3,
      "z": 1,
      "name": "Necrotic_Stone_Deep"
    },
    {
      "x": 4,
      "y": 4,
      "z": 1,
      "name": "Necrotic_Mud"
    },
    {
      "x": 4,
      "y": 5,
      "z": 1,
      "name": "Necrotic_Stone"
    },
    {
      "x": 4,
      "y": 6,
      "z": 1,
      "name": "Necrotic_Sand"
    },
    {
      "x": 4,
      "y": 7,
      "z": 1,
      "name": "Necrotic_Sand"
    },
    {
      "x": 4,
      "y": 8,
      "z": 1,
      "name": "Necrotic_Grass"
    },
    {
      "x": 4,
      "y": 4,
      "z": 2,
      "name": "Necrotic_Mud"
    },
    {
      "x": 4,
      "y": 5,
      "z": 2,
      "name": "Necrotic_Stone"
    },
    {
      "x": 4,
      "y": 6,
      "z": 2,
      "name": "Necrotic_Sand"
    },
    {
      "x": 4,
      "y": 7,
      "z": 2,
      "name": "Necrotic_Sand"
    },
    {
      "x": 4,
      "y": 4,
      "z": 3,
      "name": "Wood_Burnt_Roots"
    },
    {
      "x": 4,
      "y": 5,
      "z": 3,
      "name": "Necrotic_Stone"
    },
    {
      "x": 4,
      "y": 6,
      "z": 3,
      "name": "Necrotic_Sand"
    },
    {
      "x": 4,
      "y": 7,
      "z": 3,
      "name": "Plant_Crop_Mushroom_Flatcap_Green",
      "components": {
        "Components": {
          "FarmingBlock": {
            "GrowthProgress": -72.67256927490234,
            "LastTickGameTime": "0001-01-01T12:00:00Z"
          },
          "PlacedByInteraction": {
            "WhoPlacedUuid": {
              "$binary": "bJ0Z/pHxT/WyhVA6z1mjfg==",
              "$type": "04"
            }
          }
        }
      }
    },
    {
      "x": 4,
      "y": 5,
      "z": 4,
      "name": "Necrotic_Stone"
    },
    {
      "x": 4,
      "y": 6,
      "z": 4,
      "name": "Necrotic_Sand"
    },
    {
      "x": 4,
      "y": 4,
      "z": 5,
      "name": "Wood_Burnt_Roots"
    },
    {
      "x": 4,
      "y": 5,
      "z": 5,
      "name": "Necrotic_Stone"
    },
    {
      "x": 4,
      "y": 6,
      "z": 5,
      "name": "Necrotic_Sand"
    },
    {
      "x": 5,
      "y": 6,
      "z": -5,
      "name": "Necrotic_Sand"
    },
    {
      "x": 5,
      "y": 5,
      "z": -4,
      "name": "Necrotic_Stone"
    },
    {
      "x": 5,
      "y": 6,
      "z": -4,
      "name": "Necrotic_Sand"
    },
    {
      "x": 5,
      "y": 5,
      "z": -3,
      "name": "Necrotic_Stone"
    },
    {
      "x": 5,
      "y": 6,
      "z": -3,
      "name": "Necrotic_Sand"
    },
    {
      "x": 5,
      "y": 5,
      "z": -2,
      "name": "Necrotic_Stone"
    },
    {
      "x": 5,
      "y": 6,
      "z": -2,
      "name": "Necrotic_Sand"
    },
    {
      "x": 5,
      "y": 7,
      "z": -2,
      "name": "Necrotic_Sand"
    },
    {
      "x": 5,
      "y": 4,
      "z": -1,
      "name": "Necrotic_Mud"
    },
    {
      "x": 5,
      "y": 5,
      "z": -1,
      "name": "Necrotic_Stone"
    },
    {
      "x": 5,
      "y": 6,
      "z": -1,
      "name": "Necrotic_Sand"
    },
    {
      "x": 5,
      "y": 7,
      "z": -1,
      "name": "Necrotic_Sand"
    },
    {
      "x": 5,
      "y": 8,
      "z": -1,
      "name": "Sword_Cemetery_2"
    },
    {
      "x": 5,
      "y": 2,
      "z": 0,
      "name": "Wood_Burnt_Roots"
    },
    {
      "x": 5,
      "y": 3,
      "z": 0,
      "name": "Necrotic_Stone_Deep"
    },
    {
      "x": 5,
      "y": 4,
      "z": 0,
      "name": "Necrotic_Mud"
    },
    {
      "x": 5,
      "y": 5,
      "z": 0,
      "name": "Necrotic_Stone"
    },
    {
      "x": 5,
      "y": 6,
      "z": 0,
      "name": "Necrotic_Sand"
    },
    {
      "x": 5,
      "y": 7,
      "z": 0,
      "name": "Necrotic_Sand"
    },
    {
      "x": 5,
      "y": 4,
      "z": 1,
      "name": "Necrotic_Mud"
    },
    {
      "x": 5,
      "y": 5,
      "z": 1,
      "name": "Necrotic_Stone"
    },
    {
      "x": 5,
      "y": 6,
      "z": 1,
      "name": "Necrotic_Sand"
    },
    {
      "x": 5,
      "y": 7,
      "z": 1,
      "name": "Necrotic_Sand"
    },
    {
      "x": 5,
      "y": 4,
      "z": 2,
      "name": "Wood_Burnt_Roots"
    },
    {
      "x": 5,
      "y": 5,
      "z": 2,
      "name": "Necrotic_Stone"
    },
    {
      "x": 5,
      "y": 6,
      "z": 2,
      "name": "Necrotic_Sand"
    },
    {
      "x": 5,
      "y": 7,
      "z": 2,
      "name": "Necrotic_Sand"
    },
    {
      "x": 5,
      "y": 5,
      "z": 3,
      "name": "Necrotic_Stone"
    },
    {
      "x": 5,
      "y": 6,
      "z": 3,
      "name": "Necrotic_Sand"
    },
    {
      "x": 5,
      "y": 5,
      "z": 4,
      "name": "Necrotic_Stone"
    },
    {
      "x": 5,
      "y": 6,
      "z": 4,
      "name": "Necrotic_Sand"
    },
    {
      "x": 5,
      "y": 7,
      "z": 4,
      "name": "Prickly_Bush"
    },
    {
      "x": 5,
      "y": 6,
      "z": 5,
      "name": "Necrotic_Sand"
    },
    {
      "x": 5,
      "y": 7,
      "z": 5,
      "name": "Sword_Cemetery_2"
    },
    {
      "x": 6,
      "y": 6,
      "z": -4,
      "name": "Necrotic_Sand"
    },
    {
      "x": 6,
      "y": 5,
      "z": -3,
      "name": "Necrotic_Stone"
    },
    {
      "x": 6,
      "y": 6,
      "z": -3,
      "name": "Necrotic_Sand"
    },
    {
      "x": 6,
      "y": 5,
      "z": -2,
      "name": "Necrotic_Stone"
    },
    {
      "x": 6,
      "y": 6,
      "z": -2,
      "name": "Necrotic_Sand"
    },
    {
      "x": 6,
      "y": 7,
      "z": -2,
      "name": "Dead_Branch"
    },
    {
      "x": 6,
      "y": 5,
      "z": -1,
      "name": "Necrotic_Stone"
    },
    {
      "x": 6,
      "y": 6,
      "z": -1,
      "name": "Necrotic_Sand"
    },
    {
      "x": 6,
      "y": 7,
      "z": -1,
      "name": "Necrotic_Sand"
    },
    {
      "x": 6,
      "y": 8,
      "z": -1,
      "name": "Plant_Crop_Mushroom_Flatcap_Green",
      "components": {
        "Components": {
          "FarmingBlock": {
            "LastTickGameTime": "0001-01-01T12:00:00Z"
          }
        }
      }
    },
    {
      "x": 6,
      "y": 4,
      "z": 0,
      "name": "Wood_Burnt_Roots"
    },
    {
      "x": 6,
      "y": 5,
      "z": 0,
      "name": "Necrotic_Stone"
    },
    {
      "x": 6,
      "y": 6,
      "z": 0,
      "name": "Necrotic_Sand"
    },
    {
      "x": 6,
      "y": 7,
      "z": 0,
      "name": "Necrotic_Sand"
    },
    {
      "x": 6,
      "y": 5,
      "z": 1,
      "name": "Necrotic_Stone"
    },
    {
      "x": 6,
      "y": 6,
      "z": 1,
      "name": "Necrotic_Sand"
    },
    {
      "x": 6,
      "y": 7,
      "z": 1,
      "name": "Necrotic_Sand"
    },
    {
      "x": 6,
      "y": 5,
      "z": 2,
      "name": "Necrotic_Stone"
    },
    {
      "x": 6,
      "y": 6,
      "z": 2,
      "name": "Necrotic_Sand"
    },
    {
      "x": 6,
      "y": 5,
      "z": 3,
      "name": "Necrotic_Stone"
    },
    {
      "x": 6,
      "y": 6,
      "z": 3,
      "name": "Necrotic_Sand"
    },
    {
      "x": 6,
      "y": 6,
      "z": 4,
      "name": "Necrotic_Sand"
    },
    {
      "x": 7,
      "y": 6,
      "z": -3,
      "name": "Necrotic_Sand"
    },
    {
      "x": 7,
      "y": 6,
      "z": -2,
      "name": "Necrotic_Sand"
    },
    {
      "x": 7,
      "y": 4,
      "z": -1,
      "name": "Wood_Burnt_Roots"
    },
    {
      "x": 7,
      "y": 5,
      "z": -1,
      "name": "Necrotic_Stone"
    },
    {
      "x": 7,
      "y": 6,
      "z": -1,
      "name": "Necrotic_Sand"
    },
    {
      "x": 7,
      "y": 7,
      "z": -1,
      "name": "Prickly_Bush"
    },
    {
      "x": 7,
      "y": 5,
      "z": 0,
      "name": "Necrotic_Stone"
    },
    {
      "x": 7,
      "y": 6,
      "z": 0,
      "name": "Necrotic_Sand"
    },
    {
      "x": 7,
      "y": 5,
      "z": 1,
      "name": "Necrotic_Stone"
    },
    {
      "x": 7,
      "y": 6,
      "z": 1,
      "name": "Necrotic_Sand"
    },
    {
      "x": 7,
      "y": 7,
      "z": 1,
      "name": "Necrotic_Grass"
    },
    {
      "x": 7,
      "y": 5,
      "z": 2,
      "name": "Necrotic_Stone"
    },
    {
      "x": 7,
      "y": 6,
      "z": 2,
      "name": "Necrotic_Sand"
    },
    {
      "x": 7,
      "y": 7,
      "z": 2,
      "name": "Sword_Cemetery_3"
    },
    {
      "x": 7,
      "y": 6,
      "z": 3,
      "name": "Necrotic_Sand"
    },
    {
      "x": 8,
      "y": 6,
      "z": -1,
      "name": "Necrotic_Sand"
    },
    {
      "x": 8,
      "y": 6,
      "z": 0,
      "name": "Necrotic_Sand"
    },
    {
      "x": 8,
      "y": 7,
      "z": 0,
      "name": "Plant_Crop_Mushroom_Flatcap_Green",
      "components": {
        "Components": {
          "FarmingBlock": {
            "LastTickGameTime": "0001-01-01T12:00:00Z"
          }
        }
      }
    },
    {
      "x": 8,
      "y": 6,
      "z": 1,
      "name": "Necrotic_Sand"
    }
  ]
}