{
  "version": 8,
  "blockIdVersion": 11,
  "anchorX": 1,
  "anchorY": 0,
  "anchorZ": 0,
  "blocks": [
    {
      "x": -2,
      "y": 0,
      "z": -1,
      "name": "Rock_Slate_Brick_Stairs",
      "rotation": 3
    },
    {
      "x": -2,
      "y": 0,
      "z": 2,
      "name": "Rock_Slate_Brick_Stairs",
      "rotation": 3
    },
    {
      "x": -1,
      "y": 0,
      "z": -2,
      "name": "Rock_Slate_Brick_Stairs",
      "rotation": 2
    },
    {
      "x": -1,
      "y": 0,
      "z": -1,
      "name": "Rock_Slate_Brick_Decorative"
    },
    {
      "x": -1,
      "y": 0,
      "z": 0,
      "name": "Rock_Slate_Brick_Decorative"
    },
    {
      "x": -1,
      "y": 6,
      "z": 0,
      "name": "Rock_Slate_Brick_Stairs",
      "rotation": 9
    },
    {
      "x": -1,
      "y": 7,
      "z": 0,
      "name": "Furniture_Human_Ruins_Brazier"
    },
    {
      "x": -1,
      "y": 0,
      "z": 1,
      "name": "Rock_Slate_Brick_Decorative"
    },
    {
      "x": -1,
      "y": 6,
      "z": 1,
      "name": "Rock_Slate_Brick_Stairs",
      "rotation": 9
    },
    {
      "x": -1,
      "y": 7,
      "z": 1,
      "name": "Furniture_Human_Ruins_Brazier"
    },
    {
      "x": -1,
      "y": 0,
      "z": 2,
      "name": "Rock_Slate_Brick_Decorative"
    },
    {
      "x": -1,
      "y": 0,
      "z": 3,
      "name": "Rock_Slate_Brick_Stairs"
    },
    {
      "x": 0,
      "y": 0,
      "z": -1,
      "name": "Rock_Slate_Brick_Decorative"
    },
    {
      "x": 0,
      "y": 6,
      "z": -1,
      "name": "Rock_Slate_Brick_Stairs",
      "rotation": 8
    },
    {
      "x": 0,
      "y": 7,
      "z": -1,
      "name": "Furniture_Human_Ruins_Brazier"
    },
    {
      "x": 0,
      "y": 0,
      "z": 0,
      "name": "Rock_Slate_Brick_Decorative"
    },
    {
      "x": 0,
      "y": 1,
      "z": 0,
      "name": "Rock_Slate_Brick_Ornate"
    },
    {
      "x": 0,
      "y": 2,
      "z": 0,
      "name": "*Rock_Slate_Brick_Stairs_State_Definitions_Corner_Left",
      "rotation": 2
    },
    {
      "x": 0,
      "y": 3,
      "z": 0,
      "name": "*Rock_Slate_Brick_Stairs_State_Definitions_Corner_Left",
      "rotation": 2
    },
    {
      "x": 0,
      "y": 4,
      "z": 0,
      "name": "*Rock_Slate_Brick_Stairs_State_Definitions_Corner_Right",
      "rotation": 8
    },
    {
      "x": 0,
      "y": 5,
      "z": 0,
      "name": "*Rock_Slate_Brick_Stairs_State_Definitions_Corner_Right",
      "rotation": 8
    },
    {
      "x": 0,
      "y": 6,
      "z": 0,
      "name": "Rock_Slate_Brick_Decorative"
    },
    {
      "x": 0,
      "y": 7,
      "z": 0,
      "name": "Furniture_Human_Ruins_Brazier"
    },
    {
      "x": 0,
      "y": 0,
      "z": 1,
      "name": "Rock_Slate_Brick_Decorative"
    },
    {
      "x": 0,
      "y": 1,
      "z": 1,
      "name": "Rock_Slate_Brick_Ornate"
    },
    {
      "x": 0,
      "y": 2,
      "z": 1,
      "name": "*Rock_Slate_Brick_Stairs_State_Definitions_Corner_Left",
      "rotation": 3
    },
    {
      "x": 0,
      "y": 3,
      "z": 1,
      "name": "*Rock_Slate_Brick_Stairs_State_Definitions_Corner_Left",
      "rotation": 3
    },
    {
      "x": 0,
      "y": 4,
      "z": 1,
      "name": "*Rock_Slate_Brick_Stairs_State_Definitions_Corner_Right",
      "rotation": 9
    },
    {
      "x": 0,
      "y": 5,
      "z": 1,
      "name": "*Rock_Slate_Brick_Stairs_State_Definitions_Corner_Right",
      "rotation": 9
    },
    {
      "x": 0,
      "y": 6,
      "z": 1,
      "name": "Rock_Slate_Brick_Decorative"
    },
    {
      "x": 0,
      "y": 7,
      "z": 1,
      "name": "Furniture_Human_Ruins_Brazier"
    },
    {
      "x": 0,
      "y": 0,
      "z": 2,
      "name": "Rock_Slate_Brick_Decorative"
    },
    {
      "x": 0,
      "y": 6,
      "z": 2,
      "name": "Rock_Slate_Brick_Stairs",
      "rotation": 10
    },
    {
      "x": 0,
      "y": 7,
      "z": 2,
      "name": "Furniture_Human_Ruins_Brazier"
    },
    {
      "x": 1,
      "y": 0,
      "z": -1,
      "name": "Rock_Slate_Brick_Decorative"
    },
    {
      "x": 1,
      "y": 6,
      "z": -1,
      "name": "Rock_Slate_Brick_Stairs",
      "rotation": 8
    },
    {
      "x": 1,
      "y": 7,
      "z": -1,
      "name": "Furniture_Human_Ruins_Brazier"
    },
    {
      "x": 1,
      "y": 0,
      "z": 0,
      "name": "Rock_Slate_Brick_Decorative"
    },
    {
      "x": 1,
      "y": 1,
      "z": 0,
      "name": "Rock_Slate_Brick_Ornate"
    },
    {
      "x": 1,
      "y": 2,
      "z": 0,
      "name": "*Rock_Slate_Brick_Stairs_State_Definitions_Corner_Left",
      "rotation": 1
    },
    {
      "x": 1,
      "y": 3,
      "z": 0,
      "name": "*Rock_Slate_Brick_Stairs_State_Definitions_Corner_Left",
      "rotation": 1
    },
    {
      "x": 1,
      "y": 4,
      "z": 0,
      "name": "*Rock_Slate_Brick_Stairs_State_Definitions_Corner_Right",
      "rotation": 11
    },
    {
      "x": 1,
      "y": 5,
      "z": 0,
      "name": "*Rock_Slate_Brick_Stairs_State_Definitions_Corner_Right",
      "rotation": 11
    },
    {
      "x": 1,
      "y": 6,
      "z": 0,
      "name": "Rock_Slate_Cobble"
    },
    {
      "x": 1,
      "y": 7,
      "z": 0,
      "name": "Furniture_Human_Ruins_Brazier"
    },
    {
      "x": 1,
      "y": 0,
      "z": 1,
      "name": "Rock_Slate_Brick_Decorative"
    },
    {
      "x": 1,
      "y": 1,
      "z": 1,
      "name": "Rock_Slate_Brick_Ornate"
    },
    {
      "x": 1,
      "y": 2,
      "z": 1,
      "name": "*Rock_Slate_Brick_Stairs_State_Definitions_Corner_Left"
    },
    {
      "x": 1,
      "y": 3,
      "z": 1,
      "name": "*Rock_Slate_Brick_Stairs_State_Definitions_Corner_Left"
    },
    {
      "x": 1,
      "y": 4,
      "z": 1,
      "name": "*Rock_Slate_Brick_Stairs_State_Definitions_Corner_Right",
      "rotation": 10
    },
    {
      "x": 1,
      "y": 5,
      "z": 1,
      "name": "*Rock_Slate_Brick_Stairs_State_Definitions_Corner_Right",
      "rotation": 10
    },
    {
      "x": 1,
      "y": 6,
      "z": 1,
      "name": "Rock_Slate_Brick_Decorative"
    },
    {
      "x": 1,
      "y": 7,
      "z": 1,
      "name": "Furniture_Human_Ruins_Brazier"
    },
    {
      "x": 1,
      "y": 0,
      "z": 2,
      "name": "Rock_Slate_Brick_Decorative"
    },
    {
      "x": 1,
      "y": 6,
      "z": 2,
      "name": "Rock_Slate_Brick_Stairs",
      "rotation": 10
    },
    {
      "x": 1,
      "y": 7,
      "z": 2,
      "name": "Furniture_Human_Ruins_Brazier"
    },
    {
      "x": 2,
      "y": 0,
      "z": -2,
      "name": "Rock_Slate_Brick_Stairs",
      "rotation": 2
    },
    {
      "x": 2,
      "y": 0,
      "z": -1,
      "name": "Rock_Slate_Brick_Decorative"
    },
    {
      "x": 2,
      "y": 0,
      "z": 0,
      "name": "Rock_Slate_Brick_Decorative"
    },
    {
      "x": 2,
      "y": 6,
      "z": 0,
      "name": "Rock_Slate_Brick_Stairs",
      "rotation": 11
    },
    {
      "x": 2,
      "y": 7,
      "z": 0,
      "name": "Furniture_Human_Ruins_Brazier"
    },
    {
      "x": 2,
      "y": 0,
      "z": 1,
      "name": "Rock_Slate_Brick_Decorative"
    },
    {
      "x": 2,
      "y": 6,
      "z": 1,
      "name": "Rock_Slate_Brick_Stairs",
      "rotation": 11
    },
    {
      "x": 2,
      "y": 7,
      "z": 1,
      "name": "Furniture_Human_Ruins_Brazier"
    },
    {
      "x": 2,
      "y": 0,
      "z": 2,
      "name": "Rock_Slate_Brick_Decorative"
    },
    {
      "x": 2,
      "y": 0,
      "z": 3,
      "name": "Rock_Slate_Brick_Stairs"
    },
    {
      "x": 3,
      "y": 0,
      "z": -1,
      "name": "Rock_Slate_Brick_Stairs",
      "rotation": 1
    },
    {
      "x": 3,
      "y": 0,
      "z": 2,
      "name": "Rock_Slate_Brick_Stairs",
      "rotation": 1
    }
  ]
}